{"type":"done","side":"sell","order_id":"159b1c72-208b-4570-83dc-f347592389ab","reason":"canceled","product_id":"BTC-EUR","price":"8831.35000000","remaining_size":"0.04164971","sequence":3257977745,"time":"2018-01-22T15:14:37.500000Z"}
{"type":"received","order_id":"e1410f0a-b5b8-4949-a7af-294c02326d7f","order_type":"limit","size":"0.10500000","price":"8831.29000000","side":"sell","client_oid":"9d70195f-a949-4cff-8c4e-a132f2a3b84d","product_id":"BTC-EUR","sequence":3257977746,"time":"2018-01-22T15:14:37.501000Z"}
{"type":"open","side":"sell","price":"8831.29000000","order_id":"e1410f0a-b5b8-4949-a7af-294c02326d7f","remaining_size":"0.10500000","product_id":"BTC-EUR","sequence":3257977747,"time":"2018-01-22T15:14:37.501000Z"}
{"type":"done","side":"sell","order_id":"3e4d6176-0ce6-4919-b285-f89340f0754f","reason":"canceled","product_id":"BTC-EUR","price":"8831.29000000","remaining_size":"0.00113228","sequence":3257977748,"time":"2018-01-22T15:14:37.501000Z"}
{"type":"received","order_id":"1b54adee-518d-451a-9058-7c040352c42e","order_type":"limit","size":"0.06847422","price":"8831.28000000","side":"sell","client_oid":"6e17e9d1-7816-4d4a-a96b-650d531a7089","product_id":"BTC-EUR","sequence":3257977749,"time":"2018-01-22T15:14:37.528000Z"}
{"type":"open","side":"sell","price":"8831.28000000","order_id":"1b54adee-518d-451a-9058-7c040352c42e","remaining_size":"0.06847422","product_id":"BTC-EUR","sequence":3257977750,"time":"2018-01-22T15:14:37.528000Z"}
{"type":"done","side":"sell","order_id":"c78fe7ca-3245-4dac-90e6-039a14b52d1b","reason":"canceled","product_id":"BTC-EUR","price":"8831.30000000","remaining_size":"0.10500000","sequence":3257977751,"time":"2018-01-22T15:14:37.552000Z"}
{"type":"received","order_id":"8abfa50d-6e7f-46bd-9565-933c6c158a70","order_type":"limit","size":"0.03000000","price":"8831.27000000","side":"sell","client_oid":"372c1496-3132-45e7-9508-7b54da4decbe","product_id":"BTC-EUR","sequence":3257977752,"time":"2018-01-22T15:14:37.555000Z"}
{"type":"open","side":"sell","price":"8831.27000000","order_id":"8abfa50d-6e7f-46bd-9565-933c6c158a70","remaining_size":"0.03000000","product_id":"BTC-EUR","sequence":3257977753,"time":"2018-01-22T15:14:37.555000Z"}
{"type":"done","side":"buy","order_id":"fa26d1b4-c7a1-4068-8aee-66369992bee2","reason":"canceled","product_id":"BTC-EUR","price":"8816.88000000","remaining_size":"0.34000000","sequence":3257977754,"time":"2018-01-22T15:14:37.569000Z"}
{"type":"done","side":"sell","order_id":"10c6d4d0-0b61-4898-b89f-9d89c9f58da5","reason":"canceled","product_id":"BTC-EUR","price":"8831.32000000","remaining_size":"0.21404538","sequence":3257977755,"time":"2018-01-22T15:14:37.596000Z"}
{"type":"received","order_id":"b404bd8d-d32e-4f4c-a571-b0892391a4da","order_type":"limit","size":"0.10500000","price":"8831.29000000","side":"sell","client_oid":"984f4036-ed4a-4f53-bbad-17e209ca3040","product_id":"BTC-EUR","sequence":3257977756,"time":"2018-01-22T15:14:37.599000Z"}
{"type":"open","side":"sell","price":"8831.29000000","order_id":"b404bd8d-d32e-4f4c-a571-b0892391a4da","remaining_size":"0.10500000","product_id":"BTC-EUR","sequence":3257977757,"time":"2018-01-22T15:14:37.599000Z"}
{"type":"received","order_id":"3207d329-de22-4d72-a79e-b3f364d38d7f","order_type":"limit","size":"0.00113228","price":"8831.27000000","side":"sell","client_oid":"17f198d7-65ae-49c8-91e2-3fc310e9d88b","product_id":"BTC-EUR","sequence":3257977758,"time":"2018-01-22T15:14:37.609000Z"}
{"type":"open","side":"sell","price":"8831.27000000","order_id":"3207d329-de22-4d72-a79e-b3f364d38d7f","remaining_size":"0.00113228","product_id":"BTC-EUR","sequence":3257977759,"time":"2018-01-22T15:14:37.609000Z"}
{"type":"done","side":"sell","order_id":"e1410f0a-b5b8-4949-a7af-294c02326d7f","reason":"canceled","product_id":"BTC-EUR","price":"8831.29000000","remaining_size":"0.10500000","sequence":3257977760,"time":"2018-01-22T15:14:37.618000Z"}
{"type":"done","side":"sell","order_id":"e194d3f6-b638-47e5-85cd-51646ec1f2dd","reason":"canceled","product_id":"BTC-EUR","price":"8831.29000000","remaining_size":"0.06847422","sequence":3257977761,"time":"2018-01-22T15:14:37.625000Z"}
{"type":"received","order_id":"62a77ddb-fc83-46c7-be49-12081ce08a8d","order_type":"limit","size":"0.10500000","price":"8831.29000000","side":"sell","client_oid":"1577d89a-7534-4a6d-b74c-11a47fe53c20","product_id":"BTC-EUR","sequence":3257977762,"time":"2018-01-22T15:14:37.627000Z"}
{"type":"open","side":"sell","price":"8831.29000000","order_id":"62a77ddb-fc83-46c7-be49-12081ce08a8d","remaining_size":"0.10500000","product_id":"BTC-EUR","sequence":3257977763,"time":"2018-01-22T15:14:37.627000Z"}
{"type":"done","side":"sell","order_id":"1ffbdbfa-ac4a-4c01-93d4-15f7e63fffda","reason":"canceled","product_id":"BTC-EUR","price":"8831.30000000","remaining_size":"0.06847422","sequence":3257977764,"time":"2018-01-22T15:14:37.646000Z"}
{"type":"done","side":"sell","order_id":"0e2913e9-104a-4cfa-96dc-5f11679c9915","reason":"canceled","product_id":"BTC-EUR","price":"8831.28000000","remaining_size":"0.08000000","sequence":3257977765,"time":"2018-01-22T15:14:37.652000Z"}
{"type":"done","side":"buy","order_id":"121669f3-eb64-49c1-9880-7dd0dab607b3","reason":"canceled","product_id":"BTC-EUR","price":"7500.00000000","remaining_size":"0.10000000","sequence":3257977766,"time":"2018-01-22T15:14:37.663000Z"}
{"type":"received","order_id":"c6d654b1-d5e9-44ae-94fd-e34b08f69b5d","order_type":"limit","size":"0.01800000","price":"8831.28000000","side":"sell","client_oid":"652b8f04-0be5-427a-98ed-218855d3ca3b","product_id":"BTC-EUR","sequence":3257977767,"time":"2018-01-22T15:14:37.665000Z"}
{"type":"open","side":"sell","price":"8831.28000000","order_id":"c6d654b1-d5e9-44ae-94fd-e34b08f69b5d","remaining_size":"0.01800000","product_id":"BTC-EUR","sequence":3257977768,"time":"2018-01-22T15:14:37.665000Z"}
{"type":"done","side":"sell","order_id":"b404bd8d-d32e-4f4c-a571-b0892391a4da","reason":"canceled","product_id":"BTC-EUR","price":"8831.29000000","remaining_size":"0.10500000","sequence":3257977769,"time":"2018-01-22T15:14:37.674000Z"}
{"type":"received","order_id":"3fc57684-1374-4589-b156-c09decdb0b0b","order_type":"limit","size":"0.06847422","price":"8831.27000000","side":"sell","client_oid":"f5450c0e-acd7-40e5-8615-3960a880f989","product_id":"BTC-EUR","sequence":3257977770,"time":"2018-01-22T15:14:37.682000Z"}
{"type":"open","side":"sell","price":"8831.27000000","order_id":"3fc57684-1374-4589-b156-c09decdb0b0b","remaining_size":"0.06847422","product_id":"BTC-EUR","sequence":3257977771,"time":"2018-01-22T15:14:37.682000Z"}
{"type":"received","order_id":"4d2f36eb-5972-48d9-b6d3-19f7f076e212","order_type":"limit","size":"0.10500000","price":"8831.27000000","side":"sell","client_oid":"08cbf142-430a-4133-b1bb-94462cb81c51","product_id":"BTC-EUR","sequence":3257977772,"time":"2018-01-22T15:14:37.700000Z"}
{"type":"open","side":"sell","price":"8831.27000000","order_id":"4d2f36eb-5972-48d9-b6d3-19f7f076e212","remaining_size":"0.10500000","product_id":"BTC-EUR","sequence":3257977773,"time":"2018-01-22T15:14:37.700000Z"}
{"type":"done","side":"sell","order_id":"62a77ddb-fc83-46c7-be49-12081ce08a8d","reason":"canceled","product_id":"BTC-EUR","price":"8831.29000000","remaining_size":"0.10500000","sequence":3257977774,"time":"2018-01-22T15:14:37.732000Z"}
{"type":"received","order_id":"61b18e55-a3b3-4b8e-a1c7-a3f004a0c8db","order_type":"limit","size":"0.04164971","price":"8831.26000000","side":"sell","client_oid":"880cbfce-11f0-4eaa-ae4f-971c32eebf7c","product_id":"BTC-EUR","sequence":3257977775,"time":"2018-01-22T15:14:37.734000Z"}
{"type":"open","side":"sell","price":"8831.26000000","order_id":"61b18e55-a3b3-4b8e-a1c7-a3f004a0c8db","remaining_size":"0.04164971","product_id":"BTC-EUR","sequence":3257977776,"time":"2018-01-22T15:14:37.734000Z"}
{"type":"done","side":"sell","order_id":"1b54adee-518d-451a-9058-7c040352c42e","reason":"canceled","product_id":"BTC-EUR","price":"8831.28000000","remaining_size":"0.06847422","sequence":3257977777,"time":"2018-01-22T15:14:37.748000Z"}
{"type":"received","order_id":"fb68bf07-9c5c-480a-bf17-d4e315a969da","order_type":"limit","size":"0.10500000","price":"8831.27000000","side":"sell","client_oid":"2a9f3f98-2f29-471c-a149-2e6ff58bf351","product_id":"BTC-EUR","sequence":3257977778,"time":"2018-01-22T15:14:37.757000Z"}
{"type":"open","side":"sell","price":"8831.27000000","order_id":"fb68bf07-9c5c-480a-bf17-d4e315a969da","remaining_size":"0.10500000","product_id":"BTC-EUR","sequence":3257977779,"time":"2018-01-22T15:14:37.757000Z"}
{"type":"done","side":"sell","order_id":"c6d654b1-d5e9-44ae-94fd-e34b08f69b5d","reason":"canceled","product_id":"BTC-EUR","price":"8831.28000000","remaining_size":"0.01800000","sequence":3257977780,"time":"2018-01-22T15:14:37.761000Z"}
{"type":"done","side":"sell","order_id":"3207d329-de22-4d72-a79e-b3f364d38d7f","reason":"canceled","product_id":"BTC-EUR","price":"8831.27000000","remaining_size":"0.00113228","sequence":3257977781,"time":"2018-01-22T15:14:37.765000Z"}
{"type":"received","order_id":"1c1878f6-10fc-4cb3-aff4-4639e6954607","order_type":"limit","size":"0.06847422","price":"8831.26000000","side":"sell","client_oid":"f1869a31-fd5e-42a1-898a-248e953f5f1c","product_id":"BTC-EUR","sequence":3257977782,"time":"2018-01-22T15:14:37.782000Z"}
{"type":"open","side":"sell","price":"8831.26000000","order_id":"1c1878f6-10fc-4cb3-aff4-4639e6954607","remaining_size":"0.06847422","product_id":"BTC-EUR","sequence":3257977783,"time":"2018-01-22T15:14:37.782000Z"}
{"type":"received","order_id":"70d8afff-d333-4bfb-9466-6c0e15807693","order_type":"limit","size":"0.01800000","price":"8831.26000000","side":"sell","client_oid":"d7c8bb85-ea46-4e65-b6a5-b80a33620c4c","product_id":"BTC-EUR","sequence":3257977784,"time":"2018-01-22T15:14:37.788000Z"}
{"type":"open","side":"sell","price":"8831.26000000","order_id":"70d8afff-d333-4bfb-9466-6c0e15807693","remaining_size":"0.01800000","product_id":"BTC-EUR","sequence":3257977785,"time":"2018-01-22T15:14:37.788000Z"}
{"type":"done","side":"sell","order_id":"4d2f36eb-5972-48d9-b6d3-19f7f076e212","reason":"canceled","product_id":"BTC-EUR","price":"8831.27000000","remaining_size":"0.10500000","sequence":3257977786,"time":"2018-01-22T15:14:37.813000Z"}
{"type":"received","order_id":"6c92e5f9-30ba-4005-bac6-ca23b45b40a2","order_type":"limit","size":"0.00113228","price":"8831.25000000","side":"sell","client_oid":"11c8f27e-e62d-443f-9253-c56b815bab34","product_id":"BTC-EUR","sequence":3257977787,"time":"2018-01-22T15:14:37.835000Z"}
{"type":"open","side":"sell","price":"8831.25000000","order_id":"6c92e5f9-30ba-4005-bac6-ca23b45b40a2","remaining_size":"0.00113228","product_id":"BTC-EUR","sequence":3257977788,"time":"2018-01-22T15:14:37.835000Z"}
{"type":"done","side":"sell","order_id":"ec755e54-ba05-4cae-b091-b98ff39c7db3","reason":"canceled","product_id":"BTC-EUR","price":"8831.32000000","remaining_size":"0.01322632","sequence":3257977789,"time":"2018-01-22T15:14:37.837000Z"}
{"type":"received","order_id":"4541b4e2-cc5c-4536-b221-39625c736748","order_type":"limit","size":"0.10500000","price":"8831.26000000","side":"sell","client_oid":"322de6ec-8322-4e68-a6fa-7fb54559766e","product_id":"BTC-EUR","sequence":3257977790,"time":"2018-01-22T15:14:37.847000Z"}
{"type":"open","side":"sell","price":"8831.26000000","order_id":"4541b4e2-cc5c-4536-b221-39625c736748","remaining_size":"0.10500000","product_id":"BTC-EUR","sequence":3257977791,"time":"2018-01-22T15:14:37.847000Z"}
{"type":"received","order_id":"16ed512f-9296-427b-be2f-f764f11fc9df","order_type":"limit","size":"0.21404538","price":"8831.26000000","side":"sell","product_id":"BTC-EUR","sequence":3257977792,"time":"2018-01-22T15:14:37.854000Z"}
{"type":"open","side":"sell","price":"8831.26000000","order_id":"16ed512f-9296-427b-be2f-f764f11fc9df","remaining_size":"0.21404538","product_id":"BTC-EUR","sequence":3257977793,"time":"2018-01-22T15:14:37.854000Z"}
{"type":"done","side":"sell","order_id":"df0bdea3-6fa8-43ba-b3a7-23cb548d6413","reason":"canceled","product_id":"BTC-EUR","price":"8869.94000000","remaining_size":"0.18000000","sequence":3257977794,"time":"2018-01-22T15:14:37.860000Z"}
{"type":"done","side":"sell","order_id":"27416d2d-0184-4a77-9f94-ad96fb5eb6e7","reason":"canceled","product_id":"BTC-EUR","price":"8831.32000000","remaining_size":"0.22947933","sequence":3257977795,"time":"2018-01-22T15:14:37.869000Z"}
{"type":"done","side":"sell","order_id":"fb68bf07-9c5c-480a-bf17-d4e315a969da","reason":"canceled","product_id":"BTC-EUR","price":"8831.27000000","remaining_size":"0.10500000","sequence":3257977796,"time":"2018-01-22T15:14:37.873000Z"}
{"type":"received","order_id":"d835626f-b1a1-43a1-ba87-6596fe9f4dc7","order_type":"limit","size":"0.10500000","price":"8831.26000000","side":"sell","client_oid":"0b9bd512-1de2-407d-962e-ea1a1c6f9f6e","product_id":"BTC-EUR","sequence":3257977797,"time":"2018-01-22T15:14:37.881000Z"}
{"type":"open","side":"sell","price":"8831.26000000","order_id":"d835626f-b1a1-43a1-ba87-6596fe9f4dc7","remaining_size":"0.10500000","product_id":"BTC-EUR","sequence":3257977798,"time":"2018-01-22T15:14:37.881000Z"}
{"type":"done","side":"sell","order_id":"1c1878f6-10fc-4cb3-aff4-4639e6954607","reason":"canceled","product_id":"BTC-EUR","price":"8831.26000000","remaining_size":"0.06847422","sequence":3257977799,"time":"2018-01-22T15:14:37.903000Z"}
{"type":"done","side":"sell","order_id":"70d8afff-d333-4bfb-9466-6c0e15807693","reason":"canceled","product_id":"BTC-EUR","price":"8831.26000000","remaining_size":"0.01800000","sequence":3257977800,"time":"2018-01-22T15:14:37.912000Z"}
{"type":"done","side":"sell","order_id":"4541b4e2-cc5c-4536-b221-39625c736748","reason":"canceled","product_id":"BTC-EUR","price":"8831.26000000","remaining_size":"0.10500000","sequence":3257977801,"time":"2018-01-22T15:14:37.926000Z"}
{"type":"received","order_id":"016f4240-de12-4f87-a7ae-d4b3333a7ed7","order_type":"limit","size":"0.01800000","price":"8831.24000000","side":"sell","client_oid":"7c53d2ed-4383-4842-86bf-ec9d3da384c1","product_id":"BTC-EUR","sequence":3257977802,"time":"2018-01-22T15:14:37.936000Z"}
{"type":"open","side":"sell","price":"8831.24000000","order_id":"016f4240-de12-4f87-a7ae-d4b3333a7ed7","remaining_size":"0.01800000","product_id":"BTC-EUR","sequence":3257977803,"time":"2018-01-22T15:14:37.936000Z"}
{"type":"received","order_id":"502d12ff-2d23-4f3d-bd33-504929cc19c3","order_type":"limit","size":"0.10500000","price":"8831.25000000","side":"sell","client_oid":"16121eb0-d035-4727-a9e7-3c7b00aa070f","product_id":"BTC-EUR","sequence":3257977804,"time":"2018-01-22T15:14:37.966000Z"}
{"type":"open","side":"sell","price":"8831.25000000","order_id":"502d12ff-2d23-4f3d-bd33-504929cc19c3","remaining_size":"0.10500000","product_id":"BTC-EUR","sequence":3257977805,"time":"2018-01-22T15:14:37.966000Z"}
{"type":"done","side":"sell","order_id":"6c92e5f9-30ba-4005-bac6-ca23b45b40a2","reason":"canceled","product_id":"BTC-EUR","price":"8831.25000000","remaining_size":"0.00113228","sequence":3257977806,"time":"2018-01-22T15:14:37.969000Z"}
{"type":"done","side":"sell","order_id":"8abfa50d-6e7f-46bd-9565-933c6c158a70","reason":"canceled","product_id":"BTC-EUR","price":"8831.27000000","remaining_size":"0.03000000","sequence":3257977807,"time":"2018-01-22T15:14:38.006000Z"}
{"type":"done","side":"sell","order_id":"3fc57684-1374-4589-b156-c09decdb0b0b","reason":"canceled","product_id":"BTC-EUR","price":"8831.27000000","remaining_size":"0.06847422","sequence":3257977808,"time":"2018-01-22T15:14:38.020000Z"}
{"type":"received","order_id":"af1ec9a3-a569-4742-8335-9f4eae35f68a","order_type":"limit","size":"0.00113228","price":"8831.23000000","side":"sell","client_oid":"47971980-5723-406f-a791-8db1b4dc8fa4","product_id":"BTC-EUR","sequence":3257977809,"time":"2018-01-22T15:14:38.024000Z"}
{"type":"open","side":"sell","price":"8831.23000000","order_id":"af1ec9a3-a569-4742-8335-9f4eae35f68a","remaining_size":"0.00113228","product_id":"BTC-EUR","sequence":3257977810,"time":"2018-01-22T15:14:38.024000Z"}
{"type":"received","order_id":"2d92c670-d4b0-419c-bc2f-9b756f269617","order_type":"limit","size":"0.06847422","price":"8831.25000000","side":"sell","client_oid":"4a812bf7-5465-46ba-810f-ede5d7fbd641","product_id":"BTC-EUR","sequence":3257977811,"time":"2018-01-22T15:14:38.034000Z"}
{"type":"open","side":"sell","price":"8831.25000000","order_id":"2d92c670-d4b0-419c-bc2f-9b756f269617","remaining_size":"0.06847422","product_id":"BTC-EUR","sequence":3257977812,"time":"2018-01-22T15:14:38.034000Z"}
{"type":"done","side":"sell","order_id":"502d12ff-2d23-4f3d-bd33-504929cc19c3","reason":"canceled","product_id":"BTC-EUR","price":"8831.25000000","remaining_size":"0.10500000","sequence":3257977813,"time":"2018-01-22T15:14:38.046000Z"}
{"type":"done","side":"buy","order_id":"ef2d4279-d221-47f5-b837-bd0c08e4ff72","reason":"canceled","product_id":"BTC-EUR","price":"8750.01000000","remaining_size":"6.34763622","sequence":3257977814,"time":"2018-01-22T15:14:38.047000Z"}
{"type":"received","order_id":"39f38905-3c7d-4b29-8b73-228a07bccc59","order_type":"limit","size":"0.06847422","price":"8831.24000000","side":"sell","client_oid":"ce770f01-5b3e-4757-892b-6e80b4978ff1","product_id":"BTC-EUR","sequence":3257977815,"time":"2018-01-22T15:14:38.049000Z"}
{"type":"open","side":"sell","price":"8831.24000000","order_id":"39f38905-3c7d-4b29-8b73-228a07bccc59","remaining_size":"0.06847422","product_id":"BTC-EUR","sequence":3257977816,"time":"2018-01-22T15:14:38.049000Z"}
{"type":"done","side":"sell","order_id":"16ed512f-9296-427b-be2f-f764f11fc9df","reason":"canceled","product_id":"BTC-EUR","price":"8831.26000000","remaining_size":"0.21404538","sequence":3257977817,"time":"2018-01-22T15:14:38.055000Z"}
{"type":"received","order_id":"4a04815c-5192-49fb-9561-12f2d49cce57","order_type":"limit","size":"0.01322632","price":"8831.25000000","side":"sell","client_oid":"d77f9bc5-239c-41c1-adf7-3431bfbffdc8","product_id":"BTC-EUR","sequence":3257977818,"time":"2018-01-22T15:14:38.068000Z"}
{"type":"open","side":"sell","price":"8831.25000000","order_id":"4a04815c-5192-49fb-9561-12f2d49cce57","remaining_size":"0.01322632","product_id":"BTC-EUR","sequence":3257977819,"time":"2018-01-22T15:14:38.068000Z"}
{"type":"received","order_id":"4c14c87a-d704-405a-aa2d-717ae15fc359","order_type":"limit","size":"0.50000000","price":"9013.86000000","side":"sell","product_id":"BTC-EUR","sequence":3257977820,"time":"2018-01-22T15:14:38.073000Z"}
{"type":"open","side":"sell","price":"9013.86000000","order_id":"4c14c87a-d704-405a-aa2d-717ae15fc359","remaining_size":"0.50000000","product_id":"BTC-EUR","sequence":3257977821,"time":"2018-01-22T15:14:38.073000Z"}
{"type":"received","order_id":"2b321cab-7872-42fa-baad-c188bd77b056","order_type":"limit","size":"0.01731400","price":"8828.65000000","side":"sell","product_id":"BTC-EUR","sequence":3257977822,"time":"2018-01-22T15:14:38.074000Z"}
{"type":"open","side":"sell","price":"8828.65000000","order_id":"2b321cab-7872-42fa-baad-c188bd77b056","remaining_size":"0.01731400","product_id":"BTC-EUR","sequence":3257977823,"time":"2018-01-22T15:14:38.074000Z"}
{"type":"done","side":"sell","order_id":"af1ec9a3-a569-4742-8335-9f4eae35f68a","reason":"canceled","product_id":"BTC-EUR","price":"8831.23000000","remaining_size":"0.00113228","sequence":3257977824,"time":"2018-01-22T15:14:38.099000Z"}
{"type":"received","order_id":"dd0f96c1-e660-423a-83d1-af9db9097bb7","order_type":"limit","size":"0.22947933","price":"8831.25000000","side":"sell","client_oid":"b49dd330-57ee-4612-9566-4e0ebbcd0ee8","product_id":"BTC-EUR","sequence":3257977825,"time":"2018-01-22T15:14:38.100000Z"}
{"type":"open","side":"sell","price":"8831.25000000","order_id":"dd0f96c1-e660-423a-83d1-af9db9097bb7","remaining_size":"0.22947933","product_id":"BTC-EUR","sequence":3257977826,"time":"2018-01-22T15:14:38.100000Z"}
{"type":"received","order_id":"171e0d12-e380-4538-a911-39f375c06bec","order_type":"limit","size":"0.10500000","price":"8831.24000000","side":"sell","client_oid":"f7e896d5-3b9e-46fd-8500-72de981e01f6","product_id":"BTC-EUR","sequence":3257977827,"time":"2018-01-22T15:14:38.104000Z"}
{"type":"open","side":"sell","price":"8831.24000000","order_id":"171e0d12-e380-4538-a911-39f375c06bec","remaining_size":"0.10500000","product_id":"BTC-EUR","sequence":3257977828,"time":"2018-01-22T15:14:38.104000Z"}
{"type":"received","order_id":"c653e361-6d4d-4fb7-8d37-4e362a65e7b3","order_type":"limit","size":"0.35000000","price":"8825.29000000","side":"buy","product_id":"BTC-EUR","sequence":3257977829,"time":"2018-01-22T15:14:38.106000Z"}
{"type":"open","side":"buy","price":"8825.29000000","order_id":"c653e361-6d4d-4fb7-8d37-4e362a65e7b3","remaining_size":"0.35000000","product_id":"BTC-EUR","sequence":3257977830,"time":"2018-01-22T15:14:38.106000Z"}
{"type":"received","order_id":"082a42f3-8b1c-4892-81df-bc2576dc2d47","order_type":"limit","size":"0.01800000","price":"8831.23000000","side":"sell","client_oid":"f4358471-52b2-49fe-83a6-72f7c40ade45","product_id":"BTC-EUR","sequence":3257977831,"time":"2018-01-22T15:14:38.107000Z"}
{"type":"open","side":"sell","price":"8831.23000000","order_id":"082a42f3-8b1c-4892-81df-bc2576dc2d47","remaining_size":"0.01800000","product_id":"BTC-EUR","sequence":3257977832,"time":"2018-01-22T15:14:38.107000Z"}
{"type":"done","side":"buy","order_id":"38a3a871-21d5-473b-b5c9-d068143e36a8","reason":"canceled","product_id":"BTC-EUR","price":"8823.41000000","remaining_size":"0.00113334","sequence":3257977833,"time":"2018-01-22T15:14:38.122000Z"}
{"type":"done","side":"sell","order_id":"016f4240-de12-4f87-a7ae-d4b3333a7ed7","reason":"canceled","product_id":"BTC-EUR","price":"8831.24000000","remaining_size":"0.01800000","sequence":3257977834,"time":"2018-01-22T15:14:38.122000Z"}
{"type":"received","order_id":"9b8d83d1-1e65-4152-b75f-9234259bc199","order_type":"limit","size":"0.00113228","price":"8828.64000000","side":"sell","client_oid":"09a5eb67-3778-4b7a-acd3-2132df154ab7","product_id":"BTC-EUR","sequence":3257977835,"time":"2018-01-22T15:14:38.166000Z"}
{"type":"open","side":"sell","price":"8828.64000000","order_id":"9b8d83d1-1e65-4152-b75f-9234259bc199","remaining_size":"0.00113228","product_id":"BTC-EUR","sequence":3257977836,"time":"2018-01-22T15:14:38.166000Z"}
{"type":"done","side":"sell","order_id":"171e0d12-e380-4538-a911-39f375c06bec","reason":"canceled","product_id":"BTC-EUR","price":"8831.24000000","remaining_size":"0.10500000","sequence":3257977837,"time":"2018-01-22T15:14:38.177000Z"}
{"type":"received","order_id":"913161ce-33f6-45a6-8956-b47596c29da7","order_type":"limit","size":"0.00113310","price":"8825.30000000","side":"buy","client_oid":"45028efc-82bf-4204-b4a7-1d3c0200c270","product_id":"BTC-EUR","sequence":3257977838,"time":"2018-01-22T15:14:38.191000Z"}
{"type":"open","side":"buy","price":"8825.30000000","order_id":"913161ce-33f6-45a6-8956-b47596c29da7","remaining_size":"0.00113310","product_id":"BTC-EUR","sequence":3257977839,"time":"2018-01-22T15:14:38.191000Z"}
{"type":"done","side":"buy","order_id":"a86d0239-0511-4da8-b266-bd33ab8d6292","reason":"canceled","product_id":"BTC-EUR","price":"8823.41000000","remaining_size":"0.04000000","sequence":3257977840,"time":"2018-01-22T15:14:38.192000Z"}
{"type":"received","order_id":"59f193d7-58f9-4ec0-9f41-d8767685492a","order_type":"limit","size":"0.03000000","price":"8831.24000000","side":"sell","client_oid":"cc68eed2-ff7b-4691-9e19-562164f04d7e","product_id":"BTC-EUR","sequence":3257977841,"time":"2018-01-22T15:14:38.197000Z"}
{"type":"open","side":"sell","price":"8831.24000000","order_id":"59f193d7-58f9-4ec0-9f41-d8767685492a","remaining_size":"0.03000000","product_id":"BTC-EUR","sequence":3257977842,"time":"2018-01-22T15:14:38.197000Z"}
{"type":"received","order_id":"6640222c-1cf6-431f-b192-2523c6884948","order_type":"limit","size":"0.01800000","price":"8831.23000000","side":"sell","client_oid":"5a361a2e-c5d1-48ca-ae8c-27cd482b76a9","product_id":"BTC-EUR","sequence":3257977843,"time":"2018-01-22T15:14:38.205000Z"}
{"type":"open","side":"sell","price":"8831.23000000","order_id":"6640222c-1cf6-431f-b192-2523c6884948","remaining_size":"0.01800000","product_id":"BTC-EUR","sequence":3257977844,"time":"2018-01-22T15:14:38.205000Z"}
{"type":"done","side":"sell","order_id":"082a42f3-8b1c-4892-81df-bc2576dc2d47","reason":"canceled","product_id":"BTC-EUR","price":"8831.23000000","remaining_size":"0.01800000","sequence":3257977845,"time":"2018-01-22T15:14:38.205000Z"}
{"type":"received","order_id":"de7b4018-763a-44c6-8ae9-b05f792c987c","order_type":"limit","size":"0.01800000","price":"8831.22000000","side":"sell","client_oid":"b56f053d-2450-4569-9da4-f1f77a2b4f18","product_id":"BTC-EUR","sequence":3257977846,"time":"2018-01-22T15:14:38.211000Z"}
{"type":"open","side":"sell","price":"8831.22000000","order_id":"de7b4018-763a-44c6-8ae9-b05f792c987c","remaining_size":"0.01800000","product_id":"BTC-EUR","sequence":3257977847,"time":"2018-01-22T15:14:38.211000Z"}
{"type":"done","side":"sell","order_id":"59f193d7-58f9-4ec0-9f41-d8767685492a","reason":"canceled","product_id":"BTC-EUR","price":"8831.24000000","remaining_size":"0.03000000","sequence":3257977848,"time":"2018-01-22T15:14:38.215000Z"}
{"type":"received","order_id":"7a0ea001-bbdd-4744-a843-9d01f8982be9","order_type":"limit","size":"0.00799999","price":"8831.22000000","side":"sell","client_oid":"cdfeb8e9-669f-4f9b-8101-9b8309be4a2c","product_id":"BTC-EUR","sequence":3257977849,"time":"2018-01-22T15:14:38.215000Z"}
{"type":"open","side":"sell","price":"8831.22000000","order_id":"7a0ea001-bbdd-4744-a843-9d01f8982be9","remaining_size":"0.00799999","product_id":"BTC-EUR","sequence":3257977850,"time":"2018-01-22T15:14:38.215000Z"}
{"type":"done","side":"sell","order_id":"2b321cab-7872-42fa-baad-c188bd77b056","reason":"canceled","product_id":"BTC-EUR","price":"8828.65000000","remaining_size":"0.01731400","sequence":3257977851,"time":"2018-01-22T15:14:38.238000Z"}
{"type":"received","order_id":"f969bf81-b4fb-41e3-825e-0ad6b00e6797","order_type":"limit","size":"0.06847422","price":"8831.23000000","side":"sell","client_oid":"816f7b9a-7973-47e7-885b-2e746b96d8a4","product_id":"BTC-EUR","sequence":3257977852,"time":"2018-01-22T15:14:38.241000Z"}
{"type":"open","side":"sell","price":"8831.23000000","order_id":"f969bf81-b4fb-41e3-825e-0ad6b00e6797","remaining_size":"0.06847422","product_id":"BTC-EUR","sequence":3257977853,"time":"2018-01-22T15:14:38.241000Z"}
{"type":"received","order_id":"dc94c86c-9676-49f1-bb74-c3f7a6cf4479","order_type":"limit","size":"0.04000000","price":"8825.30000000","side":"buy","client_oid":"853f344d-52be-4754-a54b-9cf16d5075f2","product_id":"BTC-EUR","sequence":3257977854,"time":"2018-01-22T15:14:38.248000Z"}
{"type":"open","side":"buy","price":"8825.30000000","order_id":"dc94c86c-9676-49f1-bb74-c3f7a6cf4479","remaining_size":"0.04000000","product_id":"BTC-EUR","sequence":3257977855,"time":"2018-01-22T15:14:38.248000Z"}
{"type":"done","side":"buy","order_id":"dc94c86c-9676-49f1-bb74-c3f7a6cf4479","reason":"canceled","product_id":"BTC-EUR","price":"8825.30000000","remaining_size":"0.04000000","sequence":3257977856,"time":"2018-01-22T15:14:38.258000Z"}
{"type":"received","order_id":"40715390-bd44-4b47-a94d-c97c1b8364dc","order_type":"limit","size":"0.03000000","price":"8831.21000000","side":"sell","client_oid":"c0820663-a0eb-4cdc-b391-f8496864401a","product_id":"BTC-EUR","sequence":3257977857,"time":"2018-01-22T15:14:38.270000Z"}
{"type":"open","side":"sell","price":"8831.21000000","order_id":"40715390-bd44-4b47-a94d-c97c1b8364dc","remaining_size":"0.03000000","product_id":"BTC-EUR","sequence":3257977858,"time":"2018-01-22T15:14:38.270000Z"}
{"type":"received","order_id":"3abd30e7-a65d-407e-b4e6-ff775c0d8f81","order_type":"limit","size":"0.01800000","price":"8828.64000000","side":"sell","client_oid":"a0ccb64d-7ef3-4661-98ad-16c5ed8a9aa2","product_id":"BTC-EUR","sequence":3257977859,"time":"2018-01-22T15:14:38.279000Z"}
{"type":"open","side":"sell","price":"8828.64000000","order_id":"3abd30e7-a65d-407e-b4e6-ff775c0d8f81","remaining_size":"0.01800000","product_id":"BTC-EUR","sequence":3257977860,"time":"2018-01-22T15:14:38.279000Z"}
{"type":"received","order_id":"752f5c31-4121-4b18-ba96-cd911390d668","order_type":"limit","size":"0.10500000","price":"8828.65000000","side":"sell","client_oid":"7cc7ed2b-437d-47cc-8127-0f46ed84c8e7","product_id":"BTC-EUR","sequence":3257977861,"time":"2018-01-22T15:14:38.281000Z"}
{"type":"open","side":"sell","price":"8828.65000000","order_id":"752f5c31-4121-4b18-ba96-cd911390d668","remaining_size":"0.10500000","product_id":"BTC-EUR","sequence":3257977862,"time":"2018-01-22T15:14:38.281000Z"}
{"type":"done","side":"sell","order_id":"6640222c-1cf6-431f-b192-2523c6884948","reason":"canceled","product_id":"BTC-EUR","price":"8831.23000000","remaining_size":"0.01800000","sequence":3257977863,"time":"2018-01-22T15:14:38.284000Z"}
{"type":"done","side":"sell","order_id":"40715390-bd44-4b47-a94d-c97c1b8364dc","reason":"canceled","product_id":"BTC-EUR","price":"8831.21000000","remaining_size":"0.03000000","sequence":3257977864,"time":"2018-01-22T15:14:38.287000Z"}
{"type":"received","order_id":"709df843-09ef-4374-9277-ddb43d211225","order_type":"limit","size":"0.04000000","price":"8825.30000000","side":"buy","client_oid":"5ecc1d9d-2822-446b-b508-8f608960de0d","product_id":"BTC-EUR","sequence":3257977865,"time":"2018-01-22T15:14:38.289000Z"}
{"type":"open","side":"buy","price":"8825.30000000","order_id":"709df843-09ef-4374-9277-ddb43d211225","remaining_size":"0.04000000","product_id":"BTC-EUR","sequence":3257977866,"time":"2018-01-22T15:14:38.289000Z"}
{"type":"received","order_id":"735d3d1f-3332-4be9-9d01-ff6049d58d11","order_type":"limit","size":"0.10500000","price":"8828.64000000","side":"sell","client_oid":"80a2c63b-33fe-4a63-a458-7f47640faf84","product_id":"BTC-EUR","sequence":3257977867,"time":"2018-01-22T15:14:38.292000Z"}
{"type":"open","side":"sell","price":"8828.64000000","order_id":"735d3d1f-3332-4be9-9d01-ff6049d58d11","remaining_size":"0.10500000","product_id":"BTC-EUR","sequence":3257977868,"time":"2018-01-22T15:14:38.292000Z"}
{"type":"done","side":"sell","order_id":"39f38905-3c7d-4b29-8b73-228a07bccc59","reason":"canceled","product_id":"BTC-EUR","price":"8831.24000000","remaining_size":"0.06847422","sequence":3257977869,"time":"2018-01-22T15:14:38.292000Z"}
{"type":"done","side":"sell","order_id":"2d92c670-d4b0-419c-bc2f-9b756f269617","reason":"canceled","product_id":"BTC-EUR","price":"8831.25000000","remaining_size":"0.06847422","sequence":3257977870,"time":"2018-01-22T15:14:38.293000Z"}
{"type":"received","order_id":"b073226d-e42f-4eb3-ae80-a8da2b82f91a","order_type":"limit","size":"0.18000000","price":"8878.40000000","side":"sell","product_id":"BTC-EUR","sequence":3257977871,"time":"2018-01-22T15:14:38.297000Z"}
{"type":"open","side":"sell","price":"8878.40000000","order_id":"b073226d-e42f-4eb3-ae80-a8da2b82f91a","remaining_size":"0.18000000","product_id":"BTC-EUR","sequence":3257977872,"time":"2018-01-22T15:14:38.297000Z"}
{"type":"done","side":"sell","order_id":"c04b90bf-9649-4d6f-a0a7-892b3cd6f618","reason":"canceled","product_id":"BTC-EUR","price":"8986.04000000","remaining_size":"0.15121806","sequence":3257977873,"time":"2018-01-22T15:14:38.302000Z"}
{"type":"received","order_id":"f04c5b8c-d24f-45f8-9de1-e22ce8126a64","order_type":"limit","size":"0.06847422","price":"8828.64000000","side":"sell","client_oid":"73ad4895-e41a-40d0-8208-255fcb3c7aef","product_id":"BTC-EUR","sequence":3257977874,"time":"2018-01-22T15:14:38.312000Z"}
{"type":"open","side":"sell","price":"8828.64000000","order_id":"f04c5b8c-d24f-45f8-9de1-e22ce8126a64","remaining_size":"0.06847422","product_id":"BTC-EUR","sequence":3257977875,"time":"2018-01-22T15:14:38.312000Z"}
{"type":"received","order_id":"47c2d507-5788-4573-ae6a-5cc73c67581e","order_type":"limit","size":"0.21404538","price":"8828.64000000","side":"sell","product_id":"BTC-EUR","sequence":3257977876,"time":"2018-01-22T15:14:38.321000Z"}
{"type":"open","side":"sell","price":"8828.64000000","order_id":"47c2d507-5788-4573-ae6a-5cc73c67581e","remaining_size":"0.21404538","product_id":"BTC-EUR","sequence":3257977877,"time":"2018-01-22T15:14:38.321000Z"}
{"type":"received","order_id":"965d3c3b-5f5d-45c0-83d8-d0f6a5e0f862","order_type":"limit","size":"0.01800000","price":"8828.63000000","side":"sell","client_oid":"9938279e-a29b-4f19-8a26-7ca9bb5e19b1","product_id":"BTC-EUR","sequence":3257977878,"time":"2018-01-22T15:14:38.343000Z"}
{"type":"open","side":"sell","price":"8828.63000000","order_id":"965d3c3b-5f5d-45c0-83d8-d0f6a5e0f862","remaining_size":"0.01800000","product_id":"BTC-EUR","sequence":3257977879,"time":"2018-01-22T15:14:38.343000Z"}
{"type":"received","order_id":"37d026c2-2d6d-4ac7-b441-28b67e3894d1","order_type":"limit","size":"0.03000000","price":"8828.64000000","side":"sell","client_oid":"b24860fa-93d0-4095-aa2d-199e2393fb6c","product_id":"BTC-EUR","sequence":3257977880,"time":"2018-01-22T15:14:38.346000Z"}
{"type":"open","side":"sell","price":"8828.64000000","order_id":"37d026c2-2d6d-4ac7-b441-28b67e3894d1","remaining_size":"0.03000000","product_id":"BTC-EUR","sequence":3257977881,"time":"2018-01-22T15:14:38.346000Z"}
{"type":"received","order_id":"50e7fe6e-15b1-4f73-a466-19c046091b77","order_type":"limit","size":"0.06847422","price":"8828.64000000","side":"sell","client_oid":"7c419ab1-3f4c-4f18-ab8e-d1741dc4d720","product_id":"BTC-EUR","sequence":3257977882,"time":"2018-01-22T15:14:38.350000Z"}
{"type":"open","side":"sell","price":"8828.64000000","order_id":"50e7fe6e-15b1-4f73-a466-19c046091b77","remaining_size":"0.06847422","product_id":"BTC-EUR","sequence":3257977883,"time":"2018-01-22T15:14:38.350000Z"}
{"type":"received","order_id":"991923a0-8b11-43f1-9588-9ced1fedbb72","order_type":"limit","size":"0.06847422","price":"8831.22000000","side":"sell","client_oid":"dd1fb509-1aeb-45b4-b340-96918cca314b","product_id":"BTC-EUR","sequence":3257977884,"time":"2018-01-22T15:14:38.351000Z"}
{"type":"open","side":"sell","price":"8831.22000000","order_id":"991923a0-8b11-43f1-9588-9ced1fedbb72","remaining_size":"0.06847422","product_id":"BTC-EUR","sequence":3257977885,"time":"2018-01-22T15:14:38.351000Z"}
{"type":"done","side":"sell","order_id":"de7b4018-763a-44c6-8ae9-b05f792c987c","reason":"canceled","product_id":"BTC-EUR","price":"8831.22000000","remaining_size":"0.01800000","sequence":3257977886,"time":"2018-01-22T15:14:38.357000Z"}
{"type":"done","side":"sell","order_id":"7a0ea001-bbdd-4744-a843-9d01f8982be9","reason":"canceled","product_id":"BTC-EUR","price":"8831.22000000","remaining_size":"0.00799999","sequence":3257977887,"time":"2018-01-22T15:14:38.357000Z"}
{"type":"done","side":"sell","order_id":"2d17827d-cb76-4d3c-908a-366369714df1","reason":"canceled","product_id":"BTC-EUR","price":"8831.30000000","remaining_size":"0.08000000","sequence":3257977888,"time":"2018-01-22T15:14:38.360000Z"}
{"type":"done","side":"sell","order_id":"752f5c31-4121-4b18-ba96-cd911390d668","reason":"canceled","product_id":"BTC-EUR","price":"8828.65000000","remaining_size":"0.10500000","sequence":3257977889,"time":"2018-01-22T15:14:38.364000Z"}
{"type":"received","order_id":"c46dfc71-624e-466c-a106-6bc45fcb5467","order_type":"limit","size":"0.01800000","price":"8828.63000000","side":"sell","client_oid":"aa5ab512-155d-40c8-ac3c-69ac1eb7dcdf","product_id":"BTC-EUR","sequence":3257977890,"time":"2018-01-22T15:14:38.367000Z"}
{"type":"open","side":"sell","price":"8828.63000000","order_id":"c46dfc71-624e-466c-a106-6bc45fcb5467","remaining_size":"0.01800000","product_id":"BTC-EUR","sequence":3257977891,"time":"2018-01-22T15:14:38.367000Z"}
{"type":"received","order_id":"b53ca67a-2daa-408c-be41-98b1bb610bae","order_type":"limit","size":"0.06847422","price":"8828.63000000","side":"sell","client_oid":"5d1559f2-01ab-43d5-8e54-4c417ece9d1d","product_id":"BTC-EUR","sequence":3257977892,"time":"2018-01-22T15:14:38.367000Z"}
{"type":"open","side":"sell","price":"8828.63000000","order_id":"b53ca67a-2daa-408c-be41-98b1bb610bae","remaining_size":"0.06847422","product_id":"BTC-EUR","sequence":3257977893,"time":"2018-01-22T15:14:38.367000Z"}
{"type":"done","side":"sell","order_id":"9b8d83d1-1e65-4152-b75f-9234259bc199","reason":"canceled","product_id":"BTC-EUR","price":"8828.64000000","remaining_size":"0.00113228","sequence":3257977894,"time":"2018-01-22T15:14:38.371000Z"}
{"type":"done","side":"sell","order_id":"f726a3ae-345a-489a-b6d6-10f5a7c2a4ae","reason":"canceled","product_id":"BTC-EUR","price":"8831.30000000","remaining_size":"0.09800000","sequence":3257977895,"time":"2018-01-22T15:14:38.394000Z"}
{"type":"done","side":"sell","order_id":"37d026c2-2d6d-4ac7-b441-28b67e3894d1","reason":"canceled","product_id":"BTC-EUR","price":"8828.64000000","remaining_size":"0.03000000","sequence":3257977896,"time":"2018-01-22T15:14:38.411000Z"}
{"type":"done","side":"sell","order_id":"735d3d1f-3332-4be9-9d01-ff6049d58d11","reason":"canceled","product_id":"BTC-EUR","price":"8828.64000000","remaining_size":"0.10500000","sequence":3257977897,"time":"2018-01-22T15:14:38.425000Z"}
{"type":"received","order_id":"8e60c66a-3af2-4d4c-82a0-206c38d98766","order_type":"limit","size":"0.00113228","price":"8828.62000000","side":"sell","client_oid":"24538a09-5ed1-4928-969e-2b100af910b7","product_id":"BTC-EUR","sequence":3257977898,"time":"2018-01-22T15:14:38.426000Z"}
{"type":"open","side":"sell","price":"8828.62000000","order_id":"8e60c66a-3af2-4d4c-82a0-206c38d98766","remaining_size":"0.00113228","product_id":"BTC-EUR","sequence":3257977899,"time":"2018-01-22T15:14:38.426000Z"}
{"type":"done","side":"sell","order_id":"3abd30e7-a65d-407e-b4e6-ff775c0d8f81","reason":"canceled","product_id":"BTC-EUR","price":"8828.64000000","remaining_size":"0.01800000","sequence":3257977900,"time":"2018-01-22T15:14:38.440000Z"}
{"type":"received","order_id":"994fd763-53f6-42ca-8adc-75aeb68327d3","order_type":"limit","size":"0.10500000","price":"8828.63000000","side":"sell","client_oid":"eae1c267-c293-488b-989d-9a618389f773","product_id":"BTC-EUR","sequence":3257977901,"time":"2018-01-22T15:14:38.449000Z"}
{"type":"open","side":"sell","price":"8828.63000000","order_id":"994fd763-53f6-42ca-8adc-75aeb68327d3","remaining_size":"0.10500000","product_id":"BTC-EUR","sequence":3257977902,"time":"2018-01-22T15:14:38.449000Z"}
{"type":"received","order_id":"507f1840-fc9b-46a9-8a76-fef446aeec57","order_type":"limit","size":"0.03000000","price":"8828.62000000","side":"sell","client_oid":"3efefe63-f7bd-4dbb-a60e-579621b77a12","product_id":"BTC-EUR","sequence":3257977903,"time":"2018-01-22T15:14:38.454000Z"}
{"type":"open","side":"sell","price":"8828.62000000","order_id":"507f1840-fc9b-46a9-8a76-fef446aeec57","remaining_size":"0.03000000","product_id":"BTC-EUR","sequence":3257977904,"time":"2018-01-22T15:14:38.454000Z"}
{"type":"done","side":"sell","order_id":"47c2d507-5788-4573-ae6a-5cc73c67581e","reason":"canceled","product_id":"BTC-EUR","price":"8828.64000000","remaining_size":"0.21404538","sequence":3257977905,"time":"2018-01-22T15:14:38.466000Z"}
{"type":"received","order_id":"b4abad09-56e8-4bc1-a9b9-371f4b9017bc","order_type":"limit","size":"0.01800000","price":"8828.62000000","side":"sell","client_oid":"5e84dd74-99d7-41b1-8267-9c483457b0bd","product_id":"BTC-EUR","sequence":3257977906,"time":"2018-01-22T15:14:38.473000Z"}
{"type":"open","side":"sell","price":"8828.62000000","order_id":"b4abad09-56e8-4bc1-a9b9-371f4b9017bc","remaining_size":"0.01800000","product_id":"BTC-EUR","sequence":3257977907,"time":"2018-01-22T15:14:38.473000Z"}
{"type":"done","side":"sell","order_id":"b53ca67a-2daa-408c-be41-98b1bb610bae","reason":"canceled","product_id":"BTC-EUR","price":"8828.63000000","remaining_size":"0.06847422","sequence":3257977908,"time":"2018-01-22T15:14:38.514000Z"}
{"type":"done","side":"sell","order_id":"965d3c3b-5f5d-45c0-83d8-d0f6a5e0f862","reason":"canceled","product_id":"BTC-EUR","price":"8828.63000000","remaining_size":"0.01800000","sequence":3257977909,"time":"2018-01-22T15:14:38.515000Z"}
{"type":"received","order_id":"c7d7b01c-d51a-4e12-a2ad-fb442acb2102","order_type":"limit","size":"0.01800000","price":"8828.62000000","side":"sell","client_oid":"5090a500-48d4-4122-920a-007d4ebf7cc2","product_id":"BTC-EUR","sequence":3257977910,"time":"2018-01-22T15:14:38.519000Z"}
{"type":"open","side":"sell","price":"8828.62000000","order_id":"c7d7b01c-d51a-4e12-a2ad-fb442acb2102","remaining_size":"0.01800000","product_id":"BTC-EUR","sequence":3257977911,"time":"2018-01-22T15:14:38.519000Z"}
{"type":"done","side":"sell","order_id":"994fd763-53f6-42ca-8adc-75aeb68327d3","reason":"canceled","product_id":"BTC-EUR","price":"8828.63000000","remaining_size":"0.10500000","sequence":3257977912,"time":"2018-01-22T15:14:38.531000Z"}
{"type":"done","side":"sell","order_id":"c46dfc71-624e-466c-a106-6bc45fcb5467","reason":"canceled","product_id":"BTC-EUR","price":"8828.63000000","remaining_size":"0.01800000","sequence":3257977913,"time":"2018-01-22T15:14:38.549000Z"}
{"type":"received","order_id":"6009cfc2-ac0b-4b9b-a7c0-d3f25e40cc73","order_type":"limit","size":"0.01800000","price":"8828.61000000","side":"sell","client_oid":"daf13991-8419-4be3-94c2-2ebb86a683bf","product_id":"BTC-EUR","sequence":3257977914,"time":"2018-01-22T15:14:38.559000Z"}
{"type":"open","side":"sell","price":"8828.61000000","order_id":"6009cfc2-ac0b-4b9b-a7c0-d3f25e40cc73","remaining_size":"0.01800000","product_id":"BTC-EUR","sequence":3257977915,"time":"2018-01-22T15:14:38.559000Z"}
{"type":"received","order_id":"d39f1d18-c3da-410a-85ed-da861dbbe73f","order_type":"limit","size":"0.10500000","price":"8828.62000000","side":"sell","client_oid":"1c7245f2-be60-4865-90b5-db6b50b9b316","product_id":"BTC-EUR","sequence":3257977916,"time":"2018-01-22T15:14:38.559000Z"}
{"type":"open","side":"sell","price":"8828.62000000","order_id":"d39f1d18-c3da-410a-85ed-da861dbbe73f","remaining_size":"0.10500000","product_id":"BTC-EUR","sequence":3257977917,"time":"2018-01-22T15:14:38.559000Z"}
{"type":"done","side":"sell","order_id":"8e60c66a-3af2-4d4c-82a0-206c38d98766","reason":"canceled","product_id":"BTC-EUR","price":"8828.62000000","remaining_size":"0.00113228","sequence":3257977918,"time":"2018-01-22T15:14:38.570000Z"}
{"type":"received","order_id":"915b263b-fcb6-4750-a5d9-0ac00cb19f0c","order_type":"limit","size":"0.10500000","price":"8828.62000000","side":"sell","client_oid":"0a5915c7-2f88-45e2-b1fa-ea2568bc11d4","product_id":"BTC-EUR","sequence":3257977919,"time":"2018-01-22T15:14:38.615000Z"}
{"type":"open","side":"sell","price":"8828.62000000","order_id":"915b263b-fcb6-4750-a5d9-0ac00cb19f0c","remaining_size":"0.10500000","product_id":"BTC-EUR","sequence":3257977920,"time":"2018-01-22T15:14:38.615000Z"}
{"type":"received","order_id":"638aa374-1398-4567-9420-ca4677963b9d","order_type":"limit","size":"0.00113228","price":"8828.60000000","side":"sell","client_oid":"048a8ea6-addf-4214-b495-12f52d40f21a","product_id":"BTC-EUR","sequence":3257977921,"time":"2018-01-22T15:14:38.631000Z"}
{"type":"open","side":"sell","price":"8828.60000000","order_id":"638aa374-1398-4567-9420-ca4677963b9d","remaining_size":"0.00113228","product_id":"BTC-EUR","sequence":3257977922,"time":"2018-01-22T15:14:38.631000Z"}
{"type":"done","side":"sell","order_id":"f04c5b8c-d24f-45f8-9de1-e22ce8126a64","reason":"canceled","product_id":"BTC-EUR","price":"8828.64000000","remaining_size":"0.06847422","sequence":3257977923,"time":"2018-01-22T15:14:38.632000Z"}
{"type":"done","side":"sell","order_id":"50e7fe6e-15b1-4f73-a466-19c046091b77","reason":"canceled","product_id":"BTC-EUR","price":"8828.64000000","remaining_size":"0.06847422","sequence":3257977924,"time":"2018-01-22T15:14:38.632000Z"}
{"type":"done","side":"sell","order_id":"991923a0-8b11-43f1-9588-9ced1fedbb72","reason":"canceled","product_id":"BTC-EUR","price":"8831.22000000","remaining_size":"0.06847422","sequence":3257977925,"time":"2018-01-22T15:14:38.635000Z"}
{"type":"done","side":"sell","order_id":"f969bf81-b4fb-41e3-825e-0ad6b00e6797","reason":"canceled","product_id":"BTC-EUR","price":"8831.23000000","remaining_size":"0.06847422","sequence":3257977926,"time":"2018-01-22T15:14:38.635000Z"}
{"type":"received","order_id":"fe8a367e-187c-427e-aa91-0ecbc092800b","order_type":"limit","size":"0.01800000","price":"8828.61000000","side":"sell","client_oid":"1f9f05a8-c84b-4669-907c-bef281895a74","product_id":"BTC-EUR","sequence":3257977927,"time":"2018-01-22T15:14:38.637000Z"}
{"type":"open","side":"sell","price":"8828.61000000","order_id":"fe8a367e-187c-427e-aa91-0ecbc092800b","remaining_size":"0.01800000","product_id":"BTC-EUR","sequence":3257977928,"time":"2018-01-22T15:14:38.637000Z"}
{"type":"done","side":"sell","order_id":"d39f1d18-c3da-410a-85ed-da861dbbe73f","reason":"canceled","product_id":"BTC-EUR","price":"8828.62000000","remaining_size":"0.10500000","sequence":3257977929,"time":"2018-01-22T15:14:38.638000Z"}
{"type":"done","side":"sell","order_id":"507f1840-fc9b-46a9-8a76-fef446aeec57","reason":"canceled","product_id":"BTC-EUR","price":"8828.62000000","remaining_size":"0.03000000","sequence":3257977930,"time":"2018-01-22T15:14:38.644000Z"}
{"type":"done","side":"sell","order_id":"82d87309-f9a4-4443-9a38-c44e6ea56a30","reason":"canceled","product_id":"BTC-EUR","price":"9030.25000000","remaining_size":"0.50000000","sequence":3257977931,"time":"2018-01-22T15:14:38.644000Z"}
{"type":"received","order_id":"f883179b-436a-4556-a17e-a9806e4c9df4","order_type":"limit","size":"0.06847422","price":"8828.62000000","side":"sell","client_oid":"7ab3d136-272e-4618-8668-2f0496734d25","product_id":"BTC-EUR","sequence":3257977932,"time":"2018-01-22T15:14:38.645000Z"}
{"type":"open","side":"sell","price":"8828.62000000","order_id":"f883179b-436a-4556-a17e-a9806e4c9df4","remaining_size":"0.06847422","product_id":"BTC-EUR","sequence":3257977933,"time":"2018-01-22T15:14:38.645000Z"}
{"type":"received","order_id":"969b1352-193e-4aa6-b852-737396fff5ac","order_type":"limit","size":"0.06847422","price":"8828.61000000","side":"sell","client_oid":"3c8f7b2d-420b-4872-97c5-381da6041547","product_id":"BTC-EUR","sequence":3257977934,"time":"2018-01-22T15:14:38.655000Z"}
{"type":"open","side":"sell","price":"8828.61000000","order_id":"969b1352-193e-4aa6-b852-737396fff5ac","remaining_size":"0.06847422","product_id":"BTC-EUR","sequence":3257977935,"time":"2018-01-22T15:14:38.655000Z"}
{"type":"done","side":"sell","order_id":"c7d7b01c-d51a-4e12-a2ad-fb442acb2102","reason":"canceled","product_id":"BTC-EUR","price":"8828.62000000","remaining_size":"0.01800000","sequence":3257977936,"time":"2018-01-22T15:14:38.663000Z"}
{"type":"received","order_id":"18a2ce08-1568-4874-af2d-59f47f725f82","order_type":"limit","size":"0.01800000","price":"8828.60000000","side":"sell","client_oid":"fad99e7a-6463-4632-b359-8b3a5daece1b","product_id":"BTC-EUR","sequence":3257977937,"time":"2018-01-22T15:14:38.673000Z"}
{"type":"open","side":"sell","price":"8828.60000000","order_id":"18a2ce08-1568-4874-af2d-59f47f725f82","remaining_size":"0.01800000","product_id":"BTC-EUR","sequence":3257977938,"time":"2018-01-22T15:14:38.673000Z"}
{"type":"received","order_id":"751bccc0-d6e2-4cb3-9140-862b9931c9ed","order_type":"limit","size":"0.10500000","price":"8828.61000000","side":"sell","client_oid":"d12426e1-73ea-4ee2-8240-979cbfb9c376","product_id":"BTC-EUR","sequence":3257977939,"time":"2018-01-22T15:14:38.677000Z"}
{"type":"open","side":"sell","price":"8828.61000000","order_id":"751bccc0-d6e2-4cb3-9140-862b9931c9ed","remaining_size":"0.10500000","product_id":"BTC-EUR","sequence":3257977940,"time":"2018-01-22T15:14:38.677000Z"}
{"type":"done","side":"sell","order_id":"d835626f-b1a1-43a1-ba87-6596fe9f4dc7","reason":"canceled","product_id":"BTC-EUR","price":"8831.26000000","remaining_size":"0.10500000","sequence":3257977941,"time":"2018-01-22T15:14:38.693000Z"}
{"type":"received","order_id":"1d802245-4a76-4865-81ff-7fcf786184f9","order_type":"limit","size":"0.01800000","price":"8828.61000000","side":"sell","client_oid":"d3e84c9c-2387-4c3a-ab49-276438f54ecc","product_id":"BTC-EUR","sequence":3257977942,"time":"2018-01-22T15:14:38.698000Z"}
{"type":"open","side":"sell","price":"8828.61000000","order_id":"1d802245-4a76-4865-81ff-7fcf786184f9","remaining_size":"0.01800000","product_id":"BTC-EUR","sequence":3257977943,"time":"2018-01-22T15:14:38.698000Z"}
{"type":"done","side":"sell","order_id":"b4abad09-56e8-4bc1-a9b9-371f4b9017bc","reason":"canceled","product_id":"BTC-EUR","price":"8828.62000000","remaining_size":"0.01800000","sequence":3257977944,"time":"2018-01-22T15:14:38.701000Z"}
{"type":"received","order_id":"3ee0c585-1c7c-4e6a-a3c1-abe3cc0fe9e5","order_type":"limit","size":"0.03000000","price":"8828.60000000","side":"sell","client_oid":"a4db2d7e-54d4-447e-b0e7-bde3cd78f43a","product_id":"BTC-EUR","sequence":3257977945,"time":"2018-01-22T15:14:38.704000Z"}
{"type":"open","side":"sell","price":"8828.60000000","order_id":"3ee0c585-1c7c-4e6a-a3c1-abe3cc0fe9e5","remaining_size":"0.03000000","product_id":"BTC-EUR","sequence":3257977946,"time":"2018-01-22T15:14:38.704000Z"}
{"type":"done","side":"sell","order_id":"fe8a367e-187c-427e-aa91-0ecbc092800b","reason":"canceled","product_id":"BTC-EUR","price":"8828.61000000","remaining_size":"0.01800000","sequence":3257977947,"time":"2018-01-22T15:14:38.715000Z"}
{"type":"received","order_id":"b2479134-854a-458b-8106-83ecca2d1b8b","order_type":"limit","size":"0.10500000","price":"8828.61000000","side":"sell","client_oid":"09ed434f-3412-40dc-a16e-9855253e86e6","product_id":"BTC-EUR","sequence":3257977948,"time":"2018-01-22T15:14:38.720000Z"}
{"type":"open","side":"sell","price":"8828.61000000","order_id":"b2479134-854a-458b-8106-83ecca2d1b8b","remaining_size":"0.10500000","product_id":"BTC-EUR","sequence":3257977949,"time":"2018-01-22T15:14:38.720000Z"}
{"type":"done","side":"sell","order_id":"6009cfc2-ac0b-4b9b-a7c0-d3f25e40cc73","reason":"canceled","product_id":"BTC-EUR","price":"8828.61000000","remaining_size":"0.01800000","sequence":3257977950,"time":"2018-01-22T15:14:38.739000Z"}
{"type":"received","order_id":"6619e0b4-c165-463c-b707-fed3fc7c9ab9","order_type":"limit","size":"0.21404538","price":"8828.60000000","side":"sell","product_id":"BTC-EUR","sequence":3257977951,"time":"2018-01-22T15:14:38.752000Z"}
{"type":"open","side":"sell","price":"8828.60000000","order_id":"6619e0b4-c165-463c-b707-fed3fc7c9ab9","remaining_size":"0.21404538","product_id":"BTC-EUR","sequence":3257977952,"time":"2018-01-22T15:14:38.752000Z"}
{"type":"done","side":"sell","order_id":"751bccc0-d6e2-4cb3-9140-862b9931c9ed","reason":"canceled","product_id":"BTC-EUR","price":"8828.61000000","remaining_size":"0.10500000","sequence":3257977953,"time":"2018-01-22T15:14:38.752000Z"}
{"type":"received","order_id":"55d8c934-886d-4013-8a03-0b60957e1c98","order_type":"limit","size":"0.00564464","price":"8825.33000000","side":"buy","client_oid":"4c4803a2-d37a-440c-9cbd-fcdf56e6dd34","product_id":"BTC-EUR","sequence":3257977954,"time":"2018-01-22T15:14:38.766000Z"}
{"type":"open","side":"buy","price":"8825.33000000","order_id":"55d8c934-886d-4013-8a03-0b60957e1c98","remaining_size":"0.00564464","product_id":"BTC-EUR","sequence":3257977955,"time":"2018-01-22T15:14:38.766000Z"}
{"type":"done","side":"buy","order_id":"913161ce-33f6-45a6-8956-b47596c29da7","reason":"canceled","product_id":"BTC-EUR","price":"8825.30000000","remaining_size":"0.00113310","sequence":3257977956,"time":"2018-01-22T15:14:38.778000Z"}
{"type":"received","order_id":"d9a9670f-7950-4995-82a8-b6520f9c1467","order_type":"limit","size":"0.10500000","price":"8828.60000000","side":"sell","client_oid":"9973ed30-66ab-4be6-a3bb-9730ffe74c0f","product_id":"BTC-EUR","sequence":3257977957,"time":"2018-01-22T15:14:38.782000Z"}
{"type":"open","side":"sell","price":"8828.60000000","order_id":"d9a9670f-7950-4995-82a8-b6520f9c1467","remaining_size":"0.10500000","product_id":"BTC-EUR","sequence":3257977958,"time":"2018-01-22T15:14:38.782000Z"}
{"type":"received","order_id":"25522c6b-de3a-4c68-8cc0-e47ec26f7852","order_type":"limit","size":"0.01800000","price":"8828.59000000","side":"sell","client_oid":"356d61f6-a67a-48ef-8e6d-9230f46af6ed","product_id":"BTC-EUR","sequence":3257977959,"time":"2018-01-22T15:14:38.788000Z"}
{"type":"open","side":"sell","price":"8828.59000000","order_id":"25522c6b-de3a-4c68-8cc0-e47ec26f7852","remaining_size":"0.01800000","product_id":"BTC-EUR","sequence":3257977960,"time":"2018-01-22T15:14:38.788000Z"}
{"type":"done","side":"sell","order_id":"1d802245-4a76-4865-81ff-7fcf786184f9","reason":"canceled","product_id":"BTC-EUR","price":"8828.61000000","remaining_size":"0.01800000","sequence":3257977961,"time":"2018-01-22T15:14:38.789000Z"}
{"type":"done","side":"sell","order_id":"61b18e55-a3b3-4b8e-a1c7-a3f004a0c8db","reason":"canceled","product_id":"BTC-EUR","price":"8831.26000000","remaining_size":"0.04164971","sequence":3257977962,"time":"2018-01-22T15:14:38.795000Z"}
{"type":"received","order_id":"3be84140-f059-4967-b071-42f87f668aa1","order_type":"limit","size":"0.06847422","price":"8828.60000000","side":"sell","client_oid":"878ededc-99a1-4731-8acd-a0ab72496a3c","product_id":"BTC-EUR","sequence":3257977963,"time":"2018-01-22T15:14:38.801000Z"}
{"type":"open","side":"sell","price":"8828.60000000","order_id":"3be84140-f059-4967-b071-42f87f668aa1","remaining_size":"0.06847422","product_id":"BTC-EUR","sequence":3257977964,"time":"2018-01-22T15:14:38.801000Z"}
{"type":"done","side":"sell","order_id":"b2479134-854a-458b-8106-83ecca2d1b8b","reason":"canceled","product_id":"BTC-EUR","price":"8828.61000000","remaining_size":"0.10500000","sequence":3257977965,"time":"2018-01-22T15:14:38.814000Z"}
{"type":"received","order_id":"2c0c80bc-d2b2-46c1-93a7-c13afae5bcc8","order_type":"limit","size":"0.00113310","price":"8825.34000000","side":"buy","client_oid":"3e0f667b-674a-4130-a230-a5ea5a173d99","product_id":"BTC-EUR","sequence":3257977966,"time":"2018-01-22T15:14:38.818000Z"}
{"type":"open","side":"buy","price":"8825.34000000","order_id":"2c0c80bc-d2b2-46c1-93a7-c13afae5bcc8","remaining_size":"0.00113310","product_id":"BTC-EUR","sequence":3257977967,"time":"2018-01-22T15:14:38.818000Z"}
{"type":"received","order_id":"6ffdf50c-90cc-49ec-82a4-05c680fa5141","order_type":"limit","size":"0.01800000","price":"8828.59000000","side":"sell","client_oid":"d5075464-b057-43df-9d7e-5573f457b75d","product_id":"BTC-EUR","sequence":3257977968,"time":"2018-01-22T15:14:38.821000Z"}
{"type":"open","side":"sell","price":"8828.59000000","order_id":"6ffdf50c-90cc-49ec-82a4-05c680fa5141","remaining_size":"0.01800000","product_id":"BTC-EUR","sequence":3257977969,"time":"2018-01-22T15:14:38.821000Z"}
{"type":"done","side":"sell","order_id":"638aa374-1398-4567-9420-ca4677963b9d","reason":"canceled","product_id":"BTC-EUR","price":"8828.60000000","remaining_size":"0.00113228","sequence":3257977970,"time":"2018-01-22T15:14:38.832000Z"}
{"type":"done","side":"sell","order_id":"3ee0c585-1c7c-4e6a-a3c1-abe3cc0fe9e5","reason":"canceled","product_id":"BTC-EUR","price":"8828.60000000","remaining_size":"0.03000000","sequence":3257977971,"time":"2018-01-22T15:14:38.846000Z"}
{"type":"done","side":"sell","order_id":"18a2ce08-1568-4874-af2d-59f47f725f82","reason":"canceled","product_id":"BTC-EUR","price":"8828.60000000","remaining_size":"0.01800000","sequence":3257977972,"time":"2018-01-22T15:14:38.871000Z"}
{"type":"done","side":"sell","order_id":"d9a9670f-7950-4995-82a8-b6520f9c1467","reason":"canceled","product_id":"BTC-EUR","price":"8828.60000000","remaining_size":"0.10500000","sequence":3257977973,"time":"2018-01-22T15:14:38.872000Z"}
{"type":"received","order_id":"b1235b19-a462-448c-b429-6be46087b54e","order_type":"limit","size":"0.10500000","price":"8828.59000000","side":"sell","client_oid":"d8ea7573-852d-49b8-b2a2-0198bd88f5b5","product_id":"BTC-EUR","sequence":3257977974,"time":"2018-01-22T15:14:38.895000Z"}
{"type":"open","side":"sell","price":"8828.59000000","order_id":"b1235b19-a462-448c-b429-6be46087b54e","remaining_size":"0.10500000","product_id":"BTC-EUR","sequence":3257977975,"time":"2018-01-22T15:14:38.895000Z"}
{"type":"received","order_id":"fb2870aa-9f2b-4e33-98b9-38aeb711374f","order_type":"limit","size":"0.10500000","price":"8828.59000000","side":"sell","client_oid":"ebe5b50a-a5b6-4d81-84a5-34e9dad3e877","product_id":"BTC-EUR","sequence":3257977976,"time":"2018-01-22T15:14:38.913000Z"}
{"type":"open","side":"sell","price":"8828.59000000","order_id":"fb2870aa-9f2b-4e33-98b9-38aeb711374f","remaining_size":"0.10500000","product_id":"BTC-EUR","sequence":3257977977,"time":"2018-01-22T15:14:38.913000Z"}
{"type":"done","side":"sell","order_id":"6619e0b4-c165-463c-b707-fed3fc7c9ab9","reason":"canceled","product_id":"BTC-EUR","price":"8828.60000000","remaining_size":"0.21404538","sequence":3257977978,"time":"2018-01-22T15:14:38.921000Z"}
{"type":"done","side":"sell","order_id":"969b1352-193e-4aa6-b852-737396fff5ac","reason":"canceled","product_id":"BTC-EUR","price":"8828.61000000","remaining_size":"0.06847422","sequence":3257977979,"time":"2018-01-22T15:14:38.939000Z"}
{"type":"done","side":"sell","order_id":"f883179b-436a-4556-a17e-a9806e4c9df4","reason":"canceled","product_id":"BTC-EUR","price":"8828.62000000","remaining_size":"0.06847422","sequence":3257977980,"time":"2018-01-22T15:14:38.939000Z"}
{"type":"done","side":"buy","order_id":"2c0c80bc-d2b2-46c1-93a7-c13afae5bcc8","reason":"canceled","product_id":"BTC-EUR","price":"8825.34000000","remaining_size":"0.00113310","sequence":3257977981,"time":"2018-01-22T15:14:38.946000Z"}
{"type":"received","order_id":"b033873e-6ffb-4f50-8673-b9e07365140e","order_type":"limit","size":"0.03000000","price":"8828.58000000","side":"sell","client_oid":"38d45b2f-06e6-41db-ba8a-5d4f9da6b852","product_id":"BTC-EUR","sequence":3257977982,"time":"2018-01-22T15:14:38.949000Z"}
{"type":"open","side":"sell","price":"8828.58000000","order_id":"b033873e-6ffb-4f50-8673-b9e07365140e","remaining_size":"0.03000000","product_id":"BTC-EUR","sequence":3257977983,"time":"2018-01-22T15:14:38.949000Z"}
{"type":"received","order_id":"b7cd2fc5-54c6-483a-8950-0e1e32a30c66","order_type":"limit","size":"0.01800000","price":"8828.58000000","side":"sell","client_oid":"3338b4d6-03fe-4bf8-859f-5fe19124e7b3","product_id":"BTC-EUR","sequence":3257977984,"time":"2018-01-22T15:14:38.954000Z"}
{"type":"open","side":"sell","price":"8828.58000000","order_id":"b7cd2fc5-54c6-483a-8950-0e1e32a30c66","remaining_size":"0.01800000","product_id":"BTC-EUR","sequence":3257977985,"time":"2018-01-22T15:14:38.954000Z"}
{"type":"received","order_id":"2df3f89f-3ea1-4353-97cb-d1d42cd16721","order_type":"limit","size":"0.06847422","price":"8828.59000000","side":"sell","client_oid":"b0313191-47ba-4753-86fd-93412f43cf13","product_id":"BTC-EUR","sequence":3257977986,"time":"2018-01-22T15:14:38.955000Z"}
{"type":"open","side":"sell","price":"8828.59000000","order_id":"2df3f89f-3ea1-4353-97cb-d1d42cd16721","remaining_size":"0.06847422","product_id":"BTC-EUR","sequence":3257977987,"time":"2018-01-22T15:14:38.955000Z"}
{"type":"done","side":"sell","order_id":"3be84140-f059-4967-b071-42f87f668aa1","reason":"canceled","product_id":"BTC-EUR","price":"8828.60000000","remaining_size":"0.06847422","sequence":3257977988,"time":"2018-01-22T15:14:39.022000Z"}
{"type":"done","side":"sell","order_id":"25522c6b-de3a-4c68-8cc0-e47ec26f7852","reason":"canceled","product_id":"BTC-EUR","price":"8828.59000000","remaining_size":"0.01800000","sequence":3257977989,"time":"2018-01-22T15:14:39.027000Z"}
{"type":"done","side":"sell","order_id":"b1235b19-a462-448c-b429-6be46087b54e","reason":"canceled","product_id":"BTC-EUR","price":"8828.59000000","remaining_size":"0.10500000","sequence":3257977990,"time":"2018-01-22T15:14:39.030000Z"}
{"type":"done","side":"sell","order_id":"fb2870aa-9f2b-4e33-98b9-38aeb711374f","reason":"canceled","product_id":"BTC-EUR","price":"8828.59000000","remaining_size":"0.10500000","sequence":3257977991,"time":"2018-01-22T15:14:39.054000Z"}
{"type":"received","order_id":"0fb76532-ad19-4c15-976a-97ca8b56a54f","order_type":"limit","size":"0.04164971","price":"8828.59000000","side":"sell","client_oid":"f474a309-2817-4b47-a373-447b3ad3fe0e","product_id":"BTC-EUR","sequence":3257977992,"time":"2018-01-22T15:14:39.074000Z"}
{"type":"open","side":"sell","price":"8828.59000000","order_id":"0fb76532-ad19-4c15-976a-97ca8b56a54f","remaining_size":"0.04164971","product_id":"BTC-EUR","sequence":3257977993,"time":"2018-01-22T15:14:39.074000Z"}
{"type":"received","order_id":"6739c471-5895-444b-84b1-05c063106d30","order_type":"limit","size":"0.00113228","price":"8828.58000000","side":"sell","client_oid":"185dd51b-fe0b-40ec-8776-bd5f02352bfe","product_id":"BTC-EUR","sequence":3257977994,"time":"2018-01-22T15:14:39.075000Z"}
{"type":"open","side":"sell","price":"8828.58000000","order_id":"6739c471-5895-444b-84b1-05c063106d30","remaining_size":"0.00113228","product_id":"BTC-EUR","sequence":3257977995,"time":"2018-01-22T15:14:39.075000Z"}
{"type":"done","side":"sell","order_id":"6739c471-5895-444b-84b1-05c063106d30","reason":"canceled","product_id":"BTC-EUR","price":"8828.58000000","remaining_size":"0.00113228","sequence":3257977996,"time":"2018-01-22T15:14:39.080000Z"}
{"type":"received","order_id":"d12d96ab-9096-47f3-96c9-f1fd7dfc4352","order_type":"limit","size":"0.00113310","price":"8825.34000000","side":"buy","client_oid":"52668c24-98c5-49bc-b287-ea9cf82cf027","product_id":"BTC-EUR","sequence":3257977997,"time":"2018-01-22T15:14:39.080000Z"}
{"type":"open","side":"buy","price":"8825.34000000","order_id":"d12d96ab-9096-47f3-96c9-f1fd7dfc4352","remaining_size":"0.00113310","product_id":"BTC-EUR","sequence":3257977998,"time":"2018-01-22T15:14:39.080000Z"}
{"type":"done","side":"sell","order_id":"6ffdf50c-90cc-49ec-82a4-05c680fa5141","reason":"canceled","product_id":"BTC-EUR","price":"8828.59000000","remaining_size":"0.01800000","sequence":3257977999,"time":"2018-01-22T15:14:39.083000Z"}
{"type":"done","side":"buy","order_id":"56300110-f178-4248-9f57-293d2272903a","reason":"canceled","product_id":"BTC-EUR","price":"8655.40000000","remaining_size":"1.89594000","sequence":3257978000,"time":"2018-01-22T15:14:39.088000Z"}
{"type":"received","order_id":"f503da37-a2aa-4802-b774-8ecfdc8c71fd","order_type":"limit","size":"0.06847422","price":"8828.58000000","side":"sell","client_oid":"38958551-cd9f-41f2-84bd-1ac38dbaec5c","product_id":"BTC-EUR","sequence":3257978001,"time":"2018-01-22T15:14:39.094000Z"}
{"type":"open","side":"sell","price":"8828.58000000","order_id":"f503da37-a2aa-4802-b774-8ecfdc8c71fd","remaining_size":"0.06847422","product_id":"BTC-EUR","sequence":3257978002,"time":"2018-01-22T15:14:39.094000Z"}
{"type":"received","order_id":"433424d8-8b8e-42bd-a118-e3a77ea3646c","order_type":"limit","size":"0.06847422","price":"8828.59000000","side":"sell","client_oid":"8fb2cee0-8496-49be-ad9b-db481da0f4ad","product_id":"BTC-EUR","sequence":3257978003,"time":"2018-01-22T15:14:39.102000Z"}
{"type":"open","side":"sell","price":"8828.59000000","order_id":"433424d8-8b8e-42bd-a118-e3a77ea3646c","remaining_size":"0.06847422","product_id":"BTC-EUR","sequence":3257978004,"time":"2018-01-22T15:14:39.102000Z"}
{"type":"received","order_id":"6b0bb667-7bad-4c88-93cb-bf2e6477d7c1","order_type":"limit","size":"0.01800000","price":"8828.57000000","side":"sell","client_oid":"aae2172c-8de1-40eb-878c-dcce9e3b0d62","product_id":"BTC-EUR","sequence":3257978005,"time":"2018-01-22T15:14:39.109000Z"}
{"type":"open","side":"sell","price":"8828.57000000","order_id":"6b0bb667-7bad-4c88-93cb-bf2e6477d7c1","remaining_size":"0.01800000","product_id":"BTC-EUR","sequence":3257978006,"time":"2018-01-22T15:14:39.109000Z"}
{"type":"received","order_id":"9073a33c-0fe1-4ac9-b55f-941859c4275e","order_type":"limit","size":"0.10500000","price":"8828.58000000","side":"sell","client_oid":"25ba2d17-b726-4037-9554-9a9db944ef8b","product_id":"BTC-EUR","sequence":3257978007,"time":"2018-01-22T15:14:39.129000Z"}
{"type":"open","side":"sell","price":"8828.58000000","order_id":"9073a33c-0fe1-4ac9-b55f-941859c4275e","remaining_size":"0.10500000","product_id":"BTC-EUR","sequence":3257978008,"time":"2018-01-22T15:14:39.129000Z"}
{"type":"received","order_id":"4454af16-3b3b-4234-8e13-a9888581b0d4","order_type":"limit","size":"1.89779000","price":"8646.40000000","side":"buy","client_oid":"940c5406-e3e3-466c-be8d-6d20f8c141ec","product_id":"BTC-EUR","sequence":3257978009,"time":"2018-01-22T15:14:39.130000Z"}
{"type":"open","side":"buy","price":"8646.40000000","order_id":"4454af16-3b3b-4234-8e13-a9888581b0d4","remaining_size":"1.89779000","product_id":"BTC-EUR","sequence":3257978010,"time":"2018-01-22T15:14:39.130000Z"}
{"type":"done","side":"sell","order_id":"2df3f89f-3ea1-4353-97cb-d1d42cd16721","reason":"canceled","product_id":"BTC-EUR","price":"8828.59000000","remaining_size":"0.06847422","sequence":3257978011,"time":"2018-01-22T15:14:39.134000Z"}
{"type":"received","order_id":"d764cace-69bb-471f-9976-848ac23499f1","order_type":"limit","size":"0.00113228","price":"8828.57000000","side":"sell","client_oid":"38faeb16-e060-404b-999e-a3bcc6bedb26","product_id":"BTC-EUR","sequence":3257978012,"time":"2018-01-22T15:14:39.141000Z"}
{"type":"open","side":"sell","price":"8828.57000000","order_id":"d764cace-69bb-471f-9976-848ac23499f1","remaining_size":"0.00113228","product_id":"BTC-EUR","sequence":3257978013,"time":"2018-01-22T15:14:39.141000Z"}
{"type":"received","order_id":"f3ebee00-d298-4c33-9fcf-ea876c4869ea","order_type":"limit","size":"0.06847422","price":"8828.57000000","side":"sell","client_oid":"9e5d7b53-48cd-42df-abf8-d234768ea3de","product_id":"BTC-EUR","sequence":3257978014,"time":"2018-01-22T15:14:39.148000Z"}
{"type":"open","side":"sell","price":"8828.57000000","order_id":"f3ebee00-d298-4c33-9fcf-ea876c4869ea","remaining_size":"0.06847422","product_id":"BTC-EUR","sequence":3257978015,"time":"2018-01-22T15:14:39.148000Z"}
{"type":"done","side":"sell","order_id":"dd0f96c1-e660-423a-83d1-af9db9097bb7","reason":"canceled","product_id":"BTC-EUR","price":"8831.25000000","remaining_size":"0.22947933","sequence":3257978016,"time":"2018-01-22T15:14:39.151000Z"}
{"type":"done","side":"sell","order_id":"d764cace-69bb-471f-9976-848ac23499f1","reason":"canceled","product_id":"BTC-EUR","price":"8828.57000000","remaining_size":"0.00113228","sequence":3257978017,"time":"2018-01-22T15:14:39.163000Z"}
{"type":"done","side":"sell","order_id":"b033873e-6ffb-4f50-8673-b9e07365140e","reason":"canceled","product_id":"BTC-EUR","price":"8828.58000000","remaining_size":"0.03000000","sequence":3257978018,"time":"2018-01-22T15:14:39.175000Z"}
{"type":"done","side":"sell","order_id":"4a04815c-5192-49fb-9561-12f2d49cce57","reason":"canceled","product_id":"BTC-EUR","price":"8831.25000000","remaining_size":"0.01322632","sequence":3257978019,"time":"2018-01-22T15:14:39.185000Z"}
{"type":"received","order_id":"6e7a5e6e-fbba-4c69-842d-4954fc23208e","order_type":"limit","size":"0.00113228","price":"8828.56000000","side":"sell","client_oid":"0adbd4ee-4b26-4832-bf84-b21ed36ef640","product_id":"BTC-EUR","sequence":3257978020,"time":"2018-01-22T15:14:39.199000Z"}
{"type":"open","side":"sell","price":"8828.56000000","order_id":"6e7a5e6e-fbba-4c69-842d-4954fc23208e","remaining_size":"0.00113228","product_id":"BTC-EUR","sequence":3257978021,"time":"2018-01-22T15:14:39.199000Z"}
{"type":"done","side":"sell","order_id":"9073a33c-0fe1-4ac9-b55f-941859c4275e","reason":"canceled","product_id":"BTC-EUR","price":"8828.58000000","remaining_size":"0.10500000","sequence":3257978022,"time":"2018-01-22T15:14:39.210000Z"}
{"type":"received","order_id":"fd9fcc2e-2b12-4552-8615-6701d22b25f8","order_type":"limit","size":"0.03000000","price":"8828.56000000","side":"sell","client_oid":"3df45ddf-72d7-4447-94c9-fb13d0058a1a","product_id":"BTC-EUR","sequence":3257978023,"time":"2018-01-22T15:14:39.221000Z"}
{"type":"open","side":"sell","price":"8828.56000000","order_id":"fd9fcc2e-2b12-4552-8615-6701d22b25f8","remaining_size":"0.03000000","product_id":"BTC-EUR","sequence":3257978024,"time":"2018-01-22T15:14:39.221000Z"}
{"type":"received","order_id":"f5ab9e2c-7b4e-4a10-b9df-173733d007ad","order_type":"limit","size":"0.09800000","price":"8828.57000000","side":"sell","client_oid":"5eeee059-282b-4e3c-a854-eca514a5a84d","product_id":"BTC-EUR","sequence":3257978025,"time":"2018-01-22T15:14:39.222000Z"}
{"type":"open","side":"sell","price":"8828.57000000","order_id":"f5ab9e2c-7b4e-4a10-b9df-173733d007ad","remaining_size":"0.09800000","product_id":"BTC-EUR","sequence":3257978026,"time":"2018-01-22T15:14:39.222000Z"}
{"type":"received","order_id":"0410dc57-ac72-4b41-8502-7aa7032c9146","order_type":"limit","size":"19.18330619","price":"7285.19000000","side":"buy","product_id":"BTC-EUR","sequence":3257978027,"time":"2018-01-22T15:14:39.252000Z"}
{"type":"open","side":"buy","price":"7285.19000000","order_id":"0410dc57-ac72-4b41-8502-7aa7032c9146","remaining_size":"19.18330619","product_id":"BTC-EUR","sequence":3257978028,"time":"2018-01-22T15:14:39.252000Z"}
{"type":"done","side":"sell","order_id":"f503da37-a2aa-4802-b774-8ecfdc8c71fd","reason":"canceled","product_id":"BTC-EUR","price":"8828.58000000","remaining_size":"0.06847422","sequence":3257978029,"time":"2018-01-22T15:14:39.253000Z"}
{"type":"received","order_id":"3c365fcd-7c0c-4b8c-83b9-2050b59bee89","order_type":"limit","size":"0.21404538","price":"8828.57000000","side":"sell","product_id":"BTC-EUR","sequence":3257978030,"time":"2018-01-22T15:14:39.264000Z"}
{"type":"open","side":"sell","price":"8828.57000000","order_id":"3c365fcd-7c0c-4b8c-83b9-2050b59bee89","remaining_size":"0.21404538","product_id":"BTC-EUR","sequence":3257978031,"time":"2018-01-22T15:14:39.264000Z"}
{"type":"done","side":"sell","order_id":"433424d8-8b8e-42bd-a118-e3a77ea3646c","reason":"canceled","product_id":"BTC-EUR","price":"8828.59000000","remaining_size":"0.06847422","sequence":3257978032,"time":"2018-01-22T15:14:39.293000Z"}
{"type":"done","side":"sell","order_id":"6b0bb667-7bad-4c88-93cb-bf2e6477d7c1","reason":"canceled","product_id":"BTC-EUR","price":"8828.57000000","remaining_size":"0.01800000","sequence":3257978033,"time":"2018-01-22T15:14:39.293000Z"}
{"type":"received","order_id":"f9f02658-5df6-4c67-b756-68ecf3d71461","order_type":"limit","size":"0.01800000","price":"8828.55000000","side":"sell","client_oid":"cd9643ae-ca24-469a-999b-db98bc1d5718","product_id":"BTC-EUR","sequence":3257978034,"time":"2018-01-22T15:14:39.299000Z"}
{"type":"open","side":"sell","price":"8828.55000000","order_id":"f9f02658-5df6-4c67-b756-68ecf3d71461","remaining_size":"0.01800000","product_id":"BTC-EUR","sequence":3257978035,"time":"2018-01-22T15:14:39.299000Z"}
{"type":"received","order_id":"7a792f16-88d3-4b26-95e9-d0a05b778e00","order_type":"limit","size":"0.06847422","price":"8828.57000000","side":"sell","client_oid":"cc0621df-5c3d-4b38-b1be-c8711cf2740b","product_id":"BTC-EUR","sequence":3257978036,"time":"2018-01-22T15:14:39.307000Z"}
{"type":"open","side":"sell","price":"8828.57000000","order_id":"7a792f16-88d3-4b26-95e9-d0a05b778e00","remaining_size":"0.06847422","product_id":"BTC-EUR","sequence":3257978037,"time":"2018-01-22T15:14:39.307000Z"}
{"type":"received","order_id":"34068c85-2a53-4a85-bcee-39780d2c84d2","order_type":"limit","size":"0.01800000","price":"8828.55000000","side":"sell","client_oid":"3993f847-686a-410c-9b5c-d9b353fb65f9","product_id":"BTC-EUR","sequence":3257978038,"time":"2018-01-22T15:14:39.318000Z"}
{"type":"open","side":"sell","price":"8828.55000000","order_id":"34068c85-2a53-4a85-bcee-39780d2c84d2","remaining_size":"0.01800000","product_id":"BTC-EUR","sequence":3257978039,"time":"2018-01-22T15:14:39.318000Z"}
{"type":"done","side":"sell","order_id":"e28b2282-0be9-4f08-8a4b-36c6dfc46676","reason":"canceled","product_id":"BTC-EUR","price":"8948.31000000","remaining_size":"0.75000000","sequence":3257978040,"time":"2018-01-22T15:14:39.327000Z"}
{"type":"done","side":"sell","order_id":"fd9fcc2e-2b12-4552-8615-6701d22b25f8","reason":"canceled","product_id":"BTC-EUR","price":"8828.56000000","remaining_size":"0.03000000","sequence":3257978041,"time":"2018-01-22T15:14:39.341000Z"}
{"type":"done","side":"sell","order_id":"f5ab9e2c-7b4e-4a10-b9df-173733d007ad","reason":"canceled","product_id":"BTC-EUR","price":"8828.57000000","remaining_size":"0.09800000","sequence":3257978042,"time":"2018-01-22T15:14:39.342000Z"}
{"type":"done","side":"sell","order_id":"6e7a5e6e-fbba-4c69-842d-4954fc23208e","reason":"canceled","product_id":"BTC-EUR","price":"8828.56000000","remaining_size":"0.00113228","sequence":3257978043,"time":"2018-01-22T15:14:39.350000Z"}
{"type":"done","side":"buy","order_id":"4696a844-5d13-4ddf-858f-3c944ae59806","reason":"canceled","product_id":"BTC-EUR","price":"8815.11000000","remaining_size":"0.49000000","sequence":3257978044,"time":"2018-01-22T15:14:39.358000Z"}
{"type":"done","side":"sell","order_id":"b14181c0-cb10-4a6d-a15f-0b9fd46dc48a","reason":"canceled","product_id":"BTC-EUR","price":"8855.11000000","remaining_size":"0.25000000","sequence":3257978045,"time":"2018-01-22T15:14:39.358000Z"}
{"type":"done","side":"sell","order_id":"f3ebee00-d298-4c33-9fcf-ea876c4869ea","reason":"canceled","product_id":"BTC-EUR","price":"8828.57000000","remaining_size":"0.06847422","sequence":3257978046,"time":"2018-01-22T15:14:39.376000Z"}
{"type":"done","side":"sell","order_id":"d9cfc5fe-f8fd-41ff-b19f-a8ffdb2b1ec2","reason":"canceled","product_id":"BTC-EUR","price":"8831.50000000","remaining_size":"0.02753599","sequence":3257978047,"time":"2018-01-22T15:14:39.377000Z"}
{"type":"received","order_id":"e1eb1311-6008-4f0e-a076-6201ce374210","order_type":"limit","size":"0.09800000","price":"8828.55000000","side":"sell","client_oid":"533223fb-7af4-49f8-8530-b4f753164953","product_id":"BTC-EUR","sequence":3257978048,"time":"2018-01-22T15:14:39.378000Z"}
{"type":"open","side":"sell","price":"8828.55000000","order_id":"e1eb1311-6008-4f0e-a076-6201ce374210","remaining_size":"0.09800000","product_id":"BTC-EUR","sequence":3257978049,"time":"2018-01-22T15:14:39.378000Z"}
{"type":"received","order_id":"92b49294-3bed-483a-bfa9-be9118457664","order_type":"limit","size":"0.03000000","price":"8828.54000000","side":"sell","client_oid":"9970e12d-8330-4d2f-855c-4ce2a193bf74","product_id":"BTC-EUR","sequence":3257978050,"time":"2018-01-22T15:14:39.387000Z"}
{"type":"open","side":"sell","price":"8828.54000000","order_id":"92b49294-3bed-483a-bfa9-be9118457664","remaining_size":"0.03000000","product_id":"BTC-EUR","sequence":3257978051,"time":"2018-01-22T15:14:39.387000Z"}
{"type":"done","side":"sell","order_id":"3c365fcd-7c0c-4b8c-83b9-2050b59bee89","reason":"canceled","product_id":"BTC-EUR","price":"8828.57000000","remaining_size":"0.21404538","sequence":3257978052,"time":"2018-01-22T15:14:39.392000Z"}
{"type":"done","side":"sell","order_id":"b9b93c43-95d5-4f98-bf6f-fb91dc428494","reason":"canceled","product_id":"BTC-EUR","price":"9041.51000000","remaining_size":"0.75000000","sequence":3257978053,"time":"2018-01-22T15:14:39.392000Z"}
{"type":"done","side":"buy","order_id":"c87fa082-dd01-4786-9317-85a6d391e964","reason":"canceled","product_id":"BTC-EUR","price":"8721.91000000","remaining_size":"0.75000000","sequence":3257978054,"time":"2018-01-22T15:14:39.392000Z"}
{"type":"done","side":"sell","order_id":"000ed8bf-7389-4fd1-a929-e3da78546ff9","reason":"canceled","product_id":"BTC-EUR","price":"9134.71000000","remaining_size":"0.75000000","sequence":3257978055,"time":"2018-01-22T15:14:39.395000Z"}
{"type":"done","side":"buy","order_id":"f2855de0-a292-4f93-9e5b-cda58fdc0d28","reason":"canceled","product_id":"BTC-EUR","price":"8628.71000000","remaining_size":"0.75000000","sequence":3257978056,"time":"2018-01-22T15:14:39.395000Z"}
{"type":"done","side":"sell","order_id":"a85d5a6b-48f1-4aeb-8624-60c10918519f","reason":"canceled","product_id":"BTC-EUR","price":"9227.91000000","remaining_size":"0.74000000","sequence":3257978057,"time":"2018-01-22T15:14:39.397000Z"}
{"type":"done","side":"buy","order_id":"d64b33f8-abc6-4431-b32b-2d1c38738748","reason":"canceled","product_id":"BTC-EUR","price":"8535.51000000","remaining_size":"0.74000000","sequence":3257978058,"time":"2018-01-22T15:14:39.398000Z"}
{"type":"done","side":"sell","order_id":"f926c19b-e597-43cd-9317-8c52ce89c9ae","reason":"canceled","product_id":"BTC-EUR","price":"9321.11000000","remaining_size":"0.75000000","sequence":3257978059,"time":"2018-01-22T15:14:39.402000Z"}
{"type":"done","side":"buy","order_id":"d421416a-29f0-4aa8-a87d-8e007629245e","reason":"canceled","product_id":"BTC-EUR","price":"8442.31000000","remaining_size":"0.75000000","sequence":3257978060,"time":"2018-01-22T15:14:39.403000Z"}
{"type":"done","side":"sell","order_id":"9b115cd4-9848-48f4-b0b0-d4e1d7dd9968","reason":"canceled","product_id":"BTC-EUR","price":"9414.31000000","remaining_size":"0.75000000","sequence":3257978061,"time":"2018-01-22T15:14:39.406000Z"}
{"type":"done","side":"buy","order_id":"e64dd9e1-ea82-4e15-989d-4020a75bad35","reason":"canceled","product_id":"BTC-EUR","price":"8349.11000000","remaining_size":"0.75000000","sequence":3257978062,"time":"2018-01-22T15:14:39.407000Z"}
{"type":"done","side":"sell","order_id":"d7551aa1-0359-453a-8076-59d752c9d56a","reason":"canceled","product_id":"BTC-EUR","price":"9507.51000000","remaining_size":"0.75000000","sequence":3257978063,"time":"2018-01-22T15:14:39.409000Z"}
{"type":"done","side":"buy","order_id":"fb26097a-3311-4f47-963e-f3d457ea571b","reason":"canceled","product_id":"BTC-EUR","price":"8255.91000000","remaining_size":"0.75000000","sequence":3257978064,"time":"2018-01-22T15:14:39.409000Z"}
{"type":"done","side":"sell","order_id":"e6826f5d-e38f-462e-a38d-64ea715cbdd1","reason":"canceled","product_id":"BTC-EUR","price":"9600.71000000","remaining_size":"0.74000000","sequence":3257978065,"time":"2018-01-22T15:14:39.409000Z"}
{"type":"done","side":"buy","order_id":"7e6cd0a5-c2cb-44aa-a682-5f410d6b9c9a","reason":"canceled","product_id":"BTC-EUR","price":"8162.71000000","remaining_size":"0.74000000","sequence":3257978066,"time":"2018-01-22T15:14:39.409000Z"}
{"type":"done","side":"sell","order_id":"842516ff-a87d-40f7-bef5-30a8020d4d34","reason":"canceled","product_id":"BTC-EUR","price":"9693.91000000","remaining_size":"0.75000000","sequence":3257978067,"time":"2018-01-22T15:14:39.411000Z"}
{"type":"done","side":"buy","order_id":"11b06ec8-5d13-46da-a840-23f908212c63","reason":"canceled","product_id":"BTC-EUR","price":"8069.51000000","remaining_size":"0.75000000","sequence":3257978068,"time":"2018-01-22T15:14:39.411000Z"}
{"type":"done","side":"sell","order_id":"942b45cd-3665-4511-80d6-a7e218313c95","reason":"canceled","product_id":"BTC-EUR","price":"9787.11000000","remaining_size":"0.75000000","sequence":3257978069,"time":"2018-01-22T15:14:39.412000Z"}
{"type":"done","side":"buy","order_id":"0ce16003-a9e5-40a3-a6f1-358dcac85637","reason":"canceled","product_id":"BTC-EUR","price":"7976.31000000","remaining_size":"0.75000000","sequence":3257978070,"time":"2018-01-22T15:14:39.412000Z"}
{"type":"received","order_id":"1828604e-d4d1-4fcd-a197-c568cd350926","order_type":"limit","size":"0.22947933","price":"8828.55000000","side":"sell","client_oid":"2fd13259-7348-48a5-8507-0678cea92294","product_id":"BTC-EUR","sequence":3257978071,"time":"2018-01-22T15:14:39.414000Z"}
{"type":"open","side":"sell","price":"8828.55000000","order_id":"1828604e-d4d1-4fcd-a197-c568cd350926","remaining_size":"0.22947933","product_id":"BTC-EUR","sequence":3257978072,"time":"2018-01-22T15:14:39.414000Z"}
{"type":"received","order_id":"cf307850-5ff7-4a54-baa7-04f2928b00a8","order_type":"limit","size":"0.06847422","price":"8828.55000000","side":"sell","client_oid":"8ffb41d4-6ae0-448c-b6b7-fc092f7a8d1e","product_id":"BTC-EUR","sequence":3257978073,"time":"2018-01-22T15:14:39.420000Z"}
{"type":"open","side":"sell","price":"8828.55000000","order_id":"cf307850-5ff7-4a54-baa7-04f2928b00a8","remaining_size":"0.06847422","product_id":"BTC-EUR","sequence":3257978074,"time":"2018-01-22T15:14:39.420000Z"}
{"type":"received","order_id":"4316fc1c-d3c8-489a-b375-d09c700ea5ca","order_type":"limit","size":"0.00113228","price":"8828.54000000","side":"sell","client_oid":"2eb5d35e-126a-4405-9d5a-70bb8c758df0","product_id":"BTC-EUR","sequence":3257978075,"time":"2018-01-22T15:14:39.449000Z"}
{"type":"open","side":"sell","price":"8828.54000000","order_id":"4316fc1c-d3c8-489a-b375-d09c700ea5ca","remaining_size":"0.00113228","product_id":"BTC-EUR","sequence":3257978076,"time":"2018-01-22T15:14:39.449000Z"}
{"type":"done","side":"sell","order_id":"915b263b-fcb6-4750-a5d9-0ac00cb19f0c","reason":"canceled","product_id":"BTC-EUR","price":"8828.62000000","remaining_size":"0.10500000","sequence":3257978077,"time":"2018-01-22T15:14:39.458000Z"}
{"type":"received","order_id":"b2ee9ba9-10d6-4249-b8f1-0df70c29229c","order_type":"limit","size":"0.75000000","price":"8947.50000000","side":"sell","client_oid":"276dd4ed-8a2a-4854-aee0-6cd7bfd176b3","product_id":"BTC-EUR","sequence":3257978078,"time":"2018-01-22T15:14:39.458000Z"}
{"type":"open","side":"sell","price":"8947.50000000","order_id":"b2ee9ba9-10d6-4249-b8f1-0df70c29229c","remaining_size":"0.75000000","product_id":"BTC-EUR","sequence":3257978079,"time":"2018-01-22T15:14:39.458000Z"}
{"type":"done","side":"sell","order_id":"e1eb1311-6008-4f0e-a076-6201ce374210","reason":"canceled","product_id":"BTC-EUR","price":"8828.55000000","remaining_size":"0.09800000","sequence":3257978080,"time":"2018-01-22T15:14:39.466000Z"}
{"type":"received","order_id":"a49afa9d-c2b1-4b68-b5d0-dcbb3786ee4b","order_type":"limit","size":"0.25000000","price":"8854.30000000","side":"sell","client_oid":"4605f014-def3-4ef2-ace3-74eaff957d43","product_id":"BTC-EUR","sequence":3257978081,"time":"2018-01-22T15:14:39.480000Z"}
{"type":"open","side":"sell","price":"8854.30000000","order_id":"a49afa9d-c2b1-4b68-b5d0-dcbb3786ee4b","remaining_size":"0.25000000","product_id":"BTC-EUR","sequence":3257978082,"time":"2018-01-22T15:14:39.480000Z"}
{"type":"received","order_id":"ee39445d-c831-4367-8183-629666b575d5","order_type":"limit","size":"0.75000000","price":"8721.10000000","side":"buy","client_oid":"b57d7951-48fc-404e-90d1-a09c3eb0288c","product_id":"BTC-EUR","sequence":3257978083,"time":"2018-01-22T15:14:39.480000Z"}
{"type":"open","side":"buy","price":"8721.10000000","order_id":"ee39445d-c831-4367-8183-629666b575d5","remaining_size":"0.75000000","product_id":"BTC-EUR","sequence":3257978084,"time":"2018-01-22T15:14:39.480000Z"}
{"type":"received","order_id":"5ff2c13d-2115-4f69-8cc9-687b054cf4eb","order_type":"limit","size":"0.49000000","price":"8814.30000000","side":"buy","client_oid":"85cc68f7-0243-440b-9690-dee43a6a272f","product_id":"BTC-EUR","sequence":3257978085,"time":"2018-01-22T15:14:39.485000Z"}
{"type":"open","side":"buy","price":"8814.30000000","order_id":"5ff2c13d-2115-4f69-8cc9-687b054cf4eb","remaining_size":"0.49000000","product_id":"BTC-EUR","sequence":3257978086,"time":"2018-01-22T15:14:39.485000Z"}
{"type":"received","order_id":"8d4c23ea-67b7-4f2a-96a8-a811ae09ef07","order_type":"limit","size":"0.75000000","price":"9040.70000000","side":"sell","client_oid":"3e0feba6-66a7-496d-b384-8ebeded76cd9","product_id":"BTC-EUR","sequence":3257978087,"time":"2018-01-22T15:14:39.485000Z"}
{"type":"open","side":"sell","price":"9040.70000000","order_id":"8d4c23ea-67b7-4f2a-96a8-a811ae09ef07","remaining_size":"0.75000000","product_id":"BTC-EUR","sequence":3257978088,"time":"2018-01-22T15:14:39.485000Z"}
{"type":"received","order_id":"c5922dd1-e2b6-407a-884b-b23dc597e1a7","order_type":"limit","size":"0.75000000","price":"8627.90000000","side":"buy","client_oid":"4a225146-60f9-43b7-a87b-8771a4434b42","product_id":"BTC-EUR","sequence":3257978089,"time":"2018-01-22T15:14:39.490000Z"}
{"type":"open","side":"buy","price":"8627.90000000","order_id":"c5922dd1-e2b6-407a-884b-b23dc597e1a7","remaining_size":"0.75000000","product_id":"BTC-EUR","sequence":3257978090,"time":"2018-01-22T15:14:39.490000Z"}
{"type":"done","side":"sell","order_id":"7a792f16-88d3-4b26-95e9-d0a05b778e00","reason":"canceled","product_id":"BTC-EUR","price":"8828.57000000","remaining_size":"0.06847422","sequence":3257978091,"time":"2018-01-22T15:14:39.495000Z"}
{"type":"received","order_id":"f174d45c-ef7d-4cfb-869b-a9d1469e9142","order_type":"limit","size":"0.75000000","price":"9413.50000000","side":"sell","client_oid":"b24946a1-8884-4e1b-b8dc-16e55fd1b964","product_id":"BTC-EUR","sequence":3257978092,"time":"2018-01-22T15:14:39.499000Z"}
{"type":"open","side":"sell","price":"9413.50000000","order_id":"f174d45c-ef7d-4cfb-869b-a9d1469e9142","remaining_size":"0.75000000","product_id":"BTC-EUR","sequence":3257978093,"time":"2018-01-22T15:14:39.499000Z"}
{"type":"received","order_id":"d9c6feb5-c972-450d-8a8f-556cef626691","order_type":"limit","size":"0.01322632","price":"8828.55000000","side":"sell","client_oid":"850d01c5-0a5f-4e10-8375-e287370ff7bd","product_id":"BTC-EUR","sequence":3257978094,"time":"2018-01-22T15:14:39.503000Z"}
{"type":"open","side":"sell","price":"8828.55000000","order_id":"d9c6feb5-c972-450d-8a8f-556cef626691","remaining_size":"0.01322632","product_id":"BTC-EUR","sequence":3257978095,"time":"2018-01-22T15:14:39.503000Z"}
{"type":"received","order_id":"19c61b58-9ce1-4e1e-9e58-bd4c4545f8da","order_type":"limit","size":"0.06847422","price":"8828.54000000","side":"sell","client_oid":"4901e689-8367-4838-8a6f-56fe1722d549","product_id":"BTC-EUR","sequence":3257978096,"time":"2018-01-22T15:14:39.504000Z"}
{"type":"open","side":"sell","price":"8828.54000000","order_id":"19c61b58-9ce1-4e1e-9e58-bd4c4545f8da","remaining_size":"0.06847422","product_id":"BTC-EUR","sequence":3257978097,"time":"2018-01-22T15:14:39.504000Z"}
{"type":"received","order_id":"9e443a81-a8c0-4d8f-87b0-7725b8b78dd8","order_type":"limit","size":"0.02753586","price":"8831.23000000","side":"sell","product_id":"BTC-EUR","sequence":3257978098,"time":"2018-01-22T15:14:39.506000Z"}
{"type":"open","side":"sell","price":"8831.23000000","order_id":"9e443a81-a8c0-4d8f-87b0-7725b8b78dd8","remaining_size":"0.02753586","product_id":"BTC-EUR","sequence":3257978099,"time":"2018-01-22T15:14:39.506000Z"}
{"type":"done","side":"sell","order_id":"f9f02658-5df6-4c67-b756-68ecf3d71461","reason":"canceled","product_id":"BTC-EUR","price":"8828.55000000","remaining_size":"0.01800000","sequence":3257978100,"time":"2018-01-22T15:14:39.508000Z"}
{"type":"done","side":"sell","order_id":"34068c85-2a53-4a85-bcee-39780d2c84d2","reason":"canceled","product_id":"BTC-EUR","price":"8828.55000000","remaining_size":"0.01800000","sequence":3257978101,"time":"2018-01-22T15:14:39.508000Z"}
{"type":"received","order_id":"e03dddc9-fb38-4e2f-9304-e85e78cfe457","order_type":"limit","size":"0.75000000","price":"8348.30000000","side":"buy","client_oid":"8963584a-152f-4fae-9922-b7c9ae0a6988","product_id":"BTC-EUR","sequence":3257978102,"time":"2018-01-22T15:14:39.508000Z"}
{"type":"open","side":"buy","price":"8348.30000000","order_id":"e03dddc9-fb38-4e2f-9304-e85e78cfe457","remaining_size":"0.75000000","product_id":"BTC-EUR","sequence":3257978103,"time":"2018-01-22T15:14:39.508000Z"}
{"type":"received","order_id":"7f84334d-7820-4895-9813-e66cf93a139a","order_type":"limit","size":"0.74000000","price":"8534.70000000","side":"buy","client_oid":"b9023e67-57b8-48df-b1a4-589bfe83f7e8","product_id":"BTC-EUR","sequence":3257978104,"time":"2018-01-22T15:14:39.518000Z"}
{"type":"open","side":"buy","price":"8534.70000000","order_id":"7f84334d-7820-4895-9813-e66cf93a139a","remaining_size":"0.74000000","product_id":"BTC-EUR","sequence":3257978105,"time":"2018-01-22T15:14:39.518000Z"}
{"type":"received","order_id":"06908e97-55a5-48cb-a685-3dc1a1760975","order_type":"limit","size":"0.09800000","price":"8828.53000000","side":"sell","client_oid":"12ad93f9-17dc-4e86-87eb-095b8e77bfea","product_id":"BTC-EUR","sequence":3257978106,"time":"2018-01-22T15:14:39.520000Z"}
{"type":"open","side":"sell","price":"8828.53000000","order_id":"06908e97-55a5-48cb-a685-3dc1a1760975","remaining_size":"0.09800000","product_id":"BTC-EUR","sequence":3257978107,"time":"2018-01-22T15:14:39.520000Z"}
{"type":"done","side":"sell","order_id":"b2ee9ba9-10d6-4249-b8f1-0df70c29229c","reason":"canceled","product_id":"BTC-EUR","price":"8947.50000000","remaining_size":"0.75000000","sequence":3257978108,"time":"2018-01-22T15:14:39.522000Z"}
{"type":"received","order_id":"d927faa3-d068-4bf7-aba6-66ab0e9c574a","order_type":"limit","size":"0.75000000","price":"9506.70000000","side":"sell","client_oid":"4e6fd271-7e80-408b-9beb-a5aa115c818a","product_id":"BTC-EUR","sequence":3257978109,"time":"2018-01-22T15:14:39.525000Z"}
{"type":"open","side":"sell","price":"9506.70000000","order_id":"d927faa3-d068-4bf7-aba6-66ab0e9c574a","remaining_size":"0.75000000","product_id":"BTC-EUR","sequence":3257978110,"time":"2018-01-22T15:14:39.525000Z"}
{"type":"done","side":"sell","order_id":"4316fc1c-d3c8-489a-b375-d09c700ea5ca","reason":"canceled","product_id":"BTC-EUR","price":"8828.54000000","remaining_size":"0.00113228","sequence":3257978111,"time":"2018-01-22T15:14:39.525000Z"}
{"type":"done","side":"buy","order_id":"5ff2c13d-2115-4f69-8cc9-687b054cf4eb","reason":"canceled","product_id":"BTC-EUR","price":"8814.30000000","remaining_size":"0.49000000","sequence":3257978112,"time":"2018-01-22T15:14:39.526000Z"}
{"type":"done","side":"sell","order_id":"a49afa9d-c2b1-4b68-b5d0-dcbb3786ee4b","reason":"canceled","product_id":"BTC-EUR","price":"8854.30000000","remaining_size":"0.25000000","sequence":3257978113,"time":"2018-01-22T15:14:39.526000Z"}
{"type":"done","side":"sell","order_id":"92b49294-3bed-483a-bfa9-be9118457664","reason":"canceled","product_id":"BTC-EUR","price":"8828.54000000","remaining_size":"0.03000000","sequence":3257978114,"time":"2018-01-22T15:14:39.527000Z"}
{"type":"received","order_id":"d33dfaa7-0198-4ca9-8404-f32d6cd10aab","order_type":"limit","size":"0.75000000","price":"8441.50000000","side":"buy","client_oid":"2d97b91e-2cb1-44a3-abe4-56bd5b0deee6","product_id":"BTC-EUR","sequence":3257978115,"time":"2018-01-22T15:14:39.532000Z"}
{"type":"open","side":"buy","price":"8441.50000000","order_id":"d33dfaa7-0198-4ca9-8404-f32d6cd10aab","remaining_size":"0.75000000","product_id":"BTC-EUR","sequence":3257978116,"time":"2018-01-22T15:14:39.532000Z"}
{"type":"received","order_id":"6e56f949-22ec-4926-8de1-af6a4fcfc3ed","order_type":"limit","size":"0.74000000","price":"8161.90000000","side":"buy","client_oid":"1d63ee0a-69a7-4183-b2f8-abea492cdefb","product_id":"BTC-EUR","sequence":3257978117,"time":"2018-01-22T15:14:39.540000Z"}
{"type":"open","side":"buy","price":"8161.90000000","order_id":"6e56f949-22ec-4926-8de1-af6a4fcfc3ed","remaining_size":"0.74000000","product_id":"BTC-EUR","sequence":3257978118,"time":"2018-01-22T15:14:39.540000Z"}
{"type":"received","order_id":"058d35dc-ce3e-408b-932d-4ad99647a59c","order_type":"limit","size":"0.75000000","price":"9786.30000000","side":"sell","client_oid":"e46ec77b-a7d8-45a5-b371-fc76baa63898","product_id":"BTC-EUR","sequence":3257978119,"time":"2018-01-22T15:14:39.564000Z"}
{"type":"open","side":"sell","price":"9786.30000000","order_id":"058d35dc-ce3e-408b-932d-4ad99647a59c","remaining_size":"0.75000000","product_id":"BTC-EUR","sequence":3257978120,"time":"2018-01-22T15:14:39.564000Z"}
{"type":"received","order_id":"c33401eb-f070-4593-9d31-5c602382a062","order_type":"limit","size":"0.03000000","price":"8828.52000000","side":"sell","client_oid":"1a1e90c5-a45c-4dd1-bd5b-6fb905cef430","product_id":"BTC-EUR","sequence":3257978121,"time":"2018-01-22T15:14:39.567000Z"}
{"type":"open","side":"sell","price":"8828.52000000","order_id":"c33401eb-f070-4593-9d31-5c602382a062","remaining_size":"0.03000000","product_id":"BTC-EUR","sequence":3257978122,"time":"2018-01-22T15:14:39.567000Z"}
{"type":"done","side":"sell","order_id":"19cd9784-c2c8-462c-9a85-cdb869824da2","reason":"canceled","product_id":"BTC-EUR","price":"9114.10000000","remaining_size":"1.28000000","sequence":3257978123,"time":"2018-01-22T15:14:39.575000Z"}
{"type":"received","order_id":"a3b7de84-0243-45cf-996c-b46cee7ab959","order_type":"limit","size":"0.75000000","price":"7975.50000000","side":"buy","client_oid":"6cb7b555-85c3-4845-b0b1-d7514d70acc9","product_id":"BTC-EUR","sequence":3257978124,"time":"2018-01-22T15:14:39.583000Z"}
{"type":"open","side":"buy","price":"7975.50000000","order_id":"a3b7de84-0243-45cf-996c-b46cee7ab959","remaining_size":"0.75000000","product_id":"BTC-EUR","sequence":3257978125,"time":"2018-01-22T15:14:39.583000Z"}
{"type":"received","order_id":"d7621c62-1ef5-45cf-ae13-6c87cc743212","order_type":"limit","size":"0.75000000","price":"8255.10000000","side":"buy","client_oid":"8c794ee5-9050-4079-9938-481bd0b6ebb1","product_id":"BTC-EUR","sequence":3257978126,"time":"2018-01-22T15:14:39.587000Z"}
{"type":"open","side":"buy","price":"8255.10000000","order_id":"d7621c62-1ef5-45cf-ae13-6c87cc743212","remaining_size":"0.75000000","product_id":"BTC-EUR","sequence":3257978127,"time":"2018-01-22T15:14:39.587000Z"}
{"type":"received","order_id":"7032363c-59f7-4b9d-861e-a25a2b7cecee","order_type":"limit","size":"0.06847422","price":"8828.53000000","side":"sell","client_oid":"0792f81c-374e-4a4b-a101-056814d03734","product_id":"BTC-EUR","sequence":3257978128,"time":"2018-01-22T15:14:39.591000Z"}
{"type":"open","side":"sell","price":"8828.53000000","order_id":"7032363c-59f7-4b9d-861e-a25a2b7cecee","remaining_size":"0.06847422","product_id":"BTC-EUR","sequence":3257978129,"time":"2018-01-22T15:14:39.591000Z"}
{"type":"received","order_id":"7876b43a-89ff-48f3-97ed-6f5cfcba62e8","order_type":"limit","size":"0.74000000","price":"9599.90000000","side":"sell","client_oid":"33e91ab1-a372-4488-8eda-0705e2756b53","product_id":"BTC-EUR","sequence":3257978130,"time":"2018-01-22T15:14:39.594000Z"}
{"type":"open","side":"sell","price":"9599.90000000","order_id":"7876b43a-89ff-48f3-97ed-6f5cfcba62e8","remaining_size":"0.74000000","product_id":"BTC-EUR","sequence":3257978131,"time":"2018-01-22T15:14:39.594000Z"}
{"type":"received","order_id":"f4ee3645-babf-42ac-81ad-4f7f4499703d","order_type":"limit","size":"0.75000000","price":"9693.10000000","side":"sell","client_oid":"7014001d-3b3d-403f-ba1c-5a3845afb326","product_id":"BTC-EUR","sequence":3257978132,"time":"2018-01-22T15:14:39.608000Z"}
{"type":"open","side":"sell","price":"9693.10000000","order_id":"f4ee3645-babf-42ac-81ad-4f7f4499703d","remaining_size":"0.75000000","product_id":"BTC-EUR","sequence":3257978133,"time":"2018-01-22T15:14:39.608000Z"}
{"type":"received","order_id":"ce48bfb3-1227-40b6-9df8-6c0802625df8","order_type":"limit","size":"0.75000000","price":"8068.70000000","side":"buy","client_oid":"a7b80fe3-4bb1-4be1-bac2-987cc120e057","product_id":"BTC-EUR","sequence":3257978134,"time":"2018-01-22T15:14:39.613000Z"}
{"type":"open","side":"buy","price":"8068.70000000","order_id":"ce48bfb3-1227-40b6-9df8-6c0802625df8","remaining_size":"0.75000000","product_id":"BTC-EUR","sequence":3257978135,"time":"2018-01-22T15:14:39.613000Z"}
{"type":"received","order_id":"a9140b5f-d369-4f46-a2b5-bdfeb9bbd0cd","order_type":"limit","size":"0.10500000","price":"8828.54000000","side":"sell","client_oid":"d6a763c7-f5db-4c91-a3c7-c592e6c11843","product_id":"BTC-EUR","sequence":3257978136,"time":"2018-01-22T15:14:39.616000Z"}
{"type":"open","side":"sell","price":"8828.54000000","order_id":"a9140b5f-d369-4f46-a2b5-bdfeb9bbd0cd","remaining_size":"0.10500000","product_id":"BTC-EUR","sequence":3257978137,"time":"2018-01-22T15:14:39.616000Z"}
{"type":"received","order_id":"24a3ba69-3869-4448-ad10-7c3581cfe88e","order_type":"limit","size":"0.10500000","price":"8828.54000000","side":"sell","client_oid":"7b780d27-2baa-40df-858a-33e1816a5e92","product_id":"BTC-EUR","sequence":3257978138,"time":"2018-01-22T15:14:39.627000Z"}
{"type":"open","side":"sell","price":"8828.54000000","order_id":"24a3ba69-3869-4448-ad10-7c3581cfe88e","remaining_size":"0.10500000","product_id":"BTC-EUR","sequence":3257978139,"time":"2018-01-22T15:14:39.627000Z"}
{"type":"received","order_id":"d99b4e88-dd8e-44ff-8a82-22bdba8d0872","order_type":"limit","size":"0.75000000","price":"9134.30000000","side":"sell","client_oid":"453cd0c2-3ad3-4ff9-8743-ace450a71a8d","product_id":"BTC-EUR","sequence":3257978140,"time":"2018-01-22T15:14:39.630000Z"}
{"type":"open","side":"sell","price":"9134.30000000","order_id":"d99b4e88-dd8e-44ff-8a82-22bdba8d0872","remaining_size":"0.75000000","product_id":"BTC-EUR","sequence":3257978141,"time":"2018-01-22T15:14:39.630000Z"}
{"type":"received","order_id":"06508a27-8d18-4b3b-83fb-5ae73d2a79a0","order_type":"limit","size":"0.74000000","price":"9227.50000000","side":"sell","client_oid":"9ca0f27c-2e3d-4747-b6f1-93ba54b3890a","product_id":"BTC-EUR","sequence":3257978142,"time":"2018-01-22T15:14:39.642000Z"}
{"type":"open","side":"sell","price":"9227.50000000","order_id":"06508a27-8d18-4b3b-83fb-5ae73d2a79a0","remaining_size":"0.74000000","product_id":"BTC-EUR","sequence":3257978143,"time":"2018-01-22T15:14:39.642000Z"}
{"type":"done","side":"sell","order_id":"06908e97-55a5-48cb-a685-3dc1a1760975","reason":"canceled","product_id":"BTC-EUR","price":"8828.53000000","remaining_size":"0.09800000","sequence":3257978144,"time":"2018-01-22T15:14:39.657000Z"}
{"type":"received","order_id":"8e1fe7ee-57b2-4cf7-9203-256379ff48c4","order_type":"limit","size":"0.49000000","price":"8814.70000000","side":"buy","client_oid":"97bbcfa3-d6b3-4f5e-b304-63fa86270840","product_id":"BTC-EUR","sequence":3257978145,"time":"2018-01-22T15:14:39.660000Z"}
{"type":"open","side":"buy","price":"8814.70000000","order_id":"8e1fe7ee-57b2-4cf7-9203-256379ff48c4","remaining_size":"0.49000000","product_id":"BTC-EUR","sequence":3257978146,"time":"2018-01-22T15:14:39.660000Z"}
{"type":"received","order_id":"edb7fc66-2169-4b49-8765-1e0c0a928ce7","order_type":"limit","size":"0.09800000","price":"8828.51000000","side":"sell","client_oid":"b1a4e65e-d290-432d-8ada-02a0f55e0383","product_id":"BTC-EUR","sequence":3257978147,"time":"2018-01-22T15:14:39.679000Z"}
{"type":"open","side":"sell","price":"8828.51000000","order_id":"edb7fc66-2169-4b49-8765-1e0c0a928ce7","remaining_size":"0.09800000","product_id":"BTC-EUR","sequence":3257978148,"time":"2018-01-22T15:14:39.679000Z"}
{"type":"done","side":"sell","order_id":"c33401eb-f070-4593-9d31-5c602382a062","reason":"canceled","product_id":"BTC-EUR","price":"8828.52000000","remaining_size":"0.03000000","sequence":3257978149,"time":"2018-01-22T15:14:39.695000Z"}
{"type":"done","side":"sell","order_id":"a9140b5f-d369-4f46-a2b5-bdfeb9bbd0cd","reason":"canceled","product_id":"BTC-EUR","price":"8828.54000000","remaining_size":"0.10500000","sequence":3257978150,"time":"2018-01-22T15:14:39.699000Z"}
{"type":"done","side":"sell","order_id":"cf307850-5ff7-4a54-baa7-04f2928b00a8","reason":"canceled","product_id":"BTC-EUR","price":"8828.55000000","remaining_size":"0.06847422","sequence":3257978151,"time":"2018-01-22T15:14:39.708000Z"}
{"type":"received","order_id":"27de8b2e-bace-4752-b87e-39b4957f7523","order_type":"limit","size":"0.06847422","price":"8828.52000000","side":"sell","client_oid":"2a65bac3-9fb1-4e50-a9a7-1a019298af77","product_id":"BTC-EUR","sequence":3257978152,"time":"2018-01-22T15:14:39.725000Z"}
{"type":"open","side":"sell","price":"8828.52000000","order_id":"27de8b2e-bace-4752-b87e-39b4957f7523","remaining_size":"0.06847422","product_id":"BTC-EUR","sequence":3257978153,"time":"2018-01-22T15:14:39.725000Z"}
{"type":"received","order_id":"5f1a9069-988b-4e14-870f-d7c68da21ee9","order_type":"limit","size":"0.03000000","price":"8828.50000000","side":"sell","client_oid":"3f7c72cf-25cc-4e17-9ada-324c87774c6c","product_id":"BTC-EUR","sequence":3257978154,"time":"2018-01-22T15:14:39.726000Z"}
{"type":"open","side":"sell","price":"8828.50000000","order_id":"5f1a9069-988b-4e14-870f-d7c68da21ee9","remaining_size":"0.03000000","product_id":"BTC-EUR","sequence":3257978155,"time":"2018-01-22T15:14:39.726000Z"}
{"type":"done","side":"sell","order_id":"24a3ba69-3869-4448-ad10-7c3581cfe88e","reason":"canceled","product_id":"BTC-EUR","price":"8828.54000000","remaining_size":"0.10500000","sequence":3257978156,"time":"2018-01-22T15:14:39.728000Z"}
{"type":"received","order_id":"ad45e1c0-3423-43c5-8bfe-27931814f303","order_type":"limit","size":"0.00113228","price":"8828.52000000","side":"sell","client_oid":"82111099-2a62-4a83-bdb9-36db441bcf0a","product_id":"BTC-EUR","sequence":3257978157,"time":"2018-01-22T15:14:39.744000Z"}
{"type":"open","side":"sell","price":"8828.52000000","order_id":"ad45e1c0-3423-43c5-8bfe-27931814f303","remaining_size":"0.00113228","product_id":"BTC-EUR","sequence":3257978158,"time":"2018-01-22T15:14:39.744000Z"}
{"type":"done","side":"sell","order_id":"ad45e1c0-3423-43c5-8bfe-27931814f303","reason":"canceled","product_id":"BTC-EUR","price":"8828.52000000","remaining_size":"0.00113228","sequence":3257978159,"time":"2018-01-22T15:14:39.769000Z"}
{"type":"received","order_id":"d30ce8ed-c2a4-47d4-8b95-8ea5e11610f1","order_type":"limit","size":"0.10500000","price":"8828.52000000","side":"sell","client_oid":"bdd7d101-1576-4018-b1f7-20def2de0d70","product_id":"BTC-EUR","sequence":3257978160,"time":"2018-01-22T15:14:39.778000Z"}
{"type":"open","side":"sell","price":"8828.52000000","order_id":"d30ce8ed-c2a4-47d4-8b95-8ea5e11610f1","remaining_size":"0.10500000","product_id":"BTC-EUR","sequence":3257978161,"time":"2018-01-22T15:14:39.778000Z"}
{"type":"done","side":"sell","order_id":"0fb76532-ad19-4c15-976a-97ca8b56a54f","reason":"canceled","product_id":"BTC-EUR","price":"8828.59000000","remaining_size":"0.04164971","sequence":3257978162,"time":"2018-01-22T15:14:39.813000Z"}
{"type":"received","order_id":"47d76213-ffae-414b-8023-64a39de826fd","order_type":"limit","size":"0.02000000","price":"8562.61000000","side":"sell","product_id":"BTC-EUR","sequence":3257978163,"time":"2018-01-22T15:14:39.817000Z"}
{"type":"match","trade_id":10551369,"maker_order_id":"d12d96ab-9096-47f3-96c9-f1fd7dfc4352","taker_order_id":"47d76213-ffae-414b-8023-64a39de826fd","side":"buy","size":"0.00113310","price":"8825.34000000","product_id":"BTC-EUR","sequence":3257978164,"time":"2018-01-22T15:14:39.817000Z"}
{"type":"done","side":"buy","order_id":"d12d96ab-9096-47f3-96c9-f1fd7dfc4352","reason":"filled","product_id":"BTC-EUR","price":"8825.34000000","remaining_size":"0","sequence":3257978165,"time":"2018-01-22T15:14:39.817000Z"}
{"type":"match","trade_id":10551370,"maker_order_id":"55d8c934-886d-4013-8a03-0b60957e1c98","taker_order_id":"47d76213-ffae-414b-8023-64a39de826fd","side":"buy","size":"0.00564464","price":"8825.33000000","product_id":"BTC-EUR","sequence":3257978166,"time":"2018-01-22T15:14:39.817000Z"}
{"type":"done","side":"buy","order_id":"55d8c934-886d-4013-8a03-0b60957e1c98","reason":"filled","product_id":"BTC-EUR","price":"8825.33000000","remaining_size":"0","sequence":3257978167,"time":"2018-01-22T15:14:39.817000Z"}
{"type":"match","trade_id":10551371,"maker_order_id":"709df843-09ef-4374-9277-ddb43d211225","taker_order_id":"47d76213-ffae-414b-8023-64a39de826fd","side":"buy","size":"0.01322226","price":"8825.30000000","product_id":"BTC-EUR","sequence":3257978168,"time":"2018-01-22T15:14:39.817000Z"}
{"type":"done","side":"sell","order_id":"47d76213-ffae-414b-8023-64a39de826fd","reason":"filled","product_id":"BTC-EUR","price":"8562.61000000","remaining_size":"0.00000000","sequence":3257978169,"time":"2018-01-22T15:14:39.817000Z"}
{"type":"received","order_id":"f4aa0525-8659-4e40-bfba-371855159460","order_type":"limit","size":"0.01000000","price":"9091.73000000","side":"buy","product_id":"BTC-EUR","sequence":3257978170,"time":"2018-01-22T15:14:39.827000Z"}
{"type":"match","trade_id":10551372,"maker_order_id":"5f1a9069-988b-4e14-870f-d7c68da21ee9","taker_order_id":"f4aa0525-8659-4e40-bfba-371855159460","side":"sell","size":"0.01000000","price":"8828.50000000","product_id":"BTC-EUR","sequence":3257978171,"time":"2018-01-22T15:14:39.827000Z"}
{"type":"done","side":"buy","order_id":"f4aa0525-8659-4e40-bfba-371855159460","reason":"filled","product_id":"BTC-EUR","price":"9091.73000000","remaining_size":"0.00000000","sequence":3257978172,"time":"2018-01-22T15:14:39.827000Z"}
{"type":"done","side":"sell","order_id":"edb7fc66-2169-4b49-8765-1e0c0a928ce7","reason":"canceled","product_id":"BTC-EUR","price":"8828.51000000","remaining_size":"0.09800000","sequence":3257978173,"time":"2018-01-22T15:14:39.836000Z"}
{"type":"received","order_id":"fc32a7d1-0876-43ff-8d87-183e92e9a771","order_type":"limit","size":"0.00113228","price":"8828.49000000","side":"sell","client_oid":"a54db207-e1aa-4471-94cf-2f7d09fb865c","product_id":"BTC-EUR","sequence":3257978174,"time":"2018-01-22T15:14:39.841000Z"}
{"type":"open","side":"sell","price":"8828.49000000","order_id":"fc32a7d1-0876-43ff-8d87-183e92e9a771","remaining_size":"0.00113228","product_id":"BTC-EUR","sequence":3257978175,"time":"2018-01-22T15:14:39.841000Z"}
{"type":"done","side":"sell","order_id":"19c61b58-9ce1-4e1e-9e58-bd4c4545f8da","reason":"canceled","product_id":"BTC-EUR","price":"8828.54000000","remaining_size":"0.06847422","sequence":3257978176,"time":"2018-01-22T15:14:39.857000Z"}
{"type":"received","order_id":"2b46fd70-22e7-44b0-a785-54a888fa3d92","order_type":"limit","size":"0.01800000","price":"8828.50000000","side":"sell","client_oid":"853bf846-7b88-40d9-a564-dd62002b2c71","product_id":"BTC-EUR","sequence":3257978177,"time":"2018-01-22T15:14:39.859000Z"}
{"type":"open","side":"sell","price":"8828.50000000","order_id":"2b46fd70-22e7-44b0-a785-54a888fa3d92","remaining_size":"0.01800000","product_id":"BTC-EUR","sequence":3257978178,"time":"2018-01-22T15:14:39.859000Z"}
{"type":"received","order_id":"ab36c79a-7573-46c1-aa37-417ee6f15fee","order_type":"limit","size":"0.25000000","price":"8854.70000000","side":"sell","client_oid":"44582f82-bab8-4560-b158-4bf40e1319d6","product_id":"BTC-EUR","sequence":3257978179,"time":"2018-01-22T15:14:39.865000Z"}
{"type":"open","side":"sell","price":"8854.70000000","order_id":"ab36c79a-7573-46c1-aa37-417ee6f15fee","remaining_size":"0.25000000","product_id":"BTC-EUR","sequence":3257978180,"time":"2018-01-22T15:14:39.865000Z"}
{"type":"done","side":"sell","order_id":"5f1a9069-988b-4e14-870f-d7c68da21ee9","reason":"canceled","product_id":"BTC-EUR","price":"8828.50000000","remaining_size":"0.02000000","sequence":3257978181,"time":"2018-01-22T15:14:39.867000Z"}
{"type":"done","side":"sell","order_id":"b7cd2fc5-54c6-483a-8950-0e1e32a30c66","reason":"canceled","product_id":"BTC-EUR","price":"8828.58000000","remaining_size":"0.01800000","sequence":3257978182,"time":"2018-01-22T15:14:39.868000Z"}
{"type":"received","order_id":"ab632f63-5e5f-49a4-9f8a-e6e17295e86d","order_type":"limit","size":"0.10500000","price":"8828.50000000","side":"sell","client_oid":"26f99b39-daeb-4206-a921-4ae981e98983","product_id":"BTC-EUR","sequence":3257978183,"time":"2018-01-22T15:14:39.869000Z"}
{"type":"open","side":"sell","price":"8828.50000000","order_id":"ab632f63-5e5f-49a4-9f8a-e6e17295e86d","remaining_size":"0.10500000","product_id":"BTC-EUR","sequence":3257978184,"time":"2018-01-22T15:14:39.869000Z"}
{"type":"received","order_id":"82af54e9-d325-46fd-9ccd-3be3aceb150a","order_type":"limit","size":"0.01800000","price":"8828.50000000","side":"sell","client_oid":"50a44ed1-9343-4e4a-bd87-eab516160296","product_id":"BTC-EUR","sequence":3257978185,"time":"2018-01-22T15:14:39.877000Z"}
{"type":"open","side":"sell","price":"8828.50000000","order_id":"82af54e9-d325-46fd-9ccd-3be3aceb150a","remaining_size":"0.01800000","product_id":"BTC-EUR","sequence":3257978186,"time":"2018-01-22T15:14:39.877000Z"}
{"type":"received","order_id":"ad93b2a2-4789-45bd-aef8-1128415269f8","order_type":"limit","size":"0.01600000","price":"8828.50000000","side":"sell","client_oid":"b43f5892-fb24-4873-a6a3-f04ad00ba05d","product_id":"BTC-EUR","sequence":3257978187,"time":"2018-01-22T15:14:39.877000Z"}
{"type":"open","side":"sell","price":"8828.50000000","order_id":"ad93b2a2-4789-45bd-aef8-1128415269f8","remaining_size":"0.01600000","product_id":"BTC-EUR","sequence":3257978188,"time":"2018-01-22T15:14:39.877000Z"}
{"type":"received","order_id":"07c0ff39-c874-4c7f-b3ea-8ba9f17f940a","order_type":"limit","size":"0.09800000","price":"8828.49000000","side":"sell","client_oid":"9e80b28f-4483-4cff-bc89-dddb36495f3d","product_id":"BTC-EUR","sequence":3257978189,"time":"2018-01-22T15:14:39.884000Z"}
{"type":"open","side":"sell","price":"8828.49000000","order_id":"07c0ff39-c874-4c7f-b3ea-8ba9f17f940a","remaining_size":"0.09800000","product_id":"BTC-EUR","sequence":3257978190,"time":"2018-01-22T15:14:39.884000Z"}
{"type":"done","side":"buy","order_id":"8b5da55b-1964-42b8-8442-f4567b331381","reason":"canceled","product_id":"BTC-EUR","price":"8631.27000000","remaining_size":"1.28000000","sequence":3257978191,"time":"2018-01-22T15:14:39.885000Z"}
{"type":"received","order_id":"9f196558-492c-47c5-aee4-787c55409394","order_type":"limit","size":"0.06847422","price":"8828.51000000","side":"sell","client_oid":"865a5247-3e86-4a7c-84d8-5ab3d71be30b","product_id":"BTC-EUR","sequence":3257978192,"time":"2018-01-22T15:14:39.888000Z"}
{"type":"open","side":"sell","price":"8828.51000000","order_id":"9f196558-492c-47c5-aee4-787c55409394","remaining_size":"0.06847422","product_id":"BTC-EUR","sequence":3257978193,"time":"2018-01-22T15:14:39.888000Z"}
{"type":"done","side":"sell","order_id":"fc32a7d1-0876-43ff-8d87-183e92e9a771","reason":"canceled","product_id":"BTC-EUR","price":"8828.49000000","remaining_size":"0.00113228","sequence":3257978194,"time":"2018-01-22T15:14:39.888000Z"}
{"type":"received","order_id":"0a9e610d-f6a3-44bb-99e0-0af8aa789dcd","order_type":"limit","size":"0.75000000","price":"8947.90000000","side":"sell","client_oid":"a9fa1585-a76a-435e-8ad9-d74539f6a478","product_id":"BTC-EUR","sequence":3257978195,"time":"2018-01-22T15:14:39.899000Z"}
{"type":"open","side":"sell","price":"8947.90000000","order_id":"0a9e610d-f6a3-44bb-99e0-0af8aa789dcd","remaining_size":"0.75000000","product_id":"BTC-EUR","sequence":3257978196,"time":"2018-01-22T15:14:39.899000Z"}
{"type":"done","side":"sell","order_id":"d30ce8ed-c2a4-47d4-8b95-8ea5e11610f1","reason":"canceled","product_id":"BTC-EUR","price":"8828.52000000","remaining_size":"0.10500000","sequence":3257978197,"time":"2018-01-22T15:14:39.901000Z"}
{"type":"received","order_id":"65226128-bb9a-4169-a2bb-8836f79aa3a2","order_type":"limit","size":"0.01800000","price":"8828.49000000","side":"sell","client_oid":"5eeb2405-cd2e-443e-88e9-a1696260f729","product_id":"BTC-EUR","sequence":3257978198,"time":"2018-01-22T15:14:39.902000Z"}
{"type":"open","side":"sell","price":"8828.49000000","order_id":"65226128-bb9a-4169-a2bb-8836f79aa3a2","remaining_size":"0.01800000","product_id":"BTC-EUR","sequence":3257978199,"time":"2018-01-22T15:14:39.902000Z"}
{"type":"received","order_id":"6d89f361-3be2-41c0-a593-725f36d1c410","order_type":"limit","size":"0.00113228","price":"8828.48000000","side":"sell","client_oid":"d61753b2-7b9a-43a9-921a-4f6733d056e8","product_id":"BTC-EUR","sequence":3257978200,"time":"2018-01-22T15:14:39.925000Z"}
{"type":"open","side":"sell","price":"8828.48000000","order_id":"6d89f361-3be2-41c0-a593-725f36d1c410","remaining_size":"0.00113228","product_id":"BTC-EUR","sequence":3257978201,"time":"2018-01-22T15:14:39.925000Z"}
{"type":"received","order_id":"eb0e9f8a-5962-4adc-be67-8dc534b11872","order_type":"limit","size":"0.03322226","price":"8828.48000000","side":"sell","client_oid":"e3452e94-8a59-4304-aa1d-b8df55d263a1","product_id":"BTC-EUR","sequence":3257978202,"time":"2018-01-22T15:14:39.936000Z"}
{"type":"open","side":"sell","price":"8828.48000000","order_id":"eb0e9f8a-5962-4adc-be67-8dc534b11872","remaining_size":"0.03322226","product_id":"BTC-EUR","sequence":3257978203,"time":"2018-01-22T15:14:39.936000Z"}
{"type":"done","side":"sell","order_id":"2b46fd70-22e7-44b0-a785-54a888fa3d92","reason":"canceled","product_id":"BTC-EUR","price":"8828.50000000","remaining_size":"0.01800000","sequence":3257978204,"time":"2018-01-22T15:14:39.945000Z"}
{"type":"received","order_id":"269e1972-b903-47a4-9d97-fcde645500b6","order_type":"limit","size":"0.01800000","price":"8828.48000000","side":"sell","client_oid":"d25a7908-3933-4234-ad6e-26a3fb6893ac","product_id":"BTC-EUR","sequence":3257978205,"time":"2018-01-22T15:14:39.965000Z"}
{"type":"open","side":"sell","price":"8828.48000000","order_id":"269e1972-b903-47a4-9d97-fcde645500b6","remaining_size":"0.01800000","product_id":"BTC-EUR","sequence":3257978206,"time":"2018-01-22T15:14:39.965000Z"}
{"type":"done","side":"sell","order_id":"ab632f63-5e5f-49a4-9f8a-e6e17295e86d","reason":"canceled","product_id":"BTC-EUR","price":"8828.50000000","remaining_size":"0.10500000","sequence":3257978207,"time":"2018-01-22T15:14:39.969000Z"}
{"type":"received","order_id":"0e57b5b5-92b5-452c-ab1f-560bec1011ac","order_type":"limit","size":"0.10500000","price":"8828.49000000","side":"sell","client_oid":"8ccd4d05-8291-4ea6-9fbb-0957e625796f","product_id":"BTC-EUR","sequence":3257978208,"time":"2018-01-22T15:14:39.996000Z"}
{"type":"open","side":"sell","price":"8828.49000000","order_id":"0e57b5b5-92b5-452c-ab1f-560bec1011ac","remaining_size":"0.10500000","product_id":"BTC-EUR","sequence":3257978209,"time":"2018-01-22T15:14:39.996000Z"}
{"type":"received","order_id":"df586bd6-fe14-4ea4-985c-07a9e6971a12","order_type":"limit","size":"0.21404538","price":"8828.52000000","side":"sell","product_id":"BTC-EUR","sequence":3257978210,"time":"2018-01-22T15:14:39.996000Z"}
{"type":"open","side":"sell","price":"8828.52000000","order_id":"df586bd6-fe14-4ea4-985c-07a9e6971a12","remaining_size":"0.21404538","product_id":"BTC-EUR","sequence":3257978211,"time":"2018-01-22T15:14:39.996000Z"}
{"type":"done","side":"sell","order_id":"27de8b2e-bace-4752-b87e-39b4957f7523","reason":"canceled","product_id":"BTC-EUR","price":"8828.52000000","remaining_size":"0.06847422","sequence":3257978212,"time":"2018-01-22T15:14:40.003000Z"}
{"type":"done","side":"sell","order_id":"7032363c-59f7-4b9d-861e-a25a2b7cecee","reason":"canceled","product_id":"BTC-EUR","price":"8828.53000000","remaining_size":"0.06847422","sequence":3257978213,"time":"2018-01-22T15:14:40.003000Z"}
{"type":"done","side":"sell","order_id":"82af54e9-d325-46fd-9ccd-3be3aceb150a","reason":"canceled","product_id":"BTC-EUR","price":"8828.50000000","remaining_size":"0.01800000","sequence":3257978214,"time":"2018-01-22T15:14:40.009000Z"}
{"type":"received","order_id":"3e5517a0-459e-4c14-9ee9-2c3cd4244be8","order_type":"limit","size":"0.06847422","price":"8828.50000000","side":"sell","client_oid":"b1d06008-284c-4388-b4e5-cb6cee2ec39b","product_id":"BTC-EUR","sequence":3257978215,"time":"2018-01-22T15:14:40.029000Z"}
{"type":"open","side":"sell","price":"8828.50000000","order_id":"3e5517a0-459e-4c14-9ee9-2c3cd4244be8","remaining_size":"0.06847422","product_id":"BTC-EUR","sequence":3257978216,"time":"2018-01-22T15:14:40.029000Z"}
{"type":"received","order_id":"859dd624-3f74-4181-b424-6588cfc316f7","order_type":"limit","size":"0.06847422","price":"8828.49000000","side":"sell","client_oid":"3b47423f-cb24-4089-a3f0-420e7dc45062","product_id":"BTC-EUR","sequence":3257978217,"time":"2018-01-22T15:14:40.032000Z"}
{"type":"open","side":"sell","price":"8828.49000000","order_id":"859dd624-3f74-4181-b424-6588cfc316f7","remaining_size":"0.06847422","product_id":"BTC-EUR","sequence":3257978218,"time":"2018-01-22T15:14:40.032000Z"}
{"type":"received","order_id":"84dc2b14-baf4-4cf5-a922-a2b86ef9ccc5","order_type":"limit","size":"0.01800000","price":"8828.48000000","side":"sell","client_oid":"18ee8bb8-55d9-4afe-89b3-d4aa47d3d579","product_id":"BTC-EUR","sequence":3257978219,"time":"2018-01-22T15:14:40.034000Z"}
{"type":"open","side":"sell","price":"8828.48000000","order_id":"84dc2b14-baf4-4cf5-a922-a2b86ef9ccc5","remaining_size":"0.01800000","product_id":"BTC-EUR","sequence":3257978220,"time":"2018-01-22T15:14:40.034000Z"}
{"type":"done","side":"sell","order_id":"ad93b2a2-4789-45bd-aef8-1128415269f8","reason":"canceled","product_id":"BTC-EUR","price":"8828.50000000","remaining_size":"0.01600000","sequence":3257978221,"time":"2018-01-22T15:14:40.040000Z"}
{"type":"done","side":"sell","order_id":"65226128-bb9a-4169-a2bb-8836f79aa3a2","reason":"canceled","product_id":"BTC-EUR","price":"8828.49000000","remaining_size":"0.01800000","sequence":3257978222,"time":"2018-01-22T15:14:40.040000Z"}
{"type":"received","order_id":"7fbcd17c-2759-482a-8de9-ba8121b9f894","order_type":"limit","size":"0.06847422","price":"8828.48000000","side":"sell","client_oid":"79edc2fa-102e-4e5a-bbfd-a2ee589f7465","product_id":"BTC-EUR","sequence":3257978223,"time":"2018-01-22T15:14:40.042000Z"}
{"type":"open","side":"sell","price":"8828.48000000","order_id":"7fbcd17c-2759-482a-8de9-ba8121b9f894","remaining_size":"0.06847422","product_id":"BTC-EUR","sequence":3257978224,"time":"2018-01-22T15:14:40.042000Z"}
{"type":"received","order_id":"869fa380-58d9-4698-9ed6-822132e38136","order_type":"limit","size":"0.04164971","price":"8828.48000000","side":"sell","client_oid":"d7a88928-14a9-4093-9807-9185f6fe0e87","product_id":"BTC-EUR","sequence":3257978225,"time":"2018-01-22T15:14:40.042000Z"}
{"type":"open","side":"sell","price":"8828.48000000","order_id":"869fa380-58d9-4698-9ed6-822132e38136","remaining_size":"0.04164971","product_id":"BTC-EUR","sequence":3257978226,"time":"2018-01-22T15:14:40.042000Z"}
{"type":"received","order_id":"b6813d3e-ae4e-4933-bf9d-b854f5225b7a","order_type":"limit","size":"0.10500000","price":"8828.49000000","side":"sell","client_oid":"5cfb001c-6ae5-4d75-aac4-3f9b93ac829e","product_id":"BTC-EUR","sequence":3257978227,"time":"2018-01-22T15:14:40.046000Z"}
{"type":"open","side":"sell","price":"8828.49000000","order_id":"b6813d3e-ae4e-4933-bf9d-b854f5225b7a","remaining_size":"0.10500000","product_id":"BTC-EUR","sequence":3257978228,"time":"2018-01-22T15:14:40.046000Z"}
{"type":"done","side":"sell","order_id":"07c0ff39-c874-4c7f-b3ea-8ba9f17f940a","reason":"canceled","product_id":"BTC-EUR","price":"8828.49000000","remaining_size":"0.09800000","sequence":3257978229,"time":"2018-01-22T15:14:40.079000Z"}
{"type":"received","order_id":"9eb8fecb-4b41-49db-9dbf-c4716393082f","order_type":"limit","size":"0.01800000","price":"8828.47000000","side":"sell","client_oid":"2c964081-411a-4e9e-82a5-e07f0e6a5ce0","product_id":"BTC-EUR","sequence":3257978230,"time":"2018-01-22T15:14:40.088000Z"}
{"type":"open","side":"sell","price":"8828.47000000","order_id":"9eb8fecb-4b41-49db-9dbf-c4716393082f","remaining_size":"0.01800000","product_id":"BTC-EUR","sequence":3257978231,"time":"2018-01-22T15:14:40.088000Z"}
{"type":"done","side":"sell","order_id":"0e57b5b5-92b5-452c-ab1f-560bec1011ac","reason":"canceled","product_id":"BTC-EUR","price":"8828.49000000","remaining_size":"0.10500000","sequence":3257978232,"time":"2018-01-22T15:14:40.095000Z"}
{"type":"done","side":"sell","order_id":"6d89f361-3be2-41c0-a593-725f36d1c410","reason":"canceled","product_id":"BTC-EUR","price":"8828.48000000","remaining_size":"0.00113228","sequence":3257978233,"time":"2018-01-22T15:14:40.106000Z"}
{"type":"received","order_id":"d37b4361-3dd6-4d95-8abe-4a25add7b7b7","order_type":"limit","size":"0.00564464","price":"8828.49000000","side":"sell","client_oid":"3b9e3e71-4e48-43fe-9f7b-37b190a5efff","product_id":"BTC-EUR","sequence":3257978234,"time":"2018-01-22T15:14:40.118000Z"}
{"type":"open","side":"sell","price":"8828.49000000","order_id":"d37b4361-3dd6-4d95-8abe-4a25add7b7b7","remaining_size":"0.00564464","product_id":"BTC-EUR","sequence":3257978235,"time":"2018-01-22T15:14:40.118000Z"}
{"type":"done","side":"sell","order_id":"df586bd6-fe14-4ea4-985c-07a9e6971a12","reason":"canceled","product_id":"BTC-EUR","price":"8828.52000000","remaining_size":"0.21404538","sequence":3257978236,"time":"2018-01-22T15:14:40.123000Z"}
{"type":"done","side":"sell","order_id":"9f196558-492c-47c5-aee4-787c55409394","reason":"canceled","product_id":"BTC-EUR","price":"8828.51000000","remaining_size":"0.06847422","sequence":3257978237,"time":"2018-01-22T15:14:40.123000Z"}
{"type":"received","order_id":"29241bd3-35e7-48e1-9096-286e4008d0d0","order_type":"limit","size":"0.10500000","price":"8828.48000000","side":"sell","client_oid":"e6073bb8-0a54-4256-aa88-2dedd8c4f365","product_id":"BTC-EUR","sequence":3257978238,"time":"2018-01-22T15:14:40.128000Z"}
{"type":"open","side":"sell","price":"8828.48000000","order_id":"29241bd3-35e7-48e1-9096-286e4008d0d0","remaining_size":"0.10500000","product_id":"BTC-EUR","sequence":3257978239,"time":"2018-01-22T15:14:40.128000Z"}
{"type":"done","side":"sell","order_id":"b6813d3e-ae4e-4933-bf9d-b854f5225b7a","reason":"canceled","product_id":"BTC-EUR","price":"8828.49000000","remaining_size":"0.10500000","sequence":3257978240,"time":"2018-01-22T15:14:40.161000Z"}
{"type":"done","side":"sell","order_id":"269e1972-b903-47a4-9d97-fcde645500b6","reason":"canceled","product_id":"BTC-EUR","price":"8828.48000000","remaining_size":"0.01800000","sequence":3257978241,"time":"2018-01-22T15:14:40.173000Z"}
{"type":"done","side":"sell","order_id":"1828604e-d4d1-4fcd-a197-c568cd350926","reason":"canceled","product_id":"BTC-EUR","price":"8828.55000000","remaining_size":"0.22947933","sequence":3257978242,"time":"2018-01-22T15:14:40.180000Z"}
{"type":"done","side":"sell","order_id":"d9c6feb5-c972-450d-8a8f-556cef626691","reason":"canceled","product_id":"BTC-EUR","price":"8828.55000000","remaining_size":"0.01322632","sequence":3257978243,"time":"2018-01-22T15:14:40.203000Z"}
{"type":"done","side":"sell","order_id":"29241bd3-35e7-48e1-9096-286e4008d0d0","reason":"canceled","product_id":"BTC-EUR","price":"8828.48000000","remaining_size":"0.10500000","sequence":3257978244,"time":"2018-01-22T15:14:40.203000Z"}
{"type":"received","order_id":"dead9ecf-074e-480a-a9e0-a1dd5448c635","order_type":"limit","size":"0.06847422","price":"8828.47000000","side":"sell","client_oid":"45067ea3-01b6-48bd-b278-53ea3c76a0b3","product_id":"BTC-EUR","sequence":3257978245,"time":"2018-01-22T15:14:40.208000Z"}
{"type":"open","side":"sell","price":"8828.47000000","order_id":"dead9ecf-074e-480a-a9e0-a1dd5448c635","remaining_size":"0.06847422","product_id":"BTC-EUR","sequence":3257978246,"time":"2018-01-22T15:14:40.208000Z"}
{"type":"received","order_id":"ee228f96-e796-47f4-97a2-a4500d129db4","order_type":"limit","size":"0.10500000","price":"8828.48000000","side":"sell","client_oid":"bd6e0823-a2ab-47fd-b69f-40077b493b88","product_id":"BTC-EUR","sequence":3257978247,"time":"2018-01-22T15:14:40.210000Z"}
{"type":"open","side":"sell","price":"8828.48000000","order_id":"ee228f96-e796-47f4-97a2-a4500d129db4","remaining_size":"0.10500000","product_id":"BTC-EUR","sequence":3257978248,"time":"2018-01-22T15:14:40.210000Z"}
{"type":"done","side":"sell","order_id":"eb0e9f8a-5962-4adc-be67-8dc534b11872","reason":"canceled","product_id":"BTC-EUR","price":"8828.48000000","remaining_size":"0.03322226","sequence":3257978249,"time":"2018-01-22T15:14:40.216000Z"}
{"type":"done","side":"sell","order_id":"84dc2b14-baf4-4cf5-a922-a2b86ef9ccc5","reason":"canceled","product_id":"BTC-EUR","price":"8828.48000000","remaining_size":"0.01800000","sequence":3257978250,"time":"2018-01-22T15:14:40.235000Z"}
{"type":"done","side":"sell","order_id":"7fbcd17c-2759-482a-8de9-ba8121b9f894","reason":"canceled","product_id":"BTC-EUR","price":"8828.48000000","remaining_size":"0.06847422","sequence":3257978251,"time":"2018-01-22T15:14:40.240000Z"}
{"type":"done","side":"sell","order_id":"859dd624-3f74-4181-b424-6588cfc316f7","reason":"canceled","product_id":"BTC-EUR","price":"8828.49000000","remaining_size":"0.06847422","sequence":3257978252,"time":"2018-01-22T15:14:40.240000Z"}
{"type":"done","side":"sell","order_id":"3e5517a0-459e-4c14-9ee9-2c3cd4244be8","reason":"canceled","product_id":"BTC-EUR","price":"8828.50000000","remaining_size":"0.06847422","sequence":3257978253,"time":"2018-01-22T15:14:40.242000Z"}
{"type":"done","side":"buy","order_id":"4454af16-3b3b-4234-8e13-a9888581b0d4","reason":"canceled","product_id":"BTC-EUR","price":"8646.40000000","remaining_size":"1.89779000","sequence":3257978254,"time":"2018-01-22T15:14:40.249000Z"}
{"type":"received","order_id":"9e569264-5097-4d9c-b589-09a880bde865","order_type":"limit","size":"0.10500000","price":"8828.47000000","side":"sell","client_oid":"652915e2-84ca-4eff-9fad-97b36c1a525c","product_id":"BTC-EUR","sequence":3257978255,"time":"2018-01-22T15:14:40.253000Z"}
{"type":"open","side":"sell","price":"8828.47000000","order_id":"9e569264-5097-4d9c-b589-09a880bde865","remaining_size":"0.10500000","product_id":"BTC-EUR","sequence":3257978256,"time":"2018-01-22T15:14:40.253000Z"}
{"type":"received","order_id":"ba27bbb0-51b3-4090-a37b-c4f998432011","order_type":"limit","size":"0.00113228","price":"8828.46000000","side":"sell","client_oid":"97e85da4-017b-4053-8cef-2671b77ea611","product_id":"BTC-EUR","sequence":3257978257,"time":"2018-01-22T15:14:40.254000Z"}
{"type":"open","side":"sell","price":"8828.46000000","order_id":"ba27bbb0-51b3-4090-a37b-c4f998432011","remaining_size":"0.00113228","product_id":"BTC-EUR","sequence":3257978258,"time":"2018-01-22T15:14:40.254000Z"}
{"type":"received","order_id":"8b8aca28-6fc9-483f-be6c-fe9b84acfb14","order_type":"limit","size":"0.01800000","price":"8828.46000000","side":"sell","client_oid":"3dac6165-0e88-4604-88aa-0f2b75eb68cc","product_id":"BTC-EUR","sequence":3257978259,"time":"2018-01-22T15:14:40.269000Z"}
{"type":"open","side":"sell","price":"8828.46000000","order_id":"8b8aca28-6fc9-483f-be6c-fe9b84acfb14","remaining_size":"0.01800000","product_id":"BTC-EUR","sequence":3257978260,"time":"2018-01-22T15:14:40.269000Z"}
{"type":"received","order_id":"4535dd08-9e07-407e-bca1-0e83e836f743","order_type":"limit","size":"0.10500000","price":"8828.47000000","side":"sell","client_oid":"8762cd94-0ccc-4431-ac3b-df00a64ab56c","product_id":"BTC-EUR","sequence":3257978261,"time":"2018-01-22T15:14:40.270000Z"}
{"type":"open","side":"sell","price":"8828.47000000","order_id":"4535dd08-9e07-407e-bca1-0e83e836f743","remaining_size":"0.10500000","product_id":"BTC-EUR","sequence":3257978262,"time":"2018-01-22T15:14:40.270000Z"}
{"type":"received","order_id":"7f3bdbd4-85fa-4247-a5c0-5bdcf3452fe1","order_type":"limit","size":"0.03322226","price":"8828.46000000","side":"sell","client_oid":"7587e9a8-f8a6-4fea-9eba-648b610ea438","product_id":"BTC-EUR","sequence":3257978263,"time":"2018-01-22T15:14:40.300000Z"}
{"type":"open","side":"sell","price":"8828.46000000","order_id":"7f3bdbd4-85fa-4247-a5c0-5bdcf3452fe1","remaining_size":"0.03322226","product_id":"BTC-EUR","sequence":3257978264,"time":"2018-01-22T15:14:40.300000Z"}
{"type":"received","order_id":"a554a26a-5422-4f4e-867d-33fe05436b52","order_type":"limit","size":"0.06847422","price":"8828.46000000","side":"sell","client_oid":"3157b37c-b8a5-46c2-9318-304c18e59d2c","product_id":"BTC-EUR","sequence":3257978265,"time":"2018-01-22T15:14:40.300000Z"}
{"type":"open","side":"sell","price":"8828.46000000","order_id":"a554a26a-5422-4f4e-867d-33fe05436b52","remaining_size":"0.06847422","product_id":"BTC-EUR","sequence":3257978266,"time":"2018-01-22T15:14:40.300000Z"}
{"type":"done","side":"sell","order_id":"ee228f96-e796-47f4-97a2-a4500d129db4","reason":"canceled","product_id":"BTC-EUR","price":"8828.48000000","remaining_size":"0.10500000","sequence":3257978267,"time":"2018-01-22T15:14:40.318000Z"}
{"type":"received","order_id":"2286feb7-cb00-4466-9090-83a4ae9f7270","order_type":"limit","size":"0.10500000","price":"8828.47000000","side":"sell","client_oid":"496344a3-ee8c-4f17-b972-0c005fcbee7a","product_id":"BTC-EUR","sequence":3257978268,"time":"2018-01-22T15:14:40.352000Z"}
{"type":"open","side":"sell","price":"8828.47000000","order_id":"2286feb7-cb00-4466-9090-83a4ae9f7270","remaining_size":"0.10500000","product_id":"BTC-EUR","sequence":3257978269,"time":"2018-01-22T15:14:40.352000Z"}
{"type":"done","side":"sell","order_id":"9e569264-5097-4d9c-b589-09a880bde865","reason":"canceled","product_id":"BTC-EUR","price":"8828.47000000","remaining_size":"0.10500000","sequence":3257978270,"time":"2018-01-22T15:14:40.367000Z"}
{"type":"done","side":"sell","order_id":"9eb8fecb-4b41-49db-9dbf-c4716393082f","reason":"canceled","product_id":"BTC-EUR","price":"8828.47000000","remaining_size":"0.01800000","sequence":3257978271,"time":"2018-01-22T15:14:40.370000Z"}
{"type":"done","side":"sell","order_id":"4535dd08-9e07-407e-bca1-0e83e836f743","reason":"canceled","product_id":"BTC-EUR","price":"8828.47000000","remaining_size":"0.10500000","sequence":3257978272,"time":"2018-01-22T15:14:40.391000Z"}
{"type":"received","order_id":"59dddbe0-428f-41c8-a968-94f25d09a2dc","order_type":"limit","size":"0.01800000","price":"8828.45000000","side":"sell","client_oid":"dd3e38b4-07c5-4c86-a333-da1494fd4b47","product_id":"BTC-EUR","sequence":3257978273,"time":"2018-01-22T15:14:40.420000Z"}
{"type":"open","side":"sell","price":"8828.45000000","order_id":"59dddbe0-428f-41c8-a968-94f25d09a2dc","remaining_size":"0.01800000","product_id":"BTC-EUR","sequence":3257978274,"time":"2018-01-22T15:14:40.420000Z"}
{"type":"received","order_id":"b9e22ce7-1df1-42c8-8edc-f7244d21cfeb","order_type":"limit","size":"0.01322632","price":"8828.47000000","side":"sell","client_oid":"145a4abd-21ed-418d-939a-29510db47627","product_id":"BTC-EUR","sequence":3257978275,"time":"2018-01-22T15:14:40.426000Z"}
{"type":"open","side":"sell","price":"8828.47000000","order_id":"b9e22ce7-1df1-42c8-8edc-f7244d21cfeb","remaining_size":"0.01322632","product_id":"BTC-EUR","sequence":3257978276,"time":"2018-01-22T15:14:40.426000Z"}
{"type":"done","side":"sell","order_id":"ba27bbb0-51b3-4090-a37b-c4f998432011","reason":"canceled","product_id":"BTC-EUR","price":"8828.46000000","remaining_size":"0.00113228","sequence":3257978277,"time":"2018-01-22T15:14:40.431000Z"}
{"type":"received","order_id":"089646ce-3601-4b3a-be96-600b740c4b23","order_type":"limit","size":"0.22947933","price":"8828.47000000","side":"sell","client_oid":"41f14653-459c-41cb-bd57-327b0fa66c36","product_id":"BTC-EUR","sequence":3257978278,"time":"2018-01-22T15:14:40.434000Z"}
{"type":"open","side":"sell","price":"8828.47000000","order_id":"089646ce-3601-4b3a-be96-600b740c4b23","remaining_size":"0.22947933","product_id":"BTC-EUR","sequence":3257978279,"time":"2018-01-22T15:14:40.434000Z"}
{"type":"done","side":"sell","order_id":"dead9ecf-074e-480a-a9e0-a1dd5448c635","reason":"canceled","product_id":"BTC-EUR","price":"8828.47000000","remaining_size":"0.06847422","sequence":3257978280,"time":"2018-01-22T15:14:40.435000Z"}
{"type":"received","order_id":"82160d74-ca38-4859-ade3-4fb12da52657","order_type":"limit","size":"0.10500000","price":"8828.46000000","side":"sell","client_oid":"dff48c17-ba94-4d79-8501-0a20331d2d95","product_id":"BTC-EUR","sequence":3257978281,"time":"2018-01-22T15:14:40.436000Z"}
{"type":"open","side":"sell","price":"8828.46000000","order_id":"82160d74-ca38-4859-ade3-4fb12da52657","remaining_size":"0.10500000","product_id":"BTC-EUR","sequence":3257978282,"time":"2018-01-22T15:14:40.436000Z"}
{"type":"done","side":"sell","order_id":"2286feb7-cb00-4466-9090-83a4ae9f7270","reason":"canceled","product_id":"BTC-EUR","price":"8828.47000000","remaining_size":"0.10500000","sequence":3257978283,"time":"2018-01-22T15:14:40.440000Z"}
{"type":"received","order_id":"6b0fe651-74bc-4f17-9f1a-fe484023d71c","order_type":"limit","size":"0.21404538","price":"8828.45000000","side":"sell","product_id":"BTC-EUR","sequence":3257978284,"time":"2018-01-22T15:14:40.440000Z"}
{"type":"open","side":"sell","price":"8828.45000000","order_id":"6b0fe651-74bc-4f17-9f1a-fe484023d71c","remaining_size":"0.21404538","product_id":"BTC-EUR","sequence":3257978285,"time":"2018-01-22T15:14:40.440000Z"}
{"type":"done","side":"sell","order_id":"7f3bdbd4-85fa-4247-a5c0-5bdcf3452fe1","reason":"canceled","product_id":"BTC-EUR","price":"8828.46000000","remaining_size":"0.03322226","sequence":3257978286,"time":"2018-01-22T15:14:40.447000Z"}
{"type":"done","side":"buy","order_id":"c3d4b1c3-ae39-4e4a-a6df-7352f87623f4","reason":"canceled","product_id":"BTC-EUR","price":"8785.42000000","remaining_size":"0.25000000","sequence":3257978287,"time":"2018-01-22T15:14:40.452000Z"}
{"type":"received","order_id":"1d1966cc-a8e7-451f-a130-0017a3d8a349","order_type":"limit","size":"0.00113228","price":"8828.44000000","side":"sell","client_oid":"9bfd3dfb-a972-4e59-8354-5ee35e228e89","product_id":"BTC-EUR","sequence":3257978288,"time":"2018-01-22T15:14:40.460000Z"}
{"type":"open","side":"sell","price":"8828.44000000","order_id":"1d1966cc-a8e7-451f-a130-0017a3d8a349","remaining_size":"0.00113228","product_id":"BTC-EUR","sequence":3257978289,"time":"2018-01-22T15:14:40.460000Z"}
{"type":"received","order_id":"7e5bf2c5-6e1a-4de9-a440-846baf84bbcc","order_type":"limit","size":"0.03322226","price":"8828.44000000","side":"sell","client_oid":"e53ff592-a06b-4cbf-b97b-cb6924c7af7b","product_id":"BTC-EUR","sequence":3257978290,"time":"2018-01-22T15:14:40.478000Z"}
{"type":"open","side":"sell","price":"8828.44000000","order_id":"7e5bf2c5-6e1a-4de9-a440-846baf84bbcc","remaining_size":"0.03322226","product_id":"BTC-EUR","sequence":3257978291,"time":"2018-01-22T15:14:40.478000Z"}
{"type":"done","side":"sell","order_id":"8d4c23ea-67b7-4f2a-96a8-a811ae09ef07","reason":"canceled","product_id":"BTC-EUR","price":"9040.70000000","remaining_size":"0.75000000","sequence":3257978292,"time":"2018-01-22T15:14:40.484000Z"}
{"type":"done","side":"sell","order_id":"8b8aca28-6fc9-483f-be6c-fe9b84acfb14","reason":"canceled","product_id":"BTC-EUR","price":"8828.46000000","remaining_size":"0.01800000","sequence":3257978293,"time":"2018-01-22T15:14:40.506000Z"}
{"type":"done","side":"buy","order_id":"ee39445d-c831-4367-8183-629666b575d5","reason":"canceled","product_id":"BTC-EUR","price":"8721.10000000","remaining_size":"0.75000000","sequence":3257978294,"time":"2018-01-22T15:14:40.538000Z"}
{"type":"done","side":"sell","order_id":"59dddbe0-428f-41c8-a968-94f25d09a2dc","reason":"canceled","product_id":"BTC-EUR","price":"8828.45000000","remaining_size":"0.01800000","sequence":3257978295,"time":"2018-01-22T15:14:40.545000Z"}
{"type":"done","side":"buy","order_id":"c5922dd1-e2b6-407a-884b-b23dc597e1a7","reason":"canceled","product_id":"BTC-EUR","price":"8627.90000000","remaining_size":"0.75000000","sequence":3257978296,"time":"2018-01-22T15:14:40.546000Z"}
{"type":"received","order_id":"85c0995c-25b3-4a22-993a-d2f3d30d917e","order_type":"limit","size":"0.01800000","price":"8828.44000000","side":"sell","client_oid":"6760c7b4-9434-42c1-b5e2-b8f4cc5517a5","product_id":"BTC-EUR","sequence":3257978297,"time":"2018-01-22T15:14:40.550000Z"}
{"type":"open","side":"sell","price":"8828.44000000","order_id":"85c0995c-25b3-4a22-993a-d2f3d30d917e","remaining_size":"0.01800000","product_id":"BTC-EUR","sequence":3257978298,"time":"2018-01-22T15:14:40.550000Z"}
{"type":"received","order_id":"39422b04-b383-4c70-90b5-83d679ae65d7","order_type":"limit","size":"0.01800000","price":"8828.44000000","side":"sell","client_oid":"314e1057-7d12-4740-b460-4e08f057eaea","product_id":"BTC-EUR","sequence":3257978299,"time":"2018-01-22T15:14:40.554000Z"}
{"type":"open","side":"sell","price":"8828.44000000","order_id":"39422b04-b383-4c70-90b5-83d679ae65d7","remaining_size":"0.01800000","product_id":"BTC-EUR","sequence":3257978300,"time":"2018-01-22T15:14:40.554000Z"}
{"type":"received","order_id":"b4ff666c-37df-4968-8446-3558220e82b7","order_type":"limit","size":"0.01600000","price":"8828.44000000","side":"sell","client_oid":"061414f1-66d4-430b-8884-2c0a1fad7d65","product_id":"BTC-EUR","sequence":3257978301,"time":"2018-01-22T15:14:40.560000Z"}
{"type":"open","side":"sell","price":"8828.44000000","order_id":"b4ff666c-37df-4968-8446-3558220e82b7","remaining_size":"0.01600000","product_id":"BTC-EUR","sequence":3257978302,"time":"2018-01-22T15:14:40.560000Z"}
{"type":"received","order_id":"82a655b8-ed1f-4afb-b423-7c499b2797b2","order_type":"limit","size":"0.06847422","price":"8828.45000000","side":"sell","client_oid":"692184af-422a-46be-8718-53c3f7f6a602","product_id":"BTC-EUR","sequence":3257978303,"time":"2018-01-22T15:14:40.560000Z"}
{"type":"open","side":"sell","price":"8828.45000000","order_id":"82a655b8-ed1f-4afb-b423-7c499b2797b2","remaining_size":"0.06847422","product_id":"BTC-EUR","sequence":3257978304,"time":"2018-01-22T15:14:40.560000Z"}
{"type":"done","side":"buy","order_id":"7f84334d-7820-4895-9813-e66cf93a139a","reason":"canceled","product_id":"BTC-EUR","price":"8534.70000000","remaining_size":"0.74000000","sequence":3257978305,"time":"2018-01-22T15:14:40.563000Z"}
{"type":"done","side":"buy","order_id":"d33dfaa7-0198-4ca9-8404-f32d6cd10aab","reason":"canceled","product_id":"BTC-EUR","price":"8441.50000000","remaining_size":"0.75000000","sequence":3257978306,"time":"2018-01-22T15:14:40.564000Z"}
{"type":"received","order_id":"99d21c43-73a9-430f-9d56-65e9791a9b0f","order_type":"limit","size":"0.26000000","price":"8752.13000000","side":"buy","product_id":"BTC-EUR","sequence":3257978307,"time":"2018-01-22T15:14:40.567000Z"}
{"type":"open","side":"buy","price":"8752.13000000","order_id":"99d21c43-73a9-430f-9d56-65e9791a9b0f","remaining_size":"0.26000000","product_id":"BTC-EUR","sequence":3257978308,"time":"2018-01-22T15:14:40.567000Z"}
{"type":"done","side":"sell","order_id":"f174d45c-ef7d-4cfb-869b-a9d1469e9142","reason":"canceled","product_id":"BTC-EUR","price":"9413.50000000","remaining_size":"0.75000000","sequence":3257978309,"time":"2018-01-22T15:14:40.569000Z"}
{"type":"done","side":"buy","order_id":"e03dddc9-fb38-4e2f-9304-e85e78cfe457","reason":"canceled","product_id":"BTC-EUR","price":"8348.30000000","remaining_size":"0.75000000","sequence":3257978310,"time":"2018-01-22T15:14:40.569000Z"}
{"type":"received","order_id":"5229ecba-655d-4856-972e-c8cf5b9e6bf9","order_type":"limit","size":"0.01800000","price":"8828.43000000","side":"sell","client_oid":"7ab288d5-2f4d-4683-af44-3b658158f32c","product_id":"BTC-EUR","sequence":3257978311,"time":"2018-01-22T15:14:40.570000Z"}
{"type":"open","side":"sell","price":"8828.43000000","order_id":"5229ecba-655d-4856-972e-c8cf5b9e6bf9","remaining_size":"0.01800000","product_id":"BTC-EUR","sequence":3257978312,"time":"2018-01-22T15:14:40.570000Z"}
{"type":"done","side":"sell","order_id":"d927faa3-d068-4bf7-aba6-66ab0e9c574a","reason":"canceled","product_id":"BTC-EUR","price":"9506.70000000","remaining_size":"0.75000000","sequence":3257978313,"time":"2018-01-22T15:14:40.571000Z"}
{"type":"done","side":"buy","order_id":"d7621c62-1ef5-45cf-ae13-6c87cc743212","reason":"canceled","product_id":"BTC-EUR","price":"8255.10000000","remaining_size":"0.75000000","sequence":3257978314,"time":"2018-01-22T15:14:40.571000Z"}
{"type":"done","side":"sell","order_id":"7876b43a-89ff-48f3-97ed-6f5cfcba62e8","reason":"canceled","product_id":"BTC-EUR","price":"9599.90000000","remaining_size":"0.74000000","sequence":3257978315,"time":"2018-01-22T15:14:40.573000Z"}
{"type":"done","side":"buy","order_id":"6e56f949-22ec-4926-8de1-af6a4fcfc3ed","reason":"canceled","product_id":"BTC-EUR","price":"8161.90000000","remaining_size":"0.74000000","sequence":3257978316,"time":"2018-01-22T15:14:40.573000Z"}
{"type":"done","side":"sell","order_id":"f4ee3645-babf-42ac-81ad-4f7f4499703d","reason":"canceled","product_id":"BTC-EUR","price":"9693.10000000","remaining_size":"0.75000000","sequence":3257978317,"time":"2018-01-22T15:14:40.574000Z"}
{"type":"done","side":"buy","order_id":"ce48bfb3-1227-40b6-9df8-6c0802625df8","reason":"canceled","product_id":"BTC-EUR","price":"8068.70000000","remaining_size":"0.75000000","sequence":3257978318,"time":"2018-01-22T15:14:40.574000Z"}
{"type":"done","side":"sell","order_id":"058d35dc-ce3e-408b-932d-4ad99647a59c","reason":"canceled","product_id":"BTC-EUR","price":"9786.30000000","remaining_size":"0.75000000","sequence":3257978319,"time":"2018-01-22T15:14:40.576000Z"}
{"type":"done","side":"buy","order_id":"a3b7de84-0243-45cf-996c-b46cee7ab959","reason":"canceled","product_id":"BTC-EUR","price":"7975.50000000","remaining_size":"0.75000000","sequence":3257978320,"time":"2018-01-22T15:14:40.576000Z"}
{"type":"done","side":"sell","order_id":"82160d74-ca38-4859-ade3-4fb12da52657","reason":"canceled","product_id":"BTC-EUR","price":"8828.46000000","remaining_size":"0.10500000","sequence":3257978321,"time":"2018-01-22T15:14:40.576000Z"}
{"type":"received","order_id":"19599608-0773-4761-80b3-807220c388e3","order_type":"limit","size":"0.75000000","price":"8721.50000000","side":"buy","client_oid":"d7434b7e-ccfe-4890-bd67-ea800fc9c55d","product_id":"BTC-EUR","sequence":3257978322,"time":"2018-01-22T15:14:40.576000Z"}
{"type":"open","side":"buy","price":"8721.50000000","order_id":"19599608-0773-4761-80b3-807220c388e3","remaining_size":"0.75000000","product_id":"BTC-EUR","sequence":3257978323,"time":"2018-01-22T15:14:40.576000Z"}
{"type":"received","order_id":"35c66a22-b5f9-4df4-aae9-2987bc5e4bbf","order_type":"limit","size":"0.75000000","price":"9041.10000000","side":"sell","client_oid":"9fc2edf5-fc11-486a-9e5b-5f21ad2b6656","product_id":"BTC-EUR","sequence":3257978324,"time":"2018-01-22T15:14:40.577000Z"}
{"type":"open","side":"sell","price":"9041.10000000","order_id":"35c66a22-b5f9-4df4-aae9-2987bc5e4bbf","remaining_size":"0.75000000","product_id":"BTC-EUR","sequence":3257978325,"time":"2018-01-22T15:14:40.577000Z"}
{"type":"received","order_id":"edf0ca31-b528-40cc-a38b-077d10e8a996","order_type":"limit","size":"0.75000000","price":"8628.30000000","side":"buy","client_oid":"8eb1b137-f055-4a16-9454-617985a988ad","product_id":"BTC-EUR","sequence":3257978326,"time":"2018-01-22T15:14:40.577000Z"}
{"type":"open","side":"buy","price":"8628.30000000","order_id":"edf0ca31-b528-40cc-a38b-077d10e8a996","remaining_size":"0.75000000","product_id":"BTC-EUR","sequence":3257978327,"time":"2018-01-22T15:14:40.577000Z"}
{"type":"received","order_id":"a1f47014-b683-4f12-93dc-82ac9340d903","order_type":"limit","size":"0.74000000","price":"8535.10000000","side":"buy","client_oid":"7298d45f-09e4-476f-882e-9311b5dd1987","product_id":"BTC-EUR","sequence":3257978328,"time":"2018-01-22T15:14:40.580000Z"}
{"type":"open","side":"buy","price":"8535.10000000","order_id":"a1f47014-b683-4f12-93dc-82ac9340d903","remaining_size":"0.74000000","product_id":"BTC-EUR","sequence":3257978329,"time":"2018-01-22T15:14:40.580000Z"}
{"type":"done","side":"sell","order_id":"1d1966cc-a8e7-451f-a130-0017a3d8a349","reason":"canceled","product_id":"BTC-EUR","price":"8828.44000000","remaining_size":"0.00113228","sequence":3257978330,"time":"2018-01-22T15:14:40.586000Z"}
{"type":"received","order_id":"dabacf48-9da6-4738-bc63-77ac35040253","order_type":"limit","size":"0.75000000","price":"9320.70000000","side":"sell","client_oid":"5bffa7d1-44f9-4b66-8a12-ad688ab3522d","product_id":"BTC-EUR","sequence":3257978331,"time":"2018-01-22T15:14:40.590000Z"}
{"type":"open","side":"sell","price":"9320.70000000","order_id":"dabacf48-9da6-4738-bc63-77ac35040253","remaining_size":"0.75000000","product_id":"BTC-EUR","sequence":3257978332,"time":"2018-01-22T15:14:40.590000Z"}
{"type":"received","order_id":"35ec1997-2989-45c9-8698-0259912b0d75","order_type":"limit","size":"0.75000000","price":"8441.90000000","side":"buy","client_oid":"f6d1cadc-14b2-4dba-92b9-117217817c8e","product_id":"BTC-EUR","sequence":3257978333,"time":"2018-01-22T15:14:40.598000Z"}
{"type":"open","side":"buy","price":"8441.90000000","order_id":"35ec1997-2989-45c9-8698-0259912b0d75","remaining_size":"0.75000000","product_id":"BTC-EUR","sequence":3257978334,"time":"2018-01-22T15:14:40.598000Z"}
{"type":"received","order_id":"f75f4399-8ee6-4ef2-aee4-b04bc9fa8842","order_type":"limit","size":"0.00113228","price":"8828.42000000","side":"sell","client_oid":"a5abedfc-25a0-457e-8268-280d7dc6600a","product_id":"BTC-EUR","sequence":3257978335,"time":"2018-01-22T15:14:40.613000Z"}
{"type":"open","side":"sell","price":"8828.42000000","order_id":"f75f4399-8ee6-4ef2-aee4-b04bc9fa8842","remaining_size":"0.00113228","product_id":"BTC-EUR","sequence":3257978336,"time":"2018-01-22T15:14:40.613000Z"}
{"type":"received","order_id":"4cee68b2-628f-42ae-b71d-f11d07122c6b","order_type":"limit","size":"0.75000000","price":"7975.90000000","side":"buy","client_oid":"cce9be72-44d7-4182-9cde-b6d619820210","product_id":"BTC-EUR","sequence":3257978337,"time":"2018-01-22T15:14:40.639000Z"}
{"type":"open","side":"buy","price":"7975.90000000","order_id":"4cee68b2-628f-42ae-b71d-f11d07122c6b","remaining_size":"0.75000000","product_id":"BTC-EUR","sequence":3257978338,"time":"2018-01-22T15:14:40.639000Z"}
{"type":"received","order_id":"a1210b9d-fa81-4b68-ae5b-d5a165171815","order_type":"limit","size":"0.75000000","price":"8348.70000000","side":"buy","client_oid":"af8cb0a2-5f80-47eb-b79f-5d5b5257bee5","product_id":"BTC-EUR","sequence":3257978339,"time":"2018-01-22T15:14:40.676000Z"}
{"type":"open","side":"buy","price":"8348.70000000","order_id":"a1210b9d-fa81-4b68-ae5b-d5a165171815","remaining_size":"0.75000000","product_id":"BTC-EUR","sequence":3257978340,"time":"2018-01-22T15:14:40.676000Z"}
{"type":"done","side":"sell","order_id":"a554a26a-5422-4f4e-867d-33fe05436b52","reason":"canceled","product_id":"BTC-EUR","price":"8828.46000000","remaining_size":"0.06847422","sequence":3257978341,"time":"2018-01-22T15:14:40.681000Z"}
{"type":"done","side":"sell","order_id":"85c0995c-25b3-4a22-993a-d2f3d30d917e","reason":"canceled","product_id":"BTC-EUR","price":"8828.44000000","remaining_size":"0.01800000","sequence":3257978342,"time":"2018-01-22T15:14:40.693000Z"}
{"type":"received","order_id":"a099231d-4001-4add-822a-e83881da7b48","order_type":"limit","size":"0.06847422","price":"8828.44000000","side":"sell","client_oid":"a22d15cf-8ee1-43d8-a354-045a285cf55c","product_id":"BTC-EUR","sequence":3257978343,"time":"2018-01-22T15:14:40.710000Z"}
{"type":"open","side":"sell","price":"8828.44000000","order_id":"a099231d-4001-4add-822a-e83881da7b48","remaining_size":"0.06847422","product_id":"BTC-EUR","sequence":3257978344,"time":"2018-01-22T15:14:40.710000Z"}
{"type":"received","order_id":"e1f1bf60-7029-4116-b24d-e12cc36187da","order_type":"limit","size":"0.06847422","price":"8828.43000000","side":"sell","client_oid":"462d6644-9665-44f1-afe5-1137a0ea7f63","product_id":"BTC-EUR","sequence":3257978345,"time":"2018-01-22T15:14:40.714000Z"}
{"type":"open","side":"sell","price":"8828.43000000","order_id":"e1f1bf60-7029-4116-b24d-e12cc36187da","remaining_size":"0.06847422","product_id":"BTC-EUR","sequence":3257978346,"time":"2018-01-22T15:14:40.714000Z"}
{"type":"done","side":"sell","order_id":"7e5bf2c5-6e1a-4de9-a440-846baf84bbcc","reason":"canceled","product_id":"BTC-EUR","price":"8828.44000000","remaining_size":"0.03322226","sequence":3257978347,"time":"2018-01-22T15:14:40.720000Z"}
{"type":"received","order_id":"ae34a7cd-c348-4c6d-bb87-94813b9b9e81","order_type":"limit","size":"0.10500000","price":"8828.44000000","side":"sell","client_oid":"6a080127-32bf-46a7-8917-10d892e4b3c7","product_id":"BTC-EUR","sequence":3257978348,"time":"2018-01-22T15:14:40.732000Z"}
{"type":"open","side":"sell","price":"8828.44000000","order_id":"ae34a7cd-c348-4c6d-bb87-94813b9b9e81","remaining_size":"0.10500000","product_id":"BTC-EUR","sequence":3257978349,"time":"2018-01-22T15:14:40.732000Z"}
{"type":"done","side":"sell","order_id":"39422b04-b383-4c70-90b5-83d679ae65d7","reason":"canceled","product_id":"BTC-EUR","price":"8828.44000000","remaining_size":"0.01800000","sequence":3257978350,"time":"2018-01-22T15:14:40.736000Z"}