{"type":"done","side":"sell","order_id":"3d2ccf52-a56f-4b81-b7cb-44275f1291b8","reason":"canceled","product_id":"BTC-EUR","price":"8840.71000000","remaining_size":"0.11241548","sequence":3257976101,"time":"2018-01-22T15:14:07.340000Z"}
{"type":"received","order_id":"141a24e6-3332-433b-b3d8-e4cd8a8f45b1","order_type":"limit","size":"0.01020000","price":"8860.57000000","side":"sell","product_id":"BTC-EUR","sequence":3257976102,"time":"2018-01-22T15:14:07.435000Z"}
{"type":"open","side":"sell","price":"8860.57000000","order_id":"141a24e6-3332-433b-b3d8-e4cd8a8f45b1","remaining_size":"0.01020000","product_id":"BTC-EUR","sequence":3257976103,"time":"2018-01-22T15:14:07.435000Z"}
{"type":"received","order_id":"7df78783-cb80-456f-86f6-4aa80dcba419","order_type":"limit","size":"0.11241548","price":"8840.69000000","side":"sell","product_id":"BTC-EUR","sequence":3257976104,"time":"2018-01-22T15:14:07.487000Z"}
{"type":"open","side":"sell","price":"8840.69000000","order_id":"7df78783-cb80-456f-86f6-4aa80dcba419","remaining_size":"0.11241548","product_id":"BTC-EUR","sequence":3257976105,"time":"2018-01-22T15:14:07.487000Z"}
{"type":"done","side":"sell","order_id":"417188ab-fe17-48f2-abb7-317074aa46f0","reason":"canceled","product_id":"BTC-EUR","price":"8933.91000000","remaining_size":"0.75000000","sequence":3257976106,"time":"2018-01-22T15:14:07.560000Z"}
{"type":"done","side":"buy","order_id":"3e2eac3d-673b-434e-8c14-372c6aace9a2","reason":"canceled","product_id":"BTC-EUR","price":"8800.91000000","remaining_size":"0.49000000","sequence":3257976107,"time":"2018-01-22T15:14:07.576000Z"}
{"type":"done","side":"sell","order_id":"b51ae6c6-267f-42d6-95f5-585af7890116","reason":"canceled","product_id":"BTC-EUR","price":"8840.81000000","remaining_size":"0.25000000","sequence":3257976108,"time":"2018-01-22T15:14:07.577000Z"}
{"type":"done","side":"sell","order_id":"16e2e8ac-5718-411c-bcbb-8bc92904cffa","reason":"canceled","product_id":"BTC-EUR","price":"8840.69000000","remaining_size":"0.04164971","sequence":3257976109,"time":"2018-01-22T15:14:07.581000Z"}
{"type":"done","side":"sell","order_id":"b2651c7a-be6c-4c7c-92e1-a3a66bfc2118","reason":"canceled","product_id":"BTC-EUR","price":"8840.69000000","remaining_size":"0.22947933","sequence":3257976110,"time":"2018-01-22T15:14:07.597000Z"}
{"type":"done","side":"sell","order_id":"7df5b462-3a30-4d55-9615-07eed0f53642","reason":"canceled","product_id":"BTC-EUR","price":"8840.69000000","remaining_size":"0.01887096","sequence":3257976111,"time":"2018-01-22T15:14:07.598000Z"}
{"type":"done","side":"sell","order_id":"7b2104ba-c3f7-435e-9201-6eed9f68c28b","reason":"canceled","product_id":"BTC-EUR","price":"9027.01000000","remaining_size":"0.75000000","sequence":3257976112,"time":"2018-01-22T15:14:07.606000Z"}
{"type":"done","side":"buy","order_id":"a1a9ecd7-9da7-4249-90da-e61b39b0e182","reason":"canceled","product_id":"BTC-EUR","price":"8707.81000000","remaining_size":"0.75000000","sequence":3257976113,"time":"2018-01-22T15:14:07.606000Z"}
{"type":"done","side":"sell","order_id":"ce8136e7-250f-4ee6-9487-14e0eb27177e","reason":"canceled","product_id":"BTC-EUR","price":"9120.11000000","remaining_size":"0.75000000","sequence":3257976114,"time":"2018-01-22T15:14:07.612000Z"}
{"type":"done","side":"buy","order_id":"5601ecc1-3a17-49e4-841e-31e07cc4daa6","reason":"canceled","product_id":"BTC-EUR","price":"8614.71000000","remaining_size":"0.75000000","sequence":3257976115,"time":"2018-01-22T15:14:07.612000Z"}
{"type":"done","side":"sell","order_id":"bf44f084-e901-401d-9c0b-ab33a9b931f2","reason":"canceled","product_id":"BTC-EUR","price":"9213.21000000","remaining_size":"0.74000000","sequence":3257976116,"time":"2018-01-22T15:14:07.630000Z"}
{"type":"done","side":"buy","order_id":"0f81dfe3-97b9-455d-84c6-ceb65e1a4586","reason":"canceled","product_id":"BTC-EUR","price":"8521.61000000","remaining_size":"0.74000000","sequence":3257976117,"time":"2018-01-22T15:14:07.630000Z"}
{"type":"done","side":"sell","order_id":"4ff215f4-a2aa-4cd1-8c94-048bb56b7c12","reason":"canceled","product_id":"BTC-EUR","price":"9306.31000000","remaining_size":"0.75000000","sequence":3257976118,"time":"2018-01-22T15:14:07.633000Z"}
{"type":"done","side":"buy","order_id":"8715712b-830a-4ae8-a4b7-7a29a5d30153","reason":"canceled","product_id":"BTC-EUR","price":"8428.51000000","remaining_size":"0.75000000","sequence":3257976119,"time":"2018-01-22T15:14:07.634000Z"}
{"type":"done","side":"sell","order_id":"7489099b-5df3-4f3f-953a-3d5a2b83f633","reason":"canceled","product_id":"BTC-EUR","price":"9399.41000000","remaining_size":"0.75000000","sequence":3257976120,"time":"2018-01-22T15:14:07.639000Z"}
{"type":"done","side":"buy","order_id":"08a2b3e8-ff27-4617-8a71-f228361857b2","reason":"canceled","product_id":"BTC-EUR","price":"8335.41000000","remaining_size":"0.75000000","sequence":3257976121,"time":"2018-01-22T15:14:07.639000Z"}
{"type":"done","side":"sell","order_id":"6e92c044-88c7-4bdb-9c4d-75c8513cf206","reason":"canceled","product_id":"BTC-EUR","price":"9492.51000000","remaining_size":"0.75000000","sequence":3257976122,"time":"2018-01-22T15:14:07.642000Z"}
{"type":"done","side":"buy","order_id":"4fef1995-fe83-41ac-869a-a82b087dba44","reason":"canceled","product_id":"BTC-EUR","price":"8242.31000000","remaining_size":"0.75000000","sequence":3257976123,"time":"2018-01-22T15:14:07.642000Z"}
{"type":"done","side":"sell","order_id":"d2495dcd-1987-43fb-99e1-eb06a621ff1c","reason":"canceled","product_id":"BTC-EUR","price":"9585.61000000","remaining_size":"0.74000000","sequence":3257976124,"time":"2018-01-22T15:14:07.644000Z"}
{"type":"done","side":"buy","order_id":"089908ee-8e65-4cb9-825e-6b57ada0bbb8","reason":"canceled","product_id":"BTC-EUR","price":"8149.21000000","remaining_size":"0.74000000","sequence":3257976125,"time":"2018-01-22T15:14:07.644000Z"}
{"type":"done","side":"sell","order_id":"9ff7a5fa-3a8a-4c77-ac6f-f76025721715","reason":"canceled","product_id":"BTC-EUR","price":"9678.71000000","remaining_size":"0.75000000","sequence":3257976126,"time":"2018-01-22T15:14:07.649000Z"}
{"type":"done","side":"buy","order_id":"7c918ce7-72e3-415c-9ea9-b3f47d204f00","reason":"canceled","product_id":"BTC-EUR","price":"8056.11000000","remaining_size":"0.75000000","sequence":3257976127,"time":"2018-01-22T15:14:07.649000Z"}
{"type":"done","side":"sell","order_id":"efa6c7fe-900a-4de7-aaed-c1b36fa52aca","reason":"canceled","product_id":"BTC-EUR","price":"9771.81000000","remaining_size":"0.75000000","sequence":3257976128,"time":"2018-01-22T15:14:07.699000Z"}
{"type":"done","side":"buy","order_id":"2203a936-459a-48bc-a332-38e058db9928","reason":"canceled","product_id":"BTC-EUR","price":"7963.01000000","remaining_size":"0.75000000","sequence":3257976129,"time":"2018-01-22T15:14:07.699000Z"}
{"type":"received","order_id":"7cc8be83-c4ef-4b5b-a66d-da6bac96b843","order_type":"limit","size":"0.75000000","price":"8715.98000000","side":"buy","client_oid":"e82df437-a90f-43d9-80c7-07ecf72cdf26","product_id":"BTC-EUR","sequence":3257976130,"time":"2018-01-22T15:14:07.717000Z"}
{"type":"open","side":"buy","price":"8715.98000000","order_id":"7cc8be83-c4ef-4b5b-a66d-da6bac96b843","remaining_size":"0.75000000","product_id":"BTC-EUR","sequence":3257976131,"time":"2018-01-22T15:14:07.717000Z"}
{"type":"received","order_id":"9043b29a-4415-408e-a077-0dff2b3aa277","order_type":"limit","size":"0.49000000","price":"8809.08000000","side":"buy","client_oid":"b689125e-178c-4fb7-809a-f0c81ef60f2d","product_id":"BTC-EUR","sequence":3257976132,"time":"2018-01-22T15:14:07.717000Z"}
{"type":"open","side":"buy","price":"8809.08000000","order_id":"9043b29a-4415-408e-a077-0dff2b3aa277","remaining_size":"0.49000000","product_id":"BTC-EUR","sequence":3257976133,"time":"2018-01-22T15:14:07.717000Z"}
{"type":"received","order_id":"931d3586-0630-4c77-b680-10bc11484075","order_type":"limit","size":"0.25000000","price":"8848.98000000","side":"sell","client_oid":"d8c4b7a2-472d-4067-aa85-869c3ca22c31","product_id":"BTC-EUR","sequence":3257976134,"time":"2018-01-22T15:14:07.727000Z"}
{"type":"open","side":"sell","price":"8848.98000000","order_id":"931d3586-0630-4c77-b680-10bc11484075","remaining_size":"0.25000000","product_id":"BTC-EUR","sequence":3257976135,"time":"2018-01-22T15:14:07.727000Z"}
{"type":"received","order_id":"f9a9b095-1a8a-43f6-a17b-943f87658ed8","order_type":"limit","size":"0.75000000","price":"8942.08000000","side":"sell","client_oid":"b898f2f6-053c-43aa-822e-91ae84f7e20e","product_id":"BTC-EUR","sequence":3257976136,"time":"2018-01-22T15:14:07.728000Z"}
{"type":"open","side":"sell","price":"8942.08000000","order_id":"f9a9b095-1a8a-43f6-a17b-943f87658ed8","remaining_size":"0.75000000","product_id":"BTC-EUR","sequence":3257976137,"time":"2018-01-22T15:14:07.728000Z"}
{"type":"received","order_id":"8fe33ee5-135b-426e-afcc-bdb6e57ceec2","order_type":"limit","size":"0.25000000","price":"8566.73000000","side":"sell","product_id":"BTC-EUR","sequence":3257976138,"time":"2018-01-22T15:14:07.728000Z"}
{"type":"match","trade_id":10551295,"maker_order_id":"0f1e674c-f323-491c-aa6a-8dcad840dae3","taker_order_id":"8fe33ee5-135b-426e-afcc-bdb6e57ceec2","side":"buy","size":"0.03000000","price":"8831.68000000","product_id":"BTC-EUR","sequence":3257976139,"time":"2018-01-22T15:14:07.728000Z"}
{"type":"done","side":"buy","order_id":"0f1e674c-f323-491c-aa6a-8dcad840dae3","reason":"filled","product_id":"BTC-EUR","price":"8831.68000000","remaining_size":"0","sequence":3257976140,"time":"2018-01-22T15:14:07.728000Z"}
{"type":"match","trade_id":10551296,"maker_order_id":"bdf0cb95-d508-4539-9a23-4cd409adc998","taker_order_id":"8fe33ee5-135b-426e-afcc-bdb6e57ceec2","side":"buy","size":"0.22000000","price":"8831.68000000","product_id":"BTC-EUR","sequence":3257976141,"time":"2018-01-22T15:14:07.728000Z"}
{"type":"done","side":"sell","order_id":"8fe33ee5-135b-426e-afcc-bdb6e57ceec2","reason":"filled","product_id":"BTC-EUR","price":"8566.73000000","remaining_size":"0.00000000","sequence":3257976142,"time":"2018-01-22T15:14:07.728000Z"}
{"type":"received","order_id":"40c6bf20-1367-4777-9959-c2ea160807c0","order_type":"limit","size":"0.75000000","price":"9035.18000000","side":"sell","client_oid":"caf902ae-83d3-44fa-ab9a-25593e060416","product_id":"BTC-EUR","sequence":3257976143,"time":"2018-01-22T15:14:07.729000Z"}
{"type":"open","side":"sell","price":"9035.18000000","order_id":"40c6bf20-1367-4777-9959-c2ea160807c0","remaining_size":"0.75000000","product_id":"BTC-EUR","sequence":3257976144,"time":"2018-01-22T15:14:07.729000Z"}
{"type":"received","order_id":"41c656ab-8e50-41e5-a38b-20bb05c50ca1","order_type":"limit","size":"0.74000000","price":"8529.78000000","side":"buy","client_oid":"b972bc76-b232-49d2-bf1c-8edbc2e9c6fd","product_id":"BTC-EUR","sequence":3257976145,"time":"2018-01-22T15:14:07.729000Z"}
{"type":"open","side":"buy","price":"8529.78000000","order_id":"41c656ab-8e50-41e5-a38b-20bb05c50ca1","remaining_size":"0.74000000","product_id":"BTC-EUR","sequence":3257976146,"time":"2018-01-22T15:14:07.729000Z"}
{"type":"received","order_id":"f6de811d-eae6-42a7-a2d3-42af372d348d","order_type":"limit","size":"0.75000000","price":"8622.88000000","side":"buy","client_oid":"51264389-0d5c-4f0d-a180-d04723d8200e","product_id":"BTC-EUR","sequence":3257976147,"time":"2018-01-22T15:14:07.731000Z"}
{"type":"open","side":"buy","price":"8622.88000000","order_id":"f6de811d-eae6-42a7-a2d3-42af372d348d","remaining_size":"0.75000000","product_id":"BTC-EUR","sequence":3257976148,"time":"2018-01-22T15:14:07.731000Z"}
{"type":"received","order_id":"0b19a0b4-6496-462b-b2f3-e28cf214da65","order_type":"limit","size":"0.75000000","price":"9500.68000000","side":"sell","client_oid":"35d1ca71-6f93-41dd-a443-81ec072d3766","product_id":"BTC-EUR","sequence":3257976149,"time":"2018-01-22T15:14:07.764000Z"}
{"type":"open","side":"sell","price":"9500.68000000","order_id":"0b19a0b4-6496-462b-b2f3-e28cf214da65","remaining_size":"0.75000000","product_id":"BTC-EUR","sequence":3257976150,"time":"2018-01-22T15:14:07.764000Z"}
{"type":"done","side":"sell","order_id":"dab2423b-d5a7-4bc2-b6e8-7547c449d14d","reason":"canceled","product_id":"BTC-EUR","price":"9381.64000000","remaining_size":"0.01053237","sequence":3257976151,"time":"2018-01-22T15:14:07.764000Z"}
{"type":"received","order_id":"d64f16b5-547f-4cbc-a29b-34e2f3f5ca43","order_type":"limit","size":"0.75000000","price":"9407.58000000","side":"sell","client_oid":"9ddf6d05-4a61-456d-8d39-48f643a10c8b","product_id":"BTC-EUR","sequence":3257976152,"time":"2018-01-22T15:14:07.766000Z"}
{"type":"open","side":"sell","price":"9407.58000000","order_id":"d64f16b5-547f-4cbc-a29b-34e2f3f5ca43","remaining_size":"0.75000000","product_id":"BTC-EUR","sequence":3257976153,"time":"2018-01-22T15:14:07.766000Z"}
{"type":"received","order_id":"68691ec4-3a4f-4806-9b11-a255cf24d8ae","order_type":"limit","size":"0.75000000","price":"8250.48000000","side":"buy","client_oid":"eab9e993-c29c-4398-a5fe-ee34681e343e","product_id":"BTC-EUR","sequence":3257976154,"time":"2018-01-22T15:14:07.772000Z"}
{"type":"open","side":"buy","price":"8250.48000000","order_id":"68691ec4-3a4f-4806-9b11-a255cf24d8ae","remaining_size":"0.75000000","product_id":"BTC-EUR","sequence":3257976155,"time":"2018-01-22T15:14:07.772000Z"}
{"type":"received","order_id":"c15c8057-2997-44d9-b573-bfd4edf75713","order_type":"limit","size":"0.74000000","price":"9593.78000000","side":"sell","client_oid":"15d26da7-a473-49ce-b232-388116bd1670","product_id":"BTC-EUR","sequence":3257976156,"time":"2018-01-22T15:14:07.778000Z"}
{"type":"open","side":"sell","price":"9593.78000000","order_id":"c15c8057-2997-44d9-b573-bfd4edf75713","remaining_size":"0.74000000","product_id":"BTC-EUR","sequence":3257976157,"time":"2018-01-22T15:14:07.778000Z"}
{"type":"received","order_id":"e3a30845-3b24-4cb5-a933-59ac0ba38ef3","order_type":"limit","size":"0.75000000","price":"8343.58000000","side":"buy","client_oid":"0c484c9b-b0f1-45ad-851b-ee3e8b8de793","product_id":"BTC-EUR","sequence":3257976158,"time":"2018-01-22T15:14:07.783000Z"}
{"type":"open","side":"buy","price":"8343.58000000","order_id":"e3a30845-3b24-4cb5-a933-59ac0ba38ef3","remaining_size":"0.75000000","product_id":"BTC-EUR","sequence":3257976159,"time":"2018-01-22T15:14:07.783000Z"}
{"type":"received","order_id":"ced8d7f8-aa27-4828-b260-89cb9e9bb6c8","order_type":"limit","size":"0.75000000","price":"8064.28000000","side":"buy","client_oid":"b8d6be66-3721-4dc4-ad68-2af6f8ef5980","product_id":"BTC-EUR","sequence":3257976160,"time":"2018-01-22T15:14:07.818000Z"}
{"type":"open","side":"buy","price":"8064.28000000","order_id":"ced8d7f8-aa27-4828-b260-89cb9e9bb6c8","remaining_size":"0.75000000","product_id":"BTC-EUR","sequence":3257976161,"time":"2018-01-22T15:14:07.818000Z"}
{"type":"received","order_id":"957cc3b8-cff1-4d3e-a37c-bdbd6de9127d","order_type":"limit","size":"0.75000000","price":"8436.68000000","side":"buy","client_oid":"f0ede38f-9e5d-48b4-b76e-1f01495c1303","product_id":"BTC-EUR","sequence":3257976162,"time":"2018-01-22T15:14:07.827000Z"}
{"type":"open","side":"buy","price":"8436.68000000","order_id":"957cc3b8-cff1-4d3e-a37c-bdbd6de9127d","remaining_size":"0.75000000","product_id":"BTC-EUR","sequence":3257976163,"time":"2018-01-22T15:14:07.827000Z"}
{"type":"received","order_id":"300b8967-8749-4b2c-99d2-15ab3f7101c3","order_type":"limit","size":"0.03773580","price":"8896.52000000","side":"sell","client_oid":"9f3bb9d4-b947-4d2f-945d-8fa7a6881863","product_id":"BTC-EUR","sequence":3257976164,"time":"2018-01-22T15:14:07.828000Z"}
{"type":"open","side":"sell","price":"8896.52000000","order_id":"300b8967-8749-4b2c-99d2-15ab3f7101c3","remaining_size":"0.03773580","product_id":"BTC-EUR","sequence":3257976165,"time":"2018-01-22T15:14:07.828000Z"}
{"type":"received","order_id":"c01fbb85-939a-4a17-abdc-cfc2e6dcefc1","order_type":"limit","size":"0.75000000","price":"9779.98000000","side":"sell","client_oid":"88b304a1-a84b-49f8-83fb-3a149f0bb219","product_id":"BTC-EUR","sequence":3257976166,"time":"2018-01-22T15:14:07.832000Z"}
{"type":"open","side":"sell","price":"9779.98000000","order_id":"c01fbb85-939a-4a17-abdc-cfc2e6dcefc1","remaining_size":"0.75000000","product_id":"BTC-EUR","sequence":3257976167,"time":"2018-01-22T15:14:07.832000Z"}
{"type":"received","order_id":"e3e72b30-dcc7-40a8-ad4b-7f43af324571","order_type":"limit","size":"0.74000000","price":"8157.38000000","side":"buy","client_oid":"417d8293-305c-421e-a7ba-fcd513a037d4","product_id":"BTC-EUR","sequence":3257976168,"time":"2018-01-22T15:14:07.841000Z"}
{"type":"open","side":"buy","price":"8157.38000000","order_id":"e3e72b30-dcc7-40a8-ad4b-7f43af324571","remaining_size":"0.74000000","product_id":"BTC-EUR","sequence":3257976169,"time":"2018-01-22T15:14:07.841000Z"}
{"type":"received","order_id":"de0d0715-5c90-4c4a-b0d9-69072437695f","order_type":"limit","size":"0.75000000","price":"9686.88000000","side":"sell","client_oid":"4ee06392-9c21-4ff5-bab5-b629f01341a7","product_id":"BTC-EUR","sequence":3257976170,"time":"2018-01-22T15:14:07.847000Z"}
{"type":"open","side":"sell","price":"9686.88000000","order_id":"de0d0715-5c90-4c4a-b0d9-69072437695f","remaining_size":"0.75000000","product_id":"BTC-EUR","sequence":3257976171,"time":"2018-01-22T15:14:07.847000Z"}
{"type":"received","order_id":"2680a845-f17c-44b0-82e0-5d6c32b66800","order_type":"limit","size":"0.22947933","price":"8849.98000000","side":"sell","client_oid":"3a15840d-dde3-4487-b27d-51454d5ff11c","product_id":"BTC-EUR","sequence":3257976172,"time":"2018-01-22T15:14:07.849000Z"}
{"type":"open","side":"sell","price":"8849.98000000","order_id":"2680a845-f17c-44b0-82e0-5d6c32b66800","remaining_size":"0.22947933","product_id":"BTC-EUR","sequence":3257976173,"time":"2018-01-22T15:14:07.849000Z"}
{"type":"received","order_id":"070365a5-193c-4c60-89c6-26e6c034ee66","order_type":"limit","size":"0.75000000","price":"7971.18000000","side":"buy","client_oid":"0475a1c9-8828-4ade-93a3-c231aaa05331","product_id":"BTC-EUR","sequence":3257976174,"time":"2018-01-22T15:14:07.851000Z"}
{"type":"open","side":"buy","price":"7971.18000000","order_id":"070365a5-193c-4c60-89c6-26e6c034ee66","remaining_size":"0.75000000","product_id":"BTC-EUR","sequence":3257976175,"time":"2018-01-22T15:14:07.851000Z"}
{"type":"received","order_id":"52bf988b-ea5a-4777-8803-bbbcf483efe3","order_type":"limit","size":"0.04164971","price":"8849.98000000","side":"sell","client_oid":"bb3f240d-4e1a-4a57-a7ac-e92333005006","product_id":"BTC-EUR","sequence":3257976176,"time":"2018-01-22T15:14:07.855000Z"}
{"type":"open","side":"sell","price":"8849.98000000","order_id":"52bf988b-ea5a-4777-8803-bbbcf483efe3","remaining_size":"0.04164971","product_id":"BTC-EUR","sequence":3257976177,"time":"2018-01-22T15:14:07.855000Z"}
{"type":"received","order_id":"a0aea396-0842-43d0-9db8-96f5799246fb","order_type":"limit","size":"0.75000000","price":"9128.28000000","side":"sell","client_oid":"dfcc4ee0-1881-43e8-a97c-9f14d6e37e81","product_id":"BTC-EUR","sequence":3257976178,"time":"2018-01-22T15:14:07.857000Z"}
{"type":"open","side":"sell","price":"9128.28000000","order_id":"a0aea396-0842-43d0-9db8-96f5799246fb","remaining_size":"0.75000000","product_id":"BTC-EUR","sequence":3257976179,"time":"2018-01-22T15:14:07.857000Z"}
{"type":"received","order_id":"95ccd9d5-4671-4d4e-9de2-9766a73c1552","order_type":"limit","size":"0.01887096","price":"8849.98000000","side":"sell","client_oid":"86d439fc-0855-4b26-98f1-c50070e00e50","product_id":"BTC-EUR","sequence":3257976180,"time":"2018-01-22T15:14:07.867000Z"}
{"type":"open","side":"sell","price":"8849.98000000","order_id":"95ccd9d5-4671-4d4e-9de2-9766a73c1552","remaining_size":"0.01887096","product_id":"BTC-EUR","sequence":3257976181,"time":"2018-01-22T15:14:07.867000Z"}
{"type":"received","order_id":"2ae75d32-e4e7-4f22-b431-d943179827c9","order_type":"limit","size":"0.74000000","price":"9221.38000000","side":"sell","client_oid":"949f4922-7826-48dd-b052-661c3ea76fb5","product_id":"BTC-EUR","sequence":3257976182,"time":"2018-01-22T15:14:07.871000Z"}
{"type":"open","side":"sell","price":"9221.38000000","order_id":"2ae75d32-e4e7-4f22-b431-d943179827c9","remaining_size":"0.74000000","product_id":"BTC-EUR","sequence":3257976183,"time":"2018-01-22T15:14:07.871000Z"}
{"type":"received","order_id":"d1c3c9e6-57af-4569-9f04-b848c0e330f5","order_type":"limit","size":"0.75000000","price":"9314.48000000","side":"sell","client_oid":"aee52cbb-3c70-4ecd-ac90-09411a200699","product_id":"BTC-EUR","sequence":3257976184,"time":"2018-01-22T15:14:07.879000Z"}
{"type":"open","side":"sell","price":"9314.48000000","order_id":"d1c3c9e6-57af-4569-9f04-b848c0e330f5","remaining_size":"0.75000000","product_id":"BTC-EUR","sequence":3257976185,"time":"2018-01-22T15:14:07.879000Z"}
{"type":"received","order_id":"ac47d3b9-640c-493a-87f2-92638a1d1e1f","order_type":"limit","size":"1.28000000","price":"9113.57000000","side":"sell","product_id":"BTC-EUR","sequence":3257976186,"time":"2018-01-22T15:14:08.231000Z"}
{"type":"open","side":"sell","price":"9113.57000000","order_id":"ac47d3b9-640c-493a-87f2-92638a1d1e1f","remaining_size":"1.28000000","product_id":"BTC-EUR","sequence":3257976187,"time":"2018-01-22T15:14:08.231000Z"}
{"type":"received","order_id":"923309da-8e14-41b4-b8ac-c427b80a08c3","order_type":"limit","size":"0.08000000","price":"8566.73000000","side":"sell","product_id":"BTC-EUR","sequence":3257976188,"time":"2018-01-22T15:14:08.390000Z"}
{"type":"match","trade_id":10551297,"maker_order_id":"bdf0cb95-d508-4539-9a23-4cd409adc998","taker_order_id":"923309da-8e14-41b4-b8ac-c427b80a08c3","side":"buy","size":"0.08000000","price":"8831.68000000","product_id":"BTC-EUR","sequence":3257976189,"time":"2018-01-22T15:14:08.390000Z"}
{"type":"done","side":"sell","order_id":"923309da-8e14-41b4-b8ac-c427b80a08c3","reason":"filled","product_id":"BTC-EUR","price":"8566.73000000","remaining_size":"0.00000000","sequence":3257976190,"time":"2018-01-22T15:14:08.390000Z"}
{"type":"done","side":"buy","order_id":"5906ea00-32a0-4d1c-8588-d4066c4804f2","reason":"canceled","product_id":"BTC-EUR","price":"8831.68000000","remaining_size":"1.74686126","sequence":3257976191,"time":"2018-01-22T15:14:08.526000Z"}
{"type":"done","side":"sell","order_id":"95ccd9d5-4671-4d4e-9de2-9766a73c1552","reason":"canceled","product_id":"BTC-EUR","price":"8849.98000000","remaining_size":"0.01887096","sequence":3257976192,"time":"2018-01-22T15:14:08.576000Z"}
{"type":"done","side":"sell","order_id":"52bf988b-ea5a-4777-8803-bbbcf483efe3","reason":"canceled","product_id":"BTC-EUR","price":"8849.98000000","remaining_size":"0.04164971","sequence":3257976193,"time":"2018-01-22T15:14:08.580000Z"}
{"type":"done","side":"sell","order_id":"7df78783-cb80-456f-86f6-4aa80dcba419","reason":"canceled","product_id":"BTC-EUR","price":"8840.69000000","remaining_size":"0.11241548","sequence":3257976194,"time":"2018-01-22T15:14:08.585000Z"}
{"type":"done","side":"sell","order_id":"2680a845-f17c-44b0-82e0-5d6c32b66800","reason":"canceled","product_id":"BTC-EUR","price":"8849.98000000","remaining_size":"0.22947933","sequence":3257976195,"time":"2018-01-22T15:14:08.595000Z"}
{"type":"received","order_id":"70f475c2-062e-4c9f-aaff-e5896c641502","order_type":"limit","size":"0.01000000","price":"9096.64000000","side":"buy","product_id":"BTC-EUR","sequence":3257976196,"time":"2018-01-22T15:14:08.606000Z"}
{"type":"match","trade_id":10551298,"maker_order_id":"3a9a3ec7-92be-49d3-8bc8-06901765e0fb","taker_order_id":"70f475c2-062e-4c9f-aaff-e5896c641502","side":"sell","size":"0.01000000","price":"8831.69000000","product_id":"BTC-EUR","sequence":3257976197,"time":"2018-01-22T15:14:08.606000Z"}
{"type":"done","side":"buy","order_id":"70f475c2-062e-4c9f-aaff-e5896c641502","reason":"filled","product_id":"BTC-EUR","price":"9096.64000000","remaining_size":"0.00000000","sequence":3257976198,"time":"2018-01-22T15:14:08.606000Z"}
{"type":"received","order_id":"a2c8e899-85ed-4322-be4c-d614bd5144ce","order_type":"limit","size":"0.11066184","price":"8831.70000000","side":"sell","client_oid":"07a949d1-578f-4424-d7ce-f46c63e2818e","product_id":"BTC-EUR","sequence":3257976199,"time":"2018-01-22T15:14:08.712000Z"}
{"type":"open","side":"sell","price":"8831.70000000","order_id":"a2c8e899-85ed-4322-be4c-d614bd5144ce","remaining_size":"0.11066184","product_id":"BTC-EUR","sequence":3257976200,"time":"2018-01-22T15:14:08.712000Z"}
{"type":"received","order_id":"6ba6dc77-a40e-4945-927e-28a353df095d","order_type":"limit","size":"0.11241548","price":"8848.98000000","side":"sell","product_id":"BTC-EUR","sequence":3257976201,"time":"2018-01-22T15:14:08.719000Z"}
{"type":"open","side":"sell","price":"8848.98000000","order_id":"6ba6dc77-a40e-4945-927e-28a353df095d","remaining_size":"0.11241548","product_id":"BTC-EUR","sequence":3257976202,"time":"2018-01-22T15:14:08.719000Z"}
{"type":"done","side":"buy","order_id":"d03a751b-6ab7-4410-876e-1acf886b2f6c","reason":"canceled","product_id":"BTC-EUR","price":"8651.70000000","remaining_size":"1.89593000","sequence":3257976203,"time":"2018-01-22T15:14:08.741000Z"}
{"type":"received","order_id":"da2eb988-c438-4b59-af9a-fbd30740e540","order_type":"limit","size":"1.89556000","price":"8655.10000000","side":"buy","client_oid":"c82e6e7b-2b62-4993-ac53-8d83f0c7e885","product_id":"BTC-EUR","sequence":3257976204,"time":"2018-01-22T15:14:08.790000Z"}
{"type":"open","side":"buy","price":"8655.10000000","order_id":"da2eb988-c438-4b59-af9a-fbd30740e540","remaining_size":"1.89556000","product_id":"BTC-EUR","sequence":3257976205,"time":"2018-01-22T15:14:08.790000Z"}
{"type":"received","order_id":"b5575220-34a8-4ce6-8dda-1081f8e3354b","order_type":"limit","size":"0.22947933","price":"8848.96000000","side":"sell","client_oid":"b736b082-f354-4301-b1cc-edee4f943858","product_id":"BTC-EUR","sequence":3257976206,"time":"2018-01-22T15:14:08.831000Z"}
{"type":"open","side":"sell","price":"8848.96000000","order_id":"b5575220-34a8-4ce6-8dda-1081f8e3354b","remaining_size":"0.22947933","product_id":"BTC-EUR","sequence":3257976207,"time":"2018-01-22T15:14:08.831000Z"}
{"type":"done","side":"sell","order_id":"f9a9b095-1a8a-43f6-a17b-943f87658ed8","reason":"canceled","product_id":"BTC-EUR","price":"8942.08000000","remaining_size":"0.75000000","sequence":3257976208,"time":"2018-01-22T15:14:08.835000Z"}
{"type":"received","order_id":"16e5c882-7025-4847-bfd2-2072c89d7ace","order_type":"limit","size":"0.04164971","price":"8848.96000000","side":"sell","client_oid":"1c781425-738f-48ad-b9dd-03372a8bbb13","product_id":"BTC-EUR","sequence":3257976209,"time":"2018-01-22T15:14:08.836000Z"}
{"type":"open","side":"sell","price":"8848.96000000","order_id":"16e5c882-7025-4847-bfd2-2072c89d7ace","remaining_size":"0.04164971","product_id":"BTC-EUR","sequence":3257976210,"time":"2018-01-22T15:14:08.836000Z"}
{"type":"done","side":"buy","order_id":"0695e531-6766-479b-8ffe-68062c05c702","reason":"canceled","product_id":"BTC-EUR","price":"8831.68000000","remaining_size":"0.06666600","sequence":3257976211,"time":"2018-01-22T15:14:08.850000Z"}
{"type":"received","order_id":"31d0977f-772b-4801-934d-1226b70ccca0","order_type":"limit","size":"0.01887096","price":"8848.96000000","side":"sell","client_oid":"7956c3fb-7ddd-4fc1-b04f-8d225d59d5a8","product_id":"BTC-EUR","sequence":3257976212,"time":"2018-01-22T15:14:08.852000Z"}
{"type":"open","side":"sell","price":"8848.96000000","order_id":"31d0977f-772b-4801-934d-1226b70ccca0","remaining_size":"0.01887096","product_id":"BTC-EUR","sequence":3257976213,"time":"2018-01-22T15:14:08.852000Z"}
{"type":"done","side":"buy","order_id":"9043b29a-4415-408e-a077-0dff2b3aa277","reason":"canceled","product_id":"BTC-EUR","price":"8809.08000000","remaining_size":"0.49000000","sequence":3257976214,"time":"2018-01-22T15:14:08.871000Z"}
{"type":"done","side":"sell","order_id":"931d3586-0630-4c77-b680-10bc11484075","reason":"canceled","product_id":"BTC-EUR","price":"8848.98000000","remaining_size":"0.25000000","sequence":3257976215,"time":"2018-01-22T15:14:08.872000Z"}
{"type":"received","order_id":"7f7c18e4-f20a-4b40-ae32-f4ff4512cc5c","order_type":"limit","size":"0.07034716","price":"8989.58000000","side":"sell","product_id":"BTC-EUR","sequence":3257976216,"time":"2018-01-22T15:14:08.884000Z"}
{"type":"open","side":"sell","price":"8989.58000000","order_id":"7f7c18e4-f20a-4b40-ae32-f4ff4512cc5c","remaining_size":"0.07034716","product_id":"BTC-EUR","sequence":3257976217,"time":"2018-01-22T15:14:08.884000Z"}
{"type":"done","side":"sell","order_id":"40c6bf20-1367-4777-9959-c2ea160807c0","reason":"canceled","product_id":"BTC-EUR","price":"9035.18000000","remaining_size":"0.75000000","sequence":3257976218,"time":"2018-01-22T15:14:08.893000Z"}
{"type":"done","side":"buy","order_id":"7cc8be83-c4ef-4b5b-a66d-da6bac96b843","reason":"canceled","product_id":"BTC-EUR","price":"8715.98000000","remaining_size":"0.75000000","sequence":3257976219,"time":"2018-01-22T15:14:08.893000Z"}
{"type":"done","side":"sell","order_id":"a0aea396-0842-43d0-9db8-96f5799246fb","reason":"canceled","product_id":"BTC-EUR","price":"9128.28000000","remaining_size":"0.75000000","sequence":3257976220,"time":"2018-01-22T15:14:08.896000Z"}
{"type":"done","side":"buy","order_id":"f6de811d-eae6-42a7-a2d3-42af372d348d","reason":"canceled","product_id":"BTC-EUR","price":"8622.88000000","remaining_size":"0.75000000","sequence":3257976221,"time":"2018-01-22T15:14:08.896000Z"}
{"type":"done","side":"sell","order_id":"2ae75d32-e4e7-4f22-b431-d943179827c9","reason":"canceled","product_id":"BTC-EUR","price":"9221.38000000","remaining_size":"0.74000000","sequence":3257976222,"time":"2018-01-22T15:14:08.899000Z"}
{"type":"done","side":"buy","order_id":"41c656ab-8e50-41e5-a38b-20bb05c50ca1","reason":"canceled","product_id":"BTC-EUR","price":"8529.78000000","remaining_size":"0.74000000","sequence":3257976223,"time":"2018-01-22T15:14:08.900000Z"}
{"type":"done","side":"sell","order_id":"d1c3c9e6-57af-4569-9f04-b848c0e330f5","reason":"canceled","product_id":"BTC-EUR","price":"9314.48000000","remaining_size":"0.75000000","sequence":3257976224,"time":"2018-01-22T15:14:08.901000Z"}
{"type":"done","side":"buy","order_id":"957cc3b8-cff1-4d3e-a37c-bdbd6de9127d","reason":"canceled","product_id":"BTC-EUR","price":"8436.68000000","remaining_size":"0.75000000","sequence":3257976225,"time":"2018-01-22T15:14:08.902000Z"}
{"type":"done","side":"sell","order_id":"d64f16b5-547f-4cbc-a29b-34e2f3f5ca43","reason":"canceled","product_id":"BTC-EUR","price":"9407.58000000","remaining_size":"0.75000000","sequence":3257976226,"time":"2018-01-22T15:14:08.903000Z"}
{"type":"done","side":"buy","order_id":"e3a30845-3b24-4cb5-a933-59ac0ba38ef3","reason":"canceled","product_id":"BTC-EUR","price":"8343.58000000","remaining_size":"0.75000000","sequence":3257976227,"time":"2018-01-22T15:14:08.904000Z"}
{"type":"done","side":"sell","order_id":"0b19a0b4-6496-462b-b2f3-e28cf214da65","reason":"canceled","product_id":"BTC-EUR","price":"9500.68000000","remaining_size":"0.75000000","sequence":3257976228,"time":"2018-01-22T15:14:08.919000Z"}
{"type":"done","side":"buy","order_id":"68691ec4-3a4f-4806-9b11-a255cf24d8ae","reason":"canceled","product_id":"BTC-EUR","price":"8250.48000000","remaining_size":"0.75000000","sequence":3257976229,"time":"2018-01-22T15:14:08.920000Z"}
{"type":"done","side":"sell","order_id":"c15c8057-2997-44d9-b573-bfd4edf75713","reason":"canceled","product_id":"BTC-EUR","price":"9593.78000000","remaining_size":"0.74000000","sequence":3257976230,"time":"2018-01-22T15:14:08.982000Z"}
{"type":"done","side":"buy","order_id":"e3e72b30-dcc7-40a8-ad4b-7f43af324571","reason":"canceled","product_id":"BTC-EUR","price":"8157.38000000","remaining_size":"0.74000000","sequence":3257976231,"time":"2018-01-22T15:14:08.983000Z"}
{"type":"done","side":"sell","order_id":"ab55b677-1922-438f-b562-40f7589f69ce","reason":"canceled","product_id":"BTC-EUR","price":"8867.00000000","remaining_size":"0.06675000","sequence":3257976232,"time":"2018-01-22T15:14:08.994000Z"}
{"type":"received","order_id":"5843834d-bb30-4e5f-a170-090771e97d5c","order_type":"limit","size":"0.05546048","price":"7894.22000000","side":"buy","product_id":"BTC-EUR","sequence":3257976233,"time":"2018-01-22T15:14:08.994000Z"}
{"type":"open","side":"buy","price":"7894.22000000","order_id":"5843834d-bb30-4e5f-a170-090771e97d5c","remaining_size":"0.05546048","product_id":"BTC-EUR","sequence":3257976234,"time":"2018-01-22T15:14:08.994000Z"}
{"type":"done","side":"sell","order_id":"de0d0715-5c90-4c4a-b0d9-69072437695f","reason":"canceled","product_id":"BTC-EUR","price":"9686.88000000","remaining_size":"0.75000000","sequence":3257976235,"time":"2018-01-22T15:14:08.996000Z"}
{"type":"done","side":"buy","order_id":"ced8d7f8-aa27-4828-b260-89cb9e9bb6c8","reason":"canceled","product_id":"BTC-EUR","price":"8064.28000000","remaining_size":"0.75000000","sequence":3257976236,"time":"2018-01-22T15:14:08.996000Z"}
{"type":"done","side":"sell","order_id":"c01fbb85-939a-4a17-abdc-cfc2e6dcefc1","reason":"canceled","product_id":"BTC-EUR","price":"9779.98000000","remaining_size":"0.75000000","sequence":3257976237,"time":"2018-01-22T15:14:09.000000Z"}
{"type":"done","side":"buy","order_id":"070365a5-193c-4c60-89c6-26e6c034ee66","reason":"canceled","product_id":"BTC-EUR","price":"7971.18000000","remaining_size":"0.75000000","sequence":3257976238,"time":"2018-01-22T15:14:09.000000Z"}
{"type":"received","order_id":"37232213-e973-4424-a272-9653af5bb188","order_type":"limit","size":"0.75000000","price":"8950.33000000","side":"sell","client_oid":"51ed5d2a-de8e-4640-a968-ec87bdac6004","product_id":"BTC-EUR","sequence":3257976239,"time":"2018-01-22T15:14:09.003000Z"}
{"type":"open","side":"sell","price":"8950.33000000","order_id":"37232213-e973-4424-a272-9653af5bb188","remaining_size":"0.75000000","product_id":"BTC-EUR","sequence":3257976240,"time":"2018-01-22T15:14:09.003000Z"}
{"type":"done","side":"buy","order_id":"b603256b-6fb8-4cb7-b2f5-b0459beb139d","reason":"canceled","product_id":"BTC-EUR","price":"8831.68000000","remaining_size":"0.10500000","sequence":3257976241,"time":"2018-01-22T15:14:09.003000Z"}
{"type":"received","order_id":"669c18e4-47e6-4588-9c53-e6d53d3369bb","order_type":"limit","size":"0.25000000","price":"8857.13000000","side":"sell","client_oid":"4060ffdb-a128-4b2a-84e7-38757f7eb4fa","product_id":"BTC-EUR","sequence":3257976242,"time":"2018-01-22T15:14:09.008000Z"}
{"type":"open","side":"sell","price":"8857.13000000","order_id":"669c18e4-47e6-4588-9c53-e6d53d3369bb","remaining_size":"0.25000000","product_id":"BTC-EUR","sequence":3257976243,"time":"2018-01-22T15:14:09.008000Z"}
{"type":"received","order_id":"ac35fcfc-5d7f-451d-a6e1-d56734151d99","order_type":"limit","size":"0.49000000","price":"8817.13000000","side":"buy","client_oid":"121b0766-6e70-4ca0-a031-503e7b7d5147","product_id":"BTC-EUR","sequence":3257976244,"time":"2018-01-22T15:14:09.008000Z"}
{"type":"open","side":"buy","price":"8817.13000000","order_id":"ac35fcfc-5d7f-451d-a6e1-d56734151d99","remaining_size":"0.49000000","product_id":"BTC-EUR","sequence":3257976245,"time":"2018-01-22T15:14:09.008000Z"}
{"type":"received","order_id":"60d40d82-f537-496d-b43e-ccc481e4eca8","order_type":"limit","size":"0.75000000","price":"8723.93000000","side":"buy","client_oid":"45a453d2-106a-40cc-b6b0-76746830af9c","product_id":"BTC-EUR","sequence":3257976246,"time":"2018-01-22T15:14:09.009000Z"}
{"type":"open","side":"buy","price":"8723.93000000","order_id":"60d40d82-f537-496d-b43e-ccc481e4eca8","remaining_size":"0.75000000","product_id":"BTC-EUR","sequence":3257976247,"time":"2018-01-22T15:14:09.009000Z"}
{"type":"received","order_id":"129886db-fd89-4921-a5fe-2a8b1775963b","order_type":"limit","size":"0.74000000","price":"9229.93000000","side":"sell","client_oid":"9c974a8f-5b0f-4f98-b6e7-e42e38417e51","product_id":"BTC-EUR","sequence":3257976248,"time":"2018-01-22T15:14:09.009000Z"}
{"type":"open","side":"sell","price":"9229.93000000","order_id":"129886db-fd89-4921-a5fe-2a8b1775963b","remaining_size":"0.74000000","product_id":"BTC-EUR","sequence":3257976249,"time":"2018-01-22T15:14:09.009000Z"}
{"type":"received","order_id":"c150932e-c05d-4893-aa20-273f73460b66","order_type":"limit","size":"0.75000000","price":"9136.73000000","side":"sell","client_oid":"6a4c370e-a4cf-4ea1-ad5f-398b7efb6062","product_id":"BTC-EUR","sequence":3257976250,"time":"2018-01-22T15:14:09.010000Z"}
{"type":"open","side":"sell","price":"9136.73000000","order_id":"c150932e-c05d-4893-aa20-273f73460b66","remaining_size":"0.75000000","product_id":"BTC-EUR","sequence":3257976251,"time":"2018-01-22T15:14:09.010000Z"}
{"type":"received","order_id":"4bc33569-f500-48aa-9408-e978ea24890b","order_type":"limit","size":"0.75000000","price":"9323.13000000","side":"sell","client_oid":"927e708e-8437-4147-af73-8c8bd73638ae","product_id":"BTC-EUR","sequence":3257976252,"time":"2018-01-22T15:14:09.012000Z"}
{"type":"open","side":"sell","price":"9323.13000000","order_id":"4bc33569-f500-48aa-9408-e978ea24890b","remaining_size":"0.75000000","product_id":"BTC-EUR","sequence":3257976253,"time":"2018-01-22T15:14:09.012000Z"}
{"type":"done","side":"buy","order_id":"3e1b13f3-ace6-4558-b51b-4dbd8d4a103c","reason":"canceled","product_id":"BTC-EUR","price":"8831.68000000","remaining_size":"0.10500000","sequence":3257976254,"time":"2018-01-22T15:14:09.017000Z"}
{"type":"done","side":"buy","order_id":"c4568e72-3eb0-435e-8445-d59c5c6d9b24","reason":"canceled","product_id":"BTC-EUR","price":"8831.68000000","remaining_size":"0.10500000","sequence":3257976255,"time":"2018-01-22T15:14:09.017000Z"}
{"type":"received","order_id":"e25e2b16-2d0e-41c9-8446-f717a418eb51","order_type":"limit","size":"0.75000000","price":"8630.73000000","side":"buy","client_oid":"1b082b0a-c53d-4a4e-9f12-5d0d04f81974","product_id":"BTC-EUR","sequence":3257976256,"time":"2018-01-22T15:14:09.019000Z"}
{"type":"open","side":"buy","price":"8630.73000000","order_id":"e25e2b16-2d0e-41c9-8446-f717a418eb51","remaining_size":"0.75000000","product_id":"BTC-EUR","sequence":3257976257,"time":"2018-01-22T15:14:09.019000Z"}
{"type":"received","order_id":"063628ca-eb70-40f1-9605-d86071c5cd88","order_type":"limit","size":"0.74000000","price":"8537.53000000","side":"buy","client_oid":"c1c396cd-85df-4202-9037-1927a91469bc","product_id":"BTC-EUR","sequence":3257976258,"time":"2018-01-22T15:14:09.038000Z"}
{"type":"open","side":"buy","price":"8537.53000000","order_id":"063628ca-eb70-40f1-9605-d86071c5cd88","remaining_size":"0.74000000","product_id":"BTC-EUR","sequence":3257976259,"time":"2018-01-22T15:14:09.038000Z"}
{"type":"received","order_id":"ef94e42c-bd88-456d-ae2c-d3903a85307c","order_type":"limit","size":"0.75000000","price":"8444.33000000","side":"buy","client_oid":"5286cacd-201f-4984-8a6f-d869a301b351","product_id":"BTC-EUR","sequence":3257976260,"time":"2018-01-22T15:14:09.038000Z"}
{"type":"open","side":"buy","price":"8444.33000000","order_id":"ef94e42c-bd88-456d-ae2c-d3903a85307c","remaining_size":"0.75000000","product_id":"BTC-EUR","sequence":3257976261,"time":"2018-01-22T15:14:09.038000Z"}
{"type":"received","order_id":"f248c6dd-a53b-45a6-8f0c-f2a7d4c1fe66","order_type":"limit","size":"0.75000000","price":"8351.13000000","side":"buy","client_oid":"9da345a2-8f70-449e-820d-8075e4927906","product_id":"BTC-EUR","sequence":3257976262,"time":"2018-01-22T15:14:09.042000Z"}
{"type":"open","side":"buy","price":"8351.13000000","order_id":"f248c6dd-a53b-45a6-8f0c-f2a7d4c1fe66","remaining_size":"0.75000000","product_id":"BTC-EUR","sequence":3257976263,"time":"2018-01-22T15:14:09.042000Z"}
{"type":"received","order_id":"cae00ee6-c5c6-4b01-a4bc-e9a64f15ca3e","order_type":"limit","size":"0.75000000","price":"9509.53000000","side":"sell","client_oid":"925b0550-f912-4c4a-9d28-2fc9a7d81a10","product_id":"BTC-EUR","sequence":3257976264,"time":"2018-01-22T15:14:09.047000Z"}
{"type":"open","side":"sell","price":"9509.53000000","order_id":"cae00ee6-c5c6-4b01-a4bc-e9a64f15ca3e","remaining_size":"0.75000000","product_id":"BTC-EUR","sequence":3257976265,"time":"2018-01-22T15:14:09.047000Z"}
{"type":"received","order_id":"57e40096-7940-4da0-85ae-4780bd47f7fb","order_type":"limit","size":"0.75000000","price":"8257.93000000","side":"buy","client_oid":"b54a738d-20e2-4ca7-b8a5-87b6fe3da026","product_id":"BTC-EUR","sequence":3257976266,"time":"2018-01-22T15:14:09.058000Z"}
{"type":"open","side":"buy","price":"8257.93000000","order_id":"57e40096-7940-4da0-85ae-4780bd47f7fb","remaining_size":"0.75000000","product_id":"BTC-EUR","sequence":3257976267,"time":"2018-01-22T15:14:09.058000Z"}
{"type":"done","side":"sell","order_id":"37232213-e973-4424-a272-9653af5bb188","reason":"canceled","product_id":"BTC-EUR","price":"8950.33000000","remaining_size":"0.75000000","sequence":3257976268,"time":"2018-01-22T15:14:09.063000Z"}
{"type":"received","order_id":"9e84b9ba-c90d-472f-9f8a-e82d9b5d4565","order_type":"limit","size":"0.74000000","price":"9602.73000000","side":"sell","client_oid":"ea169073-d0e4-4fd6-a837-641956fbf587","product_id":"BTC-EUR","sequence":3257976269,"time":"2018-01-22T15:14:09.063000Z"}
{"type":"open","side":"sell","price":"9602.73000000","order_id":"9e84b9ba-c90d-472f-9f8a-e82d9b5d4565","remaining_size":"0.74000000","product_id":"BTC-EUR","sequence":3257976270,"time":"2018-01-22T15:14:09.063000Z"}
{"type":"done","side":"buy","order_id":"7c317dd6-dfde-4bb8-b9f4-8109200059aa","reason":"canceled","product_id":"BTC-EUR","price":"8831.68000000","remaining_size":"0.06254700","sequence":3257976271,"time":"2018-01-22T15:14:09.076000Z"}
{"type":"received","order_id":"ed9f796a-1614-4bdd-a1a1-aba511141efb","order_type":"limit","size":"0.75000000","price":"8071.53000000","side":"buy","client_oid":"43a95424-a47b-4c01-a739-14f6bfc02cc7","product_id":"BTC-EUR","sequence":3257976272,"time":"2018-01-22T15:14:09.077000Z"}
{"type":"open","side":"buy","price":"8071.53000000","order_id":"ed9f796a-1614-4bdd-a1a1-aba511141efb","remaining_size":"0.75000000","product_id":"BTC-EUR","sequence":3257976273,"time":"2018-01-22T15:14:09.077000Z"}
{"type":"received","order_id":"92c5632f-92ae-46df-8ef5-dcbc37006454","order_type":"limit","size":"0.75000000","price":"9789.13000000","side":"sell","client_oid":"baa34fdb-1567-47b0-97ea-c33d55b35e51","product_id":"BTC-EUR","sequence":3257976274,"time":"2018-01-22T15:14:09.090000Z"}
{"type":"open","side":"sell","price":"9789.13000000","order_id":"92c5632f-92ae-46df-8ef5-dcbc37006454","remaining_size":"0.75000000","product_id":"BTC-EUR","sequence":3257976275,"time":"2018-01-22T15:14:09.090000Z"}
{"type":"received","order_id":"b889ac74-41c4-4f92-a3bb-05800942ff7e","order_type":"limit","size":"0.74000000","price":"8164.73000000","side":"buy","client_oid":"4e190872-5fbb-49c1-8132-6fb86e408454","product_id":"BTC-EUR","sequence":3257976276,"time":"2018-01-22T15:14:09.091000Z"}
{"type":"open","side":"buy","price":"8164.73000000","order_id":"b889ac74-41c4-4f92-a3bb-05800942ff7e","remaining_size":"0.74000000","product_id":"BTC-EUR","sequence":3257976277,"time":"2018-01-22T15:14:09.091000Z"}
{"type":"received","order_id":"e1a9b995-6be6-40fb-83c3-55c237257264","order_type":"limit","size":"0.75000000","price":"7978.33000000","side":"buy","client_oid":"884875ab-4b7f-4397-b70d-5231569d3ddf","product_id":"BTC-EUR","sequence":3257976278,"time":"2018-01-22T15:14:09.100000Z"}
{"type":"open","side":"buy","price":"7978.33000000","order_id":"e1a9b995-6be6-40fb-83c3-55c237257264","remaining_size":"0.75000000","product_id":"BTC-EUR","sequence":3257976279,"time":"2018-01-22T15:14:09.100000Z"}
{"type":"received","order_id":"6f9fecc6-f8e4-4489-b6eb-e04007a298ed","order_type":"limit","size":"0.75000000","price":"9416.33000000","side":"sell","client_oid":"44e50529-0f4e-4881-bbd7-0ae807eb24ce","product_id":"BTC-EUR","sequence":3257976280,"time":"2018-01-22T15:14:09.104000Z"}
{"type":"open","side":"sell","price":"9416.33000000","order_id":"6f9fecc6-f8e4-4489-b6eb-e04007a298ed","remaining_size":"0.75000000","product_id":"BTC-EUR","sequence":3257976281,"time":"2018-01-22T15:14:09.104000Z"}
{"type":"received","order_id":"754c5020-a9ec-41c5-8db8-07c3fe16bca5","order_type":"limit","size":"0.06675000","price":"8860.57000000","side":"sell","product_id":"BTC-EUR","sequence":3257976282,"time":"2018-01-22T15:14:09.104000Z"}
{"type":"open","side":"sell","price":"8860.57000000","order_id":"754c5020-a9ec-41c5-8db8-07c3fe16bca5","remaining_size":"0.06675000","product_id":"BTC-EUR","sequence":3257976283,"time":"2018-01-22T15:14:09.104000Z"}
{"type":"received","order_id":"73a652ce-3477-44a1-afb9-dc4726eb300a","order_type":"limit","size":"0.75000000","price":"9695.93000000","side":"sell","client_oid":"9a8fcbc7-bb38-4241-b19b-b77693498d3a","product_id":"BTC-EUR","sequence":3257976284,"time":"2018-01-22T15:14:09.111000Z"}
{"type":"open","side":"sell","price":"9695.93000000","order_id":"73a652ce-3477-44a1-afb9-dc4726eb300a","remaining_size":"0.75000000","product_id":"BTC-EUR","sequence":3257976285,"time":"2018-01-22T15:14:09.111000Z"}
{"type":"received","order_id":"44ea8b95-a3ed-403d-880b-8e690100b70e","order_type":"limit","size":"0.10500000","price":"8831.68000000","side":"buy","client_oid":"bd046e3c-542a-44c2-a2f6-89efb739d1f7","product_id":"BTC-EUR","sequence":3257976286,"time":"2018-01-22T15:14:09.124000Z"}
{"type":"open","side":"buy","price":"8831.68000000","order_id":"44ea8b95-a3ed-403d-880b-8e690100b70e","remaining_size":"0.10500000","product_id":"BTC-EUR","sequence":3257976287,"time":"2018-01-22T15:14:09.124000Z"}
{"type":"received","order_id":"e3b05dd7-a9bc-4586-b63a-268c737325f8","order_type":"limit","size":"0.75000000","price":"9043.54000000","side":"sell","client_oid":"26bb0bb6-ae18-4d61-a26e-77b5de0ee581","product_id":"BTC-EUR","sequence":3257976288,"time":"2018-01-22T15:14:09.127000Z"}
{"type":"open","side":"sell","price":"9043.54000000","order_id":"e3b05dd7-a9bc-4586-b63a-268c737325f8","remaining_size":"0.75000000","product_id":"BTC-EUR","sequence":3257976289,"time":"2018-01-22T15:14:09.127000Z"}
{"type":"done","side":"buy","order_id":"ac35fcfc-5d7f-451d-a6e1-d56734151d99","reason":"canceled","product_id":"BTC-EUR","price":"8817.13000000","remaining_size":"0.49000000","sequence":3257976290,"time":"2018-01-22T15:14:09.137000Z"}
{"type":"done","side":"sell","order_id":"669c18e4-47e6-4588-9c53-e6d53d3369bb","reason":"canceled","product_id":"BTC-EUR","price":"8857.13000000","remaining_size":"0.25000000","sequence":3257976291,"time":"2018-01-22T15:14:09.137000Z"}
{"type":"done","side":"buy","order_id":"60d40d82-f537-496d-b43e-ccc481e4eca8","reason":"canceled","product_id":"BTC-EUR","price":"8723.93000000","remaining_size":"0.75000000","sequence":3257976292,"time":"2018-01-22T15:14:09.140000Z"}
{"type":"received","order_id":"326c4827-6d21-4807-b3a1-14cb6f253453","order_type":"limit","size":"0.10200000","price":"8610.00000000","side":"buy","client_oid":"b542dd08-5f45-4fda-aac2-465ee34ea554","product_id":"BTC-EUR","sequence":3257976293,"time":"2018-01-22T15:14:09.169000Z"}
{"type":"open","side":"buy","price":"8610.00000000","order_id":"326c4827-6d21-4807-b3a1-14cb6f253453","remaining_size":"0.10200000","product_id":"BTC-EUR","sequence":3257976294,"time":"2018-01-22T15:14:09.169000Z"}
{"type":"received","order_id":"73056ce7-537f-4363-9c33-0151d4cf1162","order_type":"limit","size":"0.75000000","price":"8950.34000000","side":"sell","client_oid":"9850944f-ce97-4a63-baf2-04d62354ca58","product_id":"BTC-EUR","sequence":3257976295,"time":"2018-01-22T15:14:09.174000Z"}
{"type":"open","side":"sell","price":"8950.34000000","order_id":"73056ce7-537f-4363-9c33-0151d4cf1162","remaining_size":"0.75000000","product_id":"BTC-EUR","sequence":3257976296,"time":"2018-01-22T15:14:09.174000Z"}
{"type":"received","order_id":"372ab20c-b7e8-4da3-898c-191087fb1d3a","order_type":"limit","size":"0.02264998","price":"8831.68000000","side":"buy","client_oid":"1ea2367a-aa27-4fe2-9338-71456d0a1924","product_id":"BTC-EUR","sequence":3257976297,"time":"2018-01-22T15:14:09.185000Z"}
{"type":"open","side":"buy","price":"8831.68000000","order_id":"372ab20c-b7e8-4da3-898c-191087fb1d3a","remaining_size":"0.02264998","product_id":"BTC-EUR","sequence":3257976298,"time":"2018-01-22T15:14:09.185000Z"}
{"type":"received","order_id":"f8ecbf5c-6176-4a2a-9860-0297fa5c82d1","order_type":"limit","size":"0.49000000","price":"8817.14000000","side":"buy","client_oid":"0a83522e-988a-4ae5-bf3d-9dc88c9aeac5","product_id":"BTC-EUR","sequence":3257976299,"time":"2018-01-22T15:14:09.190000Z"}
{"type":"open","side":"buy","price":"8817.14000000","order_id":"f8ecbf5c-6176-4a2a-9860-0297fa5c82d1","remaining_size":"0.49000000","product_id":"BTC-EUR","sequence":3257976300,"time":"2018-01-22T15:14:09.191000Z"}
{"type":"received","order_id":"df591a16-3f6a-46a9-83f4-02ed55addcf7","order_type":"limit","size":"0.25000000","price":"8857.14000000","side":"sell","client_oid":"d7ab94cf-f2de-46e9-872c-a8c6ada15f03","product_id":"BTC-EUR","sequence":3257976301,"time":"2018-01-22T15:14:09.191000Z"}
{"type":"open","side":"sell","price":"8857.14000000","order_id":"df591a16-3f6a-46a9-83f4-02ed55addcf7","remaining_size":"0.25000000","product_id":"BTC-EUR","sequence":3257976302,"time":"2018-01-22T15:14:09.191000Z"}
{"type":"done","side":"buy","order_id":"44ea8b95-a3ed-403d-880b-8e690100b70e","reason":"canceled","product_id":"BTC-EUR","price":"8831.68000000","remaining_size":"0.10500000","sequence":3257976303,"time":"2018-01-22T15:14:09.257000Z"}
{"type":"received","order_id":"f62e8b51-714e-47cb-90f4-abb8d982cfc2","order_type":"limit","size":"0.10500000","price":"8831.68000000","side":"buy","client_oid":"b919ad11-c91a-4773-a4f1-8a7eeb2b4bf0","product_id":"BTC-EUR","sequence":3257976304,"time":"2018-01-22T15:14:09.280000Z"}
{"type":"open","side":"buy","price":"8831.68000000","order_id":"f62e8b51-714e-47cb-90f4-abb8d982cfc2","remaining_size":"0.10500000","product_id":"BTC-EUR","sequence":3257976305,"time":"2018-01-22T15:14:09.280000Z"}
{"type":"received","order_id":"6620ec6e-0fd2-42e6-901d-6a244ad8ddc1","order_type":"limit","size":"0.03000000","price":"9096.64000000","side":"buy","product_id":"BTC-EUR","sequence":3257976306,"time":"2018-01-22T15:14:09.456000Z"}
{"type":"match","trade_id":10551299,"maker_order_id":"3a9a3ec7-92be-49d3-8bc8-06901765e0fb","taker_order_id":"6620ec6e-0fd2-42e6-901d-6a244ad8ddc1","side":"sell","size":"0.03000000","price":"8831.69000000","product_id":"BTC-EUR","sequence":3257976307,"time":"2018-01-22T15:14:09.456000Z"}
{"type":"done","side":"buy","order_id":"6620ec6e-0fd2-42e6-901d-6a244ad8ddc1","reason":"filled","product_id":"BTC-EUR","price":"9096.64000000","remaining_size":"0.00000000","sequence":3257976308,"time":"2018-01-22T15:14:09.456000Z"}
{"type":"received","order_id":"20f6ca71-d28d-470c-a196-1d3ea5bf4092","order_type":"limit","size":"0.10500000","price":"8831.68000000","side":"buy","client_oid":"e1ca783d-e940-4160-a677-ea2453fa8e06","product_id":"BTC-EUR","sequence":3257976309,"time":"2018-01-22T15:14:09.547000Z"}
{"type":"open","side":"buy","price":"8831.68000000","order_id":"20f6ca71-d28d-470c-a196-1d3ea5bf4092","remaining_size":"0.10500000","product_id":"BTC-EUR","sequence":3257976310,"time":"2018-01-22T15:14:09.547000Z"}
{"type":"received","order_id":"d394b3f7-e3bf-4d32-8c55-aad3773c5e52","order_type":"limit","size":"0.01000000","price":"8566.73000000","side":"sell","product_id":"BTC-EUR","sequence":3257976311,"time":"2018-01-22T15:14:09.652000Z"}
{"type":"match","trade_id":10551300,"maker_order_id":"bdf0cb95-d508-4539-9a23-4cd409adc998","taker_order_id":"d394b3f7-e3bf-4d32-8c55-aad3773c5e52","side":"buy","size":"0.01000000","price":"8831.68000000","product_id":"BTC-EUR","sequence":3257976312,"time":"2018-01-22T15:14:09.652000Z"}
{"type":"done","side":"sell","order_id":"d394b3f7-e3bf-4d32-8c55-aad3773c5e52","reason":"filled","product_id":"BTC-EUR","price":"8566.73000000","remaining_size":"0.00000000","sequence":3257976313,"time":"2018-01-22T15:14:09.652000Z"}
{"type":"done","side":"buy","order_id":"fee5232d-229b-4840-8d43-0d01233f995f","reason":"canceled","product_id":"BTC-EUR","price":"8126.16000000","remaining_size":"0.16390397","sequence":3257976314,"time":"2018-01-22T15:14:09.812000Z"}
{"type":"received","order_id":"61836444-54f9-4957-a493-e6205fc35745","order_type":"limit","size":"0.01000000","price":"9096.64000000","side":"buy","product_id":"BTC-EUR","sequence":3257976315,"time":"2018-01-22T15:14:09.879000Z"}
{"type":"match","trade_id":10551301,"maker_order_id":"3a9a3ec7-92be-49d3-8bc8-06901765e0fb","taker_order_id":"61836444-54f9-4957-a493-e6205fc35745","side":"sell","size":"0.01000000","price":"8831.69000000","product_id":"BTC-EUR","sequence":3257976316,"time":"2018-01-22T15:14:09.879000Z"}
{"type":"done","side":"buy","order_id":"61836444-54f9-4957-a493-e6205fc35745","reason":"filled","product_id":"BTC-EUR","price":"9096.64000000","remaining_size":"0.00000000","sequence":3257976317,"time":"2018-01-22T15:14:09.879000Z"}
{"type":"done","side":"buy","order_id":"78f80eb2-3a6d-48d3-b806-f80ced94e296","reason":"canceled","product_id":"BTC-EUR","price":"8819.24000000","remaining_size":"0.46302727","sequence":3257976318,"time":"2018-01-22T15:14:09.927000Z"}
{"type":"received","order_id":"d5e7c7d3-0aa4-42a6-a657-bd0aa3da6c42","order_type":"limit","size":"0.01153000","price":"8680.00000000","side":"buy","client_oid":"d0a09b56-27b7-433a-cad6-3f3ec189dbc9","product_id":"BTC-EUR","sequence":3257976319,"time":"2018-01-22T15:14:09.930000Z"}
{"type":"open","side":"buy","price":"8680.00000000","order_id":"d5e7c7d3-0aa4-42a6-a657-bd0aa3da6c42","remaining_size":"0.01153000","product_id":"BTC-EUR","sequence":3257976320,"time":"2018-01-22T15:14:09.930000Z"}
{"type":"done","side":"sell","order_id":"73056ce7-537f-4363-9c33-0151d4cf1162","reason":"canceled","product_id":"BTC-EUR","price":"8950.34000000","remaining_size":"0.75000000","sequence":3257976321,"time":"2018-01-22T15:14:09.973000Z"}
{"type":"done","side":"buy","order_id":"f8ecbf5c-6176-4a2a-9860-0297fa5c82d1","reason":"canceled","product_id":"BTC-EUR","price":"8817.14000000","remaining_size":"0.49000000","sequence":3257976322,"time":"2018-01-22T15:14:09.984000Z"}
{"type":"done","side":"sell","order_id":"df591a16-3f6a-46a9-83f4-02ed55addcf7","reason":"canceled","product_id":"BTC-EUR","price":"8857.14000000","remaining_size":"0.25000000","sequence":3257976323,"time":"2018-01-22T15:14:09.985000Z"}
{"type":"done","side":"buy","order_id":"721a5d07-7f87-4b89-b53a-96bf95ccb93b","reason":"canceled","product_id":"BTC-EUR","price":"8823.33000000","remaining_size":"0.18512519","sequence":3257976324,"time":"2018-01-22T15:14:09.998000Z"}
{"type":"done","side":"sell","order_id":"e3b05dd7-a9bc-4586-b63a-268c737325f8","reason":"canceled","product_id":"BTC-EUR","price":"9043.54000000","remaining_size":"0.75000000","sequence":3257976325,"time":"2018-01-22T15:14:10.008000Z"}
{"type":"done","side":"sell","order_id":"c150932e-c05d-4893-aa20-273f73460b66","reason":"canceled","product_id":"BTC-EUR","price":"9136.73000000","remaining_size":"0.75000000","sequence":3257976326,"time":"2018-01-22T15:14:10.008000Z"}
{"type":"done","side":"buy","order_id":"e25e2b16-2d0e-41c9-8446-f717a418eb51","reason":"canceled","product_id":"BTC-EUR","price":"8630.73000000","remaining_size":"0.75000000","sequence":3257976327,"time":"2018-01-22T15:14:10.014000Z"}
{"type":"done","side":"sell","order_id":"129886db-fd89-4921-a5fe-2a8b1775963b","reason":"canceled","product_id":"BTC-EUR","price":"9229.93000000","remaining_size":"0.74000000","sequence":3257976328,"time":"2018-01-22T15:14:10.014000Z"}
{"type":"done","side":"buy","order_id":"063628ca-eb70-40f1-9605-d86071c5cd88","reason":"canceled","product_id":"BTC-EUR","price":"8537.53000000","remaining_size":"0.74000000","sequence":3257976329,"time":"2018-01-22T15:14:10.031000Z"}
{"type":"done","side":"sell","order_id":"4bc33569-f500-48aa-9408-e978ea24890b","reason":"canceled","product_id":"BTC-EUR","price":"9323.13000000","remaining_size":"0.75000000","sequence":3257976330,"time":"2018-01-22T15:14:10.031000Z"}
{"type":"done","side":"buy","order_id":"ef94e42c-bd88-456d-ae2c-d3903a85307c","reason":"canceled","product_id":"BTC-EUR","price":"8444.33000000","remaining_size":"0.75000000","sequence":3257976331,"time":"2018-01-22T15:14:10.090000Z"}
{"type":"done","side":"sell","order_id":"6f9fecc6-f8e4-4489-b6eb-e04007a298ed","reason":"canceled","product_id":"BTC-EUR","price":"9416.33000000","remaining_size":"0.75000000","sequence":3257976332,"time":"2018-01-22T15:14:10.092000Z"}
{"type":"done","side":"buy","order_id":"f248c6dd-a53b-45a6-8f0c-f2a7d4c1fe66","reason":"canceled","product_id":"BTC-EUR","price":"8351.13000000","remaining_size":"0.75000000","sequence":3257976333,"time":"2018-01-22T15:14:10.110000Z"}
{"type":"done","side":"sell","order_id":"cae00ee6-c5c6-4b01-a4bc-e9a64f15ca3e","reason":"canceled","product_id":"BTC-EUR","price":"9509.53000000","remaining_size":"0.75000000","sequence":3257976334,"time":"2018-01-22T15:14:10.111000Z"}
{"type":"done","side":"buy","order_id":"57e40096-7940-4da0-85ae-4780bd47f7fb","reason":"canceled","product_id":"BTC-EUR","price":"8257.93000000","remaining_size":"0.75000000","sequence":3257976335,"time":"2018-01-22T15:14:10.115000Z"}
{"type":"done","side":"sell","order_id":"9e84b9ba-c90d-472f-9f8a-e82d9b5d4565","reason":"canceled","product_id":"BTC-EUR","price":"9602.73000000","remaining_size":"0.74000000","sequence":3257976336,"time":"2018-01-22T15:14:10.115000Z"}
{"type":"done","side":"buy","order_id":"b889ac74-41c4-4f92-a3bb-05800942ff7e","reason":"canceled","product_id":"BTC-EUR","price":"8164.73000000","remaining_size":"0.74000000","sequence":3257976337,"time":"2018-01-22T15:14:10.122000Z"}
{"type":"done","side":"sell","order_id":"73a652ce-3477-44a1-afb9-dc4726eb300a","reason":"canceled","product_id":"BTC-EUR","price":"9695.93000000","remaining_size":"0.75000000","sequence":3257976338,"time":"2018-01-22T15:14:10.122000Z"}
{"type":"done","side":"buy","order_id":"ed9f796a-1614-4bdd-a1a1-aba511141efb","reason":"canceled","product_id":"BTC-EUR","price":"8071.53000000","remaining_size":"0.75000000","sequence":3257976339,"time":"2018-01-22T15:14:10.122000Z"}
{"type":"done","side":"sell","order_id":"92c5632f-92ae-46df-8ef5-dcbc37006454","reason":"canceled","product_id":"BTC-EUR","price":"9789.13000000","remaining_size":"0.75000000","sequence":3257976340,"time":"2018-01-22T15:14:10.123000Z"}
{"type":"done","side":"buy","order_id":"e1a9b995-6be6-40fb-83c3-55c237257264","reason":"canceled","product_id":"BTC-EUR","price":"7978.33000000","remaining_size":"0.75000000","sequence":3257976341,"time":"2018-01-22T15:14:10.123000Z"}
{"type":"received","order_id":"cdd61241-04a1-4d58-bf1e-a03d8fdfe3b2","order_type":"limit","size":"0.75000000","price":"8956.88000000","side":"sell","client_oid":"a6676dce-6aa7-4d60-a2ea-c73781dd80dc","product_id":"BTC-EUR","sequence":3257976342,"time":"2018-01-22T15:14:10.124000Z"}
{"type":"open","side":"sell","price":"8956.88000000","order_id":"cdd61241-04a1-4d58-bf1e-a03d8fdfe3b2","remaining_size":"0.75000000","product_id":"BTC-EUR","sequence":3257976343,"time":"2018-01-22T15:14:10.124000Z"}
{"type":"received","order_id":"12d23016-3c1c-488c-a417-843f64368fe3","order_type":"limit","size":"0.49000000","price":"8823.68000000","side":"buy","client_oid":"ef745b9d-ffb9-4cf6-a0cb-809ba76b25f2","product_id":"BTC-EUR","sequence":3257976344,"time":"2018-01-22T15:14:10.124000Z"}
{"type":"open","side":"buy","price":"8823.68000000","order_id":"12d23016-3c1c-488c-a417-843f64368fe3","remaining_size":"0.49000000","product_id":"BTC-EUR","sequence":3257976345,"time":"2018-01-22T15:14:10.124000Z"}
{"type":"received","order_id":"669441ec-fd82-4c43-9490-fdb900d6317b","order_type":"limit","size":"0.25000000","price":"8863.58000000","side":"sell","client_oid":"73ea5e5c-4bb2-4b39-98b0-2dbcbc88063d","product_id":"BTC-EUR","sequence":3257976346,"time":"2018-01-22T15:14:10.125000Z"}
{"type":"open","side":"sell","price":"8863.58000000","order_id":"669441ec-fd82-4c43-9490-fdb900d6317b","remaining_size":"0.25000000","product_id":"BTC-EUR","sequence":3257976347,"time":"2018-01-22T15:14:10.125000Z"}
{"type":"received","order_id":"54322bae-b711-4ba3-9269-fe78dbe4c071","order_type":"limit","size":"0.75000000","price":"8730.38000000","side":"buy","client_oid":"e6edfe6f-4db0-494e-9dcb-b60d5aa983d2","product_id":"BTC-EUR","sequence":3257976348,"time":"2018-01-22T15:14:10.125000Z"}
{"type":"open","side":"buy","price":"8730.38000000","order_id":"54322bae-b711-4ba3-9269-fe78dbe4c071","remaining_size":"0.75000000","product_id":"BTC-EUR","sequence":3257976349,"time":"2018-01-22T15:14:10.125000Z"}
{"type":"received","order_id":"70da32ba-55b1-4db9-890a-4e0446885dd0","order_type":"limit","size":"0.75000000","price":"9330.08000000","side":"sell","client_oid":"223a8b24-b6c3-4c26-a1cf-8213f43c6b58","product_id":"BTC-EUR","sequence":3257976350,"time":"2018-01-22T15:14:10.126000Z"}
{"type":"open","side":"sell","price":"9330.08000000","order_id":"70da32ba-55b1-4db9-890a-4e0446885dd0","remaining_size":"0.75000000","product_id":"BTC-EUR","sequence":3257976351,"time":"2018-01-22T15:14:10.126000Z"}
{"type":"received","order_id":"8532631c-3c70-4dcb-98ea-61c7c444b94a","order_type":"limit","size":"0.74000000","price":"9236.78000000","side":"sell","client_oid":"1a9cef5e-cfa0-459b-aba1-29fb846570ac","product_id":"BTC-EUR","sequence":3257976352,"time":"2018-01-22T15:14:10.126000Z"}
{"type":"open","side":"sell","price":"9236.78000000","order_id":"8532631c-3c70-4dcb-98ea-61c7c444b94a","remaining_size":"0.74000000","product_id":"BTC-EUR","sequence":3257976353,"time":"2018-01-22T15:14:10.126000Z"}
{"type":"received","order_id":"aeaa99bb-e347-4423-9520-9c8504ec1f27","order_type":"limit","size":"0.75000000","price":"8637.08000000","side":"buy","client_oid":"0bb70d67-cf0f-4377-bfc2-5084a0b3b2cd","product_id":"BTC-EUR","sequence":3257976354,"time":"2018-01-22T15:14:10.131000Z"}
{"type":"open","side":"buy","price":"8637.08000000","order_id":"aeaa99bb-e347-4423-9520-9c8504ec1f27","remaining_size":"0.75000000","product_id":"BTC-EUR","sequence":3257976355,"time":"2018-01-22T15:14:10.131000Z"}
{"type":"received","order_id":"1631f4d7-1361-4920-b356-1f781f6b1522","order_type":"limit","size":"0.74000000","price":"8543.78000000","side":"buy","client_oid":"7ba85355-3535-4b9f-b6e6-3a4b52539158","product_id":"BTC-EUR","sequence":3257976356,"time":"2018-01-22T15:14:10.136000Z"}
{"type":"open","side":"buy","price":"8543.78000000","order_id":"1631f4d7-1361-4920-b356-1f781f6b1522","remaining_size":"0.74000000","product_id":"BTC-EUR","sequence":3257976357,"time":"2018-01-22T15:14:10.136000Z"}
{"type":"received","order_id":"5c5a8bc0-602e-47d3-abd7-a5144eefa2eb","order_type":"limit","size":"0.75000000","price":"8450.48000000","side":"buy","client_oid":"8fbdda75-4c9c-4e04-bd77-9bd828ae1ff3","product_id":"BTC-EUR","sequence":3257976358,"time":"2018-01-22T15:14:10.151000Z"}
{"type":"open","side":"buy","price":"8450.48000000","order_id":"5c5a8bc0-602e-47d3-abd7-a5144eefa2eb","remaining_size":"0.75000000","product_id":"BTC-EUR","sequence":3257976359,"time":"2018-01-22T15:14:10.151000Z"}
{"type":"received","order_id":"6eab05aa-19c2-49b9-9cb6-ca43119db2ed","order_type":"limit","size":"0.75000000","price":"8357.18000000","side":"buy","client_oid":"57c12d47-8087-4017-95d4-d15a48b72bda","product_id":"BTC-EUR","sequence":3257976360,"time":"2018-01-22T15:14:10.157000Z"}
{"type":"open","side":"buy","price":"8357.18000000","order_id":"6eab05aa-19c2-49b9-9cb6-ca43119db2ed","remaining_size":"0.75000000","product_id":"BTC-EUR","sequence":3257976361,"time":"2018-01-22T15:14:10.157000Z"}
{"type":"received","order_id":"d5be3499-4b31-406e-a8d4-7cd9c2eed30e","order_type":"limit","size":"0.46302727","price":"8819.24000000","side":"buy","client_oid":"45318672-0912-4bb8-aee4-f8a24831fa99","product_id":"BTC-EUR","sequence":3257976362,"time":"2018-01-22T15:14:10.212000Z"}
{"type":"open","side":"buy","price":"8819.24000000","order_id":"d5be3499-4b31-406e-a8d4-7cd9c2eed30e","remaining_size":"0.46302727","product_id":"BTC-EUR","sequence":3257976363,"time":"2018-01-22T15:14:10.212000Z"}
{"type":"received","order_id":"8c0c3468-e5a8-4803-b558-af592928b940","order_type":"limit","size":"0.75000000","price":"9423.38000000","side":"sell","client_oid":"92f56680-f1a0-4d95-b0ab-002fdad51ded","product_id":"BTC-EUR","sequence":3257976364,"time":"2018-01-22T15:14:10.212000Z"}
{"type":"open","side":"sell","price":"9423.38000000","order_id":"8c0c3468-e5a8-4803-b558-af592928b940","remaining_size":"0.75000000","product_id":"BTC-EUR","sequence":3257976365,"time":"2018-01-22T15:14:10.212000Z"}
{"type":"received","order_id":"506b2d20-877e-4e8d-9eda-5e661501ce91","order_type":"limit","size":"0.75000000","price":"9516.68000000","side":"sell","client_oid":"4b4aba80-8132-4edc-bdbd-000f65b1d1d1","product_id":"BTC-EUR","sequence":3257976366,"time":"2018-01-22T15:14:10.236000Z"}
{"type":"open","side":"sell","price":"9516.68000000","order_id":"506b2d20-877e-4e8d-9eda-5e661501ce91","remaining_size":"0.75000000","product_id":"BTC-EUR","sequence":3257976367,"time":"2018-01-22T15:14:10.236000Z"}
{"type":"received","order_id":"dba3b3e7-d034-44b0-9c43-7449af79db72","order_type":"limit","size":"0.75000000","price":"8263.88000000","side":"buy","client_oid":"b4d33c14-c4a8-4ed9-9b3d-08b54a6074dd","product_id":"BTC-EUR","sequence":3257976368,"time":"2018-01-22T15:14:10.252000Z"}
{"type":"open","side":"buy","price":"8263.88000000","order_id":"dba3b3e7-d034-44b0-9c43-7449af79db72","remaining_size":"0.75000000","product_id":"BTC-EUR","sequence":3257976369,"time":"2018-01-22T15:14:10.252000Z"}
{"type":"received","order_id":"2c14744b-126f-4d06-9934-ff976ad29b6b","order_type":"limit","size":"0.74000000","price":"9609.98000000","side":"sell","client_oid":"467fa30f-06e5-4acd-8984-afaac1659c94","product_id":"BTC-EUR","sequence":3257976370,"time":"2018-01-22T15:14:10.261000Z"}
{"type":"open","side":"sell","price":"9609.98000000","order_id":"2c14744b-126f-4d06-9934-ff976ad29b6b","remaining_size":"0.74000000","product_id":"BTC-EUR","sequence":3257976371,"time":"2018-01-22T15:14:10.261000Z"}
{"type":"received","order_id":"65a85b27-a606-41c0-b8e7-600fd5f0fa97","order_type":"limit","size":"0.75000000","price":"9796.58000000","side":"sell","client_oid":"722dea66-4b77-4977-9de8-e7b6dd7cd767","product_id":"BTC-EUR","sequence":3257976372,"time":"2018-01-22T15:14:10.270000Z"}
{"type":"open","side":"sell","price":"9796.58000000","order_id":"65a85b27-a606-41c0-b8e7-600fd5f0fa97","remaining_size":"0.75000000","product_id":"BTC-EUR","sequence":3257976373,"time":"2018-01-22T15:14:10.270000Z"}
{"type":"received","order_id":"22cea007-1059-414d-b922-d9c7c0988629","order_type":"limit","size":"0.18512519","price":"8823.33000000","side":"buy","client_oid":"508555e6-0a55-4d0d-acd5-1b9bec00df2d","product_id":"BTC-EUR","sequence":3257976374,"time":"2018-01-22T15:14:10.272000Z"}
{"type":"open","side":"buy","price":"8823.33000000","order_id":"22cea007-1059-414d-b922-d9c7c0988629","remaining_size":"0.18512519","product_id":"BTC-EUR","sequence":3257976375,"time":"2018-01-22T15:14:10.272000Z"}
{"type":"received","order_id":"981750b8-48e0-42b5-a4e2-cfda4e919536","order_type":"limit","size":"0.74000000","price":"8170.58000000","side":"buy","client_oid":"1fbdea02-19ba-4ee5-9e1d-7ed3cb3e4871","product_id":"BTC-EUR","sequence":3257976376,"time":"2018-01-22T15:14:10.280000Z"}
{"type":"open","side":"buy","price":"8170.58000000","order_id":"981750b8-48e0-42b5-a4e2-cfda4e919536","remaining_size":"0.74000000","product_id":"BTC-EUR","sequence":3257976377,"time":"2018-01-22T15:14:10.280000Z"}
{"type":"received","order_id":"e8b99a6b-9d61-4b81-b529-5c04dab90aa2","order_type":"limit","size":"0.75000000","price":"7983.98000000","side":"buy","client_oid":"2199c6a3-058d-42a2-981f-9514adfb1541","product_id":"BTC-EUR","sequence":3257976378,"time":"2018-01-22T15:14:10.290000Z"}
{"type":"open","side":"buy","price":"7983.98000000","order_id":"e8b99a6b-9d61-4b81-b529-5c04dab90aa2","remaining_size":"0.75000000","product_id":"BTC-EUR","sequence":3257976379,"time":"2018-01-22T15:14:10.290000Z"}
{"type":"received","order_id":"69071e67-4bb5-4c54-ba4e-a7c9795da08e","order_type":"limit","size":"0.75000000","price":"9703.28000000","side":"sell","client_oid":"5ddd8261-f59d-4e47-82ed-6801b20265e0","product_id":"BTC-EUR","sequence":3257976380,"time":"2018-01-22T15:14:10.297000Z"}
{"type":"open","side":"sell","price":"9703.28000000","order_id":"69071e67-4bb5-4c54-ba4e-a7c9795da08e","remaining_size":"0.75000000","product_id":"BTC-EUR","sequence":3257976381,"time":"2018-01-22T15:14:10.297000Z"}
{"type":"received","order_id":"d124288a-2e4c-48bc-8fea-bc8da811cc6f","order_type":"limit","size":"0.75000000","price":"8077.28000000","side":"buy","client_oid":"2fba7691-7b1e-4022-a24d-efdbeb1badb2","product_id":"BTC-EUR","sequence":3257976382,"time":"2018-01-22T15:14:10.303000Z"}
{"type":"open","side":"buy","price":"8077.28000000","order_id":"d124288a-2e4c-48bc-8fea-bc8da811cc6f","remaining_size":"0.75000000","product_id":"BTC-EUR","sequence":3257976383,"time":"2018-01-22T15:14:10.303000Z"}
{"type":"received","order_id":"c4c34063-b2e7-47c8-a938-8310b1b4392f","order_type":"limit","size":"0.75000000","price":"9050.18000000","side":"sell","client_oid":"0aac1552-1229-480b-95fc-9b263dbc53a8","product_id":"BTC-EUR","sequence":3257976384,"time":"2018-01-22T15:14:10.328000Z"}
{"type":"open","side":"sell","price":"9050.18000000","order_id":"c4c34063-b2e7-47c8-a938-8310b1b4392f","remaining_size":"0.75000000","product_id":"BTC-EUR","sequence":3257976385,"time":"2018-01-22T15:14:10.328000Z"}
{"type":"received","order_id":"6684a551-d10c-45f9-b414-1174699ab6f3","order_type":"limit","size":"0.75000000","price":"9143.48000000","side":"sell","client_oid":"cb03bed7-0ebe-4587-afef-e53b74fd9794","product_id":"BTC-EUR","sequence":3257976386,"time":"2018-01-22T15:14:10.328000Z"}
{"type":"open","side":"sell","price":"9143.48000000","order_id":"6684a551-d10c-45f9-b414-1174699ab6f3","remaining_size":"0.75000000","product_id":"BTC-EUR","sequence":3257976387,"time":"2018-01-22T15:14:10.328000Z"}
{"type":"received","order_id":"9561efb0-90f6-48d2-a819-618651f17a42","order_type":"limit","size":"0.06666600","price":"8831.68000000","side":"buy","product_id":"BTC-EUR","sequence":3257976388,"time":"2018-01-22T15:14:10.369000Z"}
{"type":"open","side":"buy","price":"8831.68000000","order_id":"9561efb0-90f6-48d2-a819-618651f17a42","remaining_size":"0.06666600","product_id":"BTC-EUR","sequence":3257976389,"time":"2018-01-22T15:14:10.369000Z"}
{"type":"done","side":"sell","order_id":"cdd61241-04a1-4d58-bf1e-a03d8fdfe3b2","reason":"canceled","product_id":"BTC-EUR","price":"8956.88000000","remaining_size":"0.75000000","sequence":3257976390,"time":"2018-01-22T15:14:10.442000Z"}
{"type":"done","side":"buy","order_id":"12d23016-3c1c-488c-a417-843f64368fe3","reason":"canceled","product_id":"BTC-EUR","price":"8823.68000000","remaining_size":"0.49000000","sequence":3257976391,"time":"2018-01-22T15:14:10.450000Z"}
{"type":"done","side":"sell","order_id":"669441ec-fd82-4c43-9490-fdb900d6317b","reason":"canceled","product_id":"BTC-EUR","price":"8863.58000000","remaining_size":"0.25000000","sequence":3257976392,"time":"2018-01-22T15:14:10.450000Z"}
{"type":"done","side":"sell","order_id":"c4c34063-b2e7-47c8-a938-8310b1b4392f","reason":"canceled","product_id":"BTC-EUR","price":"9050.18000000","remaining_size":"0.75000000","sequence":3257976393,"time":"2018-01-22T15:14:10.453000Z"}
{"type":"received","order_id":"4696a844-5d13-4ddf-858f-3c944ae59806","order_type":"limit","size":"0.49000000","price":"8815.11000000","side":"buy","client_oid":"d5a589d0-6d95-4e71-aa1a-81b4ae477642","product_id":"BTC-EUR","sequence":3257976394,"time":"2018-01-22T15:14:10.486000Z"}
{"type":"open","side":"buy","price":"8815.11000000","order_id":"4696a844-5d13-4ddf-858f-3c944ae59806","remaining_size":"0.49000000","product_id":"BTC-EUR","sequence":3257976395,"time":"2018-01-22T15:14:10.486000Z"}
{"type":"received","order_id":"d4a523d3-a08d-4902-8c57-4364675daf19","order_type":"limit","size":"0.13000000","price":"8566.73000000","side":"sell","product_id":"BTC-EUR","sequence":3257976396,"time":"2018-01-22T15:14:10.596000Z"}
{"type":"match","trade_id":10551302,"maker_order_id":"bdf0cb95-d508-4539-9a23-4cd409adc998","taker_order_id":"d4a523d3-a08d-4902-8c57-4364675daf19","side":"buy","size":"0.13000000","price":"8831.68000000","product_id":"BTC-EUR","sequence":3257976397,"time":"2018-01-22T15:14:10.596000Z"}
{"type":"done","side":"sell","order_id":"d4a523d3-a08d-4902-8c57-4364675daf19","reason":"filled","product_id":"BTC-EUR","price":"8566.73000000","remaining_size":"0.00000000","sequence":3257976398,"time":"2018-01-22T15:14:10.596000Z"}
{"type":"done","side":"buy","order_id":"9561efb0-90f6-48d2-a819-618651f17a42","reason":"canceled","product_id":"BTC-EUR","price":"8831.68000000","remaining_size":"0.06666600","sequence":3257976399,"time":"2018-01-22T15:14:10.857000Z"}
{"type":"received","order_id":"73663bb0-bac9-4607-a0b3-b77dcda8d249","order_type":"limit","size":"0.50000000","price":"9046.00000000","side":"sell","product_id":"BTC-EUR","sequence":3257976400,"time":"2018-01-22T15:14:11.038000Z"}
{"type":"open","side":"sell","price":"9046.00000000","order_id":"73663bb0-bac9-4607-a0b3-b77dcda8d249","remaining_size":"0.50000000","product_id":"BTC-EUR","sequence":3257976401,"time":"2018-01-22T15:14:11.038000Z"}
{"type":"received","order_id":"aabf4f54-5c3c-42af-a4b6-25c6728b4a99","order_type":"limit","size":"0.01000000","price":"9096.64000000","side":"buy","product_id":"BTC-EUR","sequence":3257976402,"time":"2018-01-22T15:14:11.060000Z"}
{"type":"match","trade_id":10551303,"maker_order_id":"3a9a3ec7-92be-49d3-8bc8-06901765e0fb","taker_order_id":"aabf4f54-5c3c-42af-a4b6-25c6728b4a99","side":"sell","size":"0.01000000","price":"8831.69000000","product_id":"BTC-EUR","sequence":3257976403,"time":"2018-01-22T15:14:11.060000Z"}
{"type":"done","side":"buy","order_id":"aabf4f54-5c3c-42af-a4b6-25c6728b4a99","reason":"filled","product_id":"BTC-EUR","price":"9096.64000000","remaining_size":"0.00000000","sequence":3257976404,"time":"2018-01-22T15:14:11.060000Z"}
{"type":"done","side":"buy","order_id":"da2eb988-c438-4b59-af9a-fbd30740e540","reason":"canceled","product_id":"BTC-EUR","price":"8655.10000000","remaining_size":"1.89556000","sequence":3257976405,"time":"2018-01-22T15:14:11.061000Z"}
{"type":"received","order_id":"a33d2d0c-2bd1-4556-a85c-9d0ea345cb01","order_type":"limit","size":"1.89631000","price":"8654.20000000","side":"buy","client_oid":"30e32afb-cc8e-4ac2-9242-0a8efb71411c","product_id":"BTC-EUR","sequence":3257976406,"time":"2018-01-22T15:14:11.083000Z"}
{"type":"open","side":"buy","price":"8654.20000000","order_id":"a33d2d0c-2bd1-4556-a85c-9d0ea345cb01","remaining_size":"1.89631000","product_id":"BTC-EUR","sequence":3257976407,"time":"2018-01-22T15:14:11.083000Z"}
{"type":"received","order_id":"07ec33d9-aefa-479f-aa23-5f86e342b465","order_type":"limit","size":"0.10500000","price":"8831.68000000","side":"buy","client_oid":"82725a89-04e3-452e-b2dd-4a731d75fc7b","product_id":"BTC-EUR","sequence":3257976408,"time":"2018-01-22T15:14:11.156000Z"}
{"type":"open","side":"buy","price":"8831.68000000","order_id":"07ec33d9-aefa-479f-aa23-5f86e342b465","remaining_size":"0.10500000","product_id":"BTC-EUR","sequence":3257976409,"time":"2018-01-22T15:14:11.157000Z"}
{"type":"done","side":"sell","order_id":"ebc27276-709e-4587-befe-bc1aa22348ac","reason":"canceled","product_id":"BTC-EUR","price":"8891.52000000","remaining_size":"0.18370534","sequence":3257976410,"time":"2018-01-22T15:14:11.195000Z"}
{"type":"received","order_id":"80ee1692-b809-4916-aeb3-90920041ea09","order_type":"limit","size":"1.00000000","price":"8831.69000000","side":"sell","client_oid":"1700a8b1-6ef6-413d-b1bd-7df1579ae6ab","product_id":"BTC-EUR","sequence":3257976411,"time":"2018-01-22T15:14:11.220000Z"}
{"type":"open","side":"sell","price":"8831.69000000","order_id":"80ee1692-b809-4916-aeb3-90920041ea09","remaining_size":"1.00000000","product_id":"BTC-EUR","sequence":3257976412,"time":"2018-01-22T15:14:11.220000Z"}
{"type":"done","side":"sell","order_id":"6ba6dc77-a40e-4945-927e-28a353df095d","reason":"canceled","product_id":"BTC-EUR","price":"8848.98000000","remaining_size":"0.11241548","sequence":3257976413,"time":"2018-01-22T15:14:11.368000Z"}
{"type":"received","order_id":"d72d7352-bbc4-4318-b078-ffe603bc3db5","order_type":"limit","size":"0.18370534","price":"8891.52000000","side":"sell","client_oid":"0ceb7b79-771e-4ebc-87b3-54323a3067b2","product_id":"BTC-EUR","sequence":3257976414,"time":"2018-01-22T15:14:11.414000Z"}
{"type":"open","side":"sell","price":"8891.52000000","order_id":"d72d7352-bbc4-4318-b078-ffe603bc3db5","remaining_size":"0.18370534","product_id":"BTC-EUR","sequence":3257976415,"time":"2018-01-22T15:14:11.414000Z"}
{"type":"received","order_id":"3a49c939-fdbc-40b9-8e57-a9e53d534dd7","order_type":"limit","size":"0.11241548","price":"8848.96000000","side":"sell","product_id":"BTC-EUR","sequence":3257976416,"time":"2018-01-22T15:14:11.501000Z"}
{"type":"open","side":"sell","price":"8848.96000000","order_id":"3a49c939-fdbc-40b9-8e57-a9e53d534dd7","remaining_size":"0.11241548","product_id":"BTC-EUR","sequence":3257976417,"time":"2018-01-22T15:14:11.501000Z"}
{"type":"done","side":"sell","order_id":"ac47d3b9-640c-493a-87f2-92638a1d1e1f","reason":"canceled","product_id":"BTC-EUR","price":"9113.57000000","remaining_size":"1.28000000","sequence":3257976418,"time":"2018-01-22T15:14:11.531000Z"}
{"type":"done","side":"sell","order_id":"31d0977f-772b-4801-934d-1226b70ccca0","reason":"canceled","product_id":"BTC-EUR","price":"8848.96000000","remaining_size":"0.01887096","sequence":3257976419,"time":"2018-01-22T15:14:11.588000Z"}
{"type":"done","side":"sell","order_id":"b5575220-34a8-4ce6-8dda-1081f8e3354b","reason":"canceled","product_id":"BTC-EUR","price":"8848.96000000","remaining_size":"0.22947933","sequence":3257976420,"time":"2018-01-22T15:14:11.598000Z"}
{"type":"done","side":"sell","order_id":"16e5c882-7025-4847-bfd2-2072c89d7ace","reason":"canceled","product_id":"BTC-EUR","price":"8848.96000000","remaining_size":"0.04164971","sequence":3257976421,"time":"2018-01-22T15:14:11.600000Z"}
{"type":"received","order_id":"9f6cea52-4c14-4d1c-b116-bf5e045737ce","order_type":"limit","size":"0.01000000","price":"9096.64000000","side":"buy","product_id":"BTC-EUR","sequence":3257976422,"time":"2018-01-22T15:14:11.650000Z"}
{"type":"match","trade_id":10551304,"maker_order_id":"3a9a3ec7-92be-49d3-8bc8-06901765e0fb","taker_order_id":"9f6cea52-4c14-4d1c-b116-bf5e045737ce","side":"sell","size":"0.01000000","price":"8831.69000000","product_id":"BTC-EUR","sequence":3257976423,"time":"2018-01-22T15:14:11.650000Z"}
{"type":"done","side":"buy","order_id":"9f6cea52-4c14-4d1c-b116-bf5e045737ce","reason":"filled","product_id":"BTC-EUR","price":"9096.64000000","remaining_size":"0.00000000","sequence":3257976424,"time":"2018-01-22T15:14:11.650000Z"}
{"type":"done","side":"buy","order_id":"defb5132-5064-4201-a696-bc0cf631a629","reason":"canceled","product_id":"BTC-EUR","price":"8831.68000000","remaining_size":"0.09800000","sequence":3257976425,"time":"2018-01-22T15:14:11.682000Z"}
{"type":"done","side":"buy","order_id":"994747d2-2f85-4d88-a843-597b1c0921d9","reason":"canceled","product_id":"BTC-EUR","price":"8831.68000000","remaining_size":"0.00200000","sequence":3257976426,"time":"2018-01-22T15:14:11.693000Z"}
{"type":"done","side":"buy","order_id":"5c6d8832-bec6-4856-ba98-158999b041ae","reason":"canceled","product_id":"BTC-EUR","price":"8831.68000000","remaining_size":"0.09800000","sequence":3257976427,"time":"2018-01-22T15:14:11.706000Z"}
{"type":"done","side":"buy","order_id":"9ac428d8-1d59-4190-aa6e-ab811321ad2f","reason":"canceled","product_id":"BTC-EUR","price":"8831.68000000","remaining_size":"0.09800000","sequence":3257976428,"time":"2018-01-22T15:14:11.718000Z"}
{"type":"received","order_id":"b95fd072-8eab-4762-bfc6-2ff5f61e1c24","order_type":"limit","size":"0.09800000","price":"8831.68000000","side":"buy","client_oid":"262acb53-73fe-4cec-8456-b914c002a673","product_id":"BTC-EUR","sequence":3257976429,"time":"2018-01-22T15:14:11.754000Z"}
{"type":"open","side":"buy","price":"8831.68000000","order_id":"b95fd072-8eab-4762-bfc6-2ff5f61e1c24","remaining_size":"0.09800000","product_id":"BTC-EUR","sequence":3257976430,"time":"2018-01-22T15:14:11.754000Z"}
{"type":"received","order_id":"151b352f-cdfd-4071-8dd1-2f5c7aa6ea1e","order_type":"limit","size":"0.21404538","price":"8831.69000000","side":"sell","product_id":"BTC-EUR","sequence":3257976431,"time":"2018-01-22T15:14:11.755000Z"}
{"type":"open","side":"sell","price":"8831.69000000","order_id":"151b352f-cdfd-4071-8dd1-2f5c7aa6ea1e","remaining_size":"0.21404538","product_id":"BTC-EUR","sequence":3257976432,"time":"2018-01-22T15:14:11.755000Z"}
{"type":"done","side":"buy","order_id":"20f6ca71-d28d-470c-a196-1d3ea5bf4092","reason":"canceled","product_id":"BTC-EUR","price":"8831.68000000","remaining_size":"0.10500000","sequence":3257976433,"time":"2018-01-22T15:14:11.782000Z"}
{"type":"done","side":"buy","order_id":"f62e8b51-714e-47cb-90f4-abb8d982cfc2","reason":"canceled","product_id":"BTC-EUR","price":"8831.68000000","remaining_size":"0.10500000","sequence":3257976434,"time":"2018-01-22T15:14:11.794000Z"}
{"type":"received","order_id":"bb113f6f-3aed-4024-bdeb-0ebbd4162b9d","order_type":"limit","size":"0.01887096","price":"8848.94000000","side":"sell","client_oid":"bcf8175c-21d3-4469-93d1-ea6859fda184","product_id":"BTC-EUR","sequence":3257976435,"time":"2018-01-22T15:14:11.835000Z"}
{"type":"open","side":"sell","price":"8848.94000000","order_id":"bb113f6f-3aed-4024-bdeb-0ebbd4162b9d","remaining_size":"0.01887096","product_id":"BTC-EUR","sequence":3257976436,"time":"2018-01-22T15:14:11.835000Z"}
{"type":"received","order_id":"482b3081-b938-40ab-9b47-fddb6ecc6753","order_type":"limit","size":"0.22947933","price":"8848.94000000","side":"sell","client_oid":"fcee4475-1397-403f-bb36-391c92c301d4","product_id":"BTC-EUR","sequence":3257976437,"time":"2018-01-22T15:14:11.847000Z"}
{"type":"open","side":"sell","price":"8848.94000000","order_id":"482b3081-b938-40ab-9b47-fddb6ecc6753","remaining_size":"0.22947933","product_id":"BTC-EUR","sequence":3257976438,"time":"2018-01-22T15:14:11.847000Z"}
{"type":"received","order_id":"2134ea33-9094-40fb-886c-7eb6f4c25bd8","order_type":"limit","size":"0.04164971","price":"8848.94000000","side":"sell","client_oid":"d331ea60-83d8-4bf7-9830-3c276ec86a4c","product_id":"BTC-EUR","sequence":3257976439,"time":"2018-01-22T15:14:11.936000Z"}
{"type":"open","side":"sell","price":"8848.94000000","order_id":"2134ea33-9094-40fb-886c-7eb6f4c25bd8","remaining_size":"0.04164971","product_id":"BTC-EUR","sequence":3257976440,"time":"2018-01-22T15:14:11.936000Z"}
{"type":"done","side":"buy","order_id":"12f646b2-d9f7-412a-993d-60fc1a66ab73","reason":"canceled","product_id":"BTC-EUR","price":"8760.01000000","remaining_size":"6.41544856","sequence":3257976441,"time":"2018-01-22T15:14:11.955000Z"}
{"type":"done","side":"buy","order_id":"b95fd072-8eab-4762-bfc6-2ff5f61e1c24","reason":"canceled","product_id":"BTC-EUR","price":"8831.68000000","remaining_size":"0.09800000","sequence":3257976442,"time":"2018-01-22T15:14:12.013000Z"}
{"type":"done","side":"buy","order_id":"07ec33d9-aefa-479f-aa23-5f86e342b465","reason":"canceled","product_id":"BTC-EUR","price":"8831.68000000","remaining_size":"0.10500000","sequence":3257976443,"time":"2018-01-22T15:14:12.015000Z"}
{"type":"done","side":"buy","order_id":"e4f862e4-89d1-4da0-bdb2-b613dd921fa1","reason":"canceled","product_id":"BTC-EUR","price":"8631.07000000","remaining_size":"1.28000000","sequence":3257976444,"time":"2018-01-22T15:14:12.056000Z"}
{"type":"received","order_id":"9dd189a5-5ca0-45f1-8525-9d2553759d33","order_type":"limit","size":"0.01000000","price":"9096.64000000","side":"buy","product_id":"BTC-EUR","sequence":3257976445,"time":"2018-01-22T15:14:12.211000Z"}
{"type":"match","trade_id":10551305,"maker_order_id":"3a9a3ec7-92be-49d3-8bc8-06901765e0fb","taker_order_id":"9dd189a5-5ca0-45f1-8525-9d2553759d33","side":"sell","size":"0.01000000","price":"8831.69000000","product_id":"BTC-EUR","sequence":3257976446,"time":"2018-01-22T15:14:12.211000Z"}
{"type":"done","side":"buy","order_id":"9dd189a5-5ca0-45f1-8525-9d2553759d33","reason":"filled","product_id":"BTC-EUR","price":"9096.64000000","remaining_size":"0.00000000","sequence":3257976447,"time":"2018-01-22T15:14:12.211000Z"}
{"type":"received","order_id":"e28b2282-0be9-4f08-8a4b-36c6dfc46676","order_type":"limit","size":"0.75000000","price":"8948.31000000","side":"sell","client_oid":"e35ded53-e6aa-4cb1-a706-4a7e077c20a7","product_id":"BTC-EUR","sequence":3257976448,"time":"2018-01-22T15:14:12.220000Z"}
{"type":"open","side":"sell","price":"8948.31000000","order_id":"e28b2282-0be9-4f08-8a4b-36c6dfc46676","remaining_size":"0.75000000","product_id":"BTC-EUR","sequence":3257976449,"time":"2018-01-22T15:14:12.220000Z"}
{"type":"done","side":"buy","order_id":"54322bae-b711-4ba3-9269-fe78dbe4c071","reason":"canceled","product_id":"BTC-EUR","price":"8730.38000000","remaining_size":"0.75000000","sequence":3257976450,"time":"2018-01-22T15:14:12.243000Z"}
{"type":"done","side":"sell","order_id":"6684a551-d10c-45f9-b414-1174699ab6f3","reason":"canceled","product_id":"BTC-EUR","price":"9143.48000000","remaining_size":"0.75000000","sequence":3257976451,"time":"2018-01-22T15:14:12.243000Z"}
{"type":"done","side":"buy","order_id":"aeaa99bb-e347-4423-9520-9c8504ec1f27","reason":"canceled","product_id":"BTC-EUR","price":"8637.08000000","remaining_size":"0.75000000","sequence":3257976452,"time":"2018-01-22T15:14:12.263000Z"}
{"type":"done","side":"sell","order_id":"8532631c-3c70-4dcb-98ea-61c7c444b94a","reason":"canceled","product_id":"BTC-EUR","price":"9236.78000000","remaining_size":"0.74000000","sequence":3257976453,"time":"2018-01-22T15:14:12.263000Z"}
{"type":"done","side":"buy","order_id":"1631f4d7-1361-4920-b356-1f781f6b1522","reason":"canceled","product_id":"BTC-EUR","price":"8543.78000000","remaining_size":"0.74000000","sequence":3257976454,"time":"2018-01-22T15:14:12.278000Z"}
{"type":"done","side":"sell","order_id":"70da32ba-55b1-4db9-890a-4e0446885dd0","reason":"canceled","product_id":"BTC-EUR","price":"9330.08000000","remaining_size":"0.75000000","sequence":3257976455,"time":"2018-01-22T15:14:12.278000Z"}
{"type":"done","side":"buy","order_id":"5c5a8bc0-602e-47d3-abd7-a5144eefa2eb","reason":"canceled","product_id":"BTC-EUR","price":"8450.48000000","remaining_size":"0.75000000","sequence":3257976456,"time":"2018-01-22T15:14:12.284000Z"}
{"type":"done","side":"sell","order_id":"8c0c3468-e5a8-4803-b558-af592928b940","reason":"canceled","product_id":"BTC-EUR","price":"9423.38000000","remaining_size":"0.75000000","sequence":3257976457,"time":"2018-01-22T15:14:12.284000Z"}
{"type":"done","side":"buy","order_id":"6eab05aa-19c2-49b9-9cb6-ca43119db2ed","reason":"canceled","product_id":"BTC-EUR","price":"8357.18000000","remaining_size":"0.75000000","sequence":3257976458,"time":"2018-01-22T15:14:12.286000Z"}
{"type":"done","side":"sell","order_id":"506b2d20-877e-4e8d-9eda-5e661501ce91","reason":"canceled","product_id":"BTC-EUR","price":"9516.68000000","remaining_size":"0.75000000","sequence":3257976459,"time":"2018-01-22T15:14:12.287000Z"}
{"type":"done","side":"buy","order_id":"dba3b3e7-d034-44b0-9c43-7449af79db72","reason":"canceled","product_id":"BTC-EUR","price":"8263.88000000","remaining_size":"0.75000000","sequence":3257976460,"time":"2018-01-22T15:14:12.288000Z"}
{"type":"done","side":"sell","order_id":"2c14744b-126f-4d06-9934-ff976ad29b6b","reason":"canceled","product_id":"BTC-EUR","price":"9609.98000000","remaining_size":"0.74000000","sequence":3257976461,"time":"2018-01-22T15:14:12.288000Z"}
{"type":"done","side":"buy","order_id":"981750b8-48e0-42b5-a4e2-cfda4e919536","reason":"canceled","product_id":"BTC-EUR","price":"8170.58000000","remaining_size":"0.74000000","sequence":3257976462,"time":"2018-01-22T15:14:12.289000Z"}
{"type":"done","side":"sell","order_id":"69071e67-4bb5-4c54-ba4e-a7c9795da08e","reason":"canceled","product_id":"BTC-EUR","price":"9703.28000000","remaining_size":"0.75000000","sequence":3257976463,"time":"2018-01-22T15:14:12.289000Z"}
{"type":"done","side":"buy","order_id":"d124288a-2e4c-48bc-8fea-bc8da811cc6f","reason":"canceled","product_id":"BTC-EUR","price":"8077.28000000","remaining_size":"0.75000000","sequence":3257976464,"time":"2018-01-22T15:14:12.290000Z"}
{"type":"done","side":"sell","order_id":"65a85b27-a606-41c0-b8e7-600fd5f0fa97","reason":"canceled","product_id":"BTC-EUR","price":"9796.58000000","remaining_size":"0.75000000","sequence":3257976465,"time":"2018-01-22T15:14:12.290000Z"}
{"type":"done","side":"buy","order_id":"e8b99a6b-9d61-4b81-b529-5c04dab90aa2","reason":"canceled","product_id":"BTC-EUR","price":"7983.98000000","remaining_size":"0.75000000","sequence":3257976466,"time":"2018-01-22T15:14:12.291000Z"}
{"type":"received","order_id":"b14181c0-cb10-4a6d-a15f-0b9fd46dc48a","order_type":"limit","size":"0.25000000","price":"8855.11000000","side":"sell","client_oid":"b6bb87e7-7a9b-47b0-8bc5-94df2d3d796c","product_id":"BTC-EUR","sequence":3257976467,"time":"2018-01-22T15:14:12.291000Z"}
{"type":"open","side":"sell","price":"8855.11000000","order_id":"b14181c0-cb10-4a6d-a15f-0b9fd46dc48a","remaining_size":"0.25000000","product_id":"BTC-EUR","sequence":3257976468,"time":"2018-01-22T15:14:12.291000Z"}
{"type":"received","order_id":"b9b93c43-95d5-4f98-bf6f-fb91dc428494","order_type":"limit","size":"0.75000000","price":"9041.51000000","side":"sell","client_oid":"53afcecd-6c9f-4cec-adbf-c0a9cec4f2dd","product_id":"BTC-EUR","sequence":3257976469,"time":"2018-01-22T15:14:12.292000Z"}
{"type":"open","side":"sell","price":"9041.51000000","order_id":"b9b93c43-95d5-4f98-bf6f-fb91dc428494","remaining_size":"0.75000000","product_id":"BTC-EUR","sequence":3257976470,"time":"2018-01-22T15:14:12.292000Z"}
{"type":"received","order_id":"000ed8bf-7389-4fd1-a929-e3da78546ff9","order_type":"limit","size":"0.75000000","price":"9134.71000000","side":"sell","client_oid":"05b730ae-f72b-4867-8c8a-9619363ec0b8","product_id":"BTC-EUR","sequence":3257976471,"time":"2018-01-22T15:14:12.293000Z"}
{"type":"open","side":"sell","price":"9134.71000000","order_id":"000ed8bf-7389-4fd1-a929-e3da78546ff9","remaining_size":"0.75000000","product_id":"BTC-EUR","sequence":3257976472,"time":"2018-01-22T15:14:12.293000Z"}
{"type":"received","order_id":"c87fa082-dd01-4786-9317-85a6d391e964","order_type":"limit","size":"0.75000000","price":"8721.91000000","side":"buy","client_oid":"2e625b51-53e8-49ad-8925-350588a5b504","product_id":"BTC-EUR","sequence":3257976473,"time":"2018-01-22T15:14:12.294000Z"}
{"type":"open","side":"buy","price":"8721.91000000","order_id":"c87fa082-dd01-4786-9317-85a6d391e964","remaining_size":"0.75000000","product_id":"BTC-EUR","sequence":3257976474,"time":"2018-01-22T15:14:12.294000Z"}
{"type":"received","order_id":"f2855de0-a292-4f93-9e5b-cda58fdc0d28","order_type":"limit","size":"0.75000000","price":"8628.71000000","side":"buy","client_oid":"12d0c208-c3e9-462f-bea0-6af0913be2ba","product_id":"BTC-EUR","sequence":3257976475,"time":"2018-01-22T15:14:12.298000Z"}
{"type":"open","side":"buy","price":"8628.71000000","order_id":"f2855de0-a292-4f93-9e5b-cda58fdc0d28","remaining_size":"0.75000000","product_id":"BTC-EUR","sequence":3257976476,"time":"2018-01-22T15:14:12.298000Z"}
{"type":"received","order_id":"d64b33f8-abc6-4431-b32b-2d1c38738748","order_type":"limit","size":"0.74000000","price":"8535.51000000","side":"buy","client_oid":"ad75e846-8a42-4535-beb7-d06c072d5a07","product_id":"BTC-EUR","sequence":3257976477,"time":"2018-01-22T15:14:12.318000Z"}
{"type":"open","side":"buy","price":"8535.51000000","order_id":"d64b33f8-abc6-4431-b32b-2d1c38738748","remaining_size":"0.74000000","product_id":"BTC-EUR","sequence":3257976478,"time":"2018-01-22T15:14:12.318000Z"}
{"type":"received","order_id":"d421416a-29f0-4aa8-a87d-8e007629245e","order_type":"limit","size":"0.75000000","price":"8442.31000000","side":"buy","client_oid":"67ec2ba7-a0d3-45dc-8a6f-10afe991746b","product_id":"BTC-EUR","sequence":3257976479,"time":"2018-01-22T15:14:12.326000Z"}
{"type":"open","side":"buy","price":"8442.31000000","order_id":"d421416a-29f0-4aa8-a87d-8e007629245e","remaining_size":"0.75000000","product_id":"BTC-EUR","sequence":3257976480,"time":"2018-01-22T15:14:12.326000Z"}
{"type":"received","order_id":"7e6cd0a5-c2cb-44aa-a682-5f410d6b9c9a","order_type":"limit","size":"0.74000000","price":"8162.71000000","side":"buy","client_oid":"aa6a4d5e-9dcb-441e-bbf6-356bfbea4c66","product_id":"BTC-EUR","sequence":3257976481,"time":"2018-01-22T15:14:12.359000Z"}
{"type":"open","side":"buy","price":"8162.71000000","order_id":"7e6cd0a5-c2cb-44aa-a682-5f410d6b9c9a","remaining_size":"0.74000000","product_id":"BTC-EUR","sequence":3257976482,"time":"2018-01-22T15:14:12.359000Z"}
{"type":"received","order_id":"842516ff-a87d-40f7-bef5-30a8020d4d34","order_type":"limit","size":"0.75000000","price":"9693.91000000","side":"sell","client_oid":"41a2dfc3-787e-4880-8041-0c550633b58a","product_id":"BTC-EUR","sequence":3257976483,"time":"2018-01-22T15:14:12.374000Z"}
{"type":"open","side":"sell","price":"9693.91000000","order_id":"842516ff-a87d-40f7-bef5-30a8020d4d34","remaining_size":"0.75000000","product_id":"BTC-EUR","sequence":3257976484,"time":"2018-01-22T15:14:12.374000Z"}
{"type":"received","order_id":"942b45cd-3665-4511-80d6-a7e218313c95","order_type":"limit","size":"0.75000000","price":"9787.11000000","side":"sell","client_oid":"be16e73a-9483-41fe-a8f9-fc229215fa69","product_id":"BTC-EUR","sequence":3257976485,"time":"2018-01-22T15:14:12.386000Z"}
{"type":"open","side":"sell","price":"9787.11000000","order_id":"942b45cd-3665-4511-80d6-a7e218313c95","remaining_size":"0.75000000","product_id":"BTC-EUR","sequence":3257976486,"time":"2018-01-22T15:14:12.386000Z"}
{"type":"received","order_id":"11b06ec8-5d13-46da-a840-23f908212c63","order_type":"limit","size":"0.75000000","price":"8069.51000000","side":"buy","client_oid":"ded64631-358f-45b0-add1-cda635ccbd4a","product_id":"BTC-EUR","sequence":3257976487,"time":"2018-01-22T15:14:12.387000Z"}
{"type":"open","side":"buy","price":"8069.51000000","order_id":"11b06ec8-5d13-46da-a840-23f908212c63","remaining_size":"0.75000000","product_id":"BTC-EUR","sequence":3257976488,"time":"2018-01-22T15:14:12.387000Z"}
{"type":"done","side":"sell","order_id":"4e25a980-1f23-428d-a9d9-485bf1c7a8ff","reason":"canceled","product_id":"BTC-EUR","price":"9020.15000000","remaining_size":"0.50000000","sequence":3257976489,"time":"2018-01-22T15:14:12.401000Z"}
{"type":"received","order_id":"fb26097a-3311-4f47-963e-f3d457ea571b","order_type":"limit","size":"0.75000000","price":"8255.91000000","side":"buy","client_oid":"9f47d683-f627-40f0-8d85-6db8df00e08c","product_id":"BTC-EUR","sequence":3257976490,"time":"2018-01-22T15:14:12.481000Z"}
{"type":"open","side":"buy","price":"8255.91000000","order_id":"fb26097a-3311-4f47-963e-f3d457ea571b","remaining_size":"0.75000000","product_id":"BTC-EUR","sequence":3257976491,"time":"2018-01-22T15:14:12.481000Z"}
{"type":"received","order_id":"a85d5a6b-48f1-4aeb-8624-60c10918519f","order_type":"limit","size":"0.74000000","price":"9227.91000000","side":"sell","client_oid":"33a9e2fa-1961-4fea-bcb9-504ee22785b3","product_id":"BTC-EUR","sequence":3257976492,"time":"2018-01-22T15:14:12.481000Z"}
{"type":"open","side":"sell","price":"9227.91000000","order_id":"a85d5a6b-48f1-4aeb-8624-60c10918519f","remaining_size":"0.74000000","product_id":"BTC-EUR","sequence":3257976493,"time":"2018-01-22T15:14:12.481000Z"}
{"type":"received","order_id":"e64dd9e1-ea82-4e15-989d-4020a75bad35","order_type":"limit","size":"0.75000000","price":"8349.11000000","side":"buy","client_oid":"6e38ddab-ce59-496f-a81b-d6e46b2c9bf0","product_id":"BTC-EUR","sequence":3257976494,"time":"2018-01-22T15:14:12.481000Z"}
{"type":"open","side":"buy","price":"8349.11000000","order_id":"e64dd9e1-ea82-4e15-989d-4020a75bad35","remaining_size":"0.75000000","product_id":"BTC-EUR","sequence":3257976495,"time":"2018-01-22T15:14:12.481000Z"}
{"type":"received","order_id":"0ce16003-a9e5-40a3-a6f1-358dcac85637","order_type":"limit","size":"0.75000000","price":"7976.31000000","side":"buy","client_oid":"1d9d7671-58f2-4ccc-9d82-ecd19514b98a","product_id":"BTC-EUR","sequence":3257976496,"time":"2018-01-22T15:14:12.482000Z"}
{"type":"open","side":"buy","price":"7976.31000000","order_id":"0ce16003-a9e5-40a3-a6f1-358dcac85637","remaining_size":"0.75000000","product_id":"BTC-EUR","sequence":3257976497,"time":"2018-01-22T15:14:12.482000Z"}
{"type":"done","side":"buy","order_id":"74c53770-74ab-4472-b4e3-99712f931703","reason":"canceled","product_id":"BTC-EUR","price":"8500.00000000","remaining_size":"0.04142991","sequence":3257976498,"time":"2018-01-22T15:14:12.515000Z"}
{"type":"received","order_id":"f926c19b-e597-43cd-9317-8c52ce89c9ae","order_type":"limit","size":"0.75000000","price":"9321.11000000","side":"sell","client_oid":"fab85f0f-99bc-41e9-ac36-86d36eba527d","product_id":"BTC-EUR","sequence":3257976499,"time":"2018-01-22T15:14:12.536000Z"}
{"type":"open","side":"sell","price":"9321.11000000","order_id":"f926c19b-e597-43cd-9317-8c52ce89c9ae","remaining_size":"0.75000000","product_id":"BTC-EUR","sequence":3257976500,"time":"2018-01-22T15:14:12.536000Z"}
{"type":"received","order_id":"9b115cd4-9848-48f4-b0b0-d4e1d7dd9968","order_type":"limit","size":"0.75000000","price":"9414.31000000","side":"sell","client_oid":"80b19063-05e2-41fe-9c75-94ca074aea4a","product_id":"BTC-EUR","sequence":3257976501,"time":"2018-01-22T15:14:12.550000Z"}
{"type":"open","side":"sell","price":"9414.31000000","order_id":"9b115cd4-9848-48f4-b0b0-d4e1d7dd9968","remaining_size":"0.75000000","product_id":"BTC-EUR","sequence":3257976502,"time":"2018-01-22T15:14:12.550000Z"}
{"type":"received","order_id":"d7551aa1-0359-453a-8076-59d752c9d56a","order_type":"limit","size":"0.75000000","price":"9507.51000000","side":"sell","client_oid":"56988c4e-1371-49c8-8f2c-f293f27ba73c","product_id":"BTC-EUR","sequence":3257976503,"time":"2018-01-22T15:14:12.554000Z"}
{"type":"open","side":"sell","price":"9507.51000000","order_id":"d7551aa1-0359-453a-8076-59d752c9d56a","remaining_size":"0.75000000","product_id":"BTC-EUR","sequence":3257976504,"time":"2018-01-22T15:14:12.554000Z"}
{"type":"received","order_id":"e6826f5d-e38f-462e-a38d-64ea715cbdd1","order_type":"limit","size":"0.74000000","price":"9600.71000000","side":"sell","client_oid":"6dbb6a58-7ee3-4a5b-a3e6-a8dba31b5d4c","product_id":"BTC-EUR","sequence":3257976505,"time":"2018-01-22T15:14:12.560000Z"}
{"type":"open","side":"sell","price":"9600.71000000","order_id":"e6826f5d-e38f-462e-a38d-64ea715cbdd1","remaining_size":"0.74000000","product_id":"BTC-EUR","sequence":3257976506,"time":"2018-01-22T15:14:12.560000Z"}
{"type":"done","side":"sell","order_id":"3a49c939-fdbc-40b9-8e57-a9e53d534dd7","reason":"canceled","product_id":"BTC-EUR","price":"8848.96000000","remaining_size":"0.11241548","sequence":3257976507,"time":"2018-01-22T15:14:13.014000Z"}
{"type":"received","order_id":"a7118cd7-d92a-4377-b041-c3b5e5b11621","order_type":"limit","size":"0.58423000","price":"8899.87000000","side":"sell","product_id":"BTC-EUR","sequence":3257976508,"time":"2018-01-22T15:14:13.092000Z"}
{"type":"open","side":"sell","price":"8899.87000000","order_id":"a7118cd7-d92a-4377-b041-c3b5e5b11621","remaining_size":"0.58423000","product_id":"BTC-EUR","sequence":3257976509,"time":"2018-01-22T15:14:13.092000Z"}
{"type":"received","order_id":"0a38c861-a210-47d1-94df-52b118f38df8","order_type":"limit","size":"0.05700000","price":"8831.50000000","side":"buy","client_oid":"676c8dae-e745-40a0-b291-e1bbea45f0dd","product_id":"BTC-EUR","sequence":3257976510,"time":"2018-01-22T15:14:13.106000Z"}
{"type":"open","side":"buy","price":"8831.50000000","order_id":"0a38c861-a210-47d1-94df-52b118f38df8","remaining_size":"0.05700000","product_id":"BTC-EUR","sequence":3257976511,"time":"2018-01-22T15:14:13.106000Z"}
{"type":"received","order_id":"9a9867d9-84cd-48c7-9074-b449149455b8","order_type":"limit","size":"0.11241548","price":"8848.94000000","side":"sell","product_id":"BTC-EUR","sequence":3257976512,"time":"2018-01-22T15:14:13.136000Z"}
{"type":"open","side":"sell","price":"8848.94000000","order_id":"9a9867d9-84cd-48c7-9074-b449149455b8","remaining_size":"0.11241548","product_id":"BTC-EUR","sequence":3257976513,"time":"2018-01-22T15:14:13.136000Z"}
{"type":"received","order_id":"a6b43a50-b059-4878-bb80-d370568ea518","order_type":"limit","size":"6.41544856","price":"8769.07000000","side":"buy","product_id":"BTC-EUR","sequence":3257976514,"time":"2018-01-22T15:14:13.174000Z"}
{"type":"open","side":"buy","price":"8769.07000000","order_id":"a6b43a50-b059-4878-bb80-d370568ea518","remaining_size":"6.41544856","product_id":"BTC-EUR","sequence":3257976515,"time":"2018-01-22T15:14:13.174000Z"}
{"type":"done","side":"buy","order_id":"a33d2d0c-2bd1-4556-a85c-9d0ea345cb01","reason":"canceled","product_id":"BTC-EUR","price":"8654.20000000","remaining_size":"1.89631000","sequence":3257976516,"time":"2018-01-22T15:14:13.208000Z"}
{"type":"received","order_id":"d248d06d-883f-4b84-83bb-64492e623182","order_type":"limit","size":"1.89570000","price":"8657.40000000","side":"buy","client_oid":"87802643-8f65-4b81-aeae-61daf8b43da5","product_id":"BTC-EUR","sequence":3257976517,"time":"2018-01-22T15:14:13.220000Z"}
{"type":"open","side":"buy","price":"8657.40000000","order_id":"d248d06d-883f-4b84-83bb-64492e623182","remaining_size":"1.89570000","product_id":"BTC-EUR","sequence":3257976518,"time":"2018-01-22T15:14:13.220000Z"}
{"type":"done","side":"sell","order_id":"2134ea33-9094-40fb-886c-7eb6f4c25bd8","reason":"canceled","product_id":"BTC-EUR","price":"8848.94000000","remaining_size":"0.04164971","sequence":3257976519,"time":"2018-01-22T15:14:13.276000Z"}
{"type":"done","side":"sell","order_id":"482b3081-b938-40ab-9b47-fddb6ecc6753","reason":"canceled","product_id":"BTC-EUR","price":"8848.94000000","remaining_size":"0.22947933","sequence":3257976520,"time":"2018-01-22T15:14:13.283000Z"}
{"type":"done","side":"sell","order_id":"bb113f6f-3aed-4024-bdeb-0ebbd4162b9d","reason":"canceled","product_id":"BTC-EUR","price":"8848.94000000","remaining_size":"0.01887096","sequence":3257976521,"time":"2018-01-22T15:14:13.298000Z"}
{"type":"received","order_id":"2139893f-a59d-4d15-8136-d588790db82f","order_type":"limit","size":"0.04164971","price":"8848.92000000","side":"sell","client_oid":"8c3cc5e8-bde3-442f-a05b-f05f76fc54c7","product_id":"BTC-EUR","sequence":3257976522,"time":"2018-01-22T15:14:13.525000Z"}
{"type":"open","side":"sell","price":"8848.92000000","order_id":"2139893f-a59d-4d15-8136-d588790db82f","remaining_size":"0.04164971","product_id":"BTC-EUR","sequence":3257976523,"time":"2018-01-22T15:14:13.525000Z"}
{"type":"received","order_id":"78e28bbc-360f-4e73-81fa-961e3ea41e72","order_type":"limit","size":"0.01887096","price":"8848.92000000","side":"sell","client_oid":"f4fedfab-d1fd-449b-93fe-8d518547c9d1","product_id":"BTC-EUR","sequence":3257976524,"time":"2018-01-22T15:14:13.541000Z"}
{"type":"open","side":"sell","price":"8848.92000000","order_id":"78e28bbc-360f-4e73-81fa-961e3ea41e72","remaining_size":"0.01887096","product_id":"BTC-EUR","sequence":3257976525,"time":"2018-01-22T15:14:13.541000Z"}
{"type":"received","order_id":"b7db123d-8c84-4341-973f-fe1332206428","order_type":"limit","size":"0.22947933","price":"8848.92000000","side":"sell","client_oid":"eadcb79e-2f8a-4c8b-8c6d-695384db3976","product_id":"BTC-EUR","sequence":3257976526,"time":"2018-01-22T15:14:13.552000Z"}
{"type":"open","side":"sell","price":"8848.92000000","order_id":"b7db123d-8c84-4341-973f-fe1332206428","remaining_size":"0.22947933","product_id":"BTC-EUR","sequence":3257976527,"time":"2018-01-22T15:14:13.552000Z"}
{"type":"received","order_id":"9a6c0ec6-a123-430b-8040-b79040ab53ba","order_type":"limit","size":"0.04000000","price":"9096.64000000","side":"buy","product_id":"BTC-EUR","sequence":3257976528,"time":"2018-01-22T15:14:13.629000Z"}
{"type":"match","trade_id":10551306,"maker_order_id":"3a9a3ec7-92be-49d3-8bc8-06901765e0fb","taker_order_id":"9a6c0ec6-a123-430b-8040-b79040ab53ba","side":"sell","size":"0.04000000","price":"8831.69000000","product_id":"BTC-EUR","sequence":3257976529,"time":"2018-01-22T15:14:13.629000Z"}
{"type":"done","side":"buy","order_id":"9a6c0ec6-a123-430b-8040-b79040ab53ba","reason":"filled","product_id":"BTC-EUR","price":"9096.64000000","remaining_size":"0.00000000","sequence":3257976530,"time":"2018-01-22T15:14:13.629000Z"}
{"type":"received","order_id":"f79df329-22ed-4a9e-ad20-db1614367a61","order_type":"limit","size":"0.05000000","price":"8800.00000000","side":"buy","client_oid":"56577bd0-9b70-4996-dba4-9969628db750","product_id":"BTC-EUR","sequence":3257976531,"time":"2018-01-22T15:14:13.677000Z"}
{"type":"open","side":"buy","price":"8800.00000000","order_id":"f79df329-22ed-4a9e-ad20-db1614367a61","remaining_size":"0.05000000","product_id":"BTC-EUR","sequence":3257976532,"time":"2018-01-22T15:14:13.677000Z"}
{"type":"received","order_id":"1f56f788-ed3b-41ab-b125-84560a409bb9","order_type":"limit","size":"1.28000000","price":"9108.88000000","side":"sell","product_id":"BTC-EUR","sequence":3257976533,"time":"2018-01-22T15:14:13.733000Z"}
{"type":"open","side":"sell","price":"9108.88000000","order_id":"1f56f788-ed3b-41ab-b125-84560a409bb9","remaining_size":"1.28000000","product_id":"BTC-EUR","sequence":3257976534,"time":"2018-01-22T15:14:13.733000Z"}
{"type":"received","order_id":"65b1f7ee-66f3-4016-ab2b-87dcb225331e","order_type":"limit","size":"0.02755676","price":"8831.69000000","side":"sell","product_id":"BTC-EUR","sequence":3257976535,"time":"2018-01-22T15:14:13.745000Z"}
{"type":"open","side":"sell","price":"8831.69000000","order_id":"65b1f7ee-66f3-4016-ab2b-87dcb225331e","remaining_size":"0.02755676","product_id":"BTC-EUR","sequence":3257976536,"time":"2018-01-22T15:14:13.745000Z"}
{"type":"received","order_id":"e3852930-11e1-467c-9b3a-22588d701aad","order_type":"limit","size":"0.18000000","price":"9096.64000000","side":"buy","product_id":"BTC-EUR","sequence":3257976537,"time":"2018-01-22T15:14:13.830000Z"}
{"type":"match","trade_id":10551307,"maker_order_id":"3a9a3ec7-92be-49d3-8bc8-06901765e0fb","taker_order_id":"e3852930-11e1-467c-9b3a-22588d701aad","side":"sell","size":"0.11770364","price":"8831.69000000","product_id":"BTC-EUR","sequence":3257976538,"time":"2018-01-22T15:14:13.830000Z"}
{"type":"done","side":"sell","order_id":"3a9a3ec7-92be-49d3-8bc8-06901765e0fb","reason":"filled","product_id":"BTC-EUR","price":"8831.69000000","remaining_size":"0","sequence":3257976539,"time":"2018-01-22T15:14:13.830000Z"}
{"type":"match","trade_id":10551308,"maker_order_id":"bd1de588-6a78-4efa-9629-30fd253ff85b","taker_order_id":"e3852930-11e1-467c-9b3a-22588d701aad","side":"sell","size":"0.06229636","price":"8831.69000000","product_id":"BTC-EUR","sequence":3257976540,"time":"2018-01-22T15:14:13.830000Z"}
{"type":"done","side":"buy","order_id":"e3852930-11e1-467c-9b3a-22588d701aad","reason":"filled","product_id":"BTC-EUR","price":"9096.64000000","remaining_size":"0.00000000","sequence":3257976541,"time":"2018-01-22T15:14:13.830000Z"}
{"type":"done","side":"buy","order_id":"a6b43a50-b059-4878-bb80-d370568ea518","reason":"canceled","product_id":"BTC-EUR","price":"8769.07000000","remaining_size":"6.41544856","sequence":3257976542,"time":"2018-01-22T15:14:13.896000Z"}
{"type":"done","side":"sell","order_id":"d72d7352-bbc4-4318-b078-ffe603bc3db5","reason":"canceled","product_id":"BTC-EUR","price":"8891.52000000","remaining_size":"0.18370534","sequence":3257976543,"time":"2018-01-22T15:14:13.955000Z"}
{"type":"received","order_id":"fe15fb54-91d6-4722-80e1-531e673664a6","order_type":"limit","size":"0.04000000","price":"9096.64000000","side":"buy","product_id":"BTC-EUR","sequence":3257976544,"time":"2018-01-22T15:14:13.993000Z"}
{"type":"match","trade_id":10551309,"maker_order_id":"bd1de588-6a78-4efa-9629-30fd253ff85b","taker_order_id":"fe15fb54-91d6-4722-80e1-531e673664a6","side":"sell","size":"0.01944911","price":"8831.69000000","product_id":"BTC-EUR","sequence":3257976545,"time":"2018-01-22T15:14:13.993000Z"}
{"type":"done","side":"sell","order_id":"bd1de588-6a78-4efa-9629-30fd253ff85b","reason":"filled","product_id":"BTC-EUR","price":"8831.69000000","remaining_size":"0","sequence":3257976546,"time":"2018-01-22T15:14:13.993000Z"}
{"type":"match","trade_id":10551310,"maker_order_id":"a3ea415b-6f77-43fc-8c37-30450d1afc4a","taker_order_id":"fe15fb54-91d6-4722-80e1-531e673664a6","side":"sell","size":"0.02055089","price":"8831.69000000","product_id":"BTC-EUR","sequence":3257976547,"time":"2018-01-22T15:14:13.993000Z"}
{"type":"done","side":"buy","order_id":"fe15fb54-91d6-4722-80e1-531e673664a6","reason":"filled","product_id":"BTC-EUR","price":"9096.64000000","remaining_size":"0.00000000","sequence":3257976548,"time":"2018-01-22T15:14:13.993000Z"}
{"type":"received","order_id":"157fa50a-98ba-4e46-9ff8-dc5dc86a688a","order_type":"limit","size":"1.28000000","price":"8632.91000000","side":"buy","product_id":"BTC-EUR","sequence":3257976549,"time":"2018-01-22T15:14:14.070000Z"}
{"type":"open","side":"buy","price":"8632.91000000","order_id":"157fa50a-98ba-4e46-9ff8-dc5dc86a688a","remaining_size":"1.28000000","product_id":"BTC-EUR","sequence":3257976550,"time":"2018-01-22T15:14:14.070000Z"}
{"type":"done","side":"sell","order_id":"a3ea415b-6f77-43fc-8c37-30450d1afc4a","reason":"canceled","product_id":"BTC-EUR","price":"8831.69000000","remaining_size":"0.00389172","sequence":3257976551,"time":"2018-01-22T15:14:14.075000Z"}
{"type":"received","order_id":"1c1369b2-f303-4418-9d1f-bb3155b20093","order_type":"limit","size":"0.18394187","price":"8880.09000000","side":"sell","client_oid":"3ba40e2b-c964-4587-9b6e-a982c3fe1aa8","product_id":"BTC-EUR","sequence":3257976552,"time":"2018-01-22T15:14:14.249000Z"}
{"type":"open","side":"sell","price":"8880.09000000","order_id":"1c1369b2-f303-4418-9d1f-bb3155b20093","remaining_size":"0.18394187","product_id":"BTC-EUR","sequence":3257976553,"time":"2018-01-22T15:14:14.249000Z"}
{"type":"received","order_id":"93ab7534-55f0-4a84-a7be-5f5e423624fb","order_type":"limit","size":"0.05343354","price":"8831.69000000","side":"sell","product_id":"BTC-EUR","sequence":3257976554,"time":"2018-01-22T15:14:14.252000Z"}
{"type":"open","side":"sell","price":"8831.69000000","order_id":"93ab7534-55f0-4a84-a7be-5f5e423624fb","remaining_size":"0.05343354","product_id":"BTC-EUR","sequence":3257976555,"time":"2018-01-22T15:14:14.252000Z"}
{"type":"received","order_id":"18df9695-56c6-494a-98a0-a24f92584525","order_type":"limit","size":"0.02900000","price":"9090.52000000","side":"buy","product_id":"BTC-EUR","sequence":3257976556,"time":"2018-01-22T15:14:14.254000Z"}
{"type":"match","trade_id":10551311,"maker_order_id":"061c5e76-5aae-4b88-8d45-63876a6b3f32","taker_order_id":"18df9695-56c6-494a-98a0-a24f92584525","side":"sell","size":"0.00113228","price":"8831.69000000","product_id":"BTC-EUR","sequence":3257976557,"time":"2018-01-22T15:14:14.254000Z"}
{"type":"done","side":"sell","order_id":"061c5e76-5aae-4b88-8d45-63876a6b3f32","reason":"filled","product_id":"BTC-EUR","price":"8831.69000000","remaining_size":"0","sequence":3257976558,"time":"2018-01-22T15:14:14.254000Z"}
{"type":"match","trade_id":10551312,"maker_order_id":"05c3704a-bdd3-4696-a90b-d60658d88540","taker_order_id":"18df9695-56c6-494a-98a0-a24f92584525","side":"sell","size":"0.02786772","price":"8831.69000000","product_id":"BTC-EUR","sequence":3257976559,"time":"2018-01-22T15:14:14.254000Z"}
{"type":"done","side":"buy","order_id":"18df9695-56c6-494a-98a0-a24f92584525","reason":"filled","product_id":"BTC-EUR","price":"9090.52000000","remaining_size":"0.00000000","sequence":3257976560,"time":"2018-01-22T15:14:14.254000Z"}
{"type":"received","order_id":"6bb17697-d648-4dc6-ad60-1837c18d8686","order_type":"limit","size":"0.00113228","price":"8831.69000000","side":"sell","client_oid":"c6c5abf2-94f7-40e1-9608-456eed452528","product_id":"BTC-EUR","sequence":3257976561,"time":"2018-01-22T15:14:14.277000Z"}
{"type":"open","side":"sell","price":"8831.69000000","order_id":"6bb17697-d648-4dc6-ad60-1837c18d8686","remaining_size":"0.00113228","product_id":"BTC-EUR","sequence":3257976562,"time":"2018-01-22T15:14:14.277000Z"}
{"type":"received","order_id":"da56b34e-b82d-48b0-9300-cf60be8eb663","order_type":"limit","size":"1.00000000","price":"8831.68000000","side":"buy","client_oid":"f89d046d-3283-4aed-81b5-f257f61ca7b5","product_id":"BTC-EUR","sequence":3257976563,"time":"2018-01-22T15:14:14.416000Z"}
{"type":"open","side":"buy","price":"8831.68000000","order_id":"da56b34e-b82d-48b0-9300-cf60be8eb663","remaining_size":"1.00000000","product_id":"BTC-EUR","sequence":3257976564,"time":"2018-01-22T15:14:14.416000Z"}
{"type":"received","order_id":"a7ec793e-276e-45f5-ac00-dd8b93c4256a","order_type":"limit","size":"0.00500000","price":"8832.00000000","side":"sell","client_oid":"3effe01d-ba92-463e-c220-41eea21a1aa1","product_id":"BTC-EUR","sequence":3257976565,"time":"2018-01-22T15:14:14.425000Z"}
{"type":"open","side":"sell","price":"8832.00000000","order_id":"a7ec793e-276e-45f5-ac00-dd8b93c4256a","remaining_size":"0.00500000","product_id":"BTC-EUR","sequence":3257976566,"time":"2018-01-22T15:14:14.425000Z"}
{"type":"done","side":"buy","order_id":"7962ffac-ed8e-435f-9235-93b05c00287b","reason":"canceled","product_id":"BTC-EUR","price":"8823.34000000","remaining_size":"0.02243610","sequence":3257976567,"time":"2018-01-22T15:14:14.488000Z"}
{"type":"done","side":"sell","order_id":"78e28bbc-360f-4e73-81fa-961e3ea41e72","reason":"canceled","product_id":"BTC-EUR","price":"8848.92000000","remaining_size":"0.01887096","sequence":3257976568,"time":"2018-01-22T15:14:14.702000Z"}
{"type":"done","side":"sell","order_id":"b7db123d-8c84-4341-973f-fe1332206428","reason":"canceled","product_id":"BTC-EUR","price":"8848.92000000","remaining_size":"0.22947933","sequence":3257976569,"time":"2018-01-22T15:14:14.707000Z"}
{"type":"received","order_id":"e23d60ab-f089-4ee7-856d-39f7d722bfb4","order_type":"limit","size":"0.15081048","price":"8831.68000000","side":"buy","client_oid":"fdd2dc74-cb59-4462-a9a7-fad774cb78c5","product_id":"BTC-EUR","sequence":3257976570,"time":"2018-01-22T15:14:14.837000Z"}
{"type":"open","side":"buy","price":"8831.68000000","order_id":"e23d60ab-f089-4ee7-856d-39f7d722bfb4","remaining_size":"0.15081048","product_id":"BTC-EUR","sequence":3257976571,"time":"2018-01-22T15:14:14.837000Z"}
{"type":"done","side":"sell","order_id":"9a9867d9-84cd-48c7-9074-b449149455b8","reason":"canceled","product_id":"BTC-EUR","price":"8848.94000000","remaining_size":"0.11241548","sequence":3257976572,"time":"2018-01-22T15:14:14.905000Z"}
{"type":"received","order_id":"3b208405-2307-40a0-b641-f2c7671b0203","order_type":"limit","size":"0.01887096","price":"8831.69000000","side":"sell","client_oid":"34495b3e-8c73-4771-84f6-ea1ff3c964a3","product_id":"BTC-EUR","sequence":3257976573,"time":"2018-01-22T15:14:14.926000Z"}
{"type":"open","side":"sell","price":"8831.69000000","order_id":"3b208405-2307-40a0-b641-f2c7671b0203","remaining_size":"0.01887096","product_id":"BTC-EUR","sequence":3257976574,"time":"2018-01-22T15:14:14.926000Z"}
{"type":"received","order_id":"438d2cf7-e4f6-4205-9d8f-d5ae520fcb9f","order_type":"limit","size":"0.00149900","price":"10970.93000000","side":"sell","client_oid":"a62be4cf-3e46-48b0-b8f6-828b89d4c51a","product_id":"BTC-EUR","sequence":3257976575,"time":"2018-01-22T15:14:14.938000Z"}
{"type":"open","side":"sell","price":"10970.93000000","order_id":"438d2cf7-e4f6-4205-9d8f-d5ae520fcb9f","remaining_size":"0.00149900","product_id":"BTC-EUR","sequence":3257976576,"time":"2018-01-22T15:14:14.938000Z"}
{"type":"received","order_id":"b245912f-a2b8-40c2-8cd4-a5327e5547f5","order_type":"limit","size":"0.22947933","price":"8831.69000000","side":"sell","client_oid":"91eafce0-86ac-4254-97bf-8776aa392718","product_id":"BTC-EUR","sequence":3257976577,"time":"2018-01-22T15:14:14.944000Z"}
{"type":"open","side":"sell","price":"8831.69000000","order_id":"b245912f-a2b8-40c2-8cd4-a5327e5547f5","remaining_size":"0.22947933","product_id":"BTC-EUR","sequence":3257976578,"time":"2018-01-22T15:14:14.944000Z"}
{"type":"done","side":"sell","order_id":"93ab7534-55f0-4a84-a7be-5f5e423624fb","reason":"canceled","product_id":"BTC-EUR","price":"8831.69000000","remaining_size":"0.05343354","sequence":3257976579,"time":"2018-01-22T15:14:14.958000Z"}
{"type":"received","order_id":"45a832f7-2b7e-4911-adb6-0240c19e2f3d","order_type":"limit","size":"0.30970815","price":"8831.68000000","side":"buy","client_oid":"d97e71bc-6a58-4ece-861b-72323863af53","product_id":"BTC-EUR","sequence":3257976580,"time":"2018-01-22T15:14:15.065000Z"}
{"type":"open","side":"buy","price":"8831.68000000","order_id":"45a832f7-2b7e-4911-adb6-0240c19e2f3d","remaining_size":"0.30970815","product_id":"BTC-EUR","sequence":3257976581,"time":"2018-01-22T15:14:15.065000Z"}
{"type":"done","side":"sell","order_id":"2139893f-a59d-4d15-8136-d588790db82f","reason":"canceled","product_id":"BTC-EUR","price":"8848.92000000","remaining_size":"0.04164971","sequence":3257976582,"time":"2018-01-22T15:14:15.070000Z"}
{"type":"received","order_id":"4841f2df-abf7-4cb4-95b7-c3d307b1bd55","order_type":"limit","size":"6.41544856","price":"8755.06000000","side":"buy","product_id":"BTC-EUR","sequence":3257976583,"time":"2018-01-22T15:14:15.071000Z"}
{"type":"open","side":"buy","price":"8755.06000000","order_id":"4841f2df-abf7-4cb4-95b7-c3d307b1bd55","remaining_size":"6.41544856","product_id":"BTC-EUR","sequence":3257976584,"time":"2018-01-22T15:14:15.071000Z"}
{"type":"received","order_id":"4b6622f4-e504-42ed-ba7d-3a232872af99","order_type":"limit","size":"0.11241548","price":"8848.92000000","side":"sell","product_id":"BTC-EUR","sequence":3257976585,"time":"2018-01-22T15:14:15.077000Z"}
{"type":"open","side":"sell","price":"8848.92000000","order_id":"4b6622f4-e504-42ed-ba7d-3a232872af99","remaining_size":"0.11241548","product_id":"BTC-EUR","sequence":3257976586,"time":"2018-01-22T15:14:15.077000Z"}
{"type":"done","side":"sell","order_id":"1c1369b2-f303-4418-9d1f-bb3155b20093","reason":"canceled","product_id":"BTC-EUR","price":"8880.09000000","remaining_size":"0.18394187","sequence":3257976587,"time":"2018-01-22T15:14:15.080000Z"}
{"type":"done","side":"sell","order_id":"e01c1f96-4e77-46e0-b51f-890e7440b0c3","reason":"canceled","product_id":"BTC-EUR","price":"8904.85000000","remaining_size":"0.03773580","sequence":3257976588,"time":"2018-01-22T15:14:15.198000Z"}
{"type":"received","order_id":"2388d0b9-7251-4ce1-bd24-89a6828e05d7","order_type":"limit","size":"0.04164971","price":"8831.69000000","side":"sell","client_oid":"8b9a8d76-aa30-463d-a784-2ab17a18ea47","product_id":"BTC-EUR","sequence":3257976589,"time":"2018-01-22T15:14:15.289000Z"}
{"type":"open","side":"sell","price":"8831.69000000","order_id":"2388d0b9-7251-4ce1-bd24-89a6828e05d7","remaining_size":"0.04164971","product_id":"BTC-EUR","sequence":3257976590,"time":"2018-01-22T15:14:15.289000Z"}
{"type":"done","side":"buy","order_id":"45a832f7-2b7e-4911-adb6-0240c19e2f3d","reason":"canceled","product_id":"BTC-EUR","price":"8831.68000000","remaining_size":"0.30970815","sequence":3257976591,"time":"2018-01-22T15:14:15.289000Z"}
{"type":"received","order_id":"bf6f5cc8-3392-49d4-910f-0cbae1c94849","order_type":"limit","size":"0.05000000","price":"9500.00000000","side":"sell","client_oid":"1c456a8d-f0dc-4d65-ac19-c58b244801f7","product_id":"BTC-EUR","sequence":3257976592,"time":"2018-01-22T15:14:15.310000Z"}
{"type":"open","side":"sell","price":"9500.00000000","order_id":"bf6f5cc8-3392-49d4-910f-0cbae1c94849","remaining_size":"0.05000000","product_id":"BTC-EUR","sequence":3257976593,"time":"2018-01-22T15:14:15.310000Z"}
{"type":"received","order_id":"dfe38310-839d-4643-81a3-fa4a91680103","order_type":"limit","size":"0.10500000","price":"8831.68000000","side":"buy","client_oid":"efc734fb-2d9e-45b8-9759-5ff6f95c454c","product_id":"BTC-EUR","sequence":3257976594,"time":"2018-01-22T15:14:15.382000Z"}
{"type":"open","side":"buy","price":"8831.68000000","order_id":"dfe38310-839d-4643-81a3-fa4a91680103","remaining_size":"0.10500000","product_id":"BTC-EUR","sequence":3257976595,"time":"2018-01-22T15:14:15.382000Z"}
{"type":"done","side":"sell","order_id":"1f56f788-ed3b-41ab-b125-84560a409bb9","reason":"canceled","product_id":"BTC-EUR","price":"9108.88000000","remaining_size":"1.28000000","sequence":3257976596,"time":"2018-01-22T15:14:15.424000Z"}
{"type":"done","side":"buy","order_id":"cc3d8608-09c0-4927-bc8c-85984f7c13a4","reason":"canceled","product_id":"BTC-EUR","price":"8778.62000000","remaining_size":"0.02243610","sequence":3257976597,"time":"2018-01-22T15:14:15.461000Z"}
{"type":"done","side":"buy","order_id":"dfe38310-839d-4643-81a3-fa4a91680103","reason":"canceled","product_id":"BTC-EUR","price":"8831.68000000","remaining_size":"0.10500000","sequence":3257976598,"time":"2018-01-22T15:14:15.462000Z"}
{"type":"done","side":"sell","order_id":"373909ec-131f-4d06-b8ef-e543135ee851","reason":"canceled","product_id":"BTC-EUR","price":"8903.54000000","remaining_size":"0.36857350","sequence":3257976599,"time":"2018-01-22T15:14:15.462000Z"}
{"type":"done","side":"sell","order_id":"96730d0f-b0a2-4bd5-b1e3-edce6f883fd8","reason":"canceled","product_id":"BTC-EUR","price":"8913.11000000","remaining_size":"0.36857350","sequence":3257976600,"time":"2018-01-22T15:14:15.462000Z"}
{"type":"done","side":"sell","order_id":"79122216-695a-4d91-8523-606eac50275f","reason":"canceled","product_id":"BTC-EUR","price":"8915.15000000","remaining_size":"0.19762425","sequence":3257976601,"time":"2018-01-22T15:14:15.463000Z"}
{"type":"done","side":"sell","order_id":"9b6b3fee-f052-4348-8b5d-04ebb6684795","reason":"canceled","product_id":"BTC-EUR","price":"8903.14000000","remaining_size":"0.19762425","sequence":3257976602,"time":"2018-01-22T15:14:15.465000Z"}
{"type":"done","side":"buy","order_id":"352c1c16-6bb1-4a25-af3c-60ff92d2b94f","reason":"canceled","product_id":"BTC-EUR","price":"8822.07000000","remaining_size":"0.01586384","sequence":3257976603,"time":"2018-01-22T15:14:15.466000Z"}
{"type":"received","order_id":"94752897-d6ab-4fe6-a74a-7cf62693113f","order_type":"limit","size":"0.02000000","price":"9096.64000000","side":"buy","product_id":"BTC-EUR","sequence":3257976604,"time":"2018-01-22T15:14:15.528000Z"}
{"type":"match","trade_id":10551313,"maker_order_id":"05c3704a-bdd3-4696-a90b-d60658d88540","taker_order_id":"94752897-d6ab-4fe6-a74a-7cf62693113f","side":"sell","size":"0.02000000","price":"8831.69000000","product_id":"BTC-EUR","sequence":3257976605,"time":"2018-01-22T15:14:15.528000Z"}
{"type":"done","side":"buy","order_id":"94752897-d6ab-4fe6-a74a-7cf62693113f","reason":"filled","product_id":"BTC-EUR","price":"9096.64000000","remaining_size":"0.00000000","sequence":3257976606,"time":"2018-01-22T15:14:15.528000Z"}
{"type":"received","order_id":"83b26ca7-493b-4a2b-b177-3284d3a7694e","order_type":"limit","size":"0.18370534","price":"8891.52000000","side":"sell","client_oid":"c2a0bdb1-2b7d-47dc-b503-70cb43cd5228","product_id":"BTC-EUR","sequence":3257976607,"time":"2018-01-22T15:14:15.630000Z"}
{"type":"open","side":"sell","price":"8891.52000000","order_id":"83b26ca7-493b-4a2b-b177-3284d3a7694e","remaining_size":"0.18370534","product_id":"BTC-EUR","sequence":3257976608,"time":"2018-01-22T15:14:15.630000Z"}
{"type":"done","side":"buy","order_id":"4841f2df-abf7-4cb4-95b7-c3d307b1bd55","reason":"canceled","product_id":"BTC-EUR","price":"8755.06000000","remaining_size":"6.41544856","sequence":3257976609,"time":"2018-01-22T15:14:15.721000Z"}
{"type":"received","order_id":"790ad1df-87a2-4965-8608-1d3c8a4e9667","order_type":"limit","size":"0.30970815","price":"8831.68000000","side":"buy","client_oid":"8ff67bad-a85e-4ec3-8115-2a7a685b9e2f","product_id":"BTC-EUR","sequence":3257976610,"time":"2018-01-22T15:14:15.847000Z"}
{"type":"open","side":"buy","price":"8831.68000000","order_id":"790ad1df-87a2-4965-8608-1d3c8a4e9667","remaining_size":"0.30970815","product_id":"BTC-EUR","sequence":3257976611,"time":"2018-01-22T15:14:15.847000Z"}
{"type":"done","side":"sell","order_id":"83b26ca7-493b-4a2b-b177-3284d3a7694e","reason":"canceled","product_id":"BTC-EUR","price":"8891.52000000","remaining_size":"0.18370534","sequence":3257976612,"time":"2018-01-22T15:14:15.974000Z"}
{"type":"received","order_id":"bed46f86-c71a-45b2-99ec-667b269809fc","order_type":"limit","size":"0.18370534","price":"8891.52000000","side":"sell","client_oid":"50643b54-d903-4f27-9298-8d86b74051d7","product_id":"BTC-EUR","sequence":3257976613,"time":"2018-01-22T15:14:16.244000Z"}
{"type":"open","side":"sell","price":"8891.52000000","order_id":"bed46f86-c71a-45b2-99ec-667b269809fc","remaining_size":"0.18370534","product_id":"BTC-EUR","sequence":3257976614,"time":"2018-01-22T15:14:16.244000Z"}
{"type":"received","order_id":"73900237-3a51-4fd9-8ffb-7d291974dc06","order_type":"limit","size":"0.07000000","price":"9096.64000000","side":"buy","product_id":"BTC-EUR","sequence":3257976615,"time":"2018-01-22T15:14:16.256000Z"}
{"type":"match","trade_id":10551314,"maker_order_id":"05c3704a-bdd3-4696-a90b-d60658d88540","taker_order_id":"73900237-3a51-4fd9-8ffb-7d291974dc06","side":"sell","size":"0.07000000","price":"8831.69000000","product_id":"BTC-EUR","sequence":3257976616,"time":"2018-01-22T15:14:16.256000Z"}
{"type":"done","side":"buy","order_id":"73900237-3a51-4fd9-8ffb-7d291974dc06","reason":"filled","product_id":"BTC-EUR","price":"9096.64000000","remaining_size":"0.00000000","sequence":3257976617,"time":"2018-01-22T15:14:16.256000Z"}
{"type":"received","order_id":"ad552a83-0c73-44b5-89d8-baf713e14597","order_type":"limit","size":"0.37323318","price":"8511.15000000","side":"buy","client_oid":"5c0c43c4-c206-4756-c868-7e3326efdec9","product_id":"BTC-EUR","sequence":3257976618,"time":"2018-01-22T15:14:16.285000Z"}
{"type":"open","side":"buy","price":"8511.15000000","order_id":"ad552a83-0c73-44b5-89d8-baf713e14597","remaining_size":"0.37323318","product_id":"BTC-EUR","sequence":3257976619,"time":"2018-01-22T15:14:16.285000Z"}
{"type":"received","order_id":"cc6056bc-d12e-48ac-9d3d-89536068182f","order_type":"limit","size":"0.02243610","price":"8819.25000000","side":"buy","client_oid":"44fe64de-6dbc-4058-bd83-d33552faadd3","product_id":"BTC-EUR","sequence":3257976620,"time":"2018-01-22T15:14:16.486000Z"}
{"type":"open","side":"buy","price":"8819.25000000","order_id":"cc6056bc-d12e-48ac-9d3d-89536068182f","remaining_size":"0.02243610","product_id":"BTC-EUR","sequence":3257976621,"time":"2018-01-22T15:14:16.486000Z"}
{"type":"received","order_id":"4541082b-59e5-437b-8aee-afb2f8bf1627","order_type":"limit","size":"0.02243610","price":"8774.05000000","side":"buy","client_oid":"2f85c1a3-175a-403b-a998-edafa66edf26","product_id":"BTC-EUR","sequence":3257976622,"time":"2018-01-22T15:14:16.625000Z"}
{"type":"open","side":"buy","price":"8774.05000000","order_id":"4541082b-59e5-437b-8aee-afb2f8bf1627","remaining_size":"0.02243610","product_id":"BTC-EUR","sequence":3257976623,"time":"2018-01-22T15:14:16.625000Z"}
{"type":"received","order_id":"2496f087-f993-456a-9d9d-ca1a9c94714a","order_type":"limit","size":"0.36857350","price":"8908.48000000","side":"sell","client_oid":"29e80000-a880-42f3-87da-1b4ae5f0154a","product_id":"BTC-EUR","sequence":3257976624,"time":"2018-01-22T15:14:16.626000Z"}
{"type":"open","side":"sell","price":"8908.48000000","order_id":"2496f087-f993-456a-9d9d-ca1a9c94714a","remaining_size":"0.36857350","product_id":"BTC-EUR","sequence":3257976625,"time":"2018-01-22T15:14:16.626000Z"}
{"type":"received","order_id":"d374f76b-ae7a-45d1-b002-a7dc6eb7b5bd","order_type":"limit","size":"0.36857350","price":"8896.51000000","side":"sell","client_oid":"1740371d-701d-44d4-8e4f-34589bc40120","product_id":"BTC-EUR","sequence":3257976626,"time":"2018-01-22T15:14:16.629000Z"}
{"type":"open","side":"sell","price":"8896.51000000","order_id":"d374f76b-ae7a-45d1-b002-a7dc6eb7b5bd","remaining_size":"0.36857350","product_id":"BTC-EUR","sequence":3257976627,"time":"2018-01-22T15:14:16.629000Z"}
{"type":"received","order_id":"657c603d-5097-42d8-8a18-38bf629bc1fe","order_type":"limit","size":"0.10500000","price":"8831.68000000","side":"buy","client_oid":"c0b98772-8e78-4a36-a86f-2280fee93711","product_id":"BTC-EUR","sequence":3257976628,"time":"2018-01-22T15:14:16.735000Z"}
{"type":"open","side":"buy","price":"8831.68000000","order_id":"657c603d-5097-42d8-8a18-38bf629bc1fe","remaining_size":"0.10500000","product_id":"BTC-EUR","sequence":3257976629,"time":"2018-01-22T15:14:16.735000Z"}
{"type":"received","order_id":"c4441ac4-95e6-43fb-b924-607b83178196","order_type":"limit","size":"0.09800000","price":"8831.68000000","side":"buy","client_oid":"99fa55ad-480a-4f97-9bcf-5ba6e0cc6161","product_id":"BTC-EUR","sequence":3257976630,"time":"2018-01-22T15:14:16.738000Z"}
{"type":"open","side":"buy","price":"8831.68000000","order_id":"c4441ac4-95e6-43fb-b924-607b83178196","remaining_size":"0.09800000","product_id":"BTC-EUR","sequence":3257976631,"time":"2018-01-22T15:14:16.738000Z"}
{"type":"done","side":"sell","order_id":"73663bb0-bac9-4607-a0b3-b77dcda8d249","reason":"canceled","product_id":"BTC-EUR","price":"9046.00000000","remaining_size":"0.50000000","sequence":3257976632,"time":"2018-01-22T15:14:16.806000Z"}
{"type":"received","order_id":"82d87309-f9a4-4443-9a38-c44e6ea56a30","order_type":"limit","size":"0.50000000","price":"9030.25000000","side":"sell","product_id":"BTC-EUR","sequence":3257976633,"time":"2018-01-22T15:14:16.814000Z"}
{"type":"open","side":"sell","price":"9030.25000000","order_id":"82d87309-f9a4-4443-9a38-c44e6ea56a30","remaining_size":"0.50000000","product_id":"BTC-EUR","sequence":3257976634,"time":"2018-01-22T15:14:16.814000Z"}
{"type":"done","side":"buy","order_id":"657c603d-5097-42d8-8a18-38bf629bc1fe","reason":"canceled","product_id":"BTC-EUR","price":"8831.68000000","remaining_size":"0.10500000","sequence":3257976635,"time":"2018-01-22T15:14:16.816000Z"}
{"type":"received","order_id":"57f03cd7-ddb9-460a-9064-22a9b11a1a26","order_type":"limit","size":"0.01000000","price":"9096.64000000","side":"buy","product_id":"BTC-EUR","sequence":3257976636,"time":"2018-01-22T15:14:16.817000Z"}
{"type":"match","trade_id":10551315,"maker_order_id":"05c3704a-bdd3-4696-a90b-d60658d88540","taker_order_id":"57f03cd7-ddb9-460a-9064-22a9b11a1a26","side":"sell","size":"0.01000000","price":"8831.69000000","product_id":"BTC-EUR","sequence":3257976637,"time":"2018-01-22T15:14:16.817000Z"}
{"type":"done","side":"buy","order_id":"57f03cd7-ddb9-460a-9064-22a9b11a1a26","reason":"filled","product_id":"BTC-EUR","price":"9096.64000000","remaining_size":"0.00000000","sequence":3257976638,"time":"2018-01-22T15:14:16.817000Z"}
{"type":"done","side":"sell","order_id":"4b6622f4-e504-42ed-ba7d-3a232872af99","reason":"canceled","product_id":"BTC-EUR","price":"8848.92000000","remaining_size":"0.11241548","sequence":3257976639,"time":"2018-01-22T15:14:16.822000Z"}
{"type":"received","order_id":"a45c35fe-ea16-4ded-955a-077ad01352d6","order_type":"limit","size":"0.09800000","price":"8831.68000000","side":"buy","client_oid":"d26e1aaf-45ea-4fb7-bcb9-f80549533c85","product_id":"BTC-EUR","sequence":3257976640,"time":"2018-01-22T15:14:16.840000Z"}
{"type":"open","side":"buy","price":"8831.68000000","order_id":"a45c35fe-ea16-4ded-955a-077ad01352d6","remaining_size":"0.09800000","product_id":"BTC-EUR","sequence":3257976641,"time":"2018-01-22T15:14:16.840000Z"}
{"type":"received","order_id":"92f218bc-85a5-4c3e-afe0-0bc5a10cc6a6","order_type":"limit","size":"0.09800000","price":"8831.68000000","side":"buy","client_oid":"9f2449e4-037b-47a3-af73-ea3a06ce088f","product_id":"BTC-EUR","sequence":3257976642,"time":"2018-01-22T15:14:16.905000Z"}
{"type":"open","side":"buy","price":"8831.68000000","order_id":"92f218bc-85a5-4c3e-afe0-0bc5a10cc6a6","remaining_size":"0.09800000","product_id":"BTC-EUR","sequence":3257976643,"time":"2018-01-22T15:14:16.905000Z"}
{"type":"received","order_id":"c3263a67-270c-44d6-be4d-ae0d81ceae8b","order_type":"limit","size":"0.10500000","price":"8831.68000000","side":"buy","client_oid":"5317f330-d75a-425c-8679-3542d2c7454c","product_id":"BTC-EUR","sequence":3257976644,"time":"2018-01-22T15:14:16.914000Z"}
{"type":"open","side":"buy","price":"8831.68000000","order_id":"c3263a67-270c-44d6-be4d-ae0d81ceae8b","remaining_size":"0.10500000","product_id":"BTC-EUR","sequence":3257976645,"time":"2018-01-22T15:14:16.914000Z"}
{"type":"received","order_id":"2c1ed2ac-54b6-49d7-8761-db07875f32fe","order_type":"limit","size":"0.00200000","price":"8831.68000000","side":"buy","client_oid":"2d564585-8c8b-4a7a-9ad3-31003e22e6c0","product_id":"BTC-EUR","sequence":3257976646,"time":"2018-01-22T15:14:16.918000Z"}
{"type":"open","side":"buy","price":"8831.68000000","order_id":"2c1ed2ac-54b6-49d7-8761-db07875f32fe","remaining_size":"0.00200000","product_id":"BTC-EUR","sequence":3257976647,"time":"2018-01-22T15:14:16.918000Z"}
{"type":"received","order_id":"bb6ac108-09f2-4d65-88cc-22a73afda755","order_type":"limit","size":"0.10500000","price":"8831.68000000","side":"buy","client_oid":"ce7ab75f-d454-4298-981e-c9df7e2c8478","product_id":"BTC-EUR","sequence":3257976648,"time":"2018-01-22T15:14:16.929000Z"}
{"type":"open","side":"buy","price":"8831.68000000","order_id":"bb6ac108-09f2-4d65-88cc-22a73afda755","remaining_size":"0.10500000","product_id":"BTC-EUR","sequence":3257976649,"time":"2018-01-22T15:14:16.929000Z"}
{"type":"received","order_id":"9eb128b5-5783-41a5-bb52-26da8551fbab","order_type":"limit","size":"0.11241548","price":"8850.00000000","side":"sell","product_id":"BTC-EUR","sequence":3257976650,"time":"2018-01-22T15:14:16.936000Z"}
{"type":"open","side":"sell","price":"8850.00000000","order_id":"9eb128b5-5783-41a5-bb52-26da8551fbab","remaining_size":"0.11241548","product_id":"BTC-EUR","sequence":3257976651,"time":"2018-01-22T15:14:16.936000Z"}
{"type":"received","order_id":"41d2ccd1-6e63-4e4e-af55-d52d500407d0","order_type":"limit","size":"6.41544856","price":"8760.01000000","side":"buy","product_id":"BTC-EUR","sequence":3257976652,"time":"2018-01-22T15:14:17.191000Z"}
{"type":"open","side":"buy","price":"8760.01000000","order_id":"41d2ccd1-6e63-4e4e-af55-d52d500407d0","remaining_size":"6.41544856","product_id":"BTC-EUR","sequence":3257976653,"time":"2018-01-22T15:14:17.191000Z"}
{"type":"received","order_id":"933e7312-9de2-482e-ba81-21521729ff06","order_type":"limit","size":"1.28000000","price":"9108.06000000","side":"sell","product_id":"BTC-EUR","sequence":3257976654,"time":"2018-01-22T15:14:17.277000Z"}
{"type":"open","side":"sell","price":"9108.06000000","order_id":"933e7312-9de2-482e-ba81-21521729ff06","remaining_size":"1.28000000","product_id":"BTC-EUR","sequence":3257976655,"time":"2018-01-22T15:14:17.277000Z"}
{"type":"done","side":"buy","order_id":"a4fb4260-23db-40d6-ad50-e1f1cd50f890","reason":"canceled","product_id":"BTC-EUR","price":"8813.96000000","remaining_size":"0.37000000","sequence":3257976656,"time":"2018-01-22T15:14:17.440000Z"}
{"type":"received","order_id":"2fd4672e-9b9d-4c5d-b63a-3d820a61eec3","order_type":"limit","size":"0.10500000","price":"8831.68000000","side":"buy","client_oid":"ca46e25c-0ab6-47e3-8d66-a5a3c12090be","product_id":"BTC-EUR","sequence":3257976657,"time":"2018-01-22T15:14:17.533000Z"}
{"type":"open","side":"buy","price":"8831.68000000","order_id":"2fd4672e-9b9d-4c5d-b63a-3d820a61eec3","remaining_size":"0.10500000","product_id":"BTC-EUR","sequence":3257976658,"time":"2018-01-22T15:14:17.533000Z"}
{"type":"done","side":"buy","order_id":"d248d06d-883f-4b84-83bb-64492e623182","reason":"canceled","product_id":"BTC-EUR","price":"8657.40000000","remaining_size":"1.89570000","sequence":3257976659,"time":"2018-01-22T15:14:17.551000Z"}
{"type":"received","order_id":"e851bb5e-4697-49c6-9c07-3102765479a3","order_type":"limit","size":"1.89425000","price":"8659.20000000","side":"buy","client_oid":"0bf05293-cf17-4cd2-bb7f-b7a8b6f7d739","product_id":"BTC-EUR","sequence":3257976660,"time":"2018-01-22T15:14:17.561000Z"}
{"type":"open","side":"buy","price":"8659.20000000","order_id":"e851bb5e-4697-49c6-9c07-3102765479a3","remaining_size":"1.89425000","product_id":"BTC-EUR","sequence":3257976661,"time":"2018-01-22T15:14:17.561000Z"}
{"type":"done","side":"sell","order_id":"bcce09a8-b77c-4f2e-bd85-1892fa88bc2d","reason":"canceled","product_id":"BTC-EUR","price":"8867.00000000","remaining_size":"0.18000000","sequence":3257976662,"time":"2018-01-22T15:14:17.589000Z"}
{"type":"received","order_id":"cf3b7f96-5801-411e-914b-3dde56dfe684","order_type":"limit","size":"0.33000000","price":"8809.29000000","side":"buy","product_id":"BTC-EUR","sequence":3257976663,"time":"2018-01-22T15:14:17.775000Z"}
{"type":"open","side":"buy","price":"8809.29000000","order_id":"cf3b7f96-5801-411e-914b-3dde56dfe684","remaining_size":"0.33000000","product_id":"BTC-EUR","sequence":3257976664,"time":"2018-01-22T15:14:17.775000Z"}
{"type":"received","order_id":"137c70ac-7a7b-47fb-8302-f718104dc306","order_type":"limit","size":"0.16000000","price":"8862.30000000","side":"sell","product_id":"BTC-EUR","sequence":3257976665,"time":"2018-01-22T15:14:17.961000Z"}
{"type":"open","side":"sell","price":"8862.30000000","order_id":"137c70ac-7a7b-47fb-8302-f718104dc306","remaining_size":"0.16000000","product_id":"BTC-EUR","sequence":3257976666,"time":"2018-01-22T15:14:17.961000Z"}
{"type":"received","order_id":"033fb076-0407-4c65-ac31-8417c5aa65d1","order_type":"limit","size":"0.01586384","price":"8818.21000000","side":"buy","client_oid":"6292a593-6f0b-424b-a386-8cf9de317cfc","product_id":"BTC-EUR","sequence":3257976667,"time":"2018-01-22T15:14:18.042000Z"}
{"type":"open","side":"buy","price":"8818.21000000","order_id":"033fb076-0407-4c65-ac31-8417c5aa65d1","remaining_size":"0.01586384","product_id":"BTC-EUR","sequence":3257976668,"time":"2018-01-22T15:14:18.042000Z"}
{"type":"received","order_id":"a9b0b15c-6d8c-4880-ae35-6f4028e104ca","order_type":"limit","size":"0.19762425","price":"8896.51000000","side":"sell","client_oid":"5bf998d3-2d6b-433a-a47c-e2cfb2921f55","product_id":"BTC-EUR","sequence":3257976669,"time":"2018-01-22T15:14:18.080000Z"}
{"type":"open","side":"sell","price":"8896.51000000","order_id":"a9b0b15c-6d8c-4880-ae35-6f4028e104ca","remaining_size":"0.19762425","product_id":"BTC-EUR","sequence":3257976670,"time":"2018-01-22T15:14:18.080000Z"}
{"type":"received","order_id":"f76d078f-9422-48ba-8762-3c5b7156c5b9","order_type":"limit","size":"0.19762425","price":"8908.53000000","side":"sell","client_oid":"5c3d11ca-1f07-45cd-94da-1bb24f28d228","product_id":"BTC-EUR","sequence":3257976671,"time":"2018-01-22T15:14:18.092000Z"}
{"type":"open","side":"sell","price":"8908.53000000","order_id":"f76d078f-9422-48ba-8762-3c5b7156c5b9","remaining_size":"0.19762425","product_id":"BTC-EUR","sequence":3257976672,"time":"2018-01-22T15:14:18.092000Z"}
{"type":"received","order_id":"3b5ba7bc-defd-4141-a56c-33b6212b9351","order_type":"limit","size":"0.11143500","price":"8831.68000000","side":"buy","product_id":"BTC-EUR","sequence":3257976673,"time":"2018-01-22T15:14:18.236000Z"}
{"type":"open","side":"buy","price":"8831.68000000","order_id":"3b5ba7bc-defd-4141-a56c-33b6212b9351","remaining_size":"0.11143500","product_id":"BTC-EUR","sequence":3257976674,"time":"2018-01-22T15:14:18.236000Z"}
{"type":"received","order_id":"06c9a7db-d21c-47d9-b10f-735148e651ea","order_type":"limit","size":"0.77808737","price":"8848.94000000","side":"sell","client_oid":"df415d24-6c61-4a32-c107-f46b60afb6be","product_id":"BTC-EUR","sequence":3257976675,"time":"2018-01-22T15:14:18.429000Z"}
{"type":"open","side":"sell","price":"8848.94000000","order_id":"06c9a7db-d21c-47d9-b10f-735148e651ea","remaining_size":"0.77808737","product_id":"BTC-EUR","sequence":3257976676,"time":"2018-01-22T15:14:18.429000Z"}
{"type":"received","order_id":"cd806d70-0236-4cb6-b3f4-5ddc6beb4aca","order_type":"limit","size":"0.03773580","price":"8907.20000000","side":"sell","client_oid":"8ec8a33a-c113-4977-9713-da95e375b779","product_id":"BTC-EUR","sequence":3257976677,"time":"2018-01-22T15:14:18.610000Z"}
{"type":"open","side":"sell","price":"8907.20000000","order_id":"cd806d70-0236-4cb6-b3f4-5ddc6beb4aca","remaining_size":"0.03773580","product_id":"BTC-EUR","sequence":3257976678,"time":"2018-01-22T15:14:18.610000Z"}
{"type":"received","order_id":"4f1f1f38-ee07-4768-a801-2e7f87f1dd5b","order_type":"limit","size":"0.17059670","price":"8742.38000000","side":"buy","product_id":"BTC-EUR","sequence":3257976679,"time":"2018-01-22T15:14:18.891000Z"}
{"type":"open","side":"buy","price":"8742.38000000","order_id":"4f1f1f38-ee07-4768-a801-2e7f87f1dd5b","remaining_size":"0.17059670","product_id":"BTC-EUR","sequence":3257976680,"time":"2018-01-22T15:14:18.891000Z"}
{"type":"done","side":"buy","order_id":"ae10533e-ee18-417d-8705-81add62fbbc4","reason":"canceled","product_id":"BTC-EUR","price":"8780.07000000","remaining_size":"0.14701842","sequence":3257976681,"time":"2018-01-22T15:14:19.068000Z"}
{"type":"done","side":"buy","order_id":"3b5ba7bc-defd-4141-a56c-33b6212b9351","reason":"canceled","product_id":"BTC-EUR","price":"8831.68000000","remaining_size":"0.11143500","sequence":3257976682,"time":"2018-01-22T15:14:19.227000Z"}
{"type":"received","order_id":"7483fc88-702c-4c83-8cd7-17edf7d93c15","order_type":"limit","size":"0.11000000","price":"9096.64000000","side":"buy","product_id":"BTC-EUR","sequence":3257976683,"time":"2018-01-22T15:14:19.589000Z"}
{"type":"match","trade_id":10551316,"maker_order_id":"05c3704a-bdd3-4696-a90b-d60658d88540","taker_order_id":"7483fc88-702c-4c83-8cd7-17edf7d93c15","side":"sell","size":"0.08955143","price":"8831.69000000","product_id":"BTC-EUR","sequence":3257976684,"time":"2018-01-22T15:14:19.589000Z"}
{"type":"done","side":"sell","order_id":"05c3704a-bdd3-4696-a90b-d60658d88540","reason":"filled","product_id":"BTC-EUR","price":"8831.69000000","remaining_size":"0","sequence":3257976685,"time":"2018-01-22T15:14:19.589000Z"}
{"type":"match","trade_id":10551317,"maker_order_id":"1c5b415e-d734-416e-96a0-4e2664348cc9","taker_order_id":"7483fc88-702c-4c83-8cd7-17edf7d93c15","side":"sell","size":"0.02044857","price":"8831.69000000","product_id":"BTC-EUR","sequence":3257976686,"time":"2018-01-22T15:14:19.589000Z"}
{"type":"done","side":"buy","order_id":"7483fc88-702c-4c83-8cd7-17edf7d93c15","reason":"filled","product_id":"BTC-EUR","price":"9096.64000000","remaining_size":"0.00000000","sequence":3257976687,"time":"2018-01-22T15:14:19.589000Z"}
{"type":"received","order_id":"81595899-8c86-4c3b-b879-4517a86a6aee","order_type":"limit","size":"0.14814796","price":"8831.69000000","side":"sell","product_id":"BTC-EUR","sequence":3257976688,"time":"2018-01-22T15:14:19.637000Z"}
{"type":"open","side":"sell","price":"8831.69000000","order_id":"81595899-8c86-4c3b-b879-4517a86a6aee","remaining_size":"0.14814796","product_id":"BTC-EUR","sequence":3257976689,"time":"2018-01-22T15:14:19.637000Z"}
{"type":"received","order_id":"0dd86f48-7232-4e11-a409-6619d3b6b8a3","order_type":"limit","size":"0.42640068","price":"8831.69000000","side":"sell","product_id":"BTC-EUR","sequence":3257976690,"time":"2018-01-22T15:14:19.854000Z"}
{"type":"open","side":"sell","price":"8831.69000000","order_id":"0dd86f48-7232-4e11-a409-6619d3b6b8a3","remaining_size":"0.42640068","product_id":"BTC-EUR","sequence":3257976691,"time":"2018-01-22T15:14:19.854000Z"}
{"type":"done","side":"buy","order_id":"41d2ccd1-6e63-4e4e-af55-d52d500407d0","reason":"canceled","product_id":"BTC-EUR","price":"8760.01000000","remaining_size":"6.41544856","sequence":3257976692,"time":"2018-01-22T15:14:19.879000Z"}
{"type":"done","side":"sell","order_id":"933e7312-9de2-482e-ba81-21521729ff06","reason":"canceled","product_id":"BTC-EUR","price":"9108.06000000","remaining_size":"1.28000000","sequence":3257976693,"time":"2018-01-22T15:14:20.026000Z"}
{"type":"done","side":"sell","order_id":"bed46f86-c71a-45b2-99ec-667b269809fc","reason":"canceled","product_id":"BTC-EUR","price":"8891.52000000","remaining_size":"0.18370534","sequence":3257976694,"time":"2018-01-22T15:14:20.058000Z"}
{"type":"received","order_id":"9ddd5e56-5c26-41ac-9e50-361f903f3869","order_type":"limit","size":"0.13208615","price":"8799.66000000","side":"buy","product_id":"BTC-EUR","sequence":3257976695,"time":"2018-01-22T15:14:20.120000Z"}
{"type":"open","side":"buy","price":"8799.66000000","order_id":"9ddd5e56-5c26-41ac-9e50-361f903f3869","remaining_size":"0.13208615","product_id":"BTC-EUR","sequence":3257976696,"time":"2018-01-22T15:14:20.120000Z"}
{"type":"done","side":"sell","order_id":"911ec139-245b-4ce9-97c2-cd483c7eb2d6","reason":"canceled","product_id":"BTC-EUR","price":"8900.10000000","remaining_size":"0.45882083","sequence":3257976697,"time":"2018-01-22T15:14:20.165000Z"}
{"type":"done","side":"sell","order_id":"9eb128b5-5783-41a5-bb52-26da8551fbab","reason":"canceled","product_id":"BTC-EUR","price":"8850.00000000","remaining_size":"0.11241548","sequence":3257976698,"time":"2018-01-22T15:14:20.208000Z"}
{"type":"done","side":"sell","order_id":"0dd86f48-7232-4e11-a409-6619d3b6b8a3","reason":"canceled","product_id":"BTC-EUR","price":"8831.69000000","remaining_size":"0.42640068","sequence":3257976699,"time":"2018-01-22T15:14:20.298000Z"}
{"type":"done","side":"buy","order_id":"4f1f1f38-ee07-4768-a801-2e7f87f1dd5b","reason":"canceled","product_id":"BTC-EUR","price":"8742.38000000","remaining_size":"0.17059670","sequence":3257976700,"time":"2018-01-22T15:14:20.319000Z"}
{"type":"received","order_id":"e4505661-026e-4aee-87e4-c33229c23f24","order_type":"limit","size":"0.45972784","price":"8882.54000000","side":"sell","client_oid":"b55e123e-3db6-454d-aa38-3e4cb32fe580","product_id":"BTC-EUR","sequence":3257976701,"time":"2018-01-22T15:14:20.395000Z"}
{"type":"open","side":"sell","price":"8882.54000000","order_id":"e4505661-026e-4aee-87e4-c33229c23f24","remaining_size":"0.45972784","product_id":"BTC-EUR","sequence":3257976702,"time":"2018-01-22T15:14:20.395000Z"}
{"type":"received","order_id":"af118848-c71b-41fb-b982-69379b9c3dfd","order_type":"limit","size":"0.07072160","price":"8831.69000000","side":"sell","product_id":"BTC-EUR","sequence":3257976703,"time":"2018-01-22T15:14:20.497000Z"}
{"type":"open","side":"sell","price":"8831.69000000","order_id":"af118848-c71b-41fb-b982-69379b9c3dfd","remaining_size":"0.07072160","product_id":"BTC-EUR","sequence":3257976704,"time":"2018-01-22T15:14:20.497000Z"}
{"type":"received","order_id":"d422e174-7148-411d-ba30-ecc17f21be69","order_type":"limit","size":"0.11241548","price":"8848.94000000","side":"sell","product_id":"BTC-EUR","sequence":3257976705,"time":"2018-01-22T15:14:20.601000Z"}
{"type":"open","side":"sell","price":"8848.94000000","order_id":"d422e174-7148-411d-ba30-ecc17f21be69","remaining_size":"0.11241548","product_id":"BTC-EUR","sequence":3257976706,"time":"2018-01-22T15:14:20.601000Z"}
{"type":"received","order_id":"829f7393-a4f4-4dc4-a0ad-0cf8b9a68024","order_type":"limit","size":"0.18394187","price":"8880.09000000","side":"sell","client_oid":"aa93ba1e-2102-401b-8c28-0f72c9d48130","product_id":"BTC-EUR","sequence":3257976707,"time":"2018-01-22T15:14:20.657000Z"}
{"type":"open","side":"sell","price":"8880.09000000","order_id":"829f7393-a4f4-4dc4-a0ad-0cf8b9a68024","remaining_size":"0.18394187","product_id":"BTC-EUR","sequence":3257976708,"time":"2018-01-22T15:14:20.657000Z"}
{"type":"done","side":"sell","order_id":"a2c8e899-85ed-4322-be4c-d614bd5144ce","reason":"canceled","product_id":"BTC-EUR","price":"8831.70000000","remaining_size":"0.11066184","sequence":3257976709,"time":"2018-01-22T15:14:20.714000Z"}
{"type":"received","order_id":"843c485f-4858-4a83-878c-991ae44b8a64","order_type":"market","side":"buy","funds":"99.7505825078000000","client_oid":"f58f50e3-c17f-44cc-d0e0-893338f45643","product_id":"BTC-EUR","sequence":3257976710,"time":"2018-01-22T15:14:20.740000Z"}
{"type":"match","trade_id":10551318,"maker_order_id":"1c5b415e-d734-416e-96a0-4e2664348cc9","taker_order_id":"843c485f-4858-4a83-878c-991ae44b8a64","side":"sell","size":"0.01129462","price":"8831.69000000","product_id":"BTC-EUR","sequence":3257976711,"time":"2018-01-22T15:14:20.740000Z"}
{"type":"done","side":"buy","order_id":"843c485f-4858-4a83-878c-991ae44b8a64","reason":"filled","product_id":"BTC-EUR","sequence":3257976712,"time":"2018-01-22T15:14:20.740000Z"}
{"type":"done","side":"sell","order_id":"e4505661-026e-4aee-87e4-c33229c23f24","reason":"canceled","product_id":"BTC-EUR","price":"8882.54000000","remaining_size":"0.45972784","sequence":3257976713,"time":"2018-01-22T15:14:20.847000Z"}
{"type":"done","side":"sell","order_id":"b245912f-a2b8-40c2-8cd4-a5327e5547f5","reason":"canceled","product_id":"BTC-EUR","price":"8831.69000000","remaining_size":"0.22947933","sequence":3257976714,"time":"2018-01-22T15:14:20.952000Z"}
{"type":"done","side":"sell","order_id":"829f7393-a4f4-4dc4-a0ad-0cf8b9a68024","reason":"canceled","product_id":"BTC-EUR","price":"8880.09000000","remaining_size":"0.18394187","sequence":3257976715,"time":"2018-01-22T15:14:20.975000Z"}
{"type":"received","order_id":"d1fc826d-f8b7-44c0-b7c3-36a7c1647ecb","order_type":"limit","size":"0.45926334","price":"8891.52000000","side":"sell","client_oid":"fa7eba92-beb9-4aa6-849c-0fb80c0ade8e","product_id":"BTC-EUR","sequence":3257976716,"time":"2018-01-22T15:14:21.071000Z"}
{"type":"open","side":"sell","price":"8891.52000000","order_id":"d1fc826d-f8b7-44c0-b7c3-36a7c1647ecb","remaining_size":"0.45926334","product_id":"BTC-EUR","sequence":3257976717,"time":"2018-01-22T15:14:21.071000Z"}
{"type":"done","side":"sell","order_id":"3b208405-2307-40a0-b641-f2c7671b0203","reason":"canceled","product_id":"BTC-EUR","price":"8831.69000000","remaining_size":"0.01887096","sequence":3257976718,"time":"2018-01-22T15:14:21.080000Z"}
{"type":"received","order_id":"bbd2e6b9-195a-46d4-b40f-3e9be6e4de60","order_type":"limit","size":"6.41544856","price":"8752.13000000","side":"buy","product_id":"BTC-EUR","sequence":3257976719,"time":"2018-01-22T15:14:21.084000Z"}
{"type":"open","side":"buy","price":"8752.13000000","order_id":"bbd2e6b9-195a-46d4-b40f-3e9be6e4de60","remaining_size":"6.41544856","product_id":"BTC-EUR","sequence":3257976720,"time":"2018-01-22T15:14:21.084000Z"}
{"type":"received","order_id":"c4acbaba-de29-40fa-ace1-1ecb527f752c","order_type":"limit","size":"0.22947933","price":"8848.92000000","side":"sell","client_oid":"bee46eec-056c-48e2-a42d-b90f55fb3b80","product_id":"BTC-EUR","sequence":3257976721,"time":"2018-01-22T15:14:21.171000Z"}
{"type":"open","side":"sell","price":"8848.92000000","order_id":"c4acbaba-de29-40fa-ace1-1ecb527f752c","remaining_size":"0.22947933","product_id":"BTC-EUR","sequence":3257976722,"time":"2018-01-22T15:14:21.171000Z"}
{"type":"received","order_id":"8e3f7fc9-7fce-416e-a7f6-c31adf41a6a5","order_type":"limit","size":"0.01000000","price":"9096.64000000","side":"buy","product_id":"BTC-EUR","sequence":3257976723,"time":"2018-01-22T15:14:21.249000Z"}
{"type":"match","trade_id":10551319,"maker_order_id":"1c5b415e-d734-416e-96a0-4e2664348cc9","taker_order_id":"8e3f7fc9-7fce-416e-a7f6-c31adf41a6a5","side":"sell","size":"0.01000000","price":"8831.69000000","product_id":"BTC-EUR","sequence":3257976724,"time":"2018-01-22T15:14:21.249000Z"}
{"type":"done","side":"buy","order_id":"8e3f7fc9-7fce-416e-a7f6-c31adf41a6a5","reason":"filled","product_id":"BTC-EUR","price":"9096.64000000","remaining_size":"0.00000000","sequence":3257976725,"time":"2018-01-22T15:14:21.249000Z"}
{"type":"received","order_id":"b49a2e3a-3642-4c1a-b348-8ce39664486d","order_type":"limit","size":"0.18370534","price":"8891.52000000","side":"sell","client_oid":"10abb6f0-e58a-4b7a-ba1f-ca81643d0fe2","product_id":"BTC-EUR","sequence":3257976726,"time":"2018-01-22T15:14:21.275000Z"}
{"type":"open","side":"sell","price":"8891.52000000","order_id":"b49a2e3a-3642-4c1a-b348-8ce39664486d","remaining_size":"0.18370534","product_id":"BTC-EUR","sequence":3257976727,"time":"2018-01-22T15:14:21.275000Z"}
{"type":"received","order_id":"7934dc53-bbdd-4643-be6d-a64017f4cece","order_type":"limit","size":"0.01887096","price":"8848.92000000","side":"sell","client_oid":"4b18a0b9-05a7-4fd1-bb10-6d001a57addd","product_id":"BTC-EUR","sequence":3257976728,"time":"2018-01-22T15:14:21.309000Z"}
{"type":"open","side":"sell","price":"8848.92000000","order_id":"7934dc53-bbdd-4643-be6d-a64017f4cece","remaining_size":"0.01887096","product_id":"BTC-EUR","sequence":3257976729,"time":"2018-01-22T15:14:21.309000Z"}
{"type":"done","side":"sell","order_id":"2388d0b9-7251-4ce1-bd24-89a6828e05d7","reason":"canceled","product_id":"BTC-EUR","price":"8831.69000000","remaining_size":"0.04164971","sequence":3257976730,"time":"2018-01-22T15:14:21.322000Z"}
{"type":"done","side":"buy","order_id":"a45c35fe-ea16-4ded-955a-077ad01352d6","reason":"canceled","product_id":"BTC-EUR","price":"8831.68000000","remaining_size":"0.09800000","sequence":3257976731,"time":"2018-01-22T15:14:21.418000Z"}
{"type":"done","side":"sell","order_id":"51321aea-a792-443d-88cb-d3b0dd37c119","reason":"canceled","product_id":"BTC-EUR","price":"9500.00000000","remaining_size":"0.00201775","sequence":3257976732,"time":"2018-01-22T15:14:21.434000Z"}
{"type":"done","side":"buy","order_id":"2c1ed2ac-54b6-49d7-8761-db07875f32fe","reason":"canceled","product_id":"BTC-EUR","price":"8831.68000000","remaining_size":"0.00200000","sequence":3257976733,"time":"2018-01-22T15:14:21.459000Z"}
{"type":"done","side":"buy","order_id":"92f218bc-85a5-4c3e-afe0-0bc5a10cc6a6","reason":"canceled","product_id":"BTC-EUR","price":"8831.68000000","remaining_size":"0.09800000","sequence":3257976734,"time":"2018-01-22T15:14:21.459000Z"}
{"type":"done","side":"buy","order_id":"c4441ac4-95e6-43fb-b924-607b83178196","reason":"canceled","product_id":"BTC-EUR","price":"8831.68000000","remaining_size":"0.09800000","sequence":3257976735,"time":"2018-01-22T15:14:21.463000Z"}
{"type":"received","order_id":"957419f9-c2c7-45d7-b607-d2be5a8d4f8c","order_type":"limit","size":"0.09800000","price":"8831.68000000","side":"buy","client_oid":"574751fc-f93a-4fe4-a3c7-65721c25ad34","product_id":"BTC-EUR","sequence":3257976736,"time":"2018-01-22T15:14:21.519000Z"}
{"type":"open","side":"buy","price":"8831.68000000","order_id":"957419f9-c2c7-45d7-b607-d2be5a8d4f8c","remaining_size":"0.09800000","product_id":"BTC-EUR","sequence":3257976737,"time":"2018-01-22T15:14:21.519000Z"}
{"type":"received","order_id":"2b910792-2c90-42c6-8e51-f3b1983d185a","order_type":"limit","size":"1.28000000","price":"9106.63000000","side":"sell","product_id":"BTC-EUR","sequence":3257976738,"time":"2018-01-22T15:14:21.541000Z"}
{"type":"open","side":"sell","price":"9106.63000000","order_id":"2b910792-2c90-42c6-8e51-f3b1983d185a","remaining_size":"1.28000000","product_id":"BTC-EUR","sequence":3257976739,"time":"2018-01-22T15:14:21.541000Z"}
{"type":"received","order_id":"ca644cd9-9ab9-4e31-a429-a0a8b1cbce6a","order_type":"limit","size":"0.04164971","price":"8848.92000000","side":"sell","client_oid":"29ffd37a-c558-41fd-a367-a1645bddb3c2","product_id":"BTC-EUR","sequence":3257976740,"time":"2018-01-22T15:14:21.554000Z"}
{"type":"open","side":"sell","price":"8848.92000000","order_id":"ca644cd9-9ab9-4e31-a429-a0a8b1cbce6a","remaining_size":"0.04164971","product_id":"BTC-EUR","sequence":3257976741,"time":"2018-01-22T15:14:21.555000Z"}
{"type":"received","order_id":"e3196008-9be9-4ab2-b5ce-57146ed44140","order_type":"limit","size":"0.09800000","price":"8831.68000000","side":"buy","client_oid":"73c5c02d-b78b-4747-a9ac-60371bbd1dfa","product_id":"BTC-EUR","sequence":3257976742,"time":"2018-01-22T15:14:21.598000Z"}
{"type":"open","side":"buy","price":"8831.68000000","order_id":"e3196008-9be9-4ab2-b5ce-57146ed44140","remaining_size":"0.09800000","product_id":"BTC-EUR","sequence":3257976743,"time":"2018-01-22T15:14:21.598000Z"}
{"type":"received","order_id":"e7d0acc1-77e4-402d-9c28-810524f8b203","order_type":"limit","size":"0.00200000","price":"8831.68000000","side":"buy","client_oid":"e407fce7-d47c-439d-a7f6-01daef0d334e","product_id":"BTC-EUR","sequence":3257976744,"time":"2018-01-22T15:14:21.599000Z"}
{"type":"open","side":"buy","price":"8831.68000000","order_id":"e7d0acc1-77e4-402d-9c28-810524f8b203","remaining_size":"0.00200000","product_id":"BTC-EUR","sequence":3257976745,"time":"2018-01-22T15:14:21.599000Z"}
{"type":"done","side":"buy","order_id":"bb6ac108-09f2-4d65-88cc-22a73afda755","reason":"canceled","product_id":"BTC-EUR","price":"8831.68000000","remaining_size":"0.10500000","sequence":3257976746,"time":"2018-01-22T15:14:21.680000Z"}
{"type":"done","side":"buy","order_id":"c3263a67-270c-44d6-be4d-ae0d81ceae8b","reason":"canceled","product_id":"BTC-EUR","price":"8831.68000000","remaining_size":"0.10500000","sequence":3257976747,"time":"2018-01-22T15:14:21.691000Z"}
{"type":"done","side":"buy","order_id":"2fd4672e-9b9d-4c5d-b63a-3d820a61eec3","reason":"canceled","product_id":"BTC-EUR","price":"8831.68000000","remaining_size":"0.10500000","sequence":3257976748,"time":"2018-01-22T15:14:21.703000Z"}
{"type":"done","side":"buy","order_id":"bbd2e6b9-195a-46d4-b40f-3e9be6e4de60","reason":"canceled","product_id":"BTC-EUR","price":"8752.13000000","remaining_size":"6.41544856","sequence":3257976749,"time":"2018-01-22T15:14:21.727000Z"}
{"type":"received","order_id":"d3ea886f-e880-41a9-8cb1-a08c14d64a62","order_type":"limit","size":"0.10500000","price":"8831.68000000","side":"buy","client_oid":"07f1cac0-1717-4207-90c7-f6e31058ec37","product_id":"BTC-EUR","sequence":3257976750,"time":"2018-01-22T15:14:21.780000Z"}
{"type":"open","side":"buy","price":"8831.68000000","order_id":"d3ea886f-e880-41a9-8cb1-a08c14d64a62","remaining_size":"0.10500000","product_id":"BTC-EUR","sequence":3257976751,"time":"2018-01-22T15:14:21.780000Z"}
{"type":"received","order_id":"91b000a8-7ec5-4474-b920-349d7b723597","order_type":"limit","size":"0.09800000","price":"8831.68000000","side":"buy","client_oid":"861659f9-c6af-4a98-97f4-368f5cf9059c","product_id":"BTC-EUR","sequence":3257976752,"time":"2018-01-22T15:14:21.783000Z"}
{"type":"open","side":"buy","price":"8831.68000000","order_id":"91b000a8-7ec5-4474-b920-349d7b723597","remaining_size":"0.09800000","product_id":"BTC-EUR","sequence":3257976753,"time":"2018-01-22T15:14:21.783000Z"}
{"type":"received","order_id":"5041a6b8-6506-475f-a8d5-608044b22c8f","order_type":"limit","size":"0.10500000","price":"8831.68000000","side":"buy","client_oid":"48a7e058-8f86-4d1b-bc66-167a1496fb05","product_id":"BTC-EUR","sequence":3257976754,"time":"2018-01-22T15:14:21.785000Z"}
{"type":"open","side":"buy","price":"8831.68000000","order_id":"5041a6b8-6506-475f-a8d5-608044b22c8f","remaining_size":"0.10500000","product_id":"BTC-EUR","sequence":3257976755,"time":"2018-01-22T15:14:21.785000Z"}
{"type":"done","side":"buy","order_id":"5041a6b8-6506-475f-a8d5-608044b22c8f","reason":"canceled","product_id":"BTC-EUR","price":"8831.68000000","remaining_size":"0.10500000","sequence":3257976756,"time":"2018-01-22T15:14:21.866000Z"}
{"type":"done","side":"buy","order_id":"d3ea886f-e880-41a9-8cb1-a08c14d64a62","reason":"canceled","product_id":"BTC-EUR","price":"8831.68000000","remaining_size":"0.10500000","sequence":3257976757,"time":"2018-01-22T15:14:21.910000Z"}
{"type":"received","order_id":"76b7dba8-9725-47cb-96f4-a5cdcdcacb98","order_type":"limit","size":"0.10500000","price":"8831.68000000","side":"buy","client_oid":"675c2f5d-8655-4ea6-acfb-5fdc41a40eeb","product_id":"BTC-EUR","sequence":3257976758,"time":"2018-01-22T15:14:21.921000Z"}
{"type":"open","side":"buy","price":"8831.68000000","order_id":"76b7dba8-9725-47cb-96f4-a5cdcdcacb98","remaining_size":"0.10500000","product_id":"BTC-EUR","sequence":3257976759,"time":"2018-01-22T15:14:21.921000Z"}
{"type":"done","side":"sell","order_id":"d422e174-7148-411d-ba30-ecc17f21be69","reason":"canceled","product_id":"BTC-EUR","price":"8848.94000000","remaining_size":"0.11241548","sequence":3257976760,"time":"2018-01-22T15:14:21.935000Z"}
{"type":"received","order_id":"bbfaf088-494f-4bf9-a1a0-0c227b07ba62","order_type":"limit","size":"0.10500000","price":"8831.68000000","side":"buy","client_oid":"666e2c00-a029-40f7-89df-21b08b387072","product_id":"BTC-EUR","sequence":3257976761,"time":"2018-01-22T15:14:21.960000Z"}
{"type":"open","side":"buy","price":"8831.68000000","order_id":"bbfaf088-494f-4bf9-a1a0-0c227b07ba62","remaining_size":"0.10500000","product_id":"BTC-EUR","sequence":3257976762,"time":"2018-01-22T15:14:21.960000Z"}
{"type":"received","order_id":"008edbe7-a597-43de-8b83-9bea4e9d774f","order_type":"limit","size":"0.05000000","price":"8000.00000000","side":"buy","client_oid":"5bdd6c3d-3670-46de-da6e-2a231be953df","product_id":"BTC-EUR","sequence":3257976763,"time":"2018-01-22T15:14:21.990000Z"}
{"type":"open","side":"buy","price":"8000.00000000","order_id":"008edbe7-a597-43de-8b83-9bea4e9d774f","remaining_size":"0.05000000","product_id":"BTC-EUR","sequence":3257976764,"time":"2018-01-22T15:14:21.990000Z"}
{"type":"received","order_id":"fe223343-6b04-44af-a01d-d3e6de982e4e","order_type":"limit","size":"0.10500000","price":"8831.68000000","side":"buy","client_oid":"dd3d7cd4-f099-4492-a23a-5ce4efcb4835","product_id":"BTC-EUR","sequence":3257976765,"time":"2018-01-22T15:14:22.182000Z"}
{"type":"open","side":"buy","price":"8831.68000000","order_id":"fe223343-6b04-44af-a01d-d3e6de982e4e","remaining_size":"0.10500000","product_id":"BTC-EUR","sequence":3257976766,"time":"2018-01-22T15:14:22.182000Z"}
{"type":"received","order_id":"78ad7e81-16d4-4fa1-be50-ea6f1526881d","order_type":"limit","size":"0.11241548","price":"8848.92000000","side":"sell","product_id":"BTC-EUR","sequence":3257976767,"time":"2018-01-22T15:14:22.290000Z"}
{"type":"open","side":"sell","price":"8848.92000000","order_id":"78ad7e81-16d4-4fa1-be50-ea6f1526881d","remaining_size":"0.11241548","product_id":"BTC-EUR","sequence":3257976768,"time":"2018-01-22T15:14:22.290000Z"}
{"type":"done","side":"buy","order_id":"e851bb5e-4697-49c6-9c07-3102765479a3","reason":"canceled","product_id":"BTC-EUR","price":"8659.20000000","remaining_size":"1.89425000","sequence":3257976769,"time":"2018-01-22T15:14:22.334000Z"}
{"type":"received","order_id":"62e969e3-5d0c-42c5-aeb5-1e7f4c5d1d51","order_type":"limit","size":"2.09868805","price":"7177.00000000","side":"buy","client_oid":"cf86fcce-4ab8-4a7b-857f-667e96114605","product_id":"BTC-EUR","sequence":3257976770,"time":"2018-01-22T15:14:22.423000Z"}
{"type":"open","side":"buy","price":"7177.00000000","order_id":"62e969e3-5d0c-42c5-aeb5-1e7f4c5d1d51","remaining_size":"2.09868805","product_id":"BTC-EUR","sequence":3257976771,"time":"2018-01-22T15:14:22.423000Z"}
{"type":"received","order_id":"72855c51-5dfe-42e6-94af-3536c9ca3a4d","order_type":"limit","size":"1.89540000","price":"8659.00000000","side":"buy","client_oid":"f18580d4-6fc7-45a9-aa88-7c935d72ab63","product_id":"BTC-EUR","sequence":3257976772,"time":"2018-01-22T15:14:22.468000Z"}
{"type":"open","side":"buy","price":"8659.00000000","order_id":"72855c51-5dfe-42e6-94af-3536c9ca3a4d","remaining_size":"1.89540000","product_id":"BTC-EUR","sequence":3257976773,"time":"2018-01-22T15:14:22.468000Z"}
{"type":"done","side":"sell","order_id":"c4acbaba-de29-40fa-ace1-1ecb527f752c","reason":"canceled","product_id":"BTC-EUR","price":"8848.92000000","remaining_size":"0.22947933","sequence":3257976774,"time":"2018-01-22T15:14:22.545000Z"}
{"type":"done","side":"sell","order_id":"ca644cd9-9ab9-4e31-a429-a0a8b1cbce6a","reason":"canceled","product_id":"BTC-EUR","price":"8848.92000000","remaining_size":"0.04164971","sequence":3257976775,"time":"2018-01-22T15:14:22.559000Z"}
{"type":"received","order_id":"392b0d34-1260-4068-8c83-9ada2f50199a","order_type":"limit","size":"0.22947933","price":"8848.90000000","side":"sell","client_oid":"3b8a6998-27de-4a4a-9b72-8e646d0e5d0c","product_id":"BTC-EUR","sequence":3257976776,"time":"2018-01-22T15:14:22.798000Z"}
{"type":"open","side":"sell","price":"8848.90000000","order_id":"392b0d34-1260-4068-8c83-9ada2f50199a","remaining_size":"0.22947933","product_id":"BTC-EUR","sequence":3257976777,"time":"2018-01-22T15:14:22.798000Z"}
{"type":"received","order_id":"cf3b29ed-87a5-444d-9536-a44932f6c0bc","order_type":"limit","size":"0.04164971","price":"8848.90000000","side":"sell","client_oid":"8d2fc9d4-1403-4baf-a4f0-2a5045c97d93","product_id":"BTC-EUR","sequence":3257976778,"time":"2018-01-22T15:14:22.802000Z"}
{"type":"open","side":"sell","price":"8848.90000000","order_id":"cf3b29ed-87a5-444d-9536-a44932f6c0bc","remaining_size":"0.04164971","product_id":"BTC-EUR","sequence":3257976779,"time":"2018-01-22T15:14:22.802000Z"}
{"type":"done","side":"sell","order_id":"7934dc53-bbdd-4643-be6d-a64017f4cece","reason":"canceled","product_id":"BTC-EUR","price":"8848.92000000","remaining_size":"0.01887096","sequence":3257976780,"time":"2018-01-22T15:14:22.910000Z"}
{"type":"received","order_id":"049f54cf-c4ff-41b4-a7d9-7e8251fbed92","order_type":"limit","size":"6.41544856","price":"8755.06000000","side":"buy","product_id":"BTC-EUR","sequence":3257976781,"time":"2018-01-22T15:14:22.924000Z"}
{"type":"open","side":"buy","price":"8755.06000000","order_id":"049f54cf-c4ff-41b4-a7d9-7e8251fbed92","remaining_size":"6.41544856","product_id":"BTC-EUR","sequence":3257976782,"time":"2018-01-22T15:14:22.924000Z"}
{"type":"received","order_id":"c5df1663-5b4e-435c-8c37-5e004a4f8d97","order_type":"limit","size":"0.01887096","price":"8848.90000000","side":"sell","client_oid":"6fabafc2-74c7-4c2d-be74-98835897664c","product_id":"BTC-EUR","sequence":3257976783,"time":"2018-01-22T15:14:23.128000Z"}
{"type":"open","side":"sell","price":"8848.90000000","order_id":"c5df1663-5b4e-435c-8c37-5e004a4f8d97","remaining_size":"0.01887096","product_id":"BTC-EUR","sequence":3257976784,"time":"2018-01-22T15:14:23.128000Z"}
{"type":"received","order_id":"3f491261-2ff4-4f15-aa86-22c7161af8e6","order_type":"limit","size":"0.04693657","price":"8611.23000000","side":"buy","client_oid":"3e51ac8b-646c-4ccb-b84b-2bff05302e01","product_id":"BTC-EUR","sequence":3257976785,"time":"2018-01-22T15:14:23.175000Z"}
{"type":"open","side":"buy","price":"8611.23000000","order_id":"3f491261-2ff4-4f15-aa86-22c7161af8e6","remaining_size":"0.04693657","product_id":"BTC-EUR","sequence":3257976786,"time":"2018-01-22T15:14:23.175000Z"}
{"type":"received","order_id":"7ac3fbb9-8988-4d33-ac73-289b4b1accb6","order_type":"limit","size":"0.04000000","price":"9096.64000000","side":"buy","product_id":"BTC-EUR","sequence":3257976787,"time":"2018-01-22T15:14:23.200000Z"}
{"type":"match","trade_id":10551320,"maker_order_id":"1c5b415e-d734-416e-96a0-4e2664348cc9","taker_order_id":"7ac3fbb9-8988-4d33-ac73-289b4b1accb6","side":"sell","size":"0.04000000","price":"8831.69000000","product_id":"BTC-EUR","sequence":3257976788,"time":"2018-01-22T15:14:23.200000Z"}
{"type":"done","side":"buy","order_id":"7ac3fbb9-8988-4d33-ac73-289b4b1accb6","reason":"filled","product_id":"BTC-EUR","price":"9096.64000000","remaining_size":"0.00000000","sequence":3257976789,"time":"2018-01-22T15:14:23.200000Z"}
{"type":"done","side":"buy","order_id":"049f54cf-c4ff-41b4-a7d9-7e8251fbed92","reason":"canceled","product_id":"BTC-EUR","price":"8755.06000000","remaining_size":"6.41544856","sequence":3257976790,"time":"2018-01-22T15:14:23.539000Z"}
{"type":"done","side":"sell","order_id":"af118848-c71b-41fb-b982-69379b9c3dfd","reason":"canceled","product_id":"BTC-EUR","price":"8831.69000000","remaining_size":"0.07072160","sequence":3257976791,"time":"2018-01-22T15:14:23.591000Z"}
{"type":"done","side":"sell","order_id":"78ad7e81-16d4-4fa1-be50-ea6f1526881d","reason":"canceled","product_id":"BTC-EUR","price":"8848.92000000","remaining_size":"0.11241548","sequence":3257976792,"time":"2018-01-22T15:14:23.627000Z"}
{"type":"received","order_id":"314e0e57-326e-4a14-a737-21ebd0a6d8dc","order_type":"limit","size":"0.07113685","price":"8800.10000000","side":"buy","client_oid":"e89b2ea2-51eb-4071-d114-da1e03cb0a9e","product_id":"BTC-EUR","sequence":3257976793,"time":"2018-01-22T15:14:23.707000Z"}
{"type":"open","side":"buy","price":"8800.10000000","order_id":"314e0e57-326e-4a14-a737-21ebd0a6d8dc","remaining_size":"0.07113685","product_id":"BTC-EUR","sequence":3257976794,"time":"2018-01-22T15:14:23.707000Z"}
{"type":"received","order_id":"923ce542-4dfc-42a8-b763-6b633499944a","order_type":"limit","size":"0.11241548","price":"8848.90000000","side":"sell","product_id":"BTC-EUR","sequence":3257976795,"time":"2018-01-22T15:14:23.790000Z"}
{"type":"open","side":"sell","price":"8848.90000000","order_id":"923ce542-4dfc-42a8-b763-6b633499944a","remaining_size":"0.11241548","product_id":"BTC-EUR","sequence":3257976796,"time":"2018-01-22T15:14:23.790000Z"}
{"type":"received","order_id":"8277571f-cea5-423f-abf2-ffa3ca914438","order_type":"limit","size":"0.17052230","price":"8831.69000000","side":"sell","product_id":"BTC-EUR","sequence":3257976797,"time":"2018-01-22T15:14:23.806000Z"}
{"type":"open","side":"sell","price":"8831.69000000","order_id":"8277571f-cea5-423f-abf2-ffa3ca914438","remaining_size":"0.17052230","product_id":"BTC-EUR","sequence":3257976798,"time":"2018-01-22T15:14:23.806000Z"}
{"type":"done","side":"buy","order_id":"22cea007-1059-414d-b922-d9c7c0988629","reason":"canceled","product_id":"BTC-EUR","price":"8823.33000000","remaining_size":"0.18512519","sequence":3257976799,"time":"2018-01-22T15:14:23.828000Z"}
{"type":"received","order_id":"5cae6571-2065-4887-a3c6-e5b1708835fb","order_type":"limit","size":"0.05000000","price":"9600.00000000","side":"sell","client_oid":"bc1a7478-66b6-4601-ed9e-bb46e46c1400","product_id":"BTC-EUR","sequence":3257976800,"time":"2018-01-22T15:14:23.857000Z"}
{"type":"open","side":"sell","price":"9600.00000000","order_id":"5cae6571-2065-4887-a3c6-e5b1708835fb","remaining_size":"0.05000000","product_id":"BTC-EUR","sequence":3257976801,"time":"2018-01-22T15:14:23.857000Z"}
{"type":"done","side":"sell","order_id":"cf3b29ed-87a5-444d-9536-a44932f6c0bc","reason":"canceled","product_id":"BTC-EUR","price":"8848.90000000","remaining_size":"0.04164971","sequence":3257976802,"time":"2018-01-22T15:14:23.998000Z"}
{"type":"done","side":"sell","order_id":"c5df1663-5b4e-435c-8c37-5e004a4f8d97","reason":"canceled","product_id":"BTC-EUR","price":"8848.90000000","remaining_size":"0.01887096","sequence":3257976803,"time":"2018-01-22T15:14:24.008000Z"}
{"type":"done","side":"sell","order_id":"392b0d34-1260-4068-8c83-9ada2f50199a","reason":"canceled","product_id":"BTC-EUR","price":"8848.90000000","remaining_size":"0.22947933","sequence":3257976804,"time":"2018-01-22T15:14:24.044000Z"}
{"type":"done","side":"sell","order_id":"2b910792-2c90-42c6-8e51-f3b1983d185a","reason":"canceled","product_id":"BTC-EUR","price":"9106.63000000","remaining_size":"1.28000000","sequence":3257976805,"time":"2018-01-22T15:14:24.045000Z"}
{"type":"received","order_id":"08d66da9-664e-469c-8056-485a31b51e5e","order_type":"limit","size":"0.01887096","price":"8848.88000000","side":"sell","client_oid":"608d4499-e3fb-4b2b-876e-86563250a5b5","product_id":"BTC-EUR","sequence":3257976806,"time":"2018-01-22T15:14:24.280000Z"}
{"type":"open","side":"sell","price":"8848.88000000","order_id":"08d66da9-664e-469c-8056-485a31b51e5e","remaining_size":"0.01887096","product_id":"BTC-EUR","sequence":3257976807,"time":"2018-01-22T15:14:24.280000Z"}
{"type":"received","order_id":"99a2428a-3a93-459a-b10d-023e1f935d1d","order_type":"limit","size":"0.22947933","price":"8848.88000000","side":"sell","client_oid":"86f839b1-9382-4436-9a12-9d1cfeebd933","product_id":"BTC-EUR","sequence":3257976808,"time":"2018-01-22T15:14:24.293000Z"}
{"type":"open","side":"sell","price":"8848.88000000","order_id":"99a2428a-3a93-459a-b10d-023e1f935d1d","remaining_size":"0.22947933","product_id":"BTC-EUR","sequence":3257976809,"time":"2018-01-22T15:14:24.293000Z"}
{"type":"received","order_id":"c2332882-c09f-40d0-8b45-6d95ea45718f","order_type":"limit","size":"0.04164971","price":"8848.88000000","side":"sell","client_oid":"cdbac12f-bfb3-434d-921d-a1aea9425e58","product_id":"BTC-EUR","sequence":3257976810,"time":"2018-01-22T15:14:24.299000Z"}
{"type":"open","side":"sell","price":"8848.88000000","order_id":"c2332882-c09f-40d0-8b45-6d95ea45718f","remaining_size":"0.04164971","product_id":"BTC-EUR","sequence":3257976811,"time":"2018-01-22T15:14:24.299000Z"}
{"type":"done","side":"buy","order_id":"157fa50a-98ba-4e46-9ff8-dc5dc86a688a","reason":"canceled","product_id":"BTC-EUR","price":"8632.91000000","remaining_size":"1.28000000","sequence":3257976812,"time":"2018-01-22T15:14:24.360000Z"}
{"type":"received","order_id":"97c623ef-012e-48cc-8b3d-f58ff87cfe68","order_type":"limit","size":"0.05000000","price":"9096.64000000","side":"buy","product_id":"BTC-EUR","sequence":3257976813,"time":"2018-01-22T15:14:24.367000Z"}
{"type":"match","trade_id":10551321,"maker_order_id":"1c5b415e-d734-416e-96a0-4e2664348cc9","taker_order_id":"97c623ef-012e-48cc-8b3d-f58ff87cfe68","side":"sell","size":"0.01825681","price":"8831.69000000","product_id":"BTC-EUR","sequence":3257976814,"time":"2018-01-22T15:14:24.367000Z"}
{"type":"done","side":"sell","order_id":"1c5b415e-d734-416e-96a0-4e2664348cc9","reason":"filled","product_id":"BTC-EUR","price":"8831.69000000","remaining_size":"0","sequence":3257976815,"time":"2018-01-22T15:14:24.367000Z"}
{"type":"match","trade_id":10551322,"maker_order_id":"80ee1692-b809-4916-aeb3-90920041ea09","taker_order_id":"97c623ef-012e-48cc-8b3d-f58ff87cfe68","side":"sell","size":"0.03174319","price":"8831.69000000","product_id":"BTC-EUR","sequence":3257976816,"time":"2018-01-22T15:14:24.367000Z"}
{"type":"done","side":"buy","order_id":"97c623ef-012e-48cc-8b3d-f58ff87cfe68","reason":"filled","product_id":"BTC-EUR","price":"9096.64000000","remaining_size":"0.00000000","sequence":3257976817,"time":"2018-01-22T15:14:24.367000Z"}
{"type":"done","side":"sell","order_id":"b49a2e3a-3642-4c1a-b348-8ce39664486d","reason":"canceled","product_id":"BTC-EUR","price":"8891.52000000","remaining_size":"0.18370534","sequence":3257976818,"time":"2018-01-22T15:14:24.369000Z"}
{"type":"done","side":"buy","order_id":"72855c51-5dfe-42e6-94af-3536c9ca3a4d","reason":"canceled","product_id":"BTC-EUR","price":"8659.00000000","remaining_size":"1.89540000","sequence":3257976819,"time":"2018-01-22T15:14:24.433000Z"}
{"type":"done","side":"buy","order_id":"76b7dba8-9725-47cb-96f4-a5cdcdcacb98","reason":"canceled","product_id":"BTC-EUR","price":"8831.68000000","remaining_size":"0.10500000","sequence":3257976820,"time":"2018-01-22T15:14:24.449000Z"}
{"type":"done","side":"buy","order_id":"fe223343-6b04-44af-a01d-d3e6de982e4e","reason":"canceled","product_id":"BTC-EUR","price":"8831.68000000","remaining_size":"0.10500000","sequence":3257976821,"time":"2018-01-22T15:14:24.462000Z"}
{"type":"done","side":"buy","order_id":"bbfaf088-494f-4bf9-a1a0-0c227b07ba62","reason":"canceled","product_id":"BTC-EUR","price":"8831.68000000","remaining_size":"0.10500000","sequence":3257976822,"time":"2018-01-22T15:14:24.473000Z"}
{"type":"received","order_id":"79926fff-9973-41de-af78-20d2454478b1","order_type":"limit","size":"1.89411000","price":"8659.40000000","side":"buy","client_oid":"33de7351-1390-4575-be1e-5033e09781bb","product_id":"BTC-EUR","sequence":3257976823,"time":"2018-01-22T15:14:24.591000Z"}
{"type":"open","side":"buy","price":"8659.40000000","order_id":"79926fff-9973-41de-af78-20d2454478b1","remaining_size":"1.89411000","product_id":"BTC-EUR","sequence":3257976824,"time":"2018-01-22T15:14:24.591000Z"}
{"type":"received","order_id":"8fd67c64-a205-455d-bbd7-215065ef6b7e","order_type":"limit","size":"0.18512519","price":"8823.33000000","side":"buy","client_oid":"1696dd38-8e45-4bdb-8eee-1160ea1049c1","product_id":"BTC-EUR","sequence":3257976825,"time":"2018-01-22T15:14:24.817000Z"}
{"type":"open","side":"buy","price":"8823.33000000","order_id":"8fd67c64-a205-455d-bbd7-215065ef6b7e","remaining_size":"0.18512519","product_id":"BTC-EUR","sequence":3257976826,"time":"2018-01-22T15:14:24.817000Z"}
{"type":"received","order_id":"e7c99267-21b2-4329-af5b-cbac6d5f4be1","order_type":"limit","size":"6.41544856","price":"8752.13000000","side":"buy","product_id":"BTC-EUR","sequence":3257976827,"time":"2018-01-22T15:14:24.980000Z"}
{"type":"open","side":"buy","price":"8752.13000000","order_id":"e7c99267-21b2-4329-af5b-cbac6d5f4be1","remaining_size":"6.41544856","product_id":"BTC-EUR","sequence":3257976828,"time":"2018-01-22T15:14:24.980000Z"}
{"type":"received","order_id":"53e35e1a-183f-43a2-980d-e2b75d837b50","order_type":"limit","size":"0.10500000","price":"8831.68000000","side":"buy","client_oid":"0708a255-ec31-4cb6-b336-3a64fa5d6c93","product_id":"BTC-EUR","sequence":3257976829,"time":"2018-01-22T15:14:25.067000Z"}
{"type":"open","side":"buy","price":"8831.68000000","order_id":"53e35e1a-183f-43a2-980d-e2b75d837b50","remaining_size":"0.10500000","product_id":"BTC-EUR","sequence":3257976830,"time":"2018-01-22T15:14:25.067000Z"}
{"type":"received","order_id":"1cef5a6f-f703-4592-b263-c7c47a74b2db","order_type":"limit","size":"0.18389114","price":"8882.54000000","side":"sell","client_oid":"4949cf4d-8306-4499-b9b6-5e3c2375d4e7","product_id":"BTC-EUR","sequence":3257976831,"time":"2018-01-22T15:14:25.128000Z"}
{"type":"open","side":"sell","price":"8882.54000000","order_id":"1cef5a6f-f703-4592-b263-c7c47a74b2db","remaining_size":"0.18389114","product_id":"BTC-EUR","sequence":3257976832,"time":"2018-01-22T15:14:25.128000Z"}
{"type":"received","order_id":"960a87a2-5cba-43f2-b0ad-b7f342e2f79c","order_type":"limit","size":"0.10500000","price":"8831.68000000","side":"buy","client_oid":"7f0fb343-e36e-4a9d-bc54-cc598d1dab7d","product_id":"BTC-EUR","sequence":3257976833,"time":"2018-01-22T15:14:25.165000Z"}
{"type":"open","side":"buy","price":"8831.68000000","order_id":"960a87a2-5cba-43f2-b0ad-b7f342e2f79c","remaining_size":"0.10500000","product_id":"BTC-EUR","sequence":3257976834,"time":"2018-01-22T15:14:25.165000Z"}
{"type":"received","order_id":"ac5a43f9-80f3-4fc2-a47d-705bd6c6ced7","order_type":"limit","size":"0.10500000","price":"8831.68000000","side":"buy","client_oid":"1f55d8c9-c492-4c9d-a3b5-f3f3392a5cd6","product_id":"BTC-EUR","sequence":3257976835,"time":"2018-01-22T15:14:25.230000Z"}
{"type":"open","side":"buy","price":"8831.68000000","order_id":"ac5a43f9-80f3-4fc2-a47d-705bd6c6ced7","remaining_size":"0.10500000","product_id":"BTC-EUR","sequence":3257976836,"time":"2018-01-22T15:14:25.230000Z"}
{"type":"done","side":"sell","order_id":"923ce542-4dfc-42a8-b763-6b633499944a","reason":"canceled","product_id":"BTC-EUR","price":"8848.90000000","remaining_size":"0.11241548","sequence":3257976837,"time":"2018-01-22T15:14:25.252000Z"}
{"type":"received","order_id":"c04b90bf-9649-4d6f-a0a7-892b3cd6f618","order_type":"limit","size":"0.15121806","price":"8986.04000000","side":"sell","product_id":"BTC-EUR","sequence":3257976838,"time":"2018-01-22T15:14:25.263000Z"}
{"type":"open","side":"sell","price":"8986.04000000","order_id":"c04b90bf-9649-4d6f-a0a7-892b3cd6f618","remaining_size":"0.15121806","product_id":"BTC-EUR","sequence":3257976839,"time":"2018-01-22T15:14:25.263000Z"}
{"type":"received","order_id":"6e20f5d3-488a-465e-9dc1-20413dbfacc5","order_type":"limit","size":"0.11241548","price":"8848.88000000","side":"sell","product_id":"BTC-EUR","sequence":3257976840,"time":"2018-01-22T15:14:25.401000Z"}
{"type":"open","side":"sell","price":"8848.88000000","order_id":"6e20f5d3-488a-465e-9dc1-20413dbfacc5","remaining_size":"0.11241548","product_id":"BTC-EUR","sequence":3257976841,"time":"2018-01-22T15:14:25.401000Z"}
{"type":"done","side":"sell","order_id":"1cef5a6f-f703-4592-b263-c7c47a74b2db","reason":"canceled","product_id":"BTC-EUR","price":"8882.54000000","remaining_size":"0.18389114","sequence":3257976842,"time":"2018-01-22T15:14:25.416000Z"}
{"type":"done","side":"sell","order_id":"f9f931b8-618b-47c9-88bb-54a799640dfa","reason":"canceled","product_id":"BTC-EUR","price":"8966.09000000","remaining_size":"0.12596372","sequence":3257976843,"time":"2018-01-22T15:14:25.437000Z"}
{"type":"done","side":"sell","order_id":"08d66da9-664e-469c-8056-485a31b51e5e","reason":"canceled","product_id":"BTC-EUR","price":"8848.88000000","remaining_size":"0.01887096","sequence":3257976844,"time":"2018-01-22T15:14:25.465000Z"}
{"type":"done","side":"sell","order_id":"99a2428a-3a93-459a-b10d-023e1f935d1d","reason":"canceled","product_id":"BTC-EUR","price":"8848.88000000","remaining_size":"0.22947933","sequence":3257976845,"time":"2018-01-22T15:14:25.490000Z"}
{"type":"done","side":"sell","order_id":"c2332882-c09f-40d0-8b45-6d95ea45718f","reason":"canceled","product_id":"BTC-EUR","price":"8848.88000000","remaining_size":"0.04164971","sequence":3257976846,"time":"2018-01-22T15:14:25.504000Z"}
{"type":"received","order_id":"adc15d8d-17c6-41d9-a7e1-400d8c9fee9f","order_type":"limit","size":"0.01887096","price":"8848.86000000","side":"sell","client_oid":"d6507b33-b1aa-49af-9500-354d03293046","product_id":"BTC-EUR","sequence":3257976847,"time":"2018-01-22T15:14:25.691000Z"}
{"type":"open","side":"sell","price":"8848.86000000","order_id":"adc15d8d-17c6-41d9-a7e1-400d8c9fee9f","remaining_size":"0.01887096","product_id":"BTC-EUR","sequence":3257976848,"time":"2018-01-22T15:14:25.691000Z"}
{"type":"received","order_id":"e3cb91c2-9d9a-4684-8f7b-0fa85ae11994","order_type":"limit","size":"0.22947933","price":"8848.86000000","side":"sell","client_oid":"d26c0baa-2d62-48a1-b875-b781555b14d6","product_id":"BTC-EUR","sequence":3257976849,"time":"2018-01-22T15:14:25.724000Z"}
{"type":"open","side":"sell","price":"8848.86000000","order_id":"e3cb91c2-9d9a-4684-8f7b-0fa85ae11994","remaining_size":"0.22947933","product_id":"BTC-EUR","sequence":3257976850,"time":"2018-01-22T15:14:25.724000Z"}
{"type":"received","order_id":"38ff62ca-daab-4a58-92b0-544d33be7beb","order_type":"limit","size":"0.04164971","price":"8848.86000000","side":"sell","client_oid":"13af369a-ddc0-40f7-a5cc-04f34a0e9cd7","product_id":"BTC-EUR","sequence":3257976851,"time":"2018-01-22T15:14:25.774000Z"}
{"type":"open","side":"sell","price":"8848.86000000","order_id":"38ff62ca-daab-4a58-92b0-544d33be7beb","remaining_size":"0.04164971","product_id":"BTC-EUR","sequence":3257976852,"time":"2018-01-22T15:14:25.774000Z"}
{"type":"received","order_id":"070a1df4-259a-43c5-80f7-3c3d088ac1bc","order_type":"limit","size":"0.01250000","price":"8800.00000000","side":"buy","client_oid":"32e013dc-19da-4d2e-fd2f-1fab96120483","product_id":"BTC-EUR","sequence":3257976853,"time":"2018-01-22T15:14:25.884000Z"}
{"type":"open","side":"buy","price":"8800.00000000","order_id":"070a1df4-259a-43c5-80f7-3c3d088ac1bc","remaining_size":"0.01250000","product_id":"BTC-EUR","sequence":3257976854,"time":"2018-01-22T15:14:25.884000Z"}
{"type":"received","order_id":"e20f707e-84ef-478b-a9cc-cf88fba84bc9","order_type":"limit","size":"0.18394187","price":"8880.09000000","side":"sell","client_oid":"35640457-e9e9-4fde-9933-421eb4091233","product_id":"BTC-EUR","sequence":3257976855,"time":"2018-01-22T15:14:25.941000Z"}
{"type":"open","side":"sell","price":"8880.09000000","order_id":"e20f707e-84ef-478b-a9cc-cf88fba84bc9","remaining_size":"0.18394187","product_id":"BTC-EUR","sequence":3257976856,"time":"2018-01-22T15:14:25.941000Z"}
{"type":"done","side":"sell","order_id":"81595899-8c86-4c3b-b879-4517a86a6aee","reason":"canceled","product_id":"BTC-EUR","price":"8831.69000000","remaining_size":"0.14814796","sequence":3257976857,"time":"2018-01-22T15:14:25.978000Z"}
{"type":"done","side":"sell","order_id":"8277571f-cea5-423f-abf2-ffa3ca914438","reason":"canceled","product_id":"BTC-EUR","price":"8831.69000000","remaining_size":"0.17052230","sequence":3257976858,"time":"2018-01-22T15:14:26.083000Z"}
{"type":"received","order_id":"0085976f-4fbd-4e2e-b2d6-2ffacc157ab0","order_type":"limit","size":"0.06000000","price":"9096.64000000","side":"buy","product_id":"BTC-EUR","sequence":3257976859,"time":"2018-01-22T15:14:26.221000Z"}
{"type":"match","trade_id":10551323,"maker_order_id":"80ee1692-b809-4916-aeb3-90920041ea09","taker_order_id":"0085976f-4fbd-4e2e-b2d6-2ffacc157ab0","side":"sell","size":"0.06000000","price":"8831.69000000","product_id":"BTC-EUR","sequence":3257976860,"time":"2018-01-22T15:14:26.221000Z"}
{"type":"done","side":"buy","order_id":"0085976f-4fbd-4e2e-b2d6-2ffacc157ab0","reason":"filled","product_id":"BTC-EUR","price":"9096.64000000","remaining_size":"0.00000000","sequence":3257976861,"time":"2018-01-22T15:14:26.221000Z"}
{"type":"received","order_id":"7684e396-2a5b-462f-90ea-9514fc838ad6","order_type":"limit","size":"1.28000000","price":"9104.09000000","side":"sell","product_id":"BTC-EUR","sequence":3257976862,"time":"2018-01-22T15:14:26.239000Z"}
{"type":"open","side":"sell","price":"9104.09000000","order_id":"7684e396-2a5b-462f-90ea-9514fc838ad6","remaining_size":"1.28000000","product_id":"BTC-EUR","sequence":3257976863,"time":"2018-01-22T15:14:26.239000Z"}
{"type":"received","order_id":"5e15f17c-d2f1-4953-9ed4-8bb9d9641fbb","order_type":"limit","size":"0.01000000","price":"9096.64000000","side":"buy","product_id":"BTC-EUR","sequence":3257976864,"time":"2018-01-22T15:14:26.351000Z"}
{"type":"match","trade_id":10551324,"maker_order_id":"80ee1692-b809-4916-aeb3-90920041ea09","taker_order_id":"5e15f17c-d2f1-4953-9ed4-8bb9d9641fbb","side":"sell","size":"0.01000000","price":"8831.69000000","product_id":"BTC-EUR","sequence":3257976865,"time":"2018-01-22T15:14:26.351000Z"}
{"type":"done","side":"buy","order_id":"5e15f17c-d2f1-4953-9ed4-8bb9d9641fbb","reason":"filled","product_id":"BTC-EUR","price":"9096.64000000","remaining_size":"0.00000000","sequence":3257976866,"time":"2018-01-22T15:14:26.351000Z"}
{"type":"received","order_id":"a3456704-5f75-4459-887b-72c082172b54","order_type":"limit","size":"0.06666600","price":"8831.68000000","side":"buy","product_id":"BTC-EUR","sequence":3257976867,"time":"2018-01-22T15:14:26.371000Z"}
{"type":"open","side":"buy","price":"8831.68000000","order_id":"a3456704-5f75-4459-887b-72c082172b54","remaining_size":"0.06666600","product_id":"BTC-EUR","sequence":3257976868,"time":"2018-01-22T15:14:26.371000Z"}
{"type":"done","side":"buy","order_id":"79926fff-9973-41de-af78-20d2454478b1","reason":"canceled","product_id":"BTC-EUR","price":"8659.40000000","remaining_size":"1.89411000","sequence":3257976869,"time":"2018-01-22T15:14:26.445000Z"}
{"type":"received","order_id":"d9cde01c-08d4-42de-b671-3732aaf9bfe0","order_type":"limit","size":"0.03000000","price":"9096.64000000","side":"buy","product_id":"BTC-EUR","sequence":3257976870,"time":"2018-01-22T15:14:26.545000Z"}
{"type":"match","trade_id":10551325,"maker_order_id":"80ee1692-b809-4916-aeb3-90920041ea09","taker_order_id":"d9cde01c-08d4-42de-b671-3732aaf9bfe0","side":"sell","size":"0.03000000","price":"8831.69000000","product_id":"BTC-EUR","sequence":3257976871,"time":"2018-01-22T15:14:26.545000Z"}
{"type":"done","side":"buy","order_id":"d9cde01c-08d4-42de-b671-3732aaf9bfe0","reason":"filled","product_id":"BTC-EUR","price":"9096.64000000","remaining_size":"0.00000000","sequence":3257976872,"time":"2018-01-22T15:14:26.545000Z"}
{"type":"received","order_id":"51f86467-7256-41ae-8c0c-6f5af256b48d","order_type":"limit","size":"1.89473000","price":"8659.00000000","side":"buy","client_oid":"ab4ae42f-b7e3-4483-b242-9e811ba1479e","product_id":"BTC-EUR","sequence":3257976873,"time":"2018-01-22T15:14:26.568000Z"}
{"type":"open","side":"buy","price":"8659.00000000","order_id":"51f86467-7256-41ae-8c0c-6f5af256b48d","remaining_size":"1.89473000","product_id":"BTC-EUR","sequence":3257976874,"time":"2018-01-22T15:14:26.568000Z"}
{"type":"received","order_id":"86b02e6a-18ec-4c8b-95de-331ad761144b","order_type":"limit","size":"1.28000000","price":"8633.31000000","side":"buy","product_id":"BTC-EUR","sequence":3257976875,"time":"2018-01-22T15:14:26.597000Z"}
{"type":"open","side":"buy","price":"8633.31000000","order_id":"86b02e6a-18ec-4c8b-95de-331ad761144b","remaining_size":"1.28000000","product_id":"BTC-EUR","sequence":3257976876,"time":"2018-01-22T15:14:26.597000Z"}
{"type":"done","side":"buy","order_id":"e7c99267-21b2-4329-af5b-cbac6d5f4be1","reason":"canceled","product_id":"BTC-EUR","price":"8752.13000000","remaining_size":"6.41544856","sequence":3257976877,"time":"2018-01-22T15:14:26.666000Z"}
{"type":"done","side":"sell","order_id":"6e20f5d3-488a-465e-9dc1-20413dbfacc5","reason":"canceled","product_id":"BTC-EUR","price":"8848.88000000","remaining_size":"0.11241548","sequence":3257976878,"time":"2018-01-22T15:14:26.909000Z"}
{"type":"received","order_id":"ba6d5b15-bf1b-448c-81d0-f9808849a847","order_type":"limit","size":"0.11241548","price":"8848.86000000","side":"sell","product_id":"BTC-EUR","sequence":3257976879,"time":"2018-01-22T15:14:27.062000Z"}
{"type":"open","side":"sell","price":"8848.86000000","order_id":"ba6d5b15-bf1b-448c-81d0-f9808849a847","remaining_size":"0.11241548","product_id":"BTC-EUR","sequence":3257976880,"time":"2018-01-22T15:14:27.062000Z"}
{"type":"received","order_id":"510df170-d3cc-4a35-a6b2-11717a3bd8bf","order_type":"limit","size":"0.05000000","price":"9096.64000000","side":"buy","product_id":"BTC-EUR","sequence":3257976881,"time":"2018-01-22T15:14:27.063000Z"}
{"type":"match","trade_id":10551326,"maker_order_id":"80ee1692-b809-4916-aeb3-90920041ea09","taker_order_id":"510df170-d3cc-4a35-a6b2-11717a3bd8bf","side":"sell","size":"0.05000000","price":"8831.69000000","product_id":"BTC-EUR","sequence":3257976882,"time":"2018-01-22T15:14:27.063000Z"}
{"type":"done","side":"buy","order_id":"510df170-d3cc-4a35-a6b2-11717a3bd8bf","reason":"filled","product_id":"BTC-EUR","price":"9096.64000000","remaining_size":"0.00000000","sequence":3257976883,"time":"2018-01-22T15:14:27.063000Z"}
{"type":"received","order_id":"9268b9a4-d629-4f8b-84b1-b4cf33dd2b2d","order_type":"limit","size":"0.01000000","price":"9096.64000000","side":"buy","product_id":"BTC-EUR","sequence":3257976884,"time":"2018-01-22T15:14:27.073000Z"}
{"type":"match","trade_id":10551327,"maker_order_id":"80ee1692-b809-4916-aeb3-90920041ea09","taker_order_id":"9268b9a4-d629-4f8b-84b1-b4cf33dd2b2d","side":"sell","size":"0.01000000","price":"8831.69000000","product_id":"BTC-EUR","sequence":3257976885,"time":"2018-01-22T15:14:27.073000Z"}
{"type":"done","side":"buy","order_id":"9268b9a4-d629-4f8b-84b1-b4cf33dd2b2d","reason":"filled","product_id":"BTC-EUR","price":"9096.64000000","remaining_size":"0.00000000","sequence":3257976886,"time":"2018-01-22T15:14:27.073000Z"}
{"type":"done","side":"sell","order_id":"38ff62ca-daab-4a58-92b0-544d33be7beb","reason":"canceled","product_id":"BTC-EUR","price":"8848.86000000","remaining_size":"0.04164971","sequence":3257976887,"time":"2018-01-22T15:14:27.118000Z"}
{"type":"done","side":"sell","order_id":"e3cb91c2-9d9a-4684-8f7b-0fa85ae11994","reason":"canceled","product_id":"BTC-EUR","price":"8848.86000000","remaining_size":"0.22947933","sequence":3257976888,"time":"2018-01-22T15:14:27.133000Z"}
{"type":"received","order_id":"09cbdbf3-ee11-4ead-a53b-fa19430b1885","order_type":"limit","size":"0.04164971","price":"8848.84000000","side":"sell","client_oid":"fe6ce6f5-06b6-4a51-a2cd-9e1b2b384267","product_id":"BTC-EUR","sequence":3257976889,"time":"2018-01-22T15:14:27.368000Z"}
{"type":"open","side":"sell","price":"8848.84000000","order_id":"09cbdbf3-ee11-4ead-a53b-fa19430b1885","remaining_size":"0.04164971","product_id":"BTC-EUR","sequence":3257976890,"time":"2018-01-22T15:14:27.368000Z"}
{"type":"received","order_id":"3942584d-7c61-4f98-aa71-5d6419c11268","order_type":"limit","size":"0.22947933","price":"8848.84000000","side":"sell","client_oid":"01d0ec50-7054-4de1-a1cb-1621f6893fd5","product_id":"BTC-EUR","sequence":3257976891,"time":"2018-01-22T15:14:27.382000Z"}
{"type":"open","side":"sell","price":"8848.84000000","order_id":"3942584d-7c61-4f98-aa71-5d6419c11268","remaining_size":"0.22947933","product_id":"BTC-EUR","sequence":3257976892,"time":"2018-01-22T15:14:27.382000Z"}
{"type":"done","side":"sell","order_id":"adc15d8d-17c6-41d9-a7e1-400d8c9fee9f","reason":"canceled","product_id":"BTC-EUR","price":"8848.86000000","remaining_size":"0.01887096","sequence":3257976893,"time":"2018-01-22T15:14:27.457000Z"}
{"type":"received","order_id":"c5eadb33-0435-4df1-a7d4-11b0dd09c87b","order_type":"limit","size":"0.01887096","price":"8848.84000000","side":"sell","client_oid":"4d95224d-6b91-494e-add2-27f364bf9d95","product_id":"BTC-EUR","sequence":3257976894,"time":"2018-01-22T15:14:27.698000Z"}
{"type":"open","side":"sell","price":"8848.84000000","order_id":"c5eadb33-0435-4df1-a7d4-11b0dd09c87b","remaining_size":"0.01887096","product_id":"BTC-EUR","sequence":3257976895,"time":"2018-01-22T15:14:27.698000Z"}
{"type":"received","order_id":"cf283498-1fa6-4ba1-845e-7864cd14a239","order_type":"market","size":"0.04932819","side":"sell","client_oid":"aaa392df-12ff-4d72-ff9b-c292b2680833","product_id":"BTC-EUR","sequence":3257976896,"time":"2018-01-22T15:14:27.943000Z"}
{"type":"match","trade_id":10551328,"maker_order_id":"bdf0cb95-d508-4539-9a23-4cd409adc998","taker_order_id":"cf283498-1fa6-4ba1-845e-7864cd14a239","side":"buy","size":"0.04932819","price":"8831.68000000","product_id":"BTC-EUR","sequence":3257976897,"time":"2018-01-22T15:14:27.943000Z"}
{"type":"done","side":"sell","order_id":"cf283498-1fa6-4ba1-845e-7864cd14a239","reason":"filled","product_id":"BTC-EUR","remaining_size":"0.00000000","sequence":3257976898,"time":"2018-01-22T15:14:27.943000Z"}
{"type":"done","side":"sell","order_id":"d1fc826d-f8b7-44c0-b7c3-36a7c1647ecb","reason":"canceled","product_id":"BTC-EUR","price":"8891.52000000","remaining_size":"0.45926334","sequence":3257976899,"time":"2018-01-22T15:14:27.991000Z"}
{"type":"received","order_id":"8bef2512-c086-4461-9c84-39e567dbff9e","order_type":"limit","size":"19.16578514","price":"7291.85000000","side":"buy","product_id":"BTC-EUR","sequence":3257976900,"time":"2018-01-22T15:14:28.216000Z"}
{"type":"open","side":"buy","price":"7291.85000000","order_id":"8bef2512-c086-4461-9c84-39e567dbff9e","remaining_size":"19.16578514","product_id":"BTC-EUR","sequence":3257976901,"time":"2018-01-22T15:14:28.216000Z"}
{"type":"done","side":"sell","order_id":"ba6d5b15-bf1b-448c-81d0-f9808849a847","reason":"canceled","product_id":"BTC-EUR","price":"8848.86000000","remaining_size":"0.11241548","sequence":3257976902,"time":"2018-01-22T15:14:28.329000Z"}
{"type":"received","order_id":"b517bf61-dfe9-4015-b650-2cfbae1921b4","order_type":"limit","size":"0.11241548","price":"8848.84000000","side":"sell","product_id":"BTC-EUR","sequence":3257976903,"time":"2018-01-22T15:14:28.452000Z"}
{"type":"open","side":"sell","price":"8848.84000000","order_id":"b517bf61-dfe9-4015-b650-2cfbae1921b4","remaining_size":"0.11241548","product_id":"BTC-EUR","sequence":3257976904,"time":"2018-01-22T15:14:28.452000Z"}
{"type":"received","order_id":"23d1fe9e-938b-4ea6-bb70-6d676d4ef808","order_type":"limit","size":"0.45985469","price":"8880.09000000","side":"sell","client_oid":"6a4fb14d-bc73-476c-9056-711c97ad5497","product_id":"BTC-EUR","sequence":3257976905,"time":"2018-01-22T15:14:28.526000Z"}
{"type":"open","side":"sell","price":"8880.09000000","order_id":"23d1fe9e-938b-4ea6-bb70-6d676d4ef808","remaining_size":"0.45985469","product_id":"BTC-EUR","sequence":3257976906,"time":"2018-01-22T15:14:28.526000Z"}
{"type":"done","side":"sell","order_id":"e20f707e-84ef-478b-a9cc-cf88fba84bc9","reason":"canceled","product_id":"BTC-EUR","price":"8880.09000000","remaining_size":"0.18394187","sequence":3257976907,"time":"2018-01-22T15:14:28.567000Z"}
{"type":"done","side":"sell","order_id":"c5eadb33-0435-4df1-a7d4-11b0dd09c87b","reason":"canceled","product_id":"BTC-EUR","price":"8848.84000000","remaining_size":"0.01887096","sequence":3257976908,"time":"2018-01-22T15:14:28.573000Z"}
{"type":"done","side":"sell","order_id":"3942584d-7c61-4f98-aa71-5d6419c11268","reason":"canceled","product_id":"BTC-EUR","price":"8848.84000000","remaining_size":"0.22947933","sequence":3257976909,"time":"2018-01-22T15:14:28.589000Z"}
{"type":"done","side":"sell","order_id":"09cbdbf3-ee11-4ead-a53b-fa19430b1885","reason":"canceled","product_id":"BTC-EUR","price":"8848.84000000","remaining_size":"0.04164971","sequence":3257976910,"time":"2018-01-22T15:14:28.589000Z"}
{"type":"received","order_id":"5944a13b-b505-4163-b599-71c31d167986","order_type":"limit","size":"0.04164971","price":"8848.82000000","side":"sell","client_oid":"97744a02-0918-4b0f-9884-ff5b99977d89","product_id":"BTC-EUR","sequence":3257976911,"time":"2018-01-22T15:14:28.923000Z"}
{"type":"open","side":"sell","price":"8848.82000000","order_id":"5944a13b-b505-4163-b599-71c31d167986","remaining_size":"0.04164971","product_id":"BTC-EUR","sequence":3257976912,"time":"2018-01-22T15:14:28.923000Z"}
{"type":"received","order_id":"bb1377ab-69cf-4e69-8b19-c35f4e1e4ab9","order_type":"limit","size":"0.22947933","price":"8848.82000000","side":"sell","client_oid":"bbde9049-2a1c-4b55-b8de-d82a06f6bad3","product_id":"BTC-EUR","sequence":3257976913,"time":"2018-01-22T15:14:28.925000Z"}
{"type":"open","side":"sell","price":"8848.82000000","order_id":"bb1377ab-69cf-4e69-8b19-c35f4e1e4ab9","remaining_size":"0.22947933","product_id":"BTC-EUR","sequence":3257976914,"time":"2018-01-22T15:14:28.925000Z"}
{"type":"received","order_id":"546f09e9-70d5-4570-b3dd-63fcf366786d","order_type":"limit","size":"0.07000000","price":"8566.73000000","side":"sell","product_id":"BTC-EUR","sequence":3257976915,"time":"2018-01-22T15:14:29.008000Z"}
{"type":"match","trade_id":10551329,"maker_order_id":"bdf0cb95-d508-4539-9a23-4cd409adc998","taker_order_id":"546f09e9-70d5-4570-b3dd-63fcf366786d","side":"buy","size":"0.01067181","price":"8831.68000000","product_id":"BTC-EUR","sequence":3257976916,"time":"2018-01-22T15:14:29.008000Z"}
{"type":"done","side":"buy","order_id":"bdf0cb95-d508-4539-9a23-4cd409adc998","reason":"filled","product_id":"BTC-EUR","price":"8831.68000000","remaining_size":"0","sequence":3257976917,"time":"2018-01-22T15:14:29.008000Z"}
{"type":"match","trade_id":10551330,"maker_order_id":"a3720b22-bb97-47b3-8739-9d842c83be6b","taker_order_id":"546f09e9-70d5-4570-b3dd-63fcf366786d","side":"buy","size":"0.00113228","price":"8831.68000000","product_id":"BTC-EUR","sequence":3257976918,"time":"2018-01-22T15:14:29.008000Z"}
{"type":"done","side":"buy","order_id":"a3720b22-bb97-47b3-8739-9d842c83be6b","reason":"filled","product_id":"BTC-EUR","price":"8831.68000000","remaining_size":"0","sequence":3257976919,"time":"2018-01-22T15:14:29.008000Z"}
{"type":"match","trade_id":10551331,"maker_order_id":"06346e81-44a3-4e99-a25a-b22a2223a943","taker_order_id":"546f09e9-70d5-4570-b3dd-63fcf366786d","side":"buy","size":"0.05819591","price":"8831.68000000","product_id":"BTC-EUR","sequence":3257976920,"time":"2018-01-22T15:14:29.008000Z"}
{"type":"done","side":"sell","order_id":"546f09e9-70d5-4570-b3dd-63fcf366786d","reason":"filled","product_id":"BTC-EUR","price":"8566.73000000","remaining_size":"0.00000000","sequence":3257976921,"time":"2018-01-22T15:14:29.008000Z"}
{"type":"done","side":"buy","order_id":"cc6056bc-d12e-48ac-9d3d-89536068182f","reason":"canceled","product_id":"BTC-EUR","price":"8819.25000000","remaining_size":"0.02243610","sequence":3257976922,"time":"2018-01-22T15:14:29.046000Z"}
{"type":"done","side":"buy","order_id":"cb87fa05-3700-47d8-adcb-f1163bebe3f7","reason":"canceled","product_id":"BTC-EUR","price":"8828.33000000","remaining_size":"0.09415844","sequence":3257976923,"time":"2018-01-22T15:14:29.163000Z"}
{"type":"received","order_id":"68eb715f-e13c-4c2e-800f-613930dfeb62","order_type":"limit","size":"0.18394187","price":"8880.09000000","side":"sell","client_oid":"b4b1caf4-db73-4eb9-ba03-584b978c0e23","product_id":"BTC-EUR","sequence":3257976924,"time":"2018-01-22T15:14:29.164000Z"}
