{"type":"open","side":"sell","price":"8880.09000000","order_id":"68eb715f-e13c-4c2e-800f-613930dfeb62","remaining_size":"0.18394187","product_id":"BTC-EUR","sequence":3257976925,"time":"2018-01-22T15:14:29.164000Z"}
{"type":"received","order_id":"7b7d1c35-0c65-4bd8-9bb1-b353c2e6c666","order_type":"limit","size":"0.00113228","price":"8831.68000000","side":"buy","client_oid":"264e6a65-6439-4399-85e6-b33c334d81f2","product_id":"BTC-EUR","sequence":3257976926,"time":"2018-01-22T15:14:29.180000Z"}
{"type":"open","side":"buy","price":"8831.68000000","order_id":"7b7d1c35-0c65-4bd8-9bb1-b353c2e6c666","remaining_size":"0.00113228","product_id":"BTC-EUR","sequence":3257976927,"time":"2018-01-22T15:14:29.180000Z"}
{"type":"received","order_id":"4df4a045-9708-4088-96ac-a90db9b865f4","order_type":"limit","size":"0.01887096","price":"8848.82000000","side":"sell","client_oid":"ee1626a7-91b2-4c2d-af49-eb3749db8139","product_id":"BTC-EUR","sequence":3257976928,"time":"2018-01-22T15:14:29.276000Z"}
{"type":"open","side":"sell","price":"8848.82000000","order_id":"4df4a045-9708-4088-96ac-a90db9b865f4","remaining_size":"0.01887096","product_id":"BTC-EUR","sequence":3257976929,"time":"2018-01-22T15:14:29.276000Z"}
{"type":"done","side":"buy","order_id":"7c9b998b-fd6b-4177-832a-52b7348fb61d","reason":"canceled","product_id":"BTC-EUR","price":"8831.68000000","remaining_size":"0.02000000","sequence":3257976930,"time":"2018-01-22T15:14:29.304000Z"}
{"type":"received","order_id":"9b41f2e8-c31f-48db-8cbb-f416e43a6821","order_type":"market","size":"1.03570000","side":"sell","client_oid":"67f53f3c-855c-434a-de55-557692500b64","product_id":"BTC-EUR","sequence":3257976931,"time":"2018-01-22T15:14:29.305000Z"}
{"type":"match","trade_id":10551332,"maker_order_id":"06346e81-44a3-4e99-a25a-b22a2223a943","taker_order_id":"9b41f2e8-c31f-48db-8cbb-f416e43a6821","side":"buy","size":"0.03596253","price":"8831.68000000","product_id":"BTC-EUR","sequence":3257976932,"time":"2018-01-22T15:14:29.305000Z"}
{"type":"done","side":"buy","order_id":"06346e81-44a3-4e99-a25a-b22a2223a943","reason":"filled","product_id":"BTC-EUR","price":"8831.68000000","remaining_size":"0.00000000","sequence":3257976933,"time":"2018-01-22T15:14:29.305000Z"}
{"type":"match","trade_id":10551333,"maker_order_id":"3bdc9be7-1e52-415d-86c1-81958228a59f","taker_order_id":"9b41f2e8-c31f-48db-8cbb-f416e43a6821","side":"buy","size":"0.02243610","price":"8831.68000000","product_id":"BTC-EUR","sequence":3257976934,"time":"2018-01-22T15:14:29.305000Z"}
{"type":"done","side":"buy","order_id":"3bdc9be7-1e52-415d-86c1-81958228a59f","reason":"filled","product_id":"BTC-EUR","price":"8831.68000000","remaining_size":"0.00000000","sequence":3257976935,"time":"2018-01-22T15:14:29.305000Z"}
{"type":"match","trade_id":10551334,"maker_order_id":"78e1eb70-40cb-439c-8b47-7936b14b3ec6","taker_order_id":"9b41f2e8-c31f-48db-8cbb-f416e43a6821","side":"buy","size":"0.01586384","price":"8831.68000000","product_id":"BTC-EUR","sequence":3257976936,"time":"2018-01-22T15:14:29.305000Z"}
{"type":"done","side":"buy","order_id":"78e1eb70-40cb-439c-8b47-7936b14b3ec6","reason":"filled","product_id":"BTC-EUR","price":"8831.68000000","remaining_size":"0.00000000","sequence":3257976937,"time":"2018-01-22T15:14:29.305000Z"}
{"type":"match","trade_id":10551335,"maker_order_id":"a6b0b111-e01e-45e9-977d-867072706f58","taker_order_id":"9b41f2e8-c31f-48db-8cbb-f416e43a6821","side":"buy","size":"0.03021616","price":"8831.68000000","product_id":"BTC-EUR","sequence":3257976938,"time":"2018-01-22T15:14:29.305000Z"}
{"type":"done","side":"buy","order_id":"a6b0b111-e01e-45e9-977d-867072706f58","reason":"filled","product_id":"BTC-EUR","price":"8831.68000000","remaining_size":"0.00000000","sequence":3257976939,"time":"2018-01-22T15:14:29.305000Z"}
{"type":"match","trade_id":10551336,"maker_order_id":"3217d93f-325b-4b34-a0ee-7327d72316c7","taker_order_id":"9b41f2e8-c31f-48db-8cbb-f416e43a6821","side":"buy","size":"0.00113000","price":"8831.68000000","product_id":"BTC-EUR","sequence":3257976940,"time":"2018-01-22T15:14:29.305000Z"}
{"type":"done","side":"buy","order_id":"3217d93f-325b-4b34-a0ee-7327d72316c7","reason":"filled","product_id":"BTC-EUR","price":"8831.68000000","remaining_size":"0.00000000","sequence":3257976941,"time":"2018-01-22T15:14:29.305000Z"}
{"type":"match","trade_id":10551337,"maker_order_id":"c8d51a9c-940d-4731-9816-c8c9f6616b2c","taker_order_id":"9b41f2e8-c31f-48db-8cbb-f416e43a6821","side":"buy","size":"0.43917000","price":"8831.68000000","product_id":"BTC-EUR","sequence":3257976942,"time":"2018-01-22T15:14:29.305000Z"}
{"type":"done","side":"buy","order_id":"c8d51a9c-940d-4731-9816-c8c9f6616b2c","reason":"filled","product_id":"BTC-EUR","price":"8831.68000000","remaining_size":"0.00000000","sequence":3257976943,"time":"2018-01-22T15:14:29.305000Z"}
{"type":"match","trade_id":10551338,"maker_order_id":"c0331567-d7cf-4ace-b01d-00047f030f9b","taker_order_id":"9b41f2e8-c31f-48db-8cbb-f416e43a6821","side":"buy","size":"0.46083000","price":"8831.68000000","product_id":"BTC-EUR","sequence":3257976944,"time":"2018-01-22T15:14:29.305000Z"}
{"type":"done","side":"buy","order_id":"c0331567-d7cf-4ace-b01d-00047f030f9b","reason":"filled","product_id":"BTC-EUR","price":"8831.68000000","remaining_size":"0.00000000","sequence":3257976945,"time":"2018-01-22T15:14:29.305000Z"}
{"type":"match","trade_id":10551339,"maker_order_id":"372ab20c-b7e8-4da3-898c-191087fb1d3a","taker_order_id":"9b41f2e8-c31f-48db-8cbb-f416e43a6821","side":"buy","size":"0.02264998","price":"8831.68000000","product_id":"BTC-EUR","sequence":3257976946,"time":"2018-01-22T15:14:29.305000Z"}
{"type":"done","side":"buy","order_id":"372ab20c-b7e8-4da3-898c-191087fb1d3a","reason":"filled","product_id":"BTC-EUR","price":"8831.68000000","remaining_size":"0.00000000","sequence":3257976947,"time":"2018-01-22T15:14:29.305000Z"}
{"type":"match","trade_id":10551340,"maker_order_id":"da56b34e-b82d-48b0-9300-cf60be8eb663","taker_order_id":"9b41f2e8-c31f-48db-8cbb-f416e43a6821","side":"buy","size":"0.00744139","price":"8831.68000000","product_id":"BTC-EUR","sequence":3257976948,"time":"2018-01-22T15:14:29.305000Z"}
{"type":"done","side":"sell","order_id":"9b41f2e8-c31f-48db-8cbb-f416e43a6821","reason":"filled","product_id":"BTC-EUR","remaining_size":"0.00000000","sequence":3257976949,"time":"2018-01-22T15:14:29.305000Z"}
{"type":"done","side":"buy","order_id":"a3456704-5f75-4459-887b-72c082172b54","reason":"canceled","product_id":"BTC-EUR","price":"8831.68000000","remaining_size":"0.06666600","sequence":3257976950,"time":"2018-01-22T15:14:29.454000Z"}
{"type":"done","side":"sell","order_id":"b517bf61-dfe9-4015-b650-2cfbae1921b4","reason":"canceled","product_id":"BTC-EUR","price":"8848.84000000","remaining_size":"0.11241548","sequence":3257976951,"time":"2018-01-22T15:14:29.566000Z"}
{"type":"done","side":"sell","order_id":"21efb525-2d85-4918-a605-fb16f9d0b5d3","reason":"canceled","product_id":"BTC-EUR","price":"8850.00000000","remaining_size":"0.00370350","sequence":3257976952,"time":"2018-01-22T15:14:29.595000Z"}
{"type":"received","order_id":"89e90773-dfa1-4e0e-be5a-1a8a7f0b1dce","order_type":"limit","size":"0.11241548","price":"8848.82000000","side":"sell","product_id":"BTC-EUR","sequence":3257976953,"time":"2018-01-22T15:14:29.692000Z"}
{"type":"open","side":"sell","price":"8848.82000000","order_id":"89e90773-dfa1-4e0e-be5a-1a8a7f0b1dce","remaining_size":"0.11241548","product_id":"BTC-EUR","sequence":3257976954,"time":"2018-01-22T15:14:29.692000Z"}
{"type":"done","side":"sell","order_id":"68eb715f-e13c-4c2e-800f-613930dfeb62","reason":"canceled","product_id":"BTC-EUR","price":"8880.09000000","remaining_size":"0.18394187","sequence":3257976955,"time":"2018-01-22T15:14:29.715000Z"}
{"type":"done","side":"sell","order_id":"bb1377ab-69cf-4e69-8b19-c35f4e1e4ab9","reason":"canceled","product_id":"BTC-EUR","price":"8848.82000000","remaining_size":"0.22947933","sequence":3257976956,"time":"2018-01-22T15:14:29.813000Z"}
{"type":"done","side":"sell","order_id":"5944a13b-b505-4163-b599-71c31d167986","reason":"canceled","product_id":"BTC-EUR","price":"8848.82000000","remaining_size":"0.04164971","sequence":3257976957,"time":"2018-01-22T15:14:29.825000Z"}
{"type":"received","order_id":"aae38628-ee23-4606-a415-cd434d7dfa66","order_type":"limit","size":"0.07000000","price":"9096.64000000","side":"buy","product_id":"BTC-EUR","sequence":3257976958,"time":"2018-01-22T15:14:29.905000Z"}
{"type":"match","trade_id":10551341,"maker_order_id":"80ee1692-b809-4916-aeb3-90920041ea09","taker_order_id":"aae38628-ee23-4606-a415-cd434d7dfa66","side":"sell","size":"0.07000000","price":"8831.69000000","product_id":"BTC-EUR","sequence":3257976959,"time":"2018-01-22T15:14:29.905000Z"}
{"type":"done","side":"buy","order_id":"aae38628-ee23-4606-a415-cd434d7dfa66","reason":"filled","product_id":"BTC-EUR","price":"9096.64000000","remaining_size":"0.00000000","sequence":3257976960,"time":"2018-01-22T15:14:29.905000Z"}
{"type":"done","side":"buy","order_id":"ac49fa77-0c88-4bc1-bf05-5caa1266d881","reason":"canceled","product_id":"BTC-EUR","price":"8828.33000000","remaining_size":"0.02108452","sequence":3257976961,"time":"2018-01-22T15:14:29.984000Z"}
{"type":"done","side":"sell","order_id":"4df4a045-9708-4088-96ac-a90db9b865f4","reason":"canceled","product_id":"BTC-EUR","price":"8848.82000000","remaining_size":"0.01887096","sequence":3257976962,"time":"2018-01-22T15:14:29.985000Z"}
{"type":"received","order_id":"a872498c-e521-4e56-a4ef-2d15a5b16c3e","order_type":"limit","size":"0.04164971","price":"8848.80000000","side":"sell","client_oid":"b37fa507-1738-425a-9e65-c7fc526c9ab6","product_id":"BTC-EUR","sequence":3257976963,"time":"2018-01-22T15:14:30.053000Z"}
{"type":"open","side":"sell","price":"8848.80000000","order_id":"a872498c-e521-4e56-a4ef-2d15a5b16c3e","remaining_size":"0.04164971","product_id":"BTC-EUR","sequence":3257976964,"time":"2018-01-22T15:14:30.053000Z"}
{"type":"received","order_id":"ae1d3123-41ea-47a7-a04b-21049e3c3da6","order_type":"limit","size":"0.22947933","price":"8848.80000000","side":"sell","client_oid":"e2d750ce-7dad-4bd4-a0dc-4e4cb1edabd3","product_id":"BTC-EUR","sequence":3257976965,"time":"2018-01-22T15:14:30.094000Z"}
{"type":"open","side":"sell","price":"8848.80000000","order_id":"ae1d3123-41ea-47a7-a04b-21049e3c3da6","remaining_size":"0.22947933","product_id":"BTC-EUR","sequence":3257976966,"time":"2018-01-22T15:14:30.094000Z"}
{"type":"received","order_id":"64340938-9c51-4970-ae37-0eddf3879a24","order_type":"limit","size":"0.02108452","price":"8823.33000000","side":"buy","product_id":"BTC-EUR","sequence":3257976967,"time":"2018-01-22T15:14:30.151000Z"}
{"type":"open","side":"buy","price":"8823.33000000","order_id":"64340938-9c51-4970-ae37-0eddf3879a24","remaining_size":"0.02108452","product_id":"BTC-EUR","sequence":3257976968,"time":"2018-01-22T15:14:30.151000Z"}
{"type":"received","order_id":"57543af7-a64a-47e4-8032-ec110544112d","order_type":"limit","size":"0.18394187","price":"8880.09000000","side":"sell","client_oid":"6efedaaf-646c-4326-bed6-7d1d9c87eedf","product_id":"BTC-EUR","sequence":3257976969,"time":"2018-01-22T15:14:30.153000Z"}
{"type":"open","side":"sell","price":"8880.09000000","order_id":"57543af7-a64a-47e4-8032-ec110544112d","remaining_size":"0.18394187","product_id":"BTC-EUR","sequence":3257976970,"time":"2018-01-22T15:14:30.153000Z"}
{"type":"done","side":"sell","order_id":"6c4a6f54-0e9a-47df-a253-722c3e4af4cd","reason":"canceled","product_id":"BTC-EUR","price":"8938.30000000","remaining_size":"0.03773580","sequence":3257976971,"time":"2018-01-22T15:14:30.171000Z"}
{"type":"received","order_id":"8ea87e02-13b2-45e8-8882-5167758c70eb","order_type":"limit","size":"0.01887096","price":"8848.80000000","side":"sell","client_oid":"08d780d0-534f-4d3d-b387-9889dd273da1","product_id":"BTC-EUR","sequence":3257976972,"time":"2018-01-22T15:14:30.243000Z"}
{"type":"open","side":"sell","price":"8848.80000000","order_id":"8ea87e02-13b2-45e8-8882-5167758c70eb","remaining_size":"0.01887096","product_id":"BTC-EUR","sequence":3257976973,"time":"2018-01-22T15:14:30.243000Z"}
{"type":"done","side":"buy","order_id":"960a87a2-5cba-43f2-b0ad-b7f342e2f79c","reason":"canceled","product_id":"BTC-EUR","price":"8831.68000000","remaining_size":"0.10500000","sequence":3257976974,"time":"2018-01-22T15:14:30.244000Z"}
{"type":"done","side":"buy","order_id":"ac5a43f9-80f3-4fc2-a47d-705bd6c6ced7","reason":"canceled","product_id":"BTC-EUR","price":"8831.68000000","remaining_size":"0.10500000","sequence":3257976975,"time":"2018-01-22T15:14:30.286000Z"}
{"type":"done","side":"buy","order_id":"53e35e1a-183f-43a2-980d-e2b75d837b50","reason":"canceled","product_id":"BTC-EUR","price":"8831.68000000","remaining_size":"0.10500000","sequence":3257976976,"time":"2018-01-22T15:14:30.286000Z"}
{"type":"received","order_id":"9864d4d7-9499-4584-ba0d-895a0be773ae","order_type":"limit","size":"0.06000000","price":"9096.64000000","side":"buy","product_id":"BTC-EUR","sequence":3257976977,"time":"2018-01-22T15:14:30.304000Z"}
{"type":"match","trade_id":10551342,"maker_order_id":"80ee1692-b809-4916-aeb3-90920041ea09","taker_order_id":"9864d4d7-9499-4584-ba0d-895a0be773ae","side":"sell","size":"0.06000000","price":"8831.69000000","product_id":"BTC-EUR","sequence":3257976978,"time":"2018-01-22T15:14:30.304000Z"}
{"type":"done","side":"buy","order_id":"9864d4d7-9499-4584-ba0d-895a0be773ae","reason":"filled","product_id":"BTC-EUR","price":"9096.64000000","remaining_size":"0.00000000","sequence":3257976979,"time":"2018-01-22T15:14:30.304000Z"}
{"type":"done","side":"sell","order_id":"57543af7-a64a-47e4-8032-ec110544112d","reason":"canceled","product_id":"BTC-EUR","price":"8880.09000000","remaining_size":"0.18394187","sequence":3257976980,"time":"2018-01-22T15:14:30.434000Z"}
{"type":"done","side":"buy","order_id":"86b02e6a-18ec-4c8b-95de-331ad761144b","reason":"canceled","product_id":"BTC-EUR","price":"8633.31000000","remaining_size":"1.28000000","sequence":3257976981,"time":"2018-01-22T15:14:30.512000Z"}
{"type":"received","order_id":"2477ce6d-96c2-4e55-b614-cb7b278092f5","order_type":"limit","size":"0.01000000","price":"9096.64000000","side":"buy","product_id":"BTC-EUR","sequence":3257976982,"time":"2018-01-22T15:14:30.556000Z"}
{"type":"match","trade_id":10551343,"maker_order_id":"80ee1692-b809-4916-aeb3-90920041ea09","taker_order_id":"2477ce6d-96c2-4e55-b614-cb7b278092f5","side":"sell","size":"0.01000000","price":"8831.69000000","product_id":"BTC-EUR","sequence":3257976983,"time":"2018-01-22T15:14:30.556000Z"}
{"type":"done","side":"buy","order_id":"2477ce6d-96c2-4e55-b614-cb7b278092f5","reason":"filled","product_id":"BTC-EUR","price":"9096.64000000","remaining_size":"0.00000000","sequence":3257976984,"time":"2018-01-22T15:14:30.556000Z"}
{"type":"done","side":"buy","order_id":"086365ca-5d2e-47b4-b13d-6b8941313802","reason":"canceled","product_id":"BTC-EUR","price":"8734.15000000","remaining_size":"0.02243610","sequence":3257976985,"time":"2018-01-22T15:14:30.559000Z"}
{"type":"done","side":"buy","order_id":"6d828aa3-4877-4771-a110-1ba293f1265a","reason":"canceled","product_id":"BTC-EUR","price":"8689.68000000","remaining_size":"0.02243610","sequence":3257976986,"time":"2018-01-22T15:14:30.559000Z"}
{"type":"done","side":"buy","order_id":"d8d0b8d5-0fc7-48de-b024-ec526867a728","reason":"canceled","product_id":"BTC-EUR","price":"8783.87000000","remaining_size":"0.09415844","sequence":3257976987,"time":"2018-01-22T15:14:30.559000Z"}
{"type":"done","side":"buy","order_id":"134ed6bd-75d2-4f38-b0dc-19ceeccce2f0","reason":"canceled","product_id":"BTC-EUR","price":"8739.42000000","remaining_size":"0.09415844","sequence":3257976988,"time":"2018-01-22T15:14:30.560000Z"}
{"type":"done","side":"sell","order_id":"6eba0505-2222-4f4c-8ac7-63d00405c338","reason":"canceled","product_id":"BTC-EUR","price":"8948.50000000","remaining_size":"0.36857349","sequence":3257976989,"time":"2018-01-22T15:14:30.561000Z"}
{"type":"done","side":"sell","order_id":"d374f76b-ae7a-45d1-b002-a7dc6eb7b5bd","reason":"canceled","product_id":"BTC-EUR","price":"8896.51000000","remaining_size":"0.36857350","sequence":3257976990,"time":"2018-01-22T15:14:30.561000Z"}
{"type":"done","side":"buy","order_id":"a18cef3a-cfe3-4251-8b1d-0a2fec9b82d1","reason":"canceled","product_id":"BTC-EUR","price":"8688.68000000","remaining_size":"0.01586384","sequence":3257976991,"time":"2018-01-22T15:14:30.561000Z"}
{"type":"done","side":"buy","order_id":"dc518476-a662-4246-b1a0-243cfc8f5e7e","reason":"canceled","product_id":"BTC-EUR","price":"8733.14000000","remaining_size":"0.01586384","sequence":3257976992,"time":"2018-01-22T15:14:30.562000Z"}
{"type":"done","side":"sell","order_id":"2496f087-f993-456a-9d9d-ca1a9c94714a","reason":"canceled","product_id":"BTC-EUR","price":"8908.48000000","remaining_size":"0.36857350","sequence":3257976993,"time":"2018-01-22T15:14:30.563000Z"}
{"type":"done","side":"buy","order_id":"50bd356e-0da1-46bf-8f3a-152cce4c14d9","reason":"canceled","product_id":"BTC-EUR","price":"8777.81000000","remaining_size":"0.01586384","sequence":3257976994,"time":"2018-01-22T15:14:30.565000Z"}
{"type":"done","side":"sell","order_id":"f76d078f-9422-48ba-8762-3c5b7156c5b9","reason":"canceled","product_id":"BTC-EUR","price":"8908.53000000","remaining_size":"0.19762425","sequence":3257976995,"time":"2018-01-22T15:14:30.565000Z"}
{"type":"done","side":"buy","order_id":"033fb076-0407-4c65-ac31-8417c5aa65d1","reason":"canceled","product_id":"BTC-EUR","price":"8818.21000000","remaining_size":"0.01586384","sequence":3257976996,"time":"2018-01-22T15:14:30.567000Z"}
{"type":"done","side":"sell","order_id":"f04b4302-3f1d-45e2-bcb3-955d20871328","reason":"canceled","product_id":"BTC-EUR","price":"8948.46000000","remaining_size":"0.19762425","sequence":3257976997,"time":"2018-01-22T15:14:30.567000Z"}
{"type":"done","side":"sell","order_id":"a9b0b15c-6d8c-4880-ae35-6f4028e104ca","reason":"canceled","product_id":"BTC-EUR","price":"8896.51000000","remaining_size":"0.19762425","sequence":3257976998,"time":"2018-01-22T15:14:30.569000Z"}
{"type":"done","side":"sell","order_id":"ba169782-e19a-4b98-84de-1ba84444c49f","reason":"canceled","product_id":"BTC-EUR","price":"8942.01000000","remaining_size":"1.35301326","sequence":3257976999,"time":"2018-01-22T15:14:30.570000Z"}
{"type":"done","side":"buy","order_id":"e0fe936f-3fb8-4b7f-90f3-0ea4d4d4175c","reason":"canceled","product_id":"BTC-EUR","price":"8699.01000000","remaining_size":"0.01510807","sequence":3257977000,"time":"2018-01-22T15:14:30.587000Z"}
{"type":"done","side":"sell","order_id":"a92a6b75-504e-4d60-8340-023c839f6e12","reason":"canceled","product_id":"BTC-EUR","price":"8958.23000000","remaining_size":"0.21455928","sequence":3257977001,"time":"2018-01-22T15:14:30.587000Z"}
{"type":"done","side":"buy","order_id":"99491e64-d2de-4c81-86e5-bccc245d4eba","reason":"canceled","product_id":"BTC-EUR","price":"8743.18000000","remaining_size":"0.01510808","sequence":3257977002,"time":"2018-01-22T15:14:30.589000Z"}
{"type":"done","side":"buy","order_id":"13fa01fc-685c-4130-a4c0-6d6dc55bbee1","reason":"canceled","product_id":"BTC-EUR","price":"8788.31000000","remaining_size":"0.01510808","sequence":3257977003,"time":"2018-01-22T15:14:30.589000Z"}
{"type":"done","side":"buy","order_id":"e7d0acc1-77e4-402d-9c28-810524f8b203","reason":"canceled","product_id":"BTC-EUR","price":"8831.68000000","remaining_size":"0.00200000","sequence":3257977004,"time":"2018-01-22T15:14:30.638000Z"}
{"type":"done","side":"buy","order_id":"e3196008-9be9-4ab2-b5ce-57146ed44140","reason":"canceled","product_id":"BTC-EUR","price":"8831.68000000","remaining_size":"0.09800000","sequence":3257977005,"time":"2018-01-22T15:14:30.652000Z"}
{"type":"done","side":"buy","order_id":"957419f9-c2c7-45d7-b607-d2be5a8d4f8c","reason":"canceled","product_id":"BTC-EUR","price":"8831.68000000","remaining_size":"0.09800000","sequence":3257977006,"time":"2018-01-22T15:14:30.662000Z"}
{"type":"received","order_id":"1491ec2c-f7b9-4ad5-b9ff-8b7605179955","order_type":"limit","size":"0.18394187","price":"8880.09000000","side":"sell","client_oid":"eabab63a-b9d3-45ab-9ac1-b05d50f4ea50","product_id":"BTC-EUR","sequence":3257977007,"time":"2018-01-22T15:14:30.677000Z"}
{"type":"open","side":"sell","price":"8880.09000000","order_id":"1491ec2c-f7b9-4ad5-b9ff-8b7605179955","remaining_size":"0.18394187","product_id":"BTC-EUR","sequence":3257977008,"time":"2018-01-22T15:14:30.677000Z"}
{"type":"done","side":"buy","order_id":"91b000a8-7ec5-4474-b920-349d7b723597","reason":"canceled","product_id":"BTC-EUR","price":"8831.68000000","remaining_size":"0.09800000","sequence":3257977009,"time":"2018-01-22T15:14:30.679000Z"}
{"type":"received","order_id":"f95461b0-5dfe-4e27-95b5-9563efcba374","order_type":"limit","size":"0.09800000","price":"8831.68000000","side":"buy","client_oid":"23562597-c53d-4515-890e-839ca540e0fb","product_id":"BTC-EUR","sequence":3257977010,"time":"2018-01-22T15:14:30.698000Z"}
{"type":"open","side":"buy","price":"8831.68000000","order_id":"f95461b0-5dfe-4e27-95b5-9563efcba374","remaining_size":"0.09800000","product_id":"BTC-EUR","sequence":3257977011,"time":"2018-01-22T15:14:30.698000Z"}
{"type":"done","side":"buy","order_id":"cf3b7f96-5801-411e-914b-3dde56dfe684","reason":"canceled","product_id":"BTC-EUR","price":"8809.29000000","remaining_size":"0.33000000","sequence":3257977012,"time":"2018-01-22T15:14:30.719000Z"}
{"type":"done","side":"sell","order_id":"a7118cd7-d92a-4377-b041-c3b5e5b11621","reason":"canceled","product_id":"BTC-EUR","price":"8899.87000000","remaining_size":"0.58423000","sequence":3257977013,"time":"2018-01-22T15:14:30.805000Z"}
{"type":"done","side":"buy","order_id":"51f86467-7256-41ae-8c0c-6f5af256b48d","reason":"canceled","product_id":"BTC-EUR","price":"8659.00000000","remaining_size":"1.89473000","sequence":3257977014,"time":"2018-01-22T15:14:30.843000Z"}
{"type":"received","order_id":"511f5132-c84d-43b9-ac2d-938af901a1e0","order_type":"limit","size":"1.89487000","price":"8658.50000000","side":"buy","client_oid":"ba41aa39-9263-47ce-bd83-66c02f156221","product_id":"BTC-EUR","sequence":3257977015,"time":"2018-01-22T15:14:30.860000Z"}
{"type":"open","side":"buy","price":"8658.50000000","order_id":"511f5132-c84d-43b9-ac2d-938af901a1e0","remaining_size":"1.89487000","product_id":"BTC-EUR","sequence":3257977016,"time":"2018-01-22T15:14:30.860000Z"}
{"type":"done","side":"sell","order_id":"137c70ac-7a7b-47fb-8302-f718104dc306","reason":"canceled","product_id":"BTC-EUR","price":"8862.30000000","remaining_size":"0.16000000","sequence":3257977017,"time":"2018-01-22T15:14:30.897000Z"}
{"type":"done","side":"buy","order_id":"d5be3499-4b31-406e-a8d4-7cd9c2eed30e","reason":"canceled","product_id":"BTC-EUR","price":"8819.24000000","remaining_size":"0.46302727","sequence":3257977018,"time":"2018-01-22T15:14:30.959000Z"}
{"type":"received","order_id":"b857e9c9-dbcc-42ea-9e7f-dbcc26d77b28","order_type":"limit","size":"1.00000000","price":"6500.00000000","side":"buy","client_oid":"7dbc3252-827e-4926-8615-0aafceef4aee","product_id":"BTC-EUR","sequence":3257977019,"time":"2018-01-22T15:14:31.025000Z"}
{"type":"open","side":"buy","price":"6500.00000000","order_id":"b857e9c9-dbcc-42ea-9e7f-dbcc26d77b28","remaining_size":"1.00000000","product_id":"BTC-EUR","sequence":3257977020,"time":"2018-01-22T15:14:31.025000Z"}
{"type":"received","order_id":"55d55fa7-a3c3-4c31-af96-a5880135fe9c","order_type":"limit","size":"0.09800000","price":"8831.68000000","side":"buy","client_oid":"fe940926-98bc-48b3-8229-31f24e7943fc","product_id":"BTC-EUR","sequence":3257977021,"time":"2018-01-22T15:14:31.072000Z"}
{"type":"open","side":"buy","price":"8831.68000000","order_id":"55d55fa7-a3c3-4c31-af96-a5880135fe9c","remaining_size":"0.09800000","product_id":"BTC-EUR","sequence":3257977022,"time":"2018-01-22T15:14:31.072000Z"}
{"type":"received","order_id":"fa26d1b4-c7a1-4068-8aee-66369992bee2","order_type":"limit","size":"0.34000000","price":"8816.88000000","side":"buy","product_id":"BTC-EUR","sequence":3257977023,"time":"2018-01-22T15:14:31.101000Z"}
{"type":"open","side":"buy","price":"8816.88000000","order_id":"fa26d1b4-c7a1-4068-8aee-66369992bee2","remaining_size":"0.34000000","product_id":"BTC-EUR","sequence":3257977024,"time":"2018-01-22T15:14:31.101000Z"}
{"type":"received","order_id":"0fce7489-f729-4e38-94f9-41fa91f18d20","order_type":"limit","size":"0.09800000","price":"8831.68000000","side":"buy","client_oid":"ce8ae232-5038-4445-9776-deae3dec07de","product_id":"BTC-EUR","sequence":3257977025,"time":"2018-01-22T15:14:31.130000Z"}
{"type":"open","side":"buy","price":"8831.68000000","order_id":"0fce7489-f729-4e38-94f9-41fa91f18d20","remaining_size":"0.09800000","product_id":"BTC-EUR","sequence":3257977026,"time":"2018-01-22T15:14:31.130000Z"}
{"type":"done","side":"buy","order_id":"8bef2512-c086-4461-9c84-39e567dbff9e","reason":"canceled","product_id":"BTC-EUR","price":"7291.85000000","remaining_size":"19.16578514","sequence":3257977027,"time":"2018-01-22T15:14:31.206000Z"}
{"type":"received","order_id":"7aa5ca8c-6bd4-4a52-b57f-a7e335d34531","order_type":"limit","size":"0.02000000","price":"9096.64000000","side":"buy","product_id":"BTC-EUR","sequence":3257977028,"time":"2018-01-22T15:14:31.210000Z"}
{"type":"match","trade_id":10551344,"maker_order_id":"80ee1692-b809-4916-aeb3-90920041ea09","taker_order_id":"7aa5ca8c-6bd4-4a52-b57f-a7e335d34531","side":"sell","size":"0.02000000","price":"8831.69000000","product_id":"BTC-EUR","sequence":3257977029,"time":"2018-01-22T15:14:31.210000Z"}
{"type":"done","side":"buy","order_id":"7aa5ca8c-6bd4-4a52-b57f-a7e335d34531","reason":"filled","product_id":"BTC-EUR","price":"9096.64000000","remaining_size":"0.00000000","sequence":3257977030,"time":"2018-01-22T15:14:31.210000Z"}
{"type":"done","side":"sell","order_id":"1491ec2c-f7b9-4ad5-b9ff-8b7605179955","reason":"canceled","product_id":"BTC-EUR","price":"8880.09000000","remaining_size":"0.18394187","sequence":3257977031,"time":"2018-01-22T15:14:31.220000Z"}
{"type":"done","side":"sell","order_id":"89e90773-dfa1-4e0e-be5a-1a8a7f0b1dce","reason":"canceled","product_id":"BTC-EUR","price":"8848.82000000","remaining_size":"0.11241548","sequence":3257977032,"time":"2018-01-22T15:14:31.250000Z"}
{"type":"received","order_id":"df0bdea3-6fa8-43ba-b3a7-23cb548d6413","order_type":"limit","size":"0.18000000","price":"8869.94000000","side":"sell","product_id":"BTC-EUR","sequence":3257977033,"time":"2018-01-22T15:14:31.305000Z"}
{"type":"open","side":"sell","price":"8869.94000000","order_id":"df0bdea3-6fa8-43ba-b3a7-23cb548d6413","remaining_size":"0.18000000","product_id":"BTC-EUR","sequence":3257977034,"time":"2018-01-22T15:14:31.305000Z"}
{"type":"received","order_id":"c50c955d-59e4-44a7-aec6-8e35f19833b2","order_type":"limit","size":"0.10500000","price":"8831.68000000","side":"buy","client_oid":"f626f080-1061-4724-8996-8d267df15503","product_id":"BTC-EUR","sequence":3257977035,"time":"2018-01-22T15:14:31.339000Z"}
{"type":"open","side":"buy","price":"8831.68000000","order_id":"c50c955d-59e4-44a7-aec6-8e35f19833b2","remaining_size":"0.10500000","product_id":"BTC-EUR","sequence":3257977036,"time":"2018-01-22T15:14:31.339000Z"}
{"type":"received","order_id":"66a94851-8197-4d87-a97e-e14360932fae","order_type":"limit","size":"0.11241548","price":"8848.80000000","side":"sell","product_id":"BTC-EUR","sequence":3257977037,"time":"2018-01-22T15:14:31.367000Z"}
{"type":"open","side":"sell","price":"8848.80000000","order_id":"66a94851-8197-4d87-a97e-e14360932fae","remaining_size":"0.11241548","product_id":"BTC-EUR","sequence":3257977038,"time":"2018-01-22T15:14:31.367000Z"}
{"type":"received","order_id":"b3e05bf3-f750-443f-8778-22990c398b48","order_type":"limit","size":"0.05000000","price":"9700.00000000","side":"sell","client_oid":"6a8339e5-542f-41aa-afbe-2a3bb0c98f1f","product_id":"BTC-EUR","sequence":3257977039,"time":"2018-01-22T15:14:31.403000Z"}
{"type":"open","side":"sell","price":"9700.00000000","order_id":"b3e05bf3-f750-443f-8778-22990c398b48","remaining_size":"0.05000000","product_id":"BTC-EUR","sequence":3257977040,"time":"2018-01-22T15:14:31.403000Z"}
{"type":"received","order_id":"2e694b37-e197-49b6-a54d-7272a9d641ad","order_type":"limit","size":"0.10500000","price":"8831.68000000","side":"buy","client_oid":"82231e3d-dc4f-4f83-84fb-f8c4b5e17a49","product_id":"BTC-EUR","sequence":3257977041,"time":"2018-01-22T15:14:31.429000Z"}
{"type":"open","side":"buy","price":"8831.68000000","order_id":"2e694b37-e197-49b6-a54d-7272a9d641ad","remaining_size":"0.10500000","product_id":"BTC-EUR","sequence":3257977042,"time":"2018-01-22T15:14:31.429000Z"}
{"type":"received","order_id":"5d614470-b359-428f-9136-02a05e40014f","order_type":"limit","size":"0.10500000","price":"8831.68000000","side":"buy","client_oid":"818fc58a-9ebf-4bcb-b2b6-10209cfe001e","product_id":"BTC-EUR","sequence":3257977043,"time":"2018-01-22T15:14:31.433000Z"}
{"type":"open","side":"buy","price":"8831.68000000","order_id":"5d614470-b359-428f-9136-02a05e40014f","remaining_size":"0.10500000","product_id":"BTC-EUR","sequence":3257977044,"time":"2018-01-22T15:14:31.433000Z"}
{"type":"received","order_id":"6d7beff6-9373-4de1-b542-1d2cd607b7b8","order_type":"limit","size":"0.46352090","price":"8809.85000000","side":"buy","client_oid":"ab861208-6058-4e3d-9dc7-9b901a7278c8","product_id":"BTC-EUR","sequence":3257977045,"time":"2018-01-22T15:14:31.462000Z"}
{"type":"open","side":"buy","price":"8809.85000000","order_id":"6d7beff6-9373-4de1-b542-1d2cd607b7b8","remaining_size":"0.46352090","product_id":"BTC-EUR","sequence":3257977046,"time":"2018-01-22T15:14:31.462000Z"}
{"type":"done","side":"sell","order_id":"a872498c-e521-4e56-a4ef-2d15a5b16c3e","reason":"canceled","product_id":"BTC-EUR","price":"8848.80000000","remaining_size":"0.04164971","sequence":3257977047,"time":"2018-01-22T15:14:31.464000Z"}
{"type":"received","order_id":"50b8ba79-5095-439d-8001-09d905286a39","order_type":"limit","size":"0.09415844","price":"8821.03000000","side":"buy","client_oid":"6220a386-5f67-4fa8-89ba-07851ccd7aa6","product_id":"BTC-EUR","sequence":3257977048,"time":"2018-01-22T15:14:31.482000Z"}
{"type":"open","side":"buy","price":"8821.03000000","order_id":"50b8ba79-5095-439d-8001-09d905286a39","remaining_size":"0.09415844","product_id":"BTC-EUR","sequence":3257977049,"time":"2018-01-22T15:14:31.482000Z"}
{"type":"done","side":"sell","order_id":"ae1d3123-41ea-47a7-a04b-21049e3c3da6","reason":"canceled","product_id":"BTC-EUR","price":"8848.80000000","remaining_size":"0.22947933","sequence":3257977050,"time":"2018-01-22T15:14:31.521000Z"}
{"type":"received","order_id":"5ca73024-4417-4674-8030-457b248ee9c1","order_type":"limit","size":"0.00200000","price":"8831.68000000","side":"buy","client_oid":"5767ff95-760c-49e2-b209-fea28ca4ce5d","product_id":"BTC-EUR","sequence":3257977051,"time":"2018-01-22T15:14:31.579000Z"}
{"type":"open","side":"buy","price":"8831.68000000","order_id":"5ca73024-4417-4674-8030-457b248ee9c1","remaining_size":"0.00200000","product_id":"BTC-EUR","sequence":3257977052,"time":"2018-01-22T15:14:31.579000Z"}
{"type":"done","side":"buy","order_id":"bf58c0a9-a62c-4033-807a-2146cd635a29","reason":"canceled","product_id":"BTC-EUR","price":"8516.16000000","remaining_size":"0.11464275","sequence":3257977053,"time":"2018-01-22T15:14:31.598000Z"}
{"type":"received","order_id":"8143bb7d-ddfd-4b35-a1b3-0383e572d098","order_type":"limit","size":"0.18415358","price":"8869.88000000","side":"sell","client_oid":"b4749645-5981-4495-9dae-d5a96ca42658","product_id":"BTC-EUR","sequence":3257977054,"time":"2018-01-22T15:14:31.602000Z"}
{"type":"open","side":"sell","price":"8869.88000000","order_id":"8143bb7d-ddfd-4b35-a1b3-0383e572d098","remaining_size":"0.18415358","product_id":"BTC-EUR","sequence":3257977055,"time":"2018-01-22T15:14:31.602000Z"}
{"type":"received","order_id":"b5fd1e37-b2dc-456c-ac10-59f013ab9ab3","order_type":"limit","size":"0.01510808","price":"8831.68000000","side":"buy","client_oid":"852d76f3-b147-4d4b-9e0b-e1d15cc6ba1a","product_id":"BTC-EUR","sequence":3257977056,"time":"2018-01-22T15:14:31.615000Z"}
{"type":"open","side":"buy","price":"8831.68000000","order_id":"b5fd1e37-b2dc-456c-ac10-59f013ab9ab3","remaining_size":"0.01510808","product_id":"BTC-EUR","sequence":3257977057,"time":"2018-01-22T15:14:31.615000Z"}
{"type":"received","order_id":"5e0f8665-6314-4b48-a766-1e3eaa89b8c5","order_type":"limit","size":"1.35301324","price":"8887.96000000","side":"sell","client_oid":"992d2dff-def7-4736-add3-16892ddb9f3e","product_id":"BTC-EUR","sequence":3257977058,"time":"2018-01-22T15:14:31.616000Z"}
{"type":"open","side":"sell","price":"8887.96000000","order_id":"5e0f8665-6314-4b48-a766-1e3eaa89b8c5","remaining_size":"1.35301324","product_id":"BTC-EUR","sequence":3257977059,"time":"2018-01-22T15:14:31.616000Z"}
{"type":"received","order_id":"71084260-c85f-4343-83f6-861b10fcd5db","order_type":"limit","size":"0.09415844","price":"8776.62000000","side":"buy","client_oid":"afc10f69-af62-4844-bd83-86e1cbeafb7d","product_id":"BTC-EUR","sequence":3257977060,"time":"2018-01-22T15:14:31.619000Z"}
{"type":"open","side":"buy","price":"8776.62000000","order_id":"71084260-c85f-4343-83f6-861b10fcd5db","remaining_size":"0.09415844","product_id":"BTC-EUR","sequence":3257977061,"time":"2018-01-22T15:14:31.619000Z"}
{"type":"received","order_id":"7f9fb242-ebce-4ae3-8486-5a976ff8815d","order_type":"limit","size":"0.09415844","price":"8732.20000000","side":"buy","client_oid":"76dc4bfb-bdd7-4c66-a8f0-35dd26c549e9","product_id":"BTC-EUR","sequence":3257977062,"time":"2018-01-22T15:14:31.624000Z"}
{"type":"open","side":"buy","price":"8732.20000000","order_id":"7f9fb242-ebce-4ae3-8486-5a976ff8815d","remaining_size":"0.09415844","product_id":"BTC-EUR","sequence":3257977063,"time":"2018-01-22T15:14:31.624000Z"}
{"type":"received","order_id":"05e12cc8-4cff-458c-a97e-cd776bce51ca","order_type":"limit","size":"0.04164971","price":"8848.78000000","side":"sell","client_oid":"7388e626-43f6-47c8-8f44-d8fd277c261e","product_id":"BTC-EUR","sequence":3257977064,"time":"2018-01-22T15:14:31.678000Z"}
{"type":"open","side":"sell","price":"8848.78000000","order_id":"05e12cc8-4cff-458c-a97e-cd776bce51ca","remaining_size":"0.04164971","product_id":"BTC-EUR","sequence":3257977065,"time":"2018-01-22T15:14:31.678000Z"}
{"type":"done","side":"buy","order_id":"2e694b37-e197-49b6-a54d-7272a9d641ad","reason":"canceled","product_id":"BTC-EUR","price":"8831.68000000","remaining_size":"0.10500000","sequence":3257977066,"time":"2018-01-22T15:14:31.702000Z"}
{"type":"done","side":"buy","order_id":"5d614470-b359-428f-9136-02a05e40014f","reason":"canceled","product_id":"BTC-EUR","price":"8831.68000000","remaining_size":"0.10500000","sequence":3257977067,"time":"2018-01-22T15:14:31.715000Z"}
{"type":"done","side":"buy","order_id":"c50c955d-59e4-44a7-aec6-8e35f19833b2","reason":"canceled","product_id":"BTC-EUR","price":"8831.68000000","remaining_size":"0.10500000","sequence":3257977068,"time":"2018-01-22T15:14:31.727000Z"}
{"type":"received","order_id":"cf1ffae0-7908-43c5-9338-dd417947097a","order_type":"limit","size":"0.10500000","price":"8831.68000000","side":"buy","client_oid":"7aee01bf-3b87-499b-94a2-3aae1f3b6fd0","product_id":"BTC-EUR","sequence":3257977069,"time":"2018-01-22T15:14:31.751000Z"}
{"type":"open","side":"buy","price":"8831.68000000","order_id":"cf1ffae0-7908-43c5-9338-dd417947097a","remaining_size":"0.10500000","product_id":"BTC-EUR","sequence":3257977070,"time":"2018-01-22T15:14:31.751000Z"}
{"type":"received","order_id":"49287499-eda8-4da6-a281-64d522bbbbad","order_type":"limit","size":"0.22947933","price":"8848.78000000","side":"sell","client_oid":"4b377d5f-ccd0-446b-900d-e45122ca96e9","product_id":"BTC-EUR","sequence":3257977071,"time":"2018-01-22T15:14:31.754000Z"}
{"type":"open","side":"sell","price":"8848.78000000","order_id":"49287499-eda8-4da6-a281-64d522bbbbad","remaining_size":"0.22947933","product_id":"BTC-EUR","sequence":3257977072,"time":"2018-01-22T15:14:31.754000Z"}
{"type":"received","order_id":"6a0687ce-e56a-49cc-b642-3cb5e730e794","order_type":"limit","size":"0.10500000","price":"8831.68000000","side":"buy","client_oid":"38698a4e-eeff-47b3-a247-fcb4ebf2625b","product_id":"BTC-EUR","sequence":3257977073,"time":"2018-01-22T15:14:31.767000Z"}
{"type":"open","side":"buy","price":"8831.68000000","order_id":"6a0687ce-e56a-49cc-b642-3cb5e730e794","remaining_size":"0.10500000","product_id":"BTC-EUR","sequence":3257977074,"time":"2018-01-22T15:14:31.767000Z"}
{"type":"received","order_id":"95ab8262-4ea1-463c-abf1-3b530ab760c2","order_type":"limit","size":"0.02243610","price":"8815.12000000","side":"buy","client_oid":"20d2b865-5f75-4a78-b228-481b3a4f0317","product_id":"BTC-EUR","sequence":3257977075,"time":"2018-01-22T15:14:31.769000Z"}
{"type":"open","side":"buy","price":"8815.12000000","order_id":"95ab8262-4ea1-463c-abf1-3b530ab760c2","remaining_size":"0.02243610","product_id":"BTC-EUR","sequence":3257977076,"time":"2018-01-22T15:14:31.769000Z"}
{"type":"received","order_id":"b3e2d03e-0b4e-491f-b4ab-80a6086a0133","order_type":"limit","size":"0.10500000","price":"8831.68000000","side":"buy","client_oid":"e52e4c8c-f0eb-45a1-8bb8-2cd80733572f","product_id":"BTC-EUR","sequence":3257977077,"time":"2018-01-22T15:14:31.778000Z"}
{"type":"open","side":"buy","price":"8831.68000000","order_id":"b3e2d03e-0b4e-491f-b4ab-80a6086a0133","remaining_size":"0.10500000","product_id":"BTC-EUR","sequence":3257977078,"time":"2018-01-22T15:14:31.778000Z"}
{"type":"done","side":"sell","order_id":"7684e396-2a5b-462f-90ea-9514fc838ad6","reason":"canceled","product_id":"BTC-EUR","price":"9104.09000000","remaining_size":"1.28000000","sequence":3257977079,"time":"2018-01-22T15:14:31.844000Z"}
{"type":"done","side":"buy","order_id":"6a0687ce-e56a-49cc-b642-3cb5e730e794","reason":"canceled","product_id":"BTC-EUR","price":"8831.68000000","remaining_size":"0.10500000","sequence":3257977080,"time":"2018-01-22T15:14:31.850000Z"}
{"type":"done","side":"buy","order_id":"cf1ffae0-7908-43c5-9338-dd417947097a","reason":"canceled","product_id":"BTC-EUR","price":"8831.68000000","remaining_size":"0.10500000","sequence":3257977081,"time":"2018-01-22T15:14:31.863000Z"}
{"type":"received","order_id":"5a3976ae-def8-4859-bdd4-4c83b336bdd5","order_type":"limit","size":"0.01510808","price":"8822.63000000","side":"buy","client_oid":"52953894-ddac-477c-a34c-9cfc6b5521cd","product_id":"BTC-EUR","sequence":3257977082,"time":"2018-01-22T15:14:31.871000Z"}
{"type":"open","side":"buy","price":"8822.63000000","order_id":"5a3976ae-def8-4859-bdd4-4c83b336bdd5","remaining_size":"0.01510808","product_id":"BTC-EUR","sequence":3257977083,"time":"2018-01-22T15:14:31.871000Z"}
{"type":"done","side":"sell","order_id":"8ea87e02-13b2-45e8-8882-5167758c70eb","reason":"canceled","product_id":"BTC-EUR","price":"8848.80000000","remaining_size":"0.01887096","sequence":3257977084,"time":"2018-01-22T15:14:31.881000Z"}
{"type":"received","order_id":"07d03fa7-0e43-432e-b9c0-f2485331f441","order_type":"limit","size":"0.21455929","price":"8900.93000000","side":"sell","client_oid":"d9702fd8-6cdc-40d5-be7b-5737987ee732","product_id":"BTC-EUR","sequence":3257977085,"time":"2018-01-22T15:14:31.882000Z"}
{"type":"open","side":"sell","price":"8900.93000000","order_id":"07d03fa7-0e43-432e-b9c0-f2485331f441","remaining_size":"0.21455929","product_id":"BTC-EUR","sequence":3257977086,"time":"2018-01-22T15:14:31.882000Z"}
{"type":"received","order_id":"b728444e-82b4-42ab-9dea-6410231b337b","order_type":"limit","size":"0.01510808","price":"8778.16000000","side":"buy","client_oid":"cb561002-e57a-47c3-8f58-059fa9f4c892","product_id":"BTC-EUR","sequence":3257977087,"time":"2018-01-22T15:14:31.889000Z"}
{"type":"open","side":"buy","price":"8778.16000000","order_id":"b728444e-82b4-42ab-9dea-6410231b337b","remaining_size":"0.01510808","product_id":"BTC-EUR","sequence":3257977088,"time":"2018-01-22T15:14:31.889000Z"}
{"type":"received","order_id":"c63f5c50-25dc-4a75-950e-80d51ac93238","order_type":"limit","size":"0.36857350","price":"8891.99000000","side":"sell","client_oid":"18aa297a-9913-452f-adaf-3f8a0c17ef94","product_id":"BTC-EUR","sequence":3257977089,"time":"2018-01-22T15:14:31.891000Z"}
{"type":"open","side":"sell","price":"8891.99000000","order_id":"c63f5c50-25dc-4a75-950e-80d51ac93238","remaining_size":"0.36857350","product_id":"BTC-EUR","sequence":3257977090,"time":"2018-01-22T15:14:31.891000Z"}
{"type":"received","order_id":"696cfd05-120d-4e78-9c17-22d935a83f31","order_type":"limit","size":"0.36857350","price":"8904.65000000","side":"sell","client_oid":"c351dc4e-d9a1-42d7-836a-44837ebade22","product_id":"BTC-EUR","sequence":3257977091,"time":"2018-01-22T15:14:31.895000Z"}
{"type":"open","side":"sell","price":"8904.65000000","order_id":"696cfd05-120d-4e78-9c17-22d935a83f31","remaining_size":"0.36857350","product_id":"BTC-EUR","sequence":3257977092,"time":"2018-01-22T15:14:31.895000Z"}
{"type":"received","order_id":"5d8d6cc1-dccd-4482-9033-62e91050b040","order_type":"limit","size":"0.36857350","price":"8916.44000000","side":"sell","client_oid":"4312b72a-1603-40ca-9b64-429ffc56c58e","product_id":"BTC-EUR","sequence":3257977093,"time":"2018-01-22T15:14:31.901000Z"}
{"type":"open","side":"sell","price":"8916.44000000","order_id":"5d8d6cc1-dccd-4482-9033-62e91050b040","remaining_size":"0.36857350","product_id":"BTC-EUR","sequence":3257977094,"time":"2018-01-22T15:14:31.901000Z"}
{"type":"received","order_id":"ba7bb9df-4ed4-4fe2-8f05-8e7ee1826d60","order_type":"limit","size":"0.02243610","price":"8725.85000000","side":"buy","client_oid":"621582a3-6ba2-4c60-a281-63c02f1ac4f8","product_id":"BTC-EUR","sequence":3257977095,"time":"2018-01-22T15:14:31.909000Z"}
{"type":"open","side":"buy","price":"8725.85000000","order_id":"ba7bb9df-4ed4-4fe2-8f05-8e7ee1826d60","remaining_size":"0.02243610","product_id":"BTC-EUR","sequence":3257977096,"time":"2018-01-22T15:14:31.909000Z"}
{"type":"received","order_id":"7653f0c5-fefa-4805-bd32-7159d6cba6fb","order_type":"limit","size":"0.02243610","price":"8681.42000000","side":"buy","client_oid":"78bb6e58-d645-4b77-8be5-6a319101beae","product_id":"BTC-EUR","sequence":3257977097,"time":"2018-01-22T15:14:31.912000Z"}
{"type":"open","side":"buy","price":"8681.42000000","order_id":"7653f0c5-fefa-4805-bd32-7159d6cba6fb","remaining_size":"0.02243610","product_id":"BTC-EUR","sequence":3257977098,"time":"2018-01-22T15:14:31.912000Z"}
{"type":"received","order_id":"f19597c7-a8b1-4bf0-977c-622a06a64a44","order_type":"limit","size":"0.10500000","price":"8831.68000000","side":"buy","client_oid":"4602d4d3-61f3-4e0a-8096-8975d9285153","product_id":"BTC-EUR","sequence":3257977099,"time":"2018-01-22T15:14:31.924000Z"}
{"type":"open","side":"buy","price":"8831.68000000","order_id":"f19597c7-a8b1-4bf0-977c-622a06a64a44","remaining_size":"0.10500000","product_id":"BTC-EUR","sequence":3257977100,"time":"2018-01-22T15:14:31.924000Z"}
{"type":"received","order_id":"14234926-99aa-4066-992c-11a69f9dd39e","order_type":"limit","size":"0.10500000","price":"8831.68000000","side":"buy","client_oid":"d5048821-8c9f-46cb-8b03-4a2570a6b71b","product_id":"BTC-EUR","sequence":3257977101,"time":"2018-01-22T15:14:31.933000Z"}
{"type":"open","side":"buy","price":"8831.68000000","order_id":"14234926-99aa-4066-992c-11a69f9dd39e","remaining_size":"0.10500000","product_id":"BTC-EUR","sequence":3257977102,"time":"2018-01-22T15:14:31.933000Z"}
{"type":"received","order_id":"19a02f91-3b41-40ae-9cfa-559b1a61aa00","order_type":"limit","size":"0.01000000","price":"9096.64000000","side":"buy","product_id":"BTC-EUR","sequence":3257977103,"time":"2018-01-22T15:14:32.110000Z"}
{"type":"match","trade_id":10551345,"maker_order_id":"80ee1692-b809-4916-aeb3-90920041ea09","taker_order_id":"19a02f91-3b41-40ae-9cfa-559b1a61aa00","side":"sell","size":"0.01000000","price":"8831.69000000","product_id":"BTC-EUR","sequence":3257977104,"time":"2018-01-22T15:14:32.110000Z"}
{"type":"done","side":"buy","order_id":"19a02f91-3b41-40ae-9cfa-559b1a61aa00","reason":"filled","product_id":"BTC-EUR","price":"9096.64000000","remaining_size":"0.00000000","sequence":3257977105,"time":"2018-01-22T15:14:32.110000Z"}
{"type":"received","order_id":"a577c677-a7a9-4ca5-b913-e21e276aec87","order_type":"limit","size":"0.01887096","price":"8848.78000000","side":"sell","client_oid":"e8d6c651-8e68-43c8-be44-a8d228ee62f5","product_id":"BTC-EUR","sequence":3257977106,"time":"2018-01-22T15:14:32.156000Z"}
{"type":"open","side":"sell","price":"8848.78000000","order_id":"a577c677-a7a9-4ca5-b913-e21e276aec87","remaining_size":"0.01887096","product_id":"BTC-EUR","sequence":3257977107,"time":"2018-01-22T15:14:32.156000Z"}
{"type":"received","order_id":"8b5da55b-1964-42b8-8442-f4567b331381","order_type":"limit","size":"1.28000000","price":"8631.27000000","side":"buy","product_id":"BTC-EUR","sequence":3257977108,"time":"2018-01-22T15:14:32.221000Z"}
{"type":"open","side":"buy","price":"8631.27000000","order_id":"8b5da55b-1964-42b8-8442-f4567b331381","remaining_size":"1.28000000","product_id":"BTC-EUR","sequence":3257977109,"time":"2018-01-22T15:14:32.221000Z"}
{"type":"done","side":"sell","order_id":"66a94851-8197-4d87-a97e-e14360932fae","reason":"canceled","product_id":"BTC-EUR","price":"8848.80000000","remaining_size":"0.11241548","sequence":3257977110,"time":"2018-01-22T15:14:32.478000Z"}
{"type":"received","order_id":"c999b74a-cd46-4ab7-9004-30873fc56d8a","order_type":"limit","size":"0.00660000","price":"14881.43000000","side":"sell","client_oid":"ef7fa530-ff86-11e7-84d8-edd6461c088f","product_id":"BTC-EUR","sequence":3257977111,"time":"2018-01-22T15:14:32.578000Z"}
{"type":"open","side":"sell","price":"14881.43000000","order_id":"c999b74a-cd46-4ab7-9004-30873fc56d8a","remaining_size":"0.00660000","product_id":"BTC-EUR","sequence":3257977112,"time":"2018-01-22T15:14:32.578000Z"}
{"type":"received","order_id":"dc5ce648-8233-4910-acea-00a47e9b6833","order_type":"limit","size":"0.11241548","price":"8848.78000000","side":"sell","product_id":"BTC-EUR","sequence":3257977113,"time":"2018-01-22T15:14:32.613000Z"}
{"type":"open","side":"sell","price":"8848.78000000","order_id":"dc5ce648-8233-4910-acea-00a47e9b6833","remaining_size":"0.11241548","product_id":"BTC-EUR","sequence":3257977114,"time":"2018-01-22T15:14:32.613000Z"}
{"type":"done","side":"sell","order_id":"8143bb7d-ddfd-4b35-a1b3-0383e572d098","reason":"canceled","product_id":"BTC-EUR","price":"8869.88000000","remaining_size":"0.18415358","sequence":3257977115,"time":"2018-01-22T15:14:32.639000Z"}
{"type":"received","order_id":"b5ae4bc6-ddbe-41c8-955d-f9673cf90af8","order_type":"limit","size":"6.34763622","price":"8731.91000000","side":"buy","product_id":"BTC-EUR","sequence":3257977116,"time":"2018-01-22T15:14:32.651000Z"}
{"type":"open","side":"buy","price":"8731.91000000","order_id":"b5ae4bc6-ddbe-41c8-955d-f9673cf90af8","remaining_size":"6.34763622","product_id":"BTC-EUR","sequence":3257977117,"time":"2018-01-22T15:14:32.651000Z"}
{"type":"done","side":"sell","order_id":"49287499-eda8-4da6-a281-64d522bbbbad","reason":"canceled","product_id":"BTC-EUR","price":"8848.78000000","remaining_size":"0.22947933","sequence":3257977118,"time":"2018-01-22T15:14:32.694000Z"}
{"type":"done","side":"sell","order_id":"05e12cc8-4cff-458c-a97e-cd776bce51ca","reason":"canceled","product_id":"BTC-EUR","price":"8848.78000000","remaining_size":"0.04164971","sequence":3257977119,"time":"2018-01-22T15:14:32.714000Z"}
{"type":"done","side":"buy","order_id":"511f5132-c84d-43b9-ac2d-938af901a1e0","reason":"canceled","product_id":"BTC-EUR","price":"8658.50000000","remaining_size":"1.89487000","sequence":3257977120,"time":"2018-01-22T15:14:32.840000Z"}
{"type":"done","side":"sell","order_id":"a577c677-a7a9-4ca5-b913-e21e276aec87","reason":"canceled","product_id":"BTC-EUR","price":"8848.78000000","remaining_size":"0.01887096","sequence":3257977121,"time":"2018-01-22T15:14:32.852000Z"}
{"type":"received","order_id":"388d3934-6920-492d-a8c4-4f278e7e2c17","order_type":"limit","size":"1.89573000","price":"8654.40000000","side":"buy","client_oid":"3d88fd20-a2cc-4dca-9b6f-24993f865505","product_id":"BTC-EUR","sequence":3257977122,"time":"2018-01-22T15:14:32.860000Z"}
{"type":"open","side":"buy","price":"8654.40000000","order_id":"388d3934-6920-492d-a8c4-4f278e7e2c17","remaining_size":"1.89573000","product_id":"BTC-EUR","sequence":3257977123,"time":"2018-01-22T15:14:32.860000Z"}
{"type":"received","order_id":"47eb3cf1-b6c9-425f-8991-295f7319016c","order_type":"limit","size":"0.04164971","price":"8848.76000000","side":"sell","client_oid":"07b0f663-75ce-4514-9925-2d94ce37c728","product_id":"BTC-EUR","sequence":3257977124,"time":"2018-01-22T15:14:32.928000Z"}
{"type":"open","side":"sell","price":"8848.76000000","order_id":"47eb3cf1-b6c9-425f-8991-295f7319016c","remaining_size":"0.04164971","product_id":"BTC-EUR","sequence":3257977125,"time":"2018-01-22T15:14:32.928000Z"}
{"type":"received","order_id":"9103d39d-5f73-420e-9919-48cb5e28120e","order_type":"limit","size":"0.22947933","price":"8848.76000000","side":"sell","client_oid":"a013a175-d18f-4460-8918-9cfa5778f299","product_id":"BTC-EUR","sequence":3257977126,"time":"2018-01-22T15:14:32.935000Z"}
{"type":"open","side":"sell","price":"8848.76000000","order_id":"9103d39d-5f73-420e-9919-48cb5e28120e","remaining_size":"0.22947933","product_id":"BTC-EUR","sequence":3257977127,"time":"2018-01-22T15:14:32.936000Z"}
{"type":"received","order_id":"2a137d1f-5780-4235-9613-42825b1d7c3f","order_type":"limit","size":"0.18415358","price":"8869.88000000","side":"sell","client_oid":"4980b4e8-5622-4671-b12f-82db81c9b39b","product_id":"BTC-EUR","sequence":3257977128,"time":"2018-01-22T15:14:32.994000Z"}
{"type":"open","side":"sell","price":"8869.88000000","order_id":"2a137d1f-5780-4235-9613-42825b1d7c3f","remaining_size":"0.18415358","product_id":"BTC-EUR","sequence":3257977129,"time":"2018-01-22T15:14:32.994000Z"}
{"type":"received","order_id":"ca8e84f5-f7ec-408a-a10a-70ea321e0bd5","order_type":"limit","size":"0.01887096","price":"8848.76000000","side":"sell","client_oid":"3a792bc5-3b1b-4733-ade3-bbd474e8edbe","product_id":"BTC-EUR","sequence":3257977130,"time":"2018-01-22T15:14:33.102000Z"}
{"type":"open","side":"sell","price":"8848.76000000","order_id":"ca8e84f5-f7ec-408a-a10a-70ea321e0bd5","remaining_size":"0.01887096","product_id":"BTC-EUR","sequence":3257977131,"time":"2018-01-22T15:14:33.102000Z"}
{"type":"received","order_id":"dcef5143-8b4b-4558-bdaa-cb47679bee88","order_type":"limit","size":"2.36000000","price":"8566.73000000","side":"sell","product_id":"BTC-EUR","sequence":3257977132,"time":"2018-01-22T15:14:33.303000Z"}
{"type":"match","trade_id":10551346,"maker_order_id":"da56b34e-b82d-48b0-9300-cf60be8eb663","taker_order_id":"dcef5143-8b4b-4558-bdaa-cb47679bee88","side":"buy","size":"0.99255861","price":"8831.68000000","product_id":"BTC-EUR","sequence":3257977133,"time":"2018-01-22T15:14:33.303000Z"}
{"type":"done","side":"buy","order_id":"da56b34e-b82d-48b0-9300-cf60be8eb663","reason":"filled","product_id":"BTC-EUR","price":"8831.68000000","remaining_size":"0","sequence":3257977134,"time":"2018-01-22T15:14:33.303000Z"}
{"type":"match","trade_id":10551347,"maker_order_id":"e23d60ab-f089-4ee7-856d-39f7d722bfb4","taker_order_id":"dcef5143-8b4b-4558-bdaa-cb47679bee88","side":"buy","size":"0.15081048","price":"8831.68000000","product_id":"BTC-EUR","sequence":3257977135,"time":"2018-01-22T15:14:33.303000Z"}
{"type":"done","side":"buy","order_id":"e23d60ab-f089-4ee7-856d-39f7d722bfb4","reason":"filled","product_id":"BTC-EUR","price":"8831.68000000","remaining_size":"0","sequence":3257977136,"time":"2018-01-22T15:14:33.303000Z"}
{"type":"match","trade_id":10551348,"maker_order_id":"790ad1df-87a2-4965-8608-1d3c8a4e9667","taker_order_id":"dcef5143-8b4b-4558-bdaa-cb47679bee88","side":"buy","size":"0.30970815","price":"8831.68000000","product_id":"BTC-EUR","sequence":3257977137,"time":"2018-01-22T15:14:33.303000Z"}
{"type":"done","side":"buy","order_id":"790ad1df-87a2-4965-8608-1d3c8a4e9667","reason":"filled","product_id":"BTC-EUR","price":"8831.68000000","remaining_size":"0","sequence":3257977138,"time":"2018-01-22T15:14:33.303000Z"}
{"type":"match","trade_id":10551349,"maker_order_id":"7b7d1c35-0c65-4bd8-9bb1-b353c2e6c666","taker_order_id":"dcef5143-8b4b-4558-bdaa-cb47679bee88","side":"buy","size":"0.00113228","price":"8831.68000000","product_id":"BTC-EUR","sequence":3257977139,"time":"2018-01-22T15:14:33.303000Z"}
{"type":"done","side":"buy","order_id":"7b7d1c35-0c65-4bd8-9bb1-b353c2e6c666","reason":"filled","product_id":"BTC-EUR","price":"8831.68000000","remaining_size":"0","sequence":3257977140,"time":"2018-01-22T15:14:33.303000Z"}
{"type":"match","trade_id":10551350,"maker_order_id":"f95461b0-5dfe-4e27-95b5-9563efcba374","taker_order_id":"dcef5143-8b4b-4558-bdaa-cb47679bee88","side":"buy","size":"0.09800000","price":"8831.68000000","product_id":"BTC-EUR","sequence":3257977141,"time":"2018-01-22T15:14:33.303000Z"}
{"type":"done","side":"buy","order_id":"f95461b0-5dfe-4e27-95b5-9563efcba374","reason":"filled","product_id":"BTC-EUR","price":"8831.68000000","remaining_size":"0","sequence":3257977142,"time":"2018-01-22T15:14:33.303000Z"}
{"type":"match","trade_id":10551351,"maker_order_id":"55d55fa7-a3c3-4c31-af96-a5880135fe9c","taker_order_id":"dcef5143-8b4b-4558-bdaa-cb47679bee88","side":"buy","size":"0.09800000","price":"8831.68000000","product_id":"BTC-EUR","sequence":3257977143,"time":"2018-01-22T15:14:33.303000Z"}
{"type":"done","side":"buy","order_id":"55d55fa7-a3c3-4c31-af96-a5880135fe9c","reason":"filled","product_id":"BTC-EUR","price":"8831.68000000","remaining_size":"0","sequence":3257977144,"time":"2018-01-22T15:14:33.303000Z"}
{"type":"match","trade_id":10551352,"maker_order_id":"0fce7489-f729-4e38-94f9-41fa91f18d20","taker_order_id":"dcef5143-8b4b-4558-bdaa-cb47679bee88","side":"buy","size":"0.09800000","price":"8831.68000000","product_id":"BTC-EUR","sequence":3257977145,"time":"2018-01-22T15:14:33.303000Z"}
{"type":"done","side":"buy","order_id":"0fce7489-f729-4e38-94f9-41fa91f18d20","reason":"filled","product_id":"BTC-EUR","price":"8831.68000000","remaining_size":"0","sequence":3257977146,"time":"2018-01-22T15:14:33.303000Z"}
{"type":"match","trade_id":10551353,"maker_order_id":"5ca73024-4417-4674-8030-457b248ee9c1","taker_order_id":"dcef5143-8b4b-4558-bdaa-cb47679bee88","side":"buy","size":"0.00200000","price":"8831.68000000","product_id":"BTC-EUR","sequence":3257977147,"time":"2018-01-22T15:14:33.303000Z"}
{"type":"done","side":"buy","order_id":"5ca73024-4417-4674-8030-457b248ee9c1","reason":"filled","product_id":"BTC-EUR","price":"8831.68000000","remaining_size":"0","sequence":3257977148,"time":"2018-01-22T15:14:33.303000Z"}
{"type":"match","trade_id":10551354,"maker_order_id":"b5fd1e37-b2dc-456c-ac10-59f013ab9ab3","taker_order_id":"dcef5143-8b4b-4558-bdaa-cb47679bee88","side":"buy","size":"0.01510808","price":"8831.68000000","product_id":"BTC-EUR","sequence":3257977149,"time":"2018-01-22T15:14:33.303000Z"}
{"type":"done","side":"buy","order_id":"b5fd1e37-b2dc-456c-ac10-59f013ab9ab3","reason":"filled","product_id":"BTC-EUR","price":"8831.68000000","remaining_size":"0","sequence":3257977150,"time":"2018-01-22T15:14:33.303000Z"}
{"type":"match","trade_id":10551355,"maker_order_id":"b3e2d03e-0b4e-491f-b4ab-80a6086a0133","taker_order_id":"dcef5143-8b4b-4558-bdaa-cb47679bee88","side":"buy","size":"0.10500000","price":"8831.68000000","product_id":"BTC-EUR","sequence":3257977151,"time":"2018-01-22T15:14:33.303000Z"}
{"type":"done","side":"buy","order_id":"b3e2d03e-0b4e-491f-b4ab-80a6086a0133","reason":"filled","product_id":"BTC-EUR","price":"8831.68000000","remaining_size":"0","sequence":3257977152,"time":"2018-01-22T15:14:33.303000Z"}
{"type":"match","trade_id":10551356,"maker_order_id":"f19597c7-a8b1-4bf0-977c-622a06a64a44","taker_order_id":"dcef5143-8b4b-4558-bdaa-cb47679bee88","side":"buy","size":"0.10500000","price":"8831.68000000","product_id":"BTC-EUR","sequence":3257977153,"time":"2018-01-22T15:14:33.303000Z"}
{"type":"done","side":"buy","order_id":"f19597c7-a8b1-4bf0-977c-622a06a64a44","reason":"filled","product_id":"BTC-EUR","price":"8831.68000000","remaining_size":"0","sequence":3257977154,"time":"2018-01-22T15:14:33.303000Z"}
{"type":"match","trade_id":10551357,"maker_order_id":"14234926-99aa-4066-992c-11a69f9dd39e","taker_order_id":"dcef5143-8b4b-4558-bdaa-cb47679bee88","side":"buy","size":"0.10500000","price":"8831.68000000","product_id":"BTC-EUR","sequence":3257977155,"time":"2018-01-22T15:14:33.303000Z"}
{"type":"done","side":"buy","order_id":"14234926-99aa-4066-992c-11a69f9dd39e","reason":"filled","product_id":"BTC-EUR","price":"8831.68000000","remaining_size":"0","sequence":3257977156,"time":"2018-01-22T15:14:33.303000Z"}
{"type":"match","trade_id":10551358,"maker_order_id":"9ce7d437-d3fd-4f81-807c-b29ba180ab4a","taker_order_id":"dcef5143-8b4b-4558-bdaa-cb47679bee88","side":"buy","size":"0.04205979","price":"8831.50000000","product_id":"BTC-EUR","sequence":3257977157,"time":"2018-01-22T15:14:33.303000Z"}
{"type":"done","side":"buy","order_id":"9ce7d437-d3fd-4f81-807c-b29ba180ab4a","reason":"filled","product_id":"BTC-EUR","price":"8831.50000000","remaining_size":"0","sequence":3257977158,"time":"2018-01-22T15:14:33.303000Z"}
{"type":"match","trade_id":10551359,"maker_order_id":"0a38c861-a210-47d1-94df-52b118f38df8","taker_order_id":"dcef5143-8b4b-4558-bdaa-cb47679bee88","side":"buy","size":"0.05700000","price":"8831.50000000","product_id":"BTC-EUR","sequence":3257977159,"time":"2018-01-22T15:14:33.303000Z"}
{"type":"done","side":"buy","order_id":"0a38c861-a210-47d1-94df-52b118f38df8","reason":"filled","product_id":"BTC-EUR","price":"8831.50000000","remaining_size":"0","sequence":3257977160,"time":"2018-01-22T15:14:33.303000Z"}
{"type":"match","trade_id":10551360,"maker_order_id":"8fd67c64-a205-455d-bbd7-215065ef6b7e","taker_order_id":"dcef5143-8b4b-4558-bdaa-cb47679bee88","side":"buy","size":"0.18062261","price":"8823.33000000","product_id":"BTC-EUR","sequence":3257977161,"time":"2018-01-22T15:14:33.303000Z"}
{"type":"done","side":"sell","order_id":"dcef5143-8b4b-4558-bdaa-cb47679bee88","reason":"filled","product_id":"BTC-EUR","price":"8566.73000000","remaining_size":"0.00000000","sequence":3257977162,"time":"2018-01-22T15:14:33.303000Z"}
{"type":"done","side":"buy","order_id":"b5ae4bc6-ddbe-41c8-955d-f9673cf90af8","reason":"canceled","product_id":"BTC-EUR","price":"8731.91000000","remaining_size":"6.34763622","sequence":3257977163,"time":"2018-01-22T15:14:33.309000Z"}
{"type":"received","order_id":"b226959a-4d09-4c21-9c5b-af480fe5a053","order_type":"limit","size":"0.05000000","price":"8823.34000000","side":"buy","client_oid":"4e420356-6a8e-46e4-896b-cf2636131fd7","product_id":"BTC-EUR","sequence":3257977164,"time":"2018-01-22T15:14:33.367000Z"}
{"type":"open","side":"buy","price":"8823.34000000","order_id":"b226959a-4d09-4c21-9c5b-af480fe5a053","remaining_size":"0.05000000","product_id":"BTC-EUR","sequence":3257977165,"time":"2018-01-22T15:14:33.367000Z"}
{"type":"received","order_id":"f4a7ce54-95d3-45c2-be61-940a7095b61c","order_type":"limit","size":"0.14814796","price":"8831.69000000","side":"sell","product_id":"BTC-EUR","sequence":3257977166,"time":"2018-01-22T15:14:33.384000Z"}
{"type":"open","side":"sell","price":"8831.69000000","order_id":"f4a7ce54-95d3-45c2-be61-940a7095b61c","remaining_size":"0.14814796","product_id":"BTC-EUR","sequence":3257977167,"time":"2018-01-22T15:14:33.384000Z"}
{"type":"received","order_id":"9dfbf040-c482-47f4-b350-e20faf71de8d","order_type":"limit","size":"0.00160300","price":"8831.63000000","side":"sell","product_id":"BTC-EUR","sequence":3257977168,"time":"2018-01-22T15:14:33.387000Z"}
{"type":"open","side":"sell","price":"8831.63000000","order_id":"9dfbf040-c482-47f4-b350-e20faf71de8d","remaining_size":"0.00160300","product_id":"BTC-EUR","sequence":3257977169,"time":"2018-01-22T15:14:33.387000Z"}
{"type":"done","side":"sell","order_id":"6bb17697-d648-4dc6-ad60-1837c18d8686","reason":"canceled","product_id":"BTC-EUR","price":"8831.69000000","remaining_size":"0.00113228","sequence":3257977170,"time":"2018-01-22T15:14:33.416000Z"}
{"type":"received","order_id":"d6f7e121-637c-4169-9392-5b20b2b25a2b","order_type":"limit","size":"0.03773580","price":"8886.72000000","side":"sell","client_oid":"44581813-635a-4889-8e66-5973ec985c17","product_id":"BTC-EUR","sequence":3257977171,"time":"2018-01-22T15:14:33.465000Z"}
{"type":"open","side":"sell","price":"8886.72000000","order_id":"d6f7e121-637c-4169-9392-5b20b2b25a2b","remaining_size":"0.03773580","product_id":"BTC-EUR","sequence":3257977172,"time":"2018-01-22T15:14:33.465000Z"}
{"type":"done","side":"sell","order_id":"9dfbf040-c482-47f4-b350-e20faf71de8d","reason":"canceled","product_id":"BTC-EUR","price":"8831.63000000","remaining_size":"0.00160300","sequence":3257977173,"time":"2018-01-22T15:14:33.486000Z"}
{"type":"received","order_id":"18cc8cb6-ec69-4413-8f81-23b7251ae79a","order_type":"limit","size":"0.01731400","price":"8831.63000000","side":"sell","product_id":"BTC-EUR","sequence":3257977174,"time":"2018-01-22T15:14:33.493000Z"}
{"type":"open","side":"sell","price":"8831.63000000","order_id":"18cc8cb6-ec69-4413-8f81-23b7251ae79a","remaining_size":"0.01731400","product_id":"BTC-EUR","sequence":3257977175,"time":"2018-01-22T15:14:33.493000Z"}
{"type":"done","side":"sell","order_id":"151b352f-cdfd-4071-8dd1-2f5c7aa6ea1e","reason":"canceled","product_id":"BTC-EUR","price":"8831.69000000","remaining_size":"0.21404538","sequence":3257977176,"time":"2018-01-22T15:14:33.517000Z"}
{"type":"done","side":"sell","order_id":"2a137d1f-5780-4235-9613-42825b1d7c3f","reason":"canceled","product_id":"BTC-EUR","price":"8869.88000000","remaining_size":"0.18415358","sequence":3257977177,"time":"2018-01-22T15:14:33.544000Z"}
{"type":"received","order_id":"6ab11d81-755a-4831-8ce2-ae5c0247af2a","order_type":"limit","size":"0.24800071","price":"8823.34000000","side":"buy","client_oid":"2805227c-d035-43f0-ad2b-bc3c30e2f027","product_id":"BTC-EUR","sequence":3257977178,"time":"2018-01-22T15:14:33.558000Z"}
{"type":"open","side":"buy","price":"8823.34000000","order_id":"6ab11d81-755a-4831-8ce2-ae5c0247af2a","remaining_size":"0.24800071","product_id":"BTC-EUR","sequence":3257977179,"time":"2018-01-22T15:14:33.558000Z"}
{"type":"received","order_id":"5b376925-5757-4175-bbe5-ecb47d445168","order_type":"limit","size":"0.00113228","price":"8831.62000000","side":"sell","client_oid":"5cbd58a6-7499-4783-b397-bb819eb2591d","product_id":"BTC-EUR","sequence":3257977180,"time":"2018-01-22T15:14:33.569000Z"}
{"type":"open","side":"sell","price":"8831.62000000","order_id":"5b376925-5757-4175-bbe5-ecb47d445168","remaining_size":"0.00113228","product_id":"BTC-EUR","sequence":3257977181,"time":"2018-01-22T15:14:33.569000Z"}
{"type":"received","order_id":"74b58004-aaa5-42ae-a9ba-e633e0227c30","order_type":"limit","size":"0.42640068","price":"8831.69000000","side":"sell","product_id":"BTC-EUR","sequence":3257977182,"time":"2018-01-22T15:14:33.572000Z"}
{"type":"open","side":"sell","price":"8831.69000000","order_id":"74b58004-aaa5-42ae-a9ba-e633e0227c30","remaining_size":"0.42640068","product_id":"BTC-EUR","sequence":3257977183,"time":"2018-01-22T15:14:33.572000Z"}
{"type":"done","side":"sell","order_id":"5b376925-5757-4175-bbe5-ecb47d445168","reason":"canceled","product_id":"BTC-EUR","price":"8831.62000000","remaining_size":"0.00113228","sequence":3257977184,"time":"2018-01-22T15:14:33.587000Z"}
{"type":"received","order_id":"b405f59e-f478-45eb-b552-fb70e61d7c17","order_type":"limit","size":"0.00113335","price":"8823.35000000","side":"buy","client_oid":"28c95d6a-8937-45a2-a505-012792c818d2","product_id":"BTC-EUR","sequence":3257977185,"time":"2018-01-22T15:14:33.632000Z"}
{"type":"open","side":"buy","price":"8823.35000000","order_id":"b405f59e-f478-45eb-b552-fb70e61d7c17","remaining_size":"0.00113335","product_id":"BTC-EUR","sequence":3257977186,"time":"2018-01-22T15:14:33.632000Z"}
{"type":"done","side":"buy","order_id":"b405f59e-f478-45eb-b552-fb70e61d7c17","reason":"canceled","product_id":"BTC-EUR","price":"8823.35000000","remaining_size":"0.00113335","sequence":3257977187,"time":"2018-01-22T15:14:33.641000Z"}
{"type":"done","side":"buy","order_id":"8fd67c64-a205-455d-bbd7-215065ef6b7e","reason":"canceled","product_id":"BTC-EUR","price":"8823.33000000","remaining_size":"0.00450258","sequence":3257977188,"time":"2018-01-22T15:14:33.653000Z"}
{"type":"received","order_id":"4219e649-d381-444c-89fa-fb9b72ea1958","order_type":"limit","size":"0.00113228","price":"8831.61000000","side":"sell","client_oid":"27f85e10-adc7-42df-8136-3dccc4423db4","product_id":"BTC-EUR","sequence":3257977189,"time":"2018-01-22T15:14:33.655000Z"}
{"type":"open","side":"sell","price":"8831.61000000","order_id":"4219e649-d381-444c-89fa-fb9b72ea1958","remaining_size":"0.00113228","product_id":"BTC-EUR","sequence":3257977190,"time":"2018-01-22T15:14:33.655000Z"}
{"type":"done","side":"sell","order_id":"18cc8cb6-ec69-4413-8f81-23b7251ae79a","reason":"canceled","product_id":"BTC-EUR","price":"8831.63000000","remaining_size":"0.01731400","sequence":3257977191,"time":"2018-01-22T15:14:33.676000Z"}
{"type":"done","side":"sell","order_id":"9103d39d-5f73-420e-9919-48cb5e28120e","reason":"canceled","product_id":"BTC-EUR","price":"8848.76000000","remaining_size":"0.22947933","sequence":3257977192,"time":"2018-01-22T15:14:33.678000Z"}
{"type":"done","side":"sell","order_id":"47eb3cf1-b6c9-425f-8991-295f7319016c","reason":"canceled","product_id":"BTC-EUR","price":"8848.76000000","remaining_size":"0.04164971","sequence":3257977193,"time":"2018-01-22T15:14:33.680000Z"}
{"type":"received","order_id":"3ad21a40-c902-4823-b78c-03fb0790135a","order_type":"limit","size":"0.24800043","price":"8823.35000000","side":"buy","client_oid":"84192537-49e6-4750-9ba1-41bdb4af8f42","product_id":"BTC-EUR","sequence":3257977194,"time":"2018-01-22T15:14:33.686000Z"}
{"type":"open","side":"buy","price":"8823.35000000","order_id":"3ad21a40-c902-4823-b78c-03fb0790135a","remaining_size":"0.24800043","product_id":"BTC-EUR","sequence":3257977195,"time":"2018-01-22T15:14:33.686000Z"}
{"type":"done","side":"sell","order_id":"4219e649-d381-444c-89fa-fb9b72ea1958","reason":"canceled","product_id":"BTC-EUR","price":"8831.61000000","remaining_size":"0.00113228","sequence":3257977196,"time":"2018-01-22T15:14:33.695000Z"}
{"type":"received","order_id":"1769ed4a-af7a-4e17-b26f-022fdf5b41c4","order_type":"limit","size":"0.00113335","price":"8823.35000000","side":"buy","client_oid":"f033bece-bbea-484f-bf34-0860e4b712f9","product_id":"BTC-EUR","sequence":3257977197,"time":"2018-01-22T15:14:33.701000Z"}
{"type":"open","side":"buy","price":"8823.35000000","order_id":"1769ed4a-af7a-4e17-b26f-022fdf5b41c4","remaining_size":"0.00113335","product_id":"BTC-EUR","sequence":3257977198,"time":"2018-01-22T15:14:33.701000Z"}
{"type":"done","side":"buy","order_id":"b226959a-4d09-4c21-9c5b-af480fe5a053","reason":"canceled","product_id":"BTC-EUR","price":"8823.34000000","remaining_size":"0.05000000","sequence":3257977199,"time":"2018-01-22T15:14:33.705000Z"}
{"type":"received","order_id":"78c0d1f9-8b2c-4de4-870e-21f9174c4ef3","order_type":"limit","size":"0.24800043","price":"8823.35000000","side":"buy","client_oid":"b64da870-b5f4-4870-922b-030a8a52030f","product_id":"BTC-EUR","sequence":3257977200,"time":"2018-01-22T15:14:33.710000Z"}
{"type":"open","side":"buy","price":"8823.35000000","order_id":"78c0d1f9-8b2c-4de4-870e-21f9174c4ef3","remaining_size":"0.24800043","product_id":"BTC-EUR","sequence":3257977201,"time":"2018-01-22T15:14:33.710000Z"}
{"type":"received","order_id":"23f3d908-3989-4110-8b69-83878c22cae9","order_type":"limit","size":"0.00113228","price":"8831.60000000","side":"sell","client_oid":"dc36333b-ebd4-4c73-af35-1b01ac23a73e","product_id":"BTC-EUR","sequence":3257977202,"time":"2018-01-22T15:14:33.724000Z"}
{"type":"open","side":"sell","price":"8831.60000000","order_id":"23f3d908-3989-4110-8b69-83878c22cae9","remaining_size":"0.00113228","product_id":"BTC-EUR","sequence":3257977203,"time":"2018-01-22T15:14:33.724000Z"}
{"type":"received","order_id":"076aaab3-5976-4b79-b009-80c27329ecee","order_type":"limit","size":"0.05000000","price":"8823.36000000","side":"buy","client_oid":"435a8644-04cc-4dc6-b0bd-c24836bf6d8a","product_id":"BTC-EUR","sequence":3257977204,"time":"2018-01-22T15:14:33.732000Z"}
{"type":"open","side":"buy","price":"8823.36000000","order_id":"076aaab3-5976-4b79-b009-80c27329ecee","remaining_size":"0.05000000","product_id":"BTC-EUR","sequence":3257977205,"time":"2018-01-22T15:14:33.732000Z"}
{"type":"done","side":"buy","order_id":"1769ed4a-af7a-4e17-b26f-022fdf5b41c4","reason":"canceled","product_id":"BTC-EUR","price":"8823.35000000","remaining_size":"0.00113335","sequence":3257977206,"time":"2018-01-22T15:14:33.751000Z"}
{"type":"received","order_id":"ed19ad3a-64e7-495d-ad51-d5acfe3898c1","order_type":"limit","size":"1.28000000","price":"9110.42000000","side":"sell","product_id":"BTC-EUR","sequence":3257977207,"time":"2018-01-22T15:14:33.755000Z"}
{"type":"open","side":"sell","price":"9110.42000000","order_id":"ed19ad3a-64e7-495d-ad51-d5acfe3898c1","remaining_size":"1.28000000","product_id":"BTC-EUR","sequence":3257977208,"time":"2018-01-22T15:14:33.755000Z"}
{"type":"done","side":"buy","order_id":"6ab11d81-755a-4831-8ce2-ae5c0247af2a","reason":"canceled","product_id":"BTC-EUR","price":"8823.34000000","remaining_size":"0.24800071","sequence":3257977209,"time":"2018-01-22T15:14:33.804000Z"}
{"type":"received","order_id":"29c5bb5f-5466-47a9-87ef-ce026b69270f","order_type":"limit","size":"0.21404538","price":"8831.60000000","side":"sell","product_id":"BTC-EUR","sequence":3257977210,"time":"2018-01-22T15:14:33.819000Z"}
{"type":"open","side":"sell","price":"8831.60000000","order_id":"29c5bb5f-5466-47a9-87ef-ce026b69270f","remaining_size":"0.21404538","product_id":"BTC-EUR","sequence":3257977211,"time":"2018-01-22T15:14:33.819000Z"}
{"type":"received","order_id":"ca78a021-f75c-4869-9c66-3a3f394aab04","order_type":"limit","size":"0.24800043","price":"8823.35000000","side":"buy","client_oid":"c3b1f565-2be0-4a5e-9c37-902a89a57d0d","product_id":"BTC-EUR","sequence":3257977212,"time":"2018-01-22T15:14:33.824000Z"}
{"type":"open","side":"buy","price":"8823.35000000","order_id":"ca78a021-f75c-4869-9c66-3a3f394aab04","remaining_size":"0.24800043","product_id":"BTC-EUR","sequence":3257977213,"time":"2018-01-22T15:14:33.824000Z"}
{"type":"received","order_id":"70faedb3-b686-409a-9433-56e73d28946c","order_type":"limit","size":"0.01586384","price":"8813.84000000","side":"buy","client_oid":"70dcbd3f-017d-4c47-8111-bf00f6254df7","product_id":"BTC-EUR","sequence":3257977214,"time":"2018-01-22T15:14:33.825000Z"}
{"type":"open","side":"buy","price":"8813.84000000","order_id":"70faedb3-b686-409a-9433-56e73d28946c","remaining_size":"0.01586384","product_id":"BTC-EUR","sequence":3257977215,"time":"2018-01-22T15:14:33.825000Z"}
{"type":"received","order_id":"8aa1590a-c71f-4231-86fa-246b4f4e6af8","order_type":"limit","size":"0.19762425","price":"8891.47000000","side":"sell","client_oid":"8f4c2cf8-400b-43b4-8391-ca2773301d61","product_id":"BTC-EUR","sequence":3257977216,"time":"2018-01-22T15:14:33.828000Z"}
{"type":"open","side":"sell","price":"8891.47000000","order_id":"8aa1590a-c71f-4231-86fa-246b4f4e6af8","remaining_size":"0.19762425","product_id":"BTC-EUR","sequence":3257977217,"time":"2018-01-22T15:14:33.828000Z"}
{"type":"received","order_id":"8acd45d4-601f-4587-b516-35f32290c911","order_type":"limit","size":"0.01586384","price":"8769.41000000","side":"buy","client_oid":"d86e667f-04da-4b0b-a78a-ee695d1d763d","product_id":"BTC-EUR","sequence":3257977218,"time":"2018-01-22T15:14:33.830000Z"}
{"type":"open","side":"buy","price":"8769.41000000","order_id":"8acd45d4-601f-4587-b516-35f32290c911","remaining_size":"0.01586384","product_id":"BTC-EUR","sequence":3257977219,"time":"2018-01-22T15:14:33.830000Z"}
{"type":"received","order_id":"d4e79519-a3d9-4dff-a654-7ab0c5583a81","order_type":"limit","size":"0.19762425","price":"8904.12000000","side":"sell","client_oid":"d6536f6b-ad88-4277-bbab-1beb92b512cb","product_id":"BTC-EUR","sequence":3257977220,"time":"2018-01-22T15:14:33.830000Z"}
{"type":"open","side":"sell","price":"8904.12000000","order_id":"d4e79519-a3d9-4dff-a654-7ab0c5583a81","remaining_size":"0.19762425","product_id":"BTC-EUR","sequence":3257977221,"time":"2018-01-22T15:14:33.830000Z"}
{"type":"done","side":"buy","order_id":"3ad21a40-c902-4823-b78c-03fb0790135a","reason":"canceled","product_id":"BTC-EUR","price":"8823.35000000","remaining_size":"0.24800043","sequence":3257977222,"time":"2018-01-22T15:14:33.832000Z"}
{"type":"received","order_id":"15bcc17c-621b-4424-a534-d278feddb4e0","order_type":"limit","size":"0.24800043","price":"8823.35000000","side":"buy","client_oid":"7de8e495-f69b-4d65-a604-664986694b43","product_id":"BTC-EUR","sequence":3257977223,"time":"2018-01-22T15:14:33.835000Z"}
{"type":"open","side":"buy","price":"8823.35000000","order_id":"15bcc17c-621b-4424-a534-d278feddb4e0","remaining_size":"0.24800043","product_id":"BTC-EUR","sequence":3257977224,"time":"2018-01-22T15:14:33.835000Z"}
{"type":"done","side":"sell","order_id":"23f3d908-3989-4110-8b69-83878c22cae9","reason":"canceled","product_id":"BTC-EUR","price":"8831.60000000","remaining_size":"0.00113228","sequence":3257977225,"time":"2018-01-22T15:14:33.837000Z"}
{"type":"received","order_id":"140db8a0-76ba-4d04-89a2-9435fcf81375","order_type":"limit","size":"0.19762425","price":"8915.60000000","side":"sell","client_oid":"555f334b-4438-4252-b420-28f2b9e52880","product_id":"BTC-EUR","sequence":3257977226,"time":"2018-01-22T15:14:33.846000Z"}
{"type":"open","side":"sell","price":"8915.60000000","order_id":"140db8a0-76ba-4d04-89a2-9435fcf81375","remaining_size":"0.19762425","product_id":"BTC-EUR","sequence":3257977227,"time":"2018-01-22T15:14:33.846000Z"}
{"type":"received","order_id":"63608d6a-51e9-482c-bd0d-fdd1ef146f63","order_type":"limit","size":"0.24800043","price":"8823.35000000","side":"buy","client_oid":"9e326292-cbe5-482c-9892-22dd4cc37137","product_id":"BTC-EUR","sequence":3257977228,"time":"2018-01-22T15:14:33.846000Z"}
{"type":"open","side":"buy","price":"8823.35000000","order_id":"63608d6a-51e9-482c-bd0d-fdd1ef146f63","remaining_size":"0.24800043","product_id":"BTC-EUR","sequence":3257977229,"time":"2018-01-22T15:14:33.846000Z"}
{"type":"done","side":"sell","order_id":"ca8e84f5-f7ec-408a-a10a-70ea321e0bd5","reason":"canceled","product_id":"BTC-EUR","price":"8848.76000000","remaining_size":"0.01887096","sequence":3257977230,"time":"2018-01-22T15:14:33.851000Z"}
{"type":"received","order_id":"e526149f-7abd-40d0-882d-86e78716c3b4","order_type":"limit","size":"0.01586384","price":"8724.99000000","side":"buy","client_oid":"9e61401b-767b-467a-a618-fca525365586","product_id":"BTC-EUR","sequence":3257977231,"time":"2018-01-22T15:14:33.865000Z"}
{"type":"open","side":"buy","price":"8724.99000000","order_id":"e526149f-7abd-40d0-882d-86e78716c3b4","remaining_size":"0.01586384","product_id":"BTC-EUR","sequence":3257977232,"time":"2018-01-22T15:14:33.865000Z"}
{"type":"received","order_id":"9a2718e2-b750-4bb6-80ac-37bb532ef09f","order_type":"limit","size":"0.01586384","price":"8680.56000000","side":"buy","client_oid":"c9a90c63-a0ee-471e-9c2f-1a7dc52303ad","product_id":"BTC-EUR","sequence":3257977233,"time":"2018-01-22T15:14:33.869000Z"}
{"type":"open","side":"buy","price":"8680.56000000","order_id":"9a2718e2-b750-4bb6-80ac-37bb532ef09f","remaining_size":"0.01586384","product_id":"BTC-EUR","sequence":3257977234,"time":"2018-01-22T15:14:33.869000Z"}
{"type":"received","order_id":"bdeaeab8-264b-41b5-bdd1-7e319e25c8f2","order_type":"limit","size":"0.10500000","price":"8831.60000000","side":"sell","client_oid":"0e83bd4c-a22e-4248-a8d1-118733004cd9","product_id":"BTC-EUR","sequence":3257977235,"time":"2018-01-22T15:14:33.894000Z"}
{"type":"open","side":"sell","price":"8831.60000000","order_id":"bdeaeab8-264b-41b5-bdd1-7e319e25c8f2","remaining_size":"0.10500000","product_id":"BTC-EUR","sequence":3257977236,"time":"2018-01-22T15:14:33.894000Z"}
{"type":"received","order_id":"2912a8ed-e018-4578-9c3a-352484a24238","order_type":"limit","size":"0.04164971","price":"8831.67000000","side":"sell","client_oid":"cb89790f-717c-44d8-b9a4-316f19145e47","product_id":"BTC-EUR","sequence":3257977237,"time":"2018-01-22T15:14:33.911000Z"}
{"type":"open","side":"sell","price":"8831.67000000","order_id":"2912a8ed-e018-4578-9c3a-352484a24238","remaining_size":"0.04164971","product_id":"BTC-EUR","sequence":3257977238,"time":"2018-01-22T15:14:33.911000Z"}
{"type":"received","order_id":"e378f5c6-83aa-4869-8b3a-0c9b5ed3dfd2","order_type":"limit","size":"0.00113335","price":"8823.36000000","side":"buy","client_oid":"787ccd90-adca-4fad-8ab7-7351403bacd5","product_id":"BTC-EUR","sequence":3257977239,"time":"2018-01-22T15:14:33.911000Z"}
{"type":"open","side":"buy","price":"8823.36000000","order_id":"e378f5c6-83aa-4869-8b3a-0c9b5ed3dfd2","remaining_size":"0.00113335","product_id":"BTC-EUR","sequence":3257977240,"time":"2018-01-22T15:14:33.911000Z"}
{"type":"done","side":"buy","order_id":"e378f5c6-83aa-4869-8b3a-0c9b5ed3dfd2","reason":"canceled","product_id":"BTC-EUR","price":"8823.36000000","remaining_size":"0.00113335","sequence":3257977241,"time":"2018-01-22T15:14:33.916000Z"}
{"type":"received","order_id":"22425d99-7029-42c7-b9d2-935dd9b0d7a8","order_type":"limit","size":"0.22947933","price":"8831.67000000","side":"sell","client_oid":"89ae53a7-b845-43a9-a344-4ed73cfe4338","product_id":"BTC-EUR","sequence":3257977242,"time":"2018-01-22T15:14:33.928000Z"}
{"type":"open","side":"sell","price":"8831.67000000","order_id":"22425d99-7029-42c7-b9d2-935dd9b0d7a8","remaining_size":"0.22947933","product_id":"BTC-EUR","sequence":3257977243,"time":"2018-01-22T15:14:33.928000Z"}
{"type":"received","order_id":"11267e55-10fc-4047-9e3a-aa241398c76d","order_type":"limit","size":"0.10500000","price":"8831.60000000","side":"sell","client_oid":"ec53f1ff-6be2-4dc2-afa7-af89578d603a","product_id":"BTC-EUR","sequence":3257977244,"time":"2018-01-22T15:14:33.938000Z"}
{"type":"open","side":"sell","price":"8831.60000000","order_id":"11267e55-10fc-4047-9e3a-aa241398c76d","remaining_size":"0.10500000","product_id":"BTC-EUR","sequence":3257977245,"time":"2018-01-22T15:14:33.938000Z"}
{"type":"received","order_id":"d8b55b08-d172-483f-9383-8f3957327fc3","order_type":"limit","size":"0.00113228","price":"8831.59000000","side":"sell","client_oid":"93df7e8f-b879-44d9-b279-b65d4fab1ca0","product_id":"BTC-EUR","sequence":3257977246,"time":"2018-01-22T15:14:33.957000Z"}
{"type":"open","side":"sell","price":"8831.59000000","order_id":"d8b55b08-d172-483f-9383-8f3957327fc3","remaining_size":"0.00113228","product_id":"BTC-EUR","sequence":3257977247,"time":"2018-01-22T15:14:33.957000Z"}
{"type":"done","side":"buy","order_id":"78c0d1f9-8b2c-4de4-870e-21f9174c4ef3","reason":"canceled","product_id":"BTC-EUR","price":"8823.35000000","remaining_size":"0.24800043","sequence":3257977248,"time":"2018-01-22T15:14:33.962000Z"}
{"type":"done","side":"sell","order_id":"bdeaeab8-264b-41b5-bdd1-7e319e25c8f2","reason":"canceled","product_id":"BTC-EUR","price":"8831.60000000","remaining_size":"0.10500000","sequence":3257977249,"time":"2018-01-22T15:14:33.976000Z"}
{"type":"received","order_id":"7414de08-466f-4c0d-b448-5283ea4c51e3","order_type":"limit","size":"0.24800015","price":"8823.36000000","side":"buy","client_oid":"f06583a8-d047-4537-a32e-510dfbf0c27e","product_id":"BTC-EUR","sequence":3257977250,"time":"2018-01-22T15:14:33.983000Z"}
{"type":"open","side":"buy","price":"8823.36000000","order_id":"7414de08-466f-4c0d-b448-5283ea4c51e3","remaining_size":"0.24800015","product_id":"BTC-EUR","sequence":3257977251,"time":"2018-01-22T15:14:33.983000Z"}
{"type":"received","order_id":"f9237f7b-5d56-4203-b90e-be0ffe7bd35d","order_type":"limit","size":"0.24799987","price":"8823.37000000","side":"buy","client_oid":"dcc8a8ba-b41e-406a-9c85-353403ef78ba","product_id":"BTC-EUR","sequence":3257977252,"time":"2018-01-22T15:14:33.985000Z"}
{"type":"open","side":"buy","price":"8823.37000000","order_id":"f9237f7b-5d56-4203-b90e-be0ffe7bd35d","remaining_size":"0.24799987","product_id":"BTC-EUR","sequence":3257977253,"time":"2018-01-22T15:14:33.985000Z"}
{"type":"received","order_id":"640e19f0-2e13-4dd3-98db-e35d7849c87c","order_type":"limit","size":"0.00113335","price":"8823.37000000","side":"buy","client_oid":"232ddaf4-4bc5-42ee-bdce-c2c4a177ad8c","product_id":"BTC-EUR","sequence":3257977254,"time":"2018-01-22T15:14:33.996000Z"}
{"type":"open","side":"buy","price":"8823.37000000","order_id":"640e19f0-2e13-4dd3-98db-e35d7849c87c","remaining_size":"0.00113335","product_id":"BTC-EUR","sequence":3257977255,"time":"2018-01-22T15:14:33.996000Z"}
{"type":"done","side":"buy","order_id":"076aaab3-5976-4b79-b009-80c27329ecee","reason":"canceled","product_id":"BTC-EUR","price":"8823.36000000","remaining_size":"0.05000000","sequence":3257977256,"time":"2018-01-22T15:14:34.001000Z"}
{"type":"received","order_id":"a02d521a-4f00-4659-9389-c927deeb9c08","order_type":"limit","size":"0.05000000","price":"8823.38000000","side":"buy","client_oid":"6d8c0e09-df71-4ee4-aed8-30c9799175ea","product_id":"BTC-EUR","sequence":3257977257,"time":"2018-01-22T15:14:34.018000Z"}
{"type":"open","side":"buy","price":"8823.38000000","order_id":"a02d521a-4f00-4659-9389-c927deeb9c08","remaining_size":"0.05000000","product_id":"BTC-EUR","sequence":3257977258,"time":"2018-01-22T15:14:34.018000Z"}
{"type":"received","order_id":"ef46484d-eeb8-4b7c-a7ac-083cdbbb1ee7","order_type":"limit","size":"0.10500000","price":"8831.60000000","side":"sell","client_oid":"16cea0a7-b86c-4c65-a27b-b03d792bb2a7","product_id":"BTC-EUR","sequence":3257977259,"time":"2018-01-22T15:14:34.021000Z"}
{"type":"open","side":"sell","price":"8831.60000000","order_id":"ef46484d-eeb8-4b7c-a7ac-083cdbbb1ee7","remaining_size":"0.10500000","product_id":"BTC-EUR","sequence":3257977260,"time":"2018-01-22T15:14:34.021000Z"}
{"type":"done","side":"buy","order_id":"640e19f0-2e13-4dd3-98db-e35d7849c87c","reason":"canceled","product_id":"BTC-EUR","price":"8823.37000000","remaining_size":"0.00113335","sequence":3257977261,"time":"2018-01-22T15:14:34.023000Z"}
{"type":"received","order_id":"85fae1d3-2ade-4cb2-841d-7d484633760c","order_type":"limit","size":"0.00113335","price":"8823.39000000","side":"buy","client_oid":"ddd88a4b-3e3c-4bf1-bcb9-2fbe253f095d","product_id":"BTC-EUR","sequence":3257977262,"time":"2018-01-22T15:14:34.047000Z"}
{"type":"open","side":"buy","price":"8823.39000000","order_id":"85fae1d3-2ade-4cb2-841d-7d484633760c","remaining_size":"0.00113335","product_id":"BTC-EUR","sequence":3257977263,"time":"2018-01-22T15:14:34.047000Z"}
{"type":"done","side":"sell","order_id":"11267e55-10fc-4047-9e3a-aa241398c76d","reason":"canceled","product_id":"BTC-EUR","price":"8831.60000000","remaining_size":"0.10500000","sequence":3257977264,"time":"2018-01-22T15:14:34.049000Z"}
{"type":"done","side":"sell","order_id":"dc5ce648-8233-4910-acea-00a47e9b6833","reason":"canceled","product_id":"BTC-EUR","price":"8848.78000000","remaining_size":"0.11241548","sequence":3257977265,"time":"2018-01-22T15:14:34.077000Z"}
{"type":"received","order_id":"2d9d06f6-6a78-45d7-a9bd-2e26838254a2","order_type":"limit","size":"0.09800000","price":"8831.58000000","side":"sell","client_oid":"3dac5571-fd42-4060-9483-331d9d099b0e","product_id":"BTC-EUR","sequence":3257977266,"time":"2018-01-22T15:14:34.084000Z"}
{"type":"open","side":"sell","price":"8831.58000000","order_id":"2d9d06f6-6a78-45d7-a9bd-2e26838254a2","remaining_size":"0.09800000","product_id":"BTC-EUR","sequence":3257977267,"time":"2018-01-22T15:14:34.084000Z"}
{"type":"received","order_id":"11655540-98de-4706-b842-e52aefc861a0","order_type":"limit","size":"0.09800000","price":"8831.58000000","side":"sell","client_oid":"e9ba781e-21d1-4cde-91a5-324c84f48cf1","product_id":"BTC-EUR","sequence":3257977268,"time":"2018-01-22T15:14:34.089000Z"}
{"type":"open","side":"sell","price":"8831.58000000","order_id":"11655540-98de-4706-b842-e52aefc861a0","remaining_size":"0.09800000","product_id":"BTC-EUR","sequence":3257977269,"time":"2018-01-22T15:14:34.089000Z"}
{"type":"done","side":"sell","order_id":"ef46484d-eeb8-4b7c-a7ac-083cdbbb1ee7","reason":"canceled","product_id":"BTC-EUR","price":"8831.60000000","remaining_size":"0.10500000","sequence":3257977270,"time":"2018-01-22T15:14:34.097000Z"}
{"type":"done","side":"sell","order_id":"d8b55b08-d172-483f-9383-8f3957327fc3","reason":"canceled","product_id":"BTC-EUR","price":"8831.59000000","remaining_size":"0.00113228","sequence":3257977271,"time":"2018-01-22T15:14:34.101000Z"}
{"type":"received","order_id":"610deb70-44e2-4f6a-9387-50c60025958b","order_type":"limit","size":"0.10500000","price":"8831.59000000","side":"sell","client_oid":"89aeafd8-48b5-48e7-aa1e-f848990c633a","product_id":"BTC-EUR","sequence":3257977272,"time":"2018-01-22T15:14:34.123000Z"}
{"type":"open","side":"sell","price":"8831.59000000","order_id":"610deb70-44e2-4f6a-9387-50c60025958b","remaining_size":"0.10500000","product_id":"BTC-EUR","sequence":3257977273,"time":"2018-01-22T15:14:34.123000Z"}
{"type":"done","side":"buy","order_id":"ca78a021-f75c-4869-9c66-3a3f394aab04","reason":"canceled","product_id":"BTC-EUR","price":"8823.35000000","remaining_size":"0.24800043","sequence":3257977274,"time":"2018-01-22T15:14:34.127000Z"}
{"type":"received","order_id":"aa08e3e5-7511-4a80-8d09-7e6ab1784983","order_type":"limit","size":"0.10500000","price":"8831.59000000","side":"sell","client_oid":"916f8a76-3a87-41ef-9dfc-258d36f477bc","product_id":"BTC-EUR","sequence":3257977275,"time":"2018-01-22T15:14:34.136000Z"}
{"type":"open","side":"sell","price":"8831.59000000","order_id":"aa08e3e5-7511-4a80-8d09-7e6ab1784983","remaining_size":"0.10500000","product_id":"BTC-EUR","sequence":3257977276,"time":"2018-01-22T15:14:34.136000Z"}
{"type":"received","order_id":"da20d4b4-3cf7-452f-8390-7611e689f008","order_type":"limit","size":"0.01887096","price":"8831.58000000","side":"sell","client_oid":"d4b81ab2-e6f5-4d71-b31b-936c3df5ca19","product_id":"BTC-EUR","sequence":3257977277,"time":"2018-01-22T15:14:34.205000Z"}
{"type":"open","side":"sell","price":"8831.58000000","order_id":"da20d4b4-3cf7-452f-8390-7611e689f008","remaining_size":"0.01887096","product_id":"BTC-EUR","sequence":3257977278,"time":"2018-01-22T15:14:34.205000Z"}
{"type":"done","side":"sell","order_id":"610deb70-44e2-4f6a-9387-50c60025958b","reason":"canceled","product_id":"BTC-EUR","price":"8831.59000000","remaining_size":"0.10500000","sequence":3257977279,"time":"2018-01-22T15:14:34.205000Z"}
{"type":"done","side":"sell","order_id":"aa08e3e5-7511-4a80-8d09-7e6ab1784983","reason":"canceled","product_id":"BTC-EUR","price":"8831.59000000","remaining_size":"0.10500000","sequence":3257977280,"time":"2018-01-22T15:14:34.223000Z"}
{"type":"done","side":"sell","order_id":"23d1fe9e-938b-4ea6-bb70-6d676d4ef808","reason":"canceled","product_id":"BTC-EUR","price":"8880.09000000","remaining_size":"0.45985469","sequence":3257977281,"time":"2018-01-22T15:14:34.246000Z"}
{"type":"received","order_id":"4330e968-89d0-4fae-9839-abc2f4ed2a73","order_type":"limit","size":"0.11241548","price":"8848.93000000","side":"sell","product_id":"BTC-EUR","sequence":3257977282,"time":"2018-01-22T15:14:34.288000Z"}
{"type":"open","side":"sell","price":"8848.93000000","order_id":"4330e968-89d0-4fae-9839-abc2f4ed2a73","remaining_size":"0.11241548","product_id":"BTC-EUR","sequence":3257977283,"time":"2018-01-22T15:14:34.288000Z"}
{"type":"received","order_id":"ac87e001-4a08-4ac6-98b6-bcd4dcfcf5c6","order_type":"limit","size":"0.00113228","price":"8831.57000000","side":"sell","client_oid":"8288941e-9fef-48f8-86c3-7f38a0d61a95","product_id":"BTC-EUR","sequence":3257977284,"time":"2018-01-22T15:14:34.291000Z"}
{"type":"open","side":"sell","price":"8831.57000000","order_id":"ac87e001-4a08-4ac6-98b6-bcd4dcfcf5c6","remaining_size":"0.00113228","product_id":"BTC-EUR","sequence":3257977285,"time":"2018-01-22T15:14:34.291000Z"}
{"type":"received","order_id":"066d2315-bb80-414d-8081-572aeb4c0495","order_type":"limit","size":"0.10500000","price":"8831.58000000","side":"sell","client_oid":"9c635554-ea83-4982-98df-e5483e5107b2","product_id":"BTC-EUR","sequence":3257977286,"time":"2018-01-22T15:14:34.320000Z"}
{"type":"open","side":"sell","price":"8831.58000000","order_id":"066d2315-bb80-414d-8081-572aeb4c0495","remaining_size":"0.10500000","product_id":"BTC-EUR","sequence":3257977287,"time":"2018-01-22T15:14:34.320000Z"}
{"type":"received","order_id":"d523933c-a047-4d20-a369-bbac4e3785bd","order_type":"limit","size":"0.18445930","price":"8855.18000000","side":"sell","client_oid":"0ca6683f-5574-4f49-ae5d-6aa6d8f68623","product_id":"BTC-EUR","sequence":3257977288,"time":"2018-01-22T15:14:34.334000Z"}
{"type":"open","side":"sell","price":"8855.18000000","order_id":"d523933c-a047-4d20-a369-bbac4e3785bd","remaining_size":"0.18445930","product_id":"BTC-EUR","sequence":3257977289,"time":"2018-01-22T15:14:34.334000Z"}
{"type":"done","side":"buy","order_id":"6d7beff6-9373-4de1-b542-1d2cd607b7b8","reason":"canceled","product_id":"BTC-EUR","price":"8809.85000000","remaining_size":"0.46352090","sequence":3257977290,"time":"2018-01-22T15:14:34.356000Z"}
{"type":"received","order_id":"67be2a14-8d2a-4790-8d38-3508031c4522","order_type":"limit","size":"0.18517661","price":"8820.88000000","side":"buy","client_oid":"8f06b08f-a566-445e-b391-23322f1792b4","product_id":"BTC-EUR","sequence":3257977291,"time":"2018-01-22T15:14:34.360000Z"}
{"type":"open","side":"buy","price":"8820.88000000","order_id":"67be2a14-8d2a-4790-8d38-3508031c4522","remaining_size":"0.18517661","product_id":"BTC-EUR","sequence":3257977292,"time":"2018-01-22T15:14:34.360000Z"}
{"type":"done","side":"sell","order_id":"11655540-98de-4706-b842-e52aefc861a0","reason":"canceled","product_id":"BTC-EUR","price":"8831.58000000","remaining_size":"0.09800000","sequence":3257977293,"time":"2018-01-22T15:14:34.379000Z"}
{"type":"done","side":"sell","order_id":"066d2315-bb80-414d-8081-572aeb4c0495","reason":"canceled","product_id":"BTC-EUR","price":"8831.58000000","remaining_size":"0.10500000","sequence":3257977294,"time":"2018-01-22T15:14:34.400000Z"}
{"type":"done","side":"sell","order_id":"2d9d06f6-6a78-45d7-a9bd-2e26838254a2","reason":"canceled","product_id":"BTC-EUR","price":"8831.58000000","remaining_size":"0.09800000","sequence":3257977295,"time":"2018-01-22T15:14:34.403000Z"}
{"type":"done","side":"sell","order_id":"29c5bb5f-5466-47a9-87ef-ce026b69270f","reason":"canceled","product_id":"BTC-EUR","price":"8831.60000000","remaining_size":"0.21404538","sequence":3257977296,"time":"2018-01-22T15:14:34.414000Z"}
{"type":"received","order_id":"c4ccc039-a604-4231-9be2-2536b0933ef2","order_type":"limit","size":"0.09800000","price":"8831.56000000","side":"sell","client_oid":"86ded71b-0cb8-4d45-83b8-6cb95edcc1fa","product_id":"BTC-EUR","sequence":3257977297,"time":"2018-01-22T15:14:34.422000Z"}
{"type":"open","side":"sell","price":"8831.56000000","order_id":"c4ccc039-a604-4231-9be2-2536b0933ef2","remaining_size":"0.09800000","product_id":"BTC-EUR","sequence":3257977298,"time":"2018-01-22T15:14:34.422000Z"}
{"type":"received","order_id":"b8510c23-a7bd-4c84-928b-b288a52990c0","order_type":"limit","size":"0.10500000","price":"8831.57000000","side":"sell","client_oid":"bbed3250-950b-48b5-8601-e9b19886261c","product_id":"BTC-EUR","sequence":3257977299,"time":"2018-01-22T15:14:34.434000Z"}
{"type":"open","side":"sell","price":"8831.57000000","order_id":"b8510c23-a7bd-4c84-928b-b288a52990c0","remaining_size":"0.10500000","product_id":"BTC-EUR","sequence":3257977300,"time":"2018-01-22T15:14:34.434000Z"}
{"type":"done","side":"sell","order_id":"ac87e001-4a08-4ac6-98b6-bcd4dcfcf5c6","reason":"canceled","product_id":"BTC-EUR","price":"8831.57000000","remaining_size":"0.00113228","sequence":3257977301,"time":"2018-01-22T15:14:34.455000Z"}
{"type":"done","side":"sell","order_id":"754c5020-a9ec-41c5-8db8-07c3fe16bca5","reason":"canceled","product_id":"BTC-EUR","price":"8860.57000000","remaining_size":"0.06675000","sequence":3257977302,"time":"2018-01-22T15:14:34.476000Z"}
{"type":"received","order_id":"c7eccc34-a3ac-465d-9625-05983d93da7e","order_type":"limit","size":"0.10500000","price":"8831.57000000","side":"sell","client_oid":"9caa5a42-64c4-4331-8ef6-8f708e5f32fe","product_id":"BTC-EUR","sequence":3257977303,"time":"2018-01-22T15:14:34.491000Z"}
{"type":"open","side":"sell","price":"8831.57000000","order_id":"c7eccc34-a3ac-465d-9625-05983d93da7e","remaining_size":"0.10500000","product_id":"BTC-EUR","sequence":3257977304,"time":"2018-01-22T15:14:34.491000Z"}
{"type":"done","side":"sell","order_id":"b8510c23-a7bd-4c84-928b-b288a52990c0","reason":"canceled","product_id":"BTC-EUR","price":"8831.57000000","remaining_size":"0.10500000","sequence":3257977305,"time":"2018-01-22T15:14:34.513000Z"}
{"type":"received","order_id":"a414f63f-ac1d-4a46-b5e1-135ecefe2a99","order_type":"limit","size":"0.09800000","price":"8831.55000000","side":"sell","client_oid":"9d490926-468a-4f18-9005-763ffd8564b3","product_id":"BTC-EUR","sequence":3257977306,"time":"2018-01-22T15:14:34.540000Z"}
{"type":"open","side":"sell","price":"8831.55000000","order_id":"a414f63f-ac1d-4a46-b5e1-135ecefe2a99","remaining_size":"0.09800000","product_id":"BTC-EUR","sequence":3257977307,"time":"2018-01-22T15:14:34.540000Z"}
{"type":"received","order_id":"185ee7b1-594d-4c72-8b98-2408cf7455ec","order_type":"limit","size":"0.00200000","price":"8831.55000000","side":"sell","client_oid":"bac47bc3-7cb2-4075-8f50-03ede3601b0b","product_id":"BTC-EUR","sequence":3257977308,"time":"2018-01-22T15:14:34.545000Z"}
{"type":"open","side":"sell","price":"8831.55000000","order_id":"185ee7b1-594d-4c72-8b98-2408cf7455ec","remaining_size":"0.00200000","product_id":"BTC-EUR","sequence":3257977309,"time":"2018-01-22T15:14:34.545000Z"}
{"type":"received","order_id":"6941b6b4-3e8c-41b5-991a-fa528f47e973","order_type":"limit","size":"0.02000000","price":"9096.64000000","side":"buy","product_id":"BTC-EUR","sequence":3257977310,"time":"2018-01-22T15:14:34.558000Z"}
{"type":"match","trade_id":10551361,"maker_order_id":"a414f63f-ac1d-4a46-b5e1-135ecefe2a99","taker_order_id":"6941b6b4-3e8c-41b5-991a-fa528f47e973","side":"sell","size":"0.02000000","price":"8831.55000000","product_id":"BTC-EUR","sequence":3257977311,"time":"2018-01-22T15:14:34.558000Z"}
{"type":"done","side":"buy","order_id":"6941b6b4-3e8c-41b5-991a-fa528f47e973","reason":"filled","product_id":"BTC-EUR","price":"9096.64000000","remaining_size":"0.00000000","sequence":3257977312,"time":"2018-01-22T15:14:34.558000Z"}
{"type":"received","order_id":"df121a64-b0c8-432e-9eea-f8747e8225a1","order_type":"limit","size":"19.17998894","price":"7286.45000000","side":"buy","product_id":"BTC-EUR","sequence":3257977313,"time":"2018-01-22T15:14:34.560000Z"}
{"type":"open","side":"buy","price":"7286.45000000","order_id":"df121a64-b0c8-432e-9eea-f8747e8225a1","remaining_size":"19.17998894","product_id":"BTC-EUR","sequence":3257977314,"time":"2018-01-22T15:14:34.560000Z"}
{"type":"received","order_id":"acb7c29f-800f-4889-ba5e-c037f10c2914","order_type":"limit","size":"0.10500000","price":"8831.56000000","side":"sell","client_oid":"88ea9aef-e3d6-49da-adf8-41d890c87ad9","product_id":"BTC-EUR","sequence":3257977315,"time":"2018-01-22T15:14:34.563000Z"}
{"type":"open","side":"sell","price":"8831.56000000","order_id":"acb7c29f-800f-4889-ba5e-c037f10c2914","remaining_size":"0.10500000","product_id":"BTC-EUR","sequence":3257977316,"time":"2018-01-22T15:14:34.563000Z"}
{"type":"received","order_id":"66f7b08b-04c6-4ebf-a5a5-80a45ee5368d","order_type":"limit","size":"0.00113228","price":"8831.55000000","side":"sell","client_oid":"1ba21712-92fd-4b76-8e96-b984c94a177f","product_id":"BTC-EUR","sequence":3257977317,"time":"2018-01-22T15:14:34.605000Z"}
{"type":"open","side":"sell","price":"8831.55000000","order_id":"66f7b08b-04c6-4ebf-a5a5-80a45ee5368d","remaining_size":"0.00113228","product_id":"BTC-EUR","sequence":3257977318,"time":"2018-01-22T15:14:34.605000Z"}
{"type":"done","side":"sell","order_id":"c7eccc34-a3ac-465d-9625-05983d93da7e","reason":"canceled","product_id":"BTC-EUR","price":"8831.57000000","remaining_size":"0.10500000","sequence":3257977319,"time":"2018-01-22T15:14:34.619000Z"}
{"type":"done","side":"sell","order_id":"c4ccc039-a604-4231-9be2-2536b0933ef2","reason":"canceled","product_id":"BTC-EUR","price":"8831.56000000","remaining_size":"0.09800000","sequence":3257977320,"time":"2018-01-22T15:14:34.620000Z"}
{"type":"done","side":"sell","order_id":"22425d99-7029-42c7-b9d2-935dd9b0d7a8","reason":"canceled","product_id":"BTC-EUR","price":"8831.67000000","remaining_size":"0.22947933","sequence":3257977321,"time":"2018-01-22T15:14:34.636000Z"}
{"type":"received","order_id":"92138cbb-002e-415e-b55a-c3b37c046faf","order_type":"limit","size":"0.09800000","price":"8831.54000000","side":"sell","client_oid":"cc639125-75c6-4f20-bdcd-9a323c21ff56","product_id":"BTC-EUR","sequence":3257977322,"time":"2018-01-22T15:14:34.643000Z"}
{"type":"open","side":"sell","price":"8831.54000000","order_id":"92138cbb-002e-415e-b55a-c3b37c046faf","remaining_size":"0.09800000","product_id":"BTC-EUR","sequence":3257977323,"time":"2018-01-22T15:14:34.643000Z"}
{"type":"done","side":"sell","order_id":"acb7c29f-800f-4889-ba5e-c037f10c2914","reason":"canceled","product_id":"BTC-EUR","price":"8831.56000000","remaining_size":"0.10500000","sequence":3257977324,"time":"2018-01-22T15:14:34.648000Z"}
{"type":"done","side":"sell","order_id":"66f7b08b-04c6-4ebf-a5a5-80a45ee5368d","reason":"canceled","product_id":"BTC-EUR","price":"8831.55000000","remaining_size":"0.00113228","sequence":3257977325,"time":"2018-01-22T15:14:34.653000Z"}
{"type":"received","order_id":"be1cc6d8-a2f1-4e5a-b252-f6ff1d190973","order_type":"limit","size":"0.06675000","price":"8860.56000000","side":"sell","product_id":"BTC-EUR","sequence":3257977326,"time":"2018-01-22T15:14:34.669000Z"}
{"type":"open","side":"sell","price":"8860.56000000","order_id":"be1cc6d8-a2f1-4e5a-b252-f6ff1d190973","remaining_size":"0.06675000","product_id":"BTC-EUR","sequence":3257977327,"time":"2018-01-22T15:14:34.669000Z"}
{"type":"done","side":"sell","order_id":"2912a8ed-e018-4578-9c3a-352484a24238","reason":"canceled","product_id":"BTC-EUR","price":"8831.67000000","remaining_size":"0.04164971","sequence":3257977328,"time":"2018-01-22T15:14:34.670000Z"}
{"type":"done","side":"sell","order_id":"d523933c-a047-4d20-a369-bbac4e3785bd","reason":"canceled","product_id":"BTC-EUR","price":"8855.18000000","remaining_size":"0.18445930","sequence":3257977329,"time":"2018-01-22T15:14:34.700000Z"}
{"type":"done","side":"sell","order_id":"a414f63f-ac1d-4a46-b5e1-135ecefe2a99","reason":"canceled","product_id":"BTC-EUR","price":"8831.55000000","remaining_size":"0.07800000","sequence":3257977330,"time":"2018-01-22T15:14:34.721000Z"}
{"type":"received","order_id":"af21e679-fe3e-4e3c-b5d8-e7b3e57567b2","order_type":"limit","size":"0.00113228","price":"8831.53000000","side":"sell","client_oid":"233ddd2c-7e73-4f25-8fee-5257e1169761","product_id":"BTC-EUR","sequence":3257977331,"time":"2018-01-22T15:14:34.724000Z"}
{"type":"open","side":"sell","price":"8831.53000000","order_id":"af21e679-fe3e-4e3c-b5d8-e7b3e57567b2","remaining_size":"0.00113228","product_id":"BTC-EUR","sequence":3257977332,"time":"2018-01-22T15:14:34.724000Z"}
{"type":"done","side":"sell","order_id":"185ee7b1-594d-4c72-8b98-2408cf7455ec","reason":"canceled","product_id":"BTC-EUR","price":"8831.55000000","remaining_size":"0.00200000","sequence":3257977333,"time":"2018-01-22T15:14:34.763000Z"}
{"type":"received","order_id":"8fb45f9f-e404-4589-bd31-e0da67c2796b","order_type":"limit","size":"0.10500000","price":"8831.55000000","side":"sell","client_oid":"1493a245-d14e-4726-b1f5-4e500fb3204e","product_id":"BTC-EUR","sequence":3257977334,"time":"2018-01-22T15:14:34.777000Z"}
{"type":"open","side":"sell","price":"8831.55000000","order_id":"8fb45f9f-e404-4589-bd31-e0da67c2796b","remaining_size":"0.10500000","product_id":"BTC-EUR","sequence":3257977335,"time":"2018-01-22T15:14:34.777000Z"}
{"type":"done","side":"sell","order_id":"8fb45f9f-e404-4589-bd31-e0da67c2796b","reason":"canceled","product_id":"BTC-EUR","price":"8831.55000000","remaining_size":"0.10500000","sequence":3257977336,"time":"2018-01-22T15:14:34.860000Z"}
{"type":"done","side":"sell","order_id":"92138cbb-002e-415e-b55a-c3b37c046faf","reason":"canceled","product_id":"BTC-EUR","price":"8831.54000000","remaining_size":"0.09800000","sequence":3257977337,"time":"2018-01-22T15:14:34.863000Z"}
{"type":"done","side":"buy","order_id":"15bcc17c-621b-4424-a534-d278feddb4e0","reason":"canceled","product_id":"BTC-EUR","price":"8823.35000000","remaining_size":"0.24800043","sequence":3257977338,"time":"2018-01-22T15:14:34.864000Z"}
{"type":"received","order_id":"5bf9da75-18ab-46db-bb33-06c63a9107d9","order_type":"limit","size":"0.22947933","price":"8831.53000000","side":"sell","client_oid":"619705a4-6fe1-4014-9685-e91634332237","product_id":"BTC-EUR","sequence":3257977339,"time":"2018-01-22T15:14:34.867000Z"}
{"type":"open","side":"sell","price":"8831.53000000","order_id":"5bf9da75-18ab-46db-bb33-06c63a9107d9","remaining_size":"0.22947933","product_id":"BTC-EUR","sequence":3257977340,"time":"2018-01-22T15:14:34.867000Z"}
{"type":"done","side":"buy","order_id":"63608d6a-51e9-482c-bd0d-fdd1ef146f63","reason":"canceled","product_id":"BTC-EUR","price":"8823.35000000","remaining_size":"0.24800043","sequence":3257977341,"time":"2018-01-22T15:14:34.873000Z"}
{"type":"done","side":"buy","order_id":"7414de08-466f-4c0d-b448-5283ea4c51e3","reason":"canceled","product_id":"BTC-EUR","price":"8823.36000000","remaining_size":"0.24800015","sequence":3257977342,"time":"2018-01-22T15:14:34.874000Z"}
{"type":"done","side":"buy","order_id":"388d3934-6920-492d-a8c4-4f278e7e2c17","reason":"canceled","product_id":"BTC-EUR","price":"8654.40000000","remaining_size":"1.89573000","sequence":3257977343,"time":"2018-01-22T15:14:34.876000Z"}
{"type":"done","side":"buy","order_id":"f9237f7b-5d56-4203-b90e-be0ffe7bd35d","reason":"canceled","product_id":"BTC-EUR","price":"8823.37000000","remaining_size":"0.24799987","sequence":3257977344,"time":"2018-01-22T15:14:34.878000Z"}
{"type":"received","order_id":"c980a88b-e036-4a4a-93da-f50aa914ca12","order_type":"limit","size":"0.09800000","price":"8831.53000000","side":"sell","client_oid":"f4786770-13ad-4a59-ac9c-3930ede30464","product_id":"BTC-EUR","sequence":3257977345,"time":"2018-01-22T15:14:34.879000Z"}
{"type":"open","side":"sell","price":"8831.53000000","order_id":"c980a88b-e036-4a4a-93da-f50aa914ca12","remaining_size":"0.09800000","product_id":"BTC-EUR","sequence":3257977346,"time":"2018-01-22T15:14:34.879000Z"}
{"type":"received","order_id":"c87f56d7-e1f8-46d7-b07d-ad00a8284087","order_type":"limit","size":"0.04164971","price":"8831.52000000","side":"sell","client_oid":"111b9ee3-d7ab-4be5-88cf-b5fedaea0f51","product_id":"BTC-EUR","sequence":3257977347,"time":"2018-01-22T15:14:34.882000Z"}
{"type":"open","side":"sell","price":"8831.52000000","order_id":"c87f56d7-e1f8-46d7-b07d-ad00a8284087","remaining_size":"0.04164971","product_id":"BTC-EUR","sequence":3257977348,"time":"2018-01-22T15:14:34.882000Z"}
{"type":"done","side":"sell","order_id":"40e67c7f-241d-4afb-97ba-8800c724a4e0","reason":"canceled","product_id":"BTC-EUR","price":"8915.61000000","remaining_size":"0.06675000","sequence":3257977349,"time":"2018-01-22T15:14:34.886000Z"}
{"type":"received","order_id":"0d3fede6-ff1b-4fe9-b558-0ce92414e7ab","order_type":"limit","size":"1.89520000","price":"8656.50000000","side":"buy","client_oid":"0e1026f6-047c-4fe0-98dc-b7464df427ae","product_id":"BTC-EUR","sequence":3257977350,"time":"2018-01-22T15:14:34.890000Z"}
{"type":"open","side":"buy","price":"8656.50000000","order_id":"0d3fede6-ff1b-4fe9-b558-0ce92414e7ab","remaining_size":"1.89520000","product_id":"BTC-EUR","sequence":3257977351,"time":"2018-01-22T15:14:34.890000Z"}
{"type":"done","side":"sell","order_id":"af21e679-fe3e-4e3c-b5d8-e7b3e57567b2","reason":"canceled","product_id":"BTC-EUR","price":"8831.53000000","remaining_size":"0.00113228","sequence":3257977352,"time":"2018-01-22T15:14:34.894000Z"}
{"type":"received","order_id":"5480cb4d-6fd0-49d1-a806-e262ece1aea9","order_type":"limit","size":"0.09800000","price":"8831.52000000","side":"sell","client_oid":"c5c68d3d-d6c3-42dd-8385-2148033b1c6f","product_id":"BTC-EUR","sequence":3257977353,"time":"2018-01-22T15:14:34.896000Z"}
{"type":"open","side":"sell","price":"8831.52000000","order_id":"5480cb4d-6fd0-49d1-a806-e262ece1aea9","remaining_size":"0.09800000","product_id":"BTC-EUR","sequence":3257977354,"time":"2018-01-22T15:14:34.896000Z"}
{"type":"done","side":"buy","order_id":"a02d521a-4f00-4659-9389-c927deeb9c08","reason":"canceled","product_id":"BTC-EUR","price":"8823.38000000","remaining_size":"0.05000000","sequence":3257977355,"time":"2018-01-22T15:14:34.899000Z"}
{"type":"received","order_id":"f2066f22-2b4d-4303-ade0-efd4fc04c64f","order_type":"limit","size":"0.24799959","price":"8823.38000000","side":"buy","client_oid":"350ecac7-3e3c-4508-9228-ab8ac2a0fc6e","product_id":"BTC-EUR","sequence":3257977356,"time":"2018-01-22T15:14:34.914000Z"}
{"type":"open","side":"buy","price":"8823.38000000","order_id":"f2066f22-2b4d-4303-ade0-efd4fc04c64f","remaining_size":"0.24799959","product_id":"BTC-EUR","sequence":3257977357,"time":"2018-01-22T15:14:34.914000Z"}
{"type":"received","order_id":"7210732d-e3e5-4f8d-8eba-c4945b7a66b3","order_type":"limit","size":"0.24799931","price":"8823.39000000","side":"buy","client_oid":"afefa342-8bcf-4add-8fe5-fbc0095d57c2","product_id":"BTC-EUR","sequence":3257977358,"time":"2018-01-22T15:14:34.915000Z"}
{"type":"open","side":"buy","price":"8823.39000000","order_id":"7210732d-e3e5-4f8d-8eba-c4945b7a66b3","remaining_size":"0.24799931","product_id":"BTC-EUR","sequence":3257977359,"time":"2018-01-22T15:14:34.915000Z"}
{"type":"done","side":"sell","order_id":"da20d4b4-3cf7-452f-8390-7611e689f008","reason":"canceled","product_id":"BTC-EUR","price":"8831.58000000","remaining_size":"0.01887096","sequence":3257977360,"time":"2018-01-22T15:14:34.928000Z"}
{"type":"received","order_id":"4f50b5f9-db9e-4ddc-8733-57a9b38e0c34","order_type":"limit","size":"0.00113228","price":"8831.51000000","side":"sell","client_oid":"ed56b274-1eed-4dd1-8e11-89b3e6057bff","product_id":"BTC-EUR","sequence":3257977361,"time":"2018-01-22T15:14:34.947000Z"}
{"type":"open","side":"sell","price":"8831.51000000","order_id":"4f50b5f9-db9e-4ddc-8733-57a9b38e0c34","remaining_size":"0.00113228","product_id":"BTC-EUR","sequence":3257977362,"time":"2018-01-22T15:14:34.947000Z"}
{"type":"received","order_id":"1935c5aa-6729-4929-b8ab-db3f80143453","order_type":"limit","size":"0.24799903","price":"8823.40000000","side":"buy","client_oid":"2bbeb395-6e67-4410-8753-eaaffb265a84","product_id":"BTC-EUR","sequence":3257977363,"time":"2018-01-22T15:14:34.947000Z"}
{"type":"open","side":"buy","price":"8823.40000000","order_id":"1935c5aa-6729-4929-b8ab-db3f80143453","remaining_size":"0.24799903","product_id":"BTC-EUR","sequence":3257977364,"time":"2018-01-22T15:14:34.947000Z"}
{"type":"received","order_id":"b47ee226-6a31-40bd-81ce-2b142652f973","order_type":"limit","size":"0.11066184","price":"8831.69000000","side":"sell","client_oid":"ebbd4dac-4ba9-4145-df52-36209bd362d6","product_id":"BTC-EUR","sequence":3257977365,"time":"2018-01-22T15:14:34.948000Z"}
{"type":"open","side":"sell","price":"8831.69000000","order_id":"b47ee226-6a31-40bd-81ce-2b142652f973","remaining_size":"0.11066184","product_id":"BTC-EUR","sequence":3257977366,"time":"2018-01-22T15:14:34.948000Z"}
{"type":"received","order_id":"969f9755-6210-4538-9614-8bea67f7e206","order_type":"limit","size":"0.05000000","price":"8823.39000000","side":"buy","client_oid":"6f079866-0b74-4956-b2a5-004b99fd0234","product_id":"BTC-EUR","sequence":3257977367,"time":"2018-01-22T15:14:34.949000Z"}
{"type":"open","side":"buy","price":"8823.39000000","order_id":"969f9755-6210-4538-9614-8bea67f7e206","remaining_size":"0.05000000","product_id":"BTC-EUR","sequence":3257977368,"time":"2018-01-22T15:14:34.949000Z"}
{"type":"received","order_id":"50c4504b-93ba-4e19-946f-6773ea4dbc10","order_type":"limit","size":"0.10500000","price":"8831.53000000","side":"sell","client_oid":"3b1b6a4a-cb5b-499c-b912-c64b96087f2a","product_id":"BTC-EUR","sequence":3257977369,"time":"2018-01-22T15:14:34.951000Z"}
{"type":"open","side":"sell","price":"8831.53000000","order_id":"50c4504b-93ba-4e19-946f-6773ea4dbc10","remaining_size":"0.10500000","product_id":"BTC-EUR","sequence":3257977370,"time":"2018-01-22T15:14:34.951000Z"}
{"type":"received","order_id":"513068cf-bac0-408d-8187-7c9837afebc1","order_type":"limit","size":"0.24799903","price":"8823.40000000","side":"buy","client_oid":"af4fd1b4-e683-42ee-9b25-86a050198d23","product_id":"BTC-EUR","sequence":3257977371,"time":"2018-01-22T15:14:34.956000Z"}
{"type":"open","side":"buy","price":"8823.40000000","order_id":"513068cf-bac0-408d-8187-7c9837afebc1","remaining_size":"0.24799903","product_id":"BTC-EUR","sequence":3257977372,"time":"2018-01-22T15:14:34.956000Z"}
{"type":"done","side":"buy","order_id":"969f9755-6210-4538-9614-8bea67f7e206","reason":"canceled","product_id":"BTC-EUR","price":"8823.39000000","remaining_size":"0.05000000","sequence":3257977373,"time":"2018-01-22T15:14:34.956000Z"}
{"type":"received","order_id":"18299145-ffcd-47ec-941e-809d2b42fde9","order_type":"limit","size":"0.24799903","price":"8823.40000000","side":"buy","client_oid":"76802565-d776-4648-93b9-0c407a916651","product_id":"BTC-EUR","sequence":3257977374,"time":"2018-01-22T15:14:34.964000Z"}
{"type":"open","side":"buy","price":"8823.40000000","order_id":"18299145-ffcd-47ec-941e-809d2b42fde9","remaining_size":"0.24799903","product_id":"BTC-EUR","sequence":3257977375,"time":"2018-01-22T15:14:34.964000Z"}
{"type":"done","side":"sell","order_id":"c980a88b-e036-4a4a-93da-f50aa914ca12","reason":"canceled","product_id":"BTC-EUR","price":"8831.53000000","remaining_size":"0.09800000","sequence":3257977376,"time":"2018-01-22T15:14:34.996000Z"}
{"type":"done","side":"buy","order_id":"85fae1d3-2ade-4cb2-841d-7d484633760c","reason":"canceled","product_id":"BTC-EUR","price":"8823.39000000","remaining_size":"0.00113335","sequence":3257977377,"time":"2018-01-22T15:14:34.996000Z"}
{"type":"received","order_id":"1e55dd5a-97a6-4f6f-b62c-eb5f74197a6e","order_type":"limit","size":"0.46038396","price":"8869.88000000","side":"sell","client_oid":"1d5ca5d2-eaf6-4f09-9e14-08b62edd01ad","product_id":"BTC-EUR","sequence":3257977378,"time":"2018-01-22T15:14:34.997000Z"}
{"type":"open","side":"sell","price":"8869.88000000","order_id":"1e55dd5a-97a6-4f6f-b62c-eb5f74197a6e","remaining_size":"0.46038396","product_id":"BTC-EUR","sequence":3257977379,"time":"2018-01-22T15:14:34.997000Z"}
{"type":"received","order_id":"16bc8a98-9b5f-45ba-93df-0a45487c7ff0","order_type":"limit","size":"0.05000000","price":"8823.41000000","side":"buy","client_oid":"79af5bb7-d6e6-496f-b7be-8e5c5a05e6d7","product_id":"BTC-EUR","sequence":3257977380,"time":"2018-01-22T15:14:35.001000Z"}
{"type":"open","side":"buy","price":"8823.41000000","order_id":"16bc8a98-9b5f-45ba-93df-0a45487c7ff0","remaining_size":"0.05000000","product_id":"BTC-EUR","sequence":3257977381,"time":"2018-01-22T15:14:35.001000Z"}
{"type":"received","order_id":"eeb5d019-097a-4da1-8975-a7ab5f8b2c9c","order_type":"limit","size":"0.21404538","price":"8831.54000000","side":"sell","product_id":"BTC-EUR","sequence":3257977382,"time":"2018-01-22T15:14:35.021000Z"}
{"type":"open","side":"sell","price":"8831.54000000","order_id":"eeb5d019-097a-4da1-8975-a7ab5f8b2c9c","remaining_size":"0.21404538","product_id":"BTC-EUR","sequence":3257977383,"time":"2018-01-22T15:14:35.021000Z"}
{"type":"done","side":"sell","order_id":"5480cb4d-6fd0-49d1-a806-e262ece1aea9","reason":"canceled","product_id":"BTC-EUR","price":"8831.52000000","remaining_size":"0.09800000","sequence":3257977384,"time":"2018-01-22T15:14:35.030000Z"}
{"type":"received","order_id":"b2915a41-fd0a-4f5e-9bcd-774ce061a2dc","order_type":"limit","size":"0.09800000","price":"8831.51000000","side":"sell","client_oid":"7fc51213-6eaf-4d51-8807-67d5c51a71e4","product_id":"BTC-EUR","sequence":3257977385,"time":"2018-01-22T15:14:35.033000Z"}
{"type":"open","side":"sell","price":"8831.51000000","order_id":"b2915a41-fd0a-4f5e-9bcd-774ce061a2dc","remaining_size":"0.09800000","product_id":"BTC-EUR","sequence":3257977386,"time":"2018-01-22T15:14:35.033000Z"}
{"type":"received","order_id":"7717ce4b-b779-4bc1-aeba-1ac0ad1f7211","order_type":"limit","size":"0.00113334","price":"8823.41000000","side":"buy","client_oid":"098eec6f-a66b-47ca-b8de-b9965a57ced1","product_id":"BTC-EUR","sequence":3257977387,"time":"2018-01-22T15:14:35.063000Z"}
{"type":"open","side":"buy","price":"8823.41000000","order_id":"7717ce4b-b779-4bc1-aeba-1ac0ad1f7211","remaining_size":"0.00113334","product_id":"BTC-EUR","sequence":3257977388,"time":"2018-01-22T15:14:35.063000Z"}
{"type":"received","order_id":"7e2b3ee7-25f2-4a14-9f2f-fea60d6609ad","order_type":"limit","size":"0.06675000","price":"8915.59000000","side":"sell","product_id":"BTC-EUR","sequence":3257977389,"time":"2018-01-22T15:14:35.066000Z"}
{"type":"open","side":"sell","price":"8915.59000000","order_id":"7e2b3ee7-25f2-4a14-9f2f-fea60d6609ad","remaining_size":"0.06675000","product_id":"BTC-EUR","sequence":3257977390,"time":"2018-01-22T15:14:35.066000Z"}
{"type":"done","side":"sell","order_id":"50c4504b-93ba-4e19-946f-6773ea4dbc10","reason":"canceled","product_id":"BTC-EUR","price":"8831.53000000","remaining_size":"0.10500000","sequence":3257977391,"time":"2018-01-22T15:14:35.069000Z"}
{"type":"received","order_id":"376ad122-abcc-42d9-b5f9-b0e85295d094","order_type":"limit","size":"0.10500000","price":"8831.51000000","side":"sell","client_oid":"9a282135-3b8e-4add-90dc-987bb5445b80","product_id":"BTC-EUR","sequence":3257977392,"time":"2018-01-22T15:14:35.097000Z"}
{"type":"open","side":"sell","price":"8831.51000000","order_id":"376ad122-abcc-42d9-b5f9-b0e85295d094","remaining_size":"0.10500000","product_id":"BTC-EUR","sequence":3257977393,"time":"2018-01-22T15:14:35.097000Z"}
{"type":"received","order_id":"2a9ea768-2595-4ea2-b98c-25d6bccc55e9","order_type":"limit","size":"0.10500000","price":"8831.51000000","side":"sell","client_oid":"0e3c224c-a220-4de5-acc9-ffcf84e07ce3","product_id":"BTC-EUR","sequence":3257977394,"time":"2018-01-22T15:14:35.106000Z"}
{"type":"open","side":"sell","price":"8831.51000000","order_id":"2a9ea768-2595-4ea2-b98c-25d6bccc55e9","remaining_size":"0.10500000","product_id":"BTC-EUR","sequence":3257977395,"time":"2018-01-22T15:14:35.106000Z"}
{"type":"done","side":"buy","order_id":"f2066f22-2b4d-4303-ade0-efd4fc04c64f","reason":"canceled","product_id":"BTC-EUR","price":"8823.38000000","remaining_size":"0.24799959","sequence":3257977396,"time":"2018-01-22T15:14:35.106000Z"}
{"type":"done","side":"sell","order_id":"eeb5d019-097a-4da1-8975-a7ab5f8b2c9c","reason":"canceled","product_id":"BTC-EUR","price":"8831.54000000","remaining_size":"0.21404538","sequence":3257977397,"time":"2018-01-22T15:14:35.145000Z"}
{"type":"done","side":"sell","order_id":"ed19ad3a-64e7-495d-ad51-d5acfe3898c1","reason":"canceled","product_id":"BTC-EUR","price":"9110.42000000","remaining_size":"1.28000000","sequence":3257977398,"time":"2018-01-22T15:14:35.186000Z"}
{"type":"received","order_id":"b50f101d-c5b5-461d-b404-514141825e37","order_type":"limit","size":"0.01887096","price":"8831.50000000","side":"sell","client_oid":"f1e1151e-c1e4-4e63-90ea-03ad776f087f","product_id":"BTC-EUR","sequence":3257977399,"time":"2018-01-22T15:14:35.188000Z"}
{"type":"open","side":"sell","price":"8831.50000000","order_id":"b50f101d-c5b5-461d-b404-514141825e37","remaining_size":"0.01887096","product_id":"BTC-EUR","sequence":3257977400,"time":"2018-01-22T15:14:35.188000Z"}
{"type":"done","side":"sell","order_id":"376ad122-abcc-42d9-b5f9-b0e85295d094","reason":"canceled","product_id":"BTC-EUR","price":"8831.51000000","remaining_size":"0.10500000","sequence":3257977401,"time":"2018-01-22T15:14:35.191000Z"}
{"type":"done","side":"sell","order_id":"2a9ea768-2595-4ea2-b98c-25d6bccc55e9","reason":"canceled","product_id":"BTC-EUR","price":"8831.51000000","remaining_size":"0.10500000","sequence":3257977402,"time":"2018-01-22T15:14:35.192000Z"}
{"type":"done","side":"sell","order_id":"4f50b5f9-db9e-4ddc-8733-57a9b38e0c34","reason":"canceled","product_id":"BTC-EUR","price":"8831.51000000","remaining_size":"0.00113228","sequence":3257977403,"time":"2018-01-22T15:14:35.209000Z"}
{"type":"done","side":"buy","order_id":"7210732d-e3e5-4f8d-8eba-c4945b7a66b3","reason":"canceled","product_id":"BTC-EUR","price":"8823.39000000","remaining_size":"0.24799931","sequence":3257977404,"time":"2018-01-22T15:14:35.224000Z"}
{"type":"done","side":"buy","order_id":"1935c5aa-6729-4929-b8ab-db3f80143453","reason":"canceled","product_id":"BTC-EUR","price":"8823.40000000","remaining_size":"0.24799903","sequence":3257977405,"time":"2018-01-22T15:14:35.224000Z"}
{"type":"done","side":"buy","order_id":"513068cf-bac0-408d-8187-7c9837afebc1","reason":"canceled","product_id":"BTC-EUR","price":"8823.40000000","remaining_size":"0.24799903","sequence":3257977406,"time":"2018-01-22T15:14:35.225000Z"}
{"type":"done","side":"buy","order_id":"18299145-ffcd-47ec-941e-809d2b42fde9","reason":"canceled","product_id":"BTC-EUR","price":"8823.40000000","remaining_size":"0.24799903","sequence":3257977407,"time":"2018-01-22T15:14:35.225000Z"}
{"type":"done","side":"buy","order_id":"16bc8a98-9b5f-45ba-93df-0a45487c7ff0","reason":"canceled","product_id":"BTC-EUR","price":"8823.41000000","remaining_size":"0.05000000","sequence":3257977408,"time":"2018-01-22T15:14:35.230000Z"}
{"type":"received","order_id":"c150c93a-ff71-4dd0-a166-30001a9e230d","order_type":"limit","size":"0.00113228","price":"8831.49000000","side":"sell","client_oid":"b038504a-5b60-4c81-9610-83c04e26539e","product_id":"BTC-EUR","sequence":3257977409,"time":"2018-01-22T15:14:35.242000Z"}
{"type":"open","side":"sell","price":"8831.49000000","order_id":"c150c93a-ff71-4dd0-a166-30001a9e230d","remaining_size":"0.00113228","product_id":"BTC-EUR","sequence":3257977410,"time":"2018-01-22T15:14:35.242000Z"}
{"type":"received","order_id":"17d44f11-dd86-42bf-98ac-0ee425546375","order_type":"limit","size":"0.05000000","price":"8823.34000000","side":"buy","client_oid":"2e482dca-b0a2-402d-8378-0b08253fe75f","product_id":"BTC-EUR","sequence":3257977411,"time":"2018-01-22T15:14:35.251000Z"}
{"type":"open","side":"buy","price":"8823.34000000","order_id":"17d44f11-dd86-42bf-98ac-0ee425546375","remaining_size":"0.05000000","product_id":"BTC-EUR","sequence":3257977412,"time":"2018-01-22T15:14:35.251000Z"}
{"type":"received","order_id":"0c0ef8e0-4327-4004-99ba-df8b7d8661d1","order_type":"limit","size":"0.46390796","price":"8802.50000000","side":"buy","client_oid":"e05829b8-f9f8-4ea8-9d97-88445447e955","product_id":"BTC-EUR","sequence":3257977413,"time":"2018-01-22T15:14:35.267000Z"}
{"type":"open","side":"buy","price":"8802.50000000","order_id":"0c0ef8e0-4327-4004-99ba-df8b7d8661d1","remaining_size":"0.46390796","product_id":"BTC-EUR","sequence":3257977414,"time":"2018-01-22T15:14:35.267000Z"}
{"type":"done","side":"sell","order_id":"f4a7ce54-95d3-45c2-be61-940a7095b61c","reason":"canceled","product_id":"BTC-EUR","price":"8831.69000000","remaining_size":"0.14814796","sequence":3257977415,"time":"2018-01-22T15:14:35.278000Z"}
{"type":"done","side":"buy","order_id":"64340938-9c51-4970-ae37-0eddf3879a24","reason":"canceled","product_id":"BTC-EUR","price":"8823.33000000","remaining_size":"0.02108452","sequence":3257977416,"time":"2018-01-22T15:14:35.279000Z"}
{"type":"done","side":"buy","order_id":"17d44f11-dd86-42bf-98ac-0ee425546375","reason":"canceled","product_id":"BTC-EUR","price":"8823.34000000","remaining_size":"0.05000000","sequence":3257977417,"time":"2018-01-22T15:14:35.304000Z"}
{"type":"received","order_id":"b737f1e3-2bf4-4d5f-8f58-167b78e7d240","order_type":"limit","size":"0.05000000","price":"8821.04000000","side":"buy","client_oid":"c73da66f-89b9-48b7-a7aa-4d38e4889d68","product_id":"BTC-EUR","sequence":3257977418,"time":"2018-01-22T15:14:35.327000Z"}
{"type":"open","side":"buy","price":"8821.04000000","order_id":"b737f1e3-2bf4-4d5f-8f58-167b78e7d240","remaining_size":"0.05000000","product_id":"BTC-EUR","sequence":3257977419,"time":"2018-01-22T15:14:35.327000Z"}
{"type":"received","order_id":"c6c65141-6ffd-49c2-98da-33d84a3f55e9","order_type":"market","side":"buy","funds":"59.8503576572000000","client_oid":"8d5761ec-05ee-4f34-89b1-8495a2cbbdb2","product_id":"BTC-EUR","sequence":3257977420,"time":"2018-01-22T15:14:35.337000Z"}
{"type":"match","trade_id":10551362,"maker_order_id":"c150c93a-ff71-4dd0-a166-30001a9e230d","taker_order_id":"c6c65141-6ffd-49c2-98da-33d84a3f55e9","side":"sell","size":"0.00113228","price":"8831.49000000","product_id":"BTC-EUR","sequence":3257977421,"time":"2018-01-22T15:14:35.337000Z"}
{"type":"done","side":"sell","order_id":"c150c93a-ff71-4dd0-a166-30001a9e230d","reason":"filled","product_id":"BTC-EUR","price":"8831.49000000","remaining_size":"0.00000000","sequence":3257977422,"time":"2018-01-22T15:14:35.337000Z"}
{"type":"match","trade_id":10551363,"maker_order_id":"b50f101d-c5b5-461d-b404-514141825e37","taker_order_id":"c6c65141-6ffd-49c2-98da-33d84a3f55e9","side":"sell","size":"0.00564464","price":"8831.50000000","product_id":"BTC-EUR","sequence":3257977423,"time":"2018-01-22T15:14:35.337000Z"}
{"type":"done","side":"buy","order_id":"c6c65141-6ffd-49c2-98da-33d84a3f55e9","reason":"filled","product_id":"BTC-EUR","sequence":3257977424,"time":"2018-01-22T15:14:35.337000Z"}
{"type":"done","side":"buy","order_id":"67be2a14-8d2a-4790-8d38-3508031c4522","reason":"canceled","product_id":"BTC-EUR","price":"8820.88000000","remaining_size":"0.18517661","sequence":3257977425,"time":"2018-01-22T15:14:35.357000Z"}
{"type":"received","order_id":"f2475c97-9751-4ae8-8e25-b78a4642af8f","order_type":"limit","size":"0.00113228","price":"8831.49000000","side":"sell","client_oid":"a3ef85eb-ba2e-47c1-9a9d-bf4f122183de","product_id":"BTC-EUR","sequence":3257977426,"time":"2018-01-22T15:14:35.384000Z"}
{"type":"open","side":"sell","price":"8831.49000000","order_id":"f2475c97-9751-4ae8-8e25-b78a4642af8f","remaining_size":"0.00113228","product_id":"BTC-EUR","sequence":3257977427,"time":"2018-01-22T15:14:35.384000Z"}
{"type":"done","side":"sell","order_id":"74b58004-aaa5-42ae-a9ba-e633e0227c30","reason":"canceled","product_id":"BTC-EUR","price":"8831.69000000","remaining_size":"0.42640068","sequence":3257977428,"time":"2018-01-22T15:14:35.404000Z"}
{"type":"received","order_id":"d6cd49fa-730b-47b3-a9cb-d6264403ef2a","order_type":"limit","size":"0.21404538","price":"8831.48000000","side":"sell","product_id":"BTC-EUR","sequence":3257977429,"time":"2018-01-22T15:14:35.433000Z"}
{"type":"open","side":"sell","price":"8831.48000000","order_id":"d6cd49fa-730b-47b3-a9cb-d6264403ef2a","remaining_size":"0.21404538","product_id":"BTC-EUR","sequence":3257977430,"time":"2018-01-22T15:14:35.433000Z"}
{"type":"received","order_id":"e8b8f98d-c9dd-463c-9ba7-c81e1334d928","order_type":"limit","size":"0.10500000","price":"8831.50000000","side":"sell","client_oid":"37cfaeb6-5917-4538-9067-7c763f40968a","product_id":"BTC-EUR","sequence":3257977431,"time":"2018-01-22T15:14:35.440000Z"}
{"type":"open","side":"sell","price":"8831.50000000","order_id":"e8b8f98d-c9dd-463c-9ba7-c81e1334d928","remaining_size":"0.10500000","product_id":"BTC-EUR","sequence":3257977432,"time":"2018-01-22T15:14:35.440000Z"}
{"type":"done","side":"sell","order_id":"f2475c97-9751-4ae8-8e25-b78a4642af8f","reason":"canceled","product_id":"BTC-EUR","price":"8831.49000000","remaining_size":"0.00113228","sequence":3257977433,"time":"2018-01-22T15:14:35.449000Z"}
{"type":"received","order_id":"1dc1d4e3-d1eb-4bfe-92ec-885d59e3ddce","order_type":"limit","size":"0.02108452","price":"8823.37000000","side":"buy","product_id":"BTC-EUR","sequence":3257977434,"time":"2018-01-22T15:14:35.451000Z"}
{"type":"open","side":"buy","price":"8823.37000000","order_id":"1dc1d4e3-d1eb-4bfe-92ec-885d59e3ddce","remaining_size":"0.02108452","product_id":"BTC-EUR","sequence":3257977435,"time":"2018-01-22T15:14:35.451000Z"}
{"type":"done","side":"buy","order_id":"b737f1e3-2bf4-4d5f-8f58-167b78e7d240","reason":"canceled","product_id":"BTC-EUR","price":"8821.04000000","remaining_size":"0.05000000","sequence":3257977436,"time":"2018-01-22T15:14:35.457000Z"}
{"type":"done","side":"sell","order_id":"e8b8f98d-c9dd-463c-9ba7-c81e1334d928","reason":"canceled","product_id":"BTC-EUR","price":"8831.50000000","remaining_size":"0.10500000","sequence":3257977437,"time":"2018-01-22T15:14:35.530000Z"}
{"type":"received","order_id":"d8aed776-de9d-4a33-96ad-1c14aa8367a1","order_type":"limit","size":"0.00113228","price":"8831.47000000","side":"sell","client_oid":"747e81a6-1b31-4858-a4e9-999694844fb6","product_id":"BTC-EUR","sequence":3257977438,"time":"2018-01-22T15:14:35.531000Z"}
{"type":"open","side":"sell","price":"8831.47000000","order_id":"d8aed776-de9d-4a33-96ad-1c14aa8367a1","remaining_size":"0.00113228","product_id":"BTC-EUR","sequence":3257977439,"time":"2018-01-22T15:14:35.531000Z"}
{"type":"received","order_id":"12f59de8-4525-4242-b51c-5344bdfc185e","order_type":"limit","size":"0.05000000","price":"8823.38000000","side":"buy","client_oid":"08930a26-4ee3-47d6-bd89-7f6be4812a23","product_id":"BTC-EUR","sequence":3257977440,"time":"2018-01-22T15:14:35.534000Z"}
{"type":"open","side":"buy","price":"8823.38000000","order_id":"12f59de8-4525-4242-b51c-5344bdfc185e","remaining_size":"0.05000000","product_id":"BTC-EUR","sequence":3257977441,"time":"2018-01-22T15:14:35.534000Z"}
{"type":"done","side":"sell","order_id":"d6cd49fa-730b-47b3-a9cb-d6264403ef2a","reason":"canceled","product_id":"BTC-EUR","price":"8831.48000000","remaining_size":"0.21404538","sequence":3257977442,"time":"2018-01-22T15:14:35.556000Z"}
{"type":"received","order_id":"55929433-043f-478e-81e1-905e76366e6d","order_type":"limit","size":"0.10500000","price":"8831.48000000","side":"sell","client_oid":"0b231e73-f54d-40b5-a614-51e4c5de9f6c","product_id":"BTC-EUR","sequence":3257977443,"time":"2018-01-22T15:14:35.564000Z"}
{"type":"open","side":"sell","price":"8831.48000000","order_id":"55929433-043f-478e-81e1-905e76366e6d","remaining_size":"0.10500000","product_id":"BTC-EUR","sequence":3257977444,"time":"2018-01-22T15:14:35.564000Z"}
{"type":"done","side":"sell","order_id":"c87f56d7-e1f8-46d7-b07d-ad00a8284087","reason":"canceled","product_id":"BTC-EUR","price":"8831.52000000","remaining_size":"0.04164971","sequence":3257977445,"time":"2018-01-22T15:14:35.610000Z"}
{"type":"received","order_id":"42b16447-1eae-40f9-93bf-2e748b51151c","order_type":"limit","size":"0.09800000","price":"8831.47000000","side":"sell","client_oid":"b9a1f9eb-ae87-4817-bb8d-db9fd6bb5658","product_id":"BTC-EUR","sequence":3257977446,"time":"2018-01-22T15:14:35.618000Z"}
{"type":"open","side":"sell","price":"8831.47000000","order_id":"42b16447-1eae-40f9-93bf-2e748b51151c","remaining_size":"0.09800000","product_id":"BTC-EUR","sequence":3257977447,"time":"2018-01-22T15:14:35.618000Z"}
{"type":"received","order_id":"f03cb24b-61e2-4766-917d-70f8ae9b10e2","order_type":"limit","size":"0.10500000","price":"8831.48000000","side":"sell","client_oid":"08938c2f-3541-4181-a80c-98502ed3d0b3","product_id":"BTC-EUR","sequence":3257977448,"time":"2018-01-22T15:14:35.618000Z"}
{"type":"open","side":"sell","price":"8831.48000000","order_id":"f03cb24b-61e2-4766-917d-70f8ae9b10e2","remaining_size":"0.10500000","product_id":"BTC-EUR","sequence":3257977449,"time":"2018-01-22T15:14:35.618000Z"}
{"type":"done","side":"sell","order_id":"55929433-043f-478e-81e1-905e76366e6d","reason":"canceled","product_id":"BTC-EUR","price":"8831.48000000","remaining_size":"0.10500000","sequence":3257977450,"time":"2018-01-22T15:14:35.726000Z"}
{"type":"received","order_id":"5f2016c4-4b2f-46fc-8e44-9ab1f12d3762","order_type":"limit","size":"0.08000000","price":"8831.46000000","side":"sell","client_oid":"fbdb3192-4dbc-4048-8bff-a6be848a54d4","product_id":"BTC-EUR","sequence":3257977451,"time":"2018-01-22T15:14:35.734000Z"}
{"type":"open","side":"sell","price":"8831.46000000","order_id":"5f2016c4-4b2f-46fc-8e44-9ab1f12d3762","remaining_size":"0.08000000","product_id":"BTC-EUR","sequence":3257977452,"time":"2018-01-22T15:14:35.734000Z"}
{"type":"received","order_id":"b3057148-2cd8-4b47-9275-a2e0d359e5b9","order_type":"limit","size":"0.10500000","price":"8831.47000000","side":"sell","client_oid":"dba99d2a-9f11-44d6-bcae-4bf68db83c3e","product_id":"BTC-EUR","sequence":3257977453,"time":"2018-01-22T15:14:35.748000Z"}
{"type":"open","side":"sell","price":"8831.47000000","order_id":"b3057148-2cd8-4b47-9275-a2e0d359e5b9","remaining_size":"0.10500000","product_id":"BTC-EUR","sequence":3257977454,"time":"2018-01-22T15:14:35.748000Z"}
{"type":"done","side":"sell","order_id":"f03cb24b-61e2-4766-917d-70f8ae9b10e2","reason":"canceled","product_id":"BTC-EUR","price":"8831.48000000","remaining_size":"0.10500000","sequence":3257977455,"time":"2018-01-22T15:14:35.750000Z"}
{"type":"done","side":"sell","order_id":"d8aed776-de9d-4a33-96ad-1c14aa8367a1","reason":"canceled","product_id":"BTC-EUR","price":"8831.47000000","remaining_size":"0.00113228","sequence":3257977456,"time":"2018-01-22T15:14:35.818000Z"}
{"type":"done","side":"sell","order_id":"42b16447-1eae-40f9-93bf-2e748b51151c","reason":"canceled","product_id":"BTC-EUR","price":"8831.47000000","remaining_size":"0.09800000","sequence":3257977457,"time":"2018-01-22T15:14:35.820000Z"}
{"type":"received","order_id":"65a02099-f490-4e07-ae82-3d72f172f673","order_type":"limit","size":"0.04164971","price":"8831.47000000","side":"sell","client_oid":"22488654-e8eb-4ac8-910f-9ec3edc0d7a1","product_id":"BTC-EUR","sequence":3257977458,"time":"2018-01-22T15:14:35.830000Z"}
{"type":"open","side":"sell","price":"8831.47000000","order_id":"65a02099-f490-4e07-ae82-3d72f172f673","remaining_size":"0.04164971","product_id":"BTC-EUR","sequence":3257977459,"time":"2018-01-22T15:14:35.830000Z"}
{"type":"done","side":"sell","order_id":"b3057148-2cd8-4b47-9275-a2e0d359e5b9","reason":"canceled","product_id":"BTC-EUR","price":"8831.47000000","remaining_size":"0.10500000","sequence":3257977460,"time":"2018-01-22T15:14:35.835000Z"}
{"type":"received","order_id":"8a8b08fb-0a5e-4825-8683-462ad18b396e","order_type":"limit","size":"0.09800000","price":"8831.45000000","side":"sell","client_oid":"f97d9843-c424-4022-b7c6-b82ab7635b50","product_id":"BTC-EUR","sequence":3257977461,"time":"2018-01-22T15:14:35.838000Z"}
{"type":"open","side":"sell","price":"8831.45000000","order_id":"8a8b08fb-0a5e-4825-8683-462ad18b396e","remaining_size":"0.09800000","product_id":"BTC-EUR","sequence":3257977462,"time":"2018-01-22T15:14:35.838000Z"}
{"type":"received","order_id":"11624d6e-bd11-4c03-a7f6-da6e99bb5431","order_type":"limit","size":"0.18458699","price":"8849.05000000","side":"sell","client_oid":"5db40c44-272d-489a-9612-fc1374374710","product_id":"BTC-EUR","sequence":3257977463,"time":"2018-01-22T15:14:35.843000Z"}
{"type":"open","side":"sell","price":"8849.05000000","order_id":"11624d6e-bd11-4c03-a7f6-da6e99bb5431","remaining_size":"0.18458699","product_id":"BTC-EUR","sequence":3257977464,"time":"2018-01-22T15:14:35.843000Z"}
{"type":"received","order_id":"9d06cb63-04c7-404c-95c3-76969eb17614","order_type":"limit","size":"0.21404538","price":"8831.46000000","side":"sell","product_id":"BTC-EUR","sequence":3257977465,"time":"2018-01-22T15:14:35.843000Z"}
{"type":"open","side":"sell","price":"8831.46000000","order_id":"9d06cb63-04c7-404c-95c3-76969eb17614","remaining_size":"0.21404538","product_id":"BTC-EUR","sequence":3257977466,"time":"2018-01-22T15:14:35.843000Z"}
{"type":"received","order_id":"6a9000e5-2b21-46f1-ba67-57f09a5ca70f","order_type":"limit","size":"0.10500000","price":"8831.46000000","side":"sell","client_oid":"4a05c051-74a4-477c-ac25-437e7f388e75","product_id":"BTC-EUR","sequence":3257977467,"time":"2018-01-22T15:14:35.867000Z"}
{"type":"open","side":"sell","price":"8831.46000000","order_id":"6a9000e5-2b21-46f1-ba67-57f09a5ca70f","remaining_size":"0.10500000","product_id":"BTC-EUR","sequence":3257977468,"time":"2018-01-22T15:14:35.867000Z"}
{"type":"received","order_id":"9e6abcba-efec-416f-8d50-c21860921061","order_type":"limit","size":"0.00113228","price":"8831.45000000","side":"sell","client_oid":"c4aea865-00d1-4fe1-9dcc-f9ed30362503","product_id":"BTC-EUR","sequence":3257977469,"time":"2018-01-22T15:14:35.881000Z"}
{"type":"open","side":"sell","price":"8831.45000000","order_id":"9e6abcba-efec-416f-8d50-c21860921061","remaining_size":"0.00113228","product_id":"BTC-EUR","sequence":3257977470,"time":"2018-01-22T15:14:35.881000Z"}
{"type":"done","side":"sell","order_id":"b50f101d-c5b5-461d-b404-514141825e37","reason":"canceled","product_id":"BTC-EUR","price":"8831.50000000","remaining_size":"0.01322632","sequence":3257977471,"time":"2018-01-22T15:14:35.905000Z"}
{"type":"done","side":"sell","order_id":"b2915a41-fd0a-4f5e-9bcd-774ce061a2dc","reason":"canceled","product_id":"BTC-EUR","price":"8831.51000000","remaining_size":"0.09800000","sequence":3257977472,"time":"2018-01-22T15:14:35.905000Z"}
{"type":"received","order_id":"21d35554-89af-4be5-bd4e-fde4a223505c","order_type":"limit","size":"0.08000000","price":"8562.61000000","side":"sell","product_id":"BTC-EUR","sequence":3257977473,"time":"2018-01-22T15:14:35.915000Z"}
{"type":"match","trade_id":10551364,"maker_order_id":"7717ce4b-b779-4bc1-aeba-1ac0ad1f7211","taker_order_id":"21d35554-89af-4be5-bd4e-fde4a223505c","side":"buy","size":"0.00113334","price":"8823.41000000","product_id":"BTC-EUR","sequence":3257977474,"time":"2018-01-22T15:14:35.915000Z"}
{"type":"done","side":"buy","order_id":"7717ce4b-b779-4bc1-aeba-1ac0ad1f7211","reason":"filled","product_id":"BTC-EUR","price":"8823.41000000","remaining_size":"0","sequence":3257977475,"time":"2018-01-22T15:14:35.915000Z"}
{"type":"match","trade_id":10551365,"maker_order_id":"12f59de8-4525-4242-b51c-5344bdfc185e","taker_order_id":"21d35554-89af-4be5-bd4e-fde4a223505c","side":"buy","size":"0.05000000","price":"8823.38000000","product_id":"BTC-EUR","sequence":3257977476,"time":"2018-01-22T15:14:35.915000Z"}
{"type":"done","side":"buy","order_id":"12f59de8-4525-4242-b51c-5344bdfc185e","reason":"filled","product_id":"BTC-EUR","price":"8823.38000000","remaining_size":"0","sequence":3257977477,"time":"2018-01-22T15:14:35.915000Z"}
{"type":"match","trade_id":10551366,"maker_order_id":"1dc1d4e3-d1eb-4bfe-92ec-885d59e3ddce","taker_order_id":"21d35554-89af-4be5-bd4e-fde4a223505c","side":"buy","size":"0.02108452","price":"8823.37000000","product_id":"BTC-EUR","sequence":3257977478,"time":"2018-01-22T15:14:35.915000Z"}
{"type":"done","side":"buy","order_id":"1dc1d4e3-d1eb-4bfe-92ec-885d59e3ddce","reason":"filled","product_id":"BTC-EUR","price":"8823.37000000","remaining_size":"0","sequence":3257977479,"time":"2018-01-22T15:14:35.915000Z"}
{"type":"match","trade_id":10551367,"maker_order_id":"5a3976ae-def8-4859-bdd4-4c83b336bdd5","taker_order_id":"21d35554-89af-4be5-bd4e-fde4a223505c","side":"buy","size":"0.00778214","price":"8822.63000000","product_id":"BTC-EUR","sequence":3257977480,"time":"2018-01-22T15:14:35.915000Z"}
{"type":"done","side":"sell","order_id":"21d35554-89af-4be5-bd4e-fde4a223505c","reason":"filled","product_id":"BTC-EUR","price":"8562.61000000","remaining_size":"0.00000000","sequence":3257977481,"time":"2018-01-22T15:14:35.915000Z"}
{"type":"done","side":"sell","order_id":"5bf9da75-18ab-46db-bb33-06c63a9107d9","reason":"canceled","product_id":"BTC-EUR","price":"8831.53000000","remaining_size":"0.22947933","sequence":3257977482,"time":"2018-01-22T15:14:35.923000Z"}
{"type":"received","order_id":"4022a55d-ef09-4f32-b510-327d2178c38f","order_type":"limit","size":"0.09800000","price":"8831.45000000","side":"sell","client_oid":"44ebdd25-bc18-434c-a6e3-642f1c043c62","product_id":"BTC-EUR","sequence":3257977483,"time":"2018-01-22T15:14:35.933000Z"}
{"type":"open","side":"sell","price":"8831.45000000","order_id":"4022a55d-ef09-4f32-b510-327d2178c38f","remaining_size":"0.09800000","product_id":"BTC-EUR","sequence":3257977484,"time":"2018-01-22T15:14:35.933000Z"}
{"type":"received","order_id":"2776239d-1568-45bc-b9be-d11dfd231644","order_type":"limit","size":"0.02000000","price":"8823.38000000","side":"buy","client_oid":"9f8cc810-1d92-4d66-8093-7d6f666d87b5","product_id":"BTC-EUR","sequence":3257977485,"time":"2018-01-22T15:14:35.934000Z"}
{"type":"open","side":"buy","price":"8823.38000000","order_id":"2776239d-1568-45bc-b9be-d11dfd231644","remaining_size":"0.02000000","product_id":"BTC-EUR","sequence":3257977486,"time":"2018-01-22T15:14:35.934000Z"}
{"type":"done","side":"sell","order_id":"6a9000e5-2b21-46f1-ba67-57f09a5ca70f","reason":"canceled","product_id":"BTC-EUR","price":"8831.46000000","remaining_size":"0.10500000","sequence":3257977487,"time":"2018-01-22T15:14:35.946000Z"}
{"type":"done","side":"buy","order_id":"2776239d-1568-45bc-b9be-d11dfd231644","reason":"canceled","product_id":"BTC-EUR","price":"8823.38000000","remaining_size":"0.02000000","sequence":3257977488,"time":"2018-01-22T15:14:35.954000Z"}
{"type":"received","order_id":"0f0ae814-4c89-41f7-8941-7851ce0c6c42","order_type":"limit","size":"0.10500000","price":"8831.45000000","side":"sell","client_oid":"61e6a7b1-a092-423e-bed1-41fbdd3f6472","product_id":"BTC-EUR","sequence":3257977489,"time":"2018-01-22T15:14:35.966000Z"}
{"type":"open","side":"sell","price":"8831.45000000","order_id":"0f0ae814-4c89-41f7-8941-7851ce0c6c42","remaining_size":"0.10500000","product_id":"BTC-EUR","sequence":3257977490,"time":"2018-01-22T15:14:35.966000Z"}
{"type":"received","order_id":"a69c6f27-4b5a-48fe-ab87-c34efed40526","order_type":"limit","size":"0.05000000","price":"8831.44000000","side":"sell","client_oid":"265d1153-a7a3-4127-bb94-9992b0f43d2f","product_id":"BTC-EUR","sequence":3257977491,"time":"2018-01-22T15:14:35.969000Z"}
{"type":"open","side":"sell","price":"8831.44000000","order_id":"a69c6f27-4b5a-48fe-ab87-c34efed40526","remaining_size":"0.05000000","product_id":"BTC-EUR","sequence":3257977492,"time":"2018-01-22T15:14:35.969000Z"}
{"type":"received","order_id":"c46be2cf-5e96-4e34-b92f-177d5f630134","order_type":"limit","size":"0.00113344","price":"8822.64000000","side":"buy","client_oid":"6dfdbd86-1f36-4684-8972-55a28ba29508","product_id":"BTC-EUR","sequence":3257977493,"time":"2018-01-22T15:14:35.987000Z"}
{"type":"open","side":"buy","price":"8822.64000000","order_id":"c46be2cf-5e96-4e34-b92f-177d5f630134","remaining_size":"0.00113344","product_id":"BTC-EUR","sequence":3257977494,"time":"2018-01-22T15:14:35.987000Z"}
{"type":"done","side":"sell","order_id":"9e6abcba-efec-416f-8d50-c21860921061","reason":"canceled","product_id":"BTC-EUR","price":"8831.45000000","remaining_size":"0.00113228","sequence":3257977495,"time":"2018-01-22T15:14:35.994000Z"}
{"type":"received","order_id":"4c58d41c-7aa2-453f-925a-f1e31fb3dc63","order_type":"limit","size":"0.02000000","price":"8821.04000000","side":"buy","client_oid":"049e0b79-7486-4052-b5aa-df4f5e8dfe93","product_id":"BTC-EUR","sequence":3257977496,"time":"2018-01-22T15:14:35.994000Z"}
{"type":"open","side":"buy","price":"8821.04000000","order_id":"4c58d41c-7aa2-453f-925a-f1e31fb3dc63","remaining_size":"0.02000000","product_id":"BTC-EUR","sequence":3257977497,"time":"2018-01-22T15:14:35.994000Z"}
{"type":"done","side":"buy","order_id":"c46be2cf-5e96-4e34-b92f-177d5f630134","reason":"canceled","product_id":"BTC-EUR","price":"8822.64000000","remaining_size":"0.00113344","sequence":3257977498,"time":"2018-01-22T15:14:35.999000Z"}
{"type":"done","side":"sell","order_id":"ddbae404-c640-48f8-9f4e-0d5514368cbf","reason":"canceled","product_id":"BTC-EUR","price":"15000.00000000","remaining_size":"0.00200000","sequence":3257977499,"time":"2018-01-22T15:14:36.010000Z"}
{"type":"done","side":"sell","order_id":"0f0ae814-4c89-41f7-8941-7851ce0c6c42","reason":"canceled","product_id":"BTC-EUR","price":"8831.45000000","remaining_size":"0.10500000","sequence":3257977500,"time":"2018-01-22T15:14:36.047000Z"}
{"type":"received","order_id":"dfd2cd26-bfdf-4b75-9628-a84d1337f674","order_type":"limit","size":"0.00113228","price":"8831.43000000","side":"sell","client_oid":"1927b0c7-52ed-4e4d-9d04-547441f6e616","product_id":"BTC-EUR","sequence":3257977501,"time":"2018-01-22T15:14:36.053000Z"}
{"type":"open","side":"sell","price":"8831.43000000","order_id":"dfd2cd26-bfdf-4b75-9628-a84d1337f674","remaining_size":"0.00113228","product_id":"BTC-EUR","sequence":3257977502,"time":"2018-01-22T15:14:36.053000Z"}
{"type":"done","side":"sell","order_id":"1e55dd5a-97a6-4f6f-b62c-eb5f74197a6e","reason":"canceled","product_id":"BTC-EUR","price":"8869.88000000","remaining_size":"0.46038396","sequence":3257977503,"time":"2018-01-22T15:14:36.057000Z"}
{"type":"received","order_id":"b2d130df-4d85-4b24-80e5-e59c454ce2a6","order_type":"limit","size":"0.00113344","price":"8822.64000000","side":"buy","client_oid":"66d725c3-b473-4e58-850f-b5d736da99e1","product_id":"BTC-EUR","sequence":3257977504,"time":"2018-01-22T15:14:36.061000Z"}
{"type":"open","side":"buy","price":"8822.64000000","order_id":"b2d130df-4d85-4b24-80e5-e59c454ce2a6","remaining_size":"0.00113344","product_id":"BTC-EUR","sequence":3257977505,"time":"2018-01-22T15:14:36.061000Z"}
{"type":"done","side":"sell","order_id":"8a8b08fb-0a5e-4825-8683-462ad18b396e","reason":"canceled","product_id":"BTC-EUR","price":"8831.45000000","remaining_size":"0.09800000","sequence":3257977506,"time":"2018-01-22T15:14:36.062000Z"}
{"type":"received","order_id":"0a3dc95a-2792-482a-a1e5-b97b895b26ed","order_type":"limit","size":"0.10500000","price":"8831.44000000","side":"sell","client_oid":"cb10b719-2c41-4d26-9939-a136893f56a1","product_id":"BTC-EUR","sequence":3257977507,"time":"2018-01-22T15:14:36.069000Z"}
{"type":"open","side":"sell","price":"8831.44000000","order_id":"0a3dc95a-2792-482a-a1e5-b97b895b26ed","remaining_size":"0.10500000","product_id":"BTC-EUR","sequence":3257977508,"time":"2018-01-22T15:14:36.069000Z"}
{"type":"done","side":"sell","order_id":"4022a55d-ef09-4f32-b510-327d2178c38f","reason":"canceled","product_id":"BTC-EUR","price":"8831.45000000","remaining_size":"0.09800000","sequence":3257977509,"time":"2018-01-22T15:14:36.074000Z"}
{"type":"done","side":"sell","order_id":"dfd2cd26-bfdf-4b75-9628-a84d1337f674","reason":"canceled","product_id":"BTC-EUR","price":"8831.43000000","remaining_size":"0.00113228","sequence":3257977510,"time":"2018-01-22T15:14:36.079000Z"}
{"type":"received","order_id":"84c81b3f-4825-41f0-b2c2-5c902ce48245","order_type":"limit","size":"0.10500000","price":"8831.44000000","side":"sell","client_oid":"9566f543-d606-4469-aa3e-212f7a41fc6a","product_id":"BTC-EUR","sequence":3257977511,"time":"2018-01-22T15:14:36.080000Z"}
{"type":"open","side":"sell","price":"8831.44000000","order_id":"84c81b3f-4825-41f0-b2c2-5c902ce48245","remaining_size":"0.10500000","product_id":"BTC-EUR","sequence":3257977512,"time":"2018-01-22T15:14:36.080000Z"}
{"type":"done","side":"buy","order_id":"b2d130df-4d85-4b24-80e5-e59c454ce2a6","reason":"canceled","product_id":"BTC-EUR","price":"8822.64000000","remaining_size":"0.00113344","sequence":3257977513,"time":"2018-01-22T15:14:36.100000Z"}
{"type":"received","order_id":"badd8044-0d09-4b86-b912-7b92b52d3c4c","order_type":"limit","size":"0.01322632","price":"8831.43000000","side":"sell","client_oid":"45c0fe2d-9786-42ab-9379-32c74d12a5ce","product_id":"BTC-EUR","sequence":3257977514,"time":"2018-01-22T15:14:36.120000Z"}
{"type":"open","side":"sell","price":"8831.43000000","order_id":"badd8044-0d09-4b86-b912-7b92b52d3c4c","remaining_size":"0.01322632","product_id":"BTC-EUR","sequence":3257977515,"time":"2018-01-22T15:14:36.120000Z"}
{"type":"done","side":"buy","order_id":"df121a64-b0c8-432e-9eea-f8747e8225a1","reason":"canceled","product_id":"BTC-EUR","price":"7286.45000000","remaining_size":"19.17998894","sequence":3257977516,"time":"2018-01-22T15:14:36.133000Z"}
{"type":"received","order_id":"75e9418a-9bcf-4414-8f1b-c2eaa5db5ddf","order_type":"limit","size":"0.09800000","price":"8831.42000000","side":"sell","client_oid":"359c6437-d2f1-41ca-906f-ccfa9db63cf8","product_id":"BTC-EUR","sequence":3257977517,"time":"2018-01-22T15:14:36.139000Z"}
{"type":"open","side":"sell","price":"8831.42000000","order_id":"75e9418a-9bcf-4414-8f1b-c2eaa5db5ddf","remaining_size":"0.09800000","product_id":"BTC-EUR","sequence":3257977518,"time":"2018-01-22T15:14:36.139000Z"}
{"type":"done","side":"sell","order_id":"0a3dc95a-2792-482a-a1e5-b97b895b26ed","reason":"canceled","product_id":"BTC-EUR","price":"8831.44000000","remaining_size":"0.10500000","sequence":3257977519,"time":"2018-01-22T15:14:36.146000Z"}
{"type":"done","side":"sell","order_id":"a69c6f27-4b5a-48fe-ab87-c34efed40526","reason":"canceled","product_id":"BTC-EUR","price":"8831.44000000","remaining_size":"0.05000000","sequence":3257977520,"time":"2018-01-22T15:14:36.154000Z"}
{"type":"received","order_id":"2e32feb6-84a8-4fb5-8893-4a67920172ef","order_type":"limit","size":"0.00113228","price":"8831.43000000","side":"sell","client_oid":"b149dc40-c2d4-42b5-a21a-c1c239e09d23","product_id":"BTC-EUR","sequence":3257977521,"time":"2018-01-22T15:14:36.155000Z"}
{"type":"open","side":"sell","price":"8831.43000000","order_id":"2e32feb6-84a8-4fb5-8893-4a67920172ef","remaining_size":"0.00113228","product_id":"BTC-EUR","sequence":3257977522,"time":"2018-01-22T15:14:36.155000Z"}
{"type":"received","order_id":"a6aafa95-748e-435e-890b-e4dc104ccbed","order_type":"limit","size":"0.00113344","price":"8822.64000000","side":"buy","client_oid":"328990a0-0a5a-4efd-a2db-e72ce07ae4d9","product_id":"BTC-EUR","sequence":3257977523,"time":"2018-01-22T15:14:36.164000Z"}
{"type":"open","side":"buy","price":"8822.64000000","order_id":"a6aafa95-748e-435e-890b-e4dc104ccbed","remaining_size":"0.00113344","product_id":"BTC-EUR","sequence":3257977524,"time":"2018-01-22T15:14:36.164000Z"}
{"type":"received","order_id":"6472e6b9-f105-4aa7-b941-b9973c2d92c6","order_type":"limit","size":"0.22947933","price":"8831.43000000","side":"sell","client_oid":"a20e9cb6-1868-4057-81f2-d72e3c0e7a4c","product_id":"BTC-EUR","sequence":3257977525,"time":"2018-01-22T15:14:36.164000Z"}
{"type":"open","side":"sell","price":"8831.43000000","order_id":"6472e6b9-f105-4aa7-b941-b9973c2d92c6","remaining_size":"0.22947933","product_id":"BTC-EUR","sequence":3257977526,"time":"2018-01-22T15:14:36.164000Z"}
{"type":"done","side":"sell","order_id":"2e32feb6-84a8-4fb5-8893-4a67920172ef","reason":"canceled","product_id":"BTC-EUR","price":"8831.43000000","remaining_size":"0.00113228","sequence":3257977527,"time":"2018-01-22T15:14:36.174000Z"}
{"type":"received","order_id":"3d68ed54-d6b0-4215-82ee-43c3b043f744","order_type":"limit","size":"0.18533105","price":"8813.52000000","side":"buy","client_oid":"bdbc3daf-38b3-44eb-b2b9-2aae66775e99","product_id":"BTC-EUR","sequence":3257977528,"time":"2018-01-22T15:14:36.176000Z"}
{"type":"open","side":"buy","price":"8813.52000000","order_id":"3d68ed54-d6b0-4215-82ee-43c3b043f744","remaining_size":"0.18533105","product_id":"BTC-EUR","sequence":3257977529,"time":"2018-01-22T15:14:36.176000Z"}
{"type":"received","order_id":"3779aaee-b58e-439c-8b1e-8c0ffb47b8f7","order_type":"limit","size":"0.05000000","price":"8831.41000000","side":"sell","client_oid":"9abe0ca1-8b82-4380-9bb4-fd882bd3982c","product_id":"BTC-EUR","sequence":3257977530,"time":"2018-01-22T15:14:36.176000Z"}
{"type":"open","side":"sell","price":"8831.41000000","order_id":"3779aaee-b58e-439c-8b1e-8c0ffb47b8f7","remaining_size":"0.05000000","product_id":"BTC-EUR","sequence":3257977531,"time":"2018-01-22T15:14:36.176000Z"}
{"type":"done","side":"buy","order_id":"a6aafa95-748e-435e-890b-e4dc104ccbed","reason":"canceled","product_id":"BTC-EUR","price":"8822.64000000","remaining_size":"0.00113344","sequence":3257977532,"time":"2018-01-22T15:14:36.199000Z"}
{"type":"received","order_id":"e5469089-c4d2-47be-b6ee-67bd339a7403","order_type":"limit","size":"0.10500000","price":"8831.43000000","side":"sell","client_oid":"fb1eb461-53e6-48c7-a182-60b8d96a3b39","product_id":"BTC-EUR","sequence":3257977533,"time":"2018-01-22T15:14:36.217000Z"}
{"type":"open","side":"sell","price":"8831.43000000","order_id":"e5469089-c4d2-47be-b6ee-67bd339a7403","remaining_size":"0.10500000","product_id":"BTC-EUR","sequence":3257977534,"time":"2018-01-22T15:14:36.217000Z"}
{"type":"received","order_id":"ed1e3e1e-5afd-459e-800a-222e1c4b2976","order_type":"limit","size":"0.00113228","price":"8831.40000000","side":"sell","client_oid":"749eac99-eb86-4d29-a02b-e6bffb253fe6","product_id":"BTC-EUR","sequence":3257977535,"time":"2018-01-22T15:14:36.238000Z"}
{"type":"open","side":"sell","price":"8831.40000000","order_id":"ed1e3e1e-5afd-459e-800a-222e1c4b2976","remaining_size":"0.00113228","product_id":"BTC-EUR","sequence":3257977536,"time":"2018-01-22T15:14:36.238000Z"}
{"type":"done","side":"sell","order_id":"75e9418a-9bcf-4414-8f1b-c2eaa5db5ddf","reason":"canceled","product_id":"BTC-EUR","price":"8831.42000000","remaining_size":"0.09800000","sequence":3257977537,"time":"2018-01-22T15:14:36.254000Z"}
{"type":"received","order_id":"17934232-f740-4dab-ba72-b3a6a756d21e","order_type":"limit","size":"0.00113344","price":"8822.64000000","side":"buy","client_oid":"29b4f61a-9554-4e3f-83fe-8cd06ad952ae","product_id":"BTC-EUR","sequence":3257977538,"time":"2018-01-22T15:14:36.258000Z"}
{"type":"open","side":"buy","price":"8822.64000000","order_id":"17934232-f740-4dab-ba72-b3a6a756d21e","remaining_size":"0.00113344","product_id":"BTC-EUR","sequence":3257977539,"time":"2018-01-22T15:14:36.258000Z"}
{"type":"done","side":"sell","order_id":"9d06cb63-04c7-404c-95c3-76969eb17614","reason":"canceled","product_id":"BTC-EUR","price":"8831.46000000","remaining_size":"0.21404538","sequence":3257977540,"time":"2018-01-22T15:14:36.261000Z"}
{"type":"done","side":"sell","order_id":"ed1e3e1e-5afd-459e-800a-222e1c4b2976","reason":"canceled","product_id":"BTC-EUR","price":"8831.40000000","remaining_size":"0.00113228","sequence":3257977541,"time":"2018-01-22T15:14:36.276000Z"}
{"type":"received","order_id":"284a59fa-4804-465f-9334-1dce018ae5eb","order_type":"limit","size":"0.09800000","price":"8831.40000000","side":"sell","client_oid":"96bf246f-7b1a-4361-b73c-daa07050a594","product_id":"BTC-EUR","sequence":3257977542,"time":"2018-01-22T15:14:36.304000Z"}
{"type":"open","side":"sell","price":"8831.40000000","order_id":"284a59fa-4804-465f-9334-1dce018ae5eb","remaining_size":"0.09800000","product_id":"BTC-EUR","sequence":3257977543,"time":"2018-01-22T15:14:36.304000Z"}
{"type":"done","side":"buy","order_id":"17934232-f740-4dab-ba72-b3a6a756d21e","reason":"canceled","product_id":"BTC-EUR","price":"8822.64000000","remaining_size":"0.00113344","sequence":3257977544,"time":"2018-01-22T15:14:36.306000Z"}
{"type":"done","side":"sell","order_id":"3779aaee-b58e-439c-8b1e-8c0ffb47b8f7","reason":"canceled","product_id":"BTC-EUR","price":"8831.41000000","remaining_size":"0.05000000","sequence":3257977545,"time":"2018-01-22T15:14:36.319000Z"}
{"type":"received","order_id":"7588674b-ddb1-4a6d-a1cd-1f58259bd58f","order_type":"limit","size":"0.00113228","price":"8831.40000000","side":"sell","client_oid":"4665f81a-18c7-4b57-99f6-a48e3c74438c","product_id":"BTC-EUR","sequence":3257977546,"time":"2018-01-22T15:14:36.333000Z"}
{"type":"open","side":"sell","price":"8831.40000000","order_id":"7588674b-ddb1-4a6d-a1cd-1f58259bd58f","remaining_size":"0.00113228","product_id":"BTC-EUR","sequence":3257977547,"time":"2018-01-22T15:14:36.333000Z"}
{"type":"done","side":"sell","order_id":"84c81b3f-4825-41f0-b2c2-5c902ce48245","reason":"canceled","product_id":"BTC-EUR","price":"8831.44000000","remaining_size":"0.10500000","sequence":3257977548,"time":"2018-01-22T15:14:36.342000Z"}
{"type":"received","order_id":"ab4f92d9-9ce0-41f3-b23c-aacc5ef30e3b","order_type":"limit","size":"0.05000000","price":"8831.39000000","side":"sell","client_oid":"348d2536-ffe9-44a0-9858-b6e3ca2f76ce","product_id":"BTC-EUR","sequence":3257977549,"time":"2018-01-22T15:14:36.348000Z"}
{"type":"open","side":"sell","price":"8831.39000000","order_id":"ab4f92d9-9ce0-41f3-b23c-aacc5ef30e3b","remaining_size":"0.05000000","product_id":"BTC-EUR","sequence":3257977550,"time":"2018-01-22T15:14:36.348000Z"}
{"type":"received","order_id":"337ad448-2cc3-49fb-9de5-8e405c156501","order_type":"limit","size":"0.00113344","price":"8822.64000000","side":"buy","client_oid":"0a81aad9-4b2a-4b11-9ddf-8ad798f05e7e","product_id":"BTC-EUR","sequence":3257977551,"time":"2018-01-22T15:14:36.360000Z"}
{"type":"open","side":"buy","price":"8822.64000000","order_id":"337ad448-2cc3-49fb-9de5-8e405c156501","remaining_size":"0.00113344","product_id":"BTC-EUR","sequence":3257977552,"time":"2018-01-22T15:14:36.360000Z"}
{"type":"done","side":"sell","order_id":"7588674b-ddb1-4a6d-a1cd-1f58259bd58f","reason":"canceled","product_id":"BTC-EUR","price":"8831.40000000","remaining_size":"0.00113228","sequence":3257977553,"time":"2018-01-22T15:14:36.379000Z"}
{"type":"done","side":"sell","order_id":"e5469089-c4d2-47be-b6ee-67bd339a7403","reason":"canceled","product_id":"BTC-EUR","price":"8831.43000000","remaining_size":"0.10500000","sequence":3257977554,"time":"2018-01-22T15:14:36.386000Z"}
{"type":"received","order_id":"e31687bb-ad94-40e0-bd13-53f15fa26033","order_type":"limit","size":"0.10500000","price":"8831.43000000","side":"sell","client_oid":"5a894150-b853-4fe0-8625-4474acbd2fb2","product_id":"BTC-EUR","sequence":3257977555,"time":"2018-01-22T15:14:36.393000Z"}
{"type":"open","side":"sell","price":"8831.43000000","order_id":"e31687bb-ad94-40e0-bd13-53f15fa26033","remaining_size":"0.10500000","product_id":"BTC-EUR","sequence":3257977556,"time":"2018-01-22T15:14:36.393000Z"}
{"type":"done","side":"sell","order_id":"284a59fa-4804-465f-9334-1dce018ae5eb","reason":"canceled","product_id":"BTC-EUR","price":"8831.40000000","remaining_size":"0.09800000","sequence":3257977557,"time":"2018-01-22T15:14:36.426000Z"}
{"type":"received","order_id":"43e7e882-369a-467b-81f9-6f2f28aebeec","order_type":"limit","size":"0.00113000","price":"8851.83000000","side":"sell","product_id":"BTC-EUR","sequence":3257977558,"time":"2018-01-22T15:14:36.429000Z"}
{"type":"open","side":"sell","price":"8851.83000000","order_id":"43e7e882-369a-467b-81f9-6f2f28aebeec","remaining_size":"0.00113000","product_id":"BTC-EUR","sequence":3257977559,"time":"2018-01-22T15:14:36.429000Z"}
{"type":"done","side":"buy","order_id":"337ad448-2cc3-49fb-9de5-8e405c156501","reason":"canceled","product_id":"BTC-EUR","price":"8822.64000000","remaining_size":"0.00113344","sequence":3257977560,"time":"2018-01-22T15:14:36.445000Z"}
{"type":"done","side":"sell","order_id":"11624d6e-bd11-4c03-a7f6-da6e99bb5431","reason":"canceled","product_id":"BTC-EUR","price":"8849.05000000","remaining_size":"0.18458699","sequence":3257977561,"time":"2018-01-22T15:14:36.461000Z"}
{"type":"done","side":"sell","order_id":"e31687bb-ad94-40e0-bd13-53f15fa26033","reason":"canceled","product_id":"BTC-EUR","price":"8831.43000000","remaining_size":"0.10500000","sequence":3257977562,"time":"2018-01-22T15:14:36.472000Z"}
{"type":"received","order_id":"6fe11748-bfc9-4939-a5e8-ba02068e8022","order_type":"limit","size":"0.09800000","price":"8831.38000000","side":"sell","client_oid":"39985b4e-cb9e-4aae-b1a0-ec063680b391","product_id":"BTC-EUR","sequence":3257977563,"time":"2018-01-22T15:14:36.476000Z"}
{"type":"open","side":"sell","price":"8831.38000000","order_id":"6fe11748-bfc9-4939-a5e8-ba02068e8022","remaining_size":"0.09800000","product_id":"BTC-EUR","sequence":3257977564,"time":"2018-01-22T15:14:36.476000Z"}
{"type":"received","order_id":"2484b908-9d13-4f5c-b3a9-fc3fb60628c7","order_type":"limit","size":"0.00113228","price":"8831.38000000","side":"sell","client_oid":"d5492347-9643-42df-9911-d17b16b93bdc","product_id":"BTC-EUR","sequence":3257977565,"time":"2018-01-22T15:14:36.480000Z"}
{"type":"open","side":"sell","price":"8831.38000000","order_id":"2484b908-9d13-4f5c-b3a9-fc3fb60628c7","remaining_size":"0.00113228","product_id":"BTC-EUR","sequence":3257977566,"time":"2018-01-22T15:14:36.480000Z"}
{"type":"received","order_id":"2caad14f-73cc-44e2-942c-5bbb910a047a","order_type":"limit","size":"0.00113344","price":"8822.64000000","side":"buy","client_oid":"7cde082a-84b3-4018-9d59-ff513a64df3a","product_id":"BTC-EUR","sequence":3257977567,"time":"2018-01-22T15:14:36.487000Z"}
{"type":"open","side":"buy","price":"8822.64000000","order_id":"2caad14f-73cc-44e2-942c-5bbb910a047a","remaining_size":"0.00113344","product_id":"BTC-EUR","sequence":3257977568,"time":"2018-01-22T15:14:36.487000Z"}
{"type":"done","side":"sell","order_id":"2484b908-9d13-4f5c-b3a9-fc3fb60628c7","reason":"canceled","product_id":"BTC-EUR","price":"8831.38000000","remaining_size":"0.00113228","sequence":3257977569,"time":"2018-01-22T15:14:36.495000Z"}
{"type":"received","order_id":"1ab6a8e1-cf19-4970-ac2f-732721d40b29","order_type":"limit","size":"0.46140359","price":"8850.28000000","side":"sell","client_oid":"fe10a8a9-c9ff-471a-87dd-557a06985a98","product_id":"BTC-EUR","sequence":3257977570,"time":"2018-01-22T15:14:36.502000Z"}
{"type":"open","side":"sell","price":"8850.28000000","order_id":"1ab6a8e1-cf19-4970-ac2f-732721d40b29","remaining_size":"0.46140359","product_id":"BTC-EUR","sequence":3257977571,"time":"2018-01-22T15:14:36.502000Z"}
{"type":"done","side":"sell","order_id":"ab4f92d9-9ce0-41f3-b23c-aacc5ef30e3b","reason":"canceled","product_id":"BTC-EUR","price":"8831.39000000","remaining_size":"0.05000000","sequence":3257977572,"time":"2018-01-22T15:14:36.503000Z"}
{"type":"received","order_id":"e9c8a829-a406-4e04-ba1a-183f2eee63e5","order_type":"limit","size":"0.10500000","price":"8831.39000000","side":"sell","client_oid":"ff71942b-6aac-44f1-94fb-9800fbaa4bf1","product_id":"BTC-EUR","sequence":3257977573,"time":"2018-01-22T15:14:36.522000Z"}
{"type":"open","side":"sell","price":"8831.39000000","order_id":"e9c8a829-a406-4e04-ba1a-183f2eee63e5","remaining_size":"0.10500000","product_id":"BTC-EUR","sequence":3257977574,"time":"2018-01-22T15:14:36.522000Z"}
{"type":"received","order_id":"cc0b5966-d496-4bfc-82a8-0fe091720b36","order_type":"limit","size":"0.05000000","price":"8831.37000000","side":"sell","client_oid":"ea659d0d-27b9-43a7-af9a-04a5a0e7abf0","product_id":"BTC-EUR","sequence":3257977575,"time":"2018-01-22T15:14:36.533000Z"}
{"type":"open","side":"sell","price":"8831.37000000","order_id":"cc0b5966-d496-4bfc-82a8-0fe091720b36","remaining_size":"0.05000000","product_id":"BTC-EUR","sequence":3257977576,"time":"2018-01-22T15:14:36.533000Z"}
{"type":"done","side":"buy","order_id":"2caad14f-73cc-44e2-942c-5bbb910a047a","reason":"canceled","product_id":"BTC-EUR","price":"8822.64000000","remaining_size":"0.00113344","sequence":3257977577,"time":"2018-01-22T15:14:36.535000Z"}
{"type":"done","side":"sell","order_id":"65a02099-f490-4e07-ae82-3d72f172f673","reason":"canceled","product_id":"BTC-EUR","price":"8831.47000000","remaining_size":"0.04164971","sequence":3257977578,"time":"2018-01-22T15:14:36.538000Z"}
{"type":"received","order_id":"728816b2-57c6-44f7-8ba3-e87ae1726465","order_type":"limit","size":"0.04257882","price":"8823.40000000","side":"buy","product_id":"BTC-EUR","sequence":3257977579,"time":"2018-01-22T15:14:36.557000Z"}
{"type":"open","side":"buy","price":"8823.40000000","order_id":"728816b2-57c6-44f7-8ba3-e87ae1726465","remaining_size":"0.04257882","product_id":"BTC-EUR","sequence":3257977580,"time":"2018-01-22T15:14:36.557000Z"}
{"type":"done","side":"buy","order_id":"4c58d41c-7aa2-453f-925a-f1e31fb3dc63","reason":"canceled","product_id":"BTC-EUR","price":"8821.04000000","remaining_size":"0.02000000","sequence":3257977581,"time":"2018-01-22T15:14:36.562000Z"}
{"type":"received","order_id":"c9fda62d-934f-42ca-a555-4e3a5e18974a","order_type":"limit","size":"0.00113228","price":"8831.37000000","side":"sell","client_oid":"356a8359-45dc-4298-91d2-bc9eda2e810a","product_id":"BTC-EUR","sequence":3257977582,"time":"2018-01-22T15:14:36.564000Z"}
{"type":"open","side":"sell","price":"8831.37000000","order_id":"c9fda62d-934f-42ca-a555-4e3a5e18974a","remaining_size":"0.00113228","product_id":"BTC-EUR","sequence":3257977583,"time":"2018-01-22T15:14:36.564000Z"}
{"type":"done","side":"sell","order_id":"e9c8a829-a406-4e04-ba1a-183f2eee63e5","reason":"canceled","product_id":"BTC-EUR","price":"8831.39000000","remaining_size":"0.10500000","sequence":3257977584,"time":"2018-01-22T15:14:36.602000Z"}
{"type":"done","side":"sell","order_id":"6fe11748-bfc9-4939-a5e8-ba02068e8022","reason":"canceled","product_id":"BTC-EUR","price":"8831.38000000","remaining_size":"0.09800000","sequence":3257977585,"time":"2018-01-22T15:14:36.610000Z"}
{"type":"done","side":"sell","order_id":"cc0b5966-d496-4bfc-82a8-0fe091720b36","reason":"canceled","product_id":"BTC-EUR","price":"8831.37000000","remaining_size":"0.05000000","sequence":3257977586,"time":"2018-01-22T15:14:36.620000Z"}
{"type":"received","order_id":"959b7a82-e8a4-435a-b02f-2c6d9f3e0aeb","order_type":"limit","size":"0.10500000","price":"8831.38000000","side":"sell","client_oid":"c90290a6-0dac-41a3-8422-1569787fd2f1","product_id":"BTC-EUR","sequence":3257977587,"time":"2018-01-22T15:14:36.674000Z"}
{"type":"open","side":"sell","price":"8831.38000000","order_id":"959b7a82-e8a4-435a-b02f-2c6d9f3e0aeb","remaining_size":"0.10500000","product_id":"BTC-EUR","sequence":3257977588,"time":"2018-01-22T15:14:36.674000Z"}
{"type":"received","order_id":"4c097b6b-0107-4fc6-8913-5240c9758953","order_type":"limit","size":"0.21404538","price":"8831.37000000","side":"sell","product_id":"BTC-EUR","sequence":3257977589,"time":"2018-01-22T15:14:36.675000Z"}
{"type":"open","side":"sell","price":"8831.37000000","order_id":"4c097b6b-0107-4fc6-8913-5240c9758953","remaining_size":"0.21404538","product_id":"BTC-EUR","sequence":3257977590,"time":"2018-01-22T15:14:36.675000Z"}
{"type":"received","order_id":"d419ffd1-e522-468c-a06b-4c461b8843c1","order_type":"limit","size":"0.00113344","price":"8822.64000000","side":"buy","client_oid":"af71d9ad-f8ad-46d6-bd85-1cc3e9972d37","product_id":"BTC-EUR","sequence":3257977591,"time":"2018-01-22T15:14:36.677000Z"}
{"type":"open","side":"buy","price":"8822.64000000","order_id":"d419ffd1-e522-468c-a06b-4c461b8843c1","remaining_size":"0.00113344","product_id":"BTC-EUR","sequence":3257977592,"time":"2018-01-22T15:14:36.677000Z"}
{"type":"received","order_id":"3b53e332-8b55-4785-8b58-93db59304607","order_type":"limit","size":"0.10500000","price":"8831.38000000","side":"sell","client_oid":"94fc124a-78f9-4e6e-8c1d-0a803b76b731","product_id":"BTC-EUR","sequence":3257977593,"time":"2018-01-22T15:14:36.679000Z"}
{"type":"open","side":"sell","price":"8831.38000000","order_id":"3b53e332-8b55-4785-8b58-93db59304607","remaining_size":"0.10500000","product_id":"BTC-EUR","sequence":3257977594,"time":"2018-01-22T15:14:36.679000Z"}
{"type":"done","side":"buy","order_id":"d419ffd1-e522-468c-a06b-4c461b8843c1","reason":"canceled","product_id":"BTC-EUR","price":"8822.64000000","remaining_size":"0.00113344","sequence":3257977595,"time":"2018-01-22T15:14:36.681000Z"}
{"type":"done","side":"sell","order_id":"5f2016c4-4b2f-46fc-8e44-9ab1f12d3762","reason":"canceled","product_id":"BTC-EUR","price":"8831.46000000","remaining_size":"0.08000000","sequence":3257977596,"time":"2018-01-22T15:14:36.689000Z"}
{"type":"received","order_id":"ef0359f7-0568-4215-a63a-356dc96cb949","order_type":"limit","size":"0.09800000","price":"8831.37000000","side":"sell","client_oid":"a71a1d5d-d272-46a0-8a2f-129194d0aff7","product_id":"BTC-EUR","sequence":3257977597,"time":"2018-01-22T15:14:36.699000Z"}
{"type":"open","side":"sell","price":"8831.37000000","order_id":"ef0359f7-0568-4215-a63a-356dc96cb949","remaining_size":"0.09800000","product_id":"BTC-EUR","sequence":3257977598,"time":"2018-01-22T15:14:36.699000Z"}
{"type":"received","order_id":"4c43fc45-8347-4ef6-bafb-5a33b229912f","order_type":"limit","size":"0.02000000","price":"8823.41000000","side":"buy","client_oid":"f9045e48-3259-4e8a-93f4-a22a7d19cee6","product_id":"BTC-EUR","sequence":3257977599,"time":"2018-01-22T15:14:36.699000Z"}
{"type":"open","side":"buy","price":"8823.41000000","order_id":"4c43fc45-8347-4ef6-bafb-5a33b229912f","remaining_size":"0.02000000","product_id":"BTC-EUR","sequence":3257977600,"time":"2018-01-22T15:14:36.699000Z"}
{"type":"received","order_id":"afd271af-2bb2-40fc-87f8-e381b1bbabd7","order_type":"limit","size":"0.00600000","price":"8831.37000000","side":"sell","client_oid":"1de235cb-9af2-4d48-a74e-5896da25248c","product_id":"BTC-EUR","sequence":3257977601,"time":"2018-01-22T15:14:36.709000Z"}
{"type":"open","side":"sell","price":"8831.37000000","order_id":"afd271af-2bb2-40fc-87f8-e381b1bbabd7","remaining_size":"0.00600000","product_id":"BTC-EUR","sequence":3257977602,"time":"2018-01-22T15:14:36.709000Z"}
{"type":"received","order_id":"5fc19d90-2802-4893-ba7a-be8e1a420870","order_type":"limit","size":"0.05000000","price":"8831.42000000","side":"sell","client_oid":"8a4cbe9c-8975-4db6-877e-3d51d003e0e5","product_id":"BTC-EUR","sequence":3257977603,"time":"2018-01-22T15:14:36.721000Z"}
{"type":"open","side":"sell","price":"8831.42000000","order_id":"5fc19d90-2802-4893-ba7a-be8e1a420870","remaining_size":"0.05000000","product_id":"BTC-EUR","sequence":3257977604,"time":"2018-01-22T15:14:36.721000Z"}
{"type":"received","order_id":"ad136c2c-f28f-49d2-9887-e1aac357d38a","order_type":"limit","size":"0.08000000","price":"8831.36000000","side":"sell","client_oid":"45982b2d-32ca-45ca-9024-aa9273d6c5f8","product_id":"BTC-EUR","sequence":3257977605,"time":"2018-01-22T15:14:36.725000Z"}
{"type":"open","side":"sell","price":"8831.36000000","order_id":"ad136c2c-f28f-49d2-9887-e1aac357d38a","remaining_size":"0.08000000","product_id":"BTC-EUR","sequence":3257977606,"time":"2018-01-22T15:14:36.725000Z"}
{"type":"received","order_id":"38a3a871-21d5-473b-b5c9-d068143e36a8","order_type":"limit","size":"0.00113334","price":"8823.41000000","side":"buy","client_oid":"25fb70dc-ac4f-4837-a1fd-ed60abf521c8","product_id":"BTC-EUR","sequence":3257977607,"time":"2018-01-22T15:14:36.728000Z"}
{"type":"open","side":"buy","price":"8823.41000000","order_id":"38a3a871-21d5-473b-b5c9-d068143e36a8","remaining_size":"0.00113334","product_id":"BTC-EUR","sequence":3257977608,"time":"2018-01-22T15:14:36.728000Z"}
{"type":"received","order_id":"58301ab5-45a7-4211-b20f-b9f349ee7df7","order_type":"limit","size":"0.18458699","price":"8849.05000000","side":"sell","client_oid":"6cf83d1d-c7b9-443d-87ee-787270b7f3e9","product_id":"BTC-EUR","sequence":3257977609,"time":"2018-01-22T15:14:36.729000Z"}
{"type":"open","side":"sell","price":"8849.05000000","order_id":"58301ab5-45a7-4211-b20f-b9f349ee7df7","remaining_size":"0.18458699","product_id":"BTC-EUR","sequence":3257977610,"time":"2018-01-22T15:14:36.729000Z"}
{"type":"done","side":"buy","order_id":"4c43fc45-8347-4ef6-bafb-5a33b229912f","reason":"canceled","product_id":"BTC-EUR","price":"8823.41000000","remaining_size":"0.02000000","sequence":3257977611,"time":"2018-01-22T15:14:36.740000Z"}
{"type":"done","side":"sell","order_id":"c9fda62d-934f-42ca-a555-4e3a5e18974a","reason":"canceled","product_id":"BTC-EUR","price":"8831.37000000","remaining_size":"0.00113228","sequence":3257977612,"time":"2018-01-22T15:14:36.740000Z"}
{"type":"done","side":"sell","order_id":"5fc19d90-2802-4893-ba7a-be8e1a420870","reason":"canceled","product_id":"BTC-EUR","price":"8831.42000000","remaining_size":"0.05000000","sequence":3257977613,"time":"2018-01-22T15:14:36.747000Z"}
{"type":"done","side":"sell","order_id":"3b53e332-8b55-4785-8b58-93db59304607","reason":"canceled","product_id":"BTC-EUR","price":"8831.38000000","remaining_size":"0.10500000","sequence":3257977614,"time":"2018-01-22T15:14:36.758000Z"}
{"type":"received","order_id":"634d678f-a4aa-46d2-ab49-cda2599990de","order_type":"limit","size":"0.02000000","price":"8823.41000000","side":"buy","client_oid":"2e4e108f-cb08-4749-90bb-1a9c69edcd59","product_id":"BTC-EUR","sequence":3257977615,"time":"2018-01-22T15:14:36.768000Z"}
{"type":"open","side":"buy","price":"8823.41000000","order_id":"634d678f-a4aa-46d2-ab49-cda2599990de","remaining_size":"0.02000000","product_id":"BTC-EUR","sequence":3257977616,"time":"2018-01-22T15:14:36.768000Z"}
{"type":"done","side":"buy","order_id":"634d678f-a4aa-46d2-ab49-cda2599990de","reason":"canceled","product_id":"BTC-EUR","price":"8823.41000000","remaining_size":"0.02000000","sequence":3257977617,"time":"2018-01-22T15:14:36.781000Z"}
{"type":"received","order_id":"84e3d3f4-2150-4bb1-a846-f3786b55cca1","order_type":"limit","size":"0.00113228","price":"8831.35000000","side":"sell","client_oid":"95b7f19a-81c3-40fa-be00-593a2942bef3","product_id":"BTC-EUR","sequence":3257977618,"time":"2018-01-22T15:14:36.787000Z"}
{"type":"open","side":"sell","price":"8831.35000000","order_id":"84e3d3f4-2150-4bb1-a846-f3786b55cca1","remaining_size":"0.00113228","product_id":"BTC-EUR","sequence":3257977619,"time":"2018-01-22T15:14:36.787000Z"}
{"type":"received","order_id":"2cca18a5-fa66-40fa-80e1-167ca44d0ed4","order_type":"limit","size":"0.05000000","price":"8831.35000000","side":"sell","client_oid":"ed53a86e-9cb3-4c92-abe9-54d6c5fb89fd","product_id":"BTC-EUR","sequence":3257977620,"time":"2018-01-22T15:14:36.788000Z"}
{"type":"open","side":"sell","price":"8831.35000000","order_id":"2cca18a5-fa66-40fa-80e1-167ca44d0ed4","remaining_size":"0.05000000","product_id":"BTC-EUR","sequence":3257977621,"time":"2018-01-22T15:14:36.788000Z"}
{"type":"received","order_id":"159b1c72-208b-4570-83dc-f347592389ab","order_type":"limit","size":"0.04164971","price":"8831.35000000","side":"sell","client_oid":"97fa21af-ba33-4747-89c2-08b5e79df908","product_id":"BTC-EUR","sequence":3257977622,"time":"2018-01-22T15:14:36.791000Z"}
{"type":"open","side":"sell","price":"8831.35000000","order_id":"159b1c72-208b-4570-83dc-f347592389ab","remaining_size":"0.04164971","product_id":"BTC-EUR","sequence":3257977623,"time":"2018-01-22T15:14:36.791000Z"}
{"type":"received","order_id":"7c4f7f64-a488-49e5-9d07-ba115f977292","order_type":"limit","size":"0.02000000","price":"8823.41000000","side":"buy","client_oid":"7c4688a7-4596-44a3-ab45-d30ffa69407b","product_id":"BTC-EUR","sequence":3257977624,"time":"2018-01-22T15:14:36.800000Z"}
{"type":"open","side":"buy","price":"8823.41000000","order_id":"7c4f7f64-a488-49e5-9d07-ba115f977292","remaining_size":"0.02000000","product_id":"BTC-EUR","sequence":3257977625,"time":"2018-01-22T15:14:36.800000Z"}
{"type":"done","side":"sell","order_id":"959b7a82-e8a4-435a-b02f-2c6d9f3e0aeb","reason":"canceled","product_id":"BTC-EUR","price":"8831.38000000","remaining_size":"0.10500000","sequence":3257977626,"time":"2018-01-22T15:14:36.802000Z"}
{"type":"received","order_id":"c57b052c-bc0f-4e5c-916c-e2847ea8118a","order_type":"limit","size":"0.10500000","price":"8831.37000000","side":"sell","client_oid":"3d67376c-177c-4c5b-b599-b2ff836ec627","product_id":"BTC-EUR","sequence":3257977627,"time":"2018-01-22T15:14:36.810000Z"}
{"type":"open","side":"sell","price":"8831.37000000","order_id":"c57b052c-bc0f-4e5c-916c-e2847ea8118a","remaining_size":"0.10500000","product_id":"BTC-EUR","sequence":3257977628,"time":"2018-01-22T15:14:36.810000Z"}
{"type":"received","order_id":"b43109b4-76b6-459c-a164-a7610e9472eb","order_type":"limit","size":"3.30000000","price":"8891.47000000","side":"sell","client_oid":"5738ae9c-e364-41a6-d654-3f768612732a","product_id":"BTC-EUR","sequence":3257977629,"time":"2018-01-22T15:14:36.829000Z"}
{"type":"open","side":"sell","price":"8891.47000000","order_id":"b43109b4-76b6-459c-a164-a7610e9472eb","remaining_size":"3.30000000","product_id":"BTC-EUR","sequence":3257977630,"time":"2018-01-22T15:14:36.829000Z"}
{"type":"done","side":"sell","order_id":"ef0359f7-0568-4215-a63a-356dc96cb949","reason":"canceled","product_id":"BTC-EUR","price":"8831.37000000","remaining_size":"0.09800000","sequence":3257977631,"time":"2018-01-22T15:14:36.832000Z"}
{"type":"received","order_id":"5c25a07c-3dee-41fc-8376-41ff4e16cd22","order_type":"limit","size":"0.09800000","price":"8831.35000000","side":"sell","client_oid":"5d54e205-9d33-4a45-8135-3c9f990ab9ee","product_id":"BTC-EUR","sequence":3257977632,"time":"2018-01-22T15:14:36.853000Z"}
{"type":"open","side":"sell","price":"8831.35000000","order_id":"5c25a07c-3dee-41fc-8376-41ff4e16cd22","remaining_size":"0.09800000","product_id":"BTC-EUR","sequence":3257977633,"time":"2018-01-22T15:14:36.853000Z"}
{"type":"done","side":"sell","order_id":"afd271af-2bb2-40fc-87f8-e381b1bbabd7","reason":"canceled","product_id":"BTC-EUR","price":"8831.37000000","remaining_size":"0.00600000","sequence":3257977634,"time":"2018-01-22T15:14:36.856000Z"}
{"type":"received","order_id":"19cd9784-c2c8-462c-9a85-cdb869824da2","order_type":"limit","size":"1.28000000","price":"9114.10000000","side":"sell","product_id":"BTC-EUR","sequence":3257977635,"time":"2018-01-22T15:14:36.861000Z"}
{"type":"open","side":"sell","price":"9114.10000000","order_id":"19cd9784-c2c8-462c-9a85-cdb869824da2","remaining_size":"1.28000000","product_id":"BTC-EUR","sequence":3257977636,"time":"2018-01-22T15:14:36.861000Z"}
{"type":"done","side":"sell","order_id":"ad136c2c-f28f-49d2-9887-e1aac357d38a","reason":"canceled","product_id":"BTC-EUR","price":"8831.36000000","remaining_size":"0.08000000","sequence":3257977637,"time":"2018-01-22T15:14:36.869000Z"}
{"type":"done","side":"sell","order_id":"4c097b6b-0107-4fc6-8913-5240c9758953","reason":"canceled","product_id":"BTC-EUR","price":"8831.37000000","remaining_size":"0.21404538","sequence":3257977638,"time":"2018-01-22T15:14:36.885000Z"}
{"type":"received","order_id":"e965a9f5-abc8-4c17-b8bd-b5e8287a4623","order_type":"limit","size":"0.08000000","price":"8831.34000000","side":"sell","client_oid":"b7d816c3-a823-45bd-a5bb-afc0e933907e","product_id":"BTC-EUR","sequence":3257977639,"time":"2018-01-22T15:14:36.889000Z"}
{"type":"open","side":"sell","price":"8831.34000000","order_id":"e965a9f5-abc8-4c17-b8bd-b5e8287a4623","remaining_size":"0.08000000","product_id":"BTC-EUR","sequence":3257977640,"time":"2018-01-22T15:14:36.889000Z"}
{"type":"done","side":"sell","order_id":"badd8044-0d09-4b86-b912-7b92b52d3c4c","reason":"canceled","product_id":"BTC-EUR","price":"8831.43000000","remaining_size":"0.01322632","sequence":3257977641,"time":"2018-01-22T15:14:36.889000Z"}
{"type":"done","side":"sell","order_id":"84e3d3f4-2150-4bb1-a846-f3786b55cca1","reason":"canceled","product_id":"BTC-EUR","price":"8831.35000000","remaining_size":"0.00113228","sequence":3257977642,"time":"2018-01-22T15:14:36.893000Z"}
{"type":"done","side":"sell","order_id":"2cca18a5-fa66-40fa-80e1-167ca44d0ed4","reason":"canceled","product_id":"BTC-EUR","price":"8831.35000000","remaining_size":"0.05000000","sequence":3257977643,"time":"2018-01-22T15:14:36.894000Z"}
{"type":"done","side":"sell","order_id":"c57b052c-bc0f-4e5c-916c-e2847ea8118a","reason":"canceled","product_id":"BTC-EUR","price":"8831.37000000","remaining_size":"0.10500000","sequence":3257977644,"time":"2018-01-22T15:14:36.902000Z"}
{"type":"done","side":"sell","order_id":"6472e6b9-f105-4aa7-b941-b9973c2d92c6","reason":"canceled","product_id":"BTC-EUR","price":"8831.43000000","remaining_size":"0.22947933","sequence":3257977645,"time":"2018-01-22T15:14:36.934000Z"}
{"type":"received","order_id":"42f4e9ba-3e8f-44a2-945d-8ede582ab0ab","order_type":"limit","size":"0.00113228","price":"8831.33000000","side":"sell","client_oid":"5b742f26-6bb6-4bd0-aff4-b976df7a0466","product_id":"BTC-EUR","sequence":3257977646,"time":"2018-01-22T15:14:36.940000Z"}
{"type":"open","side":"sell","price":"8831.33000000","order_id":"42f4e9ba-3e8f-44a2-945d-8ede582ab0ab","remaining_size":"0.00113228","product_id":"BTC-EUR","sequence":3257977647,"time":"2018-01-22T15:14:36.940000Z"}
{"type":"received","order_id":"f21e8cdf-f66e-4592-879d-ebb07e28fad5","order_type":"limit","size":"0.05000000","price":"8831.33000000","side":"sell","client_oid":"e0670ead-784d-40f6-b79e-dca5dc903a23","product_id":"BTC-EUR","sequence":3257977648,"time":"2018-01-22T15:14:36.950000Z"}
{"type":"open","side":"sell","price":"8831.33000000","order_id":"f21e8cdf-f66e-4592-879d-ebb07e28fad5","remaining_size":"0.05000000","product_id":"BTC-EUR","sequence":3257977649,"time":"2018-01-22T15:14:36.950000Z"}
{"type":"received","order_id":"5b8d1024-91cc-46c1-b3fa-201376010b05","order_type":"limit","size":"0.10500000","price":"8831.35000000","side":"sell","client_oid":"a61eedd3-a4a0-47d6-955a-be5e78106dce","product_id":"BTC-EUR","sequence":3257977650,"time":"2018-01-22T15:14:36.954000Z"}
{"type":"open","side":"sell","price":"8831.35000000","order_id":"5b8d1024-91cc-46c1-b3fa-201376010b05","remaining_size":"0.10500000","product_id":"BTC-EUR","sequence":3257977651,"time":"2018-01-22T15:14:36.954000Z"}
{"type":"done","side":"sell","order_id":"5c25a07c-3dee-41fc-8376-41ff4e16cd22","reason":"canceled","product_id":"BTC-EUR","price":"8831.35000000","remaining_size":"0.09800000","sequence":3257977652,"time":"2018-01-22T15:14:36.967000Z"}
{"type":"done","side":"sell","order_id":"65b1f7ee-66f3-4016-ab2b-87dcb225331e","reason":"canceled","product_id":"BTC-EUR","price":"8831.69000000","remaining_size":"0.02755676","sequence":3257977653,"time":"2018-01-22T15:14:36.985000Z"}
{"type":"done","side":"sell","order_id":"e965a9f5-abc8-4c17-b8bd-b5e8287a4623","reason":"canceled","product_id":"BTC-EUR","price":"8831.34000000","remaining_size":"0.08000000","sequence":3257977654,"time":"2018-01-22T15:14:37.018000Z"}
{"type":"received","order_id":"9ae3df22-a295-4bc5-a627-f76035882fa8","order_type":"limit","size":"0.09800000","price":"8831.33000000","side":"sell","client_oid":"a5f59c9a-bb4f-45ba-a401-9885e2cac81d","product_id":"BTC-EUR","sequence":3257977655,"time":"2018-01-22T15:14:37.029000Z"}
{"type":"open","side":"sell","price":"8831.33000000","order_id":"9ae3df22-a295-4bc5-a627-f76035882fa8","remaining_size":"0.09800000","product_id":"BTC-EUR","sequence":3257977656,"time":"2018-01-22T15:14:37.029000Z"}
{"type":"done","side":"sell","order_id":"5b8d1024-91cc-46c1-b3fa-201376010b05","reason":"canceled","product_id":"BTC-EUR","price":"8831.35000000","remaining_size":"0.10500000","sequence":3257977657,"time":"2018-01-22T15:14:37.033000Z"}
{"type":"received","order_id":"7135aafa-00db-4acb-9a9b-7779d1e67813","order_type":"limit","size":"0.08000000","price":"8831.32000000","side":"sell","client_oid":"03c10036-410e-4acd-b351-361da4ffdf7f","product_id":"BTC-EUR","sequence":3257977658,"time":"2018-01-22T15:14:37.039000Z"}
{"type":"open","side":"sell","price":"8831.32000000","order_id":"7135aafa-00db-4acb-9a9b-7779d1e67813","remaining_size":"0.08000000","product_id":"BTC-EUR","sequence":3257977659,"time":"2018-01-22T15:14:37.039000Z"}
{"type":"done","side":"sell","order_id":"f21e8cdf-f66e-4592-879d-ebb07e28fad5","reason":"canceled","product_id":"BTC-EUR","price":"8831.33000000","remaining_size":"0.05000000","sequence":3257977660,"time":"2018-01-22T15:14:37.052000Z"}
{"type":"done","side":"buy","order_id":"7510c945-1cc4-40b5-abba-854234f982e9","reason":"canceled","product_id":"BTC-EUR","price":"8810.00000000","remaining_size":"0.15051169","sequence":3257977661,"time":"2018-01-22T15:14:37.061000Z"}
{"type":"done","side":"sell","order_id":"42f4e9ba-3e8f-44a2-945d-8ede582ab0ab","reason":"canceled","product_id":"BTC-EUR","price":"8831.33000000","remaining_size":"0.00113228","sequence":3257977662,"time":"2018-01-22T15:14:37.061000Z"}
{"type":"received","order_id":"383097ff-cb1f-4e5b-9bd6-8b0ae823a8c0","order_type":"limit","size":"0.05000000","price":"8831.31000000","side":"sell","client_oid":"936f71f4-b5a9-4c94-86cb-8c2b9141e472","product_id":"BTC-EUR","sequence":3257977663,"time":"2018-01-22T15:14:37.078000Z"}
{"type":"open","side":"sell","price":"8831.31000000","order_id":"383097ff-cb1f-4e5b-9bd6-8b0ae823a8c0","remaining_size":"0.05000000","product_id":"BTC-EUR","sequence":3257977664,"time":"2018-01-22T15:14:37.078000Z"}
{"type":"received","order_id":"13201394-3d50-4e57-9317-580b104359ec","order_type":"limit","size":"0.10500000","price":"8831.33000000","side":"sell","client_oid":"9f807eab-6dbc-460f-8d16-895988a0cfdc","product_id":"BTC-EUR","sequence":3257977665,"time":"2018-01-22T15:14:37.091000Z"}
{"type":"open","side":"sell","price":"8831.33000000","order_id":"13201394-3d50-4e57-9317-580b104359ec","remaining_size":"0.10500000","product_id":"BTC-EUR","sequence":3257977666,"time":"2018-01-22T15:14:37.091000Z"}
{"type":"received","order_id":"36fa5fc9-7a7d-45af-bfc3-d2aa2c347e97","order_type":"limit","size":"0.10500000","price":"8831.33000000","side":"sell","client_oid":"bcae8a60-6e23-48f9-84fc-4cc3e417180e","product_id":"BTC-EUR","sequence":3257977667,"time":"2018-01-22T15:14:37.110000Z"}
{"type":"open","side":"sell","price":"8831.33000000","order_id":"36fa5fc9-7a7d-45af-bfc3-d2aa2c347e97","remaining_size":"0.10500000","product_id":"BTC-EUR","sequence":3257977668,"time":"2018-01-22T15:14:37.110000Z"}
{"type":"received","order_id":"ec92b3c8-6b12-438c-bfdf-99ad773be52b","order_type":"limit","size":"0.06847422","price":"8831.32000000","side":"sell","client_oid":"8d31cebd-17c3-4b7f-85fd-8d77422b4a6f","product_id":"BTC-EUR","sequence":3257977669,"time":"2018-01-22T15:14:37.111000Z"}
{"type":"open","side":"sell","price":"8831.32000000","order_id":"ec92b3c8-6b12-438c-bfdf-99ad773be52b","remaining_size":"0.06847422","product_id":"BTC-EUR","sequence":3257977670,"time":"2018-01-22T15:14:37.111000Z"}
{"type":"received","order_id":"d9cfc5fe-f8fd-41ff-b19f-a8ffdb2b1ec2","order_type":"limit","size":"0.02753599","price":"8831.50000000","side":"sell","product_id":"BTC-EUR","sequence":3257977671,"time":"2018-01-22T15:14:37.118000Z"}
{"type":"open","side":"sell","price":"8831.50000000","order_id":"d9cfc5fe-f8fd-41ff-b19f-a8ffdb2b1ec2","remaining_size":"0.02753599","product_id":"BTC-EUR","sequence":3257977672,"time":"2018-01-22T15:14:37.118000Z"}
{"type":"received","order_id":"ec755e54-ba05-4cae-b091-b98ff39c7db3","order_type":"limit","size":"0.01322632","price":"8831.32000000","side":"sell","client_oid":"d16470f9-cda9-431d-a085-b875d4a17f13","product_id":"BTC-EUR","sequence":3257977673,"time":"2018-01-22T15:14:37.119000Z"}
{"type":"open","side":"sell","price":"8831.32000000","order_id":"ec755e54-ba05-4cae-b091-b98ff39c7db3","remaining_size":"0.01322632","product_id":"BTC-EUR","sequence":3257977674,"time":"2018-01-22T15:14:37.119000Z"}
{"type":"received","order_id":"32b5079a-32a6-465e-8aff-9216e3fcfded","order_type":"limit","size":"0.09800000","price":"8831.32000000","side":"sell","client_oid":"7aa86dd5-613d-460a-866c-670116218c9b","product_id":"BTC-EUR","sequence":3257977675,"time":"2018-01-22T15:14:37.121000Z"}
{"type":"open","side":"sell","price":"8831.32000000","order_id":"32b5079a-32a6-465e-8aff-9216e3fcfded","remaining_size":"0.09800000","product_id":"BTC-EUR","sequence":3257977676,"time":"2018-01-22T15:14:37.121000Z"}
{"type":"done","side":"sell","order_id":"9ae3df22-a295-4bc5-a627-f76035882fa8","reason":"canceled","product_id":"BTC-EUR","price":"8831.33000000","remaining_size":"0.09800000","sequence":3257977677,"time":"2018-01-22T15:14:37.142000Z"}
{"type":"received","order_id":"27416d2d-0184-4a77-9f94-ad96fb5eb6e7","order_type":"limit","size":"0.22947933","price":"8831.32000000","side":"sell","client_oid":"e2171b07-63ed-4c1c-a777-dbe7df674e16","product_id":"BTC-EUR","sequence":3257977678,"time":"2018-01-22T15:14:37.149000Z"}
{"type":"open","side":"sell","price":"8831.32000000","order_id":"27416d2d-0184-4a77-9f94-ad96fb5eb6e7","remaining_size":"0.22947933","product_id":"BTC-EUR","sequence":3257977679,"time":"2018-01-22T15:14:37.149000Z"}
{"type":"done","side":"sell","order_id":"13201394-3d50-4e57-9317-580b104359ec","reason":"canceled","product_id":"BTC-EUR","price":"8831.33000000","remaining_size":"0.10500000","sequence":3257977680,"time":"2018-01-22T15:14:37.171000Z"}
{"type":"done","side":"buy","order_id":"0d3fede6-ff1b-4fe9-b558-0ce92414e7ab","reason":"canceled","product_id":"BTC-EUR","price":"8656.50000000","remaining_size":"1.89520000","sequence":3257977681,"time":"2018-01-22T15:14:37.181000Z"}
{"type":"done","side":"sell","order_id":"7135aafa-00db-4acb-9a9b-7779d1e67813","reason":"canceled","product_id":"BTC-EUR","price":"8831.32000000","remaining_size":"0.08000000","sequence":3257977682,"time":"2018-01-22T15:14:37.189000Z"}
{"type":"received","order_id":"b723a332-4d47-4e99-b6d2-6311fa4fbbcd","order_type":"limit","size":"0.14616719","price":"8997.24000000","side":"sell","product_id":"BTC-EUR","sequence":3257977683,"time":"2018-01-22T15:14:37.191000Z"}
{"type":"open","side":"sell","price":"8997.24000000","order_id":"b723a332-4d47-4e99-b6d2-6311fa4fbbcd","remaining_size":"0.14616719","product_id":"BTC-EUR","sequence":3257977684,"time":"2018-01-22T15:14:37.191000Z"}
{"type":"done","side":"sell","order_id":"32b5079a-32a6-465e-8aff-9216e3fcfded","reason":"canceled","product_id":"BTC-EUR","price":"8831.32000000","remaining_size":"0.09800000","sequence":3257977685,"time":"2018-01-22T15:14:37.198000Z"}
{"type":"received","order_id":"f4549843-aff9-4fb9-be47-74f585cdf285","order_type":"limit","size":"0.02000000","price":"9092.26000000","side":"buy","product_id":"BTC-EUR","sequence":3257977686,"time":"2018-01-22T15:14:37.200000Z"}
{"type":"match","trade_id":10551368,"maker_order_id":"383097ff-cb1f-4e5b-9bd6-8b0ae823a8c0","taker_order_id":"f4549843-aff9-4fb9-be47-74f585cdf285","side":"sell","size":"0.02000000","price":"8831.31000000","product_id":"BTC-EUR","sequence":3257977687,"time":"2018-01-22T15:14:37.200000Z"}
{"type":"done","side":"buy","order_id":"f4549843-aff9-4fb9-be47-74f585cdf285","reason":"filled","product_id":"BTC-EUR","price":"9092.26000000","remaining_size":"0.00000000","sequence":3257977688,"time":"2018-01-22T15:14:37.200000Z"}
{"type":"received","order_id":"2d17827d-cb76-4d3c-908a-366369714df1","order_type":"limit","size":"0.08000000","price":"8831.30000000","side":"sell","client_oid":"f46b2683-e674-456f-9b26-28969600f017","product_id":"BTC-EUR","sequence":3257977689,"time":"2018-01-22T15:14:37.202000Z"}
{"type":"open","side":"sell","price":"8831.30000000","order_id":"2d17827d-cb76-4d3c-908a-366369714df1","remaining_size":"0.08000000","product_id":"BTC-EUR","sequence":3257977690,"time":"2018-01-22T15:14:37.202000Z"}
{"type":"received","order_id":"48a8f3ea-a0df-47e3-8235-e37fc25550a0","order_type":"limit","size":"0.10500000","price":"8831.31000000","side":"sell","client_oid":"b335644b-2693-4b67-a816-31db518cac02","product_id":"BTC-EUR","sequence":3257977691,"time":"2018-01-22T15:14:37.205000Z"}
{"type":"open","side":"sell","price":"8831.31000000","order_id":"48a8f3ea-a0df-47e3-8235-e37fc25550a0","remaining_size":"0.10500000","product_id":"BTC-EUR","sequence":3257977692,"time":"2018-01-22T15:14:37.205000Z"}
{"type":"received","order_id":"63936700-8017-4383-aa37-cd479634f425","order_type":"limit","size":"0.00113228","price":"8831.31000000","side":"sell","client_oid":"55e17e2f-0b14-4896-95ba-ad0b8659a5eb","product_id":"BTC-EUR","sequence":3257977693,"time":"2018-01-22T15:14:37.212000Z"}
{"type":"open","side":"sell","price":"8831.31000000","order_id":"63936700-8017-4383-aa37-cd479634f425","remaining_size":"0.00113228","product_id":"BTC-EUR","sequence":3257977694,"time":"2018-01-22T15:14:37.212000Z"}
{"type":"done","side":"buy","order_id":"7c4f7f64-a488-49e5-9d07-ba115f977292","reason":"canceled","product_id":"BTC-EUR","price":"8823.41000000","remaining_size":"0.02000000","sequence":3257977695,"time":"2018-01-22T15:14:37.218000Z"}
{"type":"done","side":"sell","order_id":"36fa5fc9-7a7d-45af-bfc3-d2aa2c347e97","reason":"canceled","product_id":"BTC-EUR","price":"8831.33000000","remaining_size":"0.10500000","sequence":3257977696,"time":"2018-01-22T15:14:37.225000Z"}
{"type":"done","side":"sell","order_id":"383097ff-cb1f-4e5b-9bd6-8b0ae823a8c0","reason":"canceled","product_id":"BTC-EUR","price":"8831.31000000","remaining_size":"0.03000000","sequence":3257977697,"time":"2018-01-22T15:14:37.227000Z"}
{"type":"received","order_id":"c85a0891-4325-4117-8d07-5d2815aa5457","order_type":"limit","size":"0.10500000","price":"8831.31000000","side":"sell","client_oid":"38abc36a-ac6f-4ab5-8dd0-9434bd4f6c71","product_id":"BTC-EUR","sequence":3257977698,"time":"2018-01-22T15:14:37.232000Z"}
{"type":"open","side":"sell","price":"8831.31000000","order_id":"c85a0891-4325-4117-8d07-5d2815aa5457","remaining_size":"0.10500000","product_id":"BTC-EUR","sequence":3257977699,"time":"2018-01-22T15:14:37.232000Z"}
{"type":"done","side":"buy","order_id":"9ddd5e56-5c26-41ac-9e50-361f903f3869","reason":"canceled","product_id":"BTC-EUR","price":"8799.66000000","remaining_size":"0.13208615","sequence":3257977700,"time":"2018-01-22T15:14:37.233000Z"}
{"type":"received","order_id":"f726a3ae-345a-489a-b6d6-10f5a7c2a4ae","order_type":"limit","size":"0.09800000","price":"8831.30000000","side":"sell","client_oid":"7a491b98-d9c8-486f-95dd-0d3897294f87","product_id":"BTC-EUR","sequence":3257977701,"time":"2018-01-22T15:14:37.235000Z"}
{"type":"open","side":"sell","price":"8831.30000000","order_id":"f726a3ae-345a-489a-b6d6-10f5a7c2a4ae","remaining_size":"0.09800000","product_id":"BTC-EUR","sequence":3257977702,"time":"2018-01-22T15:14:37.235000Z"}
{"type":"received","order_id":"a86d0239-0511-4da8-b266-bd33ab8d6292","order_type":"limit","size":"0.04000000","price":"8823.41000000","side":"buy","client_oid":"d4a6901b-b271-465e-a6d2-6e24089e0a2f","product_id":"BTC-EUR","sequence":3257977703,"time":"2018-01-22T15:14:37.239000Z"}
{"type":"open","side":"buy","price":"8823.41000000","order_id":"a86d0239-0511-4da8-b266-bd33ab8d6292","remaining_size":"0.04000000","product_id":"BTC-EUR","sequence":3257977704,"time":"2018-01-22T15:14:37.239000Z"}
{"type":"received","order_id":"883c5104-ff1c-4a2a-b1a4-2e353fd8e79a","order_type":"limit","size":"0.06847422","price":"8831.32000000","side":"sell","client_oid":"51640e9a-88a0-49f1-8567-0f557b0e96f2","product_id":"BTC-EUR","sequence":3257977705,"time":"2018-01-22T15:14:37.240000Z"}
{"type":"open","side":"sell","price":"8831.32000000","order_id":"883c5104-ff1c-4a2a-b1a4-2e353fd8e79a","remaining_size":"0.06847422","product_id":"BTC-EUR","sequence":3257977706,"time":"2018-01-22T15:14:37.240000Z"}
{"type":"done","side":"sell","order_id":"63936700-8017-4383-aa37-cd479634f425","reason":"canceled","product_id":"BTC-EUR","price":"8831.31000000","remaining_size":"0.00113228","sequence":3257977707,"time":"2018-01-22T15:14:37.241000Z"}
{"type":"received","order_id":"56300110-f178-4248-9f57-293d2272903a","order_type":"limit","size":"1.89594000","price":"8655.40000000","side":"buy","client_oid":"1376f67f-5452-4354-9d7d-72e65b4fa6a1","product_id":"BTC-EUR","sequence":3257977708,"time":"2018-01-22T15:14:37.242000Z"}
{"type":"open","side":"buy","price":"8655.40000000","order_id":"56300110-f178-4248-9f57-293d2272903a","remaining_size":"1.89594000","product_id":"BTC-EUR","sequence":3257977709,"time":"2018-01-22T15:14:37.242000Z"}
{"type":"received","order_id":"cd7d0314-328a-44f1-9c6a-099dd40ab0d7","order_type":"limit","size":"0.08000000","price":"8831.30000000","side":"sell","client_oid":"aaebb821-8b1e-44bf-a5da-619132cef828","product_id":"BTC-EUR","sequence":3257977710,"time":"2018-01-22T15:14:37.282000Z"}
{"type":"open","side":"sell","price":"8831.30000000","order_id":"cd7d0314-328a-44f1-9c6a-099dd40ab0d7","remaining_size":"0.08000000","product_id":"BTC-EUR","sequence":3257977711,"time":"2018-01-22T15:14:37.282000Z"}
{"type":"received","order_id":"ac96b928-f086-4327-a22e-f65605b19044","order_type":"limit","size":"0.01800000","price":"8831.30000000","side":"sell","client_oid":"20ba33b5-aabb-4b6f-8981-f9310927d43b","product_id":"BTC-EUR","sequence":3257977712,"time":"2018-01-22T15:14:37.290000Z"}
{"type":"open","side":"sell","price":"8831.30000000","order_id":"ac96b928-f086-4327-a22e-f65605b19044","remaining_size":"0.01800000","product_id":"BTC-EUR","sequence":3257977713,"time":"2018-01-22T15:14:37.290000Z"}
{"type":"received","order_id":"e7c45b66-5538-43d5-9001-8fe186c95062","order_type":"limit","size":"0.03000000","price":"8831.29000000","side":"sell","client_oid":"6de15ac1-afbc-4483-b945-5be7817dd56d","product_id":"BTC-EUR","sequence":3257977714,"time":"2018-01-22T15:14:37.296000Z"}
{"type":"open","side":"sell","price":"8831.29000000","order_id":"e7c45b66-5538-43d5-9001-8fe186c95062","remaining_size":"0.03000000","product_id":"BTC-EUR","sequence":3257977715,"time":"2018-01-22T15:14:37.296000Z"}
{"type":"done","side":"sell","order_id":"4330e968-89d0-4fae-9839-abc2f4ed2a73","reason":"canceled","product_id":"BTC-EUR","price":"8848.93000000","remaining_size":"0.11241548","sequence":3257977716,"time":"2018-01-22T15:14:37.307000Z"}
{"type":"received","order_id":"3e4d6176-0ce6-4919-b285-f89340f0754f","order_type":"limit","size":"0.00113228","price":"8831.29000000","side":"sell","client_oid":"0b595378-e5b5-47ca-9730-b96ed3b549bf","product_id":"BTC-EUR","sequence":3257977717,"time":"2018-01-22T15:14:37.309000Z"}
{"type":"open","side":"sell","price":"8831.29000000","order_id":"3e4d6176-0ce6-4919-b285-f89340f0754f","remaining_size":"0.00113228","product_id":"BTC-EUR","sequence":3257977718,"time":"2018-01-22T15:14:37.309000Z"}
{"type":"done","side":"sell","order_id":"48a8f3ea-a0df-47e3-8235-e37fc25550a0","reason":"canceled","product_id":"BTC-EUR","price":"8831.31000000","remaining_size":"0.10500000","sequence":3257977719,"time":"2018-01-22T15:14:37.337000Z"}
{"type":"received","order_id":"4d312e29-05aa-4ff2-a553-70240f0e000b","order_type":"limit","size":"0.10500000","price":"8831.30000000","side":"sell","client_oid":"38766f59-bf8b-440b-acac-f8e2319bed3a","product_id":"BTC-EUR","sequence":3257977720,"time":"2018-01-22T15:14:37.352000Z"}
{"type":"open","side":"sell","price":"8831.30000000","order_id":"4d312e29-05aa-4ff2-a553-70240f0e000b","remaining_size":"0.10500000","product_id":"BTC-EUR","sequence":3257977721,"time":"2018-01-22T15:14:37.352000Z"}
{"type":"done","side":"sell","order_id":"ec92b3c8-6b12-438c-bfdf-99ad773be52b","reason":"canceled","product_id":"BTC-EUR","price":"8831.32000000","remaining_size":"0.06847422","sequence":3257977722,"time":"2018-01-22T15:14:37.356000Z"}
{"type":"done","side":"sell","order_id":"c85a0891-4325-4117-8d07-5d2815aa5457","reason":"canceled","product_id":"BTC-EUR","price":"8831.31000000","remaining_size":"0.10500000","sequence":3257977723,"time":"2018-01-22T15:14:37.368000Z"}
{"type":"received","order_id":"1ffbdbfa-ac4a-4c01-93d4-15f7e63fffda","order_type":"limit","size":"0.06847422","price":"8831.30000000","side":"sell","client_oid":"b7b4714c-b605-463a-a097-7eee1044d590","product_id":"BTC-EUR","sequence":3257977724,"time":"2018-01-22T15:14:37.370000Z"}
{"type":"open","side":"sell","price":"8831.30000000","order_id":"1ffbdbfa-ac4a-4c01-93d4-15f7e63fffda","remaining_size":"0.06847422","product_id":"BTC-EUR","sequence":3257977725,"time":"2018-01-22T15:14:37.370000Z"}
{"type":"done","side":"sell","order_id":"cd7d0314-328a-44f1-9c6a-099dd40ab0d7","reason":"canceled","product_id":"BTC-EUR","price":"8831.30000000","remaining_size":"0.08000000","sequence":3257977726,"time":"2018-01-22T15:14:37.373000Z"}
{"type":"received","order_id":"e194d3f6-b638-47e5-85cd-51646ec1f2dd","order_type":"limit","size":"0.06847422","price":"8831.29000000","side":"sell","client_oid":"8c4b29f4-245d-4898-b085-8cb0d00f6d52","product_id":"BTC-EUR","sequence":3257977727,"time":"2018-01-22T15:14:37.374000Z"}
{"type":"open","side":"sell","price":"8831.29000000","order_id":"e194d3f6-b638-47e5-85cd-51646ec1f2dd","remaining_size":"0.06847422","product_id":"BTC-EUR","sequence":3257977728,"time":"2018-01-22T15:14:37.374000Z"}
{"type":"received","order_id":"25fa957c-9534-43ff-ba7d-eb682cbbad24","order_type":"limit","size":"0.12454289","price":"8742.41000000","side":"buy","product_id":"BTC-EUR","sequence":3257977729,"time":"2018-01-22T15:14:37.401000Z"}
{"type":"open","side":"buy","price":"8742.41000000","order_id":"25fa957c-9534-43ff-ba7d-eb682cbbad24","remaining_size":"0.12454289","product_id":"BTC-EUR","sequence":3257977730,"time":"2018-01-22T15:14:37.401000Z"}
{"type":"received","order_id":"ef2d4279-d221-47f5-b837-bd0c08e4ff72","order_type":"limit","size":"6.34763622","price":"8750.01000000","side":"buy","product_id":"BTC-EUR","sequence":3257977731,"time":"2018-01-22T15:14:37.415000Z"}
{"type":"open","side":"buy","price":"8750.01000000","order_id":"ef2d4279-d221-47f5-b837-bd0c08e4ff72","remaining_size":"6.34763622","product_id":"BTC-EUR","sequence":3257977732,"time":"2018-01-22T15:14:37.415000Z"}
{"type":"received","order_id":"c78fe7ca-3245-4dac-90e6-039a14b52d1b","order_type":"limit","size":"0.10500000","price":"8831.30000000","side":"sell","client_oid":"5450592a-a0f5-4e87-9c2b-5de56deed415","product_id":"BTC-EUR","sequence":3257977733,"time":"2018-01-22T15:14:37.420000Z"}
{"type":"open","side":"sell","price":"8831.30000000","order_id":"c78fe7ca-3245-4dac-90e6-039a14b52d1b","remaining_size":"0.10500000","product_id":"BTC-EUR","sequence":3257977734,"time":"2018-01-22T15:14:37.420000Z"}
{"type":"done","side":"sell","order_id":"4d312e29-05aa-4ff2-a553-70240f0e000b","reason":"canceled","product_id":"BTC-EUR","price":"8831.30000000","remaining_size":"0.10500000","sequence":3257977735,"time":"2018-01-22T15:14:37.446000Z"}
{"type":"received","order_id":"10c6d4d0-0b61-4898-b89f-9d89c9f58da5","order_type":"limit","size":"0.21404538","price":"8831.32000000","side":"sell","product_id":"BTC-EUR","sequence":3257977736,"time":"2018-01-22T15:14:37.478000Z"}
{"type":"open","side":"sell","price":"8831.32000000","order_id":"10c6d4d0-0b61-4898-b89f-9d89c9f58da5","remaining_size":"0.21404538","product_id":"BTC-EUR","sequence":3257977737,"time":"2018-01-22T15:14:37.478000Z"}
{"type":"done","side":"sell","order_id":"ac96b928-f086-4327-a22e-f65605b19044","reason":"canceled","product_id":"BTC-EUR","price":"8831.30000000","remaining_size":"0.01800000","sequence":3257977738,"time":"2018-01-22T15:14:37.480000Z"}
{"type":"received","order_id":"0e2913e9-104a-4cfa-96dc-5f11679c9915","order_type":"limit","size":"0.08000000","price":"8831.28000000","side":"sell","client_oid":"7a0de3ab-0e3a-425e-aa81-03379c356a3a","product_id":"BTC-EUR","sequence":3257977739,"time":"2018-01-22T15:14:37.482000Z"}
{"type":"open","side":"sell","price":"8831.28000000","order_id":"0e2913e9-104a-4cfa-96dc-5f11679c9915","remaining_size":"0.08000000","product_id":"BTC-EUR","sequence":3257977740,"time":"2018-01-22T15:14:37.482000Z"}
{"type":"done","side":"sell","order_id":"883c5104-ff1c-4a2a-b1a4-2e353fd8e79a","reason":"canceled","product_id":"BTC-EUR","price":"8831.32000000","remaining_size":"0.06847422","sequence":3257977741,"time":"2018-01-22T15:14:37.490000Z"}
{"type":"received","order_id":"f0503829-97b4-4a91-84b7-217f4d382644","order_type":"limit","size":"0.13350000","price":"8848.93000000","side":"sell","product_id":"BTC-EUR","sequence":3257977742,"time":"2018-01-22T15:14:37.495000Z"}
{"type":"open","side":"sell","price":"8848.93000000","order_id":"f0503829-97b4-4a91-84b7-217f4d382644","remaining_size":"0.13350000","product_id":"BTC-EUR","sequence":3257977743,"time":"2018-01-22T15:14:37.495000Z"}
{"type":"done","side":"sell","order_id":"e7c45b66-5538-43d5-9001-8fe186c95062","reason":"canceled","product_id":"BTC-EUR","price":"8831.29000000","remaining_size":"0.03000000","sequence":3257977744,"time":"2018-01-22T15:14:37.497000Z"}
