{"type":"done","side":"buy","order_id":"98050cfb-45ea-4805-bd8c-7a06eddde0ac","reason":"canceled","product_id":"BTC-EUR","price":"8790.31000000","remaining_size":"0.92142500","sequence":3257979385,"time":"2018-01-22T15:14:45.629000Z"}
{"type":"done","side":"sell","order_id":"3f222f4a-04f0-45be-9025-907b81fb7277","reason":"canceled","product_id":"BTC-EUR","price":"8826.38000000","remaining_size":"0.03322226","sequence":3257979386,"time":"2018-01-22T15:14:45.634000Z"}
{"type":"done","side":"sell","order_id":"0a63b582-9c7e-4a2a-b888-e89a5a496fbb","reason":"canceled","product_id":"BTC-EUR","price":"8826.40000000","remaining_size":"0.06847422","sequence":3257979387,"time":"2018-01-22T15:14:45.670000Z"}
{"type":"done","side":"sell","order_id":"c36ea37d-9e8c-4d18-82b3-ea7834b15775","reason":"canceled","product_id":"BTC-EUR","price":"8826.03000000","remaining_size":"0.10500000","sequence":3257979388,"time":"2018-01-22T15:14:45.673000Z"}
{"type":"received","order_id":"7828743d-1ad1-4d09-8e08-42ca4983d361","order_type":"limit","size":"0.01656300","price":"8825.78000000","side":"sell","product_id":"BTC-EUR","sequence":3257979389,"time":"2018-01-22T15:14:45.706000Z"}
{"type":"open","side":"sell","price":"8825.78000000","order_id":"7828743d-1ad1-4d09-8e08-42ca4983d361","remaining_size":"0.01656300","product_id":"BTC-EUR","sequence":3257979390,"time":"2018-01-22T15:14:45.706000Z"}
{"type":"received","order_id":"95cdd98e-a79b-482a-90cb-153602bb970b","order_type":"limit","size":"0.10500000","price":"8826.02000000","side":"sell","client_oid":"fcc43205-1251-4d4e-89a4-58332a8fe334","product_id":"BTC-EUR","sequence":3257979391,"time":"2018-01-22T15:14:45.707000Z"}
{"type":"open","side":"sell","price":"8826.02000000","order_id":"95cdd98e-a79b-482a-90cb-153602bb970b","remaining_size":"0.10500000","product_id":"BTC-EUR","sequence":3257979392,"time":"2018-01-22T15:14:45.707000Z"}
{"type":"received","order_id":"5d0d3937-8925-4bec-a254-9ba129d5b2f7","order_type":"limit","size":"0.06847422","price":"8826.38000000","side":"sell","client_oid":"046c3c6b-0850-467b-83ed-b7950f143efd","product_id":"BTC-EUR","sequence":3257979393,"time":"2018-01-22T15:14:45.709000Z"}
{"type":"open","side":"sell","price":"8826.38000000","order_id":"5d0d3937-8925-4bec-a254-9ba129d5b2f7","remaining_size":"0.06847422","product_id":"BTC-EUR","sequence":3257979394,"time":"2018-01-22T15:14:45.709000Z"}
{"type":"done","side":"sell","order_id":"e081fa76-91c7-4ed0-8d74-6aeca8c6718a","reason":"canceled","product_id":"BTC-EUR","price":"8826.02000000","remaining_size":"0.00113290","sequence":3257979395,"time":"2018-01-22T15:14:45.714000Z"}
{"type":"received","order_id":"7bf14c97-bb54-4dd2-a1a7-1c7a60ce2264","order_type":"limit","size":"0.10500000","price":"8826.02000000","side":"sell","client_oid":"ec7230ca-b8f4-4a55-8e13-54bd10e3c5af","product_id":"BTC-EUR","sequence":3257979396,"time":"2018-01-22T15:14:45.715000Z"}
{"type":"open","side":"sell","price":"8826.02000000","order_id":"7bf14c97-bb54-4dd2-a1a7-1c7a60ce2264","remaining_size":"0.10500000","product_id":"BTC-EUR","sequence":3257979397,"time":"2018-01-22T15:14:45.715000Z"}
{"type":"received","order_id":"6918b9fb-fde5-44c3-8830-08868c0fff82","order_type":"limit","size":"19.28296090","price":"7247.54000000","side":"buy","product_id":"BTC-EUR","sequence":3257979398,"time":"2018-01-22T15:14:45.730000Z"}
{"type":"open","side":"buy","price":"7247.54000000","order_id":"6918b9fb-fde5-44c3-8830-08868c0fff82","remaining_size":"19.28296090","product_id":"BTC-EUR","sequence":3257979399,"time":"2018-01-22T15:14:45.730000Z"}
{"type":"received","order_id":"594dd54b-f11b-4c4a-b4b7-66de0295a333","order_type":"limit","size":"0.20699000","price":"8799.28000000","side":"buy","product_id":"BTC-EUR","sequence":3257979400,"time":"2018-01-22T15:14:45.759000Z"}
{"type":"open","side":"buy","price":"8799.28000000","order_id":"594dd54b-f11b-4c4a-b4b7-66de0295a333","remaining_size":"0.20699000","product_id":"BTC-EUR","sequence":3257979401,"time":"2018-01-22T15:14:45.759000Z"}
{"type":"received","order_id":"a4f80637-fb72-47f3-9a0b-1b45fbbb00a1","order_type":"limit","size":"0.00113290","price":"8825.77000000","side":"sell","client_oid":"8df361ce-0272-449c-8316-04dcabf429a1","product_id":"BTC-EUR","sequence":3257979402,"time":"2018-01-22T15:14:45.773000Z"}
{"type":"open","side":"sell","price":"8825.77000000","order_id":"a4f80637-fb72-47f3-9a0b-1b45fbbb00a1","remaining_size":"0.00113290","product_id":"BTC-EUR","sequence":3257979403,"time":"2018-01-22T15:14:45.773000Z"}
{"type":"received","order_id":"fc5be143-694d-46b2-8d5a-1d1d5175c855","order_type":"limit","size":"0.01800000","price":"8826.01000000","side":"sell","client_oid":"4fa8ab97-2d4d-416f-ac7f-f4f6cddb1e62","product_id":"BTC-EUR","sequence":3257979404,"time":"2018-01-22T15:14:45.788000Z"}
{"type":"open","side":"sell","price":"8826.01000000","order_id":"fc5be143-694d-46b2-8d5a-1d1d5175c855","remaining_size":"0.01800000","product_id":"BTC-EUR","sequence":3257979405,"time":"2018-01-22T15:14:45.788000Z"}
{"type":"done","side":"sell","order_id":"95cdd98e-a79b-482a-90cb-153602bb970b","reason":"canceled","product_id":"BTC-EUR","price":"8826.02000000","remaining_size":"0.10500000","sequence":3257979406,"time":"2018-01-22T15:14:45.788000Z"}
{"type":"received","order_id":"bc4349e5-bdaa-490e-b08c-63d813af535e","order_type":"limit","size":"0.92142500","price":"8771.83000000","side":"buy","product_id":"BTC-EUR","sequence":3257979407,"time":"2018-01-22T15:14:45.792000Z"}
{"type":"open","side":"buy","price":"8771.83000000","order_id":"bc4349e5-bdaa-490e-b08c-63d813af535e","remaining_size":"0.92142500","product_id":"BTC-EUR","sequence":3257979408,"time":"2018-01-22T15:14:45.792000Z"}
{"type":"received","order_id":"8d538785-a6e3-4e6a-8b2c-d7ee83f8b6eb","order_type":"limit","size":"0.06847422","price":"8826.02000000","side":"sell","client_oid":"c0f770a2-a6d2-4fe8-bdbf-0d1b0e2d32f3","product_id":"BTC-EUR","sequence":3257979409,"time":"2018-01-22T15:14:45.794000Z"}
{"type":"open","side":"sell","price":"8826.02000000","order_id":"8d538785-a6e3-4e6a-8b2c-d7ee83f8b6eb","remaining_size":"0.06847422","product_id":"BTC-EUR","sequence":3257979410,"time":"2018-01-22T15:14:45.794000Z"}
{"type":"received","order_id":"51d1da65-a328-4a86-b4c8-761548de7c1c","order_type":"limit","size":"0.03322226","price":"8826.39000000","side":"sell","client_oid":"34fd8b82-6a2a-456a-9cc0-8f23511d812d","product_id":"BTC-EUR","sequence":3257979411,"time":"2018-01-22T15:14:45.798000Z"}
{"type":"open","side":"sell","price":"8826.39000000","order_id":"51d1da65-a328-4a86-b4c8-761548de7c1c","remaining_size":"0.03322226","product_id":"BTC-EUR","sequence":3257979412,"time":"2018-01-22T15:14:45.798000Z"}
{"type":"done","side":"sell","order_id":"bd5b25e2-9010-446b-9aa4-360823433538","reason":"canceled","product_id":"BTC-EUR","price":"8826.02000000","remaining_size":"0.01800000","sequence":3257979413,"time":"2018-01-22T15:14:45.804000Z"}
{"type":"received","order_id":"2cd57ea8-257f-4d63-85b6-01c837961891","order_type":"limit","size":"0.09200000","price":"8826.01000000","side":"sell","client_oid":"af124674-46aa-498b-b877-5cbca0f8b905","product_id":"BTC-EUR","sequence":3257979414,"time":"2018-01-22T15:14:45.805000Z"}
{"type":"open","side":"sell","price":"8826.01000000","order_id":"2cd57ea8-257f-4d63-85b6-01c837961891","remaining_size":"0.09200000","product_id":"BTC-EUR","sequence":3257979415,"time":"2018-01-22T15:14:45.805000Z"}
{"type":"received","order_id":"b581eb85-0805-44a5-9a45-fc0d5d59ab2b","order_type":"limit","size":"0.00200000","price":"8826.01000000","side":"sell","client_oid":"7a03fce2-f247-48d2-b244-e833dc9b1c24","product_id":"BTC-EUR","sequence":3257979416,"time":"2018-01-22T15:14:45.807000Z"}
{"type":"open","side":"sell","price":"8826.01000000","order_id":"b581eb85-0805-44a5-9a45-fc0d5d59ab2b","remaining_size":"0.00200000","product_id":"BTC-EUR","sequence":3257979417,"time":"2018-01-22T15:14:45.807000Z"}
{"type":"received","order_id":"b1594d63-265e-444b-97a5-02a47e623114","order_type":"limit","size":"0.10500000","price":"8825.78000000","side":"sell","client_oid":"6bbd56fb-7b98-4144-a9da-d3bc2a0f5901","product_id":"BTC-EUR","sequence":3257979418,"time":"2018-01-22T15:14:45.807000Z"}
{"type":"open","side":"sell","price":"8825.78000000","order_id":"b1594d63-265e-444b-97a5-02a47e623114","remaining_size":"0.10500000","product_id":"BTC-EUR","sequence":3257979419,"time":"2018-01-22T15:14:45.807000Z"}
{"type":"done","side":"sell","order_id":"51d1da65-a328-4a86-b4c8-761548de7c1c","reason":"canceled","product_id":"BTC-EUR","price":"8826.39000000","remaining_size":"0.03322226","sequence":3257979420,"time":"2018-01-22T15:14:45.812000Z"}
{"type":"received","order_id":"14b4d675-7851-4620-b286-75b196275cbf","order_type":"limit","size":"0.06847422","price":"8826.01000000","side":"sell","client_oid":"172e18b1-9997-4ccd-a4ff-e9b8e0743fed","product_id":"BTC-EUR","sequence":3257979421,"time":"2018-01-22T15:14:45.815000Z"}
{"type":"open","side":"sell","price":"8826.01000000","order_id":"14b4d675-7851-4620-b286-75b196275cbf","remaining_size":"0.06847422","product_id":"BTC-EUR","sequence":3257979422,"time":"2018-01-22T15:14:45.815000Z"}
{"type":"received","order_id":"55a0f835-934a-4d3c-81e2-d08e7a3f1230","order_type":"limit","size":"0.01800000","price":"8825.77000000","side":"sell","client_oid":"af13a187-dbc9-44c7-85ef-425e8e8312d7","product_id":"BTC-EUR","sequence":3257979423,"time":"2018-01-22T15:14:45.826000Z"}
{"type":"open","side":"sell","price":"8825.77000000","order_id":"55a0f835-934a-4d3c-81e2-d08e7a3f1230","remaining_size":"0.01800000","product_id":"BTC-EUR","sequence":3257979424,"time":"2018-01-22T15:14:45.826000Z"}
{"type":"received","order_id":"a8b6e899-400a-4de2-8117-74818ac0cd8a","order_type":"limit","size":"0.03322226","price":"8825.77000000","side":"sell","client_oid":"a97ef4c9-f5e2-40b4-9a91-667465de72c4","product_id":"BTC-EUR","sequence":3257979425,"time":"2018-01-22T15:14:45.835000Z"}
{"type":"open","side":"sell","price":"8825.77000000","order_id":"a8b6e899-400a-4de2-8117-74818ac0cd8a","remaining_size":"0.03322226","product_id":"BTC-EUR","sequence":3257979426,"time":"2018-01-22T15:14:45.835000Z"}
{"type":"done","side":"sell","order_id":"05f6dafb-483c-499a-bcea-f68336dd4ecc","reason":"canceled","product_id":"BTC-EUR","price":"8826.42000000","remaining_size":"0.01800000","sequence":3257979427,"time":"2018-01-22T15:14:45.842000Z"}
{"type":"received","order_id":"7d69dd85-f032-47a9-9904-a4090057e214","order_type":"limit","size":"0.00564464","price":"8826.02000000","side":"sell","client_oid":"44b63433-6250-4a0c-9eb2-54cab339e8a4","product_id":"BTC-EUR","sequence":3257979428,"time":"2018-01-22T15:14:45.842000Z"}
{"type":"open","side":"sell","price":"8826.02000000","order_id":"7d69dd85-f032-47a9-9904-a4090057e214","remaining_size":"0.00564464","product_id":"BTC-EUR","sequence":3257979429,"time":"2018-01-22T15:14:45.842000Z"}
{"type":"done","side":"sell","order_id":"7bf14c97-bb54-4dd2-a1a7-1c7a60ce2264","reason":"canceled","product_id":"BTC-EUR","price":"8826.02000000","remaining_size":"0.10500000","sequence":3257979430,"time":"2018-01-22T15:14:45.844000Z"}
{"type":"received","order_id":"36a9e6d6-c43c-4cd3-89ab-7c5bb2ae43c6","order_type":"limit","size":"0.01800000","price":"8825.77000000","side":"sell","client_oid":"de19e5a0-ba5c-49c5-8d88-172721449310","product_id":"BTC-EUR","sequence":3257979431,"time":"2018-01-22T15:14:45.863000Z"}
{"type":"open","side":"sell","price":"8825.77000000","order_id":"36a9e6d6-c43c-4cd3-89ab-7c5bb2ae43c6","remaining_size":"0.01800000","product_id":"BTC-EUR","sequence":3257979432,"time":"2018-01-22T15:14:45.863000Z"}
{"type":"done","side":"sell","order_id":"fc5be143-694d-46b2-8d5a-1d1d5175c855","reason":"canceled","product_id":"BTC-EUR","price":"8826.01000000","remaining_size":"0.01800000","sequence":3257979433,"time":"2018-01-22T15:14:45.871000Z"}
{"type":"received","order_id":"8ee37557-f55b-47dd-aaaf-9049d32549c4","order_type":"limit","size":"0.01800000","price":"8825.76000000","side":"sell","client_oid":"63390273-73f5-4f0a-8442-65bb657d369e","product_id":"BTC-EUR","sequence":3257979434,"time":"2018-01-22T15:14:45.895000Z"}
{"type":"open","side":"sell","price":"8825.76000000","order_id":"8ee37557-f55b-47dd-aaaf-9049d32549c4","remaining_size":"0.01800000","product_id":"BTC-EUR","sequence":3257979435,"time":"2018-01-22T15:14:45.895000Z"}
{"type":"done","side":"sell","order_id":"b1594d63-265e-444b-97a5-02a47e623114","reason":"canceled","product_id":"BTC-EUR","price":"8825.78000000","remaining_size":"0.10500000","sequence":3257979436,"time":"2018-01-22T15:14:45.895000Z"}
{"type":"done","side":"sell","order_id":"b581eb85-0805-44a5-9a45-fc0d5d59ab2b","reason":"canceled","product_id":"BTC-EUR","price":"8826.01000000","remaining_size":"0.00200000","sequence":3257979437,"time":"2018-01-22T15:14:45.896000Z"}
{"type":"done","side":"sell","order_id":"a4f80637-fb72-47f3-9a0b-1b45fbbb00a1","reason":"canceled","product_id":"BTC-EUR","price":"8825.77000000","remaining_size":"0.00113290","sequence":3257979438,"time":"2018-01-22T15:14:45.925000Z"}
{"type":"received","order_id":"9cd951a1-4281-4e56-a3c2-72cf40f5a1a2","order_type":"limit","size":"0.00200000","price":"8825.76000000","side":"sell","client_oid":"528e1b02-e2cd-4e20-ae56-1c649b795b5c","product_id":"BTC-EUR","sequence":3257979439,"time":"2018-01-22T15:14:45.925000Z"}
{"type":"open","side":"sell","price":"8825.76000000","order_id":"9cd951a1-4281-4e56-a3c2-72cf40f5a1a2","remaining_size":"0.00200000","product_id":"BTC-EUR","sequence":3257979440,"time":"2018-01-22T15:14:45.925000Z"}
{"type":"received","order_id":"d8151a9a-3611-43fe-9405-4548b93cf4c0","order_type":"limit","size":"0.06847422","price":"8825.77000000","side":"sell","client_oid":"ecc44958-0419-4aba-8ac1-cd779e38bd7e","product_id":"BTC-EUR","sequence":3257979441,"time":"2018-01-22T15:14:45.927000Z"}
{"type":"open","side":"sell","price":"8825.77000000","order_id":"d8151a9a-3611-43fe-9405-4548b93cf4c0","remaining_size":"0.06847422","product_id":"BTC-EUR","sequence":3257979442,"time":"2018-01-22T15:14:45.927000Z"}
{"type":"done","side":"sell","order_id":"2cd57ea8-257f-4d63-85b6-01c837961891","reason":"canceled","product_id":"BTC-EUR","price":"8826.01000000","remaining_size":"0.09200000","sequence":3257979443,"time":"2018-01-22T15:14:45.928000Z"}
{"type":"done","side":"sell","order_id":"a8b6e899-400a-4de2-8117-74818ac0cd8a","reason":"canceled","product_id":"BTC-EUR","price":"8825.77000000","remaining_size":"0.03322226","sequence":3257979444,"time":"2018-01-22T15:14:45.932000Z"}
{"type":"done","side":"sell","order_id":"19e0a13f-4030-4cc1-a3f4-1bf7cde6ec8d","reason":"canceled","product_id":"BTC-EUR","price":"8826.41000000","remaining_size":"0.04164971","sequence":3257979445,"time":"2018-01-22T15:14:45.932000Z"}
{"type":"done","side":"sell","order_id":"740ea6b8-0114-4440-b950-55a6af9c1c38","reason":"canceled","product_id":"BTC-EUR","price":"9110.42000000","remaining_size":"1.28000000","sequence":3257979446,"time":"2018-01-22T15:14:45.936000Z"}
{"type":"done","side":"sell","order_id":"1c105ed5-a42c-43c0-88da-71ac7eba0e9e","reason":"canceled","product_id":"BTC-EUR","price":"8927.50000000","remaining_size":"0.03773580","sequence":3257979447,"time":"2018-01-22T15:14:45.959000Z"}
{"type":"done","side":"sell","order_id":"5db79357-8893-45dc-9da1-2a9fa28120a7","reason":"canceled","product_id":"BTC-EUR","price":"8826.42000000","remaining_size":"0.01322632","sequence":3257979448,"time":"2018-01-22T15:14:45.969000Z"}
{"type":"done","side":"sell","order_id":"55a0f835-934a-4d3c-81e2-d08e7a3f1230","reason":"canceled","product_id":"BTC-EUR","price":"8825.77000000","remaining_size":"0.01800000","sequence":3257979449,"time":"2018-01-22T15:14:45.989000Z"}
{"type":"received","order_id":"b4352e1a-abbc-426d-8fe7-5b816b4767e8","order_type":"limit","size":"0.10500000","price":"8825.77000000","side":"sell","client_oid":"4343cfa9-e02e-4779-98a1-55c49ba56355","product_id":"BTC-EUR","sequence":3257979450,"time":"2018-01-22T15:14:45.992000Z"}
{"type":"open","side":"sell","price":"8825.77000000","order_id":"b4352e1a-abbc-426d-8fe7-5b816b4767e8","remaining_size":"0.10500000","product_id":"BTC-EUR","sequence":3257979451,"time":"2018-01-22T15:14:45.992000Z"}
{"type":"received","order_id":"5ea03969-9765-4555-920b-8a41d05c1f04","order_type":"limit","size":"0.03322226","price":"8825.75000000","side":"sell","client_oid":"a50d6009-1b13-42c3-9a0b-591b679d9613","product_id":"BTC-EUR","sequence":3257979452,"time":"2018-01-22T15:14:46.005000Z"}
{"type":"open","side":"sell","price":"8825.75000000","order_id":"5ea03969-9765-4555-920b-8a41d05c1f04","remaining_size":"0.03322226","product_id":"BTC-EUR","sequence":3257979453,"time":"2018-01-22T15:14:46.005000Z"}
{"type":"received","order_id":"b7351946-d2eb-4c80-ac2a-919b6a749582","order_type":"limit","size":"0.01800000","price":"8825.75000000","side":"sell","client_oid":"5b64a0e8-5651-4916-a801-646d8beabcda","product_id":"BTC-EUR","sequence":3257979454,"time":"2018-01-22T15:14:46.013000Z"}
{"type":"open","side":"sell","price":"8825.75000000","order_id":"b7351946-d2eb-4c80-ac2a-919b6a749582","remaining_size":"0.01800000","product_id":"BTC-EUR","sequence":3257979455,"time":"2018-01-22T15:14:46.013000Z"}
{"type":"done","side":"sell","order_id":"36a9e6d6-c43c-4cd3-89ab-7c5bb2ae43c6","reason":"canceled","product_id":"BTC-EUR","price":"8825.77000000","remaining_size":"0.01800000","sequence":3257979456,"time":"2018-01-22T15:14:46.038000Z"}
{"type":"done","side":"sell","order_id":"6e24adff-c398-457e-8fd5-f1f991012d8e","reason":"canceled","product_id":"BTC-EUR","price":"8826.40000000","remaining_size":"0.22947933","sequence":3257979457,"time":"2018-01-22T15:14:46.040000Z"}
{"type":"done","side":"sell","order_id":"14b4d675-7851-4620-b286-75b196275cbf","reason":"canceled","product_id":"BTC-EUR","price":"8826.01000000","remaining_size":"0.06847422","sequence":3257979458,"time":"2018-01-22T15:14:46.044000Z"}
{"type":"done","side":"sell","order_id":"b47ee226-6a31-40bd-81ce-2b142652f973","reason":"canceled","product_id":"BTC-EUR","price":"8831.69000000","remaining_size":"0.11066184","sequence":3257979459,"time":"2018-01-22T15:14:46.065000Z"}
{"type":"done","side":"sell","order_id":"b4352e1a-abbc-426d-8fe7-5b816b4767e8","reason":"canceled","product_id":"BTC-EUR","price":"8825.77000000","remaining_size":"0.10500000","sequence":3257979460,"time":"2018-01-22T15:14:46.068000Z"}
{"type":"received","order_id":"e6d0c32a-f5d4-47d1-bf96-8fb15e20c3f8","order_type":"limit","size":"0.00113290","price":"8825.75000000","side":"sell","client_oid":"592f5dc9-b76d-40a9-9446-0dd573193cf2","product_id":"BTC-EUR","sequence":3257979461,"time":"2018-01-22T15:14:46.074000Z"}
{"type":"open","side":"sell","price":"8825.75000000","order_id":"e6d0c32a-f5d4-47d1-bf96-8fb15e20c3f8","remaining_size":"0.00113290","product_id":"BTC-EUR","sequence":3257979462,"time":"2018-01-22T15:14:46.074000Z"}
{"type":"done","side":"sell","order_id":"8ee37557-f55b-47dd-aaaf-9049d32549c4","reason":"canceled","product_id":"BTC-EUR","price":"8825.76000000","remaining_size":"0.01800000","sequence":3257979463,"time":"2018-01-22T15:14:46.086000Z"}
{"type":"received","order_id":"7ca99de3-632e-4fe3-ba4a-a1c12a9162c5","order_type":"limit","size":"0.10500000","price":"8825.76000000","side":"sell","client_oid":"5fc76b52-9052-40be-b74e-eb48a074e0f1","product_id":"BTC-EUR","sequence":3257979464,"time":"2018-01-22T15:14:46.088000Z"}
{"type":"open","side":"sell","price":"8825.76000000","order_id":"7ca99de3-632e-4fe3-ba4a-a1c12a9162c5","remaining_size":"0.10500000","product_id":"BTC-EUR","sequence":3257979465,"time":"2018-01-22T15:14:46.088000Z"}
{"type":"done","side":"sell","order_id":"9cd951a1-4281-4e56-a3c2-72cf40f5a1a2","reason":"canceled","product_id":"BTC-EUR","price":"8825.76000000","remaining_size":"0.00200000","sequence":3257979466,"time":"2018-01-22T15:14:46.113000Z"}
{"type":"done","side":"sell","order_id":"7828743d-1ad1-4d09-8e08-42ca4983d361","reason":"canceled","product_id":"BTC-EUR","price":"8825.78000000","remaining_size":"0.01656300","sequence":3257979467,"time":"2018-01-22T15:14:46.113000Z"}
{"type":"received","order_id":"6e6ab63f-6052-43b8-bd06-e653fb7bdaf3","order_type":"limit","size":"0.01800000","price":"8825.74000000","side":"sell","client_oid":"56dd981c-399b-4e76-8c6c-79b6ccc93ab9","product_id":"BTC-EUR","sequence":3257979468,"time":"2018-01-22T15:14:46.116000Z"}
{"type":"open","side":"sell","price":"8825.74000000","order_id":"6e6ab63f-6052-43b8-bd06-e653fb7bdaf3","remaining_size":"0.01800000","product_id":"BTC-EUR","sequence":3257979469,"time":"2018-01-22T15:14:46.116000Z"}
{"type":"received","order_id":"ef5ff2f7-aee6-4970-8114-07dd4723e6d7","order_type":"limit","size":"0.61634072","price":"8849.00000000","side":"sell","client_oid":"809c4454-f6a5-47a9-b49f-50ac0ce18a85","product_id":"BTC-EUR","sequence":3257979470,"time":"2018-01-22T15:14:46.122000Z"}
{"type":"open","side":"sell","price":"8849.00000000","order_id":"ef5ff2f7-aee6-4970-8114-07dd4723e6d7","remaining_size":"0.61634072","product_id":"BTC-EUR","sequence":3257979471,"time":"2018-01-22T15:14:46.122000Z"}
{"type":"received","order_id":"decdbab6-df99-4bca-be82-b20d3087ac15","order_type":"limit","size":"0.04164971","price":"8825.76000000","side":"sell","client_oid":"dd7f48f6-e5ac-4e60-a032-2cdd52bff9b6","product_id":"BTC-EUR","sequence":3257979472,"time":"2018-01-22T15:14:46.159000Z"}
{"type":"open","side":"sell","price":"8825.76000000","order_id":"decdbab6-df99-4bca-be82-b20d3087ac15","remaining_size":"0.04164971","product_id":"BTC-EUR","sequence":3257979473,"time":"2018-01-22T15:14:46.159000Z"}
{"type":"done","side":"sell","order_id":"8d538785-a6e3-4e6a-8b2c-d7ee83f8b6eb","reason":"canceled","product_id":"BTC-EUR","price":"8826.02000000","remaining_size":"0.06847422","sequence":3257979474,"time":"2018-01-22T15:14:46.167000Z"}
{"type":"done","side":"sell","order_id":"5d0d3937-8925-4bec-a254-9ba129d5b2f7","reason":"canceled","product_id":"BTC-EUR","price":"8826.38000000","remaining_size":"0.06847422","sequence":3257979475,"time":"2018-01-22T15:14:46.167000Z"}
{"type":"done","side":"sell","order_id":"d8151a9a-3611-43fe-9405-4548b93cf4c0","reason":"canceled","product_id":"BTC-EUR","price":"8825.77000000","remaining_size":"0.06847422","sequence":3257979476,"time":"2018-01-22T15:14:46.174000Z"}
{"type":"done","side":"sell","order_id":"7ca99de3-632e-4fe3-ba4a-a1c12a9162c5","reason":"canceled","product_id":"BTC-EUR","price":"8825.76000000","remaining_size":"0.10500000","sequence":3257979477,"time":"2018-01-22T15:14:46.181000Z"}
{"type":"done","side":"sell","order_id":"e6d0c32a-f5d4-47d1-bf96-8fb15e20c3f8","reason":"canceled","product_id":"BTC-EUR","price":"8825.75000000","remaining_size":"0.00113290","sequence":3257979478,"time":"2018-01-22T15:14:46.181000Z"}
{"type":"received","order_id":"30f6c6e7-ff06-48dc-a00e-5c9429f0a45d","order_type":"limit","size":"0.06847422","price":"8825.76000000","side":"sell","client_oid":"b0a6564c-e392-44db-96e6-de145cef3214","product_id":"BTC-EUR","sequence":3257979479,"time":"2018-01-22T15:14:46.188000Z"}
{"type":"open","side":"sell","price":"8825.76000000","order_id":"30f6c6e7-ff06-48dc-a00e-5c9429f0a45d","remaining_size":"0.06847422","product_id":"BTC-EUR","sequence":3257979480,"time":"2018-01-22T15:14:46.188000Z"}
{"type":"received","order_id":"3de85c59-06ef-4c0c-bbb9-15785aa9d6c7","order_type":"limit","size":"0.01322632","price":"8825.76000000","side":"sell","client_oid":"7ac30b53-bbac-4e65-b9e8-70e750d800b5","product_id":"BTC-EUR","sequence":3257979481,"time":"2018-01-22T15:14:46.195000Z"}
{"type":"open","side":"sell","price":"8825.76000000","order_id":"3de85c59-06ef-4c0c-bbb9-15785aa9d6c7","remaining_size":"0.01322632","product_id":"BTC-EUR","sequence":3257979482,"time":"2018-01-22T15:14:46.195000Z"}
{"type":"received","order_id":"7b141fc5-654c-4125-9791-f7f0daafc250","order_type":"limit","size":"0.06847422","price":"8825.75000000","side":"sell","client_oid":"e0db4ca4-93f1-45f9-93cd-cab9c18ee623","product_id":"BTC-EUR","sequence":3257979483,"time":"2018-01-22T15:14:46.198000Z"}
{"type":"open","side":"sell","price":"8825.75000000","order_id":"7b141fc5-654c-4125-9791-f7f0daafc250","remaining_size":"0.06847422","product_id":"BTC-EUR","sequence":3257979484,"time":"2018-01-22T15:14:46.198000Z"}
{"type":"done","side":"sell","order_id":"b7351946-d2eb-4c80-ac2a-919b6a749582","reason":"canceled","product_id":"BTC-EUR","price":"8825.75000000","remaining_size":"0.01800000","sequence":3257979485,"time":"2018-01-22T15:14:46.201000Z"}
{"type":"received","order_id":"ae47384d-5cf4-43c7-b546-c723062f8bfa","order_type":"limit","size":"0.10500000","price":"8825.75000000","side":"sell","client_oid":"67155605-78bb-443d-897a-9cf9320b4f6b","product_id":"BTC-EUR","sequence":3257979486,"time":"2018-01-22T15:14:46.214000Z"}
{"type":"open","side":"sell","price":"8825.75000000","order_id":"ae47384d-5cf4-43c7-b546-c723062f8bfa","remaining_size":"0.10500000","product_id":"BTC-EUR","sequence":3257979487,"time":"2018-01-22T15:14:46.214000Z"}
{"type":"received","order_id":"443666c7-a5af-4b59-ae4f-355740c8cd6c","order_type":"limit","size":"0.01800000","price":"8825.73000000","side":"sell","client_oid":"3cdf94a1-02ea-4538-9249-0a361bc68ada","product_id":"BTC-EUR","sequence":3257979488,"time":"2018-01-22T15:14:46.232000Z"}
{"type":"open","side":"sell","price":"8825.73000000","order_id":"443666c7-a5af-4b59-ae4f-355740c8cd6c","remaining_size":"0.01800000","product_id":"BTC-EUR","sequence":3257979489,"time":"2018-01-22T15:14:46.232000Z"}
{"type":"received","order_id":"7038e06a-dee9-4025-b63f-d8b5a3f22c50","order_type":"limit","size":"0.00113290","price":"8825.73000000","side":"sell","client_oid":"05df2159-9c14-40ed-85c9-40a1a04493e4","product_id":"BTC-EUR","sequence":3257979490,"time":"2018-01-22T15:14:46.264000Z"}
{"type":"open","side":"sell","price":"8825.73000000","order_id":"7038e06a-dee9-4025-b63f-d8b5a3f22c50","remaining_size":"0.00113290","product_id":"BTC-EUR","sequence":3257979491,"time":"2018-01-22T15:14:46.264000Z"}
{"type":"received","order_id":"b28742f5-90ae-4113-8af7-767f2967d4d1","order_type":"limit","size":"0.22947933","price":"8825.73000000","side":"sell","client_oid":"3945bcb6-2062-4cfb-b2dc-b179d8de8918","product_id":"BTC-EUR","sequence":3257979492,"time":"2018-01-22T15:14:46.269000Z"}
{"type":"open","side":"sell","price":"8825.73000000","order_id":"b28742f5-90ae-4113-8af7-767f2967d4d1","remaining_size":"0.22947933","product_id":"BTC-EUR","sequence":3257979493,"time":"2018-01-22T15:14:46.269000Z"}
{"type":"done","side":"sell","order_id":"5ea03969-9765-4555-920b-8a41d05c1f04","reason":"canceled","product_id":"BTC-EUR","price":"8825.75000000","remaining_size":"0.03322226","sequence":3257979494,"time":"2018-01-22T15:14:46.273000Z"}
{"type":"done","side":"sell","order_id":"9a053520-378a-45c7-b785-80a658450ac2","reason":"canceled","product_id":"BTC-EUR","price":"8827.28000000","remaining_size":"0.02754370","sequence":3257979495,"time":"2018-01-22T15:14:46.289000Z"}
{"type":"received","order_id":"a3681cfc-8dbf-4a17-a204-c8f4d3fb3867","order_type":"limit","size":"0.03322226","price":"8825.72000000","side":"sell","client_oid":"7ef1d8f4-0d60-4e7f-8e30-bc594623193f","product_id":"BTC-EUR","sequence":3257979496,"time":"2018-01-22T15:14:46.317000Z"}
{"type":"open","side":"sell","price":"8825.72000000","order_id":"a3681cfc-8dbf-4a17-a204-c8f4d3fb3867","remaining_size":"0.03322226","product_id":"BTC-EUR","sequence":3257979497,"time":"2018-01-22T15:14:46.317000Z"}
{"type":"done","side":"sell","order_id":"6e6ab63f-6052-43b8-bd06-e653fb7bdaf3","reason":"canceled","product_id":"BTC-EUR","price":"8825.74000000","remaining_size":"0.01800000","sequence":3257979498,"time":"2018-01-22T15:14:46.318000Z"}
{"type":"done","side":"sell","order_id":"7038e06a-dee9-4025-b63f-d8b5a3f22c50","reason":"canceled","product_id":"BTC-EUR","price":"8825.73000000","remaining_size":"0.00113290","sequence":3257979499,"time":"2018-01-22T15:14:46.327000Z"}
{"type":"received","order_id":"0601b554-6f52-430c-af2e-19658037b522","order_type":"limit","size":"0.06847422","price":"8825.74000000","side":"sell","client_oid":"28b14246-8578-4755-ae2b-21b94aa1c47b","product_id":"BTC-EUR","sequence":3257979500,"time":"2018-01-22T15:14:46.329000Z"}
{"type":"open","side":"sell","price":"8825.74000000","order_id":"0601b554-6f52-430c-af2e-19658037b522","remaining_size":"0.06847422","product_id":"BTC-EUR","sequence":3257979501,"time":"2018-01-22T15:14:46.329000Z"}
{"type":"done","side":"sell","order_id":"ae47384d-5cf4-43c7-b546-c723062f8bfa","reason":"canceled","product_id":"BTC-EUR","price":"8825.75000000","remaining_size":"0.10500000","sequence":3257979502,"time":"2018-01-22T15:14:46.332000Z"}
{"type":"received","order_id":"c45eccc9-e087-4c43-8be0-67f3dc1fe57a","order_type":"limit","size":"0.06847422","price":"8825.73000000","side":"sell","client_oid":"b7a80971-378e-4dbd-8775-75b2a1c82a10","product_id":"BTC-EUR","sequence":3257979503,"time":"2018-01-22T15:14:46.336000Z"}
{"type":"open","side":"sell","price":"8825.73000000","order_id":"c45eccc9-e087-4c43-8be0-67f3dc1fe57a","remaining_size":"0.06847422","product_id":"BTC-EUR","sequence":3257979504,"time":"2018-01-22T15:14:46.336000Z"}
{"type":"received","order_id":"c261f461-9866-4d63-a523-3f02e7887f33","order_type":"limit","size":"0.08189697","price":"9199.00000000","side":"sell","client_oid":"f5dcfc72-62de-49a8-bec3-241ff7a66c1b","product_id":"BTC-EUR","sequence":3257979505,"time":"2018-01-22T15:14:46.346000Z"}
{"type":"open","side":"sell","price":"9199.00000000","order_id":"c261f461-9866-4d63-a523-3f02e7887f33","remaining_size":"0.08189697","product_id":"BTC-EUR","sequence":3257979506,"time":"2018-01-22T15:14:46.346000Z"}
{"type":"received","order_id":"665e5a5d-8deb-40b1-b711-910bd136d132","order_type":"limit","size":"0.10500000","price":"8825.73000000","side":"sell","client_oid":"5b008ecc-db3b-4315-905c-0460947b28a3","product_id":"BTC-EUR","sequence":3257979507,"time":"2018-01-22T15:14:46.364000Z"}
{"type":"open","side":"sell","price":"8825.73000000","order_id":"665e5a5d-8deb-40b1-b711-910bd136d132","remaining_size":"0.10500000","product_id":"BTC-EUR","sequence":3257979508,"time":"2018-01-22T15:14:46.364000Z"}
{"type":"received","order_id":"f4e6e18a-e62c-4b13-8df6-6cfcd02a0159","order_type":"limit","size":"0.00113290","price":"8825.71000000","side":"sell","client_oid":"254e3de6-8304-4533-b4f1-fd8bc739ae21","product_id":"BTC-EUR","sequence":3257979509,"time":"2018-01-22T15:14:46.392000Z"}
{"type":"open","side":"sell","price":"8825.71000000","order_id":"f4e6e18a-e62c-4b13-8df6-6cfcd02a0159","remaining_size":"0.00113290","product_id":"BTC-EUR","sequence":3257979510,"time":"2018-01-22T15:14:46.392000Z"}
{"type":"received","order_id":"c8ab6ca3-e3e6-4346-944c-12c06fb95204","order_type":"limit","size":"0.02754400","price":"8826.44000000","side":"sell","product_id":"BTC-EUR","sequence":3257979511,"time":"2018-01-22T15:14:46.402000Z"}
{"type":"open","side":"sell","price":"8826.44000000","order_id":"c8ab6ca3-e3e6-4346-944c-12c06fb95204","remaining_size":"0.02754400","product_id":"BTC-EUR","sequence":3257979512,"time":"2018-01-22T15:14:46.402000Z"}
{"type":"received","order_id":"16b14d26-38bc-4a26-93ed-aa682101359a","order_type":"limit","size":"0.01800000","price":"8825.72000000","side":"sell","client_oid":"909c4d6f-e393-4af9-9d38-608d57da601d","product_id":"BTC-EUR","sequence":3257979513,"time":"2018-01-22T15:14:46.404000Z"}
{"type":"open","side":"sell","price":"8825.72000000","order_id":"16b14d26-38bc-4a26-93ed-aa682101359a","remaining_size":"0.01800000","product_id":"BTC-EUR","sequence":3257979514,"time":"2018-01-22T15:14:46.404000Z"}
{"type":"done","side":"sell","order_id":"443666c7-a5af-4b59-ae4f-355740c8cd6c","reason":"canceled","product_id":"BTC-EUR","price":"8825.73000000","remaining_size":"0.01800000","sequence":3257979515,"time":"2018-01-22T15:14:46.407000Z"}
{"type":"received","order_id":"8f82ee9f-171f-4480-94fa-26f0737e9d6a","order_type":"market","size":"0.00114053","side":"sell","client_oid":"3695e5c4-4b66-4e56-e4d3-ca7b90fa26db","product_id":"BTC-EUR","sequence":3257979516,"time":"2018-01-22T15:14:46.411000Z"}
{"type":"match","trade_id":10551375,"maker_order_id":"94579e48-9f70-49e8-9e77-0c4a2c5d6626","taker_order_id":"8f82ee9f-171f-4480-94fa-26f0737e9d6a","side":"buy","size":"0.00113310","price":"8825.30000000","product_id":"BTC-EUR","sequence":3257979517,"time":"2018-01-22T15:14:46.411000Z"}
{"type":"done","side":"buy","order_id":"94579e48-9f70-49e8-9e77-0c4a2c5d6626","reason":"filled","product_id":"BTC-EUR","price":"8825.30000000","remaining_size":"0.00000000","sequence":3257979518,"time":"2018-01-22T15:14:46.411000Z"}
{"type":"match","trade_id":10551376,"maker_order_id":"c653e361-6d4d-4fb7-8d37-4e362a65e7b3","taker_order_id":"8f82ee9f-171f-4480-94fa-26f0737e9d6a","side":"buy","size":"0.00000743","price":"8825.29000000","product_id":"BTC-EUR","sequence":3257979519,"time":"2018-01-22T15:14:46.411000Z"}
{"type":"done","side":"sell","order_id":"8f82ee9f-171f-4480-94fa-26f0737e9d6a","reason":"filled","product_id":"BTC-EUR","remaining_size":"0.00000000","sequence":3257979520,"time":"2018-01-22T15:14:46.411000Z"}
{"type":"done","side":"buy","order_id":"4541082b-59e5-437b-8aee-afb2f8bf1627","reason":"canceled","product_id":"BTC-EUR","price":"8774.05000000","remaining_size":"0.02243610","sequence":3257979521,"time":"2018-01-22T15:14:46.430000Z"}
{"type":"done","side":"buy","order_id":"ba7bb9df-4ed4-4fe2-8f05-8e7ee1826d60","reason":"canceled","product_id":"BTC-EUR","price":"8725.85000000","remaining_size":"0.02243610","sequence":3257979522,"time":"2018-01-22T15:14:46.431000Z"}
{"type":"done","side":"buy","order_id":"b728444e-82b4-42ab-9dea-6410231b337b","reason":"canceled","product_id":"BTC-EUR","price":"8778.16000000","remaining_size":"0.01510808","sequence":3257979523,"time":"2018-01-22T15:14:46.433000Z"}
{"type":"done","side":"sell","order_id":"a68cd1ff-accb-47ed-b8b2-7027da15522e","reason":"canceled","product_id":"BTC-EUR","price":"8925.82000000","remaining_size":"0.21455929","sequence":3257979524,"time":"2018-01-22T15:14:46.433000Z"}
{"type":"done","side":"buy","order_id":"7653f0c5-fefa-4805-bd32-7159d6cba6fb","reason":"canceled","product_id":"BTC-EUR","price":"8681.42000000","remaining_size":"0.02243610","sequence":3257979525,"time":"2018-01-22T15:14:46.434000Z"}
{"type":"done","side":"sell","order_id":"baa75e82-9ca7-4f4f-adad-d0eb95bb8750","reason":"canceled","product_id":"BTC-EUR","price":"8924.91000000","remaining_size":"0.36857350","sequence":3257979526,"time":"2018-01-22T15:14:46.434000Z"}
{"type":"done","side":"sell","order_id":"cb7adb81-a9a6-44f0-a353-c4ed0c54e5f8","reason":"canceled","product_id":"BTC-EUR","price":"8936.60000000","remaining_size":"0.36857350","sequence":3257979527,"time":"2018-01-22T15:14:46.434000Z"}
{"type":"done","side":"sell","order_id":"10756245-ffd4-4a61-8ee5-28085c6a3483","reason":"canceled","product_id":"BTC-EUR","price":"8913.10000000","remaining_size":"0.21455929","sequence":3257979528,"time":"2018-01-22T15:14:46.435000Z"}
{"type":"done","side":"sell","order_id":"fbaba9ff-9fc8-4d1e-b02f-a1102d16b0f8","reason":"canceled","product_id":"BTC-EUR","price":"8934.41000000","remaining_size":"0.21455929","sequence":3257979529,"time":"2018-01-22T15:14:46.435000Z"}
{"type":"done","side":"buy","order_id":"5a3976ae-def8-4859-bdd4-4c83b336bdd5","reason":"canceled","product_id":"BTC-EUR","price":"8822.63000000","remaining_size":"0.00732594","sequence":3257979530,"time":"2018-01-22T15:14:46.436000Z"}
{"type":"done","side":"sell","order_id":"33115acc-e9b4-485d-ab06-d70cd84ff17e","reason":"canceled","product_id":"BTC-EUR","price":"8946.32000000","remaining_size":"0.21455929","sequence":3257979531,"time":"2018-01-22T15:14:46.437000Z"}
{"type":"done","side":"sell","order_id":"c63f5c50-25dc-4a75-950e-80d51ac93238","reason":"canceled","product_id":"BTC-EUR","price":"8891.99000000","remaining_size":"0.36857350","sequence":3257979532,"time":"2018-01-22T15:14:46.437000Z"}
{"type":"done","side":"sell","order_id":"07d03fa7-0e43-432e-b9c0-f2485331f441","reason":"canceled","product_id":"BTC-EUR","price":"8900.93000000","remaining_size":"0.21455929","sequence":3257979533,"time":"2018-01-22T15:14:46.438000Z"}
{"type":"done","side":"sell","order_id":"696cfd05-120d-4e78-9c17-22d935a83f31","reason":"canceled","product_id":"BTC-EUR","price":"8904.65000000","remaining_size":"0.36857350","sequence":3257979534,"time":"2018-01-22T15:14:46.439000Z"}
{"type":"done","side":"sell","order_id":"7b141fc5-654c-4125-9791-f7f0daafc250","reason":"canceled","product_id":"BTC-EUR","price":"8825.75000000","remaining_size":"0.06847422","sequence":3257979535,"time":"2018-01-22T15:14:46.439000Z"}
{"type":"done","side":"sell","order_id":"30f6c6e7-ff06-48dc-a00e-5c9429f0a45d","reason":"canceled","product_id":"BTC-EUR","price":"8825.76000000","remaining_size":"0.06847422","sequence":3257979536,"time":"2018-01-22T15:14:46.440000Z"}
{"type":"done","side":"buy","order_id":"e526149f-7abd-40d0-882d-86e78716c3b4","reason":"canceled","product_id":"BTC-EUR","price":"8724.99000000","remaining_size":"0.01586384","sequence":3257979537,"time":"2018-01-22T15:14:46.441000Z"}
{"type":"done","side":"buy","order_id":"8acd45d4-601f-4587-b516-35f32290c911","reason":"canceled","product_id":"BTC-EUR","price":"8769.41000000","remaining_size":"0.01586384","sequence":3257979538,"time":"2018-01-22T15:14:46.442000Z"}
{"type":"done","side":"sell","order_id":"5d8d6cc1-dccd-4482-9033-62e91050b040","reason":"canceled","product_id":"BTC-EUR","price":"8916.44000000","remaining_size":"0.36857350","sequence":3257979539,"time":"2018-01-22T15:14:46.442000Z"}
{"type":"done","side":"buy","order_id":"70faedb3-b686-409a-9433-56e73d28946c","reason":"canceled","product_id":"BTC-EUR","price":"8813.84000000","remaining_size":"0.01586384","sequence":3257979540,"time":"2018-01-22T15:14:46.445000Z"}
{"type":"done","side":"sell","order_id":"98f0a1ad-4491-4700-b2d7-4009282f5528","reason":"canceled","product_id":"BTC-EUR","price":"8923.74000000","remaining_size":"0.19762425","sequence":3257979541,"time":"2018-01-22T15:14:46.445000Z"}
{"type":"done","side":"buy","order_id":"71084260-c85f-4343-83f6-861b10fcd5db","reason":"canceled","product_id":"BTC-EUR","price":"8776.62000000","remaining_size":"0.09415844","sequence":3257979542,"time":"2018-01-22T15:14:46.447000Z"}
{"type":"done","side":"buy","order_id":"7f9fb242-ebce-4ae3-8486-5a976ff8815d","reason":"canceled","product_id":"BTC-EUR","price":"8732.20000000","remaining_size":"0.09415844","sequence":3257979543,"time":"2018-01-22T15:14:46.447000Z"}
{"type":"done","side":"sell","order_id":"e5a82f2e-5c67-42ab-890d-a3aa48f097d6","reason":"canceled","product_id":"BTC-EUR","price":"8936.45000000","remaining_size":"0.19762425","sequence":3257979544,"time":"2018-01-22T15:14:46.450000Z"}
{"type":"done","side":"sell","order_id":"d4e79519-a3d9-4dff-a654-7ab0c5583a81","reason":"canceled","product_id":"BTC-EUR","price":"8904.12000000","remaining_size":"0.19762425","sequence":3257979545,"time":"2018-01-22T15:14:46.450000Z"}
{"type":"received","order_id":"f98a8703-5dd3-4a90-a4d5-828d7936b7b4","order_type":"limit","size":"0.21404538","price":"8825.75000000","side":"sell","product_id":"BTC-EUR","sequence":3257979546,"time":"2018-01-22T15:14:46.451000Z"}
{"type":"open","side":"sell","price":"8825.75000000","order_id":"f98a8703-5dd3-4a90-a4d5-828d7936b7b4","remaining_size":"0.21404538","product_id":"BTC-EUR","sequence":3257979547,"time":"2018-01-22T15:14:46.451000Z"}
{"type":"done","side":"buy","order_id":"9a2718e2-b750-4bb6-80ac-37bb532ef09f","reason":"canceled","product_id":"BTC-EUR","price":"8680.56000000","remaining_size":"0.01586384","sequence":3257979548,"time":"2018-01-22T15:14:46.455000Z"}
{"type":"done","side":"sell","order_id":"140db8a0-76ba-4d04-89a2-9435fcf81375","reason":"canceled","product_id":"BTC-EUR","price":"8915.60000000","remaining_size":"0.19762425","sequence":3257979549,"time":"2018-01-22T15:14:46.455000Z"}
{"type":"done","side":"sell","order_id":"8aa1590a-c71f-4231-86fa-246b4f4e6af8","reason":"canceled","product_id":"BTC-EUR","price":"8891.47000000","remaining_size":"0.19762425","sequence":3257979550,"time":"2018-01-22T15:14:46.457000Z"}
{"type":"done","side":"sell","order_id":"665e5a5d-8deb-40b1-b711-910bd136d132","reason":"canceled","product_id":"BTC-EUR","price":"8825.73000000","remaining_size":"0.10500000","sequence":3257979551,"time":"2018-01-22T15:14:46.457000Z"}
{"type":"received","order_id":"367c6217-5684-4c2d-8d8c-c237f5e34207","order_type":"limit","size":"0.06847422","price":"8825.72000000","side":"sell","client_oid":"ad01a6ae-7657-4d19-84d4-429bfa64de31","product_id":"BTC-EUR","sequence":3257979552,"time":"2018-01-22T15:14:46.460000Z"}
{"type":"open","side":"sell","price":"8825.72000000","order_id":"367c6217-5684-4c2d-8d8c-c237f5e34207","remaining_size":"0.06847422","product_id":"BTC-EUR","sequence":3257979553,"time":"2018-01-22T15:14:46.460000Z"}
{"type":"done","side":"buy","order_id":"c3a3aab5-0832-4cb0-9578-228675ca91bf","reason":"canceled","product_id":"BTC-EUR","price":"8694.97000000","remaining_size":"0.09415845","sequence":3257979554,"time":"2018-01-22T15:14:46.464000Z"}
{"type":"done","side":"sell","order_id":"50799bb6-7611-4cde-b4ef-fd2c0aaf9b8d","reason":"canceled","product_id":"BTC-EUR","price":"8919.09000000","remaining_size":"1.35301324","sequence":3257979555,"time":"2018-01-22T15:14:46.465000Z"}
{"type":"received","order_id":"3c68f438-b54a-4f41-9735-2df8c4c8bb57","order_type":"limit","size":"0.01800000","price":"8825.71000000","side":"sell","client_oid":"6c27b39d-9d37-4574-b813-50e305eb3afc","product_id":"BTC-EUR","sequence":3257979556,"time":"2018-01-22T15:14:46.468000Z"}
{"type":"open","side":"sell","price":"8825.71000000","order_id":"3c68f438-b54a-4f41-9735-2df8c4c8bb57","remaining_size":"0.01800000","product_id":"BTC-EUR","sequence":3257979557,"time":"2018-01-22T15:14:46.468000Z"}
{"type":"received","order_id":"99a4e1ab-b801-4850-859b-fd63a9182db9","order_type":"limit","size":"0.00200000","price":"8825.71000000","side":"sell","client_oid":"75b84ba1-14aa-4bfd-b172-03c8dd23b579","product_id":"BTC-EUR","sequence":3257979558,"time":"2018-01-22T15:14:46.472000Z"}
{"type":"open","side":"sell","price":"8825.71000000","order_id":"99a4e1ab-b801-4850-859b-fd63a9182db9","remaining_size":"0.00200000","product_id":"BTC-EUR","sequence":3257979559,"time":"2018-01-22T15:14:46.472000Z"}
{"type":"done","side":"sell","order_id":"73f74b3e-64f1-498f-8b1c-68f82d6c6fb5","reason":"canceled","product_id":"BTC-EUR","price":"8930.98000000","remaining_size":"1.35301324","sequence":3257979560,"time":"2018-01-22T15:14:46.473000Z"}
{"type":"done","side":"sell","order_id":"5e0f8665-6314-4b48-a766-1e3eaa89b8c5","reason":"canceled","product_id":"BTC-EUR","price":"8887.96000000","remaining_size":"1.35301324","sequence":3257979561,"time":"2018-01-22T15:14:46.473000Z"}
{"type":"done","side":"sell","order_id":"a3681cfc-8dbf-4a17-a204-c8f4d3fb3867","reason":"canceled","product_id":"BTC-EUR","price":"8825.72000000","remaining_size":"0.03322226","sequence":3257979562,"time":"2018-01-22T15:14:46.477000Z"}
{"type":"done","side":"sell","order_id":"7f4b0610-095e-4e44-9ba2-155fd3d35891","reason":"canceled","product_id":"BTC-EUR","price":"8897.77000000","remaining_size":"1.35301324","sequence":3257979563,"time":"2018-01-22T15:14:46.480000Z"}
{"type":"done","side":"sell","order_id":"a8484303-fd5b-4a96-acc7-ba32bdf62792","reason":"canceled","product_id":"BTC-EUR","price":"8907.21000000","remaining_size":"1.35301324","sequence":3257979564,"time":"2018-01-22T15:14:46.480000Z"}
{"type":"done","side":"sell","order_id":"3befd174-6fa9-4523-827a-1f4114650c17","reason":"canceled","product_id":"BTC-EUR","price":"8915.61000000","remaining_size":"0.03773580","sequence":3257979565,"time":"2018-01-22T15:14:46.483000Z"}
{"type":"done","side":"sell","order_id":"16b14d26-38bc-4a26-93ed-aa682101359a","reason":"canceled","product_id":"BTC-EUR","price":"8825.72000000","remaining_size":"0.01800000","sequence":3257979566,"time":"2018-01-22T15:14:46.495000Z"}
{"type":"received","order_id":"b091a177-de2d-440d-a6de-f0ec7bfdd8d6","order_type":"limit","size":"0.10500000","price":"8825.71000000","side":"sell","client_oid":"01bbe40d-984d-4c01-9ecd-16faae300bc8","product_id":"BTC-EUR","sequence":3257979567,"time":"2018-01-22T15:14:46.500000Z"}
{"type":"open","side":"sell","price":"8825.71000000","order_id":"b091a177-de2d-440d-a6de-f0ec7bfdd8d6","remaining_size":"0.10500000","product_id":"BTC-EUR","sequence":3257979568,"time":"2018-01-22T15:14:46.500000Z"}
{"type":"done","side":"sell","order_id":"c45eccc9-e087-4c43-8be0-67f3dc1fe57a","reason":"canceled","product_id":"BTC-EUR","price":"8825.73000000","remaining_size":"0.06847422","sequence":3257979569,"time":"2018-01-22T15:14:46.564000Z"}
{"type":"done","side":"sell","order_id":"0601b554-6f52-430c-af2e-19658037b522","reason":"canceled","product_id":"BTC-EUR","price":"8825.74000000","remaining_size":"0.06847422","sequence":3257979570,"time":"2018-01-22T15:14:46.565000Z"}
{"type":"done","side":"sell","order_id":"7d69dd85-f032-47a9-9904-a4090057e214","reason":"canceled","product_id":"BTC-EUR","price":"8826.02000000","remaining_size":"0.00564464","sequence":3257979571,"time":"2018-01-22T15:14:46.574000Z"}
{"type":"received","order_id":"d51c179e-562a-42e4-a81c-ce0ec16140b0","order_type":"limit","size":"0.01800000","price":"8825.70000000","side":"sell","client_oid":"671f8328-4651-4af3-a17c-a95b7ffe3c9e","product_id":"BTC-EUR","sequence":3257979572,"time":"2018-01-22T15:14:46.578000Z"}
{"type":"open","side":"sell","price":"8825.70000000","order_id":"d51c179e-562a-42e4-a81c-ce0ec16140b0","remaining_size":"0.01800000","product_id":"BTC-EUR","sequence":3257979573,"time":"2018-01-22T15:14:46.578000Z"}
{"type":"received","order_id":"cd31fa2e-678a-4c23-ba18-528f4327c40b","order_type":"limit","size":"0.06847422","price":"8825.71000000","side":"sell","client_oid":"b17e38af-ee0d-4109-9f5e-dcc006309a7a","product_id":"BTC-EUR","sequence":3257979574,"time":"2018-01-22T15:14:46.581000Z"}
{"type":"open","side":"sell","price":"8825.71000000","order_id":"cd31fa2e-678a-4c23-ba18-528f4327c40b","remaining_size":"0.06847422","product_id":"BTC-EUR","sequence":3257979575,"time":"2018-01-22T15:14:46.581000Z"}
{"type":"done","side":"sell","order_id":"f98a8703-5dd3-4a90-a4d5-828d7936b7b4","reason":"canceled","product_id":"BTC-EUR","price":"8825.75000000","remaining_size":"0.21404538","sequence":3257979576,"time":"2018-01-22T15:14:46.588000Z"}
{"type":"received","order_id":"7b3a976f-930b-47b2-bf62-83c3b43820b8","order_type":"limit","size":"0.03322226","price":"8825.70000000","side":"sell","client_oid":"b2839ddf-b4d9-4d78-8c23-5617e6f25259","product_id":"BTC-EUR","sequence":3257979577,"time":"2018-01-22T15:14:46.590000Z"}
{"type":"open","side":"sell","price":"8825.70000000","order_id":"7b3a976f-930b-47b2-bf62-83c3b43820b8","remaining_size":"0.03322226","product_id":"BTC-EUR","sequence":3257979578,"time":"2018-01-22T15:14:46.590000Z"}
{"type":"done","side":"sell","order_id":"f4e6e18a-e62c-4b13-8df6-6cfcd02a0159","reason":"canceled","product_id":"BTC-EUR","price":"8825.71000000","remaining_size":"0.00113290","sequence":3257979579,"time":"2018-01-22T15:14:46.604000Z"}
{"type":"done","side":"sell","order_id":"99a4e1ab-b801-4850-859b-fd63a9182db9","reason":"canceled","product_id":"BTC-EUR","price":"8825.71000000","remaining_size":"0.00200000","sequence":3257979580,"time":"2018-01-22T15:14:46.656000Z"}
{"type":"received","order_id":"56f2b587-640b-4ffd-92b8-da7566549249","order_type":"limit","size":"0.00113290","price":"8825.69000000","side":"sell","client_oid":"e5fcc468-b613-4402-8b2f-6983480608d1","product_id":"BTC-EUR","sequence":3257979581,"time":"2018-01-22T15:14:46.662000Z"}
{"type":"open","side":"sell","price":"8825.69000000","order_id":"56f2b587-640b-4ffd-92b8-da7566549249","remaining_size":"0.00113290","product_id":"BTC-EUR","sequence":3257979582,"time":"2018-01-22T15:14:46.662000Z"}
{"type":"done","side":"sell","order_id":"367c6217-5684-4c2d-8d8c-c237f5e34207","reason":"canceled","product_id":"BTC-EUR","price":"8825.72000000","remaining_size":"0.06847422","sequence":3257979583,"time":"2018-01-22T15:14:46.683000Z"}
{"type":"received","order_id":"523dd546-e932-4d77-b61a-fefa75769b3c","order_type":"limit","size":"0.00200000","price":"8825.69000000","side":"sell","client_oid":"28ba936d-4f41-4a64-a4f1-4bc017e644bf","product_id":"BTC-EUR","sequence":3257979584,"time":"2018-01-22T15:14:46.684000Z"}
{"type":"open","side":"sell","price":"8825.69000000","order_id":"523dd546-e932-4d77-b61a-fefa75769b3c","remaining_size":"0.00200000","product_id":"BTC-EUR","sequence":3257979585,"time":"2018-01-22T15:14:46.684000Z"}
{"type":"received","order_id":"e5a0c53f-f3d8-4c9f-8079-33a92914ca6a","order_type":"limit","size":"0.06847422","price":"8825.70000000","side":"sell","client_oid":"7758811e-3475-4712-a4f3-99ba0681c2f8","product_id":"BTC-EUR","sequence":3257979586,"time":"2018-01-22T15:14:46.694000Z"}
{"type":"open","side":"sell","price":"8825.70000000","order_id":"e5a0c53f-f3d8-4c9f-8079-33a92914ca6a","remaining_size":"0.06847422","product_id":"BTC-EUR","sequence":3257979587,"time":"2018-01-22T15:14:46.694000Z"}
{"type":"done","side":"sell","order_id":"b091a177-de2d-440d-a6de-f0ec7bfdd8d6","reason":"canceled","product_id":"BTC-EUR","price":"8825.71000000","remaining_size":"0.10500000","sequence":3257979588,"time":"2018-01-22T15:14:46.694000Z"}
{"type":"received","order_id":"d852dde4-0402-40d0-80d1-00e274344602","order_type":"limit","size":"0.10500000","price":"8825.71000000","side":"sell","client_oid":"a16e0aec-c43e-4ba9-b3b9-e99ad6eb9e76","product_id":"BTC-EUR","sequence":3257979589,"time":"2018-01-22T15:14:46.697000Z"}
{"type":"open","side":"sell","price":"8825.71000000","order_id":"d852dde4-0402-40d0-80d1-00e274344602","remaining_size":"0.10500000","product_id":"BTC-EUR","sequence":3257979590,"time":"2018-01-22T15:14:46.697000Z"}
{"type":"done","side":"sell","order_id":"3c68f438-b54a-4f41-9735-2df8c4c8bb57","reason":"canceled","product_id":"BTC-EUR","price":"8825.71000000","remaining_size":"0.01800000","sequence":3257979591,"time":"2018-01-22T15:14:46.712000Z"}
{"type":"done","side":"sell","order_id":"d51c179e-562a-42e4-a81c-ce0ec16140b0","reason":"canceled","product_id":"BTC-EUR","price":"8825.70000000","remaining_size":"0.01800000","sequence":3257979592,"time":"2018-01-22T15:14:46.740000Z"}
{"type":"received","order_id":"d06532ae-5eb9-4394-87e2-83bf2e44f8b0","order_type":"limit","size":"0.10500000","price":"8825.70000000","side":"sell","client_oid":"38241c64-54db-41d3-832d-8d7b36a3df3a","product_id":"BTC-EUR","sequence":3257979593,"time":"2018-01-22T15:14:46.741000Z"}
{"type":"open","side":"sell","price":"8825.70000000","order_id":"d06532ae-5eb9-4394-87e2-83bf2e44f8b0","remaining_size":"0.10500000","product_id":"BTC-EUR","sequence":3257979594,"time":"2018-01-22T15:14:46.741000Z"}
{"type":"done","side":"sell","order_id":"d852dde4-0402-40d0-80d1-00e274344602","reason":"canceled","product_id":"BTC-EUR","price":"8825.71000000","remaining_size":"0.10500000","sequence":3257979595,"time":"2018-01-22T15:14:46.775000Z"}
{"type":"received","order_id":"f04af767-d4b1-48fd-b08f-ffd06e92a687","order_type":"limit","size":"0.01800000","price":"8825.68000000","side":"sell","client_oid":"de7347fc-8f16-49b1-bf29-c1a1976e47c7","product_id":"BTC-EUR","sequence":3257979596,"time":"2018-01-22T15:14:46.788000Z"}
{"type":"open","side":"sell","price":"8825.68000000","order_id":"f04af767-d4b1-48fd-b08f-ffd06e92a687","remaining_size":"0.01800000","product_id":"BTC-EUR","sequence":3257979597,"time":"2018-01-22T15:14:46.788000Z"}
{"type":"received","order_id":"fd036868-e63a-4bb8-a6e9-5bf8061e6344","order_type":"limit","size":"0.10500000","price":"8825.69000000","side":"sell","client_oid":"b98ce35f-2ad9-4567-8f0c-61f052101aec","product_id":"BTC-EUR","sequence":3257979598,"time":"2018-01-22T15:14:46.797000Z"}
{"type":"open","side":"sell","price":"8825.69000000","order_id":"fd036868-e63a-4bb8-a6e9-5bf8061e6344","remaining_size":"0.10500000","product_id":"BTC-EUR","sequence":3257979599,"time":"2018-01-22T15:14:46.797000Z"}
{"type":"done","side":"sell","order_id":"cd31fa2e-678a-4c23-ba18-528f4327c40b","reason":"canceled","product_id":"BTC-EUR","price":"8825.71000000","remaining_size":"0.06847422","sequence":3257979600,"time":"2018-01-22T15:14:46.806000Z"}
{"type":"done","side":"sell","order_id":"7b3a976f-930b-47b2-bf62-83c3b43820b8","reason":"canceled","product_id":"BTC-EUR","price":"8825.70000000","remaining_size":"0.03322226","sequence":3257979601,"time":"2018-01-22T15:14:46.811000Z"}
{"type":"received","order_id":"629a8c20-5466-4484-a83a-9039785dab63","order_type":"limit","size":"0.06847422","price":"8825.69000000","side":"sell","client_oid":"912da5a1-e6e9-4774-95fc-1f1eaeffe21d","product_id":"BTC-EUR","sequence":3257979602,"time":"2018-01-22T15:14:46.821000Z"}
{"type":"open","side":"sell","price":"8825.69000000","order_id":"629a8c20-5466-4484-a83a-9039785dab63","remaining_size":"0.06847422","product_id":"BTC-EUR","sequence":3257979603,"time":"2018-01-22T15:14:46.821000Z"}
{"type":"received","order_id":"edd41ea7-3fba-47bd-85f5-ad2d20103f47","order_type":"limit","size":"0.00564464","price":"8825.69000000","side":"sell","client_oid":"e69972b7-8ddf-4e9c-a8e3-bae192883929","product_id":"BTC-EUR","sequence":3257979604,"time":"2018-01-22T15:14:46.828000Z"}
{"type":"open","side":"sell","price":"8825.69000000","order_id":"edd41ea7-3fba-47bd-85f5-ad2d20103f47","remaining_size":"0.00564464","product_id":"BTC-EUR","sequence":3257979605,"time":"2018-01-22T15:14:46.828000Z"}
{"type":"received","order_id":"4bf14b01-5571-47d6-abfb-39a395edb528","order_type":"limit","size":"0.03322226","price":"8825.68000000","side":"sell","client_oid":"1716dbb7-d96e-4afc-8f9e-72a902b1672b","product_id":"BTC-EUR","sequence":3257979606,"time":"2018-01-22T15:14:46.848000Z"}
{"type":"open","side":"sell","price":"8825.68000000","order_id":"4bf14b01-5571-47d6-abfb-39a395edb528","remaining_size":"0.03322226","product_id":"BTC-EUR","sequence":3257979607,"time":"2018-01-22T15:14:46.848000Z"}
{"type":"done","side":"sell","order_id":"decdbab6-df99-4bca-be82-b20d3087ac15","reason":"canceled","product_id":"BTC-EUR","price":"8825.76000000","remaining_size":"0.04164971","sequence":3257979608,"time":"2018-01-22T15:14:46.866000Z"}
{"type":"done","side":"sell","order_id":"523dd546-e932-4d77-b61a-fefa75769b3c","reason":"canceled","product_id":"BTC-EUR","price":"8825.69000000","remaining_size":"0.00200000","sequence":3257979609,"time":"2018-01-22T15:14:46.874000Z"}
{"type":"done","side":"sell","order_id":"d06532ae-5eb9-4394-87e2-83bf2e44f8b0","reason":"canceled","product_id":"BTC-EUR","price":"8825.70000000","remaining_size":"0.10500000","sequence":3257979610,"time":"2018-01-22T15:14:46.895000Z"}
{"type":"done","side":"sell","order_id":"56f2b587-640b-4ffd-92b8-da7566549249","reason":"canceled","product_id":"BTC-EUR","price":"8825.69000000","remaining_size":"0.00113290","sequence":3257979611,"time":"2018-01-22T15:14:46.902000Z"}
{"type":"received","order_id":"379d29b0-09b4-4c53-8090-425003d79e41","order_type":"limit","size":"0.10500000","price":"8825.69000000","side":"sell","client_oid":"099bd830-acac-4065-9ae9-d8e712622885","product_id":"BTC-EUR","sequence":3257979612,"time":"2018-01-22T15:14:46.906000Z"}
{"type":"open","side":"sell","price":"8825.69000000","order_id":"379d29b0-09b4-4c53-8090-425003d79e41","remaining_size":"0.10500000","product_id":"BTC-EUR","sequence":3257979613,"time":"2018-01-22T15:14:46.906000Z"}
{"type":"done","side":"sell","order_id":"3de85c59-06ef-4c0c-bbb9-15785aa9d6c7","reason":"canceled","product_id":"BTC-EUR","price":"8825.76000000","remaining_size":"0.01322632","sequence":3257979614,"time":"2018-01-22T15:14:46.912000Z"}
{"type":"received","order_id":"4ffc22cc-bbd0-4712-a5af-8a43671262e0","order_type":"limit","size":"0.14717737","price":"8979.55000000","side":"sell","product_id":"BTC-EUR","sequence":3257979615,"time":"2018-01-22T15:14:46.916000Z"}
{"type":"open","side":"sell","price":"8979.55000000","order_id":"4ffc22cc-bbd0-4712-a5af-8a43671262e0","remaining_size":"0.14717737","product_id":"BTC-EUR","sequence":3257979616,"time":"2018-01-22T15:14:46.916000Z"}
{"type":"done","side":"sell","order_id":"e5a0c53f-f3d8-4c9f-8079-33a92914ca6a","reason":"canceled","product_id":"BTC-EUR","price":"8825.70000000","remaining_size":"0.06847422","sequence":3257979617,"time":"2018-01-22T15:14:46.924000Z"}
{"type":"received","order_id":"7aaf944e-520e-4fc5-bd80-9e24acd9003f","order_type":"limit","size":"0.00200000","price":"8825.67000000","side":"sell","client_oid":"37105737-7e0c-4a5b-b9e6-d8babc0e0c74","product_id":"BTC-EUR","sequence":3257979618,"time":"2018-01-22T15:14:46.933000Z"}
{"type":"open","side":"sell","price":"8825.67000000","order_id":"7aaf944e-520e-4fc5-bd80-9e24acd9003f","remaining_size":"0.00200000","product_id":"BTC-EUR","sequence":3257979619,"time":"2018-01-22T15:14:46.933000Z"}
{"type":"received","order_id":"5e91e94b-eb18-44c4-8df3-ee780837f361","order_type":"limit","size":"0.06847422","price":"8825.68000000","side":"sell","client_oid":"ba09bb94-495c-49d4-b7c6-97388460b662","product_id":"BTC-EUR","sequence":3257979620,"time":"2018-01-22T15:14:46.935000Z"}
{"type":"open","side":"sell","price":"8825.68000000","order_id":"5e91e94b-eb18-44c4-8df3-ee780837f361","remaining_size":"0.06847422","product_id":"BTC-EUR","sequence":3257979621,"time":"2018-01-22T15:14:46.935000Z"}
{"type":"received","order_id":"85bc059c-6aaf-4295-8b47-ff78ccbbb1b2","order_type":"limit","size":"0.06847422","price":"8825.67000000","side":"sell","client_oid":"d01ab22c-1630-4d52-8d89-b2eb67130c81","product_id":"BTC-EUR","sequence":3257979622,"time":"2018-01-22T15:14:46.942000Z"}
{"type":"open","side":"sell","price":"8825.67000000","order_id":"85bc059c-6aaf-4295-8b47-ff78ccbbb1b2","remaining_size":"0.06847422","product_id":"BTC-EUR","sequence":3257979623,"time":"2018-01-22T15:14:46.942000Z"}
{"type":"received","order_id":"f1b8dc6c-b7a5-4b90-ba48-1e01b921e524","order_type":"limit","size":"0.00200000","price":"8825.67000000","side":"sell","client_oid":"fb595a18-4478-4139-a129-fef0917db63e","product_id":"BTC-EUR","sequence":3257979624,"time":"2018-01-22T15:14:46.944000Z"}
{"type":"open","side":"sell","price":"8825.67000000","order_id":"f1b8dc6c-b7a5-4b90-ba48-1e01b921e524","remaining_size":"0.00200000","product_id":"BTC-EUR","sequence":3257979625,"time":"2018-01-22T15:14:46.944000Z"}
{"type":"received","order_id":"58d611a1-f3fb-4fff-8685-aa1c571d7239","order_type":"limit","size":"0.00200000","price":"8825.67000000","side":"sell","client_oid":"5e0c50a0-c255-43dc-b9c6-cb081165ed89","product_id":"BTC-EUR","sequence":3257979626,"time":"2018-01-22T15:14:46.947000Z"}
{"type":"open","side":"sell","price":"8825.67000000","order_id":"58d611a1-f3fb-4fff-8685-aa1c571d7239","remaining_size":"0.00200000","product_id":"BTC-EUR","sequence":3257979627,"time":"2018-01-22T15:14:46.947000Z"}
{"type":"done","side":"sell","order_id":"4bf14b01-5571-47d6-abfb-39a395edb528","reason":"canceled","product_id":"BTC-EUR","price":"8825.68000000","remaining_size":"0.03322226","sequence":3257979628,"time":"2018-01-22T15:14:46.947000Z"}
{"type":"received","order_id":"eb7c92bf-dcc0-47e2-821a-f6923230a250","order_type":"limit","size":"0.00200000","price":"8825.67000000","side":"sell","client_oid":"ea6f85a3-65d8-457c-ac55-a909e89dc4e5","product_id":"BTC-EUR","sequence":3257979629,"time":"2018-01-22T15:14:46.984000Z"}
{"type":"open","side":"sell","price":"8825.67000000","order_id":"eb7c92bf-dcc0-47e2-821a-f6923230a250","remaining_size":"0.00200000","product_id":"BTC-EUR","sequence":3257979630,"time":"2018-01-22T15:14:46.984000Z"}
{"type":"done","side":"sell","order_id":"379d29b0-09b4-4c53-8090-425003d79e41","reason":"canceled","product_id":"BTC-EUR","price":"8825.69000000","remaining_size":"0.10500000","sequence":3257979631,"time":"2018-01-22T15:14:46.985000Z"}
{"type":"received","order_id":"a95123e2-8e40-4d5d-8e1a-ad8591fc8a67","order_type":"limit","size":"0.00113290","price":"8825.67000000","side":"sell","client_oid":"b228e4e9-c906-496c-bf02-34d031b1ee04","product_id":"BTC-EUR","sequence":3257979632,"time":"2018-01-22T15:14:46.985000Z"}
{"type":"open","side":"sell","price":"8825.67000000","order_id":"a95123e2-8e40-4d5d-8e1a-ad8591fc8a67","remaining_size":"0.00113290","product_id":"BTC-EUR","sequence":3257979633,"time":"2018-01-22T15:14:46.985000Z"}
{"type":"done","side":"sell","order_id":"b28742f5-90ae-4113-8af7-767f2967d4d1","reason":"canceled","product_id":"BTC-EUR","price":"8825.73000000","remaining_size":"0.22947933","sequence":3257979634,"time":"2018-01-22T15:14:46.989000Z"}
{"type":"received","order_id":"1dd76829-718d-47d4-ab66-160ea7725931","order_type":"limit","size":"0.10500000","price":"8825.68000000","side":"sell","client_oid":"f37cbe7b-6e1d-4085-b853-004441ce3ad1","product_id":"BTC-EUR","sequence":3257979635,"time":"2018-01-22T15:14:47.004000Z"}
{"type":"open","side":"sell","price":"8825.68000000","order_id":"1dd76829-718d-47d4-ab66-160ea7725931","remaining_size":"0.10500000","product_id":"BTC-EUR","sequence":3257979636,"time":"2018-01-22T15:14:47.004000Z"}
{"type":"done","side":"sell","order_id":"f04af767-d4b1-48fd-b08f-ffd06e92a687","reason":"canceled","product_id":"BTC-EUR","price":"8825.68000000","remaining_size":"0.01800000","sequence":3257979637,"time":"2018-01-22T15:14:47.020000Z"}
{"type":"received","order_id":"d3f74ca7-8a5b-4500-97b7-d99853732027","order_type":"limit","size":"0.00200000","price":"8825.67000000","side":"sell","client_oid":"1b411467-5f72-4cc8-bae9-936e3a2147a9","product_id":"BTC-EUR","sequence":3257979638,"time":"2018-01-22T15:14:47.025000Z"}
{"type":"open","side":"sell","price":"8825.67000000","order_id":"d3f74ca7-8a5b-4500-97b7-d99853732027","remaining_size":"0.00200000","product_id":"BTC-EUR","sequence":3257979639,"time":"2018-01-22T15:14:47.025000Z"}
{"type":"received","order_id":"9f7a2020-8321-4e5f-be5b-1679329d52a5","order_type":"limit","size":"0.09200000","price":"8825.67000000","side":"sell","client_oid":"eb6cc960-e36a-4eeb-9b43-417c6c4704e6","product_id":"BTC-EUR","sequence":3257979640,"time":"2018-01-22T15:14:47.026000Z"}
{"type":"open","side":"sell","price":"8825.67000000","order_id":"9f7a2020-8321-4e5f-be5b-1679329d52a5","remaining_size":"0.09200000","product_id":"BTC-EUR","sequence":3257979641,"time":"2018-01-22T15:14:47.026000Z"}
{"type":"received","order_id":"0400714a-b629-45ce-b880-2e4c43fd8b3a","order_type":"limit","size":"0.03322226","price":"8825.66000000","side":"sell","client_oid":"35063551-1021-4110-bacb-c148c4440f1e","product_id":"BTC-EUR","sequence":3257979642,"time":"2018-01-22T15:14:47.031000Z"}
{"type":"open","side":"sell","price":"8825.66000000","order_id":"0400714a-b629-45ce-b880-2e4c43fd8b3a","remaining_size":"0.03322226","product_id":"BTC-EUR","sequence":3257979643,"time":"2018-01-22T15:14:47.031000Z"}
{"type":"done","side":"sell","order_id":"a95123e2-8e40-4d5d-8e1a-ad8591fc8a67","reason":"canceled","product_id":"BTC-EUR","price":"8825.67000000","remaining_size":"0.00113290","sequence":3257979644,"time":"2018-01-22T15:14:47.040000Z"}
{"type":"received","order_id":"7de89089-312d-45f9-88ca-3724bbb14fce","order_type":"limit","size":"0.02000000","price":"8735.00000000","side":"buy","client_oid":"a36dc466-e603-4be2-a12f-70201d1a9f4f","product_id":"BTC-EUR","sequence":3257979645,"time":"2018-01-22T15:14:47.056000Z"}
{"type":"open","side":"buy","price":"8735.00000000","order_id":"7de89089-312d-45f9-88ca-3724bbb14fce","remaining_size":"0.02000000","product_id":"BTC-EUR","sequence":3257979646,"time":"2018-01-22T15:14:47.056000Z"}
{"type":"received","order_id":"ca990ede-7931-41bd-b3fa-ee176f68b7f7","order_type":"limit","size":"0.01800000","price":"8825.66000000","side":"sell","client_oid":"0727f0eb-7183-49c7-bbb3-09994eddf0a8","product_id":"BTC-EUR","sequence":3257979647,"time":"2018-01-22T15:14:47.063000Z"}
{"type":"open","side":"sell","price":"8825.66000000","order_id":"ca990ede-7931-41bd-b3fa-ee176f68b7f7","remaining_size":"0.01800000","product_id":"BTC-EUR","sequence":3257979648,"time":"2018-01-22T15:14:47.063000Z"}
{"type":"done","side":"sell","order_id":"629a8c20-5466-4484-a83a-9039785dab63","reason":"canceled","product_id":"BTC-EUR","price":"8825.69000000","remaining_size":"0.06847422","sequence":3257979649,"time":"2018-01-22T15:14:47.064000Z"}
{"type":"done","side":"sell","order_id":"1dd76829-718d-47d4-ab66-160ea7725931","reason":"canceled","product_id":"BTC-EUR","price":"8825.68000000","remaining_size":"0.10500000","sequence":3257979650,"time":"2018-01-22T15:14:47.084000Z"}
{"type":"received","order_id":"8fa84741-b9b4-47dc-a41f-dea0a5ddf04a","order_type":"limit","size":"0.04164971","price":"8825.66000000","side":"sell","client_oid":"f79156ab-c185-4bab-bf97-44784bcbeaa9","product_id":"BTC-EUR","sequence":3257979651,"time":"2018-01-22T15:14:47.101000Z"}
{"type":"open","side":"sell","price":"8825.66000000","order_id":"8fa84741-b9b4-47dc-a41f-dea0a5ddf04a","remaining_size":"0.04164971","product_id":"BTC-EUR","sequence":3257979652,"time":"2018-01-22T15:14:47.101000Z"}
{"type":"received","order_id":"d737c98f-bbda-43ad-a2ef-2a944842d221","order_type":"limit","size":"0.10500000","price":"8825.67000000","side":"sell","client_oid":"a05e4fa9-5057-4601-856c-3f681aecd4cc","product_id":"BTC-EUR","sequence":3257979653,"time":"2018-01-22T15:14:47.108000Z"}
{"type":"open","side":"sell","price":"8825.67000000","order_id":"d737c98f-bbda-43ad-a2ef-2a944842d221","remaining_size":"0.10500000","product_id":"BTC-EUR","sequence":3257979654,"time":"2018-01-22T15:14:47.108000Z"}
{"type":"done","side":"sell","order_id":"eb7c92bf-dcc0-47e2-821a-f6923230a250","reason":"canceled","product_id":"BTC-EUR","price":"8825.67000000","remaining_size":"0.00200000","sequence":3257979655,"time":"2018-01-22T15:14:47.108000Z"}
{"type":"done","side":"sell","order_id":"b723a332-4d47-4e99-b6d2-6311fa4fbbcd","reason":"canceled","product_id":"BTC-EUR","price":"8997.24000000","remaining_size":"0.14616719","sequence":3257979656,"time":"2018-01-22T15:14:47.119000Z"}
{"type":"received","order_id":"5aac6c52-a935-4002-9c9d-6b7437ca244b","order_type":"limit","size":"0.00200000","price":"8825.65000000","side":"sell","client_oid":"252452d9-226c-49f3-8122-16bee1bd1c81","product_id":"BTC-EUR","sequence":3257979657,"time":"2018-01-22T15:14:47.131000Z"}
{"type":"open","side":"sell","price":"8825.65000000","order_id":"5aac6c52-a935-4002-9c9d-6b7437ca244b","remaining_size":"0.00200000","product_id":"BTC-EUR","sequence":3257979658,"time":"2018-01-22T15:14:47.131000Z"}
{"type":"done","side":"buy","order_id":"594dd54b-f11b-4c4a-b4b7-66de0295a333","reason":"canceled","product_id":"BTC-EUR","price":"8799.28000000","remaining_size":"0.20699000","sequence":3257979659,"time":"2018-01-22T15:14:47.142000Z"}
{"type":"done","side":"sell","order_id":"7aaf944e-520e-4fc5-bd80-9e24acd9003f","reason":"canceled","product_id":"BTC-EUR","price":"8825.67000000","remaining_size":"0.00200000","sequence":3257979660,"time":"2018-01-22T15:14:47.150000Z"}
{"type":"done","side":"sell","order_id":"58d611a1-f3fb-4fff-8685-aa1c571d7239","reason":"canceled","product_id":"BTC-EUR","price":"8825.67000000","remaining_size":"0.00200000","sequence":3257979661,"time":"2018-01-22T15:14:47.150000Z"}
{"type":"received","order_id":"fb7c110d-ad96-453d-a975-3b6479578653","order_type":"limit","size":"0.01322632","price":"8825.66000000","side":"sell","client_oid":"29c8c9e0-2770-484a-8518-4da58398b5d4","product_id":"BTC-EUR","sequence":3257979662,"time":"2018-01-22T15:14:47.153000Z"}
{"type":"open","side":"sell","price":"8825.66000000","order_id":"fb7c110d-ad96-453d-a975-3b6479578653","remaining_size":"0.01322632","product_id":"BTC-EUR","sequence":3257979663,"time":"2018-01-22T15:14:47.153000Z"}
{"type":"received","order_id":"ec891f0f-4e00-4f0c-a16e-475ec7d152db","order_type":"limit","size":"0.10500000","price":"8825.66000000","side":"sell","client_oid":"021c0208-5284-4c48-be98-1a859d662ebe","product_id":"BTC-EUR","sequence":3257979664,"time":"2018-01-22T15:14:47.175000Z"}
{"type":"open","side":"sell","price":"8825.66000000","order_id":"ec891f0f-4e00-4f0c-a16e-475ec7d152db","remaining_size":"0.10500000","product_id":"BTC-EUR","sequence":3257979665,"time":"2018-01-22T15:14:47.175000Z"}
{"type":"done","side":"sell","order_id":"f1b8dc6c-b7a5-4b90-ba48-1e01b921e524","reason":"canceled","product_id":"BTC-EUR","price":"8825.67000000","remaining_size":"0.00200000","sequence":3257979666,"time":"2018-01-22T15:14:47.183000Z"}
{"type":"done","side":"sell","order_id":"d3f74ca7-8a5b-4500-97b7-d99853732027","reason":"canceled","product_id":"BTC-EUR","price":"8825.67000000","remaining_size":"0.00200000","sequence":3257979667,"time":"2018-01-22T15:14:47.183000Z"}
{"type":"done","side":"sell","order_id":"9f7a2020-8321-4e5f-be5b-1679329d52a5","reason":"canceled","product_id":"BTC-EUR","price":"8825.67000000","remaining_size":"0.09200000","sequence":3257979668,"time":"2018-01-22T15:14:47.186000Z"}
{"type":"done","side":"sell","order_id":"d737c98f-bbda-43ad-a2ef-2a944842d221","reason":"canceled","product_id":"BTC-EUR","price":"8825.67000000","remaining_size":"0.10500000","sequence":3257979669,"time":"2018-01-22T15:14:47.188000Z"}
{"type":"received","order_id":"0da3b0d7-883b-4623-9079-a0f25647c595","order_type":"limit","size":"0.06847422","price":"8825.66000000","side":"sell","client_oid":"9a58230c-e196-45dd-8705-e540201637bf","product_id":"BTC-EUR","sequence":3257979670,"time":"2018-01-22T15:14:47.196000Z"}
{"type":"open","side":"sell","price":"8825.66000000","order_id":"0da3b0d7-883b-4623-9079-a0f25647c595","remaining_size":"0.06847422","product_id":"BTC-EUR","sequence":3257979671,"time":"2018-01-22T15:14:47.196000Z"}
{"type":"received","order_id":"61464423-aab5-4113-bb0c-9822d2b21f47","order_type":"limit","size":"0.00113290","price":"8825.65000000","side":"sell","client_oid":"43eaac56-a84e-4715-86ff-77cddcee5e8a","product_id":"BTC-EUR","sequence":3257979672,"time":"2018-01-22T15:14:47.202000Z"}
{"type":"open","side":"sell","price":"8825.65000000","order_id":"61464423-aab5-4113-bb0c-9822d2b21f47","remaining_size":"0.00113290","product_id":"BTC-EUR","sequence":3257979673,"time":"2018-01-22T15:14:47.202000Z"}
{"type":"received","order_id":"479c5080-f470-4c14-a92d-648530504dee","order_type":"limit","size":"0.22947933","price":"8825.65000000","side":"sell","client_oid":"10dbb097-e9eb-4fd5-9eb2-8a1c41179692","product_id":"BTC-EUR","sequence":3257979674,"time":"2018-01-22T15:14:47.209000Z"}
{"type":"open","side":"sell","price":"8825.65000000","order_id":"479c5080-f470-4c14-a92d-648530504dee","remaining_size":"0.22947933","product_id":"BTC-EUR","sequence":3257979675,"time":"2018-01-22T15:14:47.209000Z"}
{"type":"done","side":"sell","order_id":"ca990ede-7931-41bd-b3fa-ee176f68b7f7","reason":"canceled","product_id":"BTC-EUR","price":"8825.66000000","remaining_size":"0.01800000","sequence":3257979676,"time":"2018-01-22T15:14:47.211000Z"}
{"type":"received","order_id":"7c1661e7-b8b8-4a20-9543-f19df72cd9e8","order_type":"limit","size":"0.21404538","price":"8825.65000000","side":"sell","product_id":"BTC-EUR","sequence":3257979677,"time":"2018-01-22T15:14:47.218000Z"}
{"type":"open","side":"sell","price":"8825.65000000","order_id":"7c1661e7-b8b8-4a20-9543-f19df72cd9e8","remaining_size":"0.21404538","product_id":"BTC-EUR","sequence":3257979678,"time":"2018-01-22T15:14:47.218000Z"}
{"type":"done","side":"sell","order_id":"0400714a-b629-45ce-b880-2e4c43fd8b3a","reason":"canceled","product_id":"BTC-EUR","price":"8825.66000000","remaining_size":"0.03322226","sequence":3257979679,"time":"2018-01-22T15:14:47.236000Z"}
{"type":"received","order_id":"21ad13fa-fcec-45d5-b9a7-c736607920d0","order_type":"limit","size":"0.10500000","price":"8825.66000000","side":"sell","client_oid":"a01637cb-601c-4af6-bc31-a8486bbe3773","product_id":"BTC-EUR","sequence":3257979680,"time":"2018-01-22T15:14:47.238000Z"}
{"type":"open","side":"sell","price":"8825.66000000","order_id":"21ad13fa-fcec-45d5-b9a7-c736607920d0","remaining_size":"0.10500000","product_id":"BTC-EUR","sequence":3257979681,"time":"2018-01-22T15:14:47.238000Z"}
{"type":"received","order_id":"db874232-44b3-4543-ae11-27a0253cef8e","order_type":"limit","size":"0.01800000","price":"8825.64000000","side":"sell","client_oid":"b080db82-e8a1-4540-a81c-7390b387f65c","product_id":"BTC-EUR","sequence":3257979682,"time":"2018-01-22T15:14:47.259000Z"}
{"type":"open","side":"sell","price":"8825.64000000","order_id":"db874232-44b3-4543-ae11-27a0253cef8e","remaining_size":"0.01800000","product_id":"BTC-EUR","sequence":3257979683,"time":"2018-01-22T15:14:47.259000Z"}
{"type":"done","side":"sell","order_id":"61464423-aab5-4113-bb0c-9822d2b21f47","reason":"canceled","product_id":"BTC-EUR","price":"8825.65000000","remaining_size":"0.00113290","sequence":3257979684,"time":"2018-01-22T15:14:47.273000Z"}
{"type":"done","side":"sell","order_id":"ec891f0f-4e00-4f0c-a16e-475ec7d152db","reason":"canceled","product_id":"BTC-EUR","price":"8825.66000000","remaining_size":"0.10500000","sequence":3257979685,"time":"2018-01-22T15:14:47.276000Z"}
{"type":"done","side":"sell","order_id":"85bc059c-6aaf-4295-8b47-ff78ccbbb1b2","reason":"canceled","product_id":"BTC-EUR","price":"8825.67000000","remaining_size":"0.06847422","sequence":3257979686,"time":"2018-01-22T15:14:47.314000Z"}
{"type":"done","side":"sell","order_id":"5e91e94b-eb18-44c4-8df3-ee780837f361","reason":"canceled","product_id":"BTC-EUR","price":"8825.68000000","remaining_size":"0.06847422","sequence":3257979687,"time":"2018-01-22T15:14:47.314000Z"}
{"type":"received","order_id":"6d7e981f-983d-4db6-a8d5-bf1b1ce2eed3","order_type":"limit","size":"0.10500000","price":"8825.65000000","side":"sell","client_oid":"44b06fbf-b175-4259-b6c8-f1f6b180b905","product_id":"BTC-EUR","sequence":3257979688,"time":"2018-01-22T15:14:47.324000Z"}
{"type":"open","side":"sell","price":"8825.65000000","order_id":"6d7e981f-983d-4db6-a8d5-bf1b1ce2eed3","remaining_size":"0.10500000","product_id":"BTC-EUR","sequence":3257979689,"time":"2018-01-22T15:14:47.324000Z"}
{"type":"received","order_id":"2c1fd6bc-6e04-41e8-a87a-30cb01b3c306","order_type":"limit","size":"0.06847422","price":"8825.64000000","side":"sell","client_oid":"76c9c98b-ce64-41b0-a228-f6221e8e3dbc","product_id":"BTC-EUR","sequence":3257979690,"time":"2018-01-22T15:14:47.324000Z"}
{"type":"open","side":"sell","price":"8825.64000000","order_id":"2c1fd6bc-6e04-41e8-a87a-30cb01b3c306","remaining_size":"0.06847422","product_id":"BTC-EUR","sequence":3257979691,"time":"2018-01-22T15:14:47.324000Z"}
{"type":"received","order_id":"ffc27c06-3081-44b5-a518-e7b513efd76f","order_type":"limit","size":"0.06847422","price":"8825.65000000","side":"sell","client_oid":"535ba82e-02bc-486c-96f9-ded6d1d16a17","product_id":"BTC-EUR","sequence":3257979692,"time":"2018-01-22T15:14:47.328000Z"}
{"type":"open","side":"sell","price":"8825.65000000","order_id":"ffc27c06-3081-44b5-a518-e7b513efd76f","remaining_size":"0.06847422","product_id":"BTC-EUR","sequence":3257979693,"time":"2018-01-22T15:14:47.328000Z"}
{"type":"done","side":"buy","order_id":"0c0ef8e0-4327-4004-99ba-df8b7d8661d1","reason":"canceled","product_id":"BTC-EUR","price":"8802.50000000","remaining_size":"0.46390796","sequence":3257979694,"time":"2018-01-22T15:14:47.339000Z"}
{"type":"received","order_id":"6779cb82-8195-4ee0-b7f8-125f2bca5bd3","order_type":"limit","size":"0.00113290","price":"8825.63000000","side":"sell","client_oid":"5b2c471d-c32a-40e6-b22c-0cdbebdf915f","product_id":"BTC-EUR","sequence":3257979695,"time":"2018-01-22T15:14:47.349000Z"}
{"type":"open","side":"sell","price":"8825.63000000","order_id":"6779cb82-8195-4ee0-b7f8-125f2bca5bd3","remaining_size":"0.00113290","product_id":"BTC-EUR","sequence":3257979696,"time":"2018-01-22T15:14:47.349000Z"}
{"type":"done","side":"sell","order_id":"21ad13fa-fcec-45d5-b9a7-c736607920d0","reason":"canceled","product_id":"BTC-EUR","price":"8825.66000000","remaining_size":"0.10500000","sequence":3257979697,"time":"2018-01-22T15:14:47.349000Z"}
{"type":"received","order_id":"2f2408a9-4702-41ac-89dc-296560c4b172","order_type":"limit","size":"0.01656300","price":"8825.53000000","side":"sell","product_id":"BTC-EUR","sequence":3257979698,"time":"2018-01-22T15:14:47.354000Z"}
{"type":"open","side":"sell","price":"8825.53000000","order_id":"2f2408a9-4702-41ac-89dc-296560c4b172","remaining_size":"0.01656300","product_id":"BTC-EUR","sequence":3257979699,"time":"2018-01-22T15:14:47.354000Z"}
{"type":"done","side":"sell","order_id":"6779cb82-8195-4ee0-b7f8-125f2bca5bd3","reason":"canceled","product_id":"BTC-EUR","price":"8825.63000000","remaining_size":"0.00113290","sequence":3257979700,"time":"2018-01-22T15:14:47.359000Z"}
{"type":"received","order_id":"8237cc3c-ff83-4f76-b2ca-ec6ea4c2a9eb","order_type":"limit","size":"0.20699000","price":"8799.23000000","side":"buy","product_id":"BTC-EUR","sequence":3257979701,"time":"2018-01-22T15:14:47.377000Z"}
{"type":"open","side":"buy","price":"8799.23000000","order_id":"8237cc3c-ff83-4f76-b2ca-ec6ea4c2a9eb","remaining_size":"0.20699000","product_id":"BTC-EUR","sequence":3257979702,"time":"2018-01-22T15:14:47.377000Z"}
{"type":"received","order_id":"6c534421-1460-4b7e-a189-5ad63794a908","order_type":"limit","size":"0.04094816","price":"8600.00000000","side":"buy","client_oid":"08b19386-428c-43bd-8494-5eb2af409cbd","product_id":"BTC-EUR","sequence":3257979703,"time":"2018-01-22T15:14:47.396000Z"}
{"type":"open","side":"buy","price":"8600.00000000","order_id":"6c534421-1460-4b7e-a189-5ad63794a908","remaining_size":"0.04094816","product_id":"BTC-EUR","sequence":3257979704,"time":"2018-01-22T15:14:47.396000Z"}
{"type":"done","side":"sell","order_id":"6d7e981f-983d-4db6-a8d5-bf1b1ce2eed3","reason":"canceled","product_id":"BTC-EUR","price":"8825.65000000","remaining_size":"0.10500000","sequence":3257979705,"time":"2018-01-22T15:14:47.403000Z"}
{"type":"received","order_id":"b6c480b1-4104-4757-b090-db92031b465c","order_type":"limit","size":"0.03322226","price":"8825.64000000","side":"sell","client_oid":"da363b6a-a2be-4fdf-aee1-b0ad1d1d43c8","product_id":"BTC-EUR","sequence":3257979706,"time":"2018-01-22T15:14:47.413000Z"}
{"type":"open","side":"sell","price":"8825.64000000","order_id":"b6c480b1-4104-4757-b090-db92031b465c","remaining_size":"0.03322226","product_id":"BTC-EUR","sequence":3257979707,"time":"2018-01-22T15:14:47.413000Z"}
{"type":"received","order_id":"fcc5f110-ece6-46b5-9579-80b0c738bd92","order_type":"limit","size":"0.10500000","price":"8825.64000000","side":"sell","client_oid":"f31ecb7e-8dec-4637-9f28-d6000f854607","product_id":"BTC-EUR","sequence":3257979708,"time":"2018-01-22T15:14:47.425000Z"}
{"type":"open","side":"sell","price":"8825.64000000","order_id":"fcc5f110-ece6-46b5-9579-80b0c738bd92","remaining_size":"0.10500000","product_id":"BTC-EUR","sequence":3257979709,"time":"2018-01-22T15:14:47.425000Z"}
{"type":"received","order_id":"646b860b-d4dd-4f37-8a7b-f2b6929ef25a","order_type":"limit","size":"0.00113290","price":"8825.52000000","side":"sell","client_oid":"28b37e94-cf76-4348-a866-b68ef52a2168","product_id":"BTC-EUR","sequence":3257979710,"time":"2018-01-22T15:14:47.429000Z"}
{"type":"open","side":"sell","price":"8825.52000000","order_id":"646b860b-d4dd-4f37-8a7b-f2b6929ef25a","remaining_size":"0.00113290","product_id":"BTC-EUR","sequence":3257979711,"time":"2018-01-22T15:14:47.429000Z"}
{"type":"received","order_id":"0b2ac95c-c0c8-4957-a6c7-1b163c062102","order_type":"limit","size":"0.01800000","price":"8825.63000000","side":"sell","client_oid":"84c4adeb-48a3-4ba1-852d-1f1fb8e57ddf","product_id":"BTC-EUR","sequence":3257979712,"time":"2018-01-22T15:14:47.438000Z"}
{"type":"open","side":"sell","price":"8825.63000000","order_id":"0b2ac95c-c0c8-4957-a6c7-1b163c062102","remaining_size":"0.01800000","product_id":"BTC-EUR","sequence":3257979713,"time":"2018-01-22T15:14:47.438000Z"}
{"type":"done","side":"sell","order_id":"db874232-44b3-4543-ae11-27a0253cef8e","reason":"canceled","product_id":"BTC-EUR","price":"8825.64000000","remaining_size":"0.01800000","sequence":3257979714,"time":"2018-01-22T15:14:47.445000Z"}
{"type":"received","order_id":"4cc50e5b-9c02-4213-a8ac-3d61f7c0a1fd","order_type":"limit","size":"0.01800000","price":"8825.63000000","side":"sell","client_oid":"57552c7f-5373-4ba0-9356-1110b4e1d5cd","product_id":"BTC-EUR","sequence":3257979715,"time":"2018-01-22T15:14:47.456000Z"}
{"type":"open","side":"sell","price":"8825.63000000","order_id":"4cc50e5b-9c02-4213-a8ac-3d61f7c0a1fd","remaining_size":"0.01800000","product_id":"BTC-EUR","sequence":3257979716,"time":"2018-01-22T15:14:47.456000Z"}
{"type":"received","order_id":"f56f0eb2-5848-4478-9b08-23d79b03bb8d","order_type":"limit","size":"0.01800000","price":"8825.62000000","side":"sell","client_oid":"c29e2901-7aa0-4eb2-9b81-08a65ddc7140","product_id":"BTC-EUR","sequence":3257979717,"time":"2018-01-22T15:14:47.462000Z"}
{"type":"open","side":"sell","price":"8825.62000000","order_id":"f56f0eb2-5848-4478-9b08-23d79b03bb8d","remaining_size":"0.01800000","product_id":"BTC-EUR","sequence":3257979718,"time":"2018-01-22T15:14:47.462000Z"}
{"type":"done","side":"sell","order_id":"b6c480b1-4104-4757-b090-db92031b465c","reason":"canceled","product_id":"BTC-EUR","price":"8825.64000000","remaining_size":"0.03322226","sequence":3257979719,"time":"2018-01-22T15:14:47.464000Z"}
{"type":"done","side":"sell","order_id":"2c1fd6bc-6e04-41e8-a87a-30cb01b3c306","reason":"canceled","product_id":"BTC-EUR","price":"8825.64000000","remaining_size":"0.06847422","sequence":3257979720,"time":"2018-01-22T15:14:47.484000Z"}
{"type":"received","order_id":"9f124aa4-767a-4c59-87eb-d2fe909e3163","order_type":"limit","size":"0.10500000","price":"8825.53000000","side":"sell","client_oid":"51b13f37-a876-404b-abda-569b0f39ede9","product_id":"BTC-EUR","sequence":3257979721,"time":"2018-01-22T15:14:47.490000Z"}
{"type":"open","side":"sell","price":"8825.53000000","order_id":"9f124aa4-767a-4c59-87eb-d2fe909e3163","remaining_size":"0.10500000","product_id":"BTC-EUR","sequence":3257979722,"time":"2018-01-22T15:14:47.490000Z"}
{"type":"done","side":"sell","order_id":"c542957a-c5c1-46a5-9f01-4b4905a2e20e","reason":"canceled","product_id":"BTC-EUR","price":"8915.60000000","remaining_size":"0.06675000","sequence":3257979723,"time":"2018-01-22T15:14:47.504000Z"}
{"type":"received","order_id":"5ac9fda3-9d40-4f66-9ab3-8378a5895033","order_type":"limit","size":"0.03322226","price":"8825.62000000","side":"sell","client_oid":"22c61b41-d2fa-4816-a529-1b4b803bfa2e","product_id":"BTC-EUR","sequence":3257979724,"time":"2018-01-22T15:14:47.506000Z"}
{"type":"open","side":"sell","price":"8825.62000000","order_id":"5ac9fda3-9d40-4f66-9ab3-8378a5895033","remaining_size":"0.03322226","product_id":"BTC-EUR","sequence":3257979725,"time":"2018-01-22T15:14:47.506000Z"}
{"type":"done","side":"sell","order_id":"fcc5f110-ece6-46b5-9579-80b0c738bd92","reason":"canceled","product_id":"BTC-EUR","price":"8825.64000000","remaining_size":"0.10500000","sequence":3257979726,"time":"2018-01-22T15:14:47.507000Z"}
{"type":"done","side":"sell","order_id":"0b2ac95c-c0c8-4957-a6c7-1b163c062102","reason":"canceled","product_id":"BTC-EUR","price":"8825.63000000","remaining_size":"0.01800000","sequence":3257979727,"time":"2018-01-22T15:14:47.514000Z"}
{"type":"received","order_id":"a9cbc4c4-c940-4f04-8669-abe25aa07e57","order_type":"limit","size":"0.01800000","price":"8825.51000000","side":"sell","client_oid":"015e8d6b-24c3-4250-a3fa-9611b3776652","product_id":"BTC-EUR","sequence":3257979728,"time":"2018-01-22T15:14:47.536000Z"}
{"type":"open","side":"sell","price":"8825.51000000","order_id":"a9cbc4c4-c940-4f04-8669-abe25aa07e57","remaining_size":"0.01800000","product_id":"BTC-EUR","sequence":3257979729,"time":"2018-01-22T15:14:47.536000Z"}
{"type":"done","side":"sell","order_id":"646b860b-d4dd-4f37-8a7b-f2b6929ef25a","reason":"canceled","product_id":"BTC-EUR","price":"8825.52000000","remaining_size":"0.00113290","sequence":3257979730,"time":"2018-01-22T15:14:47.542000Z"}
{"type":"done","side":"sell","order_id":"5ac9fda3-9d40-4f66-9ab3-8378a5895033","reason":"canceled","product_id":"BTC-EUR","price":"8825.62000000","remaining_size":"0.03322226","sequence":3257979731,"time":"2018-01-22T15:14:47.547000Z"}
{"type":"received","order_id":"4b931ea2-120c-492c-8f86-627a5d3c3ca3","order_type":"limit","size":"0.46457607","price":"8789.84000000","side":"buy","client_oid":"518faf45-8fdd-464f-b83c-7967ff457d3d","product_id":"BTC-EUR","sequence":3257979732,"time":"2018-01-22T15:14:47.550000Z"}
{"type":"open","side":"buy","price":"8789.84000000","order_id":"4b931ea2-120c-492c-8f86-627a5d3c3ca3","remaining_size":"0.46457607","product_id":"BTC-EUR","sequence":3257979733,"time":"2018-01-22T15:14:47.550000Z"}
{"type":"done","side":"sell","order_id":"2f2408a9-4702-41ac-89dc-296560c4b172","reason":"canceled","product_id":"BTC-EUR","price":"8825.53000000","remaining_size":"0.01656300","sequence":3257979734,"time":"2018-01-22T15:14:47.552000Z"}
{"type":"done","side":"sell","order_id":"edd41ea7-3fba-47bd-85f5-ad2d20103f47","reason":"canceled","product_id":"BTC-EUR","price":"8825.69000000","remaining_size":"0.00564464","sequence":3257979735,"time":"2018-01-22T15:14:47.553000Z"}
{"type":"received","order_id":"e0f077db-4c09-40e0-a1ce-1361ffffd8c4","order_type":"limit","size":"0.10500000","price":"8825.53000000","side":"sell","client_oid":"7ead3b2c-0944-4e25-be49-3e73ef03cb8b","product_id":"BTC-EUR","sequence":3257979736,"time":"2018-01-22T15:14:47.556000Z"}
{"type":"open","side":"sell","price":"8825.53000000","order_id":"e0f077db-4c09-40e0-a1ce-1361ffffd8c4","remaining_size":"0.10500000","product_id":"BTC-EUR","sequence":3257979737,"time":"2018-01-22T15:14:47.556000Z"}
{"type":"received","order_id":"ba83d96f-018e-453a-a8ff-46a413684e92","order_type":"limit","size":"0.01000000","price":"9091.73000000","side":"buy","product_id":"BTC-EUR","sequence":3257979738,"time":"2018-01-22T15:14:47.569000Z"}
{"type":"match","trade_id":10551377,"maker_order_id":"a9cbc4c4-c940-4f04-8669-abe25aa07e57","taker_order_id":"ba83d96f-018e-453a-a8ff-46a413684e92","side":"sell","size":"0.01000000","price":"8825.51000000","product_id":"BTC-EUR","sequence":3257979739,"time":"2018-01-22T15:14:47.569000Z"}
{"type":"done","side":"buy","order_id":"ba83d96f-018e-453a-a8ff-46a413684e92","reason":"filled","product_id":"BTC-EUR","price":"9091.73000000","remaining_size":"0.00000000","sequence":3257979740,"time":"2018-01-22T15:14:47.569000Z"}
{"type":"done","side":"sell","order_id":"9f124aa4-767a-4c59-87eb-d2fe909e3163","reason":"canceled","product_id":"BTC-EUR","price":"8825.53000000","remaining_size":"0.10500000","sequence":3257979741,"time":"2018-01-22T15:14:47.570000Z"}
{"type":"done","side":"sell","order_id":"4cc50e5b-9c02-4213-a8ac-3d61f7c0a1fd","reason":"canceled","product_id":"BTC-EUR","price":"8825.63000000","remaining_size":"0.01800000","sequence":3257979742,"time":"2018-01-22T15:14:47.577000Z"}
{"type":"received","order_id":"09d818e0-8d9b-426f-aeec-5aaf207008a3","order_type":"limit","size":"0.03322226","price":"8825.52000000","side":"sell","client_oid":"26eca3b9-8ac6-42be-9d22-498a4770032a","product_id":"BTC-EUR","sequence":3257979743,"time":"2018-01-22T15:14:47.583000Z"}
{"type":"open","side":"sell","price":"8825.52000000","order_id":"09d818e0-8d9b-426f-aeec-5aaf207008a3","remaining_size":"0.03322226","product_id":"BTC-EUR","sequence":3257979744,"time":"2018-01-22T15:14:47.583000Z"}
{"type":"received","order_id":"be9b0b6f-e30f-45b2-a7d7-d15a3c7d96d8","order_type":"limit","size":"0.10500000","price":"8825.52000000","side":"sell","client_oid":"ae936894-ffd2-45fe-aaf8-098b1babc7b7","product_id":"BTC-EUR","sequence":3257979745,"time":"2018-01-22T15:14:47.592000Z"}
{"type":"open","side":"sell","price":"8825.52000000","order_id":"be9b0b6f-e30f-45b2-a7d7-d15a3c7d96d8","remaining_size":"0.10500000","product_id":"BTC-EUR","sequence":3257979746,"time":"2018-01-22T15:14:47.592000Z"}
{"type":"done","side":"sell","order_id":"ffc27c06-3081-44b5-a518-e7b513efd76f","reason":"canceled","product_id":"BTC-EUR","price":"8825.65000000","remaining_size":"0.06847422","sequence":3257979747,"time":"2018-01-22T15:14:47.601000Z"}
{"type":"done","side":"sell","order_id":"0da3b0d7-883b-4623-9079-a0f25647c595","reason":"canceled","product_id":"BTC-EUR","price":"8825.66000000","remaining_size":"0.06847422","sequence":3257979748,"time":"2018-01-22T15:14:47.601000Z"}
{"type":"received","order_id":"34bafc74-3025-42d1-9e5e-e33d1fae38fd","order_type":"limit","size":"0.01800000","price":"8825.51000000","side":"sell","client_oid":"720db6e4-527f-4087-acd3-22fdcfc2749d","product_id":"BTC-EUR","sequence":3257979749,"time":"2018-01-22T15:14:47.606000Z"}
{"type":"open","side":"sell","price":"8825.51000000","order_id":"34bafc74-3025-42d1-9e5e-e33d1fae38fd","remaining_size":"0.01800000","product_id":"BTC-EUR","sequence":3257979750,"time":"2018-01-22T15:14:47.606000Z"}
{"type":"done","side":"sell","order_id":"f56f0eb2-5848-4478-9b08-23d79b03bb8d","reason":"canceled","product_id":"BTC-EUR","price":"8825.62000000","remaining_size":"0.01800000","sequence":3257979751,"time":"2018-01-22T15:14:47.609000Z"}
{"type":"received","order_id":"86cd82be-66b1-4dde-9e6f-195bc7cb514b","order_type":"limit","size":"0.01818505","price":"8793.75000000","side":"buy","client_oid":"01d5f661-1926-4627-adc9-d00d19bb7c91","product_id":"BTC-EUR","sequence":3257979752,"time":"2018-01-22T15:14:47.610000Z"}
{"type":"open","side":"buy","price":"8793.75000000","order_id":"86cd82be-66b1-4dde-9e6f-195bc7cb514b","remaining_size":"0.01818505","product_id":"BTC-EUR","sequence":3257979753,"time":"2018-01-22T15:14:47.610000Z"}
{"type":"done","side":"sell","order_id":"09d818e0-8d9b-426f-aeec-5aaf207008a3","reason":"canceled","product_id":"BTC-EUR","price":"8825.52000000","remaining_size":"0.03322226","sequence":3257979754,"time":"2018-01-22T15:14:47.618000Z"}
{"type":"received","order_id":"537d14a0-1884-4ca2-8a17-688a0e352a29","order_type":"limit","size":"0.06847422","price":"8825.62000000","side":"sell","client_oid":"55af763a-2234-41b0-81cf-1d8e5b65d72a","product_id":"BTC-EUR","sequence":3257979755,"time":"2018-01-22T15:14:47.619000Z"}
{"type":"open","side":"sell","price":"8825.62000000","order_id":"537d14a0-1884-4ca2-8a17-688a0e352a29","remaining_size":"0.06847422","product_id":"BTC-EUR","sequence":3257979756,"time":"2018-01-22T15:14:47.619000Z"}
{"type":"received","order_id":"f31b604c-d8ef-4936-8cda-07f6c6a04c97","order_type":"limit","size":"0.37283636","price":"8871.63000000","side":"sell","client_oid":"caf84011-6c14-4b81-899d-dbd592910ca2","product_id":"BTC-EUR","sequence":3257979757,"time":"2018-01-22T15:14:47.620000Z"}
{"type":"open","side":"sell","price":"8871.63000000","order_id":"f31b604c-d8ef-4936-8cda-07f6c6a04c97","remaining_size":"0.37283636","product_id":"BTC-EUR","sequence":3257979758,"time":"2018-01-22T15:14:47.620000Z"}
{"type":"received","order_id":"a7ae0171-86bb-43cd-8df2-eccb03b61d6d","order_type":"limit","size":"0.06675000","price":"8921.17000000","side":"sell","product_id":"BTC-EUR","sequence":3257979759,"time":"2018-01-22T15:14:47.621000Z"}
{"type":"open","side":"sell","price":"8921.17000000","order_id":"a7ae0171-86bb-43cd-8df2-eccb03b61d6d","remaining_size":"0.06675000","product_id":"BTC-EUR","sequence":3257979760,"time":"2018-01-22T15:14:47.621000Z"}
{"type":"received","order_id":"638ca042-c2ac-46d8-9288-bceb72557379","order_type":"limit","size":"0.00113290","price":"8825.50000000","side":"sell","client_oid":"9f91baf4-7178-4ab6-908d-21c76f8c201a","product_id":"BTC-EUR","sequence":3257979761,"time":"2018-01-22T15:14:47.627000Z"}
{"type":"open","side":"sell","price":"8825.50000000","order_id":"638ca042-c2ac-46d8-9288-bceb72557379","remaining_size":"0.00113290","product_id":"BTC-EUR","sequence":3257979762,"time":"2018-01-22T15:14:47.627000Z"}
{"type":"received","order_id":"fa2bf495-d52e-4f69-a36d-c93f0e5c9aaa","order_type":"limit","size":"0.06847422","price":"8825.51000000","side":"sell","client_oid":"22280ce1-4618-4d76-ac99-215d34f812a6","product_id":"BTC-EUR","sequence":3257979763,"time":"2018-01-22T15:14:47.629000Z"}
{"type":"open","side":"sell","price":"8825.51000000","order_id":"fa2bf495-d52e-4f69-a36d-c93f0e5c9aaa","remaining_size":"0.06847422","product_id":"BTC-EUR","sequence":3257979764,"time":"2018-01-22T15:14:47.629000Z"}
{"type":"received","order_id":"aab2aeec-d3a5-481a-80f5-c9f45dbeeccb","order_type":"limit","size":"0.37283636","price":"8882.53000000","side":"sell","client_oid":"4ba1766b-1d16-4bdf-a6fe-73405b34f1a0","product_id":"BTC-EUR","sequence":3257979765,"time":"2018-01-22T15:14:47.629000Z"}
{"type":"open","side":"sell","price":"8882.53000000","order_id":"aab2aeec-d3a5-481a-80f5-c9f45dbeeccb","remaining_size":"0.37283636","product_id":"BTC-EUR","sequence":3257979766,"time":"2018-01-22T15:14:47.629000Z"}
{"type":"done","side":"sell","order_id":"fd036868-e63a-4bb8-a6e9-5bf8061e6344","reason":"canceled","product_id":"BTC-EUR","price":"8825.69000000","remaining_size":"0.10500000","sequence":3257979767,"time":"2018-01-22T15:14:47.632000Z"}
{"type":"received","order_id":"b166ae21-80db-4553-b355-33915d777dbf","order_type":"limit","size":"0.37283636","price":"8894.87000000","side":"sell","client_oid":"3618a6e8-6651-4458-ba6d-6409fc6910f3","product_id":"BTC-EUR","sequence":3257979768,"time":"2018-01-22T15:14:47.633000Z"}
{"type":"open","side":"sell","price":"8894.87000000","order_id":"b166ae21-80db-4553-b355-33915d777dbf","remaining_size":"0.37283636","product_id":"BTC-EUR","sequence":3257979769,"time":"2018-01-22T15:14:47.633000Z"}
{"type":"received","order_id":"3c312c95-f814-4929-965a-1e2d8c2aeeae","order_type":"limit","size":"0.37283636","price":"8906.49000000","side":"sell","client_oid":"3adba09e-dd8e-48f2-b08c-482a65acd390","product_id":"BTC-EUR","sequence":3257979770,"time":"2018-01-22T15:14:47.640000Z"}
{"type":"open","side":"sell","price":"8906.49000000","order_id":"3c312c95-f814-4929-965a-1e2d8c2aeeae","remaining_size":"0.37283636","product_id":"BTC-EUR","sequence":3257979771,"time":"2018-01-22T15:14:47.640000Z"}
{"type":"done","side":"sell","order_id":"e0f077db-4c09-40e0-a1ce-1361ffffd8c4","reason":"canceled","product_id":"BTC-EUR","price":"8825.53000000","remaining_size":"0.10500000","sequence":3257979772,"time":"2018-01-22T15:14:47.641000Z"}
{"type":"received","order_id":"aa4a5cbb-4bd2-443b-8940-a3e62021872f","order_type":"limit","size":"0.01818505","price":"8750.01000000","side":"buy","client_oid":"3e6f712d-e459-4933-875d-4cce80d23a27","product_id":"BTC-EUR","sequence":3257979773,"time":"2018-01-22T15:14:47.644000Z"}
{"type":"open","side":"buy","price":"8750.01000000","order_id":"aa4a5cbb-4bd2-443b-8940-a3e62021872f","remaining_size":"0.01818505","product_id":"BTC-EUR","sequence":3257979774,"time":"2018-01-22T15:14:47.644000Z"}
{"type":"received","order_id":"02afcdfe-3dcf-4b96-a0e1-e4e347557a6c","order_type":"limit","size":"0.06847422","price":"8825.52000000","side":"sell","client_oid":"e07eb4cc-7a03-4849-ad14-f36f5abaa4a4","product_id":"BTC-EUR","sequence":3257979775,"time":"2018-01-22T15:14:47.644000Z"}
{"type":"open","side":"sell","price":"8825.52000000","order_id":"02afcdfe-3dcf-4b96-a0e1-e4e347557a6c","remaining_size":"0.06847422","product_id":"BTC-EUR","sequence":3257979776,"time":"2018-01-22T15:14:47.644000Z"}
{"type":"received","order_id":"08424c0d-6ed6-4849-8487-024ba3c844f1","order_type":"limit","size":"0.37283635","price":"8918.12000000","side":"sell","client_oid":"7f040f98-cff0-4f7b-a3f2-0e750b31adae","product_id":"BTC-EUR","sequence":3257979777,"time":"2018-01-22T15:14:47.649000Z"}
{"type":"open","side":"sell","price":"8918.12000000","order_id":"08424c0d-6ed6-4849-8487-024ba3c844f1","remaining_size":"0.37283635","product_id":"BTC-EUR","sequence":3257979778,"time":"2018-01-22T15:14:47.649000Z"}
{"type":"received","order_id":"37a99da8-06c1-43eb-987f-08880a5e33a5","order_type":"limit","size":"0.01818505","price":"8705.61000000","side":"buy","client_oid":"ecbccbe5-0d64-493b-9259-12d627f4f27f","product_id":"BTC-EUR","sequence":3257979779,"time":"2018-01-22T15:14:47.654000Z"}
{"type":"open","side":"buy","price":"8705.61000000","order_id":"37a99da8-06c1-43eb-987f-08880a5e33a5","remaining_size":"0.01818505","product_id":"BTC-EUR","sequence":3257979780,"time":"2018-01-22T15:14:47.654000Z"}
{"type":"received","order_id":"fa67df01-6231-4c5e-bdef-dbf86aec2eb1","order_type":"limit","size":"0.10500000","price":"8825.51000000","side":"sell","client_oid":"c98b13f5-a995-4a68-a731-e4d9da33012b","product_id":"BTC-EUR","sequence":3257979781,"time":"2018-01-22T15:14:47.659000Z"}
{"type":"open","side":"sell","price":"8825.51000000","order_id":"fa67df01-6231-4c5e-bdef-dbf86aec2eb1","remaining_size":"0.10500000","product_id":"BTC-EUR","sequence":3257979782,"time":"2018-01-22T15:14:47.659000Z"}
{"type":"received","order_id":"a6ce1e59-f7da-48ee-a82a-6baa77928609","order_type":"limit","size":"0.01818506","price":"8660.78000000","side":"buy","client_oid":"55e7b5ae-f005-449a-a6b0-4f5f662fff8e","product_id":"BTC-EUR","sequence":3257979783,"time":"2018-01-22T15:14:47.659000Z"}
{"type":"open","side":"buy","price":"8660.78000000","order_id":"a6ce1e59-f7da-48ee-a82a-6baa77928609","remaining_size":"0.01818506","product_id":"BTC-EUR","sequence":3257979784,"time":"2018-01-22T15:14:47.659000Z"}
{"type":"done","side":"sell","order_id":"be9b0b6f-e30f-45b2-a7d7-d15a3c7d96d8","reason":"canceled","product_id":"BTC-EUR","price":"8825.52000000","remaining_size":"0.10500000","sequence":3257979785,"time":"2018-01-22T15:14:47.671000Z"}
{"type":"received","order_id":"099470d1-ae39-48c8-9b62-6a99dcba7df6","order_type":"limit","size":"0.03322226","price":"8825.50000000","side":"sell","client_oid":"c5584a1a-07be-4a3a-bd3e-97fcece07b99","product_id":"BTC-EUR","sequence":3257979786,"time":"2018-01-22T15:14:47.672000Z"}
{"type":"open","side":"sell","price":"8825.50000000","order_id":"099470d1-ae39-48c8-9b62-6a99dcba7df6","remaining_size":"0.03322226","product_id":"BTC-EUR","sequence":3257979787,"time":"2018-01-22T15:14:47.672000Z"}
{"type":"received","order_id":"c449ba72-05e3-4ab0-a32b-838ad96bb6b5","order_type":"limit","size":"0.01656300","price":"8825.44000000","side":"sell","product_id":"BTC-EUR","sequence":3257979788,"time":"2018-01-22T15:14:47.684000Z"}
{"type":"open","side":"sell","price":"8825.44000000","order_id":"c449ba72-05e3-4ab0-a32b-838ad96bb6b5","remaining_size":"0.01656300","product_id":"BTC-EUR","sequence":3257979789,"time":"2018-01-22T15:14:47.684000Z"}
{"type":"done","side":"sell","order_id":"7c1661e7-b8b8-4a20-9543-f19df72cd9e8","reason":"canceled","product_id":"BTC-EUR","price":"8825.65000000","remaining_size":"0.21404538","sequence":3257979790,"time":"2018-01-22T15:14:47.685000Z"}
{"type":"done","side":"sell","order_id":"34bafc74-3025-42d1-9e5e-e33d1fae38fd","reason":"canceled","product_id":"BTC-EUR","price":"8825.51000000","remaining_size":"0.01800000","sequence":3257979791,"time":"2018-01-22T15:14:47.710000Z"}
{"type":"received","order_id":"c6c37a45-e6f6-4534-a420-896007958501","order_type":"limit","size":"0.10500000","price":"8825.51000000","side":"sell","client_oid":"d4ba117e-421b-4417-9936-9ef4e4ba882a","product_id":"BTC-EUR","sequence":3257979792,"time":"2018-01-22T15:14:47.720000Z"}
{"type":"open","side":"sell","price":"8825.51000000","order_id":"c6c37a45-e6f6-4534-a420-896007958501","remaining_size":"0.10500000","product_id":"BTC-EUR","sequence":3257979793,"time":"2018-01-22T15:14:47.720000Z"}
{"type":"received","order_id":"6a7b41f7-dc37-43f7-b140-e02b20fc270d","order_type":"limit","size":"0.10500000","price":"8825.51000000","side":"sell","client_oid":"8c817461-ca8d-44bd-b5ea-44f690b26329","product_id":"BTC-EUR","sequence":3257979794,"time":"2018-01-22T15:14:47.725000Z"}
{"type":"open","side":"sell","price":"8825.51000000","order_id":"6a7b41f7-dc37-43f7-b140-e02b20fc270d","remaining_size":"0.10500000","product_id":"BTC-EUR","sequence":3257979795,"time":"2018-01-22T15:14:47.725000Z"}
{"type":"done","side":"sell","order_id":"638ca042-c2ac-46d8-9288-bceb72557379","reason":"canceled","product_id":"BTC-EUR","price":"8825.50000000","remaining_size":"0.00113290","sequence":3257979796,"time":"2018-01-22T15:14:47.730000Z"}
{"type":"done","side":"sell","order_id":"a9cbc4c4-c940-4f04-8669-abe25aa07e57","reason":"canceled","product_id":"BTC-EUR","price":"8825.51000000","remaining_size":"0.00800000","sequence":3257979797,"time":"2018-01-22T15:14:47.734000Z"}
{"type":"received","order_id":"2d5d42c3-c58a-4f3f-9a34-d2eca9ed10ee","order_type":"limit","size":"0.01800000","price":"8825.49000000","side":"sell","client_oid":"5838bf28-f2d5-45a5-a7a8-fdfafddd867e","product_id":"BTC-EUR","sequence":3257979798,"time":"2018-01-22T15:14:47.736000Z"}
{"type":"open","side":"sell","price":"8825.49000000","order_id":"2d5d42c3-c58a-4f3f-9a34-d2eca9ed10ee","remaining_size":"0.01800000","product_id":"BTC-EUR","sequence":3257979799,"time":"2018-01-22T15:14:47.736000Z"}
{"type":"received","order_id":"3cc5335e-81b6-48b4-bacd-1d330777aa90","order_type":"limit","size":"0.06847422","price":"8825.50000000","side":"sell","client_oid":"3ec0bcad-1fc4-4455-be0f-f7b78bc00cc6","product_id":"BTC-EUR","sequence":3257979800,"time":"2018-01-22T15:14:47.744000Z"}
{"type":"open","side":"sell","price":"8825.50000000","order_id":"3cc5335e-81b6-48b4-bacd-1d330777aa90","remaining_size":"0.06847422","product_id":"BTC-EUR","sequence":3257979801,"time":"2018-01-22T15:14:47.744000Z"}
{"type":"done","side":"sell","order_id":"fa67df01-6231-4c5e-bdef-dbf86aec2eb1","reason":"canceled","product_id":"BTC-EUR","price":"8825.51000000","remaining_size":"0.10500000","sequence":3257979802,"time":"2018-01-22T15:14:47.759000Z"}
{"type":"received","order_id":"acb66362-6373-4e14-8df7-0fe44a4708d1","order_type":"limit","size":"0.00564464","price":"8825.51000000","side":"sell","client_oid":"ec314eb2-9122-4e7d-8240-e5be8e28bebc","product_id":"BTC-EUR","sequence":3257979803,"time":"2018-01-22T15:14:47.775000Z"}
{"type":"open","side":"sell","price":"8825.51000000","order_id":"acb66362-6373-4e14-8df7-0fe44a4708d1","remaining_size":"0.00564464","product_id":"BTC-EUR","sequence":3257979804,"time":"2018-01-22T15:14:47.775000Z"}
{"type":"received","order_id":"b0250c21-dd38-4d1a-84a2-28ef0e3bb4de","order_type":"limit","size":"0.10500000","price":"8825.50000000","side":"sell","client_oid":"69d577fb-0f19-45d0-94c2-fadff341f718","product_id":"BTC-EUR","sequence":3257979805,"time":"2018-01-22T15:14:47.786000Z"}
{"type":"open","side":"sell","price":"8825.50000000","order_id":"b0250c21-dd38-4d1a-84a2-28ef0e3bb4de","remaining_size":"0.10500000","product_id":"BTC-EUR","sequence":3257979806,"time":"2018-01-22T15:14:47.786000Z"}
{"type":"done","side":"sell","order_id":"c449ba72-05e3-4ab0-a32b-838ad96bb6b5","reason":"canceled","product_id":"BTC-EUR","price":"8825.44000000","remaining_size":"0.01656300","sequence":3257979807,"time":"2018-01-22T15:14:47.809000Z"}
{"type":"done","side":"sell","order_id":"c6c37a45-e6f6-4534-a420-896007958501","reason":"canceled","product_id":"BTC-EUR","price":"8825.51000000","remaining_size":"0.10500000","sequence":3257979808,"time":"2018-01-22T15:14:47.821000Z"}
{"type":"received","order_id":"aa8177a5-5071-41a0-936f-6db8e075bbbb","order_type":"limit","size":"0.10500000","price":"8825.44000000","side":"sell","client_oid":"ba12c7f0-10c2-49a4-88e0-312d9e3653c4","product_id":"BTC-EUR","sequence":3257979809,"time":"2018-01-22T15:14:47.844000Z"}
{"type":"open","side":"sell","price":"8825.44000000","order_id":"aa8177a5-5071-41a0-936f-6db8e075bbbb","remaining_size":"0.10500000","product_id":"BTC-EUR","sequence":3257979810,"time":"2018-01-22T15:14:47.844000Z"}
{"type":"done","side":"sell","order_id":"fb7c110d-ad96-453d-a975-3b6479578653","reason":"canceled","product_id":"BTC-EUR","price":"8825.66000000","remaining_size":"0.01322632","sequence":3257979811,"time":"2018-01-22T15:14:47.845000Z"}
{"type":"done","side":"sell","order_id":"099470d1-ae39-48c8-9b62-6a99dcba7df6","reason":"canceled","product_id":"BTC-EUR","price":"8825.50000000","remaining_size":"0.03322226","sequence":3257979812,"time":"2018-01-22T15:14:47.849000Z"}
{"type":"done","side":"sell","order_id":"6a7b41f7-dc37-43f7-b140-e02b20fc270d","reason":"canceled","product_id":"BTC-EUR","price":"8825.51000000","remaining_size":"0.10500000","sequence":3257979813,"time":"2018-01-22T15:14:47.850000Z"}
{"type":"done","side":"sell","order_id":"fa2bf495-d52e-4f69-a36d-c93f0e5c9aaa","reason":"canceled","product_id":"BTC-EUR","price":"8825.51000000","remaining_size":"0.06847422","sequence":3257979814,"time":"2018-01-22T15:14:47.862000Z"}
{"type":"done","side":"sell","order_id":"537d14a0-1884-4ca2-8a17-688a0e352a29","reason":"canceled","product_id":"BTC-EUR","price":"8825.62000000","remaining_size":"0.06847422","sequence":3257979815,"time":"2018-01-22T15:14:47.862000Z"}
{"type":"done","side":"sell","order_id":"2d5d42c3-c58a-4f3f-9a34-d2eca9ed10ee","reason":"canceled","product_id":"BTC-EUR","price":"8825.49000000","remaining_size":"0.01800000","sequence":3257979816,"time":"2018-01-22T15:14:47.872000Z"}
{"type":"received","order_id":"c01e44fd-4983-4470-90f9-2a3549dcdabe","order_type":"limit","size":"0.06847422","price":"8825.49000000","side":"sell","client_oid":"6f240cb4-a38c-4eef-90b0-36c2e27abe06","product_id":"BTC-EUR","sequence":3257979817,"time":"2018-01-22T15:14:47.872000Z"}
{"type":"open","side":"sell","price":"8825.49000000","order_id":"c01e44fd-4983-4470-90f9-2a3549dcdabe","remaining_size":"0.06847422","product_id":"BTC-EUR","sequence":3257979818,"time":"2018-01-22T15:14:47.872000Z"}
{"type":"done","side":"sell","order_id":"b0250c21-dd38-4d1a-84a2-28ef0e3bb4de","reason":"canceled","product_id":"BTC-EUR","price":"8825.50000000","remaining_size":"0.10500000","sequence":3257979819,"time":"2018-01-22T15:14:47.900000Z"}
{"type":"received","order_id":"21a2a4e6-7153-4ab6-a8a9-4f568beace1f","order_type":"limit","size":"0.01800000","price":"8825.43000000","side":"sell","client_oid":"0b483e23-42f4-4973-a741-b1c39fd8d0c2","product_id":"BTC-EUR","sequence":3257979820,"time":"2018-01-22T15:14:47.901000Z"}
{"type":"open","side":"sell","price":"8825.43000000","order_id":"21a2a4e6-7153-4ab6-a8a9-4f568beace1f","remaining_size":"0.01800000","product_id":"BTC-EUR","sequence":3257979821,"time":"2018-01-22T15:14:47.901000Z"}
{"type":"received","order_id":"4389f921-a63e-4926-968e-f949c2554e4b","order_type":"limit","size":"1.37090335","price":"8878.39000000","side":"sell","client_oid":"fb895360-78cf-4d0e-8d58-5c2ff640a56c","product_id":"BTC-EUR","sequence":3257979822,"time":"2018-01-22T15:14:47.903000Z"}
{"type":"open","side":"sell","price":"8878.39000000","order_id":"4389f921-a63e-4926-968e-f949c2554e4b","remaining_size":"1.37090335","product_id":"BTC-EUR","sequence":3257979823,"time":"2018-01-22T15:14:47.903000Z"}
{"type":"done","side":"sell","order_id":"479c5080-f470-4c14-a92d-648530504dee","reason":"canceled","product_id":"BTC-EUR","price":"8825.65000000","remaining_size":"0.22947933","sequence":3257979824,"time":"2018-01-22T15:14:47.912000Z"}
{"type":"received","order_id":"1410838e-f162-4d14-b048-1f0019771a60","order_type":"limit","size":"0.03322226","price":"8825.43000000","side":"sell","client_oid":"ef1bdf40-4299-4854-93e9-bfbf218e142b","product_id":"BTC-EUR","sequence":3257979825,"time":"2018-01-22T15:14:47.926000Z"}
{"type":"open","side":"sell","price":"8825.43000000","order_id":"1410838e-f162-4d14-b048-1f0019771a60","remaining_size":"0.03322226","product_id":"BTC-EUR","sequence":3257979826,"time":"2018-01-22T15:14:47.926000Z"}
{"type":"received","order_id":"677ae85d-501b-4bc8-9860-c95542b2b91a","order_type":"limit","size":"0.00113290","price":"8825.48000000","side":"sell","client_oid":"c163e73d-5af5-4c89-9d7d-912910d514af","product_id":"BTC-EUR","sequence":3257979827,"time":"2018-01-22T15:14:47.931000Z"}
{"type":"open","side":"sell","price":"8825.48000000","order_id":"677ae85d-501b-4bc8-9860-c95542b2b91a","remaining_size":"0.00113290","product_id":"BTC-EUR","sequence":3257979828,"time":"2018-01-22T15:14:47.931000Z"}
{"type":"received","order_id":"1c7a735e-24a1-44a9-ac31-34550940430f","order_type":"limit","size":"1.37090335","price":"8867.47000000","side":"sell","client_oid":"62658b08-62dc-477d-bc7c-302e2d2e2333","product_id":"BTC-EUR","sequence":3257979829,"time":"2018-01-22T15:14:47.931000Z"}
{"type":"open","side":"sell","price":"8867.47000000","order_id":"1c7a735e-24a1-44a9-ac31-34550940430f","remaining_size":"1.37090335","product_id":"BTC-EUR","sequence":3257979830,"time":"2018-01-22T15:14:47.931000Z"}
{"type":"received","order_id":"aa1d7bde-bcc4-4fb0-99bc-62b622fee194","order_type":"limit","size":"0.10500000","price":"8825.49000000","side":"sell","client_oid":"4ada1097-4a1a-4af4-a353-d2a84c340453","product_id":"BTC-EUR","sequence":3257979831,"time":"2018-01-22T15:14:47.935000Z"}
{"type":"open","side":"sell","price":"8825.49000000","order_id":"aa1d7bde-bcc4-4fb0-99bc-62b622fee194","remaining_size":"0.10500000","product_id":"BTC-EUR","sequence":3257979832,"time":"2018-01-22T15:14:47.935000Z"}
{"type":"received","order_id":"81640b3f-531c-46b6-8161-e725a61708d1","order_type":"limit","size":"1.37090335","price":"8890.86000000","side":"sell","client_oid":"680a378f-cfdf-4c3c-b460-9958346e2cbd","product_id":"BTC-EUR","sequence":3257979833,"time":"2018-01-22T15:14:47.941000Z"}
{"type":"open","side":"sell","price":"8890.86000000","order_id":"81640b3f-531c-46b6-8161-e725a61708d1","remaining_size":"1.37090335","product_id":"BTC-EUR","sequence":3257979834,"time":"2018-01-22T15:14:47.941000Z"}
{"type":"received","order_id":"d6b3e62b-8164-4326-a89d-9a85f12b41d1","order_type":"limit","size":"0.07631791","price":"8801.01000000","side":"buy","client_oid":"cc094dd3-74d2-470b-a4b4-dcc7b06ed3dc","product_id":"BTC-EUR","sequence":3257979835,"time":"2018-01-22T15:14:47.943000Z"}
{"type":"open","side":"buy","price":"8801.01000000","order_id":"d6b3e62b-8164-4326-a89d-9a85f12b41d1","remaining_size":"0.07631791","product_id":"BTC-EUR","sequence":3257979836,"time":"2018-01-22T15:14:47.943000Z"}
{"type":"received","order_id":"ff5c9282-e06a-464b-8281-c2e5e9aa7757","order_type":"limit","size":"0.07631791","price":"8756.44000000","side":"buy","client_oid":"cded85d0-d376-4bbf-b225-2584355c7fc7","product_id":"BTC-EUR","sequence":3257979837,"time":"2018-01-22T15:14:47.957000Z"}
{"type":"open","side":"buy","price":"8756.44000000","order_id":"ff5c9282-e06a-464b-8281-c2e5e9aa7757","remaining_size":"0.07631791","product_id":"BTC-EUR","sequence":3257979838,"time":"2018-01-22T15:14:47.957000Z"}
{"type":"received","order_id":"02204765-674e-482f-853f-59cad38295b7","order_type":"limit","size":"1.37090335","price":"8902.56000000","side":"sell","client_oid":"bf6b0fd7-ed90-42fb-ae14-a4b4bf207ccc","product_id":"BTC-EUR","sequence":3257979839,"time":"2018-01-22T15:14:47.957000Z"}
{"type":"open","side":"sell","price":"8902.56000000","order_id":"02204765-674e-482f-853f-59cad38295b7","remaining_size":"1.37090335","product_id":"BTC-EUR","sequence":3257979840,"time":"2018-01-22T15:14:47.957000Z"}
{"type":"received","order_id":"1ec06e28-f025-4164-ad3c-192d2c3d191d","order_type":"limit","size":"0.21404538","price":"8825.48000000","side":"sell","product_id":"BTC-EUR","sequence":3257979841,"time":"2018-01-22T15:14:47.963000Z"}
{"type":"open","side":"sell","price":"8825.48000000","order_id":"1ec06e28-f025-4164-ad3c-192d2c3d191d","remaining_size":"0.21404538","product_id":"BTC-EUR","sequence":3257979842,"time":"2018-01-22T15:14:47.963000Z"}
{"type":"received","order_id":"b4e5d521-457f-4b0e-b36c-c8cf0a38695d","order_type":"limit","size":"0.07631791","price":"8712.13000000","side":"buy","client_oid":"7c215375-cc86-48e9-9cdf-3646971d2a9f","product_id":"BTC-EUR","sequence":3257979843,"time":"2018-01-22T15:14:47.963000Z"}
{"type":"open","side":"buy","price":"8712.13000000","order_id":"b4e5d521-457f-4b0e-b36c-c8cf0a38695d","remaining_size":"0.07631791","product_id":"BTC-EUR","sequence":3257979844,"time":"2018-01-22T15:14:47.963000Z"}
{"type":"done","side":"sell","order_id":"677ae85d-501b-4bc8-9860-c95542b2b91a","reason":"canceled","product_id":"BTC-EUR","price":"8825.48000000","remaining_size":"0.00113290","sequence":3257979845,"time":"2018-01-22T15:14:47.963000Z"}
{"type":"received","order_id":"169b2151-939b-4eae-9fa2-f585b6c22003","order_type":"limit","size":"1.37090334","price":"8914.25000000","side":"sell","client_oid":"73da2892-f5e9-47ee-860a-a576dc3b69e5","product_id":"BTC-EUR","sequence":3257979846,"time":"2018-01-22T15:14:47.968000Z"}
{"type":"open","side":"sell","price":"8914.25000000","order_id":"169b2151-939b-4eae-9fa2-f585b6c22003","remaining_size":"1.37090334","product_id":"BTC-EUR","sequence":3257979847,"time":"2018-01-22T15:14:47.968000Z"}
{"type":"received","order_id":"b84c7117-8574-40dc-be75-d2b36a7998a6","order_type":"limit","size":"0.07631789","price":"8667.81000000","side":"buy","client_oid":"3deb7b30-27f6-4dd8-abe0-8bfdc290a44e","product_id":"BTC-EUR","sequence":3257979848,"time":"2018-01-22T15:14:47.968000Z"}
{"type":"open","side":"buy","price":"8667.81000000","order_id":"b84c7117-8574-40dc-be75-d2b36a7998a6","remaining_size":"0.07631789","product_id":"BTC-EUR","sequence":3257979849,"time":"2018-01-22T15:14:47.968000Z"}
{"type":"received","order_id":"19252218-7666-4407-9ca5-5cf6cd7d93b3","order_type":"limit","size":"0.01656300","price":"8825.39000000","side":"sell","product_id":"BTC-EUR","sequence":3257979850,"time":"2018-01-22T15:14:47.978000Z"}
{"type":"open","side":"sell","price":"8825.39000000","order_id":"19252218-7666-4407-9ca5-5cf6cd7d93b3","remaining_size":"0.01656300","product_id":"BTC-EUR","sequence":3257979851,"time":"2018-01-22T15:14:47.978000Z"}
{"type":"done","side":"sell","order_id":"aa8177a5-5071-41a0-936f-6db8e075bbbb","reason":"canceled","product_id":"BTC-EUR","price":"8825.44000000","remaining_size":"0.10500000","sequence":3257979852,"time":"2018-01-22T15:14:47.983000Z"}
{"type":"done","side":"sell","order_id":"3cc5335e-81b6-48b4-bacd-1d330777aa90","reason":"canceled","product_id":"BTC-EUR","price":"8825.50000000","remaining_size":"0.06847422","sequence":3257979853,"time":"2018-01-22T15:14:47.987000Z"}
{"type":"done","side":"sell","order_id":"02afcdfe-3dcf-4b96-a0e1-e4e347557a6c","reason":"canceled","product_id":"BTC-EUR","price":"8825.52000000","remaining_size":"0.06847422","sequence":3257979854,"time":"2018-01-22T15:14:47.987000Z"}
{"type":"done","side":"sell","order_id":"5aac6c52-a935-4002-9c9d-6b7437ca244b","reason":"canceled","product_id":"BTC-EUR","price":"8825.65000000","remaining_size":"0.00200000","sequence":3257979855,"time":"2018-01-22T15:14:48.003000Z"}
{"type":"done","side":"sell","order_id":"aa1d7bde-bcc4-4fb0-99bc-62b622fee194","reason":"canceled","product_id":"BTC-EUR","price":"8825.49000000","remaining_size":"0.10500000","sequence":3257979856,"time":"2018-01-22T15:14:48.089000Z"}
{"type":"done","side":"sell","order_id":"1ec06e28-f025-4164-ad3c-192d2c3d191d","reason":"canceled","product_id":"BTC-EUR","price":"8825.48000000","remaining_size":"0.21404538","sequence":3257979857,"time":"2018-01-22T15:14:48.093000Z"}
{"type":"done","side":"sell","order_id":"19252218-7666-4407-9ca5-5cf6cd7d93b3","reason":"canceled","product_id":"BTC-EUR","price":"8825.39000000","remaining_size":"0.01656300","sequence":3257979858,"time":"2018-01-22T15:14:48.097000Z"}
{"type":"done","side":"sell","order_id":"c01e44fd-4983-4470-90f9-2a3549dcdabe","reason":"canceled","product_id":"BTC-EUR","price":"8825.49000000","remaining_size":"0.06847422","sequence":3257979859,"time":"2018-01-22T15:14:48.107000Z"}
{"type":"done","side":"sell","order_id":"1410838e-f162-4d14-b048-1f0019771a60","reason":"canceled","product_id":"BTC-EUR","price":"8825.43000000","remaining_size":"0.03322226","sequence":3257979860,"time":"2018-01-22T15:14:48.110000Z"}
{"type":"received","order_id":"0f35816b-2c40-49d1-872e-845d84f21f48","order_type":"limit","size":"0.06847422","price":"8825.43000000","side":"sell","client_oid":"ac71e6e0-b94d-41c1-b7d3-9e685398968e","product_id":"BTC-EUR","sequence":3257979861,"time":"2018-01-22T15:14:48.162000Z"}
{"type":"open","side":"sell","price":"8825.43000000","order_id":"0f35816b-2c40-49d1-872e-845d84f21f48","remaining_size":"0.06847422","product_id":"BTC-EUR","sequence":3257979862,"time":"2018-01-22T15:14:48.162000Z"}
{"type":"received","order_id":"3342f609-a0c8-41da-9c8e-6695ab874814","order_type":"limit","size":"0.10500000","price":"8825.43000000","side":"sell","client_oid":"679fa59a-18d6-4c61-b77e-76d78498b6a7","product_id":"BTC-EUR","sequence":3257979863,"time":"2018-01-22T15:14:48.163000Z"}
{"type":"open","side":"sell","price":"8825.43000000","order_id":"3342f609-a0c8-41da-9c8e-6695ab874814","remaining_size":"0.10500000","product_id":"BTC-EUR","sequence":3257979864,"time":"2018-01-22T15:14:48.163000Z"}
{"type":"received","order_id":"67ebc261-35c4-440a-8a92-3c1ccd2762a1","order_type":"limit","size":"0.22947933","price":"8825.43000000","side":"sell","client_oid":"fcbab4f2-f1e9-4888-97b3-c509bea6f1bc","product_id":"BTC-EUR","sequence":3257979865,"time":"2018-01-22T15:14:48.165000Z"}
{"type":"open","side":"sell","price":"8825.43000000","order_id":"67ebc261-35c4-440a-8a92-3c1ccd2762a1","remaining_size":"0.22947933","product_id":"BTC-EUR","sequence":3257979866,"time":"2018-01-22T15:14:48.165000Z"}
{"type":"done","side":"sell","order_id":"8fa84741-b9b4-47dc-a41f-dea0a5ddf04a","reason":"canceled","product_id":"BTC-EUR","price":"8825.66000000","remaining_size":"0.04164971","sequence":3257979867,"time":"2018-01-22T15:14:48.165000Z"}
{"type":"received","order_id":"59c6321a-29fb-46c0-8b91-9a56f87a41ee","order_type":"limit","size":"0.00113290","price":"8825.42000000","side":"sell","client_oid":"adf9b307-cfaf-4b1c-a871-109e20fa52a8","product_id":"BTC-EUR","sequence":3257979868,"time":"2018-01-22T15:14:48.170000Z"}
{"type":"open","side":"sell","price":"8825.42000000","order_id":"59c6321a-29fb-46c0-8b91-9a56f87a41ee","remaining_size":"0.00113290","product_id":"BTC-EUR","sequence":3257979869,"time":"2018-01-22T15:14:48.170000Z"}
{"type":"done","side":"sell","order_id":"59c6321a-29fb-46c0-8b91-9a56f87a41ee","reason":"canceled","product_id":"BTC-EUR","price":"8825.42000000","remaining_size":"0.00113290","sequence":3257979870,"time":"2018-01-22T15:14:48.176000Z"}
{"type":"received","order_id":"94cc6094-8586-4270-b593-3a87a964789f","order_type":"limit","size":"0.06847422","price":"8825.48000000","side":"sell","client_oid":"09603704-a7ec-439c-85d9-f0075d4c7481","product_id":"BTC-EUR","sequence":3257979871,"time":"2018-01-22T15:14:48.179000Z"}
{"type":"open","side":"sell","price":"8825.48000000","order_id":"94cc6094-8586-4270-b593-3a87a964789f","remaining_size":"0.06847422","product_id":"BTC-EUR","sequence":3257979872,"time":"2018-01-22T15:14:48.179000Z"}
{"type":"received","order_id":"17ad4970-a210-4b53-b8e5-2149783a2bf4","order_type":"limit","size":"0.00200000","price":"8825.42000000","side":"sell","client_oid":"6c950271-d903-4729-98db-3652cf6fb95a","product_id":"BTC-EUR","sequence":3257979873,"time":"2018-01-22T15:14:48.188000Z"}
{"type":"open","side":"sell","price":"8825.42000000","order_id":"17ad4970-a210-4b53-b8e5-2149783a2bf4","remaining_size":"0.00200000","product_id":"BTC-EUR","sequence":3257979874,"time":"2018-01-22T15:14:48.188000Z"}
{"type":"received","order_id":"2e1401eb-6de2-48df-b84d-b1cf2dc40da5","order_type":"limit","size":"1.28000000","price":"9110.22000000","side":"sell","product_id":"BTC-EUR","sequence":3257979875,"time":"2018-01-22T15:14:48.191000Z"}
{"type":"open","side":"sell","price":"9110.22000000","order_id":"2e1401eb-6de2-48df-b84d-b1cf2dc40da5","remaining_size":"1.28000000","product_id":"BTC-EUR","sequence":3257979876,"time":"2018-01-22T15:14:48.191000Z"}
{"type":"received","order_id":"0e4b3d79-d3a6-476b-8414-2680b48e3ef5","order_type":"limit","size":"0.06847422","price":"8825.43000000","side":"sell","client_oid":"42855745-9c81-4dbc-8050-814b404cca25","product_id":"BTC-EUR","sequence":3257979877,"time":"2018-01-22T15:14:48.194000Z"}
{"type":"open","side":"sell","price":"8825.43000000","order_id":"0e4b3d79-d3a6-476b-8414-2680b48e3ef5","remaining_size":"0.06847422","product_id":"BTC-EUR","sequence":3257979878,"time":"2018-01-22T15:14:48.194000Z"}
{"type":"received","order_id":"2343be78-af81-447b-b5b7-6129db09e880","order_type":"limit","size":"0.06847422","price":"8825.42000000","side":"sell","client_oid":"7bc49736-ade6-4046-a5a9-73e7b6a5fe30","product_id":"BTC-EUR","sequence":3257979879,"time":"2018-01-22T15:14:48.196000Z"}
{"type":"open","side":"sell","price":"8825.42000000","order_id":"2343be78-af81-447b-b5b7-6129db09e880","remaining_size":"0.06847422","product_id":"BTC-EUR","sequence":3257979880,"time":"2018-01-22T15:14:48.196000Z"}
{"type":"received","order_id":"e28f8548-4db1-4b43-9472-7c62b81e10d6","order_type":"limit","size":"0.03322226","price":"8825.65000000","side":"sell","client_oid":"d900d575-8cd2-4460-bcfc-8fbef92c7937","product_id":"BTC-EUR","sequence":3257979881,"time":"2018-01-22T15:14:48.198000Z"}
{"type":"open","side":"sell","price":"8825.65000000","order_id":"e28f8548-4db1-4b43-9472-7c62b81e10d6","remaining_size":"0.03322226","product_id":"BTC-EUR","sequence":3257979882,"time":"2018-01-22T15:14:48.198000Z"}
{"type":"done","side":"sell","order_id":"e28f8548-4db1-4b43-9472-7c62b81e10d6","reason":"canceled","product_id":"BTC-EUR","price":"8825.65000000","remaining_size":"0.03322226","sequence":3257979883,"time":"2018-01-22T15:14:48.202000Z"}
{"type":"received","order_id":"263820db-48d9-442d-9c26-d5bc210033d6","order_type":"limit","size":"0.01511324","price":"8801.01000000","side":"buy","client_oid":"b50b2ce1-2471-4dde-afbe-c2d6b3b4ba91","product_id":"BTC-EUR","sequence":3257979884,"time":"2018-01-22T15:14:48.213000Z"}
{"type":"open","side":"buy","price":"8801.01000000","order_id":"263820db-48d9-442d-9c26-d5bc210033d6","remaining_size":"0.01511324","product_id":"BTC-EUR","sequence":3257979885,"time":"2018-01-22T15:14:48.213000Z"}
{"type":"received","order_id":"20d4a9f2-5127-41ee-ac5d-365d0d2d4ca7","order_type":"limit","size":"0.22464950","price":"8878.39000000","side":"sell","client_oid":"6b953feb-d9b5-4250-b6dd-a81fe5e91831","product_id":"BTC-EUR","sequence":3257979886,"time":"2018-01-22T15:14:48.218000Z"}
{"type":"open","side":"sell","price":"8878.39000000","order_id":"20d4a9f2-5127-41ee-ac5d-365d0d2d4ca7","remaining_size":"0.22464950","product_id":"BTC-EUR","sequence":3257979887,"time":"2018-01-22T15:14:48.218000Z"}
{"type":"received","order_id":"a4869d42-935f-462a-8a35-9ff1bcbdcf54","order_type":"limit","size":"0.22464950","price":"8889.84000000","side":"sell","client_oid":"16c5be9b-84b4-472f-8bc3-37853602ce0d","product_id":"BTC-EUR","sequence":3257979888,"time":"2018-01-22T15:14:48.232000Z"}
{"type":"open","side":"sell","price":"8889.84000000","order_id":"a4869d42-935f-462a-8a35-9ff1bcbdcf54","remaining_size":"0.22464950","product_id":"BTC-EUR","sequence":3257979889,"time":"2018-01-22T15:14:48.232000Z"}
{"type":"received","order_id":"bc25bf24-f7cc-4cbe-baea-b4daae51e981","order_type":"limit","size":"0.22464950","price":"8901.17000000","side":"sell","client_oid":"f6802048-1060-4ffb-a15a-1660570f72a0","product_id":"BTC-EUR","sequence":3257979890,"time":"2018-01-22T15:14:48.237000Z"}
{"type":"open","side":"sell","price":"8901.17000000","order_id":"bc25bf24-f7cc-4cbe-baea-b4daae51e981","remaining_size":"0.22464950","product_id":"BTC-EUR","sequence":3257979891,"time":"2018-01-22T15:14:48.237000Z"}
{"type":"received","order_id":"0b44ad57-f9dd-4aea-adee-40e016c22719","order_type":"limit","size":"0.00113290","price":"8825.41000000","side":"sell","client_oid":"82eac093-77de-4100-8a35-2cd03f6a976f","product_id":"BTC-EUR","sequence":3257979892,"time":"2018-01-22T15:14:48.249000Z"}
{"type":"open","side":"sell","price":"8825.41000000","order_id":"0b44ad57-f9dd-4aea-adee-40e016c22719","remaining_size":"0.00113290","product_id":"BTC-EUR","sequence":3257979893,"time":"2018-01-22T15:14:48.249000Z"}
{"type":"received","order_id":"89a32632-fa94-48c3-94a6-031bee06da3a","order_type":"limit","size":"0.10500000","price":"8825.43000000","side":"sell","client_oid":"47462772-b59f-4a23-ac32-be899f9af09d","product_id":"BTC-EUR","sequence":3257979894,"time":"2018-01-22T15:14:48.252000Z"}
{"type":"open","side":"sell","price":"8825.43000000","order_id":"89a32632-fa94-48c3-94a6-031bee06da3a","remaining_size":"0.10500000","product_id":"BTC-EUR","sequence":3257979895,"time":"2018-01-22T15:14:48.252000Z"}
{"type":"received","order_id":"3ecb8686-2d34-4787-8321-a46996679c00","order_type":"limit","size":"0.22464950","price":"8911.88000000","side":"sell","client_oid":"4096b3a5-8d74-4b64-8959-835bb175cf97","product_id":"BTC-EUR","sequence":3257979896,"time":"2018-01-22T15:14:48.255000Z"}
{"type":"open","side":"sell","price":"8911.88000000","order_id":"3ecb8686-2d34-4787-8321-a46996679c00","remaining_size":"0.22464950","product_id":"BTC-EUR","sequence":3257979897,"time":"2018-01-22T15:14:48.255000Z"}
{"type":"received","order_id":"3031c20b-5331-4708-90e1-528449c0a24d","order_type":"limit","size":"0.22464950","price":"8923.73000000","side":"sell","client_oid":"221d1901-eeb1-49b1-adb4-c694f6910aca","product_id":"BTC-EUR","sequence":3257979898,"time":"2018-01-22T15:14:48.265000Z"}
{"type":"open","side":"sell","price":"8923.73000000","order_id":"3031c20b-5331-4708-90e1-528449c0a24d","remaining_size":"0.22464950","product_id":"BTC-EUR","sequence":3257979899,"time":"2018-01-22T15:14:48.265000Z"}
{"type":"received","order_id":"62ed4114-fc08-4b86-a783-d32ba3754250","order_type":"limit","size":"0.01322632","price":"8825.42000000","side":"sell","client_oid":"1a794eec-4e69-4b48-91e6-785a7320bafa","product_id":"BTC-EUR","sequence":3257979900,"time":"2018-01-22T15:14:48.268000Z"}
{"type":"open","side":"sell","price":"8825.42000000","order_id":"62ed4114-fc08-4b86-a783-d32ba3754250","remaining_size":"0.01322632","product_id":"BTC-EUR","sequence":3257979901,"time":"2018-01-22T15:14:48.268000Z"}
{"type":"received","order_id":"783f3d58-c435-49e0-8b2b-50cd60493383","order_type":"limit","size":"0.00200000","price":"8825.38000000","side":"sell","client_oid":"0d3b8f4b-4312-4c9c-89d7-b1dca0fbe3ba","product_id":"BTC-EUR","sequence":3257979902,"time":"2018-01-22T15:14:48.275000Z"}
{"type":"open","side":"sell","price":"8825.38000000","order_id":"783f3d58-c435-49e0-8b2b-50cd60493383","remaining_size":"0.00200000","product_id":"BTC-EUR","sequence":3257979903,"time":"2018-01-22T15:14:48.275000Z"}
{"type":"done","side":"sell","order_id":"3342f609-a0c8-41da-9c8e-6695ab874814","reason":"canceled","product_id":"BTC-EUR","price":"8825.43000000","remaining_size":"0.10500000","sequence":3257979904,"time":"2018-01-22T15:14:48.285000Z"}
{"type":"received","order_id":"9cd77588-acbb-4b85-adc1-cfedcfe578cf","order_type":"limit","size":"0.10500000","price":"8825.43000000","side":"sell","client_oid":"1fe0f5a0-2a0f-432c-9830-9cb8c5074760","product_id":"BTC-EUR","sequence":3257979905,"time":"2018-01-22T15:14:48.295000Z"}
{"type":"open","side":"sell","price":"8825.43000000","order_id":"9cd77588-acbb-4b85-adc1-cfedcfe578cf","remaining_size":"0.10500000","product_id":"BTC-EUR","sequence":3257979906,"time":"2018-01-22T15:14:48.295000Z"}
{"type":"done","side":"sell","order_id":"0b44ad57-f9dd-4aea-adee-40e016c22719","reason":"canceled","product_id":"BTC-EUR","price":"8825.41000000","remaining_size":"0.00113290","sequence":3257979907,"time":"2018-01-22T15:14:48.296000Z"}
{"type":"received","order_id":"edc49591-1b83-4e88-be57-dfbee71472af","order_type":"limit","size":"0.00113290","price":"8825.37000000","side":"sell","client_oid":"01fd3a56-9903-4863-b518-f0fa3c966632","product_id":"BTC-EUR","sequence":3257979908,"time":"2018-01-22T15:14:48.328000Z"}
{"type":"open","side":"sell","price":"8825.37000000","order_id":"edc49591-1b83-4e88-be57-dfbee71472af","remaining_size":"0.00113290","product_id":"BTC-EUR","sequence":3257979909,"time":"2018-01-22T15:14:48.328000Z"}
{"type":"done","side":"sell","order_id":"89a32632-fa94-48c3-94a6-031bee06da3a","reason":"canceled","product_id":"BTC-EUR","price":"8825.43000000","remaining_size":"0.10500000","sequence":3257979910,"time":"2018-01-22T15:14:48.359000Z"}
{"type":"done","side":"sell","order_id":"17ad4970-a210-4b53-b8e5-2149783a2bf4","reason":"canceled","product_id":"BTC-EUR","price":"8825.42000000","remaining_size":"0.00200000","sequence":3257979911,"time":"2018-01-22T15:14:48.360000Z"}
{"type":"received","order_id":"d0784d92-898d-46ee-a522-2faf70eba6de","order_type":"limit","size":"0.08800000","price":"8825.38000000","side":"sell","client_oid":"60c351e4-d0eb-4e81-85f1-27d8c99317ae","product_id":"BTC-EUR","sequence":3257979912,"time":"2018-01-22T15:14:48.363000Z"}
{"type":"open","side":"sell","price":"8825.38000000","order_id":"d0784d92-898d-46ee-a522-2faf70eba6de","remaining_size":"0.08800000","product_id":"BTC-EUR","sequence":3257979913,"time":"2018-01-22T15:14:48.363000Z"}
{"type":"received","order_id":"473e713e-4c5d-45bf-bb9d-603711a84613","order_type":"limit","size":"0.10500000","price":"8825.38000000","side":"sell","client_oid":"072e9d89-7f87-4ab5-a3d1-29d3d23d5070","product_id":"BTC-EUR","sequence":3257979914,"time":"2018-01-22T15:14:48.367000Z"}
{"type":"open","side":"sell","price":"8825.38000000","order_id":"473e713e-4c5d-45bf-bb9d-603711a84613","remaining_size":"0.10500000","product_id":"BTC-EUR","sequence":3257979915,"time":"2018-01-22T15:14:48.367000Z"}
{"type":"received","order_id":"54519315-339e-407b-a4a0-1faf3a57fe0f","order_type":"limit","size":"0.00200000","price":"8825.42000000","side":"sell","client_oid":"f02d0556-8bb2-476a-8972-2d23d79ce0c0","product_id":"BTC-EUR","sequence":3257979916,"time":"2018-01-22T15:14:48.375000Z"}
{"type":"open","side":"sell","price":"8825.42000000","order_id":"54519315-339e-407b-a4a0-1faf3a57fe0f","remaining_size":"0.00200000","product_id":"BTC-EUR","sequence":3257979917,"time":"2018-01-22T15:14:48.375000Z"}
{"type":"received","order_id":"cb1320e1-aaf0-4835-a7ce-9ac19821f8df","order_type":"limit","size":"0.03322226","price":"8825.42000000","side":"sell","client_oid":"a20f2e8e-847d-4bff-ae49-4fc99f96819d","product_id":"BTC-EUR","sequence":3257979918,"time":"2018-01-22T15:14:48.380000Z"}
{"type":"open","side":"sell","price":"8825.42000000","order_id":"cb1320e1-aaf0-4835-a7ce-9ac19821f8df","remaining_size":"0.03322226","product_id":"BTC-EUR","sequence":3257979919,"time":"2018-01-22T15:14:48.380000Z"}
{"type":"received","order_id":"e863a855-2ae3-48ec-bfa0-bf09c31acf62","order_type":"limit","size":"0.00200000","price":"8825.40000000","side":"sell","client_oid":"1600218b-8401-45ad-b48c-faadee932761","product_id":"BTC-EUR","sequence":3257979920,"time":"2018-01-22T15:14:48.382000Z"}
{"type":"open","side":"sell","price":"8825.40000000","order_id":"e863a855-2ae3-48ec-bfa0-bf09c31acf62","remaining_size":"0.00200000","product_id":"BTC-EUR","sequence":3257979921,"time":"2018-01-22T15:14:48.382000Z"}
{"type":"done","side":"sell","order_id":"cb1320e1-aaf0-4835-a7ce-9ac19821f8df","reason":"canceled","product_id":"BTC-EUR","price":"8825.42000000","remaining_size":"0.03322226","sequence":3257979922,"time":"2018-01-22T15:14:48.385000Z"}
{"type":"done","side":"sell","order_id":"783f3d58-c435-49e0-8b2b-50cd60493383","reason":"canceled","product_id":"BTC-EUR","price":"8825.38000000","remaining_size":"0.00200000","sequence":3257979923,"time":"2018-01-22T15:14:48.405000Z"}
{"type":"done","side":"sell","order_id":"9cd77588-acbb-4b85-adc1-cfedcfe578cf","reason":"canceled","product_id":"BTC-EUR","price":"8825.43000000","remaining_size":"0.10500000","sequence":3257979924,"time":"2018-01-22T15:14:48.414000Z"}
{"type":"received","order_id":"a0f0047c-971b-4341-9ea3-e107d0d15ac4","order_type":"limit","size":"0.04164971","price":"8825.42000000","side":"sell","client_oid":"a544ada7-a63f-4531-aafe-ed651c0c6884","product_id":"BTC-EUR","sequence":3257979925,"time":"2018-01-22T15:14:48.421000Z"}
{"type":"open","side":"sell","price":"8825.42000000","order_id":"a0f0047c-971b-4341-9ea3-e107d0d15ac4","remaining_size":"0.04164971","product_id":"BTC-EUR","sequence":3257979926,"time":"2018-01-22T15:14:48.421000Z"}
{"type":"done","side":"sell","order_id":"2343be78-af81-447b-b5b7-6129db09e880","reason":"canceled","product_id":"BTC-EUR","price":"8825.42000000","remaining_size":"0.06847422","sequence":3257979927,"time":"2018-01-22T15:14:48.428000Z"}
{"type":"received","order_id":"d432856b-f820-4a4c-ad85-fbb5c9a15934","order_type":"limit","size":"0.03322226","price":"8825.38000000","side":"sell","client_oid":"4854ff77-0afb-4078-b8b5-6e60bad0b8a0","product_id":"BTC-EUR","sequence":3257979928,"time":"2018-01-22T15:14:48.429000Z"}
{"type":"open","side":"sell","price":"8825.38000000","order_id":"d432856b-f820-4a4c-ad85-fbb5c9a15934","remaining_size":"0.03322226","product_id":"BTC-EUR","sequence":3257979929,"time":"2018-01-22T15:14:48.429000Z"}
{"type":"received","order_id":"7a3fa390-6c8c-47c8-b891-559ed1854668","order_type":"limit","size":"0.10500000","price":"8825.37000000","side":"sell","client_oid":"24df61fd-d849-456e-819b-be550dd22c95","product_id":"BTC-EUR","sequence":3257979930,"time":"2018-01-22T15:14:48.445000Z"}
{"type":"open","side":"sell","price":"8825.37000000","order_id":"7a3fa390-6c8c-47c8-b891-559ed1854668","remaining_size":"0.10500000","product_id":"BTC-EUR","sequence":3257979931,"time":"2018-01-22T15:14:48.445000Z"}
{"type":"received","order_id":"2a3a5377-c7f4-4933-a54b-557eedc93c0c","order_type":"limit","size":"0.00200000","price":"8825.36000000","side":"sell","client_oid":"448b3e3c-c80a-4605-9785-e0ddd6ad8f55","product_id":"BTC-EUR","sequence":3257979932,"time":"2018-01-22T15:14:48.451000Z"}
{"type":"open","side":"sell","price":"8825.36000000","order_id":"2a3a5377-c7f4-4933-a54b-557eedc93c0c","remaining_size":"0.00200000","product_id":"BTC-EUR","sequence":3257979933,"time":"2018-01-22T15:14:48.451000Z"}
{"type":"done","side":"buy","order_id":"25fa957c-9534-43ff-ba7d-eb682cbbad24","reason":"canceled","product_id":"BTC-EUR","price":"8742.41000000","remaining_size":"0.12454289","sequence":3257979934,"time":"2018-01-22T15:14:48.453000Z"}
{"type":"done","side":"sell","order_id":"e863a855-2ae3-48ec-bfa0-bf09c31acf62","reason":"canceled","product_id":"BTC-EUR","price":"8825.40000000","remaining_size":"0.00200000","sequence":3257979935,"time":"2018-01-22T15:14:48.460000Z"}
{"type":"done","side":"sell","order_id":"d432856b-f820-4a4c-ad85-fbb5c9a15934","reason":"canceled","product_id":"BTC-EUR","price":"8825.38000000","remaining_size":"0.03322226","sequence":3257979936,"time":"2018-01-22T15:14:48.464000Z"}
{"type":"done","side":"sell","order_id":"edc49591-1b83-4e88-be57-dfbee71472af","reason":"canceled","product_id":"BTC-EUR","price":"8825.37000000","remaining_size":"0.00113290","sequence":3257979937,"time":"2018-01-22T15:14:48.467000Z"}
{"type":"done","side":"sell","order_id":"acb66362-6373-4e14-8df7-0fe44a4708d1","reason":"canceled","product_id":"BTC-EUR","price":"8825.51000000","remaining_size":"0.00564464","sequence":3257979938,"time":"2018-01-22T15:14:48.481000Z"}
{"type":"done","side":"sell","order_id":"473e713e-4c5d-45bf-bb9d-603711a84613","reason":"canceled","product_id":"BTC-EUR","price":"8825.38000000","remaining_size":"0.10500000","sequence":3257979939,"time":"2018-01-22T15:14:48.485000Z"}
{"type":"done","side":"sell","order_id":"c8ab6ca3-e3e6-4346-944c-12c06fb95204","reason":"canceled","product_id":"BTC-EUR","price":"8826.44000000","remaining_size":"0.02754400","sequence":3257979940,"time":"2018-01-22T15:14:48.486000Z"}
{"type":"received","order_id":"f30a169b-b53f-4c52-9b5e-4f346defa4cb","order_type":"limit","size":"0.00200000","price":"8825.36000000","side":"sell","client_oid":"46bfc0aa-3341-4763-b3ad-16b8006e2456","product_id":"BTC-EUR","sequence":3257979941,"time":"2018-01-22T15:14:48.499000Z"}
{"type":"open","side":"sell","price":"8825.36000000","order_id":"f30a169b-b53f-4c52-9b5e-4f346defa4cb","remaining_size":"0.00200000","product_id":"BTC-EUR","sequence":3257979942,"time":"2018-01-22T15:14:48.499000Z"}
{"type":"received","order_id":"f38446d5-480b-4499-8fe2-15633e0c0d8f","order_type":"limit","size":"0.10500000","price":"8825.37000000","side":"sell","client_oid":"8bf63a05-021a-4333-a2e5-79ec5e0a8de1","product_id":"BTC-EUR","sequence":3257979943,"time":"2018-01-22T15:14:48.506000Z"}
{"type":"open","side":"sell","price":"8825.37000000","order_id":"f38446d5-480b-4499-8fe2-15633e0c0d8f","remaining_size":"0.10500000","product_id":"BTC-EUR","sequence":3257979944,"time":"2018-01-22T15:14:48.506000Z"}
{"type":"done","side":"sell","order_id":"54519315-339e-407b-a4a0-1faf3a57fe0f","reason":"canceled","product_id":"BTC-EUR","price":"8825.42000000","remaining_size":"0.00200000","sequence":3257979945,"time":"2018-01-22T15:14:48.523000Z"}
{"type":"received","order_id":"a33d1844-aea4-4f60-9939-5303495b5670","order_type":"limit","size":"0.01656300","price":"8825.34000000","side":"sell","product_id":"BTC-EUR","sequence":3257979946,"time":"2018-01-22T15:14:48.523000Z"}
{"type":"open","side":"sell","price":"8825.34000000","order_id":"a33d1844-aea4-4f60-9939-5303495b5670","remaining_size":"0.01656300","product_id":"BTC-EUR","sequence":3257979947,"time":"2018-01-22T15:14:48.523000Z"}
{"type":"done","side":"sell","order_id":"d0784d92-898d-46ee-a522-2faf70eba6de","reason":"canceled","product_id":"BTC-EUR","price":"8825.38000000","remaining_size":"0.08800000","sequence":3257979948,"time":"2018-01-22T15:14:48.524000Z"}
{"type":"done","side":"sell","order_id":"7a3fa390-6c8c-47c8-b891-559ed1854668","reason":"canceled","product_id":"BTC-EUR","price":"8825.37000000","remaining_size":"0.10500000","sequence":3257979949,"time":"2018-01-22T15:14:48.537000Z"}
{"type":"done","side":"sell","order_id":"0f35816b-2c40-49d1-872e-845d84f21f48","reason":"canceled","product_id":"BTC-EUR","price":"8825.43000000","remaining_size":"0.06847422","sequence":3257979950,"time":"2018-01-22T15:14:48.545000Z"}
{"type":"done","side":"sell","order_id":"0e4b3d79-d3a6-476b-8414-2680b48e3ef5","reason":"canceled","product_id":"BTC-EUR","price":"8825.43000000","remaining_size":"0.06847422","sequence":3257979951,"time":"2018-01-22T15:14:48.545000Z"}
{"type":"done","side":"sell","order_id":"94cc6094-8586-4270-b593-3a87a964789f","reason":"canceled","product_id":"BTC-EUR","price":"8825.48000000","remaining_size":"0.06847422","sequence":3257979952,"time":"2018-01-22T15:14:48.549000Z"}
{"type":"received","order_id":"970d8dc9-dc6e-4483-8997-8fca7c3eb0cf","order_type":"limit","size":"0.03322226","price":"8825.37000000","side":"sell","client_oid":"63749b64-4c64-4955-ac00-42cbde87229f","product_id":"BTC-EUR","sequence":3257979953,"time":"2018-01-22T15:14:48.553000Z"}
{"type":"open","side":"sell","price":"8825.37000000","order_id":"970d8dc9-dc6e-4483-8997-8fca7c3eb0cf","remaining_size":"0.03322226","product_id":"BTC-EUR","sequence":3257979954,"time":"2018-01-22T15:14:48.553000Z"}
{"type":"received","order_id":"890a0c30-9609-4f57-b106-2f3486948075","order_type":"limit","size":"0.06847422","price":"8825.41000000","side":"sell","client_oid":"224a37f3-3a32-4a74-883a-3aa4fb1afafb","product_id":"BTC-EUR","sequence":3257979955,"time":"2018-01-22T15:14:48.557000Z"}
{"type":"open","side":"sell","price":"8825.41000000","order_id":"890a0c30-9609-4f57-b106-2f3486948075","remaining_size":"0.06847422","product_id":"BTC-EUR","sequence":3257979956,"time":"2018-01-22T15:14:48.557000Z"}
{"type":"received","order_id":"7b50a090-3dcf-4f0c-816e-54566fd07ad9","order_type":"limit","size":"0.10500000","price":"8825.36000000","side":"sell","client_oid":"9497def1-864f-485a-bb4d-42f3ea66be6d","product_id":"BTC-EUR","sequence":3257979957,"time":"2018-01-22T15:14:48.566000Z"}
{"type":"open","side":"sell","price":"8825.36000000","order_id":"7b50a090-3dcf-4f0c-816e-54566fd07ad9","remaining_size":"0.10500000","product_id":"BTC-EUR","sequence":3257979958,"time":"2018-01-22T15:14:48.566000Z"}
{"type":"received","order_id":"240d82a3-f20c-47ef-883f-12b8dfd4a181","order_type":"limit","size":"0.06847422","price":"8825.37000000","side":"sell","client_oid":"6cb8a83e-cf16-4d4a-a5d8-1e80af3e40e8","product_id":"BTC-EUR","sequence":3257979959,"time":"2018-01-22T15:14:48.574000Z"}
{"type":"open","side":"sell","price":"8825.37000000","order_id":"240d82a3-f20c-47ef-883f-12b8dfd4a181","remaining_size":"0.06847422","product_id":"BTC-EUR","sequence":3257979960,"time":"2018-01-22T15:14:48.574000Z"}
{"type":"done","side":"sell","order_id":"970d8dc9-dc6e-4483-8997-8fca7c3eb0cf","reason":"canceled","product_id":"BTC-EUR","price":"8825.37000000","remaining_size":"0.03322226","sequence":3257979961,"time":"2018-01-22T15:14:48.575000Z"}
{"type":"done","side":"sell","order_id":"f38446d5-480b-4499-8fe2-15633e0c0d8f","reason":"canceled","product_id":"BTC-EUR","price":"8825.37000000","remaining_size":"0.10500000","sequence":3257979962,"time":"2018-01-22T15:14:48.590000Z"}
{"type":"done","side":"sell","order_id":"f30a169b-b53f-4c52-9b5e-4f346defa4cb","reason":"canceled","product_id":"BTC-EUR","price":"8825.36000000","remaining_size":"0.00200000","sequence":3257979963,"time":"2018-01-22T15:14:48.600000Z"}
{"type":"received","order_id":"dc8e6d82-b9c7-49e0-aec2-5f54974a08d6","order_type":"limit","size":"0.02754471","price":"8825.64000000","side":"sell","product_id":"BTC-EUR","sequence":3257979964,"time":"2018-01-22T15:14:48.611000Z"}
{"type":"open","side":"sell","price":"8825.64000000","order_id":"dc8e6d82-b9c7-49e0-aec2-5f54974a08d6","remaining_size":"0.02754471","product_id":"BTC-EUR","sequence":3257979965,"time":"2018-01-22T15:14:48.611000Z"}
{"type":"received","order_id":"5167d9a8-993b-4ae8-8775-3cf3fadd7709","order_type":"limit","size":"0.10500000","price":"8825.36000000","side":"sell","client_oid":"d4b278a7-c403-4e81-b98a-cb07a4198d45","product_id":"BTC-EUR","sequence":3257979966,"time":"2018-01-22T15:14:48.626000Z"}
{"type":"open","side":"sell","price":"8825.36000000","order_id":"5167d9a8-993b-4ae8-8775-3cf3fadd7709","remaining_size":"0.10500000","product_id":"BTC-EUR","sequence":3257979967,"time":"2018-01-22T15:14:48.626000Z"}
{"type":"received","order_id":"6447e454-dfe1-4bb8-9e35-6d127bbd65c6","order_type":"limit","size":"0.03322226","price":"8825.36000000","side":"sell","client_oid":"d45a49e5-6c60-4347-b987-773259cd13b0","product_id":"BTC-EUR","sequence":3257979968,"time":"2018-01-22T15:14:48.629000Z"}
{"type":"open","side":"sell","price":"8825.36000000","order_id":"6447e454-dfe1-4bb8-9e35-6d127bbd65c6","remaining_size":"0.03322226","product_id":"BTC-EUR","sequence":3257979969,"time":"2018-01-22T15:14:48.629000Z"}
{"type":"received","order_id":"737614bb-cbd2-42bf-8e7a-032e7d14de0d","order_type":"limit","size":"0.00113290","price":"8825.33000000","side":"sell","client_oid":"cc8b309b-2fea-426c-a946-0416b10542e2","product_id":"BTC-EUR","sequence":3257979970,"time":"2018-01-22T15:14:48.636000Z"}
{"type":"open","side":"sell","price":"8825.33000000","order_id":"737614bb-cbd2-42bf-8e7a-032e7d14de0d","remaining_size":"0.00113290","product_id":"BTC-EUR","sequence":3257979971,"time":"2018-01-22T15:14:48.636000Z"}
{"type":"done","side":"sell","order_id":"2a3a5377-c7f4-4933-a54b-557eedc93c0c","reason":"canceled","product_id":"BTC-EUR","price":"8825.36000000","remaining_size":"0.00200000","sequence":3257979972,"time":"2018-01-22T15:14:48.640000Z"}
{"type":"received","order_id":"bd9e2f41-5825-46ac-a2ed-d491a0760c43","order_type":"limit","size":"0.10500000","price":"8825.34000000","side":"sell","client_oid":"d99faffb-e376-4d7d-87b8-8e66f02a1616","product_id":"BTC-EUR","sequence":3257979973,"time":"2018-01-22T15:14:48.647000Z"}
{"type":"open","side":"sell","price":"8825.34000000","order_id":"bd9e2f41-5825-46ac-a2ed-d491a0760c43","remaining_size":"0.10500000","product_id":"BTC-EUR","sequence":3257979974,"time":"2018-01-22T15:14:48.647000Z"}
{"type":"received","order_id":"2c602f80-9945-4cbd-90ec-bbe535ec1485","order_type":"limit","size":"0.00200000","price":"8825.33000000","side":"sell","client_oid":"c3137925-39e6-470c-aa5b-aeb88d3f4cbc","product_id":"BTC-EUR","sequence":3257979975,"time":"2018-01-22T15:14:48.649000Z"}
{"type":"open","side":"sell","price":"8825.33000000","order_id":"2c602f80-9945-4cbd-90ec-bbe535ec1485","remaining_size":"0.00200000","product_id":"BTC-EUR","sequence":3257979976,"time":"2018-01-22T15:14:48.649000Z"}
{"type":"done","side":"sell","order_id":"6447e454-dfe1-4bb8-9e35-6d127bbd65c6","reason":"canceled","product_id":"BTC-EUR","price":"8825.36000000","remaining_size":"0.03322226","sequence":3257979977,"time":"2018-01-22T15:14:48.662000Z"}
{"type":"done","side":"sell","order_id":"7b50a090-3dcf-4f0c-816e-54566fd07ad9","reason":"canceled","product_id":"BTC-EUR","price":"8825.36000000","remaining_size":"0.10500000","sequence":3257979978,"time":"2018-01-22T15:14:48.664000Z"}
{"type":"done","side":"sell","order_id":"a33d1844-aea4-4f60-9939-5303495b5670","reason":"canceled","product_id":"BTC-EUR","price":"8825.34000000","remaining_size":"0.01656300","sequence":3257979979,"time":"2018-01-22T15:14:48.683000Z"}
{"type":"received","order_id":"b7fc019a-06ba-4ba8-ba2e-918c2b9dd42b","order_type":"limit","size":"0.06847422","price":"8825.36000000","side":"sell","client_oid":"ee476aa9-223d-4c67-a1d5-fce2084e8799","product_id":"BTC-EUR","sequence":3257979980,"time":"2018-01-22T15:14:48.691000Z"}
{"type":"open","side":"sell","price":"8825.36000000","order_id":"b7fc019a-06ba-4ba8-ba2e-918c2b9dd42b","remaining_size":"0.06847422","product_id":"BTC-EUR","sequence":3257979981,"time":"2018-01-22T15:14:48.691000Z"}
{"type":"received","order_id":"de5032d8-0c19-4aa5-ba15-40c572526e33","order_type":"limit","size":"0.06847422","price":"8825.35000000","side":"sell","client_oid":"b7283492-43b3-42a9-8c93-2659b4f7d160","product_id":"BTC-EUR","sequence":3257979982,"time":"2018-01-22T15:14:48.693000Z"}
{"type":"open","side":"sell","price":"8825.35000000","order_id":"de5032d8-0c19-4aa5-ba15-40c572526e33","remaining_size":"0.06847422","product_id":"BTC-EUR","sequence":3257979983,"time":"2018-01-22T15:14:48.693000Z"}
{"type":"received","order_id":"0a8f6108-dee3-41ab-b408-431c58db10ad","order_type":"limit","size":"0.06847422","price":"8825.33000000","side":"sell","client_oid":"115c4558-4dc2-4826-864a-285c23ca4520","product_id":"BTC-EUR","sequence":3257979984,"time":"2018-01-22T15:14:48.701000Z"}
{"type":"open","side":"sell","price":"8825.33000000","order_id":"0a8f6108-dee3-41ab-b408-431c58db10ad","remaining_size":"0.06847422","product_id":"BTC-EUR","sequence":3257979985,"time":"2018-01-22T15:14:48.701000Z"}
{"type":"received","order_id":"d1ab1506-8ef1-41cb-a477-d6214eaa5664","order_type":"limit","size":"0.00200000","price":"8825.33000000","side":"sell","client_oid":"bbd53b03-2d95-4b40-b503-8095a05f39a0","product_id":"BTC-EUR","sequence":3257979986,"time":"2018-01-22T15:14:48.701000Z"}
{"type":"open","side":"sell","price":"8825.33000000","order_id":"d1ab1506-8ef1-41cb-a477-d6214eaa5664","remaining_size":"0.00200000","product_id":"BTC-EUR","sequence":3257979987,"time":"2018-01-22T15:14:48.701000Z"}
{"type":"done","side":"sell","order_id":"21a2a4e6-7153-4ab6-a8a9-4f568beace1f","reason":"canceled","product_id":"BTC-EUR","price":"8825.43000000","remaining_size":"0.01800000","sequence":3257979988,"time":"2018-01-22T15:14:48.704000Z"}
{"type":"done","side":"sell","order_id":"5167d9a8-993b-4ae8-8775-3cf3fadd7709","reason":"canceled","product_id":"BTC-EUR","price":"8825.36000000","remaining_size":"0.10500000","sequence":3257979989,"time":"2018-01-22T15:14:48.704000Z"}
{"type":"received","order_id":"94cd536e-4f7e-4290-bc26-a551a515646d","order_type":"limit","size":"0.01800000","price":"8825.33000000","side":"sell","client_oid":"b1c2b92e-cf1e-4805-871f-5570aab14771","product_id":"BTC-EUR","sequence":3257979990,"time":"2018-01-22T15:14:48.707000Z"}
{"type":"open","side":"sell","price":"8825.33000000","order_id":"94cd536e-4f7e-4290-bc26-a551a515646d","remaining_size":"0.01800000","product_id":"BTC-EUR","sequence":3257979991,"time":"2018-01-22T15:14:48.707000Z"}
{"type":"received","order_id":"8c3a5de8-e035-4858-9196-866216a90af2","order_type":"limit","size":"0.03322226","price":"8825.34000000","side":"sell","client_oid":"eb8ea492-392a-448d-be6c-c9da946280a9","product_id":"BTC-EUR","sequence":3257979992,"time":"2018-01-22T15:14:48.714000Z"}
{"type":"open","side":"sell","price":"8825.34000000","order_id":"8c3a5de8-e035-4858-9196-866216a90af2","remaining_size":"0.03322226","product_id":"BTC-EUR","sequence":3257979993,"time":"2018-01-22T15:14:48.714000Z"}
{"type":"received","order_id":"e9220f80-8639-4028-92d1-05f8934c0a38","order_type":"limit","size":"0.00564464","price":"8825.36000000","side":"sell","client_oid":"693f672c-66fb-4b42-8118-7dd17fd4f6e1","product_id":"BTC-EUR","sequence":3257979994,"time":"2018-01-22T15:14:48.718000Z"}
{"type":"open","side":"sell","price":"8825.36000000","order_id":"e9220f80-8639-4028-92d1-05f8934c0a38","remaining_size":"0.00564464","product_id":"BTC-EUR","sequence":3257979995,"time":"2018-01-22T15:14:48.718000Z"}
{"type":"received","order_id":"090cdcc5-b09f-4651-978b-d90b52ea6408","order_type":"limit","size":"0.10500000","price":"8825.34000000","side":"sell","client_oid":"7c06ec67-330e-4525-a635-f85c3fc2bb53","product_id":"BTC-EUR","sequence":3257979996,"time":"2018-01-22T15:14:48.731000Z"}
{"type":"open","side":"sell","price":"8825.34000000","order_id":"090cdcc5-b09f-4651-978b-d90b52ea6408","remaining_size":"0.10500000","product_id":"BTC-EUR","sequence":3257979997,"time":"2018-01-22T15:14:48.731000Z"}
{"type":"done","side":"sell","order_id":"bd9e2f41-5825-46ac-a2ed-d491a0760c43","reason":"canceled","product_id":"BTC-EUR","price":"8825.34000000","remaining_size":"0.10500000","sequence":3257979998,"time":"2018-01-22T15:14:48.741000Z"}
{"type":"received","order_id":"bee138c5-5f7a-4c7e-aff6-faaf2b5761bf","order_type":"limit","size":"0.01800000","price":"8825.33000000","side":"sell","client_oid":"229ac4ec-da0a-4f9f-b9ce-3cc9a41ae413","product_id":"BTC-EUR","sequence":3257979999,"time":"2018-01-22T15:14:48.755000Z"}
{"type":"open","side":"sell","price":"8825.33000000","order_id":"bee138c5-5f7a-4c7e-aff6-faaf2b5761bf","remaining_size":"0.01800000","product_id":"BTC-EUR","sequence":3257980000,"time":"2018-01-22T15:14:48.755000Z"}
{"type":"done","side":"sell","order_id":"8c3a5de8-e035-4858-9196-866216a90af2","reason":"canceled","product_id":"BTC-EUR","price":"8825.34000000","remaining_size":"0.03322226","sequence":3257980001,"time":"2018-01-22T15:14:48.760000Z"}
{"type":"received","order_id":"71068ffa-445c-4192-a943-3633cad405cb","order_type":"limit","size":"0.10500000","price":"8825.33000000","side":"sell","client_oid":"0a9fae61-8081-470f-b4b2-a4ca98223b68","product_id":"BTC-EUR","sequence":3257980002,"time":"2018-01-22T15:14:48.785000Z"}
{"type":"open","side":"sell","price":"8825.33000000","order_id":"71068ffa-445c-4192-a943-3633cad405cb","remaining_size":"0.10500000","product_id":"BTC-EUR","sequence":3257980003,"time":"2018-01-22T15:14:48.785000Z"}
{"type":"received","order_id":"90d7e2fb-d1e6-4b79-9793-40d802d9a1af","order_type":"limit","size":"0.10500000","price":"8825.33000000","side":"sell","client_oid":"7c9b9f0c-6709-4564-94c9-0e849460fb2b","product_id":"BTC-EUR","sequence":3257980004,"time":"2018-01-22T15:14:48.790000Z"}
{"type":"open","side":"sell","price":"8825.33000000","order_id":"90d7e2fb-d1e6-4b79-9793-40d802d9a1af","remaining_size":"0.10500000","product_id":"BTC-EUR","sequence":3257980005,"time":"2018-01-22T15:14:48.790000Z"}
{"type":"received","order_id":"e50c84c1-b8fa-4fbc-86da-7edbafa78daa","order_type":"limit","size":"0.03322226","price":"8825.33000000","side":"sell","client_oid":"299dd76a-90d9-42db-9d55-5ec998a38429","product_id":"BTC-EUR","sequence":3257980006,"time":"2018-01-22T15:14:48.806000Z"}
{"type":"open","side":"sell","price":"8825.33000000","order_id":"e50c84c1-b8fa-4fbc-86da-7edbafa78daa","remaining_size":"0.03322226","product_id":"BTC-EUR","sequence":3257980007,"time":"2018-01-22T15:14:48.806000Z"}
{"type":"done","side":"sell","order_id":"240d82a3-f20c-47ef-883f-12b8dfd4a181","reason":"canceled","product_id":"BTC-EUR","price":"8825.37000000","remaining_size":"0.06847422","sequence":3257980008,"time":"2018-01-22T15:14:48.806000Z"}
{"type":"done","side":"sell","order_id":"090cdcc5-b09f-4651-978b-d90b52ea6408","reason":"canceled","product_id":"BTC-EUR","price":"8825.34000000","remaining_size":"0.10500000","sequence":3257980009,"time":"2018-01-22T15:14:48.810000Z"}
{"type":"done","side":"sell","order_id":"67ebc261-35c4-440a-8a92-3c1ccd2762a1","reason":"canceled","product_id":"BTC-EUR","price":"8825.43000000","remaining_size":"0.22947933","sequence":3257980010,"time":"2018-01-22T15:14:48.871000Z"}
{"type":"received","order_id":"a9d10e5b-b31a-4007-a528-12f6965c05b1","order_type":"limit","size":"0.00552100","price":"8825.32000000","side":"sell","product_id":"BTC-EUR","sequence":3257980011,"time":"2018-01-22T15:14:48.898000Z"}
{"type":"open","side":"sell","price":"8825.32000000","order_id":"a9d10e5b-b31a-4007-a528-12f6965c05b1","remaining_size":"0.00552100","product_id":"BTC-EUR","sequence":3257980012,"time":"2018-01-22T15:14:48.898000Z"}
{"type":"done","side":"sell","order_id":"737614bb-cbd2-42bf-8e7a-032e7d14de0d","reason":"canceled","product_id":"BTC-EUR","price":"8825.33000000","remaining_size":"0.00113290","sequence":3257980013,"time":"2018-01-22T15:14:48.905000Z"}
{"type":"done","side":"sell","order_id":"890a0c30-9609-4f57-b106-2f3486948075","reason":"canceled","product_id":"BTC-EUR","price":"8825.41000000","remaining_size":"0.06847422","sequence":3257980014,"time":"2018-01-22T15:14:48.924000Z"}
{"type":"received","order_id":"9e48899c-9e9a-4a65-8ddc-f9a54668d6d8","order_type":"limit","size":"0.06847422","price":"8825.32000000","side":"sell","client_oid":"c6b80ea9-6638-44bc-8a40-ab461ff99f70","product_id":"BTC-EUR","sequence":3257980015,"time":"2018-01-22T15:14:48.932000Z"}
{"type":"open","side":"sell","price":"8825.32000000","order_id":"9e48899c-9e9a-4a65-8ddc-f9a54668d6d8","remaining_size":"0.06847422","product_id":"BTC-EUR","sequence":3257980016,"time":"2018-01-22T15:14:48.932000Z"}
{"type":"done","side":"sell","order_id":"e50c84c1-b8fa-4fbc-86da-7edbafa78daa","reason":"canceled","product_id":"BTC-EUR","price":"8825.33000000","remaining_size":"0.03322226","sequence":3257980017,"time":"2018-01-22T15:14:48.947000Z"}
{"type":"received","order_id":"8ae9882a-7884-409a-b4af-f652ea25d593","order_type":"limit","size":"0.10500000","price":"8825.33000000","side":"sell","client_oid":"6eae57e3-ea2a-488a-aa63-c0eca165a78d","product_id":"BTC-EUR","sequence":3257980018,"time":"2018-01-22T15:14:48.969000Z"}
{"type":"open","side":"sell","price":"8825.33000000","order_id":"8ae9882a-7884-409a-b4af-f652ea25d593","remaining_size":"0.10500000","product_id":"BTC-EUR","sequence":3257980019,"time":"2018-01-22T15:14:48.969000Z"}
{"type":"done","side":"sell","order_id":"94cd536e-4f7e-4290-bc26-a551a515646d","reason":"canceled","product_id":"BTC-EUR","price":"8825.33000000","remaining_size":"0.01800000","sequence":3257980020,"time":"2018-01-22T15:14:48.977000Z"}
{"type":"received","order_id":"dd1867fd-139a-429c-849d-bd3b8b5e23e8","order_type":"limit","size":"0.00113290","price":"8825.31000000","side":"sell","client_oid":"9be53f9b-be84-4c69-be8a-a691fcf80735","product_id":"BTC-EUR","sequence":3257980021,"time":"2018-01-22T15:14:48.982000Z"}
{"type":"open","side":"sell","price":"8825.31000000","order_id":"dd1867fd-139a-429c-849d-bd3b8b5e23e8","remaining_size":"0.00113290","product_id":"BTC-EUR","sequence":3257980022,"time":"2018-01-22T15:14:48.982000Z"}
{"type":"done","side":"sell","order_id":"62ed4114-fc08-4b86-a783-d32ba3754250","reason":"canceled","product_id":"BTC-EUR","price":"8825.42000000","remaining_size":"0.01322632","sequence":3257980023,"time":"2018-01-22T15:14:48.988000Z"}
{"type":"received","order_id":"91bb483a-1884-4486-ade5-bce1f9a6ef3e","order_type":"limit","size":"0.03322226","price":"8825.32000000","side":"sell","client_oid":"df2c82ee-eba2-4c92-9bc3-6ca21eb242d9","product_id":"BTC-EUR","sequence":3257980024,"time":"2018-01-22T15:14:48.992000Z"}
{"type":"open","side":"sell","price":"8825.32000000","order_id":"91bb483a-1884-4486-ade5-bce1f9a6ef3e","remaining_size":"0.03322226","product_id":"BTC-EUR","sequence":3257980025,"time":"2018-01-22T15:14:48.992000Z"}
{"type":"done","side":"sell","order_id":"90d7e2fb-d1e6-4b79-9793-40d802d9a1af","reason":"canceled","product_id":"BTC-EUR","price":"8825.33000000","remaining_size":"0.10500000","sequence":3257980026,"time":"2018-01-22T15:14:48.994000Z"}
{"type":"received","order_id":"53f9d760-5619-4ad0-80d9-751342be0a63","order_type":"limit","size":"0.21404538","price":"8825.33000000","side":"sell","product_id":"BTC-EUR","sequence":3257980027,"time":"2018-01-22T15:14:48.998000Z"}
{"type":"open","side":"sell","price":"8825.33000000","order_id":"53f9d760-5619-4ad0-80d9-751342be0a63","remaining_size":"0.21404538","product_id":"BTC-EUR","sequence":3257980028,"time":"2018-01-22T15:14:48.998000Z"}
{"type":"done","side":"sell","order_id":"71068ffa-445c-4192-a943-3633cad405cb","reason":"canceled","product_id":"BTC-EUR","price":"8825.33000000","remaining_size":"0.10500000","sequence":3257980029,"time":"2018-01-22T15:14:49.001000Z"}
{"type":"done","side":"sell","order_id":"a9d10e5b-b31a-4007-a528-12f6965c05b1","reason":"canceled","product_id":"BTC-EUR","price":"8825.32000000","remaining_size":"0.00552100","sequence":3257980030,"time":"2018-01-22T15:14:49.021000Z"}
{"type":"done","side":"sell","order_id":"d1ab1506-8ef1-41cb-a477-d6214eaa5664","reason":"canceled","product_id":"BTC-EUR","price":"8825.33000000","remaining_size":"0.00200000","sequence":3257980031,"time":"2018-01-22T15:14:49.028000Z"}
{"type":"done","side":"sell","order_id":"2c602f80-9945-4cbd-90ec-bbe535ec1485","reason":"canceled","product_id":"BTC-EUR","price":"8825.33000000","remaining_size":"0.00200000","sequence":3257980032,"time":"2018-01-22T15:14:49.028000Z"}
{"type":"received","order_id":"21738cf8-5244-46df-aec9-544ee901eb30","order_type":"limit","size":"0.10500000","price":"8825.32000000","side":"sell","client_oid":"e91f5691-a7a8-4a7e-a490-c610bef22274","product_id":"BTC-EUR","sequence":3257980033,"time":"2018-01-22T15:14:49.047000Z"}
{"type":"open","side":"sell","price":"8825.32000000","order_id":"21738cf8-5244-46df-aec9-544ee901eb30","remaining_size":"0.10500000","product_id":"BTC-EUR","sequence":3257980034,"time":"2018-01-22T15:14:49.047000Z"}
{"type":"done","side":"sell","order_id":"bee138c5-5f7a-4c7e-aff6-faaf2b5761bf","reason":"canceled","product_id":"BTC-EUR","price":"8825.33000000","remaining_size":"0.01800000","sequence":3257980035,"time":"2018-01-22T15:14:49.088000Z"}
{"type":"done","side":"sell","order_id":"8ae9882a-7884-409a-b4af-f652ea25d593","reason":"canceled","product_id":"BTC-EUR","price":"8825.33000000","remaining_size":"0.10500000","sequence":3257980036,"time":"2018-01-22T15:14:49.089000Z"}
{"type":"done","side":"sell","order_id":"9e48899c-9e9a-4a65-8ddc-f9a54668d6d8","reason":"canceled","product_id":"BTC-EUR","price":"8825.32000000","remaining_size":"0.06847422","sequence":3257980037,"time":"2018-01-22T15:14:49.095000Z"}
{"type":"received","order_id":"debea23b-bcc6-49ef-a1c4-aca8a699907b","order_type":"limit","size":"0.01800000","price":"8825.31000000","side":"sell","client_oid":"5a99ec28-956f-49a8-bdfa-10dcd622a928","product_id":"BTC-EUR","sequence":3257980038,"time":"2018-01-22T15:14:49.100000Z"}
{"type":"open","side":"sell","price":"8825.31000000","order_id":"debea23b-bcc6-49ef-a1c4-aca8a699907b","remaining_size":"0.01800000","product_id":"BTC-EUR","sequence":3257980039,"time":"2018-01-22T15:14:49.100000Z"}
{"type":"done","side":"sell","order_id":"ac4b80e1-0813-435c-8e99-f594b5bccbe7","reason":"canceled","product_id":"BTC-EUR","price":"8900.00000000","remaining_size":"0.02177656","sequence":3257980040,"time":"2018-01-22T15:14:49.109000Z"}
{"type":"received","order_id":"9763ce66-f17f-4eb0-8189-1f997f244aa1","order_type":"limit","size":"0.10500000","price":"8825.30000000","side":"sell","client_oid":"d5c6d1da-000a-421c-8c2c-22c219919523","product_id":"BTC-EUR","sequence":3257980041,"time":"2018-01-22T15:14:49.111000Z"}
{"type":"open","side":"sell","price":"8825.30000000","order_id":"9763ce66-f17f-4eb0-8189-1f997f244aa1","remaining_size":"0.10500000","product_id":"BTC-EUR","sequence":3257980042,"time":"2018-01-22T15:14:49.111000Z"}
{"type":"done","side":"sell","order_id":"53f9d760-5619-4ad0-80d9-751342be0a63","reason":"canceled","product_id":"BTC-EUR","price":"8825.33000000","remaining_size":"0.21404538","sequence":3257980043,"time":"2018-01-22T15:14:49.124000Z"}
{"type":"received","order_id":"4cb0dcfe-626f-4a18-bf23-530ebf3bed94","order_type":"limit","size":"0.22947933","price":"8825.31000000","side":"sell","client_oid":"666284e8-d351-4e17-8cb1-9bd058d62956","product_id":"BTC-EUR","sequence":3257980044,"time":"2018-01-22T15:14:49.130000Z"}
{"type":"open","side":"sell","price":"8825.31000000","order_id":"4cb0dcfe-626f-4a18-bf23-530ebf3bed94","remaining_size":"0.22947933","product_id":"BTC-EUR","sequence":3257980045,"time":"2018-01-22T15:14:49.130000Z"}
{"type":"done","side":"sell","order_id":"91bb483a-1884-4486-ade5-bce1f9a6ef3e","reason":"canceled","product_id":"BTC-EUR","price":"8825.32000000","remaining_size":"0.03322226","sequence":3257980046,"time":"2018-01-22T15:14:49.131000Z"}
{"type":"received","order_id":"0850906a-cc9d-44e7-b29d-ed4657674ccc","order_type":"limit","size":"0.02000000","price":"9090.06000000","side":"buy","product_id":"BTC-EUR","sequence":3257980047,"time":"2018-01-22T15:14:49.138000Z"}
{"type":"match","trade_id":10551378,"maker_order_id":"9763ce66-f17f-4eb0-8189-1f997f244aa1","taker_order_id":"0850906a-cc9d-44e7-b29d-ed4657674ccc","side":"sell","size":"0.02000000","price":"8825.30000000","product_id":"BTC-EUR","sequence":3257980048,"time":"2018-01-22T15:14:49.138000Z"}
{"type":"done","side":"buy","order_id":"0850906a-cc9d-44e7-b29d-ed4657674ccc","reason":"filled","product_id":"BTC-EUR","price":"9090.06000000","remaining_size":"0.00000000","sequence":3257980049,"time":"2018-01-22T15:14:49.138000Z"}
{"type":"done","side":"sell","order_id":"dd1867fd-139a-429c-849d-bd3b8b5e23e8","reason":"canceled","product_id":"BTC-EUR","price":"8825.31000000","remaining_size":"0.00113290","sequence":3257980050,"time":"2018-01-22T15:14:49.139000Z"}
{"type":"received","order_id":"f2c8bf21-05b3-44ee-99c5-e35efe391c9d","order_type":"limit","size":"0.10500000","price":"8825.30000000","side":"sell","client_oid":"65db2920-907c-469a-a24f-3edba5de9cc1","product_id":"BTC-EUR","sequence":3257980051,"time":"2018-01-22T15:14:49.152000Z"}
{"type":"open","side":"sell","price":"8825.30000000","order_id":"f2c8bf21-05b3-44ee-99c5-e35efe391c9d","remaining_size":"0.10500000","product_id":"BTC-EUR","sequence":3257980052,"time":"2018-01-22T15:14:49.152000Z"}
{"type":"received","order_id":"3d5ec085-6a8c-47ac-882c-90551e10ed7c","order_type":"limit","size":"0.03322226","price":"8825.30000000","side":"sell","client_oid":"df246cd2-39be-4f2c-a4bf-c6afefc5f9c6","product_id":"BTC-EUR","sequence":3257980053,"time":"2018-01-22T15:14:49.156000Z"}
{"type":"open","side":"sell","price":"8825.30000000","order_id":"3d5ec085-6a8c-47ac-882c-90551e10ed7c","remaining_size":"0.03322226","product_id":"BTC-EUR","sequence":3257980054,"time":"2018-01-22T15:14:49.156000Z"}
{"type":"done","side":"sell","order_id":"21738cf8-5244-46df-aec9-544ee901eb30","reason":"canceled","product_id":"BTC-EUR","price":"8825.32000000","remaining_size":"0.10500000","sequence":3257980055,"time":"2018-01-22T15:14:49.166000Z"}
{"type":"done","side":"sell","order_id":"a0f0047c-971b-4341-9ea3-e107d0d15ac4","reason":"canceled","product_id":"BTC-EUR","price":"8825.42000000","remaining_size":"0.04164971","sequence":3257980056,"time":"2018-01-22T15:14:49.167000Z"}
{"type":"received","order_id":"f09e4218-4155-405d-8e22-471b66399e57","order_type":"limit","size":"0.10500000","price":"8825.30000000","side":"sell","client_oid":"ef48f17d-8226-4529-833b-9957d8a52692","product_id":"BTC-EUR","sequence":3257980057,"time":"2018-01-22T15:14:49.193000Z"}
{"type":"open","side":"sell","price":"8825.30000000","order_id":"f09e4218-4155-405d-8e22-471b66399e57","remaining_size":"0.10500000","product_id":"BTC-EUR","sequence":3257980058,"time":"2018-01-22T15:14:49.193000Z"}
{"type":"done","side":"sell","order_id":"debea23b-bcc6-49ef-a1c4-aca8a699907b","reason":"canceled","product_id":"BTC-EUR","price":"8825.31000000","remaining_size":"0.01800000","sequence":3257980059,"time":"2018-01-22T15:14:49.201000Z"}
{"type":"received","order_id":"b96d9b3f-77a4-4ff1-a413-7cb057fc7fe9","order_type":"limit","size":"0.00113290","price":"8825.30000000","side":"sell","client_oid":"bf7e3ba0-c1ea-4d04-9ea1-2dd030aac591","product_id":"BTC-EUR","sequence":3257980060,"time":"2018-01-22T15:14:49.203000Z"}
{"type":"open","side":"sell","price":"8825.30000000","order_id":"b96d9b3f-77a4-4ff1-a413-7cb057fc7fe9","remaining_size":"0.00113290","product_id":"BTC-EUR","sequence":3257980061,"time":"2018-01-22T15:14:49.203000Z"}
{"type":"received","order_id":"65078308-e0bf-499b-b8d1-0ea44259d49d","order_type":"limit","size":"0.01322632","price":"8825.31000000","side":"sell","client_oid":"ea1b1ec8-ce98-44cf-8b4a-706d0e3b2f4e","product_id":"BTC-EUR","sequence":3257980062,"time":"2018-01-22T15:14:49.215000Z"}
{"type":"open","side":"sell","price":"8825.31000000","order_id":"65078308-e0bf-499b-b8d1-0ea44259d49d","remaining_size":"0.01322632","product_id":"BTC-EUR","sequence":3257980063,"time":"2018-01-22T15:14:49.215000Z"}
{"type":"done","side":"sell","order_id":"0a8f6108-dee3-41ab-b408-431c58db10ad","reason":"canceled","product_id":"BTC-EUR","price":"8825.33000000","remaining_size":"0.06847422","sequence":3257980064,"time":"2018-01-22T15:14:49.216000Z"}
{"type":"done","side":"sell","order_id":"de5032d8-0c19-4aa5-ba15-40c572526e33","reason":"canceled","product_id":"BTC-EUR","price":"8825.35000000","remaining_size":"0.06847422","sequence":3257980065,"time":"2018-01-22T15:14:49.217000Z"}
{"type":"done","side":"sell","order_id":"b7fc019a-06ba-4ba8-ba2e-918c2b9dd42b","reason":"canceled","product_id":"BTC-EUR","price":"8825.36000000","remaining_size":"0.06847422","sequence":3257980066,"time":"2018-01-22T15:14:49.220000Z"}
{"type":"received","order_id":"019dcf89-7df0-4f40-8ba5-975778d3f7df","order_type":"limit","size":"0.06847422","price":"8825.30000000","side":"sell","client_oid":"6295e827-51e5-408e-8106-3d48186ae5ea","product_id":"BTC-EUR","sequence":3257980067,"time":"2018-01-22T15:14:49.227000Z"}
{"type":"open","side":"sell","price":"8825.30000000","order_id":"019dcf89-7df0-4f40-8ba5-975778d3f7df","remaining_size":"0.06847422","product_id":"BTC-EUR","sequence":3257980068,"time":"2018-01-22T15:14:49.227000Z"}
{"type":"received","order_id":"12a805ce-a7ed-4a27-9eb3-589c8e6e592f","order_type":"limit","size":"0.06847422","price":"8825.31000000","side":"sell","client_oid":"619c01ae-847f-46ce-bb32-1e803b1aed24","product_id":"BTC-EUR","sequence":3257980069,"time":"2018-01-22T15:14:49.236000Z"}
{"type":"open","side":"sell","price":"8825.31000000","order_id":"12a805ce-a7ed-4a27-9eb3-589c8e6e592f","remaining_size":"0.06847422","product_id":"BTC-EUR","sequence":3257980070,"time":"2018-01-22T15:14:49.236000Z"}
{"type":"received","order_id":"85b7ecf8-8e84-4f74-9c3a-450fb58fef98","order_type":"limit","size":"0.01800000","price":"8825.30000000","side":"sell","client_oid":"bf89bcd5-ae35-4266-9153-4ee5022dc374","product_id":"BTC-EUR","sequence":3257980071,"time":"2018-01-22T15:14:49.251000Z"}
{"type":"open","side":"sell","price":"8825.30000000","order_id":"85b7ecf8-8e84-4f74-9c3a-450fb58fef98","remaining_size":"0.01800000","product_id":"BTC-EUR","sequence":3257980072,"time":"2018-01-22T15:14:49.251000Z"}
{"type":"done","side":"sell","order_id":"a7ae0171-86bb-43cd-8df2-eccb03b61d6d","reason":"canceled","product_id":"BTC-EUR","price":"8921.17000000","remaining_size":"0.06675000","sequence":3257980073,"time":"2018-01-22T15:14:49.268000Z"}
{"type":"received","order_id":"ebe3916d-1830-4eaa-8d91-21e1d484daa0","order_type":"limit","size":"0.06847422","price":"8825.30000000","side":"sell","client_oid":"b9d73cba-8eb5-4a24-9fb5-d4aa755c9525","product_id":"BTC-EUR","sequence":3257980074,"time":"2018-01-22T15:14:49.357000Z"}
{"type":"open","side":"sell","price":"8825.30000000","order_id":"ebe3916d-1830-4eaa-8d91-21e1d484daa0","remaining_size":"0.06847422","product_id":"BTC-EUR","sequence":3257980075,"time":"2018-01-22T15:14:49.357000Z"}
{"type":"received","order_id":"5befe00a-52f6-466b-bb00-1868ef6165da","order_type":"limit","size":"0.06675000","price":"8918.12000000","side":"sell","product_id":"BTC-EUR","sequence":3257980076,"time":"2018-01-22T15:14:49.384000Z"}
{"type":"open","side":"sell","price":"8918.12000000","order_id":"5befe00a-52f6-466b-bb00-1868ef6165da","remaining_size":"0.06675000","product_id":"BTC-EUR","sequence":3257980077,"time":"2018-01-22T15:14:49.384000Z"}
{"type":"received","order_id":"36aee47e-8aba-4a1b-8abe-3c59e99b9b04","order_type":"limit","size":"0.04164971","price":"8825.30000000","side":"sell","client_oid":"848655e5-1c6c-4e18-b657-9c37427dc0a2","product_id":"BTC-EUR","sequence":3257980078,"time":"2018-01-22T15:14:49.397000Z"}
{"type":"open","side":"sell","price":"8825.30000000","order_id":"36aee47e-8aba-4a1b-8abe-3c59e99b9b04","remaining_size":"0.04164971","product_id":"BTC-EUR","sequence":3257980079,"time":"2018-01-22T15:14:49.397000Z"}
{"type":"received","order_id":"67bb8006-0dd4-45b1-9280-6837b754867e","order_type":"limit","size":"0.21404538","price":"8825.30000000","side":"sell","product_id":"BTC-EUR","sequence":3257980080,"time":"2018-01-22T15:14:49.405000Z"}
{"type":"open","side":"sell","price":"8825.30000000","order_id":"67bb8006-0dd4-45b1-9280-6837b754867e","remaining_size":"0.21404538","product_id":"BTC-EUR","sequence":3257980081,"time":"2018-01-22T15:14:49.405000Z"}
{"type":"received","order_id":"cc884c8c-e301-4d6d-b2b5-0b8443b3235a","order_type":"limit","size":"0.01800000","price":"8825.30000000","side":"sell","client_oid":"d3da8a6c-df42-403d-a561-22b56925d60a","product_id":"BTC-EUR","sequence":3257980082,"time":"2018-01-22T15:14:49.448000Z"}
{"type":"open","side":"sell","price":"8825.30000000","order_id":"cc884c8c-e301-4d6d-b2b5-0b8443b3235a","remaining_size":"0.01800000","product_id":"BTC-EUR","sequence":3257980083,"time":"2018-01-22T15:14:49.448000Z"}
{"type":"received","order_id":"8c666eff-1738-4f5e-94c7-b6377b811edc","order_type":"limit","size":"0.00200000","price":"8825.30000000","side":"sell","client_oid":"be6f647e-9dbe-4a3a-9565-8c85b72660d8","product_id":"BTC-EUR","sequence":3257980084,"time":"2018-01-22T15:14:49.489000Z"}
{"type":"open","side":"sell","price":"8825.30000000","order_id":"8c666eff-1738-4f5e-94c7-b6377b811edc","remaining_size":"0.00200000","product_id":"BTC-EUR","sequence":3257980085,"time":"2018-01-22T15:14:49.489000Z"}
{"type":"received","order_id":"24c8140b-4374-4aeb-b42e-e22b11090643","order_type":"limit","size":"0.04600000","price":"8825.30000000","side":"sell","client_oid":"3b5fbea6-eeaa-4d82-baf4-6d0a1fa31357","product_id":"BTC-EUR","sequence":3257980086,"time":"2018-01-22T15:14:49.493000Z"}
{"type":"open","side":"sell","price":"8825.30000000","order_id":"24c8140b-4374-4aeb-b42e-e22b11090643","remaining_size":"0.04600000","product_id":"BTC-EUR","sequence":3257980087,"time":"2018-01-22T15:14:49.493000Z"}
{"type":"received","order_id":"61edf8b3-51d7-4b73-81e5-137ba4ea9995","order_type":"limit","size":"0.01000000","price":"14500.00000000","side":"sell","client_oid":"366b2338-f35e-4800-c944-b4662f6a1980","product_id":"BTC-EUR","sequence":3257980088,"time":"2018-01-22T15:14:49.520000Z"}
{"type":"open","side":"sell","price":"14500.00000000","order_id":"61edf8b3-51d7-4b73-81e5-137ba4ea9995","remaining_size":"0.01000000","product_id":"BTC-EUR","sequence":3257980089,"time":"2018-01-22T15:14:49.520000Z"}
{"type":"received","order_id":"c969fef6-09c7-44ce-9b49-68f2e9835cb3","order_type":"limit","size":"0.00552100","price":"8825.30000000","side":"sell","product_id":"BTC-EUR","sequence":3257980090,"time":"2018-01-22T15:14:49.558000Z"}
{"type":"open","side":"sell","price":"8825.30000000","order_id":"c969fef6-09c7-44ce-9b49-68f2e9835cb3","remaining_size":"0.00552100","product_id":"BTC-EUR","sequence":3257980091,"time":"2018-01-22T15:14:49.558000Z"}
{"type":"received","order_id":"29570106-076c-4c25-a276-e7b4437bb8a1","order_type":"limit","size":"0.01285806","price":"8792.70000000","side":"buy","client_oid":"9e3faf0e-34f4-4fb2-b9c0-1c6438ca4c4a","product_id":"BTC-EUR","sequence":3257980092,"time":"2018-01-22T15:14:49.737000Z"}
{"type":"open","side":"buy","price":"8792.70000000","order_id":"29570106-076c-4c25-a276-e7b4437bb8a1","remaining_size":"0.01285806","product_id":"BTC-EUR","sequence":3257980093,"time":"2018-01-22T15:14:49.737000Z"}
{"type":"received","order_id":"a032477f-b3fd-4b2d-95ff-535f44ff8e4a","order_type":"limit","size":"0.20063838","price":"8882.47000000","side":"sell","client_oid":"c9e3ce96-100f-411c-b9c6-c2d63f5bf5c1","product_id":"BTC-EUR","sequence":3257980094,"time":"2018-01-22T15:14:49.740000Z"}
{"type":"open","side":"sell","price":"8882.47000000","order_id":"a032477f-b3fd-4b2d-95ff-535f44ff8e4a","remaining_size":"0.20063838","product_id":"BTC-EUR","sequence":3257980095,"time":"2018-01-22T15:14:49.740000Z"}
{"type":"received","order_id":"a16dd4c9-81a3-407d-b030-250b6b88d7b4","order_type":"limit","size":"0.20063838","price":"8870.68000000","side":"sell","client_oid":"fbfaf2d2-4219-4cab-aa57-f058fb03e2c3","product_id":"BTC-EUR","sequence":3257980096,"time":"2018-01-22T15:14:49.762000Z"}
{"type":"open","side":"sell","price":"8870.68000000","order_id":"a16dd4c9-81a3-407d-b030-250b6b88d7b4","remaining_size":"0.20063838","product_id":"BTC-EUR","sequence":3257980097,"time":"2018-01-22T15:14:49.762000Z"}
{"type":"done","side":"sell","order_id":"e9220f80-8639-4028-92d1-05f8934c0a38","reason":"canceled","product_id":"BTC-EUR","price":"8825.36000000","remaining_size":"0.00564464","sequence":3257980098,"time":"2018-01-22T15:14:49.771000Z"}
{"type":"received","order_id":"4c06cfed-ed3b-4215-823e-424ad2bce9b5","order_type":"limit","size":"0.20063838","price":"8894.26000000","side":"sell","client_oid":"74808d06-f26e-4637-9c2c-1617e881cac6","product_id":"BTC-EUR","sequence":3257980099,"time":"2018-01-22T15:14:49.790000Z"}
{"type":"open","side":"sell","price":"8894.26000000","order_id":"4c06cfed-ed3b-4215-823e-424ad2bce9b5","remaining_size":"0.20063838","product_id":"BTC-EUR","sequence":3257980100,"time":"2018-01-22T15:14:49.790000Z"}
{"type":"received","order_id":"f9d16169-47ec-478b-9d55-45e812533884","order_type":"limit","size":"0.20063838","price":"8906.05000000","side":"sell","client_oid":"92984a13-4d81-43c4-8a3c-c3bd224dcbab","product_id":"BTC-EUR","sequence":3257980101,"time":"2018-01-22T15:14:49.791000Z"}
{"type":"open","side":"sell","price":"8906.05000000","order_id":"f9d16169-47ec-478b-9d55-45e812533884","remaining_size":"0.20063838","product_id":"BTC-EUR","sequence":3257980102,"time":"2018-01-22T15:14:49.791000Z"}
{"type":"received","order_id":"8e50fcd2-3c18-4513-b28e-cee603912164","order_type":"limit","size":"0.01285806","price":"8748.67000000","side":"buy","client_oid":"1c9ee187-c723-4cb7-ad7d-296623d8a155","product_id":"BTC-EUR","sequence":3257980103,"time":"2018-01-22T15:14:49.792000Z"}
{"type":"open","side":"buy","price":"8748.67000000","order_id":"8e50fcd2-3c18-4513-b28e-cee603912164","remaining_size":"0.01285806","product_id":"BTC-EUR","sequence":3257980104,"time":"2018-01-22T15:14:49.792000Z"}
{"type":"received","order_id":"16503fcf-9117-44dd-8522-69d017cbc4e1","order_type":"limit","size":"0.20063838","price":"8917.84000000","side":"sell","client_oid":"57ee80fa-07a1-41a3-ae45-292480a93676","product_id":"BTC-EUR","sequence":3257980105,"time":"2018-01-22T15:14:49.803000Z"}
{"type":"open","side":"sell","price":"8917.84000000","order_id":"16503fcf-9117-44dd-8522-69d017cbc4e1","remaining_size":"0.20063838","product_id":"BTC-EUR","sequence":3257980106,"time":"2018-01-22T15:14:49.803000Z"}
{"type":"received","order_id":"bd7ca5a5-8692-4ceb-a963-9e5573003784","order_type":"limit","size":"0.01285806","price":"8704.07000000","side":"buy","client_oid":"b5a0a9d8-9c99-46b4-b106-83602ab437bb","product_id":"BTC-EUR","sequence":3257980107,"time":"2018-01-22T15:14:49.815000Z"}
{"type":"open","side":"buy","price":"8704.07000000","order_id":"bd7ca5a5-8692-4ceb-a963-9e5573003784","remaining_size":"0.01285806","product_id":"BTC-EUR","sequence":3257980108,"time":"2018-01-22T15:14:49.815000Z"}
{"type":"received","order_id":"0a1ad831-1baf-4f80-9f71-acccf59f7764","order_type":"limit","size":"0.01285807","price":"8659.75000000","side":"buy","client_oid":"a8a9a48b-5779-4ed0-969c-958245b115d8","product_id":"BTC-EUR","sequence":3257980109,"time":"2018-01-22T15:14:49.825000Z"}
{"type":"open","side":"buy","price":"8659.75000000","order_id":"0a1ad831-1baf-4f80-9f71-acccf59f7764","remaining_size":"0.01285807","product_id":"BTC-EUR","sequence":3257980110,"time":"2018-01-22T15:14:49.825000Z"}
{"type":"received","order_id":"c176d25c-d42b-487a-9765-eb0dfa17db2e","order_type":"limit","size":"0.03773580","price":"8866.29000000","side":"sell","client_oid":"61f91586-a89d-4ef9-a786-d2a2f4063904","product_id":"BTC-EUR","sequence":3257980111,"time":"2018-01-22T15:14:49.838000Z"}
{"type":"open","side":"sell","price":"8866.29000000","order_id":"c176d25c-d42b-487a-9765-eb0dfa17db2e","remaining_size":"0.03773580","product_id":"BTC-EUR","sequence":3257980112,"time":"2018-01-22T15:14:49.838000Z"}
{"type":"done","side":"sell","order_id":"4cb0dcfe-626f-4a18-bf23-530ebf3bed94","reason":"canceled","product_id":"BTC-EUR","price":"8825.31000000","remaining_size":"0.22947933","sequence":3257980113,"time":"2018-01-22T15:14:49.838000Z"}
{"type":"received","order_id":"bd39cd7d-76d0-4156-9d8d-4ba3f752b0bd","order_type":"limit","size":"0.03773580","price":"8877.40000000","side":"sell","client_oid":"c7dd53a0-5748-48b6-b92a-b3a7129fc026","product_id":"BTC-EUR","sequence":3257980114,"time":"2018-01-22T15:14:49.847000Z"}
{"type":"open","side":"sell","price":"8877.40000000","order_id":"bd39cd7d-76d0-4156-9d8d-4ba3f752b0bd","remaining_size":"0.03773580","product_id":"BTC-EUR","sequence":3257980115,"time":"2018-01-22T15:14:49.847000Z"}
{"type":"done","side":"sell","order_id":"65078308-e0bf-499b-b8d1-0ea44259d49d","reason":"canceled","product_id":"BTC-EUR","price":"8825.31000000","remaining_size":"0.01322632","sequence":3257980116,"time":"2018-01-22T15:14:49.926000Z"}
{"type":"received","order_id":"f240c11e-3602-4d64-b849-8f63e47995d6","order_type":"market","size":"0.01213165","side":"sell","client_oid":"200c2df2-7c63-4992-e3db-b085d6ce0b1a","product_id":"BTC-EUR","sequence":3257980117,"time":"2018-01-22T15:14:49.933000Z"}
{"type":"match","trade_id":10551379,"maker_order_id":"c653e361-6d4d-4fb7-8d37-4e362a65e7b3","taker_order_id":"f240c11e-3602-4d64-b849-8f63e47995d6","side":"buy","size":"0.01213165","price":"8825.29000000","product_id":"BTC-EUR","sequence":3257980118,"time":"2018-01-22T15:14:49.933000Z"}
{"type":"done","side":"sell","order_id":"f240c11e-3602-4d64-b849-8f63e47995d6","reason":"filled","product_id":"BTC-EUR","remaining_size":"0.00000000","sequence":3257980119,"time":"2018-01-22T15:14:49.933000Z"}
{"type":"received","order_id":"b2daee57-9a2f-4bae-a95b-ece57040267c","order_type":"limit","size":"0.08800000","price":"8825.30000000","side":"sell","client_oid":"fbf08a14-ab30-4c49-824b-314b3511cc5d","product_id":"BTC-EUR","sequence":3257980120,"time":"2018-01-22T15:14:49.948000Z"}
{"type":"open","side":"sell","price":"8825.30000000","order_id":"b2daee57-9a2f-4bae-a95b-ece57040267c","remaining_size":"0.08800000","product_id":"BTC-EUR","sequence":3257980121,"time":"2018-01-22T15:14:49.948000Z"}
{"type":"received","order_id":"f4460fb6-295f-40f2-bc7f-b3b560e41494","order_type":"limit","size":"0.08800000","price":"8825.30000000","side":"sell","client_oid":"5d3f6964-86a3-4e38-95ac-8b1df79d78d3","product_id":"BTC-EUR","sequence":3257980122,"time":"2018-01-22T15:14:49.955000Z"}
{"type":"open","side":"sell","price":"8825.30000000","order_id":"f4460fb6-295f-40f2-bc7f-b3b560e41494","remaining_size":"0.08800000","product_id":"BTC-EUR","sequence":3257980123,"time":"2018-01-22T15:14:49.955000Z"}
{"type":"received","order_id":"c4624ca4-ea00-4dd2-add5-4fd6b9298c94","order_type":"limit","size":"0.00600000","price":"8825.30000000","side":"sell","client_oid":"d897823d-f912-4ec2-b935-7ef6c7f7d63f","product_id":"BTC-EUR","sequence":3257980124,"time":"2018-01-22T15:14:49.964000Z"}
{"type":"open","side":"sell","price":"8825.30000000","order_id":"c4624ca4-ea00-4dd2-add5-4fd6b9298c94","remaining_size":"0.00600000","product_id":"BTC-EUR","sequence":3257980125,"time":"2018-01-22T15:14:49.964000Z"}
{"type":"received","order_id":"7a9bd4e0-38cc-4b10-b7e2-72ec53143c09","order_type":"limit","size":"0.00564464","price":"8825.30000000","side":"sell","client_oid":"5d594668-0bbc-49a9-b7e3-3a5345ba36e1","product_id":"BTC-EUR","sequence":3257980126,"time":"2018-01-22T15:14:49.997000Z"}
{"type":"open","side":"sell","price":"8825.30000000","order_id":"7a9bd4e0-38cc-4b10-b7e2-72ec53143c09","remaining_size":"0.00564464","product_id":"BTC-EUR","sequence":3257980127,"time":"2018-01-22T15:14:49.997000Z"}
{"type":"received","order_id":"35ee91af-f42f-4982-85c5-48162df89ecd","order_type":"limit","size":"0.22947933","price":"8825.30000000","side":"sell","client_oid":"76be3367-9a9f-43d3-998a-0787aa698f97","product_id":"BTC-EUR","sequence":3257980128,"time":"2018-01-22T15:14:50.062000Z"}
{"type":"open","side":"sell","price":"8825.30000000","order_id":"35ee91af-f42f-4982-85c5-48162df89ecd","remaining_size":"0.22947933","product_id":"BTC-EUR","sequence":3257980129,"time":"2018-01-22T15:14:50.062000Z"}
{"type":"received","order_id":"17d39c42-d07b-4e36-809c-f8163d1c7e31","order_type":"limit","size":"0.00160300","price":"8825.30000000","side":"sell","product_id":"BTC-EUR","sequence":3257980130,"time":"2018-01-22T15:14:50.104000Z"}
{"type":"open","side":"sell","price":"8825.30000000","order_id":"17d39c42-d07b-4e36-809c-f8163d1c7e31","remaining_size":"0.00160300","product_id":"BTC-EUR","sequence":3257980131,"time":"2018-01-22T15:14:50.104000Z"}
{"type":"received","order_id":"a4ce4460-a79d-4b21-98a7-fe461ed59dfc","order_type":"limit","size":"0.01322632","price":"8825.30000000","side":"sell","client_oid":"0c7e71be-085a-474a-abb6-4cb619990e2b","product_id":"BTC-EUR","sequence":3257980132,"time":"2018-01-22T15:14:50.146000Z"}
{"type":"open","side":"sell","price":"8825.30000000","order_id":"a4ce4460-a79d-4b21-98a7-fe461ed59dfc","remaining_size":"0.01322632","product_id":"BTC-EUR","sequence":3257980133,"time":"2018-01-22T15:14:50.146000Z"}
{"type":"received","order_id":"47cd627d-5c76-4ad3-b81f-bd5eb473abb5","order_type":"limit","size":"0.11066184","price":"8826.71000000","side":"sell","client_oid":"1b4d9b04-2d49-42bd-f679-a35e86bd82dc","product_id":"BTC-EUR","sequence":3257980134,"time":"2018-01-22T15:14:50.515000Z"}
{"type":"open","side":"sell","price":"8826.71000000","order_id":"47cd627d-5c76-4ad3-b81f-bd5eb473abb5","remaining_size":"0.11066184","product_id":"BTC-EUR","sequence":3257980135,"time":"2018-01-22T15:14:50.515000Z"}
{"type":"done","side":"sell","order_id":"2e1401eb-6de2-48df-b84d-b1cf2dc40da5","reason":"canceled","product_id":"BTC-EUR","price":"9110.22000000","remaining_size":"1.28000000","sequence":3257980136,"time":"2018-01-22T15:14:50.608000Z"}
{"type":"done","side":"buy","order_id":"3d68ed54-d6b0-4215-82ee-43c3b043f744","reason":"canceled","product_id":"BTC-EUR","price":"8813.52000000","remaining_size":"0.18533105","sequence":3257980137,"time":"2018-01-22T15:14:50.730000Z"}
{"type":"received","order_id":"58ac1e09-a559-4ab2-9216-66cccbfadcf2","order_type":"limit","size":"0.29000000","price":"8825.30000000","side":"sell","client_oid":"e65fb021-d12c-4b6a-f4a6-d9a579f82e31","product_id":"BTC-EUR","sequence":3257980138,"time":"2018-01-22T15:14:50.808000Z"}
{"type":"open","side":"sell","price":"8825.30000000","order_id":"58ac1e09-a559-4ab2-9216-66cccbfadcf2","remaining_size":"0.29000000","product_id":"BTC-EUR","sequence":3257980139,"time":"2018-01-22T15:14:50.808000Z"}
{"type":"done","side":"sell","order_id":"5befe00a-52f6-466b-bb00-1868ef6165da","reason":"canceled","product_id":"BTC-EUR","price":"8918.12000000","remaining_size":"0.06675000","sequence":3257980140,"time":"2018-01-22T15:14:50.938000Z"}
{"type":"received","order_id":"0eee83c5-dc52-4062-ac37-ff47cd8e1b40","order_type":"limit","size":"0.18556318","price":"8802.50000000","side":"buy","client_oid":"e83d3aed-2226-41a6-8255-902b18697d7f","product_id":"BTC-EUR","sequence":3257980141,"time":"2018-01-22T15:14:50.978000Z"}
{"type":"open","side":"buy","price":"8802.50000000","order_id":"0eee83c5-dc52-4062-ac37-ff47cd8e1b40","remaining_size":"0.18556318","product_id":"BTC-EUR","sequence":3257980142,"time":"2018-01-22T15:14:50.978000Z"}
{"type":"received","order_id":"a5c4fcae-f754-4bed-8b3e-d3d3c1d8f8d8","order_type":"limit","size":"0.06675000","price":"8917.84000000","side":"sell","product_id":"BTC-EUR","sequence":3257980143,"time":"2018-01-22T15:14:51.087000Z"}
{"type":"open","side":"sell","price":"8917.84000000","order_id":"a5c4fcae-f754-4bed-8b3e-d3d3c1d8f8d8","remaining_size":"0.06675000","product_id":"BTC-EUR","sequence":3257980144,"time":"2018-01-22T15:14:51.087000Z"}
{"type":"done","side":"sell","order_id":"1ab6a8e1-cf19-4970-ac2f-732721d40b29","reason":"canceled","product_id":"BTC-EUR","price":"8850.28000000","remaining_size":"0.46140359","sequence":3257980145,"time":"2018-01-22T15:14:51.547000Z"}
{"type":"done","side":"sell","order_id":"58301ab5-45a7-4211-b20f-b9f349ee7df7","reason":"canceled","product_id":"BTC-EUR","price":"8849.05000000","remaining_size":"0.18458699","sequence":3257980146,"time":"2018-01-22T15:14:51.552000Z"}
{"type":"done","side":"buy","order_id":"0eee83c5-dc52-4062-ac37-ff47cd8e1b40","reason":"canceled","product_id":"BTC-EUR","price":"8802.50000000","remaining_size":"0.18556318","sequence":3257980147,"time":"2018-01-22T15:14:51.659000Z"}
{"type":"received","order_id":"0916641b-28f6-4645-9b2e-23040168f85c","order_type":"limit","size":"0.46193644","price":"8840.07000000","side":"sell","client_oid":"08f3e5aa-06e7-4cdb-b528-fdfe592e4722","product_id":"BTC-EUR","sequence":3257980148,"time":"2018-01-22T15:14:51.834000Z"}
{"type":"open","side":"sell","price":"8840.07000000","order_id":"0916641b-28f6-4645-9b2e-23040168f85c","remaining_size":"0.46193644","product_id":"BTC-EUR","sequence":3257980149,"time":"2018-01-22T15:14:51.834000Z"}
{"type":"received","order_id":"d42c938c-b2a9-4ff2-8867-d8b9b1a8d1c2","order_type":"limit","size":"0.22797000","price":"8825.30000000","side":"sell","product_id":"BTC-EUR","sequence":3257980150,"time":"2018-01-22T15:14:51.892000Z"}
{"type":"open","side":"sell","price":"8825.30000000","order_id":"d42c938c-b2a9-4ff2-8867-d8b9b1a8d1c2","remaining_size":"0.22797000","product_id":"BTC-EUR","sequence":3257980151,"time":"2018-01-22T15:14:51.892000Z"}
{"type":"received","order_id":"986d95f9-981d-4ab2-a3ae-db1d62cf6652","order_type":"limit","size":"0.18491124","price":"8833.53000000","side":"sell","client_oid":"b12bc6f7-a39e-4ede-8ede-fbc03e35d4b2","product_id":"BTC-EUR","sequence":3257980152,"time":"2018-01-22T15:14:51.909000Z"}
{"type":"open","side":"sell","price":"8833.53000000","order_id":"986d95f9-981d-4ab2-a3ae-db1d62cf6652","remaining_size":"0.18491124","product_id":"BTC-EUR","sequence":3257980153,"time":"2018-01-22T15:14:51.909000Z"}
{"type":"received","order_id":"8374f513-b8aa-4db9-900b-42e4352e0fef","order_type":"limit","size":"0.18563208","price":"8799.23000000","side":"buy","client_oid":"c1864506-f73d-4a2b-8091-77ae79f3286f","product_id":"BTC-EUR","sequence":3257980154,"time":"2018-01-22T15:14:51.914000Z"}
{"type":"open","side":"buy","price":"8799.23000000","order_id":"8374f513-b8aa-4db9-900b-42e4352e0fef","remaining_size":"0.18563208","product_id":"BTC-EUR","sequence":3257980155,"time":"2018-01-22T15:14:51.914000Z"}
{"type":"received","order_id":"cfd0dba1-ea43-4da9-8055-89682de8d27e","order_type":"limit","size":"0.67203000","price":"8825.30000000","side":"sell","product_id":"BTC-EUR","sequence":3257980156,"time":"2018-01-22T15:14:51.991000Z"}
{"type":"open","side":"sell","price":"8825.30000000","order_id":"cfd0dba1-ea43-4da9-8055-89682de8d27e","remaining_size":"0.67203000","product_id":"BTC-EUR","sequence":3257980157,"time":"2018-01-22T15:14:51.991000Z"}
{"type":"received","order_id":"f88a1c30-107a-480a-baee-8282686d03bf","order_type":"limit","size":"1.28000000","price":"9106.95000000","side":"sell","product_id":"BTC-EUR","sequence":3257980158,"time":"2018-01-22T15:14:52.094000Z"}
{"type":"open","side":"sell","price":"9106.95000000","order_id":"f88a1c30-107a-480a-baee-8282686d03bf","remaining_size":"1.28000000","product_id":"BTC-EUR","sequence":3257980159,"time":"2018-01-22T15:14:52.094000Z"}
{"type":"received","order_id":"78dcd80c-8bfa-4a49-b54b-f1930b4b65ae","order_type":"limit","size":"0.00163571","price":"9100.00000000","side":"sell","client_oid":"1a56fcf8-45f0-4016-de57-86f859212baf","product_id":"BTC-EUR","sequence":3257980160,"time":"2018-01-22T15:14:52.413000Z"}
{"type":"open","side":"sell","price":"9100.00000000","order_id":"78dcd80c-8bfa-4a49-b54b-f1930b4b65ae","remaining_size":"0.00163571","product_id":"BTC-EUR","sequence":3257980161,"time":"2018-01-22T15:14:52.413000Z"}
{"type":"received","order_id":"7a9bee82-adc5-4581-81fb-f0d670be69ed","order_type":"limit","size":"0.60315201","price":"8825.30000000","side":"sell","client_oid":"2a0dce98-2d20-430f-db85-441a7500b675","product_id":"BTC-EUR","sequence":3257980162,"time":"2018-01-22T15:14:52.989000Z"}
{"type":"open","side":"sell","price":"8825.30000000","order_id":"7a9bee82-adc5-4581-81fb-f0d670be69ed","remaining_size":"0.60315201","product_id":"BTC-EUR","sequence":3257980163,"time":"2018-01-22T15:14:52.989000Z"}
{"type":"received","order_id":"2d59fba1-9a1b-45f9-b73f-7d7996db22f8","order_type":"limit","size":"0.00370350","price":"8849.00000000","side":"sell","client_oid":"2552c875-8046-4744-8b28-5e0c1931acd6","product_id":"BTC-EUR","sequence":3257980164,"time":"2018-01-22T15:14:53.292000Z"}
{"type":"open","side":"sell","price":"8849.00000000","order_id":"2d59fba1-9a1b-45f9-b73f-7d7996db22f8","remaining_size":"0.00370350","product_id":"BTC-EUR","sequence":3257980165,"time":"2018-01-22T15:14:53.292000Z"}
{"type":"done","side":"buy","order_id":"8237cc3c-ff83-4f76-b2ca-ec6ea4c2a9eb","reason":"canceled","product_id":"BTC-EUR","price":"8799.23000000","remaining_size":"0.20699000","sequence":3257980166,"time":"2018-01-22T15:14:53.325000Z"}
{"type":"received","order_id":"6d4050d6-a896-479b-ba0b-399d1902c672","order_type":"limit","size":"0.01000000","price":"9090.05000000","side":"buy","product_id":"BTC-EUR","sequence":3257980167,"time":"2018-01-22T15:14:53.380000Z"}
{"type":"match","trade_id":10551380,"maker_order_id":"9763ce66-f17f-4eb0-8189-1f997f244aa1","taker_order_id":"6d4050d6-a896-479b-ba0b-399d1902c672","side":"sell","size":"0.01000000","price":"8825.30000000","product_id":"BTC-EUR","sequence":3257980168,"time":"2018-01-22T15:14:53.380000Z"}
{"type":"done","side":"buy","order_id":"6d4050d6-a896-479b-ba0b-399d1902c672","reason":"filled","product_id":"BTC-EUR","price":"9090.05000000","remaining_size":"0.00000000","sequence":3257980169,"time":"2018-01-22T15:14:53.380000Z"}
{"type":"done","side":"buy","order_id":"728816b2-57c6-44f7-8ba3-e87ae1726465","reason":"canceled","product_id":"BTC-EUR","price":"8823.40000000","remaining_size":"0.04257882","sequence":3257980170,"time":"2018-01-22T15:14:53.766000Z"}
{"type":"received","order_id":"6da3ded3-35e7-4754-b444-e0cbccebc7b1","order_type":"limit","size":"0.20692000","price":"8802.08000000","side":"buy","product_id":"BTC-EUR","sequence":3257980171,"time":"2018-01-22T15:14:53.857000Z"}
{"type":"open","side":"buy","price":"8802.08000000","order_id":"6da3ded3-35e7-4754-b444-e0cbccebc7b1","remaining_size":"0.20692000","product_id":"BTC-EUR","sequence":3257980172,"time":"2018-01-22T15:14:53.857000Z"}
{"type":"done","side":"sell","order_id":"dc8e6d82-b9c7-49e0-aec2-5f54974a08d6","reason":"canceled","product_id":"BTC-EUR","price":"8825.64000000","remaining_size":"0.02754471","sequence":3257980173,"time":"2018-01-22T15:14:53.921000Z"}
{"type":"received","order_id":"4f4238d6-7526-4c8b-8fa4-1ac584c857e8","order_type":"limit","size":"0.02754489","price":"8825.30000000","side":"sell","product_id":"BTC-EUR","sequence":3257980174,"time":"2018-01-22T15:14:54.018000Z"}
{"type":"open","side":"sell","price":"8825.30000000","order_id":"4f4238d6-7526-4c8b-8fa4-1ac584c857e8","remaining_size":"0.02754489","product_id":"BTC-EUR","sequence":3257980175,"time":"2018-01-22T15:14:54.018000Z"}
{"type":"received","order_id":"5634a183-605a-49f7-b38f-ca80a4ce610f","order_type":"limit","size":"0.05000000","price":"9090.05000000","side":"buy","product_id":"BTC-EUR","sequence":3257980176,"time":"2018-01-22T15:14:54.031000Z"}
{"type":"match","trade_id":10551381,"maker_order_id":"9763ce66-f17f-4eb0-8189-1f997f244aa1","taker_order_id":"5634a183-605a-49f7-b38f-ca80a4ce610f","side":"sell","size":"0.05000000","price":"8825.30000000","product_id":"BTC-EUR","sequence":3257980177,"time":"2018-01-22T15:14:54.031000Z"}
{"type":"done","side":"buy","order_id":"5634a183-605a-49f7-b38f-ca80a4ce610f","reason":"filled","product_id":"BTC-EUR","price":"9090.05000000","remaining_size":"0.00000000","sequence":3257980178,"time":"2018-01-22T15:14:54.031000Z"}
{"type":"received","order_id":"e419a4f8-8611-4f6f-99a6-7c3de6255bfb","order_type":"limit","size":"0.05000000","price":"9090.06000000","side":"buy","product_id":"BTC-EUR","sequence":3257980179,"time":"2018-01-22T15:14:54.190000Z"}
{"type":"match","trade_id":10551382,"maker_order_id":"9763ce66-f17f-4eb0-8189-1f997f244aa1","taker_order_id":"e419a4f8-8611-4f6f-99a6-7c3de6255bfb","side":"sell","size":"0.02500000","price":"8825.30000000","product_id":"BTC-EUR","sequence":3257980180,"time":"2018-01-22T15:14:54.190000Z"}
{"type":"done","side":"sell","order_id":"9763ce66-f17f-4eb0-8189-1f997f244aa1","reason":"filled","product_id":"BTC-EUR","price":"8825.30000000","remaining_size":"0","sequence":3257980181,"time":"2018-01-22T15:14:54.190000Z"}
{"type":"match","trade_id":10551383,"maker_order_id":"f2c8bf21-05b3-44ee-99c5-e35efe391c9d","taker_order_id":"e419a4f8-8611-4f6f-99a6-7c3de6255bfb","side":"sell","size":"0.02500000","price":"8825.30000000","product_id":"BTC-EUR","sequence":3257980182,"time":"2018-01-22T15:14:54.190000Z"}
{"type":"done","side":"buy","order_id":"e419a4f8-8611-4f6f-99a6-7c3de6255bfb","reason":"filled","product_id":"BTC-EUR","price":"9090.06000000","remaining_size":"0.00000000","sequence":3257980183,"time":"2018-01-22T15:14:54.190000Z"}
{"type":"done","side":"sell","order_id":"ca75bf31-e472-4459-9e31-a5f7bc5ba705","reason":"canceled","product_id":"BTC-EUR","price":"9177.69000000","remaining_size":"0.00367246","sequence":3257980184,"time":"2018-01-22T15:14:54.209000Z"}
{"type":"received","order_id":"f5468e4c-096a-4940-9645-64648033940c","order_type":"limit","size":"0.00367253","price":"9175.36000000","side":"sell","client_oid":"88f37dea-f4b8-4c94-8000-005b9a553840","product_id":"BTC-EUR","sequence":3257980185,"time":"2018-01-22T15:14:54.220000Z"}
{"type":"open","side":"sell","price":"9175.36000000","order_id":"f5468e4c-096a-4940-9645-64648033940c","remaining_size":"0.00367253","product_id":"BTC-EUR","sequence":3257980186,"time":"2018-01-22T15:14:54.220000Z"}
{"type":"done","side":"buy","order_id":"6da3ded3-35e7-4754-b444-e0cbccebc7b1","reason":"canceled","product_id":"BTC-EUR","price":"8802.08000000","remaining_size":"0.20692000","sequence":3257980187,"time":"2018-01-22T15:14:54.420000Z"}
{"type":"received","order_id":"fe9fbdf0-d63a-4b06-8e3b-ea91c30b50d6","order_type":"market","size":"0.18794594","side":"sell","client_oid":"72bba558-fd47-4cf6-f8ae-aeb4729e8984","product_id":"BTC-EUR","sequence":3257980188,"time":"2018-01-22T15:14:54.564000Z"}
{"type":"match","trade_id":10551384,"maker_order_id":"c653e361-6d4d-4fb7-8d37-4e362a65e7b3","taker_order_id":"fe9fbdf0-d63a-4b06-8e3b-ea91c30b50d6","side":"buy","size":"0.18794594","price":"8825.29000000","product_id":"BTC-EUR","sequence":3257980189,"time":"2018-01-22T15:14:54.564000Z"}
{"type":"done","side":"sell","order_id":"fe9fbdf0-d63a-4b06-8e3b-ea91c30b50d6","reason":"filled","product_id":"BTC-EUR","remaining_size":"0.00000000","sequence":3257980190,"time":"2018-01-22T15:14:54.564000Z"}
{"type":"done","side":"sell","order_id":"f88a1c30-107a-480a-baee-8282686d03bf","reason":"canceled","product_id":"BTC-EUR","price":"9106.95000000","remaining_size":"1.28000000","sequence":3257980191,"time":"2018-01-22T15:14:54.600000Z"}
{"type":"received","order_id":"e05e0678-41bd-41a6-8f3b-7bc6aecc42e2","order_type":"limit","size":"0.02000000","price":"9090.05000000","side":"buy","product_id":"BTC-EUR","sequence":3257980192,"time":"2018-01-22T15:14:54.615000Z"}
{"type":"match","trade_id":10551385,"maker_order_id":"f2c8bf21-05b3-44ee-99c5-e35efe391c9d","taker_order_id":"e05e0678-41bd-41a6-8f3b-7bc6aecc42e2","side":"sell","size":"0.02000000","price":"8825.30000000","product_id":"BTC-EUR","sequence":3257980193,"time":"2018-01-22T15:14:54.615000Z"}
{"type":"done","side":"buy","order_id":"e05e0678-41bd-41a6-8f3b-7bc6aecc42e2","reason":"filled","product_id":"BTC-EUR","price":"9090.05000000","remaining_size":"0.00000000","sequence":3257980194,"time":"2018-01-22T15:14:54.615000Z"}
{"type":"received","order_id":"3ea2d4d7-ddc2-4825-bd4e-3794a6fad4b6","order_type":"limit","size":"0.20686000","price":"8804.95000000","side":"buy","product_id":"BTC-EUR","sequence":3257980195,"time":"2018-01-22T15:14:54.682000Z"}
{"type":"open","side":"buy","price":"8804.95000000","order_id":"3ea2d4d7-ddc2-4825-bd4e-3794a6fad4b6","remaining_size":"0.20686000","product_id":"BTC-EUR","sequence":3257980196,"time":"2018-01-22T15:14:54.682000Z"}
{"type":"done","side":"sell","order_id":"7af705df-8498-46c8-bc5a-a8d4bead465a","reason":"canceled","product_id":"BTC-EUR","price":"8991.46000000","remaining_size":"1.05000000","sequence":3257980197,"time":"2018-01-22T15:14:54.727000Z"}
{"type":"received","order_id":"c5914c55-d4ae-4d5e-8b32-80f5b5fe341a","order_type":"market","size":"0.17797448","side":"sell","client_oid":"38f3c472-8f9d-450d-9c81-a324052c830b","product_id":"BTC-EUR","sequence":3257980198,"time":"2018-01-22T15:14:54.817000Z"}
{"type":"match","trade_id":10551386,"maker_order_id":"c653e361-6d4d-4fb7-8d37-4e362a65e7b3","taker_order_id":"c5914c55-d4ae-4d5e-8b32-80f5b5fe341a","side":"buy","size":"0.14991498","price":"8825.29000000","product_id":"BTC-EUR","sequence":3257980199,"time":"2018-01-22T15:14:54.817000Z"}
{"type":"done","side":"buy","order_id":"c653e361-6d4d-4fb7-8d37-4e362a65e7b3","reason":"filled","product_id":"BTC-EUR","price":"8825.29000000","remaining_size":"0.00000000","sequence":3257980200,"time":"2018-01-22T15:14:54.817000Z"}
{"type":"match","trade_id":10551387,"maker_order_id":"87218abe-3b14-4fd2-8e8c-7ef59b96eca8","taker_order_id":"c5914c55-d4ae-4d5e-8b32-80f5b5fe341a","side":"buy","size":"0.02805950","price":"8816.00000000","product_id":"BTC-EUR","sequence":3257980201,"time":"2018-01-22T15:14:54.817000Z"}
{"type":"done","side":"sell","order_id":"c5914c55-d4ae-4d5e-8b32-80f5b5fe341a","reason":"filled","product_id":"BTC-EUR","remaining_size":"0.00000000","sequence":3257980202,"time":"2018-01-22T15:14:54.817000Z"}
{"type":"received","order_id":"258e5c8e-6739-47df-ae86-75f34c34d97b","order_type":"limit","size":"0.03677774","price":"8816.01000000","side":"buy","client_oid":"2fbcae53-d36a-4009-997d-ca0b05cc4990","product_id":"BTC-EUR","sequence":3257980203,"time":"2018-01-22T15:14:54.830000Z"}
{"type":"open","side":"buy","price":"8816.01000000","order_id":"258e5c8e-6739-47df-ae86-75f34c34d97b","remaining_size":"0.03677774","product_id":"BTC-EUR","sequence":3257980204,"time":"2018-01-22T15:14:54.830000Z"}
{"type":"done","side":"sell","order_id":"62e5793d-043e-4025-bf96-b7247646d20a","reason":"canceled","product_id":"BTC-EUR","price":"9110.00000000","remaining_size":"0.32800000","sequence":3257980205,"time":"2018-01-22T15:14:54.847000Z"}
