{"type":"open","side":"sell","price":"9502.89000000","order_id":"aad2cfb4-3ea4-440e-ab5f-420466038929","remaining_size":"0.75000000","product_id":"BTC-EUR","sequence":3257978565,"time":"2018-01-22T15:14:41.781000Z"}
{"type":"done","side":"sell","order_id":"5e51d510-456a-43a4-b34f-0be8c089ffe3","reason":"canceled","product_id":"BTC-EUR","price":"8828.35000000","remaining_size":"0.01800000","sequence":3257978566,"time":"2018-01-22T15:14:41.788000Z"}
{"type":"done","side":"sell","order_id":"1f286587-4cee-4008-a1d0-98f6e54779c6","reason":"canceled","product_id":"BTC-EUR","price":"8828.35000000","remaining_size":"0.09200000","sequence":3257978567,"time":"2018-01-22T15:14:41.801000Z"}
{"type":"done","side":"sell","order_id":"a6d088cf-1cc0-404c-9f33-a7ba6e019c2b","reason":"canceled","product_id":"BTC-EUR","price":"8828.39000000","remaining_size":"0.00564464","sequence":3257978568,"time":"2018-01-22T15:14:41.804000Z"}
{"type":"received","order_id":"7692db9e-5218-4950-881c-2fedfe3ada7e","order_type":"limit","size":"0.75000000","price":"9316.49000000","side":"sell","client_oid":"d2427c21-0ace-4b67-ac0e-ed2b4a3193e1","product_id":"BTC-EUR","sequence":3257978569,"time":"2018-01-22T15:14:41.808000Z"}
{"type":"open","side":"sell","price":"9316.49000000","order_id":"7692db9e-5218-4950-881c-2fedfe3ada7e","remaining_size":"0.75000000","product_id":"BTC-EUR","sequence":3257978570,"time":"2018-01-22T15:14:41.808000Z"}
{"type":"done","side":"sell","order_id":"9009629f-52b8-4de6-b006-f66de6ac74d1","reason":"canceled","product_id":"BTC-EUR","price":"8828.35000000","remaining_size":"0.00800000","sequence":3257978571,"time":"2018-01-22T15:14:41.814000Z"}
{"type":"received","order_id":"2b927548-d261-4358-94d0-a6f53bd2ac3a","order_type":"limit","size":"0.21404538","price":"8828.33000000","side":"sell","product_id":"BTC-EUR","sequence":3257978572,"time":"2018-01-22T15:14:41.817000Z"}
{"type":"open","side":"sell","price":"8828.33000000","order_id":"2b927548-d261-4358-94d0-a6f53bd2ac3a","remaining_size":"0.21404538","product_id":"BTC-EUR","sequence":3257978573,"time":"2018-01-22T15:14:41.817000Z"}
{"type":"received","order_id":"123bae03-98aa-4762-a712-8effa5bcaa25","order_type":"limit","size":"0.75000000","price":"9409.69000000","side":"sell","client_oid":"d749c3ab-6e36-4cba-91e2-e5392360bf95","product_id":"BTC-EUR","sequence":3257978574,"time":"2018-01-22T15:14:41.818000Z"}
{"type":"open","side":"sell","price":"9409.69000000","order_id":"123bae03-98aa-4762-a712-8effa5bcaa25","remaining_size":"0.75000000","product_id":"BTC-EUR","sequence":3257978575,"time":"2018-01-22T15:14:41.818000Z"}
{"type":"received","order_id":"dff13b03-8a70-4125-a8bb-b3c2a538ddaa","order_type":"limit","size":"0.01731400","price":"8827.33000000","side":"sell","product_id":"BTC-EUR","sequence":3257978576,"time":"2018-01-22T15:14:41.819000Z"}
{"type":"open","side":"sell","price":"8827.33000000","order_id":"dff13b03-8a70-4125-a8bb-b3c2a538ddaa","remaining_size":"0.01731400","product_id":"BTC-EUR","sequence":3257978577,"time":"2018-01-22T15:14:41.819000Z"}
{"type":"done","side":"sell","order_id":"8558a0e8-bbdc-4ff6-a621-618056bfd428","reason":"canceled","product_id":"BTC-EUR","price":"8828.34000000","remaining_size":"0.00113228","sequence":3257978578,"time":"2018-01-22T15:14:41.821000Z"}
{"type":"received","order_id":"ccbce712-7093-47b0-bf99-856686ea2d77","order_type":"limit","size":"0.75000000","price":"8344.69000000","side":"buy","client_oid":"c0dd6729-1f70-4eab-b154-839648710215","product_id":"BTC-EUR","sequence":3257978579,"time":"2018-01-22T15:14:41.834000Z"}
{"type":"open","side":"buy","price":"8344.69000000","order_id":"ccbce712-7093-47b0-bf99-856686ea2d77","remaining_size":"0.75000000","product_id":"BTC-EUR","sequence":3257978580,"time":"2018-01-22T15:14:41.834000Z"}
{"type":"received","order_id":"5c05b690-4b0b-45b6-bc9f-26896ad4b375","order_type":"limit","size":"0.75000000","price":"8251.49000000","side":"buy","client_oid":"dd6c0578-1e5c-4668-b6ce-696890deecfe","product_id":"BTC-EUR","sequence":3257978581,"time":"2018-01-22T15:14:41.842000Z"}
{"type":"open","side":"buy","price":"8251.49000000","order_id":"5c05b690-4b0b-45b6-bc9f-26896ad4b375","remaining_size":"0.75000000","product_id":"BTC-EUR","sequence":3257978582,"time":"2018-01-22T15:14:41.842000Z"}
{"type":"done","side":"sell","order_id":"3d2672f9-d2ee-4044-96e4-c9479cc29de2","reason":"canceled","product_id":"BTC-EUR","price":"8828.34000000","remaining_size":"0.03322226","sequence":3257978583,"time":"2018-01-22T15:14:41.856000Z"}
{"type":"received","order_id":"fae0d7f2-d107-40cb-a6f6-8270b159d3f2","order_type":"limit","size":"0.74000000","price":"9596.09000000","side":"sell","client_oid":"ca98ea44-e309-475c-92c7-26918f36b9b0","product_id":"BTC-EUR","sequence":3257978584,"time":"2018-01-22T15:14:41.864000Z"}
{"type":"open","side":"sell","price":"9596.09000000","order_id":"fae0d7f2-d107-40cb-a6f6-8270b159d3f2","remaining_size":"0.74000000","product_id":"BTC-EUR","sequence":3257978585,"time":"2018-01-22T15:14:41.864000Z"}
{"type":"received","order_id":"e05447d8-6861-407c-aaf9-4ba1b54e85bb","order_type":"limit","size":"0.74000000","price":"8158.29000000","side":"buy","client_oid":"e9760e3d-7d4f-401e-b1d8-da9ce6dbddc9","product_id":"BTC-EUR","sequence":3257978586,"time":"2018-01-22T15:14:41.870000Z"}
{"type":"open","side":"buy","price":"8158.29000000","order_id":"e05447d8-6861-407c-aaf9-4ba1b54e85bb","remaining_size":"0.74000000","product_id":"BTC-EUR","sequence":3257978587,"time":"2018-01-22T15:14:41.870000Z"}
{"type":"received","order_id":"94af149f-e48e-42f2-aa24-60cb71279cbe","order_type":"limit","size":"0.75000000","price":"9689.29000000","side":"sell","client_oid":"b21d3d59-e9e2-476b-83d7-84576220ee2f","product_id":"BTC-EUR","sequence":3257978588,"time":"2018-01-22T15:14:41.874000Z"}
{"type":"open","side":"sell","price":"9689.29000000","order_id":"94af149f-e48e-42f2-aa24-60cb71279cbe","remaining_size":"0.75000000","product_id":"BTC-EUR","sequence":3257978589,"time":"2018-01-22T15:14:41.874000Z"}
{"type":"received","order_id":"0553c3f1-63fd-45e2-a26c-68ca3bcb5386","order_type":"limit","size":"0.02754270","price":"8828.46000000","side":"sell","product_id":"BTC-EUR","sequence":3257978590,"time":"2018-01-22T15:14:41.874000Z"}
{"type":"open","side":"sell","price":"8828.46000000","order_id":"0553c3f1-63fd-45e2-a26c-68ca3bcb5386","remaining_size":"0.02754270","product_id":"BTC-EUR","sequence":3257978591,"time":"2018-01-22T15:14:41.874000Z"}
{"type":"received","order_id":"d92b70d0-b520-4769-822b-76dc99dcbf18","order_type":"limit","size":"0.03322226","price":"8828.32000000","side":"sell","client_oid":"ae067847-7fa5-4a0d-a9c9-173fd19bc782","product_id":"BTC-EUR","sequence":3257978592,"time":"2018-01-22T15:14:41.879000Z"}
{"type":"open","side":"sell","price":"8828.32000000","order_id":"d92b70d0-b520-4769-822b-76dc99dcbf18","remaining_size":"0.03322226","product_id":"BTC-EUR","sequence":3257978593,"time":"2018-01-22T15:14:41.879000Z"}
{"type":"received","order_id":"e8ea907f-d01f-416a-9564-67028e6657f8","order_type":"limit","size":"0.75000000","price":"8065.09000000","side":"buy","client_oid":"c332c61f-5f47-48a2-b958-295bcc3f7f66","product_id":"BTC-EUR","sequence":3257978594,"time":"2018-01-22T15:14:41.879000Z"}
{"type":"open","side":"buy","price":"8065.09000000","order_id":"e8ea907f-d01f-416a-9564-67028e6657f8","remaining_size":"0.75000000","product_id":"BTC-EUR","sequence":3257978595,"time":"2018-01-22T15:14:41.879000Z"}
{"type":"received","order_id":"9d0aa8d0-1c1b-4ceb-8fdc-4fd5820dd907","order_type":"limit","size":"0.10500000","price":"8828.35000000","side":"sell","client_oid":"00848795-9f6e-4be5-a1b5-28234eee6e64","product_id":"BTC-EUR","sequence":3257978596,"time":"2018-01-22T15:14:41.882000Z"}
{"type":"open","side":"sell","price":"8828.35000000","order_id":"9d0aa8d0-1c1b-4ceb-8fdc-4fd5820dd907","remaining_size":"0.10500000","product_id":"BTC-EUR","sequence":3257978597,"time":"2018-01-22T15:14:41.882000Z"}
{"type":"received","order_id":"49e13b0e-11e1-45f5-8aab-4ce80a0d2d15","order_type":"limit","size":"0.00113228","price":"8827.32000000","side":"sell","client_oid":"466f8dde-fb0a-4f24-b5f4-735930324c21","product_id":"BTC-EUR","sequence":3257978598,"time":"2018-01-22T15:14:41.882000Z"}
{"type":"open","side":"sell","price":"8827.32000000","order_id":"49e13b0e-11e1-45f5-8aab-4ce80a0d2d15","remaining_size":"0.00113228","product_id":"BTC-EUR","sequence":3257978599,"time":"2018-01-22T15:14:41.882000Z"}
{"type":"done","side":"sell","order_id":"f7cffeed-6fe0-4ddf-bfb9-440ff9ee2f56","reason":"canceled","product_id":"BTC-EUR","price":"8828.34000000","remaining_size":"0.01800000","sequence":3257978600,"time":"2018-01-22T15:14:41.895000Z"}
{"type":"received","order_id":"4a801855-60a6-4808-bada-fdb733cd93f9","order_type":"limit","size":"0.00800000","price":"8828.33000000","side":"sell","client_oid":"b52fcfcd-1fac-4aa8-9caf-299c2e45f66a","product_id":"BTC-EUR","sequence":3257978601,"time":"2018-01-22T15:14:41.895000Z"}
{"type":"open","side":"sell","price":"8828.33000000","order_id":"4a801855-60a6-4808-bada-fdb733cd93f9","remaining_size":"0.00800000","product_id":"BTC-EUR","sequence":3257978602,"time":"2018-01-22T15:14:41.895000Z"}
{"type":"done","side":"sell","order_id":"2c604412-09d0-4dad-b545-b0f021f0ec00","reason":"canceled","product_id":"BTC-EUR","price":"8828.35000000","remaining_size":"0.06847422","sequence":3257978603,"time":"2018-01-22T15:14:41.933000Z"}
{"type":"received","order_id":"d20169ac-0e5d-4355-aa40-35b07ce745ee","order_type":"limit","size":"0.01800000","price":"8828.32000000","side":"sell","client_oid":"e41ad400-0bc7-4919-8507-60fcb916b427","product_id":"BTC-EUR","sequence":3257978604,"time":"2018-01-22T15:14:41.934000Z"}
{"type":"open","side":"sell","price":"8828.32000000","order_id":"d20169ac-0e5d-4355-aa40-35b07ce745ee","remaining_size":"0.01800000","product_id":"BTC-EUR","sequence":3257978605,"time":"2018-01-22T15:14:41.934000Z"}
{"type":"received","order_id":"d0a6775b-f221-45fc-9ae9-25b1a5dade66","order_type":"market","side":"buy","funds":"19.9501075704000000","client_oid":"90236a13-4166-44d7-c192-0bc898e35faa","product_id":"BTC-EUR","sequence":3257978606,"time":"2018-01-22T15:14:41.948000Z"}
{"type":"match","trade_id":10551373,"maker_order_id":"49e13b0e-11e1-45f5-8aab-4ce80a0d2d15","taker_order_id":"d0a6775b-f221-45fc-9ae9-25b1a5dade66","side":"sell","size":"0.00113228","price":"8827.32000000","product_id":"BTC-EUR","sequence":3257978607,"time":"2018-01-22T15:14:41.948000Z"}
{"type":"done","side":"sell","order_id":"49e13b0e-11e1-45f5-8aab-4ce80a0d2d15","reason":"filled","product_id":"BTC-EUR","price":"8827.32000000","remaining_size":"0.00000000","sequence":3257978608,"time":"2018-01-22T15:14:41.949000Z"}
{"type":"match","trade_id":10551374,"maker_order_id":"dff13b03-8a70-4125-a8bb-b3c2a538ddaa","taker_order_id":"d0a6775b-f221-45fc-9ae9-25b1a5dade66","side":"sell","size":"0.00112776","price":"8827.33000000","product_id":"BTC-EUR","sequence":3257978609,"time":"2018-01-22T15:14:41.949000Z"}
{"type":"done","side":"buy","order_id":"d0a6775b-f221-45fc-9ae9-25b1a5dade66","reason":"filled","product_id":"BTC-EUR","sequence":3257978610,"time":"2018-01-22T15:14:41.949000Z"}
{"type":"received","order_id":"3c31a693-baa2-42b2-b4fd-aab2575cb058","order_type":"limit","size":"0.04164971","price":"8828.32000000","side":"sell","client_oid":"e33590ca-ef61-4c6f-ab53-a0a0fe7fb955","product_id":"BTC-EUR","sequence":3257978611,"time":"2018-01-22T15:14:41.951000Z"}
{"type":"open","side":"sell","price":"8828.32000000","order_id":"3c31a693-baa2-42b2-b4fd-aab2575cb058","remaining_size":"0.04164971","product_id":"BTC-EUR","sequence":3257978612,"time":"2018-01-22T15:14:41.951000Z"}
{"type":"done","side":"sell","order_id":"9d0aa8d0-1c1b-4ceb-8fdc-4fd5820dd907","reason":"canceled","product_id":"BTC-EUR","price":"8828.35000000","remaining_size":"0.10500000","sequence":3257978613,"time":"2018-01-22T15:14:41.958000Z"}
{"type":"received","order_id":"238d6020-f920-4b67-b8fc-4edf72f426dc","order_type":"limit","size":"0.10500000","price":"8827.33000000","side":"sell","client_oid":"b610a30c-1392-468e-aa0e-81279fa28214","product_id":"BTC-EUR","sequence":3257978614,"time":"2018-01-22T15:14:41.977000Z"}
{"type":"open","side":"sell","price":"8827.33000000","order_id":"238d6020-f920-4b67-b8fc-4edf72f426dc","remaining_size":"0.10500000","product_id":"BTC-EUR","sequence":3257978615,"time":"2018-01-22T15:14:41.977000Z"}
{"type":"received","order_id":"815aeb4c-8a37-4aa5-b7ba-3220b8319256","order_type":"limit","size":"0.00113290","price":"8827.31000000","side":"sell","client_oid":"2a0d6313-d00c-4bad-b219-545b0c7f0822","product_id":"BTC-EUR","sequence":3257978616,"time":"2018-01-22T15:14:41.979000Z"}
{"type":"open","side":"sell","price":"8827.31000000","order_id":"815aeb4c-8a37-4aa5-b7ba-3220b8319256","remaining_size":"0.00113290","product_id":"BTC-EUR","sequence":3257978617,"time":"2018-01-22T15:14:41.979000Z"}
{"type":"done","side":"sell","order_id":"2b927548-d261-4358-94d0-a6f53bd2ac3a","reason":"canceled","product_id":"BTC-EUR","price":"8828.33000000","remaining_size":"0.21404538","sequence":3257978618,"time":"2018-01-22T15:14:41.995000Z"}
{"type":"received","order_id":"d2241070-69f0-442e-8c59-8cca1d514d6c","order_type":"limit","size":"0.00113310","price":"8825.31000000","side":"buy","client_oid":"f7afc14a-dd33-48aa-b260-94c9526034a4","product_id":"BTC-EUR","sequence":3257978619,"time":"2018-01-22T15:14:42.003000Z"}
{"type":"open","side":"buy","price":"8825.31000000","order_id":"d2241070-69f0-442e-8c59-8cca1d514d6c","remaining_size":"0.00113310","product_id":"BTC-EUR","sequence":3257978620,"time":"2018-01-22T15:14:42.003000Z"}
{"type":"done","side":"sell","order_id":"815aeb4c-8a37-4aa5-b7ba-3220b8319256","reason":"canceled","product_id":"BTC-EUR","price":"8827.31000000","remaining_size":"0.00113290","sequence":3257978621,"time":"2018-01-22T15:14:42.011000Z"}
{"type":"done","side":"sell","order_id":"4a801855-60a6-4808-bada-fdb733cd93f9","reason":"canceled","product_id":"BTC-EUR","price":"8828.33000000","remaining_size":"0.00800000","sequence":3257978622,"time":"2018-01-22T15:14:42.016000Z"}
{"type":"done","side":"sell","order_id":"d92b70d0-b520-4769-822b-76dc99dcbf18","reason":"canceled","product_id":"BTC-EUR","price":"8828.32000000","remaining_size":"0.03322226","sequence":3257978623,"time":"2018-01-22T15:14:42.022000Z"}
{"type":"received","order_id":"b6cd4721-b631-46de-9c4c-7fc9401bfeed","order_type":"limit","size":"0.00564464","price":"8828.32000000","side":"sell","client_oid":"293da6f2-adee-4940-95c4-f6a64d948432","product_id":"BTC-EUR","sequence":3257978624,"time":"2018-01-22T15:14:42.029000Z"}
{"type":"open","side":"sell","price":"8828.32000000","order_id":"b6cd4721-b631-46de-9c4c-7fc9401bfeed","remaining_size":"0.00564464","product_id":"BTC-EUR","sequence":3257978625,"time":"2018-01-22T15:14:42.029000Z"}
{"type":"done","side":"sell","order_id":"d20169ac-0e5d-4355-aa40-35b07ce745ee","reason":"canceled","product_id":"BTC-EUR","price":"8828.32000000","remaining_size":"0.01800000","sequence":3257978626,"time":"2018-01-22T15:14:42.042000Z"}
{"type":"received","order_id":"40b4aa25-f847-4d02-9fb9-218789fbf166","order_type":"limit","size":"0.00800000","price":"8827.31000000","side":"sell","client_oid":"23c60d45-774e-4349-9a11-3e5bea9f8ca5","product_id":"BTC-EUR","sequence":3257978627,"time":"2018-01-22T15:14:42.043000Z"}
{"type":"open","side":"sell","price":"8827.31000000","order_id":"40b4aa25-f847-4d02-9fb9-218789fbf166","remaining_size":"0.00800000","product_id":"BTC-EUR","sequence":3257978628,"time":"2018-01-22T15:14:42.043000Z"}
{"type":"done","side":"buy","order_id":"d2241070-69f0-442e-8c59-8cca1d514d6c","reason":"canceled","product_id":"BTC-EUR","price":"8825.31000000","remaining_size":"0.00113310","sequence":3257978629,"time":"2018-01-22T15:14:42.044000Z"}
{"type":"received","order_id":"99de76a1-a325-4dce-9e44-3735008c4860","order_type":"limit","size":"0.03322226","price":"8827.32000000","side":"sell","client_oid":"a4cf5aaa-4871-45e2-9776-acfd6a745d40","product_id":"BTC-EUR","sequence":3257978630,"time":"2018-01-22T15:14:42.053000Z"}
{"type":"open","side":"sell","price":"8827.32000000","order_id":"99de76a1-a325-4dce-9e44-3735008c4860","remaining_size":"0.03322226","product_id":"BTC-EUR","sequence":3257978631,"time":"2018-01-22T15:14:42.053000Z"}
{"type":"done","side":"sell","order_id":"238d6020-f920-4b67-b8fc-4edf72f426dc","reason":"canceled","product_id":"BTC-EUR","price":"8827.33000000","remaining_size":"0.10500000","sequence":3257978632,"time":"2018-01-22T15:14:42.058000Z"}
{"type":"received","order_id":"9dccbaa7-a7dc-4ca4-8fb3-6823760a656c","order_type":"limit","size":"0.06847422","price":"8828.33000000","side":"sell","client_oid":"0372a944-003a-40da-98b0-c403f634149e","product_id":"BTC-EUR","sequence":3257978633,"time":"2018-01-22T15:14:42.058000Z"}
{"type":"open","side":"sell","price":"8828.33000000","order_id":"9dccbaa7-a7dc-4ca4-8fb3-6823760a656c","remaining_size":"0.06847422","product_id":"BTC-EUR","sequence":3257978634,"time":"2018-01-22T15:14:42.058000Z"}
{"type":"done","side":"sell","order_id":"99de76a1-a325-4dce-9e44-3735008c4860","reason":"canceled","product_id":"BTC-EUR","price":"8827.32000000","remaining_size":"0.03322226","sequence":3257978635,"time":"2018-01-22T15:14:42.062000Z"}
{"type":"done","side":"sell","order_id":"f5ea9ad4-ca42-4fce-bad0-e004f80cc6b5","reason":"canceled","product_id":"BTC-EUR","price":"8828.36000000","remaining_size":"0.01322632","sequence":3257978636,"time":"2018-01-22T15:14:42.087000Z"}
{"type":"received","order_id":"752315a1-6440-4d11-982e-8a09f6a5354d","order_type":"limit","size":"0.00113290","price":"8827.32000000","side":"sell","client_oid":"568aeb2c-f013-400b-a18e-fb15c55e3967","product_id":"BTC-EUR","sequence":3257978637,"time":"2018-01-22T15:14:42.097000Z"}
{"type":"open","side":"sell","price":"8827.32000000","order_id":"752315a1-6440-4d11-982e-8a09f6a5354d","remaining_size":"0.00113290","product_id":"BTC-EUR","sequence":3257978638,"time":"2018-01-22T15:14:42.097000Z"}
{"type":"done","side":"sell","order_id":"c2c26fb6-3724-40de-bbea-b7bdcc57e42f","reason":"canceled","product_id":"BTC-EUR","price":"8828.36000000","remaining_size":"0.22947933","sequence":3257978639,"time":"2018-01-22T15:14:42.100000Z"}
{"type":"done","side":"sell","order_id":"752315a1-6440-4d11-982e-8a09f6a5354d","reason":"canceled","product_id":"BTC-EUR","price":"8827.32000000","remaining_size":"0.00113290","sequence":3257978640,"time":"2018-01-22T15:14:42.107000Z"}
{"type":"done","side":"sell","order_id":"986521e6-b358-4263-acc3-298ade99fe18","reason":"canceled","product_id":"BTC-EUR","price":"8828.37000000","remaining_size":"0.09200000","sequence":3257978641,"time":"2018-01-22T15:14:42.108000Z"}
{"type":"received","order_id":"bd18972c-d8a2-4031-b8f0-63909e523d76","order_type":"limit","size":"0.01800000","price":"8827.32000000","side":"sell","client_oid":"16a45077-8bc1-4826-b551-90e8d7d2b8d3","product_id":"BTC-EUR","sequence":3257978642,"time":"2018-01-22T15:14:42.111000Z"}
{"type":"open","side":"sell","price":"8827.32000000","order_id":"bd18972c-d8a2-4031-b8f0-63909e523d76","remaining_size":"0.01800000","product_id":"BTC-EUR","sequence":3257978643,"time":"2018-01-22T15:14:42.111000Z"}
{"type":"received","order_id":"fb2fe9e4-c390-4e1c-8eb5-1f27a35db77f","order_type":"limit","size":"0.03322226","price":"8828.31000000","side":"sell","client_oid":"bf1d9843-bee6-478e-9489-bb9174e56b23","product_id":"BTC-EUR","sequence":3257978644,"time":"2018-01-22T15:14:42.114000Z"}
{"type":"open","side":"sell","price":"8828.31000000","order_id":"fb2fe9e4-c390-4e1c-8eb5-1f27a35db77f","remaining_size":"0.03322226","product_id":"BTC-EUR","sequence":3257978645,"time":"2018-01-22T15:14:42.114000Z"}
{"type":"received","order_id":"0c40529c-8fda-4627-ad8f-52449408706c","order_type":"limit","size":"0.10500000","price":"8827.33000000","side":"sell","client_oid":"b98f854c-35fd-492b-9aed-4767866f8fbc","product_id":"BTC-EUR","sequence":3257978646,"time":"2018-01-22T15:14:42.121000Z"}
{"type":"open","side":"sell","price":"8827.33000000","order_id":"0c40529c-8fda-4627-ad8f-52449408706c","remaining_size":"0.10500000","product_id":"BTC-EUR","sequence":3257978647,"time":"2018-01-22T15:14:42.121000Z"}
{"type":"received","order_id":"c5a76936-65bb-483d-a658-4988a56325cc","order_type":"limit","size":"0.09200000","price":"8827.32000000","side":"sell","client_oid":"d081d8aa-de7d-40b0-9814-77dd7e86a92c","product_id":"BTC-EUR","sequence":3257978648,"time":"2018-01-22T15:14:42.126000Z"}
{"type":"open","side":"sell","price":"8827.32000000","order_id":"c5a76936-65bb-483d-a658-4988a56325cc","remaining_size":"0.09200000","product_id":"BTC-EUR","sequence":3257978649,"time":"2018-01-22T15:14:42.126000Z"}
{"type":"done","side":"sell","order_id":"fb2fe9e4-c390-4e1c-8eb5-1f27a35db77f","reason":"canceled","product_id":"BTC-EUR","price":"8828.31000000","remaining_size":"0.03322226","sequence":3257978650,"time":"2018-01-22T15:14:42.128000Z"}
{"type":"received","order_id":"3e4be82e-5968-4f7f-80bf-74e45c2ed675","order_type":"limit","size":"0.06847422","price":"8827.32000000","side":"sell","client_oid":"5c65a293-5a01-47f0-987f-5c28e63b9321","product_id":"BTC-EUR","sequence":3257978651,"time":"2018-01-22T15:14:42.183000Z"}
{"type":"open","side":"sell","price":"8827.32000000","order_id":"3e4be82e-5968-4f7f-80bf-74e45c2ed675","remaining_size":"0.06847422","product_id":"BTC-EUR","sequence":3257978652,"time":"2018-01-22T15:14:42.183000Z"}
{"type":"received","order_id":"175d937a-3882-4299-96f8-29be82ee56a1","order_type":"limit","size":"0.00113310","price":"8825.32000000","side":"buy","client_oid":"6d4a5428-dbce-4adc-9c68-f8a3fe84a3ee","product_id":"BTC-EUR","sequence":3257978653,"time":"2018-01-22T15:14:42.185000Z"}
{"type":"open","side":"buy","price":"8825.32000000","order_id":"175d937a-3882-4299-96f8-29be82ee56a1","remaining_size":"0.00113310","product_id":"BTC-EUR","sequence":3257978654,"time":"2018-01-22T15:14:42.185000Z"}
{"type":"received","order_id":"9693cfb7-51e6-414f-907f-c9767ce6d165","order_type":"limit","size":"0.10500000","price":"8827.31000000","side":"sell","client_oid":"f3b5d623-3318-4458-9dde-458c9ca1480c","product_id":"BTC-EUR","sequence":3257978655,"time":"2018-01-22T15:14:42.198000Z"}
{"type":"open","side":"sell","price":"8827.31000000","order_id":"9693cfb7-51e6-414f-907f-c9767ce6d165","remaining_size":"0.10500000","product_id":"BTC-EUR","sequence":3257978656,"time":"2018-01-22T15:14:42.198000Z"}
{"type":"done","side":"sell","order_id":"bd18972c-d8a2-4031-b8f0-63909e523d76","reason":"canceled","product_id":"BTC-EUR","price":"8827.32000000","remaining_size":"0.01800000","sequence":3257978657,"time":"2018-01-22T15:14:42.202000Z"}
{"type":"received","order_id":"a8aec36d-dcec-4e04-a83a-49dd6eb86f1f","order_type":"limit","size":"0.06847422","price":"8828.32000000","side":"sell","client_oid":"f49b437a-348c-4d0c-af08-36e36dcbc4bb","product_id":"BTC-EUR","sequence":3257978658,"time":"2018-01-22T15:14:42.203000Z"}
{"type":"open","side":"sell","price":"8828.32000000","order_id":"a8aec36d-dcec-4e04-a83a-49dd6eb86f1f","remaining_size":"0.06847422","product_id":"BTC-EUR","sequence":3257978659,"time":"2018-01-22T15:14:42.203000Z"}
{"type":"received","order_id":"bb9d95b8-b8e3-4aef-8402-01ef333b346b","order_type":"limit","size":"0.06847422","price":"8827.32000000","side":"sell","client_oid":"b972e28b-d33e-468c-95f1-6c0b0b7bd8b5","product_id":"BTC-EUR","sequence":3257978660,"time":"2018-01-22T15:14:42.203000Z"}
{"type":"open","side":"sell","price":"8827.32000000","order_id":"bb9d95b8-b8e3-4aef-8402-01ef333b346b","remaining_size":"0.06847422","product_id":"BTC-EUR","sequence":3257978661,"time":"2018-01-22T15:14:42.203000Z"}
{"type":"done","side":"sell","order_id":"0c40529c-8fda-4627-ad8f-52449408706c","reason":"canceled","product_id":"BTC-EUR","price":"8827.33000000","remaining_size":"0.10500000","sequence":3257978662,"time":"2018-01-22T15:14:42.206000Z"}
{"type":"received","order_id":"00f0317b-87e4-4689-a3d3-93490b648ed6","order_type":"limit","size":"0.03322226","price":"8827.31000000","side":"sell","client_oid":"fc9bab8b-18bb-42eb-b4d3-d203e3ec253d","product_id":"BTC-EUR","sequence":3257978663,"time":"2018-01-22T15:14:42.211000Z"}
{"type":"open","side":"sell","price":"8827.31000000","order_id":"00f0317b-87e4-4689-a3d3-93490b648ed6","remaining_size":"0.03322226","product_id":"BTC-EUR","sequence":3257978664,"time":"2018-01-22T15:14:42.211000Z"}
{"type":"done","side":"sell","order_id":"dff13b03-8a70-4125-a8bb-b3c2a538ddaa","reason":"canceled","product_id":"BTC-EUR","price":"8827.33000000","remaining_size":"0.01618624","sequence":3257978665,"time":"2018-01-22T15:14:42.218000Z"}
{"type":"done","side":"buy","order_id":"175d937a-3882-4299-96f8-29be82ee56a1","reason":"canceled","product_id":"BTC-EUR","price":"8825.32000000","remaining_size":"0.00113310","sequence":3257978666,"time":"2018-01-22T15:14:42.223000Z"}
{"type":"received","order_id":"7c7263ca-dbb7-498f-91bd-4c81fc993c1f","order_type":"limit","size":"0.01800000","price":"8827.30000000","side":"sell","client_oid":"6ff08868-2ff0-4531-be52-7702ac8e2d8a","product_id":"BTC-EUR","sequence":3257978667,"time":"2018-01-22T15:14:42.235000Z"}
{"type":"open","side":"sell","price":"8827.30000000","order_id":"7c7263ca-dbb7-498f-91bd-4c81fc993c1f","remaining_size":"0.01800000","product_id":"BTC-EUR","sequence":3257978668,"time":"2018-01-22T15:14:42.235000Z"}
{"type":"received","order_id":"7e87cf00-96b1-4b4a-955e-5e89705c56c3","order_type":"limit","size":"0.00113290","price":"8827.30000000","side":"sell","client_oid":"5a5d2982-7f41-46e9-a20e-e65e90058cdc","product_id":"BTC-EUR","sequence":3257978669,"time":"2018-01-22T15:14:42.244000Z"}
{"type":"open","side":"sell","price":"8827.30000000","order_id":"7e87cf00-96b1-4b4a-955e-5e89705c56c3","remaining_size":"0.00113290","product_id":"BTC-EUR","sequence":3257978670,"time":"2018-01-22T15:14:42.244000Z"}
{"type":"received","order_id":"5d51c3a8-c8c7-4a6a-b3f0-7f269b87675a","order_type":"limit","size":"0.58423000","price":"8879.87000000","side":"sell","product_id":"BTC-EUR","sequence":3257978671,"time":"2018-01-22T15:14:42.252000Z"}
{"type":"open","side":"sell","price":"8879.87000000","order_id":"5d51c3a8-c8c7-4a6a-b3f0-7f269b87675a","remaining_size":"0.58423000","product_id":"BTC-EUR","sequence":3257978672,"time":"2018-01-22T15:14:42.252000Z"}
{"type":"done","side":"sell","order_id":"c5a76936-65bb-483d-a658-4988a56325cc","reason":"canceled","product_id":"BTC-EUR","price":"8827.32000000","remaining_size":"0.09200000","sequence":3257978673,"time":"2018-01-22T15:14:42.267000Z"}
{"type":"done","side":"sell","order_id":"7e87cf00-96b1-4b4a-955e-5e89705c56c3","reason":"canceled","product_id":"BTC-EUR","price":"8827.30000000","remaining_size":"0.00113290","sequence":3257978674,"time":"2018-01-22T15:14:42.271000Z"}
{"type":"done","side":"sell","order_id":"9693cfb7-51e6-414f-907f-c9767ce6d165","reason":"canceled","product_id":"BTC-EUR","price":"8827.31000000","remaining_size":"0.10500000","sequence":3257978675,"time":"2018-01-22T15:14:42.278000Z"}
{"type":"received","order_id":"a37d3f49-ff21-4c83-ac6e-73cfeafd4f2e","order_type":"limit","size":"0.75000000","price":"9782.49000000","side":"sell","client_oid":"c61e5cf1-6fc9-48ce-93e2-2c860375f9f1","product_id":"BTC-EUR","sequence":3257978676,"time":"2018-01-22T15:14:42.281000Z"}
{"type":"open","side":"sell","price":"9782.49000000","order_id":"a37d3f49-ff21-4c83-ac6e-73cfeafd4f2e","remaining_size":"0.75000000","product_id":"BTC-EUR","sequence":3257978677,"time":"2018-01-22T15:14:42.281000Z"}
{"type":"done","side":"buy","order_id":"4cee68b2-628f-42ae-b71d-f11d07122c6b","reason":"canceled","product_id":"BTC-EUR","price":"7975.90000000","remaining_size":"0.75000000","sequence":3257978678,"time":"2018-01-22T15:14:42.285000Z"}
{"type":"received","order_id":"dad4a805-a49e-402e-92af-37afc1d44812","order_type":"limit","size":"0.09200000","price":"8827.30000000","side":"sell","client_oid":"b351da9d-ca0f-4287-8a35-0f2f59f911eb","product_id":"BTC-EUR","sequence":3257978679,"time":"2018-01-22T15:14:42.287000Z"}
{"type":"open","side":"sell","price":"8827.30000000","order_id":"dad4a805-a49e-402e-92af-37afc1d44812","remaining_size":"0.09200000","product_id":"BTC-EUR","sequence":3257978680,"time":"2018-01-22T15:14:42.287000Z"}
{"type":"received","order_id":"1fa10a4d-210e-42a0-a6ca-27b78c41953d","order_type":"limit","size":"0.00113310","price":"8825.33000000","side":"buy","client_oid":"5652c88d-ab50-4810-8f48-94666302318f","product_id":"BTC-EUR","sequence":3257978681,"time":"2018-01-22T15:14:42.291000Z"}
{"type":"open","side":"buy","price":"8825.33000000","order_id":"1fa10a4d-210e-42a0-a6ca-27b78c41953d","remaining_size":"0.00113310","product_id":"BTC-EUR","sequence":3257978682,"time":"2018-01-22T15:14:42.291000Z"}
{"type":"received","order_id":"57aee3b1-1361-473d-9695-c0bb17fcb1dc","order_type":"limit","size":"0.75000000","price":"7971.89000000","side":"buy","client_oid":"11b87cde-00df-45cb-a8f0-4ee298577e92","product_id":"BTC-EUR","sequence":3257978683,"time":"2018-01-22T15:14:42.293000Z"}
{"type":"open","side":"buy","price":"7971.89000000","order_id":"57aee3b1-1361-473d-9695-c0bb17fcb1dc","remaining_size":"0.75000000","product_id":"BTC-EUR","sequence":3257978684,"time":"2018-01-22T15:14:42.293000Z"}
{"type":"received","order_id":"59a89e3e-cafa-4dcc-ba7a-bf2ec9b5e6b7","order_type":"limit","size":"0.21404538","price":"8827.30000000","side":"sell","product_id":"BTC-EUR","sequence":3257978685,"time":"2018-01-22T15:14:42.295000Z"}
{"type":"open","side":"sell","price":"8827.30000000","order_id":"59a89e3e-cafa-4dcc-ba7a-bf2ec9b5e6b7","remaining_size":"0.21404538","product_id":"BTC-EUR","sequence":3257978686,"time":"2018-01-22T15:14:42.295000Z"}
{"type":"received","order_id":"f43bcd6d-458d-4a76-ac7e-3334da477e74","order_type":"limit","size":"0.10500000","price":"8827.31000000","side":"sell","client_oid":"b46dd698-a10d-49d4-ba6f-da33252243e5","product_id":"BTC-EUR","sequence":3257978687,"time":"2018-01-22T15:14:42.300000Z"}
{"type":"open","side":"sell","price":"8827.31000000","order_id":"f43bcd6d-458d-4a76-ac7e-3334da477e74","remaining_size":"0.10500000","product_id":"BTC-EUR","sequence":3257978688,"time":"2018-01-22T15:14:42.300000Z"}
{"type":"done","side":"sell","order_id":"9dccbaa7-a7dc-4ca4-8fb3-6823760a656c","reason":"canceled","product_id":"BTC-EUR","price":"8828.33000000","remaining_size":"0.06847422","sequence":3257978689,"time":"2018-01-22T15:14:42.307000Z"}
{"type":"received","order_id":"25e60341-c92b-4a27-af86-dae07ad11c72","order_type":"limit","size":"0.01322632","price":"8827.31000000","side":"sell","client_oid":"482db68a-e4dc-4bee-98c4-69761c88236b","product_id":"BTC-EUR","sequence":3257978690,"time":"2018-01-22T15:14:42.321000Z"}
{"type":"open","side":"sell","price":"8827.31000000","order_id":"25e60341-c92b-4a27-af86-dae07ad11c72","remaining_size":"0.01322632","product_id":"BTC-EUR","sequence":3257978691,"time":"2018-01-22T15:14:42.321000Z"}
{"type":"received","order_id":"39662888-2fa0-44c5-b4af-c35f6badcda3","order_type":"limit","size":"0.22947933","price":"8827.31000000","side":"sell","client_oid":"6343a29b-0a9e-4276-a38a-6543ac5846ee","product_id":"BTC-EUR","sequence":3257978692,"time":"2018-01-22T15:14:42.328000Z"}
{"type":"open","side":"sell","price":"8827.31000000","order_id":"39662888-2fa0-44c5-b4af-c35f6badcda3","remaining_size":"0.22947933","product_id":"BTC-EUR","sequence":3257978693,"time":"2018-01-22T15:14:42.328000Z"}
{"type":"received","order_id":"a8b1d379-7ffb-49c6-93b7-ae99194ece0f","order_type":"limit","size":"0.00113290","price":"8827.29000000","side":"sell","client_oid":"bd474be4-2f3f-4862-8c1d-38324c719645","product_id":"BTC-EUR","sequence":3257978694,"time":"2018-01-22T15:14:42.337000Z"}
{"type":"open","side":"sell","price":"8827.29000000","order_id":"a8b1d379-7ffb-49c6-93b7-ae99194ece0f","remaining_size":"0.00113290","product_id":"BTC-EUR","sequence":3257978695,"time":"2018-01-22T15:14:42.337000Z"}
{"type":"received","order_id":"9f2cb8e0-961c-47f9-95ba-1369e321d390","order_type":"limit","size":"0.10500000","price":"8827.31000000","side":"sell","client_oid":"f2d79cdc-4ed8-4ddf-ab87-3ce3f5d267f0","product_id":"BTC-EUR","sequence":3257978696,"time":"2018-01-22T15:14:42.343000Z"}
{"type":"open","side":"sell","price":"8827.31000000","order_id":"9f2cb8e0-961c-47f9-95ba-1369e321d390","remaining_size":"0.10500000","product_id":"BTC-EUR","sequence":3257978697,"time":"2018-01-22T15:14:42.343000Z"}
{"type":"done","side":"buy","order_id":"1fa10a4d-210e-42a0-a6ca-27b78c41953d","reason":"canceled","product_id":"BTC-EUR","price":"8825.33000000","remaining_size":"0.00113310","sequence":3257978698,"time":"2018-01-22T15:14:42.345000Z"}
{"type":"done","side":"sell","order_id":"f43bcd6d-458d-4a76-ac7e-3334da477e74","reason":"canceled","product_id":"BTC-EUR","price":"8827.31000000","remaining_size":"0.10500000","sequence":3257978699,"time":"2018-01-22T15:14:42.376000Z"}
{"type":"done","side":"sell","order_id":"00f0317b-87e4-4689-a3d3-93490b648ed6","reason":"canceled","product_id":"BTC-EUR","price":"8827.31000000","remaining_size":"0.03322226","sequence":3257978700,"time":"2018-01-22T15:14:42.378000Z"}
{"type":"done","side":"buy","order_id":"709df843-09ef-4374-9277-ddb43d211225","reason":"canceled","product_id":"BTC-EUR","price":"8825.30000000","remaining_size":"0.02677774","sequence":3257978701,"time":"2018-01-22T15:14:42.378000Z"}
{"type":"done","side":"sell","order_id":"40b4aa25-f847-4d02-9fb9-218789fbf166","reason":"canceled","product_id":"BTC-EUR","price":"8827.31000000","remaining_size":"0.00800000","sequence":3257978702,"time":"2018-01-22T15:14:42.394000Z"}
{"type":"received","order_id":"4a7e5f22-1cdb-4c83-a756-5c10cef224f0","order_type":"limit","size":"0.06847422","price":"8827.30000000","side":"sell","client_oid":"6583673d-4d51-4407-9f18-6eb4033950fd","product_id":"BTC-EUR","sequence":3257978703,"time":"2018-01-22T15:14:42.407000Z"}
{"type":"open","side":"sell","price":"8827.30000000","order_id":"4a7e5f22-1cdb-4c83-a756-5c10cef224f0","remaining_size":"0.06847422","product_id":"BTC-EUR","sequence":3257978704,"time":"2018-01-22T15:14:42.407000Z"}
{"type":"received","order_id":"e8a97650-4769-410c-b285-524ba5295f21","order_type":"limit","size":"0.06847422","price":"8827.30000000","side":"sell","client_oid":"9005ee24-796b-40a3-a720-157630f8f499","product_id":"BTC-EUR","sequence":3257978705,"time":"2018-01-22T15:14:42.408000Z"}
{"type":"open","side":"sell","price":"8827.30000000","order_id":"e8a97650-4769-410c-b285-524ba5295f21","remaining_size":"0.06847422","product_id":"BTC-EUR","sequence":3257978706,"time":"2018-01-22T15:14:42.408000Z"}
{"type":"done","side":"sell","order_id":"7c7263ca-dbb7-498f-91bd-4c81fc993c1f","reason":"canceled","product_id":"BTC-EUR","price":"8827.30000000","remaining_size":"0.01800000","sequence":3257978707,"time":"2018-01-22T15:14:42.419000Z"}
{"type":"received","order_id":"8b98c06f-6a12-4934-bc09-f14f0faff1fa","order_type":"limit","size":"0.10500000","price":"8827.30000000","side":"sell","client_oid":"5365f38a-fc0a-4d17-a641-bc51b8aea472","product_id":"BTC-EUR","sequence":3257978708,"time":"2018-01-22T15:14:42.424000Z"}
{"type":"open","side":"sell","price":"8827.30000000","order_id":"8b98c06f-6a12-4934-bc09-f14f0faff1fa","remaining_size":"0.10500000","product_id":"BTC-EUR","sequence":3257978709,"time":"2018-01-22T15:14:42.424000Z"}
{"type":"received","order_id":"94579e48-9f70-49e8-9e77-0c4a2c5d6626","order_type":"limit","size":"0.00113310","price":"8825.30000000","side":"buy","client_oid":"b5c71eda-3fd9-42a7-9df9-a8995e7ed297","product_id":"BTC-EUR","sequence":3257978710,"time":"2018-01-22T15:14:42.427000Z"}
{"type":"open","side":"buy","price":"8825.30000000","order_id":"94579e48-9f70-49e8-9e77-0c4a2c5d6626","remaining_size":"0.00113310","product_id":"BTC-EUR","sequence":3257978711,"time":"2018-01-22T15:14:42.427000Z"}
{"type":"received","order_id":"5ba99b42-fdb2-41f1-9737-c5f8fe3c646b","order_type":"limit","size":"0.00800000","price":"8827.29000000","side":"sell","client_oid":"77c46382-ca02-4582-8d1e-4dbb8e49ef68","product_id":"BTC-EUR","sequence":3257978712,"time":"2018-01-22T15:14:42.451000Z"}
{"type":"open","side":"sell","price":"8827.29000000","order_id":"5ba99b42-fdb2-41f1-9737-c5f8fe3c646b","remaining_size":"0.00800000","product_id":"BTC-EUR","sequence":3257978713,"time":"2018-01-22T15:14:42.451000Z"}
{"type":"done","side":"sell","order_id":"3e4be82e-5968-4f7f-80bf-74e45c2ed675","reason":"canceled","product_id":"BTC-EUR","price":"8827.32000000","remaining_size":"0.06847422","sequence":3257978714,"time":"2018-01-22T15:14:42.454000Z"}
{"type":"done","side":"sell","order_id":"bb9d95b8-b8e3-4aef-8402-01ef333b346b","reason":"canceled","product_id":"BTC-EUR","price":"8827.32000000","remaining_size":"0.06847422","sequence":3257978715,"time":"2018-01-22T15:14:42.455000Z"}
{"type":"done","side":"sell","order_id":"a8aec36d-dcec-4e04-a83a-49dd6eb86f1f","reason":"canceled","product_id":"BTC-EUR","price":"8828.32000000","remaining_size":"0.06847422","sequence":3257978716,"time":"2018-01-22T15:14:42.458000Z"}
{"type":"done","side":"sell","order_id":"9f2cb8e0-961c-47f9-95ba-1369e321d390","reason":"canceled","product_id":"BTC-EUR","price":"8827.31000000","remaining_size":"0.10500000","sequence":3257978717,"time":"2018-01-22T15:14:42.458000Z"}
{"type":"done","side":"sell","order_id":"dad4a805-a49e-402e-92af-37afc1d44812","reason":"canceled","product_id":"BTC-EUR","price":"8827.30000000","remaining_size":"0.09200000","sequence":3257978718,"time":"2018-01-22T15:14:42.461000Z"}
{"type":"received","order_id":"ffba62c3-6b4e-485e-9252-8d2e7d2ca53e","order_type":"limit","size":"0.03322226","price":"8827.29000000","side":"sell","client_oid":"76b55a0a-76ec-4b0c-bdfa-13a247c06069","product_id":"BTC-EUR","sequence":3257978719,"time":"2018-01-22T15:14:42.462000Z"}
{"type":"open","side":"sell","price":"8827.29000000","order_id":"ffba62c3-6b4e-485e-9252-8d2e7d2ca53e","remaining_size":"0.03322226","product_id":"BTC-EUR","sequence":3257978720,"time":"2018-01-22T15:14:42.462000Z"}
{"type":"received","order_id":"5c7ca091-c382-4f9c-b956-77bc9d400ecd","order_type":"limit","size":"0.10500000","price":"8827.29000000","side":"sell","client_oid":"91959b09-654d-4991-9117-0f4311e4a952","product_id":"BTC-EUR","sequence":3257978721,"time":"2018-01-22T15:14:42.467000Z"}
{"type":"open","side":"sell","price":"8827.29000000","order_id":"5c7ca091-c382-4f9c-b956-77bc9d400ecd","remaining_size":"0.10500000","product_id":"BTC-EUR","sequence":3257978722,"time":"2018-01-22T15:14:42.467000Z"}
{"type":"done","side":"sell","order_id":"59a89e3e-cafa-4dcc-ba7a-bf2ec9b5e6b7","reason":"canceled","product_id":"BTC-EUR","price":"8827.30000000","remaining_size":"0.21404538","sequence":3257978723,"time":"2018-01-22T15:14:42.469000Z"}
{"type":"received","order_id":"5ff9348a-e2a7-4864-9ab1-085abfbf5ae8","order_type":"limit","size":"0.03677774","price":"8825.30000000","side":"buy","client_oid":"75bca1d6-5056-4efa-88bb-c122a32a11f6","product_id":"BTC-EUR","sequence":3257978724,"time":"2018-01-22T15:14:42.515000Z"}
{"type":"open","side":"buy","price":"8825.30000000","order_id":"5ff9348a-e2a7-4864-9ab1-085abfbf5ae8","remaining_size":"0.03677774","product_id":"BTC-EUR","sequence":3257978725,"time":"2018-01-22T15:14:42.515000Z"}
{"type":"received","order_id":"8439e56a-90f4-43b4-b936-55189fc8965b","order_type":"limit","size":"0.06847422","price":"8827.30000000","side":"sell","client_oid":"48773eee-436b-4f87-8c69-2ad846646324","product_id":"BTC-EUR","sequence":3257978726,"time":"2018-01-22T15:14:42.519000Z"}
{"type":"open","side":"sell","price":"8827.30000000","order_id":"8439e56a-90f4-43b4-b936-55189fc8965b","remaining_size":"0.06847422","product_id":"BTC-EUR","sequence":3257978727,"time":"2018-01-22T15:14:42.519000Z"}
{"type":"done","side":"buy","order_id":"5ff9348a-e2a7-4864-9ab1-085abfbf5ae8","reason":"canceled","product_id":"BTC-EUR","price":"8825.30000000","remaining_size":"0.03677774","sequence":3257978728,"time":"2018-01-22T15:14:42.527000Z"}
{"type":"received","order_id":"e1671032-6075-4fc8-8058-af45a80e1b42","order_type":"limit","size":"0.06847422","price":"8827.29000000","side":"sell","client_oid":"cd132ef6-f51d-4934-bd11-08e4af9ef938","product_id":"BTC-EUR","sequence":3257978729,"time":"2018-01-22T15:14:42.527000Z"}
{"type":"open","side":"sell","price":"8827.29000000","order_id":"e1671032-6075-4fc8-8058-af45a80e1b42","remaining_size":"0.06847422","product_id":"BTC-EUR","sequence":3257978730,"time":"2018-01-22T15:14:42.527000Z"}
{"type":"received","order_id":"30cf5ce3-1f1c-4004-b011-ce1fc1300d14","order_type":"limit","size":"0.01800000","price":"8827.28000000","side":"sell","client_oid":"d51bdf9d-a169-4b1f-b5e6-7ac999efb870","product_id":"BTC-EUR","sequence":3257978731,"time":"2018-01-22T15:14:42.529000Z"}
{"type":"open","side":"sell","price":"8827.28000000","order_id":"30cf5ce3-1f1c-4004-b011-ce1fc1300d14","remaining_size":"0.01800000","product_id":"BTC-EUR","sequence":3257978732,"time":"2018-01-22T15:14:42.529000Z"}
{"type":"received","order_id":"5a8413c3-f1bd-493a-8453-bb78df2423c7","order_type":"limit","size":"0.06847422","price":"8827.29000000","side":"sell","client_oid":"ed9b4703-6ed0-4217-8e3d-8a5019fe5ade","product_id":"BTC-EUR","sequence":3257978733,"time":"2018-01-22T15:14:42.531000Z"}
{"type":"open","side":"sell","price":"8827.29000000","order_id":"5a8413c3-f1bd-493a-8453-bb78df2423c7","remaining_size":"0.06847422","product_id":"BTC-EUR","sequence":3257978734,"time":"2018-01-22T15:14:42.531000Z"}
{"type":"done","side":"sell","order_id":"a8b1d379-7ffb-49c6-93b7-ae99194ece0f","reason":"canceled","product_id":"BTC-EUR","price":"8827.29000000","remaining_size":"0.00113290","sequence":3257978735,"time":"2018-01-22T15:14:42.542000Z"}
{"type":"received","order_id":"ab6f4f36-4450-4d28-93f7-a0e2f2d1b334","order_type":"limit","size":"0.01800000","price":"8827.28000000","side":"sell","client_oid":"ccd35a04-0994-4e9b-a234-8f1a3ad44d4d","product_id":"BTC-EUR","sequence":3257978736,"time":"2018-01-22T15:14:42.544000Z"}
{"type":"open","side":"sell","price":"8827.28000000","order_id":"ab6f4f36-4450-4d28-93f7-a0e2f2d1b334","remaining_size":"0.01800000","product_id":"BTC-EUR","sequence":3257978737,"time":"2018-01-22T15:14:42.544000Z"}
{"type":"received","order_id":"fca25b78-9a08-4b75-8e35-65b23c954bda","order_type":"limit","size":"0.01800000","price":"8827.28000000","side":"sell","client_oid":"ecb0cba5-2071-4ab2-9d88-faec8643c481","product_id":"BTC-EUR","sequence":3257978738,"time":"2018-01-22T15:14:42.553000Z"}
{"type":"open","side":"sell","price":"8827.28000000","order_id":"fca25b78-9a08-4b75-8e35-65b23c954bda","remaining_size":"0.01800000","product_id":"BTC-EUR","sequence":3257978739,"time":"2018-01-22T15:14:42.553000Z"}
{"type":"received","order_id":"8056ec01-80e9-4cc9-95e1-50c66b1c3c63","order_type":"limit","size":"0.01731400","price":"8826.62000000","side":"sell","product_id":"BTC-EUR","sequence":3257978740,"time":"2018-01-22T15:14:42.560000Z"}
{"type":"open","side":"sell","price":"8826.62000000","order_id":"8056ec01-80e9-4cc9-95e1-50c66b1c3c63","remaining_size":"0.01731400","product_id":"BTC-EUR","sequence":3257978741,"time":"2018-01-22T15:14:42.560000Z"}
{"type":"received","order_id":"56a8b0a9-4693-440e-90d0-0b8046cf41f3","order_type":"limit","size":"0.03677774","price":"8825.30000000","side":"buy","client_oid":"2fd788bb-d359-449d-81b4-c377aa333877","product_id":"BTC-EUR","sequence":3257978742,"time":"2018-01-22T15:14:42.560000Z"}
{"type":"open","side":"buy","price":"8825.30000000","order_id":"56a8b0a9-4693-440e-90d0-0b8046cf41f3","remaining_size":"0.03677774","product_id":"BTC-EUR","sequence":3257978743,"time":"2018-01-22T15:14:42.560000Z"}
{"type":"received","order_id":"4826511d-f295-4bf9-a652-bf0dc3fbbf2e","order_type":"limit","size":"0.00799999","price":"8827.28000000","side":"sell","client_oid":"cf5aebe2-c9e1-43a3-b09a-3d400986e0f0","product_id":"BTC-EUR","sequence":3257978744,"time":"2018-01-22T15:14:42.560000Z"}
{"type":"open","side":"sell","price":"8827.28000000","order_id":"4826511d-f295-4bf9-a652-bf0dc3fbbf2e","remaining_size":"0.00799999","product_id":"BTC-EUR","sequence":3257978745,"time":"2018-01-22T15:14:42.560000Z"}
{"type":"done","side":"sell","order_id":"ffba62c3-6b4e-485e-9252-8d2e7d2ca53e","reason":"canceled","product_id":"BTC-EUR","price":"8827.29000000","remaining_size":"0.03322226","sequence":3257978746,"time":"2018-01-22T15:14:42.562000Z"}
{"type":"received","order_id":"24402946-a949-42d3-9f72-e19d81ac7e92","order_type":"limit","size":"0.00113290","price":"8827.27000000","side":"sell","client_oid":"84c098ee-5d8c-4a0a-ba15-d2a6dda4d175","product_id":"BTC-EUR","sequence":3257978747,"time":"2018-01-22T15:14:42.583000Z"}
{"type":"open","side":"sell","price":"8827.27000000","order_id":"24402946-a949-42d3-9f72-e19d81ac7e92","remaining_size":"0.00113290","product_id":"BTC-EUR","sequence":3257978748,"time":"2018-01-22T15:14:42.583000Z"}
{"type":"done","side":"sell","order_id":"24402946-a949-42d3-9f72-e19d81ac7e92","reason":"canceled","product_id":"BTC-EUR","price":"8827.27000000","remaining_size":"0.00113290","sequence":3257978749,"time":"2018-01-22T15:14:42.587000Z"}
{"type":"done","side":"buy","order_id":"56a8b0a9-4693-440e-90d0-0b8046cf41f3","reason":"canceled","product_id":"BTC-EUR","price":"8825.30000000","remaining_size":"0.03677774","sequence":3257978750,"time":"2018-01-22T15:14:42.589000Z"}
{"type":"done","side":"sell","order_id":"5ba99b42-fdb2-41f1-9737-c5f8fe3c646b","reason":"canceled","product_id":"BTC-EUR","price":"8827.29000000","remaining_size":"0.00800000","sequence":3257978751,"time":"2018-01-22T15:14:42.608000Z"}
{"type":"received","order_id":"88232700-12d4-4059-8f13-0ae367c40d69","order_type":"limit","size":"0.03322226","price":"8827.27000000","side":"sell","client_oid":"d04eaf61-8e8b-4a11-8f92-1b3fca76afee","product_id":"BTC-EUR","sequence":3257978752,"time":"2018-01-22T15:14:42.608000Z"}
{"type":"open","side":"sell","price":"8827.27000000","order_id":"88232700-12d4-4059-8f13-0ae367c40d69","remaining_size":"0.03322226","product_id":"BTC-EUR","sequence":3257978753,"time":"2018-01-22T15:14:42.608000Z"}
{"type":"done","side":"sell","order_id":"5c7ca091-c382-4f9c-b956-77bc9d400ecd","reason":"canceled","product_id":"BTC-EUR","price":"8827.29000000","remaining_size":"0.10500000","sequence":3257978754,"time":"2018-01-22T15:14:42.608000Z"}
{"type":"done","side":"sell","order_id":"4a7e5f22-1cdb-4c83-a756-5c10cef224f0","reason":"canceled","product_id":"BTC-EUR","price":"8827.30000000","remaining_size":"0.06847422","sequence":3257978755,"time":"2018-01-22T15:14:42.613000Z"}
{"type":"done","side":"sell","order_id":"e8a97650-4769-410c-b285-524ba5295f21","reason":"canceled","product_id":"BTC-EUR","price":"8827.30000000","remaining_size":"0.06847422","sequence":3257978756,"time":"2018-01-22T15:14:42.613000Z"}
{"type":"received","order_id":"6e78ab4d-4a4a-443f-b6d9-853fc8c63dd7","order_type":"limit","size":"0.10500000","price":"8827.28000000","side":"sell","client_oid":"750fe991-5496-42b0-9f78-e05a1762bb9b","product_id":"BTC-EUR","sequence":3257978757,"time":"2018-01-22T15:14:42.630000Z"}
{"type":"open","side":"sell","price":"8827.28000000","order_id":"6e78ab4d-4a4a-443f-b6d9-853fc8c63dd7","remaining_size":"0.10500000","product_id":"BTC-EUR","sequence":3257978758,"time":"2018-01-22T15:14:42.630000Z"}
{"type":"done","side":"sell","order_id":"30cf5ce3-1f1c-4004-b011-ce1fc1300d14","reason":"canceled","product_id":"BTC-EUR","price":"8827.28000000","remaining_size":"0.01800000","sequence":3257978759,"time":"2018-01-22T15:14:42.646000Z"}
{"type":"received","order_id":"3dc32908-d58c-40be-afc4-43fd102cbc85","order_type":"limit","size":"0.00800000","price":"8827.27000000","side":"sell","client_oid":"b74eaeb9-4b67-4e32-84ec-851816588ef9","product_id":"BTC-EUR","sequence":3257978760,"time":"2018-01-22T15:14:42.661000Z"}
{"type":"open","side":"sell","price":"8827.27000000","order_id":"3dc32908-d58c-40be-afc4-43fd102cbc85","remaining_size":"0.00800000","product_id":"BTC-EUR","sequence":3257978761,"time":"2018-01-22T15:14:42.661000Z"}
{"type":"received","order_id":"cd9e061e-8bba-4412-b7d1-90f33c023094","order_type":"limit","size":"0.00113290","price":"8826.61000000","side":"sell","client_oid":"75d90c5e-9c77-4d4d-85d6-e5143c98983f","product_id":"BTC-EUR","sequence":3257978762,"time":"2018-01-22T15:14:42.664000Z"}
{"type":"open","side":"sell","price":"8826.61000000","order_id":"cd9e061e-8bba-4412-b7d1-90f33c023094","remaining_size":"0.00113290","product_id":"BTC-EUR","sequence":3257978763,"time":"2018-01-22T15:14:42.664000Z"}
{"type":"received","order_id":"fcd8d91d-9394-410c-990c-f773f998092c","order_type":"limit","size":"0.01800000","price":"8826.61000000","side":"sell","client_oid":"0002f79d-3c40-4830-90d5-08da9ea9398b","product_id":"BTC-EUR","sequence":3257978764,"time":"2018-01-22T15:14:42.667000Z"}
{"type":"open","side":"sell","price":"8826.61000000","order_id":"fcd8d91d-9394-410c-990c-f773f998092c","remaining_size":"0.01800000","product_id":"BTC-EUR","sequence":3257978765,"time":"2018-01-22T15:14:42.667000Z"}
{"type":"done","side":"sell","order_id":"3c31a693-baa2-42b2-b4fd-aab2575cb058","reason":"canceled","product_id":"BTC-EUR","price":"8828.32000000","remaining_size":"0.04164971","sequence":3257978766,"time":"2018-01-22T15:14:42.671000Z"}
{"type":"done","side":"sell","order_id":"fca25b78-9a08-4b75-8e35-65b23c954bda","reason":"canceled","product_id":"BTC-EUR","price":"8827.28000000","remaining_size":"0.01800000","sequence":3257978767,"time":"2018-01-22T15:14:42.688000Z"}
{"type":"done","side":"sell","order_id":"ab6f4f36-4450-4d28-93f7-a0e2f2d1b334","reason":"canceled","product_id":"BTC-EUR","price":"8827.28000000","remaining_size":"0.01800000","sequence":3257978768,"time":"2018-01-22T15:14:42.688000Z"}
{"type":"received","order_id":"23e0708c-5e26-4750-962d-601f1a876e06","order_type":"limit","size":"0.01800000","price":"8826.61000000","side":"sell","client_oid":"5e216595-fa19-41ef-a15c-bccd11c191f1","product_id":"BTC-EUR","sequence":3257978769,"time":"2018-01-22T15:14:42.705000Z"}
{"type":"open","side":"sell","price":"8826.61000000","order_id":"23e0708c-5e26-4750-962d-601f1a876e06","remaining_size":"0.01800000","product_id":"BTC-EUR","sequence":3257978770,"time":"2018-01-22T15:14:42.705000Z"}
{"type":"done","side":"sell","order_id":"6e78ab4d-4a4a-443f-b6d9-853fc8c63dd7","reason":"canceled","product_id":"BTC-EUR","price":"8827.28000000","remaining_size":"0.10500000","sequence":3257978771,"time":"2018-01-22T15:14:42.705000Z"}
{"type":"done","side":"sell","order_id":"88232700-12d4-4059-8f13-0ae367c40d69","reason":"canceled","product_id":"BTC-EUR","price":"8827.27000000","remaining_size":"0.03322226","sequence":3257978772,"time":"2018-01-22T15:14:42.711000Z"}
{"type":"done","side":"sell","order_id":"8056ec01-80e9-4cc9-95e1-50c66b1c3c63","reason":"canceled","product_id":"BTC-EUR","price":"8826.62000000","remaining_size":"0.01731400","sequence":3257978773,"time":"2018-01-22T15:14:42.723000Z"}
{"type":"done","side":"sell","order_id":"4826511d-f295-4bf9-a652-bf0dc3fbbf2e","reason":"canceled","product_id":"BTC-EUR","price":"8827.28000000","remaining_size":"0.00799999","sequence":3257978774,"time":"2018-01-22T15:14:42.723000Z"}
{"type":"received","order_id":"61b393d9-e427-41e9-af5e-763eb9961bde","order_type":"limit","size":"0.10500000","price":"8826.62000000","side":"sell","client_oid":"521ea981-85fc-4656-b1f3-6739280ffa50","product_id":"BTC-EUR","sequence":3257978775,"time":"2018-01-22T15:14:42.726000Z"}
{"type":"open","side":"sell","price":"8826.62000000","order_id":"61b393d9-e427-41e9-af5e-763eb9961bde","remaining_size":"0.10500000","product_id":"BTC-EUR","sequence":3257978776,"time":"2018-01-22T15:14:42.726000Z"}
{"type":"received","order_id":"1ff0e28b-a3ce-4b57-a7ac-7fb00979b620","order_type":"limit","size":"0.03322226","price":"8826.60000000","side":"sell","client_oid":"34239374-ddec-4eb4-9249-355f84667bcf","product_id":"BTC-EUR","sequence":3257978777,"time":"2018-01-22T15:14:42.729000Z"}
{"type":"open","side":"sell","price":"8826.60000000","order_id":"1ff0e28b-a3ce-4b57-a7ac-7fb00979b620","remaining_size":"0.03322226","product_id":"BTC-EUR","sequence":3257978778,"time":"2018-01-22T15:14:42.729000Z"}
{"type":"done","side":"sell","order_id":"e1671032-6075-4fc8-8058-af45a80e1b42","reason":"canceled","product_id":"BTC-EUR","price":"8827.29000000","remaining_size":"0.06847422","sequence":3257978779,"time":"2018-01-22T15:14:42.731000Z"}
{"type":"done","side":"sell","order_id":"5a8413c3-f1bd-493a-8453-bb78df2423c7","reason":"canceled","product_id":"BTC-EUR","price":"8827.29000000","remaining_size":"0.06847422","sequence":3257978780,"time":"2018-01-22T15:14:42.731000Z"}
{"type":"done","side":"sell","order_id":"8439e56a-90f4-43b4-b936-55189fc8965b","reason":"canceled","product_id":"BTC-EUR","price":"8827.30000000","remaining_size":"0.06847422","sequence":3257978781,"time":"2018-01-22T15:14:42.733000Z"}
{"type":"received","order_id":"e39a52c0-37da-4603-b4af-ac72dec54b78","order_type":"limit","size":"0.06847422","price":"8826.61000000","side":"sell","client_oid":"70c012e9-7a55-4ccb-b34e-7be49044b0d1","product_id":"BTC-EUR","sequence":3257978782,"time":"2018-01-22T15:14:42.740000Z"}
{"type":"open","side":"sell","price":"8826.61000000","order_id":"e39a52c0-37da-4603-b4af-ac72dec54b78","remaining_size":"0.06847422","product_id":"BTC-EUR","sequence":3257978783,"time":"2018-01-22T15:14:42.740000Z"}
{"type":"received","order_id":"fb87bab9-2602-4c46-a522-8cab0c6953be","order_type":"limit","size":"0.21404538","price":"8826.61000000","side":"sell","product_id":"BTC-EUR","sequence":3257978784,"time":"2018-01-22T15:14:42.745000Z"}
{"type":"open","side":"sell","price":"8826.61000000","order_id":"fb87bab9-2602-4c46-a522-8cab0c6953be","remaining_size":"0.21404538","product_id":"BTC-EUR","sequence":3257978785,"time":"2018-01-22T15:14:42.745000Z"}
{"type":"done","side":"sell","order_id":"3dc32908-d58c-40be-afc4-43fd102cbc85","reason":"canceled","product_id":"BTC-EUR","price":"8827.27000000","remaining_size":"0.00800000","sequence":3257978786,"time":"2018-01-22T15:14:42.761000Z"}
{"type":"done","side":"sell","order_id":"b404efcf-7c72-4692-9e10-821a72d3cee8","reason":"canceled","product_id":"BTC-EUR","price":"8943.69000000","remaining_size":"0.75000000","sequence":3257978787,"time":"2018-01-22T15:14:42.763000Z"}
{"type":"done","side":"sell","order_id":"b6cd4721-b631-46de-9c4c-7fc9401bfeed","reason":"canceled","product_id":"BTC-EUR","price":"8828.32000000","remaining_size":"0.00564464","sequence":3257978788,"time":"2018-01-22T15:14:42.763000Z"}
{"type":"done","side":"sell","order_id":"cd9e061e-8bba-4412-b7d1-90f33c023094","reason":"canceled","product_id":"BTC-EUR","price":"8826.61000000","remaining_size":"0.00113290","sequence":3257978789,"time":"2018-01-22T15:14:42.768000Z"}
{"type":"done","side":"buy","order_id":"4d1ed166-0970-460e-99c0-11d519168769","reason":"canceled","product_id":"BTC-EUR","price":"8810.69000000","remaining_size":"0.49000000","sequence":3257978790,"time":"2018-01-22T15:14:42.775000Z"}
{"type":"done","side":"sell","order_id":"0af6d1e9-9708-4af9-ad3a-c59939e0984d","reason":"canceled","product_id":"BTC-EUR","price":"8850.49000000","remaining_size":"0.25000000","sequence":3257978791,"time":"2018-01-22T15:14:42.775000Z"}
{"type":"received","order_id":"72d4d54f-10b9-49f0-9cc4-4a70d70b884b","order_type":"limit","size":"0.00800000","price":"8826.61000000","side":"sell","client_oid":"7ad3ffc8-45e6-4ea3-a87b-e751a5fae9e6","product_id":"BTC-EUR","sequence":3257978792,"time":"2018-01-22T15:14:42.782000Z"}
{"type":"open","side":"sell","price":"8826.61000000","order_id":"72d4d54f-10b9-49f0-9cc4-4a70d70b884b","remaining_size":"0.00800000","product_id":"BTC-EUR","sequence":3257978793,"time":"2018-01-22T15:14:42.782000Z"}
{"type":"done","side":"sell","order_id":"b7f60151-1d63-4c10-a7e6-b8527802d2a5","reason":"canceled","product_id":"BTC-EUR","price":"9036.89000000","remaining_size":"0.75000000","sequence":3257978794,"time":"2018-01-22T15:14:42.797000Z"}
{"type":"done","side":"buy","order_id":"0478a667-a72e-4b93-aa24-870916fc975d","reason":"canceled","product_id":"BTC-EUR","price":"8717.49000000","remaining_size":"0.75000000","sequence":3257978795,"time":"2018-01-22T15:14:42.797000Z"}
{"type":"done","side":"sell","order_id":"161d9b15-d542-4ed8-8ace-dd731e5abc31","reason":"canceled","product_id":"BTC-EUR","price":"9130.09000000","remaining_size":"0.75000000","sequence":3257978796,"time":"2018-01-22T15:14:42.801000Z"}
{"type":"done","side":"buy","order_id":"5b2e2050-2e91-4f00-bd60-4be01376bada","reason":"canceled","product_id":"BTC-EUR","price":"8624.29000000","remaining_size":"0.75000000","sequence":3257978797,"time":"2018-01-22T15:14:42.801000Z"}
{"type":"done","side":"sell","order_id":"47e3a65e-7926-49af-bb50-f97f9b593146","reason":"canceled","product_id":"BTC-EUR","price":"9223.29000000","remaining_size":"0.74000000","sequence":3257978798,"time":"2018-01-22T15:14:42.807000Z"}
{"type":"done","side":"buy","order_id":"ca5e5349-7254-490f-9aa7-eaff9571103e","reason":"canceled","product_id":"BTC-EUR","price":"8531.09000000","remaining_size":"0.74000000","sequence":3257978799,"time":"2018-01-22T15:14:42.807000Z"}
{"type":"done","side":"sell","order_id":"7692db9e-5218-4950-881c-2fedfe3ada7e","reason":"canceled","product_id":"BTC-EUR","price":"9316.49000000","remaining_size":"0.75000000","sequence":3257978800,"time":"2018-01-22T15:14:42.824000Z"}
{"type":"done","side":"buy","order_id":"7d71984b-12d2-462a-b765-b923ad427b85","reason":"canceled","product_id":"BTC-EUR","price":"8437.89000000","remaining_size":"0.75000000","sequence":3257978801,"time":"2018-01-22T15:14:42.825000Z"}
{"type":"done","side":"sell","order_id":"123bae03-98aa-4762-a712-8effa5bcaa25","reason":"canceled","product_id":"BTC-EUR","price":"9409.69000000","remaining_size":"0.75000000","sequence":3257978802,"time":"2018-01-22T15:14:42.830000Z"}
{"type":"done","side":"buy","order_id":"ccbce712-7093-47b0-bf99-856686ea2d77","reason":"canceled","product_id":"BTC-EUR","price":"8344.69000000","remaining_size":"0.75000000","sequence":3257978803,"time":"2018-01-22T15:14:42.831000Z"}
{"type":"done","side":"sell","order_id":"aad2cfb4-3ea4-440e-ab5f-420466038929","reason":"canceled","product_id":"BTC-EUR","price":"9502.89000000","remaining_size":"0.75000000","sequence":3257978804,"time":"2018-01-22T15:14:42.834000Z"}
{"type":"done","side":"buy","order_id":"5c05b690-4b0b-45b6-bc9f-26896ad4b375","reason":"canceled","product_id":"BTC-EUR","price":"8251.49000000","remaining_size":"0.75000000","sequence":3257978805,"time":"2018-01-22T15:14:42.834000Z"}
{"type":"done","side":"sell","order_id":"23e0708c-5e26-4750-962d-601f1a876e06","reason":"canceled","product_id":"BTC-EUR","price":"8826.61000000","remaining_size":"0.01800000","sequence":3257978806,"time":"2018-01-22T15:14:42.834000Z"}
{"type":"done","side":"sell","order_id":"fae0d7f2-d107-40cb-a6f6-8270b159d3f2","reason":"canceled","product_id":"BTC-EUR","price":"9596.09000000","remaining_size":"0.74000000","sequence":3257978807,"time":"2018-01-22T15:14:42.836000Z"}
{"type":"done","side":"buy","order_id":"e05447d8-6861-407c-aaf9-4ba1b54e85bb","reason":"canceled","product_id":"BTC-EUR","price":"8158.29000000","remaining_size":"0.74000000","sequence":3257978808,"time":"2018-01-22T15:14:42.836000Z"}
{"type":"done","side":"sell","order_id":"94af149f-e48e-42f2-aa24-60cb71279cbe","reason":"canceled","product_id":"BTC-EUR","price":"9689.29000000","remaining_size":"0.75000000","sequence":3257978809,"time":"2018-01-22T15:14:42.838000Z"}
{"type":"done","side":"buy","order_id":"e8ea907f-d01f-416a-9564-67028e6657f8","reason":"canceled","product_id":"BTC-EUR","price":"8065.09000000","remaining_size":"0.75000000","sequence":3257978810,"time":"2018-01-22T15:14:42.838000Z"}
{"type":"done","side":"sell","order_id":"a37d3f49-ff21-4c83-ac6e-73cfeafd4f2e","reason":"canceled","product_id":"BTC-EUR","price":"9782.49000000","remaining_size":"0.75000000","sequence":3257978811,"time":"2018-01-22T15:14:42.839000Z"}
{"type":"done","side":"buy","order_id":"57aee3b1-1361-473d-9695-c0bb17fcb1dc","reason":"canceled","product_id":"BTC-EUR","price":"7971.89000000","remaining_size":"0.75000000","sequence":3257978812,"time":"2018-01-22T15:14:42.839000Z"}
{"type":"done","side":"sell","order_id":"61b393d9-e427-41e9-af5e-763eb9961bde","reason":"canceled","product_id":"BTC-EUR","price":"8826.62000000","remaining_size":"0.10500000","sequence":3257978813,"time":"2018-01-22T15:14:42.840000Z"}
{"type":"received","order_id":"195a1723-2295-479c-b179-c3fe25351698","order_type":"limit","size":"0.49000000","price":"8806.99000000","side":"buy","client_oid":"151c5097-b181-48c3-be35-d45cf225562b","product_id":"BTC-EUR","sequence":3257978814,"time":"2018-01-22T15:14:42.840000Z"}
{"type":"open","side":"buy","price":"8806.99000000","order_id":"195a1723-2295-479c-b179-c3fe25351698","remaining_size":"0.49000000","product_id":"BTC-EUR","sequence":3257978815,"time":"2018-01-22T15:14:42.840000Z"}
{"type":"received","order_id":"1a9b7b52-a97f-459a-8687-db5fd33973a8","order_type":"limit","size":"0.75000000","price":"9033.09000000","side":"sell","client_oid":"3db0776c-5e93-44cf-8a4c-3688e522f7c8","product_id":"BTC-EUR","sequence":3257978816,"time":"2018-01-22T15:14:42.840000Z"}
{"type":"open","side":"sell","price":"9033.09000000","order_id":"1a9b7b52-a97f-459a-8687-db5fd33973a8","remaining_size":"0.75000000","product_id":"BTC-EUR","sequence":3257978817,"time":"2018-01-22T15:14:42.840000Z"}
{"type":"received","order_id":"1eded325-5459-4737-b33a-fa022c1adc0e","order_type":"limit","size":"0.75000000","price":"8713.89000000","side":"buy","client_oid":"b3ce4884-3c79-4a9b-b6d4-2ae7f69aa61e","product_id":"BTC-EUR","sequence":3257978818,"time":"2018-01-22T15:14:42.844000Z"}
{"type":"open","side":"buy","price":"8713.89000000","order_id":"1eded325-5459-4737-b33a-fa022c1adc0e","remaining_size":"0.75000000","product_id":"BTC-EUR","sequence":3257978819,"time":"2018-01-22T15:14:42.844000Z"}
{"type":"received","order_id":"aed2b4a9-66d3-4413-8b5b-5fadb7f27ecb","order_type":"limit","size":"0.25000000","price":"8846.89000000","side":"sell","client_oid":"4f6e62bb-31e9-4f38-95e4-8b7ce9ee6a23","product_id":"BTC-EUR","sequence":3257978820,"time":"2018-01-22T15:14:42.844000Z"}
{"type":"open","side":"sell","price":"8846.89000000","order_id":"aed2b4a9-66d3-4413-8b5b-5fadb7f27ecb","remaining_size":"0.25000000","product_id":"BTC-EUR","sequence":3257978821,"time":"2018-01-22T15:14:42.844000Z"}
{"type":"received","order_id":"3c3d7759-be2b-4fe5-8f9f-de55fa00c3a0","order_type":"limit","size":"0.01800000","price":"8826.60000000","side":"sell","client_oid":"dee22a15-bf67-4dc3-81bd-580b5dd28d0a","product_id":"BTC-EUR","sequence":3257978822,"time":"2018-01-22T15:14:42.844000Z"}
{"type":"open","side":"sell","price":"8826.60000000","order_id":"3c3d7759-be2b-4fe5-8f9f-de55fa00c3a0","remaining_size":"0.01800000","product_id":"BTC-EUR","sequence":3257978823,"time":"2018-01-22T15:14:42.844000Z"}
{"type":"received","order_id":"9a05e736-73d6-4444-9878-686ad6e66df8","order_type":"limit","size":"0.20710000","price":"8794.43000000","side":"buy","product_id":"BTC-EUR","sequence":3257978824,"time":"2018-01-22T15:14:42.844000Z"}
{"type":"open","side":"buy","price":"8794.43000000","order_id":"9a05e736-73d6-4444-9878-686ad6e66df8","remaining_size":"0.20710000","product_id":"BTC-EUR","sequence":3257978825,"time":"2018-01-22T15:14:42.844000Z"}
{"type":"received","order_id":"d27635f5-219d-45e9-89b0-43c10e0a59e8","order_type":"limit","size":"0.75000000","price":"8939.99000000","side":"sell","client_oid":"92f39af9-33f7-4882-a3ec-f03ba7aee544","product_id":"BTC-EUR","sequence":3257978826,"time":"2018-01-22T15:14:42.845000Z"}
{"type":"open","side":"sell","price":"8939.99000000","order_id":"d27635f5-219d-45e9-89b0-43c10e0a59e8","remaining_size":"0.75000000","product_id":"BTC-EUR","sequence":3257978827,"time":"2018-01-22T15:14:42.845000Z"}
{"type":"received","order_id":"650ad18f-3e95-4638-9051-eb1be2b71cae","order_type":"limit","size":"0.74000000","price":"8527.69000000","side":"buy","client_oid":"195c8230-8f46-47d0-aaeb-79e0f4e5b5ef","product_id":"BTC-EUR","sequence":3257978828,"time":"2018-01-22T15:14:42.847000Z"}
{"type":"open","side":"buy","price":"8527.69000000","order_id":"650ad18f-3e95-4638-9051-eb1be2b71cae","remaining_size":"0.74000000","product_id":"BTC-EUR","sequence":3257978829,"time":"2018-01-22T15:14:42.847000Z"}
{"type":"received","order_id":"66929f75-b80a-4a5c-95e0-c82aa0d85800","order_type":"limit","size":"0.75000000","price":"9312.39000000","side":"sell","client_oid":"a08a5c5d-1c44-46ca-a725-4adac2a8ac1e","product_id":"BTC-EUR","sequence":3257978830,"time":"2018-01-22T15:14:42.851000Z"}
{"type":"open","side":"sell","price":"9312.39000000","order_id":"66929f75-b80a-4a5c-95e0-c82aa0d85800","remaining_size":"0.75000000","product_id":"BTC-EUR","sequence":3257978831,"time":"2018-01-22T15:14:42.851000Z"}
{"type":"received","order_id":"94912490-1429-4ad6-ac5c-ef31a327230d","order_type":"limit","size":"0.75000000","price":"9405.49000000","side":"sell","client_oid":"f6ccfd9e-95c5-4187-9e06-8052e6ed422c","product_id":"BTC-EUR","sequence":3257978832,"time":"2018-01-22T15:14:42.860000Z"}
{"type":"open","side":"sell","price":"9405.49000000","order_id":"94912490-1429-4ad6-ac5c-ef31a327230d","remaining_size":"0.75000000","product_id":"BTC-EUR","sequence":3257978833,"time":"2018-01-22T15:14:42.860000Z"}
{"type":"received","order_id":"52a987c4-28c0-4fd3-a448-0bb8603f3dd4","order_type":"limit","size":"0.00113290","price":"8826.59000000","side":"sell","client_oid":"f5efd822-c482-4711-8298-97f97b338ac9","product_id":"BTC-EUR","sequence":3257978834,"time":"2018-01-22T15:14:42.860000Z"}
{"type":"open","side":"sell","price":"8826.59000000","order_id":"52a987c4-28c0-4fd3-a448-0bb8603f3dd4","remaining_size":"0.00113290","product_id":"BTC-EUR","sequence":3257978835,"time":"2018-01-22T15:14:42.860000Z"}
{"type":"received","order_id":"252e1b20-2d73-4138-ab52-8578d5ea7268","order_type":"limit","size":"0.01800000","price":"8826.59000000","side":"sell","client_oid":"f03d1372-4d64-455d-be84-ed1b7a25a4fa","product_id":"BTC-EUR","sequence":3257978836,"time":"2018-01-22T15:14:42.862000Z"}
{"type":"open","side":"sell","price":"8826.59000000","order_id":"252e1b20-2d73-4138-ab52-8578d5ea7268","remaining_size":"0.01800000","product_id":"BTC-EUR","sequence":3257978837,"time":"2018-01-22T15:14:42.862000Z"}
{"type":"received","order_id":"72afd8b0-2535-410c-90ab-dc54834c1213","order_type":"limit","size":"0.06847422","price":"8826.60000000","side":"sell","client_oid":"72aad284-b92f-479f-a1bd-ad9269614a0c","product_id":"BTC-EUR","sequence":3257978838,"time":"2018-01-22T15:14:42.862000Z"}
{"type":"open","side":"sell","price":"8826.60000000","order_id":"72afd8b0-2535-410c-90ab-dc54834c1213","remaining_size":"0.06847422","product_id":"BTC-EUR","sequence":3257978839,"time":"2018-01-22T15:14:42.862000Z"}
{"type":"done","side":"sell","order_id":"fb87bab9-2602-4c46-a522-8cab0c6953be","reason":"canceled","product_id":"BTC-EUR","price":"8826.61000000","remaining_size":"0.21404538","sequence":3257978840,"time":"2018-01-22T15:14:42.864000Z"}
{"type":"done","side":"sell","order_id":"fcd8d91d-9394-410c-990c-f773f998092c","reason":"canceled","product_id":"BTC-EUR","price":"8826.61000000","remaining_size":"0.01800000","sequence":3257978841,"time":"2018-01-22T15:14:42.868000Z"}
{"type":"received","order_id":"715e00b4-2f11-48ed-99a1-173bb10f2790","order_type":"limit","size":"0.74000000","price":"8155.29000000","side":"buy","client_oid":"5cb9baae-eddd-48b0-9c3e-2f171a833e47","product_id":"BTC-EUR","sequence":3257978842,"time":"2018-01-22T15:14:42.882000Z"}
{"type":"open","side":"buy","price":"8155.29000000","order_id":"715e00b4-2f11-48ed-99a1-173bb10f2790","remaining_size":"0.74000000","product_id":"BTC-EUR","sequence":3257978843,"time":"2018-01-22T15:14:42.882000Z"}
{"type":"received","order_id":"40346d48-3e2b-49b2-a235-4e6b8bd320b6","order_type":"limit","size":"0.75000000","price":"8248.39000000","side":"buy","client_oid":"9636f144-cc7f-40a3-9928-26f547dc6770","product_id":"BTC-EUR","sequence":3257978844,"time":"2018-01-22T15:14:42.889000Z"}
{"type":"open","side":"buy","price":"8248.39000000","order_id":"40346d48-3e2b-49b2-a235-4e6b8bd320b6","remaining_size":"0.75000000","product_id":"BTC-EUR","sequence":3257978845,"time":"2018-01-22T15:14:42.889000Z"}
{"type":"received","order_id":"545ba26c-f003-40ac-87df-1c9f0638a4fa","order_type":"limit","size":"0.75000000","price":"8620.79000000","side":"buy","client_oid":"075dca6b-4c8c-437f-bf05-73781f9b1cfc","product_id":"BTC-EUR","sequence":3257978846,"time":"2018-01-22T15:14:42.913000Z"}
{"type":"open","side":"buy","price":"8620.79000000","order_id":"545ba26c-f003-40ac-87df-1c9f0638a4fa","remaining_size":"0.75000000","product_id":"BTC-EUR","sequence":3257978847,"time":"2018-01-22T15:14:42.913000Z"}
{"type":"received","order_id":"44c0e53b-5676-4cfa-9317-0f6646a1a947","order_type":"limit","size":"0.75000000","price":"8341.49000000","side":"buy","client_oid":"6c74e301-db9f-4573-a62d-502ae37acbdb","product_id":"BTC-EUR","sequence":3257978848,"time":"2018-01-22T15:14:42.920000Z"}
{"type":"open","side":"buy","price":"8341.49000000","order_id":"44c0e53b-5676-4cfa-9317-0f6646a1a947","remaining_size":"0.75000000","product_id":"BTC-EUR","sequence":3257978849,"time":"2018-01-22T15:14:42.920000Z"}
{"type":"done","side":"sell","order_id":"d27635f5-219d-45e9-89b0-43c10e0a59e8","reason":"canceled","product_id":"BTC-EUR","price":"8939.99000000","remaining_size":"0.75000000","sequence":3257978850,"time":"2018-01-22T15:14:42.926000Z"}
{"type":"received","order_id":"c3f89f74-fa01-42f5-8b11-c212a75e9d1e","order_type":"limit","size":"0.75000000","price":"8434.59000000","side":"buy","client_oid":"bd11dc58-ae20-4377-8600-223622ac1c55","product_id":"BTC-EUR","sequence":3257978851,"time":"2018-01-22T15:14:42.928000Z"}
{"type":"open","side":"buy","price":"8434.59000000","order_id":"c3f89f74-fa01-42f5-8b11-c212a75e9d1e","remaining_size":"0.75000000","product_id":"BTC-EUR","sequence":3257978852,"time":"2018-01-22T15:14:42.928000Z"}
{"type":"received","order_id":"dbec7f50-cb03-4bef-9c76-17bb8a876ceb","order_type":"limit","size":"0.75000000","price":"9777.89000000","side":"sell","client_oid":"98a91390-1ed1-48e9-9533-6cb9bf7b1964","product_id":"BTC-EUR","sequence":3257978853,"time":"2018-01-22T15:14:42.939000Z"}
{"type":"open","side":"sell","price":"9777.89000000","order_id":"dbec7f50-cb03-4bef-9c76-17bb8a876ceb","remaining_size":"0.75000000","product_id":"BTC-EUR","sequence":3257978854,"time":"2018-01-22T15:14:42.939000Z"}
{"type":"received","order_id":"b91db1a6-18a4-46fc-bcb2-f137305a7a3c","order_type":"limit","size":"0.10500000","price":"8826.61000000","side":"sell","client_oid":"96e0028d-df10-415f-8ffa-dfc3d860303b","product_id":"BTC-EUR","sequence":3257978855,"time":"2018-01-22T15:14:42.955000Z"}
{"type":"open","side":"sell","price":"8826.61000000","order_id":"b91db1a6-18a4-46fc-bcb2-f137305a7a3c","remaining_size":"0.10500000","product_id":"BTC-EUR","sequence":3257978856,"time":"2018-01-22T15:14:42.955000Z"}
{"type":"done","side":"sell","order_id":"3c3d7759-be2b-4fe5-8f9f-de55fa00c3a0","reason":"canceled","product_id":"BTC-EUR","price":"8826.60000000","remaining_size":"0.01800000","sequence":3257978857,"time":"2018-01-22T15:14:42.969000Z"}
{"type":"received","order_id":"1132d19c-a4a5-4afb-a5b7-b02497066e96","order_type":"limit","size":"0.75000000","price":"9684.79000000","side":"sell","client_oid":"ffdf1468-a13c-4653-8880-be532d23354d","product_id":"BTC-EUR","sequence":3257978858,"time":"2018-01-22T15:14:42.974000Z"}
{"type":"open","side":"sell","price":"9684.79000000","order_id":"1132d19c-a4a5-4afb-a5b7-b02497066e96","remaining_size":"0.75000000","product_id":"BTC-EUR","sequence":3257978859,"time":"2018-01-22T15:14:42.974000Z"}
{"type":"received","order_id":"86dc9a3a-fd1e-4ab1-8f3c-54039eb48696","order_type":"limit","size":"0.75000000","price":"8062.19000000","side":"buy","client_oid":"4707d9c7-99d8-4ecb-90f4-618da85c55ee","product_id":"BTC-EUR","sequence":3257978860,"time":"2018-01-22T15:14:42.983000Z"}
{"type":"open","side":"buy","price":"8062.19000000","order_id":"86dc9a3a-fd1e-4ab1-8f3c-54039eb48696","remaining_size":"0.75000000","product_id":"BTC-EUR","sequence":3257978861,"time":"2018-01-22T15:14:42.983000Z"}
{"type":"received","order_id":"65b6e35a-875c-441a-b7d8-4c5c2bc7b2fc","order_type":"limit","size":"0.75000000","price":"7969.09000000","side":"buy","client_oid":"f358ea6d-9fd9-4576-8831-f9b110e73731","product_id":"BTC-EUR","sequence":3257978862,"time":"2018-01-22T15:14:42.989000Z"}
{"type":"open","side":"buy","price":"7969.09000000","order_id":"65b6e35a-875c-441a-b7d8-4c5c2bc7b2fc","remaining_size":"0.75000000","product_id":"BTC-EUR","sequence":3257978863,"time":"2018-01-22T15:14:42.989000Z"}
{"type":"done","side":"sell","order_id":"e39a52c0-37da-4603-b4af-ac72dec54b78","reason":"canceled","product_id":"BTC-EUR","price":"8826.61000000","remaining_size":"0.06847422","sequence":3257978864,"time":"2018-01-22T15:14:42.992000Z"}
{"type":"received","order_id":"b084c6cc-b43c-4eab-804d-483e67c9d858","order_type":"limit","size":"0.00564464","price":"8826.58000000","side":"sell","client_oid":"56239c0f-1a63-46d2-ae83-1dd156eba782","product_id":"BTC-EUR","sequence":3257978865,"time":"2018-01-22T15:14:42.998000Z"}
{"type":"open","side":"sell","price":"8826.58000000","order_id":"b084c6cc-b43c-4eab-804d-483e67c9d858","remaining_size":"0.00564464","product_id":"BTC-EUR","sequence":3257978866,"time":"2018-01-22T15:14:42.998000Z"}
{"type":"received","order_id":"c1722393-b349-492c-86ed-89646228f985","order_type":"limit","size":"0.75000000","price":"9126.19000000","side":"sell","client_oid":"9a985f3e-4d3c-48a3-832e-3506a0f86fb6","product_id":"BTC-EUR","sequence":3257978867,"time":"2018-01-22T15:14:43.006000Z"}
{"type":"open","side":"sell","price":"9126.19000000","order_id":"c1722393-b349-492c-86ed-89646228f985","remaining_size":"0.75000000","product_id":"BTC-EUR","sequence":3257978868,"time":"2018-01-22T15:14:43.006000Z"}
{"type":"received","order_id":"39fb7c62-913e-4788-aab2-5626bbf69cf1","order_type":"limit","size":"0.75000000","price":"9498.59000000","side":"sell","client_oid":"a2ec2a47-652b-4bf6-974d-51ea4bfb59bf","product_id":"BTC-EUR","sequence":3257978869,"time":"2018-01-22T15:14:43.006000Z"}
{"type":"open","side":"sell","price":"9498.59000000","order_id":"39fb7c62-913e-4788-aab2-5626bbf69cf1","remaining_size":"0.75000000","product_id":"BTC-EUR","sequence":3257978870,"time":"2018-01-22T15:14:43.006000Z"}
{"type":"received","order_id":"9b926975-56cc-4530-8948-09a5a4d9359e","order_type":"limit","size":"0.74000000","price":"9219.29000000","side":"sell","client_oid":"fbf1f05d-ca84-46ee-a19f-f9517775d0eb","product_id":"BTC-EUR","sequence":3257978871,"time":"2018-01-22T15:14:43.009000Z"}
{"type":"open","side":"sell","price":"9219.29000000","order_id":"9b926975-56cc-4530-8948-09a5a4d9359e","remaining_size":"0.74000000","product_id":"BTC-EUR","sequence":3257978872,"time":"2018-01-22T15:14:43.009000Z"}
{"type":"received","order_id":"ed1d61d0-588c-45d4-812a-6e015ade9e66","order_type":"limit","size":"0.74000000","price":"9591.69000000","side":"sell","client_oid":"c794fcd6-9a12-450b-9087-665e6e68aa43","product_id":"BTC-EUR","sequence":3257978873,"time":"2018-01-22T15:14:43.013000Z"}
{"type":"open","side":"sell","price":"9591.69000000","order_id":"ed1d61d0-588c-45d4-812a-6e015ade9e66","remaining_size":"0.74000000","product_id":"BTC-EUR","sequence":3257978874,"time":"2018-01-22T15:14:43.013000Z"}
{"type":"done","side":"sell","order_id":"25e60341-c92b-4a27-af86-dae07ad11c72","reason":"canceled","product_id":"BTC-EUR","price":"8827.31000000","remaining_size":"0.01322632","sequence":3257978875,"time":"2018-01-22T15:14:43.026000Z"}
{"type":"done","side":"sell","order_id":"39662888-2fa0-44c5-b4af-c35f6badcda3","reason":"canceled","product_id":"BTC-EUR","price":"8827.31000000","remaining_size":"0.22947933","sequence":3257978876,"time":"2018-01-22T15:14:43.033000Z"}
{"type":"done","side":"sell","order_id":"b91db1a6-18a4-46fc-bcb2-f137305a7a3c","reason":"canceled","product_id":"BTC-EUR","price":"8826.61000000","remaining_size":"0.10500000","sequence":3257978877,"time":"2018-01-22T15:14:43.035000Z"}
{"type":"done","side":"sell","order_id":"52a987c4-28c0-4fd3-a448-0bb8603f3dd4","reason":"canceled","product_id":"BTC-EUR","price":"8826.59000000","remaining_size":"0.00113290","sequence":3257978878,"time":"2018-01-22T15:14:43.045000Z"}
{"type":"done","side":"buy","order_id":"ee9dc007-9682-4742-8cf3-116d5ba968d5","reason":"canceled","product_id":"BTC-EUR","price":"8755.00000000","remaining_size":"0.02000000","sequence":3257978879,"time":"2018-01-22T15:14:43.054000Z"}
{"type":"received","order_id":"189eb78d-927d-424f-b64d-74d038f20652","order_type":"limit","size":"0.10500000","price":"8826.59000000","side":"sell","client_oid":"c2eed900-0c4b-41b7-9050-38ce37867659","product_id":"BTC-EUR","sequence":3257978880,"time":"2018-01-22T15:14:43.058000Z"}
{"type":"open","side":"sell","price":"8826.59000000","order_id":"189eb78d-927d-424f-b64d-74d038f20652","remaining_size":"0.10500000","product_id":"BTC-EUR","sequence":3257978881,"time":"2018-01-22T15:14:43.058000Z"}
{"type":"done","side":"sell","order_id":"1ff0e28b-a3ce-4b57-a7ac-7fb00979b620","reason":"canceled","product_id":"BTC-EUR","price":"8826.60000000","remaining_size":"0.03322226","sequence":3257978882,"time":"2018-01-22T15:14:43.102000Z"}
{"type":"received","order_id":"b51169c4-044a-4e2c-aebc-194d242140a1","order_type":"limit","size":"0.01800000","price":"8826.58000000","side":"sell","client_oid":"62303347-d721-43e0-a752-8e10940daa99","product_id":"BTC-EUR","sequence":3257978883,"time":"2018-01-22T15:14:43.125000Z"}
{"type":"open","side":"sell","price":"8826.58000000","order_id":"b51169c4-044a-4e2c-aebc-194d242140a1","remaining_size":"0.01800000","product_id":"BTC-EUR","sequence":3257978884,"time":"2018-01-22T15:14:43.125000Z"}
{"type":"received","order_id":"2dcc1c12-9ced-4b32-b549-3d8ec2d6c547","order_type":"limit","size":"0.06847422","price":"8826.59000000","side":"sell","client_oid":"f3458a31-5ae6-4dd4-98e7-94b975fe686e","product_id":"BTC-EUR","sequence":3257978885,"time":"2018-01-22T15:14:43.125000Z"}
{"type":"open","side":"sell","price":"8826.59000000","order_id":"2dcc1c12-9ced-4b32-b549-3d8ec2d6c547","remaining_size":"0.06847422","product_id":"BTC-EUR","sequence":3257978886,"time":"2018-01-22T15:14:43.125000Z"}
{"type":"done","side":"sell","order_id":"72afd8b0-2535-410c-90ab-dc54834c1213","reason":"canceled","product_id":"BTC-EUR","price":"8826.60000000","remaining_size":"0.06847422","sequence":3257978887,"time":"2018-01-22T15:14:43.132000Z"}
{"type":"received","order_id":"a1ea682b-691e-4c21-a404-1e97e79526fc","order_type":"limit","size":"0.00800000","price":"8826.58000000","side":"sell","client_oid":"55282815-db76-4824-bac5-7677276d68e9","product_id":"BTC-EUR","sequence":3257978888,"time":"2018-01-22T15:14:43.134000Z"}
{"type":"open","side":"sell","price":"8826.58000000","order_id":"a1ea682b-691e-4c21-a404-1e97e79526fc","remaining_size":"0.00800000","product_id":"BTC-EUR","sequence":3257978889,"time":"2018-01-22T15:14:43.134000Z"}
{"type":"done","side":"sell","order_id":"189eb78d-927d-424f-b64d-74d038f20652","reason":"canceled","product_id":"BTC-EUR","price":"8826.59000000","remaining_size":"0.10500000","sequence":3257978890,"time":"2018-01-22T15:14:43.138000Z"}
{"type":"received","order_id":"f17c3f62-0abf-4219-9373-2aaaa91d8e62","order_type":"limit","size":"0.00113290","price":"8826.57000000","side":"sell","client_oid":"e02b33b5-d196-4db4-9b0b-734cfe318096","product_id":"BTC-EUR","sequence":3257978891,"time":"2018-01-22T15:14:43.140000Z"}
{"type":"open","side":"sell","price":"8826.57000000","order_id":"f17c3f62-0abf-4219-9373-2aaaa91d8e62","remaining_size":"0.00113290","product_id":"BTC-EUR","sequence":3257978892,"time":"2018-01-22T15:14:43.140000Z"}
{"type":"received","order_id":"3020543e-3ed0-459e-8428-7a6b4093374e","order_type":"limit","size":"0.00800000","price":"8826.58000000","side":"sell","client_oid":"d8ca775e-4217-46ae-8a50-9df0c59cd221","product_id":"BTC-EUR","sequence":3257978893,"time":"2018-01-22T15:14:43.142000Z"}
{"type":"open","side":"sell","price":"8826.58000000","order_id":"3020543e-3ed0-459e-8428-7a6b4093374e","remaining_size":"0.00800000","product_id":"BTC-EUR","sequence":3257978894,"time":"2018-01-22T15:14:43.142000Z"}
{"type":"done","side":"sell","order_id":"252e1b20-2d73-4138-ab52-8578d5ea7268","reason":"canceled","product_id":"BTC-EUR","price":"8826.59000000","remaining_size":"0.01800000","sequence":3257978895,"time":"2018-01-22T15:14:43.150000Z"}
{"type":"received","order_id":"2839f1dd-9bce-4994-8ec4-6b7402826406","order_type":"limit","size":"0.10500000","price":"8826.58000000","side":"sell","client_oid":"99816a93-521d-4225-a9b2-11382a49df10","product_id":"BTC-EUR","sequence":3257978896,"time":"2018-01-22T15:14:43.155000Z"}
{"type":"open","side":"sell","price":"8826.58000000","order_id":"2839f1dd-9bce-4994-8ec4-6b7402826406","remaining_size":"0.10500000","product_id":"BTC-EUR","sequence":3257978897,"time":"2018-01-22T15:14:43.155000Z"}
{"type":"received","order_id":"355df314-4328-4662-bbfd-a9612d605920","order_type":"limit","size":"0.00200000","price":"8826.58000000","side":"sell","client_oid":"709bac19-83f6-4f94-bb79-db84ea0630df","product_id":"BTC-EUR","sequence":3257978898,"time":"2018-01-22T15:14:43.155000Z"}
{"type":"open","side":"sell","price":"8826.58000000","order_id":"355df314-4328-4662-bbfd-a9612d605920","remaining_size":"0.00200000","product_id":"BTC-EUR","sequence":3257978899,"time":"2018-01-22T15:14:43.155000Z"}
{"type":"received","order_id":"6783618b-fcc1-472f-b711-42f3f8c710a3","order_type":"limit","size":"0.21404538","price":"8826.58000000","side":"sell","product_id":"BTC-EUR","sequence":3257978900,"time":"2018-01-22T15:14:43.164000Z"}
{"type":"open","side":"sell","price":"8826.58000000","order_id":"6783618b-fcc1-472f-b711-42f3f8c710a3","remaining_size":"0.21404538","product_id":"BTC-EUR","sequence":3257978901,"time":"2018-01-22T15:14:43.164000Z"}
{"type":"done","side":"sell","order_id":"8b98c06f-6a12-4934-bc09-f14f0faff1fa","reason":"canceled","product_id":"BTC-EUR","price":"8827.30000000","remaining_size":"0.10500000","sequence":3257978902,"time":"2018-01-22T15:14:43.183000Z"}
{"type":"received","order_id":"1da53140-9964-4732-b505-784648dcee3f","order_type":"limit","size":"0.06847422","price":"8826.58000000","side":"sell","client_oid":"62fc3e35-cede-4ceb-902e-ea27a4b8d912","product_id":"BTC-EUR","sequence":3257978903,"time":"2018-01-22T15:14:43.190000Z"}
{"type":"open","side":"sell","price":"8826.58000000","order_id":"1da53140-9964-4732-b505-784648dcee3f","remaining_size":"0.06847422","product_id":"BTC-EUR","sequence":3257978904,"time":"2018-01-22T15:14:43.190000Z"}
{"type":"received","order_id":"5a412522-4da5-45e4-8e14-5967c5aabc70","order_type":"limit","size":"0.04164971","price":"8826.61000000","side":"sell","client_oid":"f5520c2f-5c8d-450a-9fb0-07c3502c44ca","product_id":"BTC-EUR","sequence":3257978905,"time":"2018-01-22T15:14:43.214000Z"}
{"type":"open","side":"sell","price":"8826.61000000","order_id":"5a412522-4da5-45e4-8e14-5967c5aabc70","remaining_size":"0.04164971","product_id":"BTC-EUR","sequence":3257978906,"time":"2018-01-22T15:14:43.214000Z"}
{"type":"received","order_id":"34d4b571-9f69-456f-aa2a-73efc0fc54f2","order_type":"limit","size":"0.10500000","price":"8826.58000000","side":"sell","client_oid":"f849cefa-94b2-4faa-bbbf-6a7fdfaca386","product_id":"BTC-EUR","sequence":3257978907,"time":"2018-01-22T15:14:43.215000Z"}
{"type":"open","side":"sell","price":"8826.58000000","order_id":"34d4b571-9f69-456f-aa2a-73efc0fc54f2","remaining_size":"0.10500000","product_id":"BTC-EUR","sequence":3257978908,"time":"2018-01-22T15:14:43.215000Z"}
{"type":"received","order_id":"556f3e23-3e13-4c2a-ac66-c904490d8797","order_type":"limit","size":"0.03322226","price":"8826.57000000","side":"sell","client_oid":"81430c95-0c4a-45a5-9e6b-4037194a551e","product_id":"BTC-EUR","sequence":3257978909,"time":"2018-01-22T15:14:43.217000Z"}
{"type":"open","side":"sell","price":"8826.57000000","order_id":"556f3e23-3e13-4c2a-ac66-c904490d8797","remaining_size":"0.03322226","product_id":"BTC-EUR","sequence":3257978910,"time":"2018-01-22T15:14:43.217000Z"}
{"type":"received","order_id":"1865e14a-c918-4293-857e-25ab41ed283f","order_type":"limit","size":"0.01800000","price":"8826.57000000","side":"sell","client_oid":"c41c61b3-05e4-4c63-9761-926952040ef5","product_id":"BTC-EUR","sequence":3257978911,"time":"2018-01-22T15:14:43.233000Z"}
{"type":"open","side":"sell","price":"8826.57000000","order_id":"1865e14a-c918-4293-857e-25ab41ed283f","remaining_size":"0.01800000","product_id":"BTC-EUR","sequence":3257978912,"time":"2018-01-22T15:14:43.233000Z"}
{"type":"done","side":"sell","order_id":"2839f1dd-9bce-4994-8ec4-6b7402826406","reason":"canceled","product_id":"BTC-EUR","price":"8826.58000000","remaining_size":"0.10500000","sequence":3257978913,"time":"2018-01-22T15:14:43.235000Z"}
{"type":"done","side":"sell","order_id":"b51169c4-044a-4e2c-aebc-194d242140a1","reason":"canceled","product_id":"BTC-EUR","price":"8826.58000000","remaining_size":"0.01800000","sequence":3257978914,"time":"2018-01-22T15:14:43.265000Z"}
{"type":"received","order_id":"e18ccaec-e17b-4b14-bb40-8896dbdd0344","order_type":"limit","size":"0.22947933","price":"8826.59000000","side":"sell","client_oid":"9766ecd9-fab6-4c1c-a6d0-361dd04526fc","product_id":"BTC-EUR","sequence":3257978915,"time":"2018-01-22T15:14:43.270000Z"}
{"type":"open","side":"sell","price":"8826.59000000","order_id":"e18ccaec-e17b-4b14-bb40-8896dbdd0344","remaining_size":"0.22947933","product_id":"BTC-EUR","sequence":3257978916,"time":"2018-01-22T15:14:43.270000Z"}
{"type":"received","order_id":"7175504f-bcfc-42c6-991a-bf4ac98cca63","order_type":"limit","size":"0.01322632","price":"8826.59000000","side":"sell","client_oid":"942fbb54-e5f5-4085-a766-3b3c4db898e0","product_id":"BTC-EUR","sequence":3257978917,"time":"2018-01-22T15:14:43.292000Z"}
{"type":"open","side":"sell","price":"8826.59000000","order_id":"7175504f-bcfc-42c6-991a-bf4ac98cca63","remaining_size":"0.01322632","product_id":"BTC-EUR","sequence":3257978918,"time":"2018-01-22T15:14:43.292000Z"}
{"type":"done","side":"sell","order_id":"34d4b571-9f69-456f-aa2a-73efc0fc54f2","reason":"canceled","product_id":"BTC-EUR","price":"8826.58000000","remaining_size":"0.10500000","sequence":3257978919,"time":"2018-01-22T15:14:43.297000Z"}
{"type":"done","side":"sell","order_id":"a1ea682b-691e-4c21-a404-1e97e79526fc","reason":"canceled","product_id":"BTC-EUR","price":"8826.58000000","remaining_size":"0.00800000","sequence":3257978920,"time":"2018-01-22T15:14:43.302000Z"}
{"type":"done","side":"sell","order_id":"3020543e-3ed0-459e-8428-7a6b4093374e","reason":"canceled","product_id":"BTC-EUR","price":"8826.58000000","remaining_size":"0.00800000","sequence":3257978921,"time":"2018-01-22T15:14:43.302000Z"}
{"type":"done","side":"sell","order_id":"2dcc1c12-9ced-4b32-b549-3d8ec2d6c547","reason":"canceled","product_id":"BTC-EUR","price":"8826.59000000","remaining_size":"0.06847422","sequence":3257978922,"time":"2018-01-22T15:14:43.308000Z"}
{"type":"done","side":"sell","order_id":"355df314-4328-4662-bbfd-a9612d605920","reason":"canceled","product_id":"BTC-EUR","price":"8826.58000000","remaining_size":"0.00200000","sequence":3257978923,"time":"2018-01-22T15:14:43.313000Z"}
{"type":"received","order_id":"42badf5c-cd56-49d8-9b41-f6a9b7d3b576","order_type":"limit","size":"0.06847422","price":"8826.57000000","side":"sell","client_oid":"0b2787c8-fcc7-4f7e-a4e5-9b29cc10bff5","product_id":"BTC-EUR","sequence":3257978924,"time":"2018-01-22T15:14:43.328000Z"}
{"type":"open","side":"sell","price":"8826.57000000","order_id":"42badf5c-cd56-49d8-9b41-f6a9b7d3b576","remaining_size":"0.06847422","product_id":"BTC-EUR","sequence":3257978925,"time":"2018-01-22T15:14:43.328000Z"}
{"type":"done","side":"sell","order_id":"6783618b-fcc1-472f-b711-42f3f8c710a3","reason":"canceled","product_id":"BTC-EUR","price":"8826.58000000","remaining_size":"0.21404538","sequence":3257978926,"time":"2018-01-22T15:14:43.332000Z"}
{"type":"received","order_id":"731d1257-c01c-4b03-87a4-cb6313ce3006","order_type":"limit","size":"0.01800000","price":"8826.56000000","side":"sell","client_oid":"00d1f79c-b12c-4a9e-a578-a9577e4a010a","product_id":"BTC-EUR","sequence":3257978927,"time":"2018-01-22T15:14:43.348000Z"}
{"type":"open","side":"sell","price":"8826.56000000","order_id":"731d1257-c01c-4b03-87a4-cb6313ce3006","remaining_size":"0.01800000","product_id":"BTC-EUR","sequence":3257978928,"time":"2018-01-22T15:14:43.348000Z"}
{"type":"received","order_id":"06e12b55-150c-4ca7-95c7-5a0c2468b120","order_type":"limit","size":"0.05000000","price":"8720.00000000","side":"buy","client_oid":"4f71be57-48b9-49fd-b40b-fdcd0b539b31","product_id":"BTC-EUR","sequence":3257978929,"time":"2018-01-22T15:14:43.357000Z"}
{"type":"open","side":"buy","price":"8720.00000000","order_id":"06e12b55-150c-4ca7-95c7-5a0c2468b120","remaining_size":"0.05000000","product_id":"BTC-EUR","sequence":3257978930,"time":"2018-01-22T15:14:43.357000Z"}
{"type":"received","order_id":"be8a8c98-2424-45a5-8264-d2bb7aa02afe","order_type":"limit","size":"0.06847422","price":"8826.56000000","side":"sell","client_oid":"652833e0-1755-45dc-8e42-28800d66ecef","product_id":"BTC-EUR","sequence":3257978931,"time":"2018-01-22T15:14:43.360000Z"}
{"type":"open","side":"sell","price":"8826.56000000","order_id":"be8a8c98-2424-45a5-8264-d2bb7aa02afe","remaining_size":"0.06847422","product_id":"BTC-EUR","sequence":3257978932,"time":"2018-01-22T15:14:43.360000Z"}
{"type":"done","side":"sell","order_id":"556f3e23-3e13-4c2a-ac66-c904490d8797","reason":"canceled","product_id":"BTC-EUR","price":"8826.57000000","remaining_size":"0.03322226","sequence":3257978933,"time":"2018-01-22T15:14:43.364000Z"}
{"type":"done","side":"sell","order_id":"f17c3f62-0abf-4219-9373-2aaaa91d8e62","reason":"canceled","product_id":"BTC-EUR","price":"8826.57000000","remaining_size":"0.00113290","sequence":3257978934,"time":"2018-01-22T15:14:43.367000Z"}
{"type":"done","side":"buy","order_id":"195a1723-2295-479c-b179-c3fe25351698","reason":"canceled","product_id":"BTC-EUR","price":"8806.99000000","remaining_size":"0.49000000","sequence":3257978935,"time":"2018-01-22T15:14:43.399000Z"}
{"type":"done","side":"sell","order_id":"1865e14a-c918-4293-857e-25ab41ed283f","reason":"canceled","product_id":"BTC-EUR","price":"8826.57000000","remaining_size":"0.01800000","sequence":3257978936,"time":"2018-01-22T15:14:43.433000Z"}
{"type":"received","order_id":"873cc160-66e8-4510-90a7-06c639fb68cc","order_type":"limit","size":"0.00200000","price":"8826.56000000","side":"sell","client_oid":"0d9ec84e-bb4a-4352-976a-2b8631b35638","product_id":"BTC-EUR","sequence":3257978937,"time":"2018-01-22T15:14:43.460000Z"}
{"type":"open","side":"sell","price":"8826.56000000","order_id":"873cc160-66e8-4510-90a7-06c639fb68cc","remaining_size":"0.00200000","product_id":"BTC-EUR","sequence":3257978938,"time":"2018-01-22T15:14:43.460000Z"}
{"type":"received","order_id":"d626f4f9-47f4-4c39-8a95-42196329ce8c","order_type":"limit","size":"0.75000000","price":"8936.57000000","side":"sell","client_oid":"d9fc631b-ab3b-4aec-84f9-24a25828a145","product_id":"BTC-EUR","sequence":3257978939,"time":"2018-01-22T15:14:43.461000Z"}
{"type":"open","side":"sell","price":"8936.57000000","order_id":"d626f4f9-47f4-4c39-8a95-42196329ce8c","remaining_size":"0.75000000","product_id":"BTC-EUR","sequence":3257978940,"time":"2018-01-22T15:14:43.461000Z"}
{"type":"received","order_id":"b2758ab6-dae2-444e-ac1e-330a9f74f54e","order_type":"limit","size":"0.10500000","price":"8826.57000000","side":"sell","client_oid":"905995e1-a9b7-427d-8313-fda3ec2e43de","product_id":"BTC-EUR","sequence":3257978941,"time":"2018-01-22T15:14:43.461000Z"}
{"type":"open","side":"sell","price":"8826.57000000","order_id":"b2758ab6-dae2-444e-ac1e-330a9f74f54e","remaining_size":"0.10500000","product_id":"BTC-EUR","sequence":3257978942,"time":"2018-01-22T15:14:43.461000Z"}
{"type":"received","order_id":"f0ee4ddf-34d9-4680-9da0-97815d9c94dc","order_type":"limit","size":"0.10500000","price":"8826.57000000","side":"sell","client_oid":"0322e479-8eee-42e9-a4bb-7e7d3c980013","product_id":"BTC-EUR","sequence":3257978943,"time":"2018-01-22T15:14:43.478000Z"}
{"type":"open","side":"sell","price":"8826.57000000","order_id":"f0ee4ddf-34d9-4680-9da0-97815d9c94dc","remaining_size":"0.10500000","product_id":"BTC-EUR","sequence":3257978944,"time":"2018-01-22T15:14:43.478000Z"}
{"type":"received","order_id":"cd847458-893d-4203-84cf-83e19b48353a","order_type":"limit","size":"0.49000000","price":"8803.57000000","side":"buy","client_oid":"3c6b4bcf-7c7f-424a-b275-62158470dc59","product_id":"BTC-EUR","sequence":3257978945,"time":"2018-01-22T15:14:43.479000Z"}
{"type":"open","side":"buy","price":"8803.57000000","order_id":"cd847458-893d-4203-84cf-83e19b48353a","remaining_size":"0.49000000","product_id":"BTC-EUR","sequence":3257978946,"time":"2018-01-22T15:14:43.479000Z"}
{"type":"received","order_id":"f03e6c39-40bb-425a-923a-004f44dcce55","order_type":"limit","size":"0.01800000","price":"8826.55000000","side":"sell","client_oid":"105d0ace-f993-4288-ac01-c6ea35873f6d","product_id":"BTC-EUR","sequence":3257978947,"time":"2018-01-22T15:14:43.516000Z"}
{"type":"open","side":"sell","price":"8826.55000000","order_id":"f03e6c39-40bb-425a-923a-004f44dcce55","remaining_size":"0.01800000","product_id":"BTC-EUR","sequence":3257978948,"time":"2018-01-22T15:14:43.516000Z"}
{"type":"received","order_id":"4383ab09-e6f1-4222-9e0b-82b7b549e399","order_type":"limit","size":"0.00113290","price":"8826.55000000","side":"sell","client_oid":"05da96a9-38d1-430d-bdf7-768d1bb13eb2","product_id":"BTC-EUR","sequence":3257978949,"time":"2018-01-22T15:14:43.520000Z"}
{"type":"open","side":"sell","price":"8826.55000000","order_id":"4383ab09-e6f1-4222-9e0b-82b7b549e399","remaining_size":"0.00113290","product_id":"BTC-EUR","sequence":3257978950,"time":"2018-01-22T15:14:43.520000Z"}
{"type":"received","order_id":"9cce49a3-d893-41fd-8a1c-7240c91aabd9","order_type":"limit","size":"0.03322226","price":"8826.55000000","side":"sell","client_oid":"0050ba53-0c3a-4561-9f34-e582bfe03e05","product_id":"BTC-EUR","sequence":3257978951,"time":"2018-01-22T15:14:43.524000Z"}
{"type":"open","side":"sell","price":"8826.55000000","order_id":"9cce49a3-d893-41fd-8a1c-7240c91aabd9","remaining_size":"0.03322226","product_id":"BTC-EUR","sequence":3257978952,"time":"2018-01-22T15:14:43.524000Z"}
{"type":"received","order_id":"3870aec6-dc59-4e0d-a7fc-bfb835a75aef","order_type":"limit","size":"0.00800000","price":"8826.55000000","side":"sell","client_oid":"ed818f18-8148-4363-ba89-8bb97920e6eb","product_id":"BTC-EUR","sequence":3257978953,"time":"2018-01-22T15:14:43.531000Z"}
{"type":"open","side":"sell","price":"8826.55000000","order_id":"3870aec6-dc59-4e0d-a7fc-bfb835a75aef","remaining_size":"0.00800000","product_id":"BTC-EUR","sequence":3257978954,"time":"2018-01-22T15:14:43.531000Z"}
{"type":"done","side":"sell","order_id":"be8a8c98-2424-45a5-8264-d2bb7aa02afe","reason":"canceled","product_id":"BTC-EUR","price":"8826.56000000","remaining_size":"0.06847422","sequence":3257978955,"time":"2018-01-22T15:14:43.544000Z"}
{"type":"received","order_id":"187159a5-998d-4e90-bf6f-2c9fcea3fedd","order_type":"limit","size":"0.00800000","price":"8826.55000000","side":"sell","client_oid":"4743792d-0b49-43ae-91f3-3c67e950f3c0","product_id":"BTC-EUR","sequence":3257978956,"time":"2018-01-22T15:14:43.565000Z"}
{"type":"open","side":"sell","price":"8826.55000000","order_id":"187159a5-998d-4e90-bf6f-2c9fcea3fedd","remaining_size":"0.00800000","product_id":"BTC-EUR","sequence":3257978957,"time":"2018-01-22T15:14:43.565000Z"}
{"type":"received","order_id":"a5fafc00-05a3-450f-bc4f-2f222072d911","order_type":"limit","size":"0.00800000","price":"8826.55000000","side":"sell","client_oid":"ead32c82-8bba-4dd9-8e7a-be79463f4479","product_id":"BTC-EUR","sequence":3257978958,"time":"2018-01-22T15:14:43.572000Z"}
{"type":"open","side":"sell","price":"8826.55000000","order_id":"a5fafc00-05a3-450f-bc4f-2f222072d911","remaining_size":"0.00800000","product_id":"BTC-EUR","sequence":3257978959,"time":"2018-01-22T15:14:43.572000Z"}
{"type":"received","order_id":"aa8a3b9e-003b-4f94-992f-11ede34dcae7","order_type":"limit","size":"0.00800000","price":"8826.55000000","side":"sell","client_oid":"8b87ed94-1b1b-41e1-8d3f-ac807d7196b7","product_id":"BTC-EUR","sequence":3257978960,"time":"2018-01-22T15:14:43.589000Z"}
{"type":"open","side":"sell","price":"8826.55000000","order_id":"aa8a3b9e-003b-4f94-992f-11ede34dcae7","remaining_size":"0.00800000","product_id":"BTC-EUR","sequence":3257978961,"time":"2018-01-22T15:14:43.589000Z"}
{"type":"done","side":"sell","order_id":"873cc160-66e8-4510-90a7-06c639fb68cc","reason":"canceled","product_id":"BTC-EUR","price":"8826.56000000","remaining_size":"0.00200000","sequence":3257978962,"time":"2018-01-22T15:14:43.594000Z"}
{"type":"done","side":"sell","order_id":"b2758ab6-dae2-444e-ac1e-330a9f74f54e","reason":"canceled","product_id":"BTC-EUR","price":"8826.57000000","remaining_size":"0.10500000","sequence":3257978963,"time":"2018-01-22T15:14:43.594000Z"}
{"type":"done","side":"sell","order_id":"f0503829-97b4-4a91-84b7-217f4d382644","reason":"canceled","product_id":"BTC-EUR","price":"8848.93000000","remaining_size":"0.13350000","sequence":3257978964,"time":"2018-01-22T15:14:43.598000Z"}
{"type":"done","side":"sell","order_id":"f0ee4ddf-34d9-4680-9da0-97815d9c94dc","reason":"canceled","product_id":"BTC-EUR","price":"8826.57000000","remaining_size":"0.10500000","sequence":3257978965,"time":"2018-01-22T15:14:43.606000Z"}
{"type":"received","order_id":"832f25e2-e960-47ab-a099-3d1e31f55ddc","order_type":"limit","size":"0.00200000","price":"8826.54000000","side":"sell","client_oid":"1a793238-daa2-4e23-8973-3621b3af0702","product_id":"BTC-EUR","sequence":3257978966,"time":"2018-01-22T15:14:43.614000Z"}
{"type":"open","side":"sell","price":"8826.54000000","order_id":"832f25e2-e960-47ab-a099-3d1e31f55ddc","remaining_size":"0.00200000","product_id":"BTC-EUR","sequence":3257978967,"time":"2018-01-22T15:14:43.614000Z"}
{"type":"done","side":"sell","order_id":"4383ab09-e6f1-4222-9e0b-82b7b549e399","reason":"canceled","product_id":"BTC-EUR","price":"8826.55000000","remaining_size":"0.00113290","sequence":3257978968,"time":"2018-01-22T15:14:43.621000Z"}
{"type":"received","order_id":"3f2c8240-a34e-410c-a792-3b76063a4fff","order_type":"limit","size":"0.21404538","price":"8826.55000000","side":"sell","product_id":"BTC-EUR","sequence":3257978969,"time":"2018-01-22T15:14:43.629000Z"}
{"type":"open","side":"sell","price":"8826.55000000","order_id":"3f2c8240-a34e-410c-a792-3b76063a4fff","remaining_size":"0.21404538","product_id":"BTC-EUR","sequence":3257978970,"time":"2018-01-22T15:14:43.629000Z"}
{"type":"done","side":"sell","order_id":"731d1257-c01c-4b03-87a4-cb6313ce3006","reason":"canceled","product_id":"BTC-EUR","price":"8826.56000000","remaining_size":"0.01800000","sequence":3257978971,"time":"2018-01-22T15:14:43.649000Z"}
{"type":"done","side":"sell","order_id":"72d4d54f-10b9-49f0-9cc4-4a70d70b884b","reason":"canceled","product_id":"BTC-EUR","price":"8826.61000000","remaining_size":"0.00800000","sequence":3257978972,"time":"2018-01-22T15:14:43.649000Z"}
{"type":"done","side":"sell","order_id":"42badf5c-cd56-49d8-9b41-f6a9b7d3b576","reason":"canceled","product_id":"BTC-EUR","price":"8826.57000000","remaining_size":"0.06847422","sequence":3257978973,"time":"2018-01-22T15:14:43.664000Z"}
{"type":"done","side":"sell","order_id":"1da53140-9964-4732-b505-784648dcee3f","reason":"canceled","product_id":"BTC-EUR","price":"8826.58000000","remaining_size":"0.06847422","sequence":3257978974,"time":"2018-01-22T15:14:43.664000Z"}
{"type":"received","order_id":"a84b4bfc-a89e-4748-932d-c17ee663da23","order_type":"limit","size":"0.00800000","price":"8826.54000000","side":"sell","client_oid":"63ebea26-7b06-4b75-9b79-d6493e256d4c","product_id":"BTC-EUR","sequence":3257978975,"time":"2018-01-22T15:14:43.678000Z"}
{"type":"open","side":"sell","price":"8826.54000000","order_id":"a84b4bfc-a89e-4748-932d-c17ee663da23","remaining_size":"0.00800000","product_id":"BTC-EUR","sequence":3257978976,"time":"2018-01-22T15:14:43.678000Z"}
{"type":"received","order_id":"099e58d7-df05-49f6-9419-d109b3dd1157","order_type":"limit","size":"0.06847422","price":"8826.55000000","side":"sell","client_oid":"5fc9197a-c262-4f6e-8cd6-58b8666ec31b","product_id":"BTC-EUR","sequence":3257978977,"time":"2018-01-22T15:14:43.689000Z"}
{"type":"open","side":"sell","price":"8826.55000000","order_id":"099e58d7-df05-49f6-9419-d109b3dd1157","remaining_size":"0.06847422","product_id":"BTC-EUR","sequence":3257978978,"time":"2018-01-22T15:14:43.689000Z"}
{"type":"received","order_id":"9edecf4e-534f-4b97-8aa9-41fa7984c09f","order_type":"limit","size":"0.10500000","price":"8826.55000000","side":"sell","client_oid":"5cce73f5-593d-4938-a914-9fecb7197256","product_id":"BTC-EUR","sequence":3257978979,"time":"2018-01-22T15:14:43.692000Z"}
{"type":"open","side":"sell","price":"8826.55000000","order_id":"9edecf4e-534f-4b97-8aa9-41fa7984c09f","remaining_size":"0.10500000","product_id":"BTC-EUR","sequence":3257978980,"time":"2018-01-22T15:14:43.692000Z"}
{"type":"received","order_id":"19b75412-e50f-4fdc-aabf-b094b679965e","order_type":"limit","size":"0.10500000","price":"8826.55000000","side":"sell","client_oid":"6935c44e-d8c7-44ce-9c82-635bb5cc10a7","product_id":"BTC-EUR","sequence":3257978981,"time":"2018-01-22T15:14:43.696000Z"}
{"type":"open","side":"sell","price":"8826.55000000","order_id":"19b75412-e50f-4fdc-aabf-b094b679965e","remaining_size":"0.10500000","product_id":"BTC-EUR","sequence":3257978982,"time":"2018-01-22T15:14:43.696000Z"}
{"type":"done","side":"sell","order_id":"187159a5-998d-4e90-bf6f-2c9fcea3fedd","reason":"canceled","product_id":"BTC-EUR","price":"8826.55000000","remaining_size":"0.00800000","sequence":3257978983,"time":"2018-01-22T15:14:43.696000Z"}
{"type":"done","side":"sell","order_id":"b084c6cc-b43c-4eab-804d-483e67c9d858","reason":"canceled","product_id":"BTC-EUR","price":"8826.58000000","remaining_size":"0.00564464","sequence":3257978984,"time":"2018-01-22T15:14:43.701000Z"}
{"type":"received","order_id":"9aec2f55-5ca7-4b61-a9bc-391a75ce9672","order_type":"limit","size":"0.00113290","price":"8826.53000000","side":"sell","client_oid":"a504e031-c2d3-4b27-abd7-3f070d52c01e","product_id":"BTC-EUR","sequence":3257978985,"time":"2018-01-22T15:14:43.708000Z"}
{"type":"open","side":"sell","price":"8826.53000000","order_id":"9aec2f55-5ca7-4b61-a9bc-391a75ce9672","remaining_size":"0.00113290","product_id":"BTC-EUR","sequence":3257978986,"time":"2018-01-22T15:14:43.708000Z"}
{"type":"received","order_id":"de18189f-9356-487f-8841-ac068a8510df","order_type":"limit","size":"0.00800000","price":"8826.53000000","side":"sell","client_oid":"6b6d69d6-144d-404b-a028-b0e06bc4d28f","product_id":"BTC-EUR","sequence":3257978987,"time":"2018-01-22T15:14:43.717000Z"}
{"type":"open","side":"sell","price":"8826.53000000","order_id":"de18189f-9356-487f-8841-ac068a8510df","remaining_size":"0.00800000","product_id":"BTC-EUR","sequence":3257978988,"time":"2018-01-22T15:14:43.717000Z"}
{"type":"received","order_id":"c5ca286a-31a5-423a-9ccd-06f874740ac6","order_type":"limit","size":"0.10500000","price":"8826.55000000","side":"sell","client_oid":"01fbe449-4fe0-4f4e-aac5-99eb8ef63e18","product_id":"BTC-EUR","sequence":3257978989,"time":"2018-01-22T15:14:43.720000Z"}
{"type":"open","side":"sell","price":"8826.55000000","order_id":"c5ca286a-31a5-423a-9ccd-06f874740ac6","remaining_size":"0.10500000","product_id":"BTC-EUR","sequence":3257978990,"time":"2018-01-22T15:14:43.720000Z"}
{"type":"done","side":"sell","order_id":"a5fafc00-05a3-450f-bc4f-2f222072d911","reason":"canceled","product_id":"BTC-EUR","price":"8826.55000000","remaining_size":"0.00800000","sequence":3257978991,"time":"2018-01-22T15:14:43.727000Z"}
{"type":"received","order_id":"d4523d37-f6e4-45a7-bc1b-cefecdca9036","order_type":"limit","size":"0.13350000","price":"8832.00000000","side":"sell","product_id":"BTC-EUR","sequence":3257978992,"time":"2018-01-22T15:14:43.741000Z"}
{"type":"open","side":"sell","price":"8832.00000000","order_id":"d4523d37-f6e4-45a7-bc1b-cefecdca9036","remaining_size":"0.13350000","product_id":"BTC-EUR","sequence":3257978993,"time":"2018-01-22T15:14:43.741000Z"}
{"type":"done","side":"sell","order_id":"3f2c8240-a34e-410c-a792-3b76063a4fff","reason":"canceled","product_id":"BTC-EUR","price":"8826.55000000","remaining_size":"0.21404538","sequence":3257978994,"time":"2018-01-22T15:14:43.762000Z"}
{"type":"done","side":"sell","order_id":"aed2b4a9-66d3-4413-8b5b-5fadb7f27ecb","reason":"canceled","product_id":"BTC-EUR","price":"8846.89000000","remaining_size":"0.25000000","sequence":3257978995,"time":"2018-01-22T15:14:43.765000Z"}
{"type":"done","side":"sell","order_id":"3870aec6-dc59-4e0d-a7fc-bfb835a75aef","reason":"canceled","product_id":"BTC-EUR","price":"8826.55000000","remaining_size":"0.00800000","sequence":3257978996,"time":"2018-01-22T15:14:43.768000Z"}
{"type":"done","side":"sell","order_id":"aa8a3b9e-003b-4f94-992f-11ede34dcae7","reason":"canceled","product_id":"BTC-EUR","price":"8826.55000000","remaining_size":"0.00800000","sequence":3257978997,"time":"2018-01-22T15:14:43.768000Z"}
{"type":"done","side":"sell","order_id":"19b75412-e50f-4fdc-aabf-b094b679965e","reason":"canceled","product_id":"BTC-EUR","price":"8826.55000000","remaining_size":"0.10500000","sequence":3257978998,"time":"2018-01-22T15:14:43.774000Z"}
{"type":"done","side":"sell","order_id":"1a9b7b52-a97f-459a-8687-db5fd33973a8","reason":"canceled","product_id":"BTC-EUR","price":"9033.09000000","remaining_size":"0.75000000","sequence":3257978999,"time":"2018-01-22T15:14:43.775000Z"}
{"type":"done","side":"sell","order_id":"0553c3f1-63fd-45e2-a26c-68ca3bcb5386","reason":"canceled","product_id":"BTC-EUR","price":"8828.46000000","remaining_size":"0.02754270","sequence":3257979000,"time":"2018-01-22T15:14:43.777000Z"}
{"type":"received","order_id":"e7f024bc-40b9-4a70-9d6e-9b86f499f31b","order_type":"limit","size":"0.06847422","price":"8826.54000000","side":"sell","client_oid":"718ac1ae-bbcf-4cdb-bcef-bf82f76c203b","product_id":"BTC-EUR","sequence":3257979001,"time":"2018-01-22T15:14:43.789000Z"}
{"type":"open","side":"sell","price":"8826.54000000","order_id":"e7f024bc-40b9-4a70-9d6e-9b86f499f31b","remaining_size":"0.06847422","product_id":"BTC-EUR","sequence":3257979002,"time":"2018-01-22T15:14:43.789000Z"}
{"type":"received","order_id":"b08ec2b2-8f1d-440b-b505-c0b4fe9ba497","order_type":"limit","size":"0.06847422","price":"8826.53000000","side":"sell","client_oid":"eb428830-9e58-4de6-bbe3-d87d724ea058","product_id":"BTC-EUR","sequence":3257979003,"time":"2018-01-22T15:14:43.796000Z"}
{"type":"open","side":"sell","price":"8826.53000000","order_id":"b08ec2b2-8f1d-440b-b505-c0b4fe9ba497","remaining_size":"0.06847422","product_id":"BTC-EUR","sequence":3257979004,"time":"2018-01-22T15:14:43.796000Z"}
{"type":"done","side":"sell","order_id":"9cce49a3-d893-41fd-8a1c-7240c91aabd9","reason":"canceled","product_id":"BTC-EUR","price":"8826.55000000","remaining_size":"0.03322226","sequence":3257979005,"time":"2018-01-22T15:14:43.800000Z"}
{"type":"done","side":"buy","order_id":"1eded325-5459-4737-b33a-fa022c1adc0e","reason":"canceled","product_id":"BTC-EUR","price":"8713.89000000","remaining_size":"0.75000000","sequence":3257979006,"time":"2018-01-22T15:14:43.805000Z"}
{"type":"done","side":"sell","order_id":"c1722393-b349-492c-86ed-89646228f985","reason":"canceled","product_id":"BTC-EUR","price":"9126.19000000","remaining_size":"0.75000000","sequence":3257979007,"time":"2018-01-22T15:14:43.806000Z"}
{"type":"done","side":"sell","order_id":"832f25e2-e960-47ab-a099-3d1e31f55ddc","reason":"canceled","product_id":"BTC-EUR","price":"8826.54000000","remaining_size":"0.00200000","sequence":3257979008,"time":"2018-01-22T15:14:43.808000Z"}
{"type":"done","side":"buy","order_id":"545ba26c-f003-40ac-87df-1c9f0638a4fa","reason":"canceled","product_id":"BTC-EUR","price":"8620.79000000","remaining_size":"0.75000000","sequence":3257979009,"time":"2018-01-22T15:14:43.810000Z"}
{"type":"done","side":"sell","order_id":"9b926975-56cc-4530-8948-09a5a4d9359e","reason":"canceled","product_id":"BTC-EUR","price":"9219.29000000","remaining_size":"0.74000000","sequence":3257979010,"time":"2018-01-22T15:14:43.811000Z"}
{"type":"done","side":"buy","order_id":"650ad18f-3e95-4638-9051-eb1be2b71cae","reason":"canceled","product_id":"BTC-EUR","price":"8527.69000000","remaining_size":"0.74000000","sequence":3257979011,"time":"2018-01-22T15:14:43.814000Z"}
{"type":"done","side":"sell","order_id":"66929f75-b80a-4a5c-95e0-c82aa0d85800","reason":"canceled","product_id":"BTC-EUR","price":"9312.39000000","remaining_size":"0.75000000","sequence":3257979012,"time":"2018-01-22T15:14:43.815000Z"}
{"type":"done","side":"buy","order_id":"c3f89f74-fa01-42f5-8b11-c212a75e9d1e","reason":"canceled","product_id":"BTC-EUR","price":"8434.59000000","remaining_size":"0.75000000","sequence":3257979013,"time":"2018-01-22T15:14:43.816000Z"}
{"type":"done","side":"sell","order_id":"94912490-1429-4ad6-ac5c-ef31a327230d","reason":"canceled","product_id":"BTC-EUR","price":"9405.49000000","remaining_size":"0.75000000","sequence":3257979014,"time":"2018-01-22T15:14:43.817000Z"}
{"type":"done","side":"buy","order_id":"44c0e53b-5676-4cfa-9317-0f6646a1a947","reason":"canceled","product_id":"BTC-EUR","price":"8341.49000000","remaining_size":"0.75000000","sequence":3257979015,"time":"2018-01-22T15:14:43.818000Z"}
{"type":"done","side":"sell","order_id":"39fb7c62-913e-4788-aab2-5626bbf69cf1","reason":"canceled","product_id":"BTC-EUR","price":"9498.59000000","remaining_size":"0.75000000","sequence":3257979016,"time":"2018-01-22T15:14:43.819000Z"}
{"type":"done","side":"buy","order_id":"40346d48-3e2b-49b2-a235-4e6b8bd320b6","reason":"canceled","product_id":"BTC-EUR","price":"8248.39000000","remaining_size":"0.75000000","sequence":3257979017,"time":"2018-01-22T15:14:43.823000Z"}
{"type":"done","side":"sell","order_id":"ed1d61d0-588c-45d4-812a-6e015ade9e66","reason":"canceled","product_id":"BTC-EUR","price":"9591.69000000","remaining_size":"0.74000000","sequence":3257979018,"time":"2018-01-22T15:14:43.823000Z"}
{"type":"received","order_id":"0031e4f4-e1b1-4dba-8a98-227550c57b65","order_type":"limit","size":"0.03322226","price":"8826.52000000","side":"sell","client_oid":"036af99b-5674-49ea-920b-f77e51384b94","product_id":"BTC-EUR","sequence":3257979019,"time":"2018-01-22T15:14:43.823000Z"}
{"type":"open","side":"sell","price":"8826.52000000","order_id":"0031e4f4-e1b1-4dba-8a98-227550c57b65","remaining_size":"0.03322226","product_id":"BTC-EUR","sequence":3257979020,"time":"2018-01-22T15:14:43.823000Z"}
{"type":"done","side":"buy","order_id":"715e00b4-2f11-48ed-99a1-173bb10f2790","reason":"canceled","product_id":"BTC-EUR","price":"8155.29000000","remaining_size":"0.74000000","sequence":3257979021,"time":"2018-01-22T15:14:43.824000Z"}
{"type":"done","side":"sell","order_id":"1132d19c-a4a5-4afb-a5b7-b02497066e96","reason":"canceled","product_id":"BTC-EUR","price":"9684.79000000","remaining_size":"0.75000000","sequence":3257979022,"time":"2018-01-22T15:14:43.824000Z"}
{"type":"done","side":"buy","order_id":"86dc9a3a-fd1e-4ab1-8f3c-54039eb48696","reason":"canceled","product_id":"BTC-EUR","price":"8062.19000000","remaining_size":"0.75000000","sequence":3257979023,"time":"2018-01-22T15:14:43.826000Z"}
{"type":"done","side":"sell","order_id":"dbec7f50-cb03-4bef-9c76-17bb8a876ceb","reason":"canceled","product_id":"BTC-EUR","price":"9777.89000000","remaining_size":"0.75000000","sequence":3257979024,"time":"2018-01-22T15:14:43.826000Z"}
{"type":"done","side":"buy","order_id":"65b6e35a-875c-441a-b7d8-4c5c2bc7b2fc","reason":"canceled","product_id":"BTC-EUR","price":"7969.09000000","remaining_size":"0.75000000","sequence":3257979025,"time":"2018-01-22T15:14:43.829000Z"}
{"type":"done","side":"sell","order_id":"9edecf4e-534f-4b97-8aa9-41fa7984c09f","reason":"canceled","product_id":"BTC-EUR","price":"8826.55000000","remaining_size":"0.10500000","sequence":3257979026,"time":"2018-01-22T15:14:43.829000Z"}
{"type":"received","order_id":"349e95d1-8b03-4e4c-a973-5af4927b0803","order_type":"limit","size":"0.25000000","price":"8843.47000000","side":"sell","client_oid":"081ff9a0-a985-4d74-9101-1e6a97662ed5","product_id":"BTC-EUR","sequence":3257979027,"time":"2018-01-22T15:14:43.830000Z"}
{"type":"open","side":"sell","price":"8843.47000000","order_id":"349e95d1-8b03-4e4c-a973-5af4927b0803","remaining_size":"0.25000000","product_id":"BTC-EUR","sequence":3257979028,"time":"2018-01-22T15:14:43.830000Z"}
{"type":"received","order_id":"3d27dbe3-75cf-4cac-8146-64535bd1f828","order_type":"limit","size":"0.75000000","price":"9029.67000000","side":"sell","client_oid":"772d8eac-b579-4f9d-9575-aa44df098a38","product_id":"BTC-EUR","sequence":3257979029,"time":"2018-01-22T15:14:43.830000Z"}
{"type":"open","side":"sell","price":"9029.67000000","order_id":"3d27dbe3-75cf-4cac-8146-64535bd1f828","remaining_size":"0.75000000","product_id":"BTC-EUR","sequence":3257979030,"time":"2018-01-22T15:14:43.830000Z"}
{"type":"received","order_id":"4f803f6d-00a5-4e84-a346-32fd8b20f3eb","order_type":"limit","size":"0.75000000","price":"8617.37000000","side":"buy","client_oid":"32afefeb-eaa1-4533-8ecf-946037583e54","product_id":"BTC-EUR","sequence":3257979031,"time":"2018-01-22T15:14:43.831000Z"}
{"type":"open","side":"buy","price":"8617.37000000","order_id":"4f803f6d-00a5-4e84-a346-32fd8b20f3eb","remaining_size":"0.75000000","product_id":"BTC-EUR","sequence":3257979032,"time":"2018-01-22T15:14:43.831000Z"}
{"type":"received","order_id":"2eecfe46-2b5e-41a8-8780-bb541d77f4f7","order_type":"limit","size":"0.75000000","price":"8710.47000000","side":"buy","client_oid":"4afb2df8-6eab-452b-9e34-8d704fca7b8e","product_id":"BTC-EUR","sequence":3257979033,"time":"2018-01-22T15:14:43.832000Z"}
{"type":"open","side":"buy","price":"8710.47000000","order_id":"2eecfe46-2b5e-41a8-8780-bb541d77f4f7","remaining_size":"0.75000000","product_id":"BTC-EUR","sequence":3257979034,"time":"2018-01-22T15:14:43.832000Z"}
{"type":"done","side":"sell","order_id":"9aec2f55-5ca7-4b61-a9bc-391a75ce9672","reason":"canceled","product_id":"BTC-EUR","price":"8826.53000000","remaining_size":"0.00113290","sequence":3257979035,"time":"2018-01-22T15:14:43.837000Z"}
{"type":"done","side":"sell","order_id":"a84b4bfc-a89e-4748-932d-c17ee663da23","reason":"canceled","product_id":"BTC-EUR","price":"8826.54000000","remaining_size":"0.00800000","sequence":3257979036,"time":"2018-01-22T15:14:43.846000Z"}
{"type":"done","side":"sell","order_id":"c5ca286a-31a5-423a-9ccd-06f874740ac6","reason":"canceled","product_id":"BTC-EUR","price":"8826.55000000","remaining_size":"0.10500000","sequence":3257979037,"time":"2018-01-22T15:14:43.851000Z"}
{"type":"received","order_id":"37e244e3-fc0c-4cfa-a92e-a0f847d1fff5","order_type":"limit","size":"0.75000000","price":"8338.07000000","side":"buy","client_oid":"23215d3f-2898-462c-9e44-413d433763a9","product_id":"BTC-EUR","sequence":3257979038,"time":"2018-01-22T15:14:43.859000Z"}
{"type":"open","side":"buy","price":"8338.07000000","order_id":"37e244e3-fc0c-4cfa-a92e-a0f847d1fff5","remaining_size":"0.75000000","product_id":"BTC-EUR","sequence":3257979039,"time":"2018-01-22T15:14:43.859000Z"}
{"type":"received","order_id":"ad41663d-608f-4a00-963e-3c4e5072a02b","order_type":"limit","size":"0.74000000","price":"8524.27000000","side":"buy","client_oid":"bd795388-25ac-464d-93e4-5f3914822f0d","product_id":"BTC-EUR","sequence":3257979040,"time":"2018-01-22T15:14:43.859000Z"}
{"type":"open","side":"buy","price":"8524.27000000","order_id":"ad41663d-608f-4a00-963e-3c4e5072a02b","remaining_size":"0.74000000","product_id":"BTC-EUR","sequence":3257979041,"time":"2018-01-22T15:14:43.859000Z"}
{"type":"received","order_id":"40acefad-6b79-4f1f-a39a-9c97a6ae41ba","order_type":"limit","size":"0.74000000","price":"8151.87000000","side":"buy","client_oid":"1985025d-fd94-4242-af54-07f0ab2c7b4a","product_id":"BTC-EUR","sequence":3257979042,"time":"2018-01-22T15:14:43.872000Z"}
{"type":"open","side":"buy","price":"8151.87000000","order_id":"40acefad-6b79-4f1f-a39a-9c97a6ae41ba","remaining_size":"0.74000000","product_id":"BTC-EUR","sequence":3257979043,"time":"2018-01-22T15:14:43.872000Z"}
{"type":"received","order_id":"95db5aa1-5404-447a-963a-3736c56ee89d","order_type":"limit","size":"0.75000000","price":"8058.77000000","side":"buy","client_oid":"c7e3e7b9-0526-45f7-9447-c24f21ff9216","product_id":"BTC-EUR","sequence":3257979044,"time":"2018-01-22T15:14:43.895000Z"}
{"type":"open","side":"buy","price":"8058.77000000","order_id":"95db5aa1-5404-447a-963a-3736c56ee89d","remaining_size":"0.75000000","product_id":"BTC-EUR","sequence":3257979045,"time":"2018-01-22T15:14:43.895000Z"}
{"type":"received","order_id":"9a053520-378a-45c7-b785-80a658450ac2","order_type":"limit","size":"0.02754370","price":"8827.28000000","side":"sell","product_id":"BTC-EUR","sequence":3257979046,"time":"2018-01-22T15:14:43.899000Z"}
{"type":"open","side":"sell","price":"8827.28000000","order_id":"9a053520-378a-45c7-b785-80a658450ac2","remaining_size":"0.02754370","product_id":"BTC-EUR","sequence":3257979047,"time":"2018-01-22T15:14:43.899000Z"}
{"type":"done","side":"sell","order_id":"099e58d7-df05-49f6-9419-d109b3dd1157","reason":"canceled","product_id":"BTC-EUR","price":"8826.55000000","remaining_size":"0.06847422","sequence":3257979048,"time":"2018-01-22T15:14:43.913000Z"}
{"type":"received","order_id":"e0bbc8ee-ca1d-4c18-a465-685ccb2116db","order_type":"limit","size":"0.75000000","price":"7965.67000000","side":"buy","client_oid":"042f3f25-5bf3-477a-a0fb-991e8130cda2","product_id":"BTC-EUR","sequence":3257979049,"time":"2018-01-22T15:14:43.915000Z"}
{"type":"open","side":"buy","price":"7965.67000000","order_id":"e0bbc8ee-ca1d-4c18-a465-685ccb2116db","remaining_size":"0.75000000","product_id":"BTC-EUR","sequence":3257979050,"time":"2018-01-22T15:14:43.915000Z"}
{"type":"done","side":"sell","order_id":"de18189f-9356-487f-8841-ac068a8510df","reason":"canceled","product_id":"BTC-EUR","price":"8826.53000000","remaining_size":"0.00800000","sequence":3257979051,"time":"2018-01-22T15:14:43.916000Z"}
{"type":"received","order_id":"f320d8a2-2f47-4d27-8143-e29f0ee5e9f1","order_type":"limit","size":"0.00200000","price":"8826.52000000","side":"sell","client_oid":"1788cb43-98b7-4557-af87-2a797fdad9e8","product_id":"BTC-EUR","sequence":3257979052,"time":"2018-01-22T15:14:43.918000Z"}
{"type":"open","side":"sell","price":"8826.52000000","order_id":"f320d8a2-2f47-4d27-8143-e29f0ee5e9f1","remaining_size":"0.00200000","product_id":"BTC-EUR","sequence":3257979053,"time":"2018-01-22T15:14:43.918000Z"}
{"type":"received","order_id":"d127316f-762d-4f5b-9d54-2177b45dd02f","order_type":"limit","size":"0.10500000","price":"8826.54000000","side":"sell","client_oid":"f8ef9e5f-c15f-40fa-a330-3f7f6959d266","product_id":"BTC-EUR","sequence":3257979054,"time":"2018-01-22T15:14:43.922000Z"}
{"type":"open","side":"sell","price":"8826.54000000","order_id":"d127316f-762d-4f5b-9d54-2177b45dd02f","remaining_size":"0.10500000","product_id":"BTC-EUR","sequence":3257979055,"time":"2018-01-22T15:14:43.922000Z"}
{"type":"received","order_id":"8f84ece3-3488-4b5e-bef6-61940d5bf409","order_type":"limit","size":"0.75000000","price":"9681.37000000","side":"sell","client_oid":"edb30a0b-5095-4364-89fb-c7197cd64275","product_id":"BTC-EUR","sequence":3257979056,"time":"2018-01-22T15:14:43.922000Z"}
{"type":"open","side":"sell","price":"9681.37000000","order_id":"8f84ece3-3488-4b5e-bef6-61940d5bf409","remaining_size":"0.75000000","product_id":"BTC-EUR","sequence":3257979057,"time":"2018-01-22T15:14:43.922000Z"}
{"type":"received","order_id":"dfbf0398-227a-4049-986c-c78f7268e8ba","order_type":"limit","size":"0.06847422","price":"8826.52000000","side":"sell","client_oid":"40b6b447-e855-4975-b94e-51c7ce611367","product_id":"BTC-EUR","sequence":3257979058,"time":"2018-01-22T15:14:43.924000Z"}
{"type":"open","side":"sell","price":"8826.52000000","order_id":"dfbf0398-227a-4049-986c-c78f7268e8ba","remaining_size":"0.06847422","product_id":"BTC-EUR","sequence":3257979059,"time":"2018-01-22T15:14:43.924000Z"}
{"type":"received","order_id":"dd4629a8-11d9-4822-940a-e4fd403c0d4d","order_type":"limit","size":"0.75000000","price":"8431.17000000","side":"buy","client_oid":"0f647f65-83be-4dac-8dc3-7f831dfc2218","product_id":"BTC-EUR","sequence":3257979060,"time":"2018-01-22T15:14:43.935000Z"}
{"type":"open","side":"buy","price":"8431.17000000","order_id":"dd4629a8-11d9-4822-940a-e4fd403c0d4d","remaining_size":"0.75000000","product_id":"BTC-EUR","sequence":3257979061,"time":"2018-01-22T15:14:43.935000Z"}
{"type":"received","order_id":"450d94d8-ed8b-47cd-9632-ca4f667520f6","order_type":"limit","size":"0.00800000","price":"8826.51000000","side":"sell","client_oid":"020514b1-5fda-40cc-bd6d-a49fdd385615","product_id":"BTC-EUR","sequence":3257979062,"time":"2018-01-22T15:14:43.938000Z"}
{"type":"open","side":"sell","price":"8826.51000000","order_id":"450d94d8-ed8b-47cd-9632-ca4f667520f6","remaining_size":"0.00800000","product_id":"BTC-EUR","sequence":3257979063,"time":"2018-01-22T15:14:43.938000Z"}
{"type":"received","order_id":"cd3a4fdd-23ff-4de2-8243-ea30d94d7896","order_type":"limit","size":"0.10500000","price":"8826.53000000","side":"sell","client_oid":"1fd32144-9fcd-42e4-a6ef-54c5a19d5b1c","product_id":"BTC-EUR","sequence":3257979064,"time":"2018-01-22T15:14:43.940000Z"}
{"type":"open","side":"sell","price":"8826.53000000","order_id":"cd3a4fdd-23ff-4de2-8243-ea30d94d7896","remaining_size":"0.10500000","product_id":"BTC-EUR","sequence":3257979065,"time":"2018-01-22T15:14:43.940000Z"}
{"type":"done","side":"sell","order_id":"5a412522-4da5-45e4-8e14-5967c5aabc70","reason":"canceled","product_id":"BTC-EUR","price":"8826.61000000","remaining_size":"0.04164971","sequence":3257979066,"time":"2018-01-22T15:14:43.943000Z"}
{"type":"received","order_id":"7a947a99-4698-4850-a791-9a99b21614a2","order_type":"limit","size":"0.75000000","price":"8244.97000000","side":"buy","client_oid":"b5455561-a3ba-45dd-9227-9874e3358d06","product_id":"BTC-EUR","sequence":3257979067,"time":"2018-01-22T15:14:43.949000Z"}
{"type":"open","side":"buy","price":"8244.97000000","order_id":"7a947a99-4698-4850-a791-9a99b21614a2","remaining_size":"0.75000000","product_id":"BTC-EUR","sequence":3257979068,"time":"2018-01-22T15:14:43.949000Z"}
{"type":"received","order_id":"300f3e75-5ed7-4e15-b6b4-4b5c0b44cce6","order_type":"limit","size":"0.00113290","price":"8826.51000000","side":"sell","client_oid":"a3aae073-91a3-40a6-8987-7a7782516bee","product_id":"BTC-EUR","sequence":3257979069,"time":"2018-01-22T15:14:43.949000Z"}
{"type":"open","side":"sell","price":"8826.51000000","order_id":"300f3e75-5ed7-4e15-b6b4-4b5c0b44cce6","remaining_size":"0.00113290","product_id":"BTC-EUR","sequence":3257979070,"time":"2018-01-22T15:14:43.949000Z"}
{"type":"received","order_id":"ac015337-4bea-4c49-929b-9e2202252738","order_type":"limit","size":"0.74000000","price":"9215.87000000","side":"sell","client_oid":"fb098311-28a8-4685-b792-195d4e070483","product_id":"BTC-EUR","sequence":3257979071,"time":"2018-01-22T15:14:43.960000Z"}
{"type":"open","side":"sell","price":"9215.87000000","order_id":"ac015337-4bea-4c49-929b-9e2202252738","remaining_size":"0.74000000","product_id":"BTC-EUR","sequence":3257979072,"time":"2018-01-22T15:14:43.960000Z"}
{"type":"done","side":"sell","order_id":"d626f4f9-47f4-4c39-8a95-42196329ce8c","reason":"canceled","product_id":"BTC-EUR","price":"8936.57000000","remaining_size":"0.75000000","sequence":3257979073,"time":"2018-01-22T15:14:43.961000Z"}
{"type":"received","order_id":"3052c435-044a-4a25-9f4a-8cf05a2a8696","order_type":"limit","size":"0.75000000","price":"9308.97000000","side":"sell","client_oid":"9533c1b7-3829-4475-a9da-f288d54e7164","product_id":"BTC-EUR","sequence":3257979074,"time":"2018-01-22T15:14:43.965000Z"}
{"type":"open","side":"sell","price":"9308.97000000","order_id":"3052c435-044a-4a25-9f4a-8cf05a2a8696","remaining_size":"0.75000000","product_id":"BTC-EUR","sequence":3257979075,"time":"2018-01-22T15:14:43.965000Z"}
{"type":"received","order_id":"d406315c-a06c-458e-aa19-7dc857715162","order_type":"limit","size":"0.00564464","price":"8826.54000000","side":"sell","client_oid":"a423d601-1a82-43ad-bc5f-f03d2e00f93d","product_id":"BTC-EUR","sequence":3257979076,"time":"2018-01-22T15:14:43.968000Z"}
{"type":"open","side":"sell","price":"8826.54000000","order_id":"d406315c-a06c-458e-aa19-7dc857715162","remaining_size":"0.00564464","product_id":"BTC-EUR","sequence":3257979077,"time":"2018-01-22T15:14:43.968000Z"}
{"type":"done","side":"buy","order_id":"cd847458-893d-4203-84cf-83e19b48353a","reason":"canceled","product_id":"BTC-EUR","price":"8803.57000000","remaining_size":"0.49000000","sequence":3257979078,"time":"2018-01-22T15:14:43.981000Z"}
{"type":"received","order_id":"127d909d-1bea-4b57-b82b-84a871af6e1b","order_type":"limit","size":"0.75000000","price":"9495.17000000","side":"sell","client_oid":"207212ac-a77b-466d-bad7-2c2481b27355","product_id":"BTC-EUR","sequence":3257979079,"time":"2018-01-22T15:14:43.987000Z"}
{"type":"open","side":"sell","price":"9495.17000000","order_id":"127d909d-1bea-4b57-b82b-84a871af6e1b","remaining_size":"0.75000000","product_id":"BTC-EUR","sequence":3257979080,"time":"2018-01-22T15:14:43.987000Z"}
{"type":"received","order_id":"7770c1eb-38a3-40ea-a5aa-36c3046d3dc3","order_type":"limit","size":"0.74000000","price":"9588.27000000","side":"sell","client_oid":"10f21494-7bab-47fb-8425-79e0c211460d","product_id":"BTC-EUR","sequence":3257979081,"time":"2018-01-22T15:14:43.990000Z"}
{"type":"open","side":"sell","price":"9588.27000000","order_id":"7770c1eb-38a3-40ea-a5aa-36c3046d3dc3","remaining_size":"0.74000000","product_id":"BTC-EUR","sequence":3257979082,"time":"2018-01-22T15:14:43.990000Z"}
{"type":"received","order_id":"95fe69db-40f0-431e-9bed-e3168b6e666c","order_type":"limit","size":"0.00200000","price":"8826.51000000","side":"sell","client_oid":"2471e690-6a90-46fd-8474-4e42bc634709","product_id":"BTC-EUR","sequence":3257979083,"time":"2018-01-22T15:14:43.993000Z"}
{"type":"open","side":"sell","price":"8826.51000000","order_id":"95fe69db-40f0-431e-9bed-e3168b6e666c","remaining_size":"0.00200000","product_id":"BTC-EUR","sequence":3257979084,"time":"2018-01-22T15:14:43.993000Z"}
{"type":"done","side":"sell","order_id":"d127316f-762d-4f5b-9d54-2177b45dd02f","reason":"canceled","product_id":"BTC-EUR","price":"8826.54000000","remaining_size":"0.10500000","sequence":3257979085,"time":"2018-01-22T15:14:43.996000Z"}
{"type":"done","side":"sell","order_id":"be1cc6d8-a2f1-4e5a-b252-f6ff1d190973","reason":"canceled","product_id":"BTC-EUR","price":"8860.56000000","remaining_size":"0.06675000","sequence":3257979086,"time":"2018-01-22T15:14:44.000000Z"}
{"type":"received","order_id":"f8223769-fa7d-4e27-9514-4c4eb002375c","order_type":"limit","size":"0.75000000","price":"9402.07000000","side":"sell","client_oid":"39a9266f-d8b3-450a-b55c-41394918793e","product_id":"BTC-EUR","sequence":3257979087,"time":"2018-01-22T15:14:44.001000Z"}
{"type":"open","side":"sell","price":"9402.07000000","order_id":"f8223769-fa7d-4e27-9514-4c4eb002375c","remaining_size":"0.75000000","product_id":"BTC-EUR","sequence":3257979088,"time":"2018-01-22T15:14:44.001000Z"}
{"type":"done","side":"sell","order_id":"7175504f-bcfc-42c6-991a-bf4ac98cca63","reason":"canceled","product_id":"BTC-EUR","price":"8826.59000000","remaining_size":"0.01322632","sequence":3257979089,"time":"2018-01-22T15:14:44.003000Z"}
{"type":"received","order_id":"7181936d-d3fd-4b6c-ae17-2d5df5096eb5","order_type":"limit","size":"0.00800000","price":"8826.51000000","side":"sell","client_oid":"ca926ae4-12b8-4497-8cfc-7124f8bf5d58","product_id":"BTC-EUR","sequence":3257979090,"time":"2018-01-22T15:14:44.006000Z"}
{"type":"open","side":"sell","price":"8826.51000000","order_id":"7181936d-d3fd-4b6c-ae17-2d5df5096eb5","remaining_size":"0.00800000","product_id":"BTC-EUR","sequence":3257979091,"time":"2018-01-22T15:14:44.006000Z"}
{"type":"received","order_id":"564a3b53-bc0a-4e26-b02b-a48f7c24777f","order_type":"limit","size":"0.75000000","price":"9774.47000000","side":"sell","client_oid":"4b7d7bf2-0ad1-466f-b1fb-6525140502f7","product_id":"BTC-EUR","sequence":3257979092,"time":"2018-01-22T15:14:44.013000Z"}
{"type":"open","side":"sell","price":"9774.47000000","order_id":"564a3b53-bc0a-4e26-b02b-a48f7c24777f","remaining_size":"0.75000000","product_id":"BTC-EUR","sequence":3257979093,"time":"2018-01-22T15:14:44.013000Z"}
{"type":"done","side":"sell","order_id":"e18ccaec-e17b-4b14-bb40-8896dbdd0344","reason":"canceled","product_id":"BTC-EUR","price":"8826.59000000","remaining_size":"0.22947933","sequence":3257979094,"time":"2018-01-22T15:14:44.017000Z"}
{"type":"received","order_id":"1e2aba54-37e8-4ab0-b1bc-2abb3d5a11bb","order_type":"limit","size":"0.75000000","price":"8933.06000000","side":"sell","client_oid":"ae9eade0-8208-4691-8d35-e591e0af8ae9","product_id":"BTC-EUR","sequence":3257979095,"time":"2018-01-22T15:14:44.018000Z"}
{"type":"open","side":"sell","price":"8933.06000000","order_id":"1e2aba54-37e8-4ab0-b1bc-2abb3d5a11bb","remaining_size":"0.75000000","product_id":"BTC-EUR","sequence":3257979096,"time":"2018-01-22T15:14:44.018000Z"}
{"type":"received","order_id":"abb930df-1cd5-417e-a395-ea3e8f0b7ab5","order_type":"limit","size":"0.10500000","price":"8826.52000000","side":"sell","client_oid":"83fb46ca-0e63-410d-b057-3b18cd31c72d","product_id":"BTC-EUR","sequence":3257979097,"time":"2018-01-22T15:14:44.022000Z"}
{"type":"open","side":"sell","price":"8826.52000000","order_id":"abb930df-1cd5-417e-a395-ea3e8f0b7ab5","remaining_size":"0.10500000","product_id":"BTC-EUR","sequence":3257979098,"time":"2018-01-22T15:14:44.022000Z"}
{"type":"received","order_id":"26d5bdda-8546-4d44-bf39-69b76d62a388","order_type":"limit","size":"0.75000000","price":"9122.77000000","side":"sell","client_oid":"e039161b-e9f4-49c7-8b94-65f5085926db","product_id":"BTC-EUR","sequence":3257979099,"time":"2018-01-22T15:14:44.025000Z"}
{"type":"open","side":"sell","price":"9122.77000000","order_id":"26d5bdda-8546-4d44-bf39-69b76d62a388","remaining_size":"0.75000000","product_id":"BTC-EUR","sequence":3257979100,"time":"2018-01-22T15:14:44.025000Z"}
{"type":"done","side":"sell","order_id":"b08ec2b2-8f1d-440b-b505-c0b4fe9ba497","reason":"canceled","product_id":"BTC-EUR","price":"8826.53000000","remaining_size":"0.06847422","sequence":3257979101,"time":"2018-01-22T15:14:44.043000Z"}
{"type":"received","order_id":"bb3e46f8-05a9-4c7c-b6d0-e9c2af3715e0","order_type":"limit","size":"0.21404538","price":"8826.51000000","side":"sell","product_id":"BTC-EUR","sequence":3257979102,"time":"2018-01-22T15:14:44.052000Z"}
{"type":"open","side":"sell","price":"8826.51000000","order_id":"bb3e46f8-05a9-4c7c-b6d0-e9c2af3715e0","remaining_size":"0.21404538","product_id":"BTC-EUR","sequence":3257979103,"time":"2018-01-22T15:14:44.052000Z"}
{"type":"done","side":"sell","order_id":"f320d8a2-2f47-4d27-8143-e29f0ee5e9f1","reason":"canceled","product_id":"BTC-EUR","price":"8826.52000000","remaining_size":"0.00200000","sequence":3257979104,"time":"2018-01-22T15:14:44.054000Z"}
{"type":"done","side":"sell","order_id":"cd3a4fdd-23ff-4de2-8243-ea30d94d7896","reason":"canceled","product_id":"BTC-EUR","price":"8826.53000000","remaining_size":"0.10500000","sequence":3257979105,"time":"2018-01-22T15:14:44.057000Z"}
{"type":"received","order_id":"746265c5-a252-42ab-bf49-871ae717f550","order_type":"limit","size":"0.10500000","price":"8826.52000000","side":"sell","client_oid":"4b8d6acb-9610-4f6d-891f-e84edd8b50fa","product_id":"BTC-EUR","sequence":3257979106,"time":"2018-01-22T15:14:44.064000Z"}
{"type":"open","side":"sell","price":"8826.52000000","order_id":"746265c5-a252-42ab-bf49-871ae717f550","remaining_size":"0.10500000","product_id":"BTC-EUR","sequence":3257979107,"time":"2018-01-22T15:14:44.064000Z"}
{"type":"done","side":"sell","order_id":"0031e4f4-e1b1-4dba-8a98-227550c57b65","reason":"canceled","product_id":"BTC-EUR","price":"8826.52000000","remaining_size":"0.03322226","sequence":3257979108,"time":"2018-01-22T15:14:44.078000Z"}
{"type":"received","order_id":"b9f04788-b626-4259-a8d3-72525b693d16","order_type":"limit","size":"0.00200000","price":"8826.50000000","side":"sell","client_oid":"f271e36d-637e-412c-b139-46603af78fee","product_id":"BTC-EUR","sequence":3257979109,"time":"2018-01-22T15:14:44.080000Z"}
{"type":"open","side":"sell","price":"8826.50000000","order_id":"b9f04788-b626-4259-a8d3-72525b693d16","remaining_size":"0.00200000","product_id":"BTC-EUR","sequence":3257979110,"time":"2018-01-22T15:14:44.080000Z"}
{"type":"done","side":"sell","order_id":"300f3e75-5ed7-4e15-b6b4-4b5c0b44cce6","reason":"canceled","product_id":"BTC-EUR","price":"8826.51000000","remaining_size":"0.00113290","sequence":3257979111,"time":"2018-01-22T15:14:44.098000Z"}
{"type":"done","side":"sell","order_id":"abb930df-1cd5-417e-a395-ea3e8f0b7ab5","reason":"canceled","product_id":"BTC-EUR","price":"8826.52000000","remaining_size":"0.10500000","sequence":3257979112,"time":"2018-01-22T15:14:44.099000Z"}
{"type":"received","order_id":"5b9bad47-ffa2-4f8c-ae1d-9bf51a681571","order_type":"limit","size":"0.03322226","price":"8826.50000000","side":"sell","client_oid":"fdfa14b6-b391-4750-80ee-65e7c12dda32","product_id":"BTC-EUR","sequence":3257979113,"time":"2018-01-22T15:14:44.111000Z"}
{"type":"open","side":"sell","price":"8826.50000000","order_id":"5b9bad47-ffa2-4f8c-ae1d-9bf51a681571","remaining_size":"0.03322226","product_id":"BTC-EUR","sequence":3257979114,"time":"2018-01-22T15:14:44.111000Z"}
{"type":"received","order_id":"14c84e18-87ff-4614-9ac1-d8a561030e12","order_type":"limit","size":"0.06675000","price":"8860.57000000","side":"sell","product_id":"BTC-EUR","sequence":3257979115,"time":"2018-01-22T15:14:44.131000Z"}
{"type":"open","side":"sell","price":"8860.57000000","order_id":"14c84e18-87ff-4614-9ac1-d8a561030e12","remaining_size":"0.06675000","product_id":"BTC-EUR","sequence":3257979116,"time":"2018-01-22T15:14:44.131000Z"}
{"type":"received","order_id":"283a3f22-ef6f-4969-8d64-34838424e3f7","order_type":"limit","size":"0.10500000","price":"8826.51000000","side":"sell","client_oid":"a990d12b-b90f-43f4-9fc5-2c810929c4f2","product_id":"BTC-EUR","sequence":3257979117,"time":"2018-01-22T15:14:44.139000Z"}
{"type":"open","side":"sell","price":"8826.51000000","order_id":"283a3f22-ef6f-4969-8d64-34838424e3f7","remaining_size":"0.10500000","product_id":"BTC-EUR","sequence":3257979118,"time":"2018-01-22T15:14:44.139000Z"}
{"type":"done","side":"sell","order_id":"e7f024bc-40b9-4a70-9d6e-9b86f499f31b","reason":"canceled","product_id":"BTC-EUR","price":"8826.54000000","remaining_size":"0.06847422","sequence":3257979119,"time":"2018-01-22T15:14:44.160000Z"}
{"type":"done","side":"sell","order_id":"450d94d8-ed8b-47cd-9632-ca4f667520f6","reason":"canceled","product_id":"BTC-EUR","price":"8826.51000000","remaining_size":"0.00800000","sequence":3257979120,"time":"2018-01-22T15:14:44.161000Z"}
{"type":"received","order_id":"75d44ba9-7630-41e9-acf3-4304f6194e7f","order_type":"limit","size":"0.06847422","price":"8826.51000000","side":"sell","client_oid":"e9bc275b-3a6c-4a83-8fda-c76bb3a8ff40","product_id":"BTC-EUR","sequence":3257979121,"time":"2018-01-22T15:14:44.170000Z"}
{"type":"open","side":"sell","price":"8826.51000000","order_id":"75d44ba9-7630-41e9-acf3-4304f6194e7f","remaining_size":"0.06847422","product_id":"BTC-EUR","sequence":3257979122,"time":"2018-01-22T15:14:44.170000Z"}
{"type":"done","side":"sell","order_id":"746265c5-a252-42ab-bf49-871ae717f550","reason":"canceled","product_id":"BTC-EUR","price":"8826.52000000","remaining_size":"0.10500000","sequence":3257979123,"time":"2018-01-22T15:14:44.176000Z"}
{"type":"received","order_id":"64bf3ed0-3278-4dec-9b3e-aecabaa716dd","order_type":"limit","size":"0.00113290","price":"8826.49000000","side":"sell","client_oid":"b32d8089-360f-4997-9c5f-8053a045f9b7","product_id":"BTC-EUR","sequence":3257979124,"time":"2018-01-22T15:14:44.203000Z"}
{"type":"open","side":"sell","price":"8826.49000000","order_id":"64bf3ed0-3278-4dec-9b3e-aecabaa716dd","remaining_size":"0.00113290","product_id":"BTC-EUR","sequence":3257979125,"time":"2018-01-22T15:14:44.203000Z"}
{"type":"done","side":"buy","order_id":"9a05e736-73d6-4444-9878-686ad6e66df8","reason":"canceled","product_id":"BTC-EUR","price":"8794.43000000","remaining_size":"0.20710000","sequence":3257979126,"time":"2018-01-22T15:14:44.207000Z"}
{"type":"done","side":"sell","order_id":"95fe69db-40f0-431e-9bed-e3168b6e666c","reason":"canceled","product_id":"BTC-EUR","price":"8826.51000000","remaining_size":"0.00200000","sequence":3257979127,"time":"2018-01-22T15:14:44.207000Z"}
{"type":"done","side":"sell","order_id":"7181936d-d3fd-4b6c-ae17-2d5df5096eb5","reason":"canceled","product_id":"BTC-EUR","price":"8826.51000000","remaining_size":"0.00800000","sequence":3257979128,"time":"2018-01-22T15:14:44.208000Z"}
{"type":"done","side":"sell","order_id":"bb3e46f8-05a9-4c7c-b6d0-e9c2af3715e0","reason":"canceled","product_id":"BTC-EUR","price":"8826.51000000","remaining_size":"0.21404538","sequence":3257979129,"time":"2018-01-22T15:14:44.219000Z"}
{"type":"received","order_id":"c30df724-4cc6-40d0-a7b5-e338f1771d91","order_type":"limit","size":"0.04164971","price":"8826.51000000","side":"sell","client_oid":"3848c8bf-2916-4690-b228-c6679509440a","product_id":"BTC-EUR","sequence":3257979130,"time":"2018-01-22T15:14:44.222000Z"}
{"type":"open","side":"sell","price":"8826.51000000","order_id":"c30df724-4cc6-40d0-a7b5-e338f1771d91","remaining_size":"0.04164971","product_id":"BTC-EUR","sequence":3257979131,"time":"2018-01-22T15:14:44.222000Z"}
{"type":"done","side":"buy","order_id":"0410dc57-ac72-4b41-8502-7aa7032c9146","reason":"canceled","product_id":"BTC-EUR","price":"7285.19000000","remaining_size":"19.18330619","sequence":3257979132,"time":"2018-01-22T15:14:44.231000Z"}
{"type":"received","order_id":"c2c53366-355e-4e63-8fa0-aa027174fecf","order_type":"limit","size":"0.00800000","price":"8826.50000000","side":"sell","client_oid":"abdfb864-1aed-4aef-b206-50f9c492ffd0","product_id":"BTC-EUR","sequence":3257979133,"time":"2018-01-22T15:14:44.234000Z"}
{"type":"open","side":"sell","price":"8826.50000000","order_id":"c2c53366-355e-4e63-8fa0-aa027174fecf","remaining_size":"0.00800000","product_id":"BTC-EUR","sequence":3257979134,"time":"2018-01-22T15:14:44.234000Z"}
{"type":"done","side":"sell","order_id":"283a3f22-ef6f-4969-8d64-34838424e3f7","reason":"canceled","product_id":"BTC-EUR","price":"8826.51000000","remaining_size":"0.10500000","sequence":3257979135,"time":"2018-01-22T15:14:44.250000Z"}
{"type":"done","side":"sell","order_id":"dfbf0398-227a-4049-986c-c78f7268e8ba","reason":"canceled","product_id":"BTC-EUR","price":"8826.52000000","remaining_size":"0.06847422","sequence":3257979136,"time":"2018-01-22T15:14:44.281000Z"}
{"type":"done","side":"sell","order_id":"b9f04788-b626-4259-a8d3-72525b693d16","reason":"canceled","product_id":"BTC-EUR","price":"8826.50000000","remaining_size":"0.00200000","sequence":3257979137,"time":"2018-01-22T15:14:44.288000Z"}
{"type":"received","order_id":"66bd333d-c80c-4fa2-b18a-3081017eb616","order_type":"limit","size":"0.01322632","price":"8826.51000000","side":"sell","client_oid":"96b68104-ee91-4ff9-a617-6e93edc065c8","product_id":"BTC-EUR","sequence":3257979138,"time":"2018-01-22T15:14:44.291000Z"}
{"type":"open","side":"sell","price":"8826.51000000","order_id":"66bd333d-c80c-4fa2-b18a-3081017eb616","remaining_size":"0.01322632","product_id":"BTC-EUR","sequence":3257979139,"time":"2018-01-22T15:14:44.291000Z"}
{"type":"received","order_id":"04c3b08f-680c-4d05-b934-6bb0ba10851b","order_type":"limit","size":"0.06847422","price":"8826.50000000","side":"sell","client_oid":"b9444690-13c2-4ea4-839d-cf2736b6079c","product_id":"BTC-EUR","sequence":3257979140,"time":"2018-01-22T15:14:44.299000Z"}
{"type":"open","side":"sell","price":"8826.50000000","order_id":"04c3b08f-680c-4d05-b934-6bb0ba10851b","remaining_size":"0.06847422","product_id":"BTC-EUR","sequence":3257979141,"time":"2018-01-22T15:14:44.299000Z"}
{"type":"received","order_id":"58641f2d-4400-4534-8389-b7b5ace4c022","order_type":"limit","size":"0.00200000","price":"8826.48000000","side":"sell","client_oid":"7df78166-70cf-498e-bf97-553915ac7928","product_id":"BTC-EUR","sequence":3257979142,"time":"2018-01-22T15:14:44.309000Z"}
{"type":"open","side":"sell","price":"8826.48000000","order_id":"58641f2d-4400-4534-8389-b7b5ace4c022","remaining_size":"0.00200000","product_id":"BTC-EUR","sequence":3257979143,"time":"2018-01-22T15:14:44.309000Z"}
{"type":"received","order_id":"10d20f06-3320-493c-b2f9-c2ffe90edb8d","order_type":"limit","size":"0.22947933","price":"8826.51000000","side":"sell","client_oid":"1bd9d290-d210-4dae-a5cf-c9b421a628a7","product_id":"BTC-EUR","sequence":3257979144,"time":"2018-01-22T15:14:44.314000Z"}
{"type":"open","side":"sell","price":"8826.51000000","order_id":"10d20f06-3320-493c-b2f9-c2ffe90edb8d","remaining_size":"0.22947933","product_id":"BTC-EUR","sequence":3257979145,"time":"2018-01-22T15:14:44.314000Z"}
{"type":"received","order_id":"55d05bf6-b9df-402a-91e1-d7f9c09fafbd","order_type":"limit","size":"0.10500000","price":"8826.49000000","side":"sell","client_oid":"2598bb8f-22cf-4960-9b15-81dc185e5774","product_id":"BTC-EUR","sequence":3257979146,"time":"2018-01-22T15:14:44.323000Z"}
{"type":"open","side":"sell","price":"8826.49000000","order_id":"55d05bf6-b9df-402a-91e1-d7f9c09fafbd","remaining_size":"0.10500000","product_id":"BTC-EUR","sequence":3257979147,"time":"2018-01-22T15:14:44.323000Z"}
{"type":"done","side":"sell","order_id":"5b9bad47-ffa2-4f8c-ae1d-9bf51a681571","reason":"canceled","product_id":"BTC-EUR","price":"8826.50000000","remaining_size":"0.03322226","sequence":3257979148,"time":"2018-01-22T15:14:44.329000Z"}
{"type":"done","side":"sell","order_id":"c2c53366-355e-4e63-8fa0-aa027174fecf","reason":"canceled","product_id":"BTC-EUR","price":"8826.50000000","remaining_size":"0.00800000","sequence":3257979149,"time":"2018-01-22T15:14:44.331000Z"}
{"type":"done","side":"sell","order_id":"64bf3ed0-3278-4dec-9b3e-aecabaa716dd","reason":"canceled","product_id":"BTC-EUR","price":"8826.49000000","remaining_size":"0.00113290","sequence":3257979150,"time":"2018-01-22T15:14:44.341000Z"}
{"type":"received","order_id":"ec205db8-e00e-41bc-90fa-154eec30b030","order_type":"limit","size":"0.03322226","price":"8826.48000000","side":"sell","client_oid":"61e6d722-f0b9-418f-8855-cf0eefd6d573","product_id":"BTC-EUR","sequence":3257979151,"time":"2018-01-22T15:14:44.352000Z"}
{"type":"open","side":"sell","price":"8826.48000000","order_id":"ec205db8-e00e-41bc-90fa-154eec30b030","remaining_size":"0.03322226","product_id":"BTC-EUR","sequence":3257979152,"time":"2018-01-22T15:14:44.352000Z"}
{"type":"received","order_id":"0cdccc3e-53ec-4e90-9e4e-c8e6476733d0","order_type":"limit","size":"0.00113290","price":"8826.47000000","side":"sell","client_oid":"1bf36aa4-114d-4e81-90dc-069b715d4fef","product_id":"BTC-EUR","sequence":3257979153,"time":"2018-01-22T15:14:44.365000Z"}
{"type":"open","side":"sell","price":"8826.47000000","order_id":"0cdccc3e-53ec-4e90-9e4e-c8e6476733d0","remaining_size":"0.00113290","product_id":"BTC-EUR","sequence":3257979154,"time":"2018-01-22T15:14:44.365000Z"}
{"type":"received","order_id":"edd1c3ca-9c6e-40db-b7ab-4f345d6c4b9c","order_type":"limit","size":"0.49000000","price":"8800.26000000","side":"buy","client_oid":"dca43ae6-9df4-4dfa-8d56-92f237c0973b","product_id":"BTC-EUR","sequence":3257979155,"time":"2018-01-22T15:14:44.372000Z"}
{"type":"open","side":"buy","price":"8800.26000000","order_id":"edd1c3ca-9c6e-40db-b7ab-4f345d6c4b9c","remaining_size":"0.49000000","product_id":"BTC-EUR","sequence":3257979156,"time":"2018-01-22T15:14:44.372000Z"}
{"type":"done","side":"sell","order_id":"f03e6c39-40bb-425a-923a-004f44dcce55","reason":"canceled","product_id":"BTC-EUR","price":"8826.55000000","remaining_size":"0.01800000","sequence":3257979157,"time":"2018-01-22T15:14:44.378000Z"}
{"type":"done","side":"sell","order_id":"349e95d1-8b03-4e4c-a973-5af4927b0803","reason":"canceled","product_id":"BTC-EUR","price":"8843.47000000","remaining_size":"0.25000000","sequence":3257979158,"time":"2018-01-22T15:14:44.391000Z"}
{"type":"received","order_id":"e5af2250-5c1c-469b-8274-9b00d1795b1e","order_type":"limit","size":"0.00800000","price":"8826.48000000","side":"sell","client_oid":"466e657c-3665-4d53-8714-8c67a3e42292","product_id":"BTC-EUR","sequence":3257979159,"time":"2018-01-22T15:14:44.397000Z"}
{"type":"open","side":"sell","price":"8826.48000000","order_id":"e5af2250-5c1c-469b-8274-9b00d1795b1e","remaining_size":"0.00800000","product_id":"BTC-EUR","sequence":3257979160,"time":"2018-01-22T15:14:44.397000Z"}
{"type":"done","side":"sell","order_id":"7e2b3ee7-25f2-4a14-9f2f-fea60d6609ad","reason":"canceled","product_id":"BTC-EUR","price":"8915.59000000","remaining_size":"0.06675000","sequence":3257979161,"time":"2018-01-22T15:14:44.405000Z"}
{"type":"done","side":"sell","order_id":"75d44ba9-7630-41e9-acf3-4304f6194e7f","reason":"canceled","product_id":"BTC-EUR","price":"8826.51000000","remaining_size":"0.06847422","sequence":3257979162,"time":"2018-01-22T15:14:44.408000Z"}
{"type":"done","side":"sell","order_id":"55d05bf6-b9df-402a-91e1-d7f9c09fafbd","reason":"canceled","product_id":"BTC-EUR","price":"8826.49000000","remaining_size":"0.10500000","sequence":3257979163,"time":"2018-01-22T15:14:44.409000Z"}
{"type":"done","side":"sell","order_id":"58641f2d-4400-4534-8389-b7b5ace4c022","reason":"canceled","product_id":"BTC-EUR","price":"8826.48000000","remaining_size":"0.00200000","sequence":3257979164,"time":"2018-01-22T15:14:44.464000Z"}
{"type":"received","order_id":"fe0d8fe6-2bdc-4402-852b-f637f42e20a9","order_type":"limit","size":"0.10500000","price":"8826.48000000","side":"sell","client_oid":"c8543b7a-cd8b-48ab-91ed-989a4874cecc","product_id":"BTC-EUR","sequence":3257979165,"time":"2018-01-22T15:14:44.467000Z"}
{"type":"open","side":"sell","price":"8826.48000000","order_id":"fe0d8fe6-2bdc-4402-852b-f637f42e20a9","remaining_size":"0.10500000","product_id":"BTC-EUR","sequence":3257979166,"time":"2018-01-22T15:14:44.467000Z"}
{"type":"received","order_id":"488999c2-1796-48f2-ad3d-803e1aa79d3e","order_type":"limit","size":"0.20711000","price":"8794.21000000","side":"buy","product_id":"BTC-EUR","sequence":3257979167,"time":"2018-01-22T15:14:44.467000Z"}
{"type":"open","side":"buy","price":"8794.21000000","order_id":"488999c2-1796-48f2-ad3d-803e1aa79d3e","remaining_size":"0.20711000","product_id":"BTC-EUR","sequence":3257979168,"time":"2018-01-22T15:14:44.467000Z"}
{"type":"received","order_id":"7c88b367-523d-4a2e-9325-6f8b4fb33738","order_type":"limit","size":"0.01800000","price":"8826.48000000","side":"sell","client_oid":"42465967-2982-4880-9c5a-e0d3194cd8b7","product_id":"BTC-EUR","sequence":3257979169,"time":"2018-01-22T15:14:44.476000Z"}
{"type":"open","side":"sell","price":"8826.48000000","order_id":"7c88b367-523d-4a2e-9325-6f8b4fb33738","remaining_size":"0.01800000","product_id":"BTC-EUR","sequence":3257979170,"time":"2018-01-22T15:14:44.476000Z"}
{"type":"received","order_id":"cbc907b3-b2a8-424b-9e5d-2d239b2df341","order_type":"limit","size":"0.06847422","price":"8826.49000000","side":"sell","client_oid":"797eca69-ca51-4dc9-9189-d026e0a82105","product_id":"BTC-EUR","sequence":3257979171,"time":"2018-01-22T15:14:44.476000Z"}
{"type":"open","side":"sell","price":"8826.49000000","order_id":"cbc907b3-b2a8-424b-9e5d-2d239b2df341","remaining_size":"0.06847422","product_id":"BTC-EUR","sequence":3257979172,"time":"2018-01-22T15:14:44.476000Z"}
{"type":"received","order_id":"0a73c111-da80-43fb-a548-a7ba263d2a71","order_type":"limit","size":"0.06847422","price":"8826.48000000","side":"sell","client_oid":"f2613849-1bef-4689-b025-b7427a5473c2","product_id":"BTC-EUR","sequence":3257979173,"time":"2018-01-22T15:14:44.479000Z"}
{"type":"open","side":"sell","price":"8826.48000000","order_id":"0a73c111-da80-43fb-a548-a7ba263d2a71","remaining_size":"0.06847422","product_id":"BTC-EUR","sequence":3257979174,"time":"2018-01-22T15:14:44.479000Z"}
{"type":"received","order_id":"ec2e4081-086e-4349-bb07-c2296ca49df5","order_type":"limit","size":"0.15145722","price":"8755.00000000","side":"buy","client_oid":"ab083f55-55f0-4c06-ac46-7ffb85af2644","product_id":"BTC-EUR","sequence":3257979175,"time":"2018-01-22T15:14:44.487000Z"}
{"type":"open","side":"buy","price":"8755.00000000","order_id":"ec2e4081-086e-4349-bb07-c2296ca49df5","remaining_size":"0.15145722","product_id":"BTC-EUR","sequence":3257979176,"time":"2018-01-22T15:14:44.487000Z"}
{"type":"received","order_id":"f484c3ec-a0a3-4693-b6b9-1143064d7dc5","order_type":"limit","size":"0.00200000","price":"8826.46000000","side":"sell","client_oid":"d6481eed-e841-4bb9-bf9f-14feacb316c9","product_id":"BTC-EUR","sequence":3257979177,"time":"2018-01-22T15:14:44.511000Z"}
{"type":"open","side":"sell","price":"8826.46000000","order_id":"f484c3ec-a0a3-4693-b6b9-1143064d7dc5","remaining_size":"0.00200000","product_id":"BTC-EUR","sequence":3257979178,"time":"2018-01-22T15:14:44.511000Z"}
{"type":"received","order_id":"df8129ad-ad78-4d7b-964d-b813c0286f63","order_type":"limit","size":"0.01800000","price":"8826.46000000","side":"sell","client_oid":"472a8e88-1d88-41ae-82e7-db58e925a872","product_id":"BTC-EUR","sequence":3257979179,"time":"2018-01-22T15:14:44.515000Z"}
{"type":"open","side":"sell","price":"8826.46000000","order_id":"df8129ad-ad78-4d7b-964d-b813c0286f63","remaining_size":"0.01800000","product_id":"BTC-EUR","sequence":3257979180,"time":"2018-01-22T15:14:44.515000Z"}
{"type":"done","side":"sell","order_id":"0cdccc3e-53ec-4e90-9e4e-c8e6476733d0","reason":"canceled","product_id":"BTC-EUR","price":"8826.47000000","remaining_size":"0.00113290","sequence":3257979181,"time":"2018-01-22T15:14:44.521000Z"}
{"type":"done","side":"sell","order_id":"ec205db8-e00e-41bc-90fa-154eec30b030","reason":"canceled","product_id":"BTC-EUR","price":"8826.48000000","remaining_size":"0.03322226","sequence":3257979182,"time":"2018-01-22T15:14:44.522000Z"}
{"type":"received","order_id":"c542957a-c5c1-46a5-9f01-4b4905a2e20e","order_type":"limit","size":"0.06675000","price":"8915.60000000","side":"sell","product_id":"BTC-EUR","sequence":3257979183,"time":"2018-01-22T15:14:44.524000Z"}
{"type":"open","side":"sell","price":"8915.60000000","order_id":"c542957a-c5c1-46a5-9f01-4b4905a2e20e","remaining_size":"0.06675000","product_id":"BTC-EUR","sequence":3257979184,"time":"2018-01-22T15:14:44.524000Z"}
{"type":"done","side":"sell","order_id":"04c3b08f-680c-4d05-b934-6bb0ba10851b","reason":"canceled","product_id":"BTC-EUR","price":"8826.50000000","remaining_size":"0.06847422","sequence":3257979185,"time":"2018-01-22T15:14:44.524000Z"}
{"type":"received","order_id":"d98893cd-72f9-473f-a24a-3ec214beff16","order_type":"limit","size":"0.21404538","price":"8826.47000000","side":"sell","product_id":"BTC-EUR","sequence":3257979186,"time":"2018-01-22T15:14:44.535000Z"}
{"type":"open","side":"sell","price":"8826.47000000","order_id":"d98893cd-72f9-473f-a24a-3ec214beff16","remaining_size":"0.21404538","product_id":"BTC-EUR","sequence":3257979187,"time":"2018-01-22T15:14:44.535000Z"}
{"type":"received","order_id":"3726d9b7-af4d-4616-bcd6-65daaaa32802","order_type":"limit","size":"0.06847422","price":"8826.47000000","side":"sell","client_oid":"e96dd04d-be4c-46a8-b35e-ed964cb4f0d4","product_id":"BTC-EUR","sequence":3257979188,"time":"2018-01-22T15:14:44.540000Z"}
{"type":"open","side":"sell","price":"8826.47000000","order_id":"3726d9b7-af4d-4616-bcd6-65daaaa32802","remaining_size":"0.06847422","product_id":"BTC-EUR","sequence":3257979189,"time":"2018-01-22T15:14:44.540000Z"}
{"type":"received","order_id":"54ba788a-8250-4239-9a1b-5cff57b072ad","order_type":"limit","size":"0.06847422","price":"8826.46000000","side":"sell","client_oid":"c03780c3-d5ec-4282-86df-3b125b5e1818","product_id":"BTC-EUR","sequence":3257979190,"time":"2018-01-22T15:14:44.540000Z"}
{"type":"open","side":"sell","price":"8826.46000000","order_id":"54ba788a-8250-4239-9a1b-5cff57b072ad","remaining_size":"0.06847422","product_id":"BTC-EUR","sequence":3257979191,"time":"2018-01-22T15:14:44.540000Z"}
{"type":"done","side":"sell","order_id":"e5af2250-5c1c-469b-8274-9b00d1795b1e","reason":"canceled","product_id":"BTC-EUR","price":"8826.48000000","remaining_size":"0.00800000","sequence":3257979192,"time":"2018-01-22T15:14:44.542000Z"}
{"type":"done","side":"sell","order_id":"fe0d8fe6-2bdc-4402-852b-f637f42e20a9","reason":"canceled","product_id":"BTC-EUR","price":"8826.48000000","remaining_size":"0.10500000","sequence":3257979193,"time":"2018-01-22T15:14:44.544000Z"}
{"type":"received","order_id":"35a428bf-0c9f-40ec-8e95-5e20b3c2db14","order_type":"limit","size":"0.00800000","price":"8826.46000000","side":"sell","client_oid":"a8e71c94-4325-4633-be2c-bf757b17d279","product_id":"BTC-EUR","sequence":3257979194,"time":"2018-01-22T15:14:44.563000Z"}
{"type":"open","side":"sell","price":"8826.46000000","order_id":"35a428bf-0c9f-40ec-8e95-5e20b3c2db14","remaining_size":"0.00800000","product_id":"BTC-EUR","sequence":3257979195,"time":"2018-01-22T15:14:44.563000Z"}
{"type":"received","order_id":"512fe8db-08c1-45dc-9010-d29cd298a630","order_type":"limit","size":"0.00113290","price":"8826.45000000","side":"sell","client_oid":"278d30d1-f44f-48a2-9124-28347882b127","product_id":"BTC-EUR","sequence":3257979196,"time":"2018-01-22T15:14:44.584000Z"}
{"type":"open","side":"sell","price":"8826.45000000","order_id":"512fe8db-08c1-45dc-9010-d29cd298a630","remaining_size":"0.00113290","product_id":"BTC-EUR","sequence":3257979197,"time":"2018-01-22T15:14:44.584000Z"}
{"type":"done","side":"sell","order_id":"7c88b367-523d-4a2e-9325-6f8b4fb33738","reason":"canceled","product_id":"BTC-EUR","price":"8826.48000000","remaining_size":"0.01800000","sequence":3257979198,"time":"2018-01-22T15:14:44.589000Z"}
{"type":"received","order_id":"bdd1a119-6421-4712-b540-45d9f3225936","order_type":"limit","size":"0.03322226","price":"8826.45000000","side":"sell","client_oid":"8728f4bd-731c-4443-afb3-21f9835d3e52","product_id":"BTC-EUR","sequence":3257979199,"time":"2018-01-22T15:14:44.603000Z"}
{"type":"open","side":"sell","price":"8826.45000000","order_id":"bdd1a119-6421-4712-b540-45d9f3225936","remaining_size":"0.03322226","product_id":"BTC-EUR","sequence":3257979200,"time":"2018-01-22T15:14:44.603000Z"}
{"type":"received","order_id":"22d16913-f0be-46d2-bfcd-9c6f007d1656","order_type":"limit","size":"0.01800000","price":"8826.46000000","side":"sell","client_oid":"1066fc12-7511-46a4-9c67-dcd2f6d40494","product_id":"BTC-EUR","sequence":3257979201,"time":"2018-01-22T15:14:44.603000Z"}
{"type":"open","side":"sell","price":"8826.46000000","order_id":"22d16913-f0be-46d2-bfcd-9c6f007d1656","remaining_size":"0.01800000","product_id":"BTC-EUR","sequence":3257979202,"time":"2018-01-22T15:14:44.603000Z"}
{"type":"received","order_id":"c8454edd-8878-462c-aad3-6e64305a2c15","order_type":"limit","size":"0.10500000","price":"8826.47000000","side":"sell","client_oid":"829ef02f-ffe6-4287-826e-df476fe85825","product_id":"BTC-EUR","sequence":3257979203,"time":"2018-01-22T15:14:44.606000Z"}
{"type":"open","side":"sell","price":"8826.47000000","order_id":"c8454edd-8878-462c-aad3-6e64305a2c15","remaining_size":"0.10500000","product_id":"BTC-EUR","sequence":3257979204,"time":"2018-01-22T15:14:44.606000Z"}
{"type":"done","side":"sell","order_id":"df8129ad-ad78-4d7b-964d-b813c0286f63","reason":"canceled","product_id":"BTC-EUR","price":"8826.46000000","remaining_size":"0.01800000","sequence":3257979205,"time":"2018-01-22T15:14:44.669000Z"}
{"type":"done","side":"sell","order_id":"c8454edd-8878-462c-aad3-6e64305a2c15","reason":"canceled","product_id":"BTC-EUR","price":"8826.47000000","remaining_size":"0.10500000","sequence":3257979206,"time":"2018-01-22T15:14:44.689000Z"}
{"type":"done","side":"sell","order_id":"0a73c111-da80-43fb-a548-a7ba263d2a71","reason":"canceled","product_id":"BTC-EUR","price":"8826.48000000","remaining_size":"0.06847422","sequence":3257979207,"time":"2018-01-22T15:14:44.691000Z"}
{"type":"done","side":"sell","order_id":"f484c3ec-a0a3-4693-b6b9-1143064d7dc5","reason":"canceled","product_id":"BTC-EUR","price":"8826.46000000","remaining_size":"0.00200000","sequence":3257979208,"time":"2018-01-22T15:14:44.695000Z"}
{"type":"done","side":"sell","order_id":"d406315c-a06c-458e-aa19-7dc857715162","reason":"canceled","product_id":"BTC-EUR","price":"8826.54000000","remaining_size":"0.00564464","sequence":3257979209,"time":"2018-01-22T15:14:44.698000Z"}
{"type":"received","order_id":"a1ba39ba-4fcc-4322-b538-2976c21e80b5","order_type":"limit","size":"0.01800000","price":"8826.44000000","side":"sell","client_oid":"fba98fcc-c94f-4f72-94e0-fe57d0102ab8","product_id":"BTC-EUR","sequence":3257979210,"time":"2018-01-22T15:14:44.712000Z"}
{"type":"open","side":"sell","price":"8826.44000000","order_id":"a1ba39ba-4fcc-4322-b538-2976c21e80b5","remaining_size":"0.01800000","product_id":"BTC-EUR","sequence":3257979211,"time":"2018-01-22T15:14:44.712000Z"}
{"type":"done","side":"sell","order_id":"512fe8db-08c1-45dc-9010-d29cd298a630","reason":"canceled","product_id":"BTC-EUR","price":"8826.45000000","remaining_size":"0.00113290","sequence":3257979212,"time":"2018-01-22T15:14:44.732000Z"}
{"type":"done","side":"sell","order_id":"35a428bf-0c9f-40ec-8e95-5e20b3c2db14","reason":"canceled","product_id":"BTC-EUR","price":"8826.46000000","remaining_size":"0.00800000","sequence":3257979213,"time":"2018-01-22T15:14:44.735000Z"}
{"type":"received","order_id":"dfe67bb1-e7f4-4347-a670-ef81f85a7c41","order_type":"limit","size":"0.10500000","price":"8826.45000000","side":"sell","client_oid":"fb7c445c-02d6-48ad-b80d-eccd91029b74","product_id":"BTC-EUR","sequence":3257979214,"time":"2018-01-22T15:14:44.738000Z"}
{"type":"open","side":"sell","price":"8826.45000000","order_id":"dfe67bb1-e7f4-4347-a670-ef81f85a7c41","remaining_size":"0.10500000","product_id":"BTC-EUR","sequence":3257979215,"time":"2018-01-22T15:14:44.738000Z"}
{"type":"done","side":"sell","order_id":"22d16913-f0be-46d2-bfcd-9c6f007d1656","reason":"canceled","product_id":"BTC-EUR","price":"8826.46000000","remaining_size":"0.01800000","sequence":3257979216,"time":"2018-01-22T15:14:44.746000Z"}
{"type":"done","side":"sell","order_id":"d98893cd-72f9-473f-a24a-3ec214beff16","reason":"canceled","product_id":"BTC-EUR","price":"8826.47000000","remaining_size":"0.21404538","sequence":3257979217,"time":"2018-01-22T15:14:44.770000Z"}
{"type":"received","order_id":"9122da33-9060-4efb-8028-2a3cc9e941d9","order_type":"limit","size":"0.01800000","price":"8826.44000000","side":"sell","client_oid":"2eb73510-3c1c-4bb7-9095-b900e1d5b37d","product_id":"BTC-EUR","sequence":3257979218,"time":"2018-01-22T15:14:44.778000Z"}
{"type":"open","side":"sell","price":"8826.44000000","order_id":"9122da33-9060-4efb-8028-2a3cc9e941d9","remaining_size":"0.01800000","product_id":"BTC-EUR","sequence":3257979219,"time":"2018-01-22T15:14:44.778000Z"}
{"type":"received","order_id":"f3c7a5a6-5381-4f31-a3bb-c5582b981dbd","order_type":"limit","size":"0.00113290","price":"8826.43000000","side":"sell","client_oid":"065fdd17-5546-4b5c-90b1-4a32f54544a5","product_id":"BTC-EUR","sequence":3257979220,"time":"2018-01-22T15:14:44.789000Z"}
{"type":"open","side":"sell","price":"8826.43000000","order_id":"f3c7a5a6-5381-4f31-a3bb-c5582b981dbd","remaining_size":"0.00113290","product_id":"BTC-EUR","sequence":3257979221,"time":"2018-01-22T15:14:44.789000Z"}
{"type":"done","side":"sell","order_id":"bdd1a119-6421-4712-b540-45d9f3225936","reason":"canceled","product_id":"BTC-EUR","price":"8826.45000000","remaining_size":"0.03322226","sequence":3257979222,"time":"2018-01-22T15:14:44.792000Z"}
{"type":"done","side":"sell","order_id":"6d4d15d7-abcc-469d-9c22-5b25b3c81158","reason":"canceled","product_id":"BTC-EUR","price":"9786.69000000","remaining_size":"0.12700000","sequence":3257979223,"time":"2018-01-22T15:14:44.799000Z"}
{"type":"done","side":"sell","order_id":"cbc907b3-b2a8-424b-9e5d-2d239b2df341","reason":"canceled","product_id":"BTC-EUR","price":"8826.49000000","remaining_size":"0.06847422","sequence":3257979224,"time":"2018-01-22T15:14:44.807000Z"}
{"type":"done","side":"sell","order_id":"54ba788a-8250-4239-9a1b-5cff57b072ad","reason":"canceled","product_id":"BTC-EUR","price":"8826.46000000","remaining_size":"0.06847422","sequence":3257979225,"time":"2018-01-22T15:14:44.807000Z"}
{"type":"done","side":"sell","order_id":"3726d9b7-af4d-4616-bcd6-65daaaa32802","reason":"canceled","product_id":"BTC-EUR","price":"8826.47000000","remaining_size":"0.06847422","sequence":3257979226,"time":"2018-01-22T15:14:44.810000Z"}
{"type":"done","side":"sell","order_id":"dfe67bb1-e7f4-4347-a670-ef81f85a7c41","reason":"canceled","product_id":"BTC-EUR","price":"8826.45000000","remaining_size":"0.10500000","sequence":3257979227,"time":"2018-01-22T15:14:44.818000Z"}
{"type":"received","order_id":"c917b09d-8b44-4672-8714-216945695daf","order_type":"limit","size":"0.25000000","price":"8840.06000000","side":"sell","client_oid":"a72d4b60-21b1-47ec-bff4-de06d18cb2a3","product_id":"BTC-EUR","sequence":3257979228,"time":"2018-01-22T15:14:44.846000Z"}
{"type":"open","side":"sell","price":"8840.06000000","order_id":"c917b09d-8b44-4672-8714-216945695daf","remaining_size":"0.25000000","product_id":"BTC-EUR","sequence":3257979229,"time":"2018-01-22T15:14:44.846000Z"}
{"type":"done","side":"sell","order_id":"3d27dbe3-75cf-4cac-8146-64535bd1f828","reason":"canceled","product_id":"BTC-EUR","price":"9029.67000000","remaining_size":"0.75000000","sequence":3257979230,"time":"2018-01-22T15:14:44.847000Z"}
{"type":"done","side":"buy","order_id":"2eecfe46-2b5e-41a8-8780-bb541d77f4f7","reason":"canceled","product_id":"BTC-EUR","price":"8710.47000000","remaining_size":"0.75000000","sequence":3257979231,"time":"2018-01-22T15:14:44.848000Z"}
{"type":"done","side":"sell","order_id":"26d5bdda-8546-4d44-bf39-69b76d62a388","reason":"canceled","product_id":"BTC-EUR","price":"9122.77000000","remaining_size":"0.75000000","sequence":3257979232,"time":"2018-01-22T15:14:44.868000Z"}
{"type":"done","side":"buy","order_id":"4f803f6d-00a5-4e84-a346-32fd8b20f3eb","reason":"canceled","product_id":"BTC-EUR","price":"8617.37000000","remaining_size":"0.75000000","sequence":3257979233,"time":"2018-01-22T15:14:44.870000Z"}
{"type":"done","side":"sell","order_id":"ac015337-4bea-4c49-929b-9e2202252738","reason":"canceled","product_id":"BTC-EUR","price":"9215.87000000","remaining_size":"0.74000000","sequence":3257979234,"time":"2018-01-22T15:14:44.873000Z"}
{"type":"done","side":"buy","order_id":"ad41663d-608f-4a00-963e-3c4e5072a02b","reason":"canceled","product_id":"BTC-EUR","price":"8524.27000000","remaining_size":"0.74000000","sequence":3257979235,"time":"2018-01-22T15:14:44.876000Z"}
{"type":"done","side":"sell","order_id":"3052c435-044a-4a25-9f4a-8cf05a2a8696","reason":"canceled","product_id":"BTC-EUR","price":"9308.97000000","remaining_size":"0.75000000","sequence":3257979236,"time":"2018-01-22T15:14:44.878000Z"}
{"type":"done","side":"buy","order_id":"dd4629a8-11d9-4822-940a-e4fd403c0d4d","reason":"canceled","product_id":"BTC-EUR","price":"8431.17000000","remaining_size":"0.75000000","sequence":3257979237,"time":"2018-01-22T15:14:44.879000Z"}
{"type":"done","side":"sell","order_id":"f8223769-fa7d-4e27-9514-4c4eb002375c","reason":"canceled","product_id":"BTC-EUR","price":"9402.07000000","remaining_size":"0.75000000","sequence":3257979238,"time":"2018-01-22T15:14:44.879000Z"}
{"type":"done","side":"buy","order_id":"37e244e3-fc0c-4cfa-a92e-a0f847d1fff5","reason":"canceled","product_id":"BTC-EUR","price":"8338.07000000","remaining_size":"0.75000000","sequence":3257979239,"time":"2018-01-22T15:14:44.881000Z"}
{"type":"done","side":"sell","order_id":"127d909d-1bea-4b57-b82b-84a871af6e1b","reason":"canceled","product_id":"BTC-EUR","price":"9495.17000000","remaining_size":"0.75000000","sequence":3257979240,"time":"2018-01-22T15:14:44.882000Z"}
{"type":"done","side":"buy","order_id":"7a947a99-4698-4850-a791-9a99b21614a2","reason":"canceled","product_id":"BTC-EUR","price":"8244.97000000","remaining_size":"0.75000000","sequence":3257979241,"time":"2018-01-22T15:14:44.882000Z"}
{"type":"done","side":"sell","order_id":"7770c1eb-38a3-40ea-a5aa-36c3046d3dc3","reason":"canceled","product_id":"BTC-EUR","price":"9588.27000000","remaining_size":"0.74000000","sequence":3257979242,"time":"2018-01-22T15:14:44.882000Z"}
{"type":"done","side":"buy","order_id":"40acefad-6b79-4f1f-a39a-9c97a6ae41ba","reason":"canceled","product_id":"BTC-EUR","price":"8151.87000000","remaining_size":"0.74000000","sequence":3257979243,"time":"2018-01-22T15:14:44.883000Z"}
{"type":"done","side":"sell","order_id":"8f84ece3-3488-4b5e-bef6-61940d5bf409","reason":"canceled","product_id":"BTC-EUR","price":"9681.37000000","remaining_size":"0.75000000","sequence":3257979244,"time":"2018-01-22T15:14:44.883000Z"}
{"type":"done","side":"buy","order_id":"95db5aa1-5404-447a-963a-3736c56ee89d","reason":"canceled","product_id":"BTC-EUR","price":"8058.77000000","remaining_size":"0.75000000","sequence":3257979245,"time":"2018-01-22T15:14:44.883000Z"}
{"type":"done","side":"sell","order_id":"564a3b53-bc0a-4e26-b02b-a48f7c24777f","reason":"canceled","product_id":"BTC-EUR","price":"9774.47000000","remaining_size":"0.75000000","sequence":3257979246,"time":"2018-01-22T15:14:44.883000Z"}
{"type":"done","side":"buy","order_id":"e0bbc8ee-ca1d-4c18-a465-685ccb2116db","reason":"canceled","product_id":"BTC-EUR","price":"7965.67000000","remaining_size":"0.75000000","sequence":3257979247,"time":"2018-01-22T15:14:44.884000Z"}
{"type":"received","order_id":"14890b41-389d-4de9-ad5a-5fff2204ea88","order_type":"limit","size":"0.75000000","price":"8614.26000000","side":"buy","client_oid":"1f95cc6b-60f2-4256-a37c-8f679609a313","product_id":"BTC-EUR","sequence":3257979248,"time":"2018-01-22T15:14:44.885000Z"}
{"type":"open","side":"buy","price":"8614.26000000","order_id":"14890b41-389d-4de9-ad5a-5fff2204ea88","remaining_size":"0.75000000","product_id":"BTC-EUR","sequence":3257979249,"time":"2018-01-22T15:14:44.885000Z"}
{"type":"received","order_id":"4d51e809-9c8f-4c63-ae28-3949b0072d91","order_type":"limit","size":"0.75000000","price":"9026.06000000","side":"sell","client_oid":"84681302-1631-4f47-b61a-428a183b746d","product_id":"BTC-EUR","sequence":3257979250,"time":"2018-01-22T15:14:44.885000Z"}
{"type":"open","side":"sell","price":"9026.06000000","order_id":"4d51e809-9c8f-4c63-ae28-3949b0072d91","remaining_size":"0.75000000","product_id":"BTC-EUR","sequence":3257979251,"time":"2018-01-22T15:14:44.885000Z"}
{"type":"received","order_id":"674425d3-9f57-4be7-8c58-88b320a0c388","order_type":"limit","size":"0.75000000","price":"8707.26000000","side":"buy","client_oid":"4eff3463-e03a-4e87-834a-dc00f42d3c8b","product_id":"BTC-EUR","sequence":3257979252,"time":"2018-01-22T15:14:44.886000Z"}
{"type":"open","side":"buy","price":"8707.26000000","order_id":"674425d3-9f57-4be7-8c58-88b320a0c388","remaining_size":"0.75000000","product_id":"BTC-EUR","sequence":3257979253,"time":"2018-01-22T15:14:44.886000Z"}
{"type":"received","order_id":"3c12bb6d-b7ff-482b-8ccd-e3a82222b735","order_type":"limit","size":"0.06847422","price":"8826.44000000","side":"sell","client_oid":"d7dd71ee-5f75-40ce-b216-634195ee7dc1","product_id":"BTC-EUR","sequence":3257979254,"time":"2018-01-22T15:14:44.897000Z"}
{"type":"open","side":"sell","price":"8826.44000000","order_id":"3c12bb6d-b7ff-482b-8ccd-e3a82222b735","remaining_size":"0.06847422","product_id":"BTC-EUR","sequence":3257979255,"time":"2018-01-22T15:14:44.897000Z"}
{"type":"received","order_id":"52fd2d1b-f5ea-4f50-98dd-6d294b423baa","order_type":"limit","size":"0.06847422","price":"8826.45000000","side":"sell","client_oid":"7037ba7e-fd99-440a-996b-b93cacde9a58","product_id":"BTC-EUR","sequence":3257979256,"time":"2018-01-22T15:14:44.897000Z"}
{"type":"open","side":"sell","price":"8826.45000000","order_id":"52fd2d1b-f5ea-4f50-98dd-6d294b423baa","remaining_size":"0.06847422","product_id":"BTC-EUR","sequence":3257979257,"time":"2018-01-22T15:14:44.897000Z"}
{"type":"received","order_id":"46b60595-868b-4405-adf4-40b0a9b3d649","order_type":"limit","size":"0.74000000","price":"9212.06000000","side":"sell","client_oid":"8c75bc6d-ad8c-462c-b48f-c0d7fbbacf4e","product_id":"BTC-EUR","sequence":3257979258,"time":"2018-01-22T15:14:44.906000Z"}
{"type":"open","side":"sell","price":"9212.06000000","order_id":"46b60595-868b-4405-adf4-40b0a9b3d649","remaining_size":"0.74000000","product_id":"BTC-EUR","sequence":3257979259,"time":"2018-01-22T15:14:44.906000Z"}
{"type":"received","order_id":"c671388f-1e71-43ee-a00c-78a60e09bfb2","order_type":"limit","size":"0.75000000","price":"8428.26000000","side":"buy","client_oid":"5e7c4743-fa30-4f6c-8bfd-c1af8aa8c8d5","product_id":"BTC-EUR","sequence":3257979260,"time":"2018-01-22T15:14:44.908000Z"}
{"type":"open","side":"buy","price":"8428.26000000","order_id":"c671388f-1e71-43ee-a00c-78a60e09bfb2","remaining_size":"0.75000000","product_id":"BTC-EUR","sequence":3257979261,"time":"2018-01-22T15:14:44.908000Z"}
{"type":"received","order_id":"ad3d240b-76a0-4174-bfad-6b2b513db940","order_type":"limit","size":"0.00564464","price":"8826.43000000","side":"sell","client_oid":"a523e41c-ac5b-424c-b242-884c52cfd622","product_id":"BTC-EUR","sequence":3257979262,"time":"2018-01-22T15:14:44.910000Z"}
{"type":"open","side":"sell","price":"8826.43000000","order_id":"ad3d240b-76a0-4174-bfad-6b2b513db940","remaining_size":"0.00564464","product_id":"BTC-EUR","sequence":3257979263,"time":"2018-01-22T15:14:44.910000Z"}
{"type":"received","order_id":"9c307303-d7b0-4631-81b5-6b9ffa36884c","order_type":"limit","size":"0.03322226","price":"8826.43000000","side":"sell","client_oid":"8a99cafb-1097-4a76-90a2-72f69b6c903a","product_id":"BTC-EUR","sequence":3257979264,"time":"2018-01-22T15:14:44.911000Z"}
{"type":"open","side":"sell","price":"8826.43000000","order_id":"9c307303-d7b0-4631-81b5-6b9ffa36884c","remaining_size":"0.03322226","product_id":"BTC-EUR","sequence":3257979265,"time":"2018-01-22T15:14:44.911000Z"}
{"type":"received","order_id":"e80972e4-c981-42b8-8a61-aa6b052febda","order_type":"limit","size":"0.74000000","price":"8521.26000000","side":"buy","client_oid":"dceac2de-fd0e-4be8-b58d-80c289240bd6","product_id":"BTC-EUR","sequence":3257979266,"time":"2018-01-22T15:14:44.913000Z"}
{"type":"open","side":"buy","price":"8521.26000000","order_id":"e80972e4-c981-42b8-8a61-aa6b052febda","remaining_size":"0.74000000","product_id":"BTC-EUR","sequence":3257979267,"time":"2018-01-22T15:14:44.913000Z"}
{"type":"done","side":"sell","order_id":"a1ba39ba-4fcc-4322-b538-2976c21e80b5","reason":"canceled","product_id":"BTC-EUR","price":"8826.44000000","remaining_size":"0.01800000","sequence":3257979268,"time":"2018-01-22T15:14:44.921000Z"}
{"type":"done","side":"sell","order_id":"9c307303-d7b0-4631-81b5-6b9ffa36884c","reason":"canceled","product_id":"BTC-EUR","price":"8826.43000000","remaining_size":"0.03322226","sequence":3257979269,"time":"2018-01-22T15:14:44.930000Z"}
{"type":"received","order_id":"f4357586-ce40-4849-a726-cf89f7c4e046","order_type":"limit","size":"0.06847422","price":"8826.43000000","side":"sell","client_oid":"2fd1ed4a-b615-4dff-adbd-a840345730cc","product_id":"BTC-EUR","sequence":3257979270,"time":"2018-01-22T15:14:44.943000Z"}
{"type":"open","side":"sell","price":"8826.43000000","order_id":"f4357586-ce40-4849-a726-cf89f7c4e046","remaining_size":"0.06847422","product_id":"BTC-EUR","sequence":3257979271,"time":"2018-01-22T15:14:44.943000Z"}
{"type":"done","side":"sell","order_id":"c30df724-4cc6-40d0-a7b5-e338f1771d91","reason":"canceled","product_id":"BTC-EUR","price":"8826.51000000","remaining_size":"0.04164971","sequence":3257979272,"time":"2018-01-22T15:14:44.945000Z"}
{"type":"received","order_id":"1e5b951d-0c58-40e5-8fe7-6d11345de403","order_type":"limit","size":"0.12700000","price":"9786.81000000","side":"sell","product_id":"BTC-EUR","sequence":3257979273,"time":"2018-01-22T15:14:44.950000Z"}
{"type":"open","side":"sell","price":"9786.81000000","order_id":"1e5b951d-0c58-40e5-8fe7-6d11345de403","remaining_size":"0.12700000","product_id":"BTC-EUR","sequence":3257979274,"time":"2018-01-22T15:14:44.950000Z"}
{"type":"done","side":"sell","order_id":"9122da33-9060-4efb-8028-2a3cc9e941d9","reason":"canceled","product_id":"BTC-EUR","price":"8826.44000000","remaining_size":"0.01800000","sequence":3257979275,"time":"2018-01-22T15:14:44.960000Z"}
{"type":"received","order_id":"614b8023-dccc-4b7d-a5ac-e19e448bd0b0","order_type":"limit","size":"0.75000000","price":"8056.26000000","side":"buy","client_oid":"c5434be7-583d-4ffc-9ca2-ebcc1fc12f88","product_id":"BTC-EUR","sequence":3257979276,"time":"2018-01-22T15:14:44.972000Z"}
{"type":"open","side":"buy","price":"8056.26000000","order_id":"614b8023-dccc-4b7d-a5ac-e19e448bd0b0","remaining_size":"0.75000000","product_id":"BTC-EUR","sequence":3257979277,"time":"2018-01-22T15:14:44.972000Z"}
{"type":"received","order_id":"05f6dafb-483c-499a-bcea-f68336dd4ecc","order_type":"limit","size":"0.01800000","price":"8826.42000000","side":"sell","client_oid":"7f88085c-e46b-4c28-9ec4-31500e363fe7","product_id":"BTC-EUR","sequence":3257979278,"time":"2018-01-22T15:14:44.976000Z"}
{"type":"open","side":"sell","price":"8826.42000000","order_id":"05f6dafb-483c-499a-bcea-f68336dd4ecc","remaining_size":"0.01800000","product_id":"BTC-EUR","sequence":3257979279,"time":"2018-01-22T15:14:44.976000Z"}
{"type":"received","order_id":"2040a434-d8f1-4672-af38-9f59090028b0","order_type":"limit","size":"0.75000000","price":"8242.26000000","side":"buy","client_oid":"db43336f-ca57-4a66-91bd-7c4551749095","product_id":"BTC-EUR","sequence":3257979280,"time":"2018-01-22T15:14:44.985000Z"}
{"type":"open","side":"buy","price":"8242.26000000","order_id":"2040a434-d8f1-4672-af38-9f59090028b0","remaining_size":"0.75000000","product_id":"BTC-EUR","sequence":3257979281,"time":"2018-01-22T15:14:44.985000Z"}
{"type":"received","order_id":"a0b80270-2205-4bea-a1f0-b597bc63e1df","order_type":"limit","size":"0.75000000","price":"9491.06000000","side":"sell","client_oid":"7eda64ac-07df-4365-b008-77f2a363e245","product_id":"BTC-EUR","sequence":3257979282,"time":"2018-01-22T15:14:44.989000Z"}
{"type":"open","side":"sell","price":"9491.06000000","order_id":"a0b80270-2205-4bea-a1f0-b597bc63e1df","remaining_size":"0.75000000","product_id":"BTC-EUR","sequence":3257979283,"time":"2018-01-22T15:14:44.989000Z"}
{"type":"done","side":"buy","order_id":"95ab8262-4ea1-463c-abf1-3b530ab760c2","reason":"canceled","product_id":"BTC-EUR","price":"8815.12000000","remaining_size":"0.02243610","sequence":3257979284,"time":"2018-01-22T15:14:44.998000Z"}
{"type":"done","side":"sell","order_id":"f3c7a5a6-5381-4f31-a3bb-c5582b981dbd","reason":"canceled","product_id":"BTC-EUR","price":"8826.43000000","remaining_size":"0.00113290","sequence":3257979285,"time":"2018-01-22T15:14:45.001000Z"}
{"type":"done","side":"sell","order_id":"66bd333d-c80c-4fa2-b18a-3081017eb616","reason":"canceled","product_id":"BTC-EUR","price":"8826.51000000","remaining_size":"0.01322632","sequence":3257979286,"time":"2018-01-22T15:14:45.004000Z"}
{"type":"received","order_id":"75247aa8-4207-44cd-8089-91d2d4ed7126","order_type":"limit","size":"0.03322226","price":"8826.42000000","side":"sell","client_oid":"eeff2167-0746-441d-8c90-23fca7247436","product_id":"BTC-EUR","sequence":3257979287,"time":"2018-01-22T15:14:45.016000Z"}
{"type":"open","side":"sell","price":"8826.42000000","order_id":"75247aa8-4207-44cd-8089-91d2d4ed7126","remaining_size":"0.03322226","product_id":"BTC-EUR","sequence":3257979288,"time":"2018-01-22T15:14:45.016000Z"}
{"type":"received","order_id":"95225037-e093-460c-aba8-bf17c58cbb5d","order_type":"limit","size":"0.10500000","price":"8826.44000000","side":"sell","client_oid":"80a988ad-00c7-4b4e-bad8-ded07de1f09f","product_id":"BTC-EUR","sequence":3257979289,"time":"2018-01-22T15:14:45.020000Z"}
{"type":"open","side":"sell","price":"8826.44000000","order_id":"95225037-e093-460c-aba8-bf17c58cbb5d","remaining_size":"0.10500000","product_id":"BTC-EUR","sequence":3257979290,"time":"2018-01-22T15:14:45.020000Z"}
{"type":"received","order_id":"5631cf06-b52d-4370-8a5a-7e77732888b0","order_type":"limit","size":"0.75000000","price":"8335.26000000","side":"buy","client_oid":"be0d0b30-faa1-4049-9b11-67442560d968","product_id":"BTC-EUR","sequence":3257979291,"time":"2018-01-22T15:14:45.020000Z"}
{"type":"open","side":"buy","price":"8335.26000000","order_id":"5631cf06-b52d-4370-8a5a-7e77732888b0","remaining_size":"0.75000000","product_id":"BTC-EUR","sequence":3257979292,"time":"2018-01-22T15:14:45.020000Z"}
{"type":"done","side":"sell","order_id":"10d20f06-3320-493c-b2f9-c2ffe90edb8d","reason":"canceled","product_id":"BTC-EUR","price":"8826.51000000","remaining_size":"0.22947933","sequence":3257979293,"time":"2018-01-22T15:14:45.023000Z"}
{"type":"received","order_id":"bbd5ad66-d583-436c-bb94-17027f7b024b","order_type":"limit","size":"0.75000000","price":"7963.26000000","side":"buy","client_oid":"58b2f20d-a0d9-4ff7-87d1-2120d0fd1503","product_id":"BTC-EUR","sequence":3257979294,"time":"2018-01-22T15:14:45.027000Z"}
{"type":"open","side":"buy","price":"7963.26000000","order_id":"bbd5ad66-d583-436c-bb94-17027f7b024b","remaining_size":"0.75000000","product_id":"BTC-EUR","sequence":3257979295,"time":"2018-01-22T15:14:45.027000Z"}
{"type":"received","order_id":"abd85066-7fbd-4f1f-9131-b737c92567d7","order_type":"limit","size":"0.06847422","price":"8826.42000000","side":"sell","client_oid":"2d845b40-affb-4dbd-b5a2-3e6b851ec530","product_id":"BTC-EUR","sequence":3257979296,"time":"2018-01-22T15:14:45.031000Z"}
{"type":"open","side":"sell","price":"8826.42000000","order_id":"abd85066-7fbd-4f1f-9131-b737c92567d7","remaining_size":"0.06847422","product_id":"BTC-EUR","sequence":3257979297,"time":"2018-01-22T15:14:45.031000Z"}
{"type":"received","order_id":"c824515e-3d7e-4642-b58c-8dbf6b7f8ca0","order_type":"limit","size":"0.75000000","price":"9119.06000000","side":"sell","client_oid":"5e73625f-9a75-4a4c-b519-24154b5e179c","product_id":"BTC-EUR","sequence":3257979298,"time":"2018-01-22T15:14:45.032000Z"}
{"type":"open","side":"sell","price":"9119.06000000","order_id":"c824515e-3d7e-4642-b58c-8dbf6b7f8ca0","remaining_size":"0.75000000","product_id":"BTC-EUR","sequence":3257979299,"time":"2018-01-22T15:14:45.032000Z"}
{"type":"received","order_id":"78b8d616-9318-4ec7-ad2c-7c42840f5de1","order_type":"limit","size":"0.75000000","price":"9770.06000000","side":"sell","client_oid":"c28038b5-5243-4175-a720-f30876b57ffc","product_id":"BTC-EUR","sequence":3257979300,"time":"2018-01-22T15:14:45.037000Z"}
{"type":"open","side":"sell","price":"9770.06000000","order_id":"78b8d616-9318-4ec7-ad2c-7c42840f5de1","remaining_size":"0.75000000","product_id":"BTC-EUR","sequence":3257979301,"time":"2018-01-22T15:14:45.037000Z"}
{"type":"received","order_id":"e3d68315-2e37-4654-8f8d-b9b2e1bf2f15","order_type":"limit","size":"0.00113290","price":"8826.41000000","side":"sell","client_oid":"97fbbc94-a2bf-472f-a347-9a41b7ee896c","product_id":"BTC-EUR","sequence":3257979302,"time":"2018-01-22T15:14:45.039000Z"}
{"type":"open","side":"sell","price":"8826.41000000","order_id":"e3d68315-2e37-4654-8f8d-b9b2e1bf2f15","remaining_size":"0.00113290","product_id":"BTC-EUR","sequence":3257979303,"time":"2018-01-22T15:14:45.039000Z"}
{"type":"received","order_id":"171cdba3-92d6-4252-b1ea-93fd10f35a2c","order_type":"limit","size":"0.74000000","price":"8149.26000000","side":"buy","client_oid":"45f4777c-f94f-4d16-96e8-31dd2d540b83","product_id":"BTC-EUR","sequence":3257979304,"time":"2018-01-22T15:14:45.041000Z"}
{"type":"open","side":"buy","price":"8149.26000000","order_id":"171cdba3-92d6-4252-b1ea-93fd10f35a2c","remaining_size":"0.74000000","product_id":"BTC-EUR","sequence":3257979305,"time":"2018-01-22T15:14:45.041000Z"}
{"type":"received","order_id":"1c576e8f-7de6-4a05-8a28-d139c74a155c","order_type":"limit","size":"0.75000000","price":"9305.06000000","side":"sell","client_oid":"6074f017-e899-4e90-88a5-a5027663b339","product_id":"BTC-EUR","sequence":3257979306,"time":"2018-01-22T15:14:45.044000Z"}
{"type":"open","side":"sell","price":"9305.06000000","order_id":"1c576e8f-7de6-4a05-8a28-d139c74a155c","remaining_size":"0.75000000","product_id":"BTC-EUR","sequence":3257979307,"time":"2018-01-22T15:14:45.044000Z"}
{"type":"received","order_id":"43df78ce-e59d-43a6-8905-e18bdffd5bd2","order_type":"limit","size":"0.75000000","price":"9398.06000000","side":"sell","client_oid":"91b28756-6cd2-4db2-ac1c-d184cf45c65f","product_id":"BTC-EUR","sequence":3257979308,"time":"2018-01-22T15:14:45.046000Z"}
{"type":"open","side":"sell","price":"9398.06000000","order_id":"43df78ce-e59d-43a6-8905-e18bdffd5bd2","remaining_size":"0.75000000","product_id":"BTC-EUR","sequence":3257979309,"time":"2018-01-22T15:14:45.046000Z"}
{"type":"received","order_id":"78c9f80c-0a0c-47f8-809a-15d23810bca8","order_type":"limit","size":"0.74000000","price":"9584.06000000","side":"sell","client_oid":"43bc26af-9dbb-432a-ab4c-3992cfb0353d","product_id":"BTC-EUR","sequence":3257979310,"time":"2018-01-22T15:14:45.052000Z"}
{"type":"open","side":"sell","price":"9584.06000000","order_id":"78c9f80c-0a0c-47f8-809a-15d23810bca8","remaining_size":"0.74000000","product_id":"BTC-EUR","sequence":3257979311,"time":"2018-01-22T15:14:45.052000Z"}
{"type":"received","order_id":"4357bbb9-bf51-4d19-9b76-f5475976095e","order_type":"limit","size":"0.75000000","price":"9677.06000000","side":"sell","client_oid":"c9b46475-9f69-4af2-ab7e-add8ed2c84ad","product_id":"BTC-EUR","sequence":3257979312,"time":"2018-01-22T15:14:45.059000Z"}
{"type":"open","side":"sell","price":"9677.06000000","order_id":"4357bbb9-bf51-4d19-9b76-f5475976095e","remaining_size":"0.75000000","product_id":"BTC-EUR","sequence":3257979313,"time":"2018-01-22T15:14:45.059000Z"}
{"type":"done","side":"buy","order_id":"50b8ba79-5095-439d-8001-09d905286a39","reason":"canceled","product_id":"BTC-EUR","price":"8821.03000000","remaining_size":"0.09415844","sequence":3257979314,"time":"2018-01-22T15:14:45.092000Z"}
{"type":"done","side":"sell","order_id":"95225037-e093-460c-aba8-bf17c58cbb5d","reason":"canceled","product_id":"BTC-EUR","price":"8826.44000000","remaining_size":"0.10500000","sequence":3257979315,"time":"2018-01-22T15:14:45.109000Z"}
{"type":"done","side":"sell","order_id":"f4357586-ce40-4849-a726-cf89f7c4e046","reason":"canceled","product_id":"BTC-EUR","price":"8826.43000000","remaining_size":"0.06847422","sequence":3257979316,"time":"2018-01-22T15:14:45.150000Z"}
{"type":"done","side":"sell","order_id":"3c12bb6d-b7ff-482b-8ccd-e3a82222b735","reason":"canceled","product_id":"BTC-EUR","price":"8826.44000000","remaining_size":"0.06847422","sequence":3257979317,"time":"2018-01-22T15:14:45.150000Z"}
{"type":"done","side":"sell","order_id":"52fd2d1b-f5ea-4f50-98dd-6d294b423baa","reason":"canceled","product_id":"BTC-EUR","price":"8826.45000000","remaining_size":"0.06847422","sequence":3257979318,"time":"2018-01-22T15:14:45.162000Z"}
{"type":"received","order_id":"81ebffd7-0d04-4d4e-b14c-17ee54149f73","order_type":"limit","size":"0.10500000","price":"8826.41000000","side":"sell","client_oid":"9e4b533e-8ece-41cc-bd5c-f9b579dcae89","product_id":"BTC-EUR","sequence":3257979319,"time":"2018-01-22T15:14:45.192000Z"}
{"type":"open","side":"sell","price":"8826.41000000","order_id":"81ebffd7-0d04-4d4e-b14c-17ee54149f73","remaining_size":"0.10500000","product_id":"BTC-EUR","sequence":3257979320,"time":"2018-01-22T15:14:45.192000Z"}
{"type":"received","order_id":"6cd1d1f9-cfc6-4c75-8ddb-c7b2b6367a6d","order_type":"limit","size":"0.06847422","price":"8826.41000000","side":"sell","client_oid":"df9fbc2a-37ce-4489-bfdd-afa106dd3435","product_id":"BTC-EUR","sequence":3257979321,"time":"2018-01-22T15:14:45.204000Z"}
{"type":"open","side":"sell","price":"8826.41000000","order_id":"6cd1d1f9-cfc6-4c75-8ddb-c7b2b6367a6d","remaining_size":"0.06847422","product_id":"BTC-EUR","sequence":3257979322,"time":"2018-01-22T15:14:45.204000Z"}
{"type":"received","order_id":"19e0a13f-4030-4cc1-a3f4-1bf7cde6ec8d","order_type":"limit","size":"0.04164971","price":"8826.41000000","side":"sell","client_oid":"ae8d8753-2632-4087-9c41-62018cd34291","product_id":"BTC-EUR","sequence":3257979323,"time":"2018-01-22T15:14:45.216000Z"}
{"type":"open","side":"sell","price":"8826.41000000","order_id":"19e0a13f-4030-4cc1-a3f4-1bf7cde6ec8d","remaining_size":"0.04164971","product_id":"BTC-EUR","sequence":3257979324,"time":"2018-01-22T15:14:45.216000Z"}
{"type":"received","order_id":"5db79357-8893-45dc-9da1-2a9fa28120a7","order_type":"limit","size":"0.01322632","price":"8826.42000000","side":"sell","client_oid":"8b0d0e55-609c-47fd-88a6-c8f35a643f43","product_id":"BTC-EUR","sequence":3257979325,"time":"2018-01-22T15:14:45.236000Z"}
{"type":"open","side":"sell","price":"8826.42000000","order_id":"5db79357-8893-45dc-9da1-2a9fa28120a7","remaining_size":"0.01322632","product_id":"BTC-EUR","sequence":3257979326,"time":"2018-01-22T15:14:45.236000Z"}
{"type":"received","order_id":"ad7008e0-dcdc-4f42-a832-482616bf07db","order_type":"limit","size":"0.01800000","price":"8826.40000000","side":"sell","client_oid":"5de9ce6a-68f2-4e52-af5c-0c62d96813c2","product_id":"BTC-EUR","sequence":3257979327,"time":"2018-01-22T15:14:45.237000Z"}
{"type":"open","side":"sell","price":"8826.40000000","order_id":"ad7008e0-dcdc-4f42-a832-482616bf07db","remaining_size":"0.01800000","product_id":"BTC-EUR","sequence":3257979328,"time":"2018-01-22T15:14:45.237000Z"}
{"type":"done","side":"sell","order_id":"e3d68315-2e37-4654-8f8d-b9b2e1bf2f15","reason":"canceled","product_id":"BTC-EUR","price":"8826.41000000","remaining_size":"0.00113290","sequence":3257979329,"time":"2018-01-22T15:14:45.244000Z"}
{"type":"received","order_id":"f35cfbb3-16f2-4420-9738-f7784e9d5a45","order_type":"limit","size":"0.10500000","price":"8826.41000000","side":"sell","client_oid":"8e3b61d8-e8d9-4de9-b648-5da92fec3d94","product_id":"BTC-EUR","sequence":3257979330,"time":"2018-01-22T15:14:45.249000Z"}
{"type":"open","side":"sell","price":"8826.41000000","order_id":"f35cfbb3-16f2-4420-9738-f7784e9d5a45","remaining_size":"0.10500000","product_id":"BTC-EUR","sequence":3257979331,"time":"2018-01-22T15:14:45.249000Z"}
{"type":"received","order_id":"6e24adff-c398-457e-8fd5-f1f991012d8e","order_type":"limit","size":"0.22947933","price":"8826.40000000","side":"sell","client_oid":"86033bc5-6706-4b43-8344-1eef084c7759","product_id":"BTC-EUR","sequence":3257979332,"time":"2018-01-22T15:14:45.252000Z"}
{"type":"open","side":"sell","price":"8826.40000000","order_id":"6e24adff-c398-457e-8fd5-f1f991012d8e","remaining_size":"0.22947933","product_id":"BTC-EUR","sequence":3257979333,"time":"2018-01-22T15:14:45.252000Z"}
{"type":"received","order_id":"e963c190-9f83-4be2-bb12-84451cddc0e3","order_type":"limit","size":"0.09200000","price":"8826.40000000","side":"sell","client_oid":"932b0d3a-2696-4149-a35e-8d677ac6b483","product_id":"BTC-EUR","sequence":3257979334,"time":"2018-01-22T15:14:45.275000Z"}
{"type":"open","side":"sell","price":"8826.40000000","order_id":"e963c190-9f83-4be2-bb12-84451cddc0e3","remaining_size":"0.09200000","product_id":"BTC-EUR","sequence":3257979335,"time":"2018-01-22T15:14:45.275000Z"}
{"type":"done","side":"sell","order_id":"75247aa8-4207-44cd-8089-91d2d4ed7126","reason":"canceled","product_id":"BTC-EUR","price":"8826.42000000","remaining_size":"0.03322226","sequence":3257979336,"time":"2018-01-22T15:14:45.278000Z"}
{"type":"done","side":"sell","order_id":"abd85066-7fbd-4f1f-9131-b737c92567d7","reason":"canceled","product_id":"BTC-EUR","price":"8826.42000000","remaining_size":"0.06847422","sequence":3257979337,"time":"2018-01-22T15:14:45.293000Z"}
{"type":"received","order_id":"92195555-08ad-4083-bbcd-81fe1115ad41","order_type":"limit","size":"0.01800000","price":"8826.40000000","side":"sell","client_oid":"b877e6da-802c-4be8-b573-2af560ceb24d","product_id":"BTC-EUR","sequence":3257979338,"time":"2018-01-22T15:14:45.299000Z"}
{"type":"open","side":"sell","price":"8826.40000000","order_id":"92195555-08ad-4083-bbcd-81fe1115ad41","remaining_size":"0.01800000","product_id":"BTC-EUR","sequence":3257979339,"time":"2018-01-22T15:14:45.299000Z"}
{"type":"received","order_id":"06ee40e3-619b-4d00-be34-5409494194a8","order_type":"limit","size":"0.00200000","price":"8826.40000000","side":"sell","client_oid":"ec71d8b7-86ef-47d2-9740-80ffa2eba608","product_id":"BTC-EUR","sequence":3257979340,"time":"2018-01-22T15:14:45.299000Z"}
{"type":"open","side":"sell","price":"8826.40000000","order_id":"06ee40e3-619b-4d00-be34-5409494194a8","remaining_size":"0.00200000","product_id":"BTC-EUR","sequence":3257979341,"time":"2018-01-22T15:14:45.299000Z"}
{"type":"received","order_id":"0a63b582-9c7e-4a2a-b888-e89a5a496fbb","order_type":"limit","size":"0.06847422","price":"8826.40000000","side":"sell","client_oid":"7114b14b-a4c9-49dc-835b-ce33fb33e13f","product_id":"BTC-EUR","sequence":3257979342,"time":"2018-01-22T15:14:45.306000Z"}
{"type":"open","side":"sell","price":"8826.40000000","order_id":"0a63b582-9c7e-4a2a-b888-e89a5a496fbb","remaining_size":"0.06847422","product_id":"BTC-EUR","sequence":3257979343,"time":"2018-01-22T15:14:45.306000Z"}
{"type":"received","order_id":"73612b11-608f-470d-9256-b4d5780acdeb","order_type":"limit","size":"0.03322226","price":"8826.40000000","side":"sell","client_oid":"94876e21-ead5-4598-b77e-c330c57dc515","product_id":"BTC-EUR","sequence":3257979344,"time":"2018-01-22T15:14:45.315000Z"}
{"type":"open","side":"sell","price":"8826.40000000","order_id":"73612b11-608f-470d-9256-b4d5780acdeb","remaining_size":"0.03322226","product_id":"BTC-EUR","sequence":3257979345,"time":"2018-01-22T15:14:45.315000Z"}
{"type":"done","side":"sell","order_id":"f35cfbb3-16f2-4420-9738-f7784e9d5a45","reason":"canceled","product_id":"BTC-EUR","price":"8826.41000000","remaining_size":"0.10500000","sequence":3257979346,"time":"2018-01-22T15:14:45.332000Z"}
{"type":"received","order_id":"9944c48c-a556-423d-9978-bc77807324e9","order_type":"limit","size":"0.00113290","price":"8826.39000000","side":"sell","client_oid":"6c3c8bf0-6ff2-4bbd-8d8e-b7ffc7cc99f0","product_id":"BTC-EUR","sequence":3257979347,"time":"2018-01-22T15:14:45.369000Z"}
{"type":"open","side":"sell","price":"8826.39000000","order_id":"9944c48c-a556-423d-9978-bc77807324e9","remaining_size":"0.00113290","product_id":"BTC-EUR","sequence":3257979348,"time":"2018-01-22T15:14:45.369000Z"}
{"type":"done","side":"sell","order_id":"81ebffd7-0d04-4d4e-b14c-17ee54149f73","reason":"canceled","product_id":"BTC-EUR","price":"8826.41000000","remaining_size":"0.10500000","sequence":3257979349,"time":"2018-01-22T15:14:45.380000Z"}
{"type":"received","order_id":"c222a94b-828e-4c68-8ba9-97d83f095af5","order_type":"limit","size":"0.21404538","price":"8826.42000000","side":"sell","product_id":"BTC-EUR","sequence":3257979350,"time":"2018-01-22T15:14:45.393000Z"}
{"type":"open","side":"sell","price":"8826.42000000","order_id":"c222a94b-828e-4c68-8ba9-97d83f095af5","remaining_size":"0.21404538","product_id":"BTC-EUR","sequence":3257979351,"time":"2018-01-22T15:14:45.393000Z"}
{"type":"done","side":"sell","order_id":"6cd1d1f9-cfc6-4c75-8ddb-c7b2b6367a6d","reason":"canceled","product_id":"BTC-EUR","price":"8826.41000000","remaining_size":"0.06847422","sequence":3257979352,"time":"2018-01-22T15:14:45.411000Z"}
{"type":"received","order_id":"ab3e1d40-ff8d-46a8-907d-952cbef90330","order_type":"limit","size":"0.06847422","price":"8826.39000000","side":"sell","client_oid":"2637a62e-4067-4dbc-b195-0c36a8f5b26d","product_id":"BTC-EUR","sequence":3257979353,"time":"2018-01-22T15:14:45.419000Z"}
{"type":"open","side":"sell","price":"8826.39000000","order_id":"ab3e1d40-ff8d-46a8-907d-952cbef90330","remaining_size":"0.06847422","product_id":"BTC-EUR","sequence":3257979354,"time":"2018-01-22T15:14:45.419000Z"}
{"type":"received","order_id":"a05b319d-6d4d-437e-8415-7d4a567173d2","order_type":"limit","size":"0.01656300","price":"8826.03000000","side":"sell","product_id":"BTC-EUR","sequence":3257979355,"time":"2018-01-22T15:14:45.423000Z"}
{"type":"open","side":"sell","price":"8826.03000000","order_id":"a05b319d-6d4d-437e-8415-7d4a567173d2","remaining_size":"0.01656300","product_id":"BTC-EUR","sequence":3257979356,"time":"2018-01-22T15:14:45.423000Z"}
{"type":"done","side":"sell","order_id":"73612b11-608f-470d-9256-b4d5780acdeb","reason":"canceled","product_id":"BTC-EUR","price":"8826.40000000","remaining_size":"0.03322226","sequence":3257979357,"time":"2018-01-22T15:14:45.426000Z"}
{"type":"done","side":"sell","order_id":"9944c48c-a556-423d-9978-bc77807324e9","reason":"canceled","product_id":"BTC-EUR","price":"8826.39000000","remaining_size":"0.00113290","sequence":3257979358,"time":"2018-01-22T15:14:45.429000Z"}
{"type":"done","side":"sell","order_id":"92195555-08ad-4083-bbcd-81fe1115ad41","reason":"canceled","product_id":"BTC-EUR","price":"8826.40000000","remaining_size":"0.01800000","sequence":3257979359,"time":"2018-01-22T15:14:45.447000Z"}
{"type":"received","order_id":"3f222f4a-04f0-45be-9025-907b81fb7277","order_type":"limit","size":"0.03322226","price":"8826.38000000","side":"sell","client_oid":"0118e398-ef7d-47a1-be7b-962603a27747","product_id":"BTC-EUR","sequence":3257979360,"time":"2018-01-22T15:14:45.451000Z"}
{"type":"open","side":"sell","price":"8826.38000000","order_id":"3f222f4a-04f0-45be-9025-907b81fb7277","remaining_size":"0.03322226","product_id":"BTC-EUR","sequence":3257979361,"time":"2018-01-22T15:14:45.451000Z"}
{"type":"received","order_id":"225a9f58-ece2-4f86-8360-f2080f48df85","order_type":"limit","size":"0.10500000","price":"8826.39000000","side":"sell","client_oid":"26c2d05b-903a-471a-b3d4-22edf72353e1","product_id":"BTC-EUR","sequence":3257979362,"time":"2018-01-22T15:14:45.468000Z"}
{"type":"open","side":"sell","price":"8826.39000000","order_id":"225a9f58-ece2-4f86-8360-f2080f48df85","remaining_size":"0.10500000","product_id":"BTC-EUR","sequence":3257979363,"time":"2018-01-22T15:14:45.468000Z"}
{"type":"done","side":"sell","order_id":"ad7008e0-dcdc-4f42-a832-482616bf07db","reason":"canceled","product_id":"BTC-EUR","price":"8826.40000000","remaining_size":"0.01800000","sequence":3257979364,"time":"2018-01-22T15:14:45.477000Z"}
{"type":"received","order_id":"6301ba25-3635-482c-b942-6b750943c061","order_type":"limit","size":"0.01800000","price":"8826.38000000","side":"sell","client_oid":"845f55e7-d102-4c9f-a748-82368b4491a9","product_id":"BTC-EUR","sequence":3257979365,"time":"2018-01-22T15:14:45.482000Z"}
{"type":"open","side":"sell","price":"8826.38000000","order_id":"6301ba25-3635-482c-b942-6b750943c061","remaining_size":"0.01800000","product_id":"BTC-EUR","sequence":3257979366,"time":"2018-01-22T15:14:45.482000Z"}
{"type":"received","order_id":"e081fa76-91c7-4ed0-8d74-6aeca8c6718a","order_type":"limit","size":"0.00113290","price":"8826.02000000","side":"sell","client_oid":"5e25f918-49dc-4504-897d-86fa0baab53d","product_id":"BTC-EUR","sequence":3257979367,"time":"2018-01-22T15:14:45.485000Z"}
{"type":"open","side":"sell","price":"8826.02000000","order_id":"e081fa76-91c7-4ed0-8d74-6aeca8c6718a","remaining_size":"0.00113290","product_id":"BTC-EUR","sequence":3257979368,"time":"2018-01-22T15:14:45.485000Z"}
{"type":"done","side":"sell","order_id":"e963c190-9f83-4be2-bb12-84451cddc0e3","reason":"canceled","product_id":"BTC-EUR","price":"8826.40000000","remaining_size":"0.09200000","sequence":3257979369,"time":"2018-01-22T15:14:45.485000Z"}
{"type":"done","side":"sell","order_id":"06ee40e3-619b-4d00-be34-5409494194a8","reason":"canceled","product_id":"BTC-EUR","price":"8826.40000000","remaining_size":"0.00200000","sequence":3257979370,"time":"2018-01-22T15:14:45.497000Z"}
{"type":"done","side":"buy","order_id":"488999c2-1796-48f2-ad3d-803e1aa79d3e","reason":"canceled","product_id":"BTC-EUR","price":"8794.21000000","remaining_size":"0.20711000","sequence":3257979371,"time":"2018-01-22T15:14:45.511000Z"}
{"type":"received","order_id":"d5f58bba-d1b6-47c9-86a6-3b84e7b4e51e","order_type":"limit","size":"0.10500000","price":"8826.39000000","side":"sell","client_oid":"15e54c35-2598-43d2-8fbd-58e640666cae","product_id":"BTC-EUR","sequence":3257979372,"time":"2018-01-22T15:14:45.511000Z"}
{"type":"open","side":"sell","price":"8826.39000000","order_id":"d5f58bba-d1b6-47c9-86a6-3b84e7b4e51e","remaining_size":"0.10500000","product_id":"BTC-EUR","sequence":3257979373,"time":"2018-01-22T15:14:45.511000Z"}
{"type":"done","side":"sell","order_id":"a05b319d-6d4d-437e-8415-7d4a567173d2","reason":"canceled","product_id":"BTC-EUR","price":"8826.03000000","remaining_size":"0.01656300","sequence":3257979374,"time":"2018-01-22T15:14:45.547000Z"}
{"type":"done","side":"sell","order_id":"c222a94b-828e-4c68-8ba9-97d83f095af5","reason":"canceled","product_id":"BTC-EUR","price":"8826.42000000","remaining_size":"0.21404538","sequence":3257979375,"time":"2018-01-22T15:14:45.549000Z"}
{"type":"done","side":"sell","order_id":"225a9f58-ece2-4f86-8360-f2080f48df85","reason":"canceled","product_id":"BTC-EUR","price":"8826.39000000","remaining_size":"0.10500000","sequence":3257979376,"time":"2018-01-22T15:14:45.550000Z"}
{"type":"done","side":"sell","order_id":"ab3e1d40-ff8d-46a8-907d-952cbef90330","reason":"canceled","product_id":"BTC-EUR","price":"8826.39000000","remaining_size":"0.06847422","sequence":3257979377,"time":"2018-01-22T15:14:45.551000Z"}
{"type":"done","side":"sell","order_id":"6301ba25-3635-482c-b942-6b750943c061","reason":"canceled","product_id":"BTC-EUR","price":"8826.38000000","remaining_size":"0.01800000","sequence":3257979378,"time":"2018-01-22T15:14:45.563000Z"}
{"type":"received","order_id":"bd5b25e2-9010-446b-9aa4-360823433538","order_type":"limit","size":"0.01800000","price":"8826.02000000","side":"sell","client_oid":"1bedbba4-ea41-41ab-b9df-795ac6996b84","product_id":"BTC-EUR","sequence":3257979379,"time":"2018-01-22T15:14:45.584000Z"}
{"type":"open","side":"sell","price":"8826.02000000","order_id":"bd5b25e2-9010-446b-9aa4-360823433538","remaining_size":"0.01800000","product_id":"BTC-EUR","sequence":3257979380,"time":"2018-01-22T15:14:45.584000Z"}
{"type":"received","order_id":"c36ea37d-9e8c-4d18-82b3-ea7834b15775","order_type":"limit","size":"0.10500000","price":"8826.03000000","side":"sell","client_oid":"2f8addd3-38b5-4555-ba2a-a63d266c02d9","product_id":"BTC-EUR","sequence":3257979381,"time":"2018-01-22T15:14:45.591000Z"}
{"type":"open","side":"sell","price":"8826.03000000","order_id":"c36ea37d-9e8c-4d18-82b3-ea7834b15775","remaining_size":"0.10500000","product_id":"BTC-EUR","sequence":3257979382,"time":"2018-01-22T15:14:45.591000Z"}
{"type":"done","side":"sell","order_id":"ad3d240b-76a0-4174-bfad-6b2b513db940","reason":"canceled","product_id":"BTC-EUR","price":"8826.43000000","remaining_size":"0.00564464","sequence":3257979383,"time":"2018-01-22T15:14:45.617000Z"}
{"type":"done","side":"sell","order_id":"d5f58bba-d1b6-47c9-86a6-3b84e7b4e51e","reason":"canceled","product_id":"BTC-EUR","price":"8826.39000000","remaining_size":"0.10500000","sequence":3257979384,"time":"2018-01-22T15:14:45.624000Z"}
